Workbook

Sheet Dashboard
A1: MRV Business Intelligence | Charm Industrial
A2: Rolling 12-month view (Jul-25 → Jun-26) | updated each reporting close
A3: YTD Net CDR (tCO₂e) | F3: Net Efficiency — YTD | K3: Last Injection → Credits (days)
A4: blended total — all sources | F4: net / gross CDR | K4: from last ton of reporting period
A6: Pipeline: injected, unverified (tCO₂e) | F6: Penalties / Gross CDR — YTD | K6: Source Concentration
A7: batches in Certify draft status | F7: all sources + downstream + well facility | K7: largest single-source % of net CDR
A9: Monthly Summary — Key Metrics (see detail tabs for drilldowns)
A10: Metric | B10: Jul-25 | C10: Aug-25 | D10: Sep-25 | E10: Oct-25 | F10: Nov-25 | G10: Dec-25 | H10: Jan-26 | I10: Feb-26 | J10: Mar-26 | K10: Apr-26 | L10: May-26 | M10: Jun-26 | N10: YTD 2026 | O10: FY 2025*
A11: Net CDR — total operation (tCO₂e) | B11: =IF('Run Rate'!B5<>"",'Run Rate'!B5,"") | C11: =IF('Run Rate'!C5<>"",'Run Rate'!C5,"") | D11: =IF('Run Rate'!D5<>"",'Run Rate'!D5,"") | E11: =IF('Run Rate'!E5<>"",'Run Rate'!E5,"") | F11: =IF('Run Rate'!F5<>"",'Run Rate'!F5,"") | G11: =IF('Run Rate'!G5<>"",'Run Rate'!G5,"") | H11: =IF('Run Rate'!H5<>"",'Run Rate'!H5,"") | I11: =IF('Run Rate'!I5<>"",'Run Rate'!I5,"") | ... M11: =IF('Run Rate'!M5<>"",'Run Rate'!M5,"") | N11: =IFERROR('Run Rate'!N5,"") | O11: 4461.21
A12: AECN | B12: =IF('Run Rate'!B6<>"",'Run Rate'!B6,"") | C12: =IF('Run Rate'!C6<>"",'Run Rate'!C6,"") | D12: =IF('Run Rate'!D6<>"",'Run Rate'!D6,"") | E12: =IF('Run Rate'!E6<>"",'Run Rate'!E6,"") | F12: =IF('Run Rate'!F6<>"",'Run Rate'!F6,"") | G12: =IF('Run Rate'!G6<>"",'Run Rate'!G6,"") | H12: =IF('Run Rate'!H6<>"",'Run Rate'!H6,"") | I12: =IF('Run Rate'!I6<>"",'Run Rate'!I6,"") | ... M12: =IF('Run Rate'!M6<>"",'Run Rate'!M6,"") | N12: =IFERROR('Run Rate'!N6,"") | O12: 1362.06
A13: Charm | B13: =IF('Run Rate'!B7<>"",'Run Rate'!B7,"") | C13: =IF('Run Rate'!C7<>"",'Run Rate'!C7,"") | D13: =IF('Run Rate'!D7<>"",'Run Rate'!D7,"") | E13: =IF('Run Rate'!E7<>"",'Run Rate'!E7,"") | F13: =IF('Run Rate'!F7<>"",'Run Rate'!F7,"") | G13: =IF('Run Rate'!G7<>"",'Run Rate'!G7,"") | H13: =IF('Run Rate'!H7<>"",'Run Rate'!H7,"") | I13: =IF('Run Rate'!I7<>"",'Run Rate'!I7,"") | ... M13: =IF('Run Rate'!M7<>"",'Run Rate'!M7,"") | N13: =IFERROR('Run Rate'!N7,"") | O13: 0
A14: Kerry | B14: =IF('Run Rate'!B8<>"",'Run Rate'!B8,"") | C14: =IF('Run Rate'!C8<>"",'Run Rate'!C8,"") | D14: =IF('Run Rate'!D8<>"",'Run Rate'!D8,"") | E14: =IF('Run Rate'!E8<>"",'Run Rate'!E8,"") | F14: =IF('Run Rate'!F8<>"",'Run Rate'!F8,"") | G14: =IF('Run Rate'!G8<>"",'Run Rate'!G8,"") | H14: =IF('Run Rate'!H8<>"",'Run Rate'!H8,"") | I14: =IF('Run Rate'!I8<>"",'Run Rate'!I8,"") | ... M14: =IF('Run Rate'!M8<>"",'Run Rate'!M8,"") | N14: =IFERROR('Run Rate'!N8,"") | O14: 242.24
A15: Gross CDR — total operation (tCO₂e) | B15: =IF('Run Rate'!B11<>"",'Run Rate'!B11,"") | C15: =IF('Run Rate'!C11<>"",'Run Rate'!C11,"") | D15: =IF('Run Rate'!D11<>"",'Run Rate'!D11,"") | E15: =IF('Run Rate'!E11<>"",'Run Rate'!E11,"") | F15: =IF('Run Rate'!F11<>"",'Run Rate'!F11,"") | G15: =IF('Run Rate'!G11<>"",'Run Rate'!G11,"") | H15: =IF('Run Rate'!H11<>"",'Run Rate'!H11,"") | I15: =IF('Run Rate'!I11<>"",'Run Rate'!I11,"") | ... M15: =IF('Run Rate'!M11<>"",'Run Rate'!M11,"") | N15: =IFERROR('Run Rate'!N11,"") | O15: 2177.562
A16: Net efficiency (net / gross CDR) | B16: =IFERROR('Efficiency'!B5,"") | C16: =IFERROR('Efficiency'!C5,"") | D16: =IFERROR('Efficiency'!D5,"") | E16: =IFERROR('Efficiency'!E5,"") | F16: =IFERROR('Efficiency'!F5,"") | G16: =IFERROR('Efficiency'!G5,"") | H16: =IFERROR('Efficiency'!H5,"") | I16: =IFERROR('Efficiency'!I5,"") | ... N16: =IFERROR('Efficiency'!N5,"") | O16: 0.7367
A17: Injected in Certify draft (pipeline, tCO₂e) | B17: =IF('Run Rate'!B17<>"",'Run Rate'!B17,"") | C17: =IF('Run Rate'!C17<>"",'Run Rate'!C17,"") | D17: =IF('Run Rate'!D17<>"",'Run Rate'!D17,"") | E17: =IF('Run Rate'!E17<>"",'Run Rate'!E17,"") | F17: =IF('Run Rate'!F17<>"",'Run Rate'!F17,"") | G17: =IF('Run Rate'!G17<>"",'Run Rate'!G17,"") | H17: =IF('Run Rate'!H17<>"",'Run Rate'!H17,"") | I17: =IF('Run Rate'!I17<>"",'Run Rate'!I17,"") | ... M17: =IF('Run Rate'!M17<>"",'Run Rate'!M17,"") | N17: =IFERROR('Run Rate'!N17,"") | O17: 0
A18: Last injection → credits (days) | B18: =IF('Run Rate'!B23<>"",'Run Rate'!B23,"") | C18: =IF('Run Rate'!C23<>"",'Run Rate'!C23,"") | D18: =IF('Run Rate'!D23<>"",'Run Rate'!D23,"") | E18: =IF('Run Rate'!E23<>"",'Run Rate'!E23,"") | F18: =IF('Run Rate'!F23<>"",'Run Rate'!F23,"") | G18: =IF('Run Rate'!G23<>"",'Run Rate'!G23,"") | H18: =IF('Run Rate'!H23<>"",'Run Rate'!H23,"") | I18: =IF('Run Rate'!I23<>"",'Run Rate'!I23,"") | ... M18: =IF('Run Rate'!M23<>"",'Run Rate'!M23,"") | N18: =IFERROR('Run Rate'!N23,"") | O18: 26.8
A19: Penalties as % of gross CDR — total | B19: =IF('Penalties'!B5>0,'Penalties'!B5/'Run Rate'!B11,"") | C19: =IF('Penalties'!C5>0,'Penalties'!C5/'Run Rate'!C11,"") | D19: =IF('Penalties'!D5>0,'Penalties'!D5/'Run Rate'!D11,"") | E19: =IF('Penalties'!E5>0,'Penalties'!E5/'Run Rate'!E11,"") | F19: =IF('Penalties'!F5>0,'Penalties'!F5/'Run Rate'!F11,"") | G19: =IF('Penalties'!G5>0,'Penalties'!G5/'Run Rate'!G11,"") | H19: =IF('Penalties'!H5>0,'Penalties'!H5/'Run Rate'!H11,"") | I19: =IF('Penalties'!I5>0,'Penalties'!I5/'Run Rate'!I11,"") | ... M19: =IF('Penalties'!M5>0,'Penalties'!M5/'Run Rate'!M11,"") | N19: =IF(SUM('Run Rate'!H11:M11)>0,SUM('Penalties'!H5:M5)/SUM('Run Rate'!H11:M11),"") | O19: 0.2633
A20: AECN share of net CDR (%) | B20: =IF('Source Mix'!B11<>"",'Source Mix'!B11,"") | C20: =IF('Source Mix'!C11<>"",'Source Mix'!C11,"") | D20: =IF('Source Mix'!D11<>"",'Source Mix'!D11,"") | E20: =IF('Source Mix'!E11<>"",'Source Mix'!E11,"") | F20: =IF('Source Mix'!F11<>"",'Source Mix'!F11,"") | G20: =IF('Source Mix'!G11<>"",'Source Mix'!G11,"") | H20: =IF('Source Mix'!H11<>"",'Source Mix'!H11,"") | I20: =IF('Source Mix'!I11<>"",'Source Mix'!I11,"") | ... M20: =IF('Source Mix'!M11<>"",'Source Mix'!M11,"") | N20: =IF(SUM('Run Rate'!H11:M11)>0,SUM('Source Mix'!H11:M11)/SUM('Run Rate'!H11:M11),"") | O20: 0.849
A21: Charm share of net CDR (%) | B21: =IF('Source Mix'!B12<>"",'Source Mix'!B12,"") | C21: =IF('Source Mix'!C12<>"",'Source Mix'!C12,"") | D21: =IF('Source Mix'!D12<>"",'Source Mix'!D12,"") | E21: =IF('Source Mix'!E12<>"",'Source Mix'!E12,"") | F21: =IF('Source Mix'!F12<>"",'Source Mix'!F12,"") | G21: =IF('Source Mix'!G12<>"",'Source Mix'!G12,"") | H21: =IF('Source Mix'!H12<>"",'Source Mix'!H12,"") | I21: =IF('Source Mix'!I12<>"",'Source Mix'!I12,"") | ... M21: =IF('Source Mix'!M12<>"",'Source Mix'!M12,"") | N21: =IF(SUM('Run Rate'!H11:M11)>0,SUM('Source Mix'!H12:M12)/SUM('Run Rate'!H11:M11),"") | O21: 0
A22: Kerry share of net CDR (%) | B22: =IF('Source Mix'!B13<>"",'Source Mix'!B13,"") | C22: =IF('Source Mix'!C13<>"",'Source Mix'!C13,"") | D22: =IF('Source Mix'!D13<>"",'Source Mix'!D13,"") | E22: =IF('Source Mix'!E13<>"",'Source Mix'!E13,"") | F22: =IF('Source Mix'!F13<>"",'Source Mix'!F13,"") | G22: =IF('Source Mix'!G13<>"",'Source Mix'!G13,"") | H22: =IF('Source Mix'!H13<>"",'Source Mix'!H13,"") | I22: =IF('Source Mix'!I13<>"",'Source Mix'!I13,"") | ... M22: =IF('Source Mix'!M13<>"",'Source Mix'!M13,"") | N22: =IF(SUM('Run Rate'!H11:M11)>0,SUM('Source Mix'!H13:M13)/SUM('Run Rate'!H11:M11),"") | O22: 0.151
A23: Charm bio-oil CI (tCO₂e / tCO₂ stored)
A24: Charm biochar CI (tCO₂e / tCO₂ stored)
A26: ℹ Last injection → credits = OKR. FY 2025* = credits issued in calendar year 2025.

Sheet Run Rate
A1: Run Rate — Net CDR Credited & Pipeline
A2: Credits attributed to month of issuance (revenue timing). Rolling 12-month. tCO₂e.
A3: Metric | B3: Jul-25 | C3: Aug-25 | D3: Sep-25 | E3: Oct-25 | F3: Nov-25 | G3: Dec-25 | H3: Jan-26 | I3: Feb-26 | J3: Mar-26 | K3: Apr-26 | L3: May-26 | M3: Jun-26 | N3: YTD 2026 | O3: FY 2025*
A4: Credited — Net CDR (tCO₂e)
A5: Total operation | C5: 555.95 | D5: 135.39 | E5: =166.40+291.85 | F5: 454.71 | I5: 43.47 | J5: 764.14 | K5: 612.99 | L5: 490.82 | N5: =SUM(H5:M5) | O5: 4461.21
A6: AECN | C6: 555.95 | D6: 0 | E6: =59.55+291.85 | F6: 454.71 | I6: 43.47 | J6: 764.14 | K6: 612.99 | L6: 475.09 | N6: =SUM(H6:M6) | O6: 1362.06
A7: Charm | C7: 0 | D7: 0 | E7: 0 | F7: 0 | G7: 0 | H7: 0 | I7: 0 | J7: 0 | K7: 0 | L7: 6.93 | N7: =SUM(H7:M7) | O7: 0
A8: Kerry | C8: 0 | D8: 135.39 | E8: 106.85 | F8: 0 | G8: 0 | H8: 0 | I8: 0 | J8: 0 | K8: 0 | L8: 8.8 | N8: =SUM(H8:M8) | O8: 242.24
A10: Gross CDR — for reference (tCO₂e, not directly credited)
A11: Total operation | C11: 804.551 | D11: 161.907 | E11: =285.139+351.170 | F11: 574.795 | I11: 157.052 | J11: 863.601 | K11: 702.779 | L11: 578.696 | N11: =SUM(H11:M11) | O11: 2177.562
A12: AECN | C12: 804.551 | D12: 0 | E12: =351.170+285.139*59.55/166.40 | F12: 574.795 | I12: 157.052 | J12: 863.601 | K12: 702.779 | L12: =578.696*475.09/490.82 | N12: =SUM(H12:M12) | O12: 1832.566
A13: Charm | B13: 0 | C13: 0 | D13: 0 | E13: 0 | F13: 0 | G13: 0 | H13: 0 | I13: 0 | J13: 0 | K13: 0 | L13: =578.696*6.93/490.82 | M13: 0 | N13: =SUM(H13:M13) | O13: 0
A14: Kerry | B14: 0 | C14: 0 | D14: 161.907 | E14: =285.139*106.85/166.40 | F14: 0 | G14: 0 | H14: 0 | I14: 0 | J14: 0 | K14: 0 | L14: =578.696*8.80/490.82 | M14: 0 | N14: =SUM(H14:M14) | O14: 344.987
A16: Pipeline — Batches in Certify Draft Status (tCO₂e)
A17: Total operation | B17: 0 | C17: 0 | D17: 0 | E17: 0 | F17: 0 | G17: 0 | H17: 0 | I17: 0 | J17: 0 | K17: 0 | L17: 0 | M17: 235.7 | N17: =SUM(H17:M17) | O17: 0
A18: AECN | B18: 0 | C18: 0 | D18: 0 | E18: 0 | F18: 0 | G18: 0 | H18: 0 | I18: 0 | J18: 0 | K18: 0 | L18: 0 | M18: =69.12+138.62+18.85 | N18: =SUM(H18:M18) | O18: 0
A19: Charm | B19: 0 | C19: 0 | D19: 0 | E19: 0 | F19: 0 | G19: 0 | H19: 0 | I19: 0 | J19: 0 | K19: 0 | L19: 0 | M19: 0 | N19: =SUM(H19:M19) | O19: 0
A20: Kerry | B20: 0 | C20: 0 | D20: 0 | E20: 0 | F20: 0 | G20: 0 | H20: 0 | I20: 0 | J20: 0 | K20: 0 | L20: 0 | M20: 9.11 | N20: =SUM(H20:M20) | O20: 0
A22: Verification Timing
A23: Last injection → credits — total operation (days) [OKR metric] | C23: 27 | D23: 35 | E23: 31 | F23: 14 | I23: 68 | J23: 8 | K23: 21 | L23: 14 | N23: 26.8 | O23: 26.8
A24: Last injection of period → period close (days) | C24: 8 | D24: 0 | E24: 0 | F24: 1 | I24: 50 | J24: 0 | K24: 5 | L24: 1 | N24: 2.2 | O24: 2.2
A25: Period close → credit issuance (days) | C25: 19 | D25: 35 | E25: 31 | F25: 13 | I25: 18 | J25: 8 | K25: 16 | L25: 13 | N25: 24.5 | O25: 24.5
A27: Blended avg injection-to-credit lag — total (days, ton-weighted)
A28: AECN blended avg lag (days)
A29: Charm blended avg lag (days)
A30: Kerry blended avg lag (days)
A32: ℹ FY 2025* = credits issued in calendar year 2025 = 4,461.21 tCO₂e. Oct-25 cell = =166.40+291.85 (two periods both issued Oct 2025). Source breakdown (AECN/Charm/Kerry) pending — requires drilling individual GHG statements.
A34: ▸ Chart: Net CDR Credited — Monthly (tCO₂e)

Sheet Efficiency
A1: Efficiency — Net CDR Yield
A2: Net/gross CDR and net CDR per tonne injected
A3: Metric | B3: Jul-25 | C3: Aug-25 | D3: Sep-25 | E3: Oct-25 | F3: Nov-25 | G3: Dec-25 | H3: Jan-26 | I3: Feb-26 | J3: Mar-26 | K3: Apr-26 | L3: May-26 | M3: Jun-26 | N3: YTD 2026 | O3: FY 2025*
A4: Net CDR / Gross CDR (carbon efficiency ratio)
A5: Total operation | B5: =IF(B18>0,B17/B18,"") | C5: =IF(C18>0,C17/C18,"") | D5: =IF(D18>0,D17/D18,"") | E5: =IF(E18>0,E17/E18,"") | F5: =IF(F18>0,F17/F18,"") | G5: =IF(G18>0,G17/G18,"") | H5: =IF(H18>0,H17/H18,"") | I5: =IF(I18>0,I17/I18,"") | ... M5: =IF(M18>0,M17/M18,"") | N5: =IF(SUM(H18:M18)>0,SUM(H17:M17)/SUM(H18:M18),"") | O5: 0.7367
A6: AECN | B6: =IF('Run Rate'!B12>0,'Run Rate'!B6/'Run Rate'!B12,"") | C6: =IF('Run Rate'!C12>0,'Run Rate'!C6/'Run Rate'!C12,"") | D6: =IF('Run Rate'!D12>0,'Run Rate'!D6/'Run Rate'!D12,"") | E6: =IF('Run Rate'!E12>0,'Run Rate'!E6/'Run Rate'!E12,"") | F6: =IF('Run Rate'!F12>0,'Run Rate'!F6/'Run Rate'!F12,"") | G6: =IF('Run Rate'!G12>0,'Run Rate'!G6/'Run Rate'!G12,"") | H6: =IF('Run Rate'!H12>0,'Run Rate'!H6/'Run Rate'!H12,"") | I6: =IF('Run Rate'!I12>0,'Run Rate'!I6/'Run Rate'!I12,"") | ... M6: =IF('Run Rate'!M12>0,'Run Rate'!M6/'Run Rate'!M12,"") | N6: =IF(SUM('Run Rate'!H12:M12)>0,SUM('Run Rate'!H6:M6)/SUM('Run Rate'!H12:M12),"") | O6: 0.7433
A7: Charm | B7: =IF('Run Rate'!B13>0,'Run Rate'!B7/'Run Rate'!B13,"") | C7: =IF('Run Rate'!C13>0,'Run Rate'!C7/'Run Rate'!C13,"") | D7: =IF('Run Rate'!D13>0,'Run Rate'!D7/'Run Rate'!D13,"") | E7: =IF('Run Rate'!E13>0,'Run Rate'!E7/'Run Rate'!E13,"") | F7: =IF('Run Rate'!F13>0,'Run Rate'!F7/'Run Rate'!F13,"") | G7: =IF('Run Rate'!G13>0,'Run Rate'!G7/'Run Rate'!G13,"") | H7: =IF('Run Rate'!H13>0,'Run Rate'!H7/'Run Rate'!H13,"") | I7: =IF('Run Rate'!I13>0,'Run Rate'!I7/'Run Rate'!I13,"") | ... M7: =IF('Run Rate'!M13>0,'Run Rate'!M7/'Run Rate'!M13,"") | N7: =IF(SUM('Run Rate'!H13:M13)>0,SUM('Run Rate'!H7:M7)/SUM('Run Rate'!H13:M13),"")
A8: Kerry | B8: =IF('Run Rate'!B14>0,'Run Rate'!B8/'Run Rate'!B14,"") | C8: =IF('Run Rate'!C14>0,'Run Rate'!C8/'Run Rate'!C14,"") | D8: =IF('Run Rate'!D14>0,'Run Rate'!D8/'Run Rate'!D14,"") | E8: =IF('Run Rate'!E14>0,'Run Rate'!E8/'Run Rate'!E14,"") | F8: =IF('Run Rate'!F14>0,'Run Rate'!F8/'Run Rate'!F14,"") | G8: =IF('Run Rate'!G14>0,'Run Rate'!G8/'Run Rate'!G14,"") | H8: =IF('Run Rate'!H14>0,'Run Rate'!H8/'Run Rate'!H14,"") | I8: =IF('Run Rate'!I14>0,'Run Rate'!I8/'Run Rate'!I14,"") | ... M8: =IF('Run Rate'!M14>0,'Run Rate'!M8/'Run Rate'!M14,"") | N8: =IF(SUM('Run Rate'!H14:M14)>0,SUM('Run Rate'!H8:M8)/SUM('Run Rate'!H14:M14),"") | O8: 0.7022
A10: Net CDR per Tonne Bio-Oil Injected (tCO₂e / tonne)
A11: Total operation | B11: =IF(B19>0,B17/B19,"") | C11: =IF(C19>0,C17/C19,"") | D11: =IF(D19>0,D17/D19,"") | E11: =IF(E19>0,E17/E19,"") | F11: =IF(F19>0,F17/F19,"") | G11: =IF(G19>0,G17/G19,"") | H11: =IF(H19>0,H17/H19,"") | I11: =IF(I19>0,I17/I19,"") | ... M11: =IF(M19>0,M17/M19,"") | N11: =IF(SUM(H19:M19)>0,SUM(H17:M17)/SUM(H19:M19),"") | O11: 0.9707
A12: AECN | B12: =IF(B20>0,'Run Rate'!B6/B20,"") | C12: =IF(C20>0,'Run Rate'!C6/C20,"") | D12: =IF(D20>0,'Run Rate'!D6/D20,"") | E12: =IF(E20>0,'Run Rate'!E6/E20,"") | F12: =IF(F20>0,'Run Rate'!F6/F20,"") | G12: =IF(G20>0,'Run Rate'!G6/G20,"") | H12: =IF(H20>0,'Run Rate'!H6/H20,"") | I12: =IF(I20>0,'Run Rate'!I6/I20,"") | ... M12: =IF(M20>0,'Run Rate'!M6/M20,"") | O12: 0.9981
A13: Charm | B13: =IF(B21>0,'Run Rate'!B7/B21,"") | C13: =IF(C21>0,'Run Rate'!C7/C21,"") | D13: =IF(D21>0,'Run Rate'!D7/D21,"") | E13: =IF(E21>0,'Run Rate'!E7/E21,"") | F13: =IF(F21>0,'Run Rate'!F7/F21,"") | G13: =IF(G21>0,'Run Rate'!G7/G21,"") | H13: =IF(H21>0,'Run Rate'!H7/H21,"") | I13: =IF(I21>0,'Run Rate'!I7/I21,"") | ... M13: =IF(M21>0,'Run Rate'!M7/M21,"")
A14: Kerry | B14: =IF(B22>0,'Run Rate'!B8/B22,"") | C14: =IF(C22>0,'Run Rate'!C8/C22,"") | D14: =IF(D22>0,'Run Rate'!D8/D22,"") | E14: =IF(E22>0,'Run Rate'!E8/E22,"") | F14: =IF(F22>0,'Run Rate'!F8/F22,"") | G14: =IF(G22>0,'Run Rate'!G8/G22,"") | H14: =IF(H22>0,'Run Rate'!H8/H22,"") | I14: =IF(I22>0,'Run Rate'!I8/I22,"") | ... M14: =IF(M22>0,'Run Rate'!M8/M22,"") | O14: 0.8408
A16: Memo: Volumes
A17: Net CDR — total (tCO₂e) | C17: 555.95 | D17: 135.39 | E17: =166.40+291.85 | F17: 454.71 | I17: 43.47 | J17: 764.14 | K17: 612.99 | L17: 490.82 | N17: =SUM(H17:M17) | O17: 1604.3
A18: Gross CDR — total (tCO₂e) | C18: 804.551 | D18: 161.907 | E18: =285.139+351.170 | F18: 574.795 | I18: 157.052 | J18: 863.601 | K18: 702.779 | L18: 578.696 | N18: =SUM(H18:M18) | O18: 2177.562
A19: Bio-oil injected — total (tonnes) | C19: 553.599 | D19: 118.562 | E19: =264.139+284.436 | F19: 432.06 | I19: 98.867 | J19: 568.558 | K19: 462.251 | L19: 407.596 | M19: 198.977 | N19: =SUM(H19:M19) | O19: 1652.796
A20: AECN bio-oil injected (tonnes) | C20: 553.599 | D20: 0 | E20: =284.436+264.139*59.55/166.40 | F20: 432.06 | I20: 98.867 | J20: 568.558 | K20: 462.251 | L20: =407.596*475.09/490.82 | M20: =121.287+22.835+50.297 | N20: =SUM(H20:M20) | O20: 1364.695
A21: Charm bio-oil injected (tonnes) | C21: 20.928 | D21: 12.63 | E21: 14.227 | F21: 9.984 | G21: 6.481 | H21: 8.888 | I21: 10.966 | J21: 16.307 | L21: 5.7549413 | N21: =SUM(H21:M21) | O21: 0
A22: Kerry bio-oil injected (tonnes) | C22: 0 | D22: 118.562 | E22: =264.139*106.85/166.40 | F22: 0 | I22: 0 | J22: 0 | K22: 0 | L22: =407.596*8.80/490.82 | M22: 4.558 | N22: =SUM(H22:M22) | O22: 288.101
A23: ℹ Efficiency ratios: derive YTD from YTD memo row totals.
A26: ▸ Chart: Net/Gross CDR Efficiency — Monthly

Sheet Penalties
A1: Penalties — Emission Deductions from Gross CDR
A2: System flow: Charm prod → AECN prod → Kerry prod → Downstream Transport → Well Facility
A3: Metric | B3: Jul-25 | C3: Aug-25 | D3: Sep-25 | E3: Oct-25 | F3: Nov-25 | G3: Dec-25 | H3: Jan-26 | I3: Feb-26 | J3: Mar-26 | K3: Apr-26 | L3: May-26 | M3: Jun-26 | N3: YTD 2026 | O3: FY 2025*
A4: Total Penalties — All Sources (tCO₂e)
A5: Total operation | C5: 248.601 | D5: 26.517 | E5: =285.139+351.170-166.40-291.85 | F5: 120.085 | I5: 113.582 | J5: 99.461 | K5: 89.789 | L5: 87.876 | N5: =SUM(H5:M5) | O5: 573.262
A6: Charm (production-side) | C6: 25.021 | D6: 16.508 | E6: 20.105 | F6: 16.396 | G6: 13.523 | H6: 16.552 | I6: 17.724 | J6: 20.497 | N6: =SUM(H6:M6) | O6: 66.532
A7: AECN (production-side) | C7: 248.601 | D7: 0 | E7: =59.32+118.739*59.55/166.40 | F7: 120.085 | I7: 113.582 | J7: 99.461 | K7: 89.789 | L7: =87.876*475.09/490.82 | N7: =SUM(H7:M7) | O7: 470.476
A8: Kerry (production-side) | B8: 0 | C8: 0 | D8: 26.517 | E8: =118.739*106.85/166.40 | F8: 0 | G8: 0 | H8: 0 | I8: 0 | J8: 0 | K8: 0 | L8: =87.876*8.80/490.82 | M8: 0 | N8: =SUM(H8:M8) | O8: 102.787
A9: Downstream transport | C9: 4.859488 | D9: 3.631574 | E9: =453.22*0.00604+183.08*0.02243 | F9: 3.4717618 | I9: 0.94859408 | J9: 5.21615 | K9: 4.2447852 | L9: =560.21*0.00604+10.367*0.02243 | N9: =SUM(H9:M9) | O9: 18.81
A10: Well facility (site emissions) | C10: 176.185 | D10: 2.988 | E10: =148.307+13.730 | F10: 24.975 | I10: 129.935 | J10: 26.473 | K10: 0 | L10: 15.413 | N10: =SUM(H10:M10) | O10: 366.185
A12: Charm — Production Penalties (tCO₂e)
A13: Energy — propane (pyrolysis / drying) | C13: 16.023 | D13: 8.638 | E13: 12.905 | F13: 10.574 | G13: 8.205 | H13: 10.232 | I13: 11.194 | J13: 12.269 | N13: =SUM(H13:M13) | O13: 40.322
A14: Capital Goods EE (equipment amortization) | C14: 4.231 | D14: 3.091 | E14: 2.474 | F14: 1.202 | G14: 1.527 | H14: 2.28 | I14: 2.458 | J14: 3.379 | N14: =SUM(H14:M14) | O14: 8.294
A15: Transportation — truck (feedstock to facility) | C15: 1.299 | D15: 2.218 | E15: 1.174 | F15: 1.368 | G15: 1.76 | H15: 1.734 | I15: 1.332 | J15: 1.754 | N15: =SUM(H15:M15) | O15: 6.52
A16: SP+C EE (spare parts & consumables) | C16: 1.768 | D16: 1.015 | E16: 1.286 | F16: 0.906 | G16: 0.658 | H16: 0.879 | I16: 0.994 | J16: 1.354 | N16: =SUM(H16:M16) | O16: 3.865
A17: Energy — electricity | C17: 1.34 | D17: 0.985 | E17: 1.157 | F17: 1.002 | G17: 0.747 | H17: 1.004 | I17: 1.033 | J17: 1.11 | N17: =SUM(H17:M17) | O17: 3.891
A18: Other / residual (gasoline, tailgas, water, waste — each <5% avg) | C18: 0.355 | D18: 0.559 | E18: 1.119 | F18: 1.339 | G18: 0.627 | H18: 0.416 | I18: 0.709 | J18: 0.645 | N18: =SUM(H18:M18) | O18: 3.644
A20: AECN — Production Penalties (tCO₂e)
A21: Transportation — truck (feedstock to facility) | B21: 0 | C21: 0 | D21: 0 | E21: 0 | F21: 0 | G21: 0 | H21: 0 | I21: 0 | J21: 0 | K21: 0 | L21: 0 | M21: 0 | N21: =SUM(H21:M21) | O21: 0
A22: Energy — electricity | B22: 0 | C22: 0 | D22: 0 | E22: 0 | F22: 0 | G22: 0 | H22: 0 | I22: 0 | J22: 0 | K22: 0 | L22: 0 | M22: 0 | N22: =SUM(H22:M22) | O22: 0
A23: N₂O / process emissions | C23: 1.243 | D23: 0 | E23: 0.509 | F23: 0.6 | I23: 0.568 | J23: 0.497 | K23: 0.449 | L23: 0.425 | N23: 1.939 | O23: 2.352
A24: Other / residual | C24: 247.358 | D24: 0 | E24: 101.281 | F24: 119.485 | I24: 113.014 | J24: 98.964 | K24: 89.34 | L24: 84.645 | N24: =SUM(H24:M24) | O24: 468.124
A26: Kerry — Production Penalties (tCO₂e)
A27: Transportation — truck (feedstock to facility) | B27: 0 | C27: 0 | D27: 0 | E27: 0 | F27: 0 | G27: 0 | H27: 0 | I27: 0 | J27: 0 | K27: 0 | L27: 0 | M27: 0 | N27: =SUM(H27:M27) | O27: 0
A28: Energy — electricity | B28: 0 | C28: 0 | D28: 0 | E28: 0 | F28: 0 | G28: 0 | H28: 0 | I28: 0 | J28: 0 | K28: 0 | L28: 0 | M28: 0 | N28: =SUM(H28:M28) | O28: 0
A29: N₂O / process emissions | B29: 0 | C29: 0 | D29: 0 | E29: 0 | F29: 0 | G29: 0 | H29: 0 | I29: 0 | J29: 0 | K29: 0 | L29: 0 | M29: 0 | N29: =SUM(H29:M29) | O29: 0
A30: Other / residual | B30: 0 | C30: 0 | D30: 0 | E30: 0 | F30: 0 | G30: 0 | H30: 0 | I30: 0 | J30: 0 | K30: 0 | L30: 0 | M30: 0 | N30: =SUM(H30:M30) | O30: 0
A32: Downstream Transport — Oil to Injection Well (tCO₂e)
A33: Total all sources | B33: =SUM(B34:B40) | C33: =SUM(C34:C40) | D33: =SUM(D34:D40) | E33: =SUM(E34:E40) | F33: =SUM(F34:F40) | G33: =SUM(G34:G40) | H33: =SUM(H34:H40) | I33: =SUM(I34:I40) | ... M33: =SUM(M34:M40) | N33: =SUM(H33:M33) | O33: 18.81
A34: AECN — rail to injection well | B34: 0 | C34: 0 | D34: 0 | E34: 0 | F34: 0 | G34: 0 | H34: 0 | I34: 0 | J34: 0 | K34: 0 | L34: 0 | M34: 0 | N34: =SUM(H34:M34)
A35: AECN — final truck to injection well | C35: 4.859 | D35: 0 | E35: 2.737 | F35: 3.472 | I35: 0.949 | J35: 5.216 | K35: 4.245 | L35: 3.384 | N35: =SUM(H35:M35) | O35: 11.069
A36: Charm — rail to injection well | B36: 0 | C36: 0 | D36: 0 | E36: 0 | F36: 0 | G36: 0 | H36: 0 | I36: 0 | J36: 0 | K36: 0 | L36: 0 | M36: 0 | N36: 0 | O36: 0
A37: Charm — final truck to injection well | B37: 0 | C37: 0 | D37: 0 | E37: 0 | F37: 0 | G37: 0 | H37: 0 | I37: 0 | J37: 0 | K37: 0 | L37: 0 | M37: 0 | N37: 0 | O37: 0
A38: Kerry — rail to injection well | B38: 0 | C38: 0 | D38: 0 | E38: 0 | F38: 0 | G38: 0 | H38: 0 | I38: 0 | J38: 0 | K38: 0 | L38: 0 | M38: 0 | N38: 0 | O38: 0
A39: Kerry — final truck to injection well | D39: 3.632 | E39: 4.106 | L39: 0.233 | N39: =SUM(H39:M39) | O39: 7.738
A41: Well Facility — Site Emissions (tCO₂e)
A42: Energy — electricity (injection site operations) | L42: 2.168 | N42: =SUM(H42:M42) | O42: 0
A43: Energy — methanol (well operations) | L43: 2.731 | N43: =SUM(H43:M43) | O43: 0
A44: Fugitive / venting emissions | L44: 0.162 | N44: =SUM(H44:M44) | O44: 0
A45: Other site emissions | L45: =15.413-2.168-2.731-0.162 | N45: =SUM(H45:M45) | O45: 0
...

Sheet Scaling Analysis
A1: Scaling Analysis — Penalty Trendlines vs. Volume
A2: Slope & R² per penalty type vs. bio-oil volume. Diagnosis: R²≥0.85=Linear | 0.60-0.84=Investigate | <0.60=Non-linear.
A3: Penalty Type | B3: Source | C3: N (months) | D3: Slope vs Volume | E3: Intercept | F3: R² | G3: Diagnosis
A4: Energy — propane (pyrolysis / drying) | B4: Charm | C4: =COUNTA('Penalties'!B13:M13) | D4: link vol row | E4: link vol row | F4: link vol row | G4: link vol row
A5: Capital Goods EE (equipment amortization) | B5: Charm | C5: =COUNTA('Penalties'!B14:M14) | D5: link vol row | E5: link vol row | F5: link vol row | G5: link vol row
A6: Transportation — truck (feedstock to facility) | B6: Charm | C6: =COUNTA('Penalties'!B15:M15) | D6: link vol row | E6: link vol row | F6: link vol row | G6: link vol row
A7: SP+C EE (spare parts & consumables) | B7: Charm | C7: =COUNTA('Penalties'!B16:M16) | D7: link vol row | E7: link vol row | F7: link vol row | G7: link vol row
A8: Energy — electricity | B8: Charm | C8: =COUNTA('Penalties'!B17:M17) | D8: link vol row | E8: link vol row | F8: link vol row | G8: link vol row
A9: Other / residual (gasoline, tailgas, water, waste — each <5% avg) | B9: Charm | C9: =COUNTA('Penalties'!B18:M18) | D9: link vol row | E9: link vol row | F9: link vol row | G9: link vol row
A10: Transportation — truck (feedstock to facility) | B10: AECN | C10: =COUNTA('Penalties'!B21:M21) | D10: link vol row | E10: link vol row | F10: link vol row | G10: link vol row
A11: Energy — electricity | B11: AECN | C11: =COUNTA('Penalties'!B22:M22) | D11: link vol row | E11: link vol row | F11: link vol row | G11: link vol row
A12: N₂O / process emissions | B12: AECN | C12: =COUNTA('Penalties'!B23:M23) | D12: link vol row | E12: link vol row | F12: link vol row | G12: link vol row
A13: Other / residual | B13: AECN | C13: =COUNTA('Penalties'!B24:M24) | D13: link vol row | E13: link vol row | F13: link vol row | G13: link vol row
A14: Transportation — truck (feedstock to facility) | B14: Kerry | C14: =COUNTA('Penalties'!B27:M27) | D14: link vol row | E14: link vol row | F14: link vol row | G14: link vol row
A15: Energy — electricity | B15: Kerry | C15: =COUNTA('Penalties'!B28:M28) | D15: link vol row | E15: link vol row | F15: link vol row | G15: link vol row
A16: N₂O / process emissions | B16: Kerry | C16: =COUNTA('Penalties'!B29:M29) | D16: link vol row | E16: link vol row | F16: link vol row | G16: link vol row
A17: Other / residual | B17: Kerry | C17: =COUNTA('Penalties'!B30:M30) | D17: link vol row | E17: link vol row | F17: link vol row | G17: link vol row
A18: Energy — electricity (injection site operations) | B18: Site | C18: =COUNTA('Penalties'!B42:M42) | D18: link vol row | E18: link vol row | F18: link vol row | G18: link vol row
A19: Energy — methanol (well operations) | B19: Site | C19: =COUNTA('Penalties'!B43:M43) | D19: link vol row | E19: link vol row | F19: link vol row | G19: link vol row
A20: Fugitive / venting emissions | B20: Site | C20: =COUNTA('Penalties'!B44:M44) | D20: link vol row | E20: link vol row | F20: link vol row | G20: link vol row
A21: Other site emissions | B21: Site | C21: =COUNTA('Penalties'!B45:M45) | D21: link vol row | E21: link vol row | F21: link vol row | G21: link vol row
A23: ℹ Wire D=SLOPE, E=INTERCEPT, F=RSQ against Production (Charm) bio-oil volume row after data is connected.

Sheet Production (Charm)
A1: Production — Charm Bio-Oil & Biochar (Charm-produced oil only)
A2: Source: Charm PP close summary sheets. Jul-25 not separate (combined Jun-Jul period). Apr-26 pending PP close.
A3: Metric | B3: Jul-25 | C3: Aug-25 | D3: Sep-25 | E3: Oct-25 | F3: Nov-25 | G3: Dec-25 | H3: Jan-26 | I3: Feb-26 | J3: Mar-26 | K3: Apr-26 | L3: May-26 | M3: Jun-26 | N3: YTD 2026 | O3: FY 2025*
A4: Inputs — Biomass Processed by Charm
A5: Total dry biomass processed (dry MT) | C5: 84.84 | D5: 64.58 | E5: 47.45 | F5: 25 | G5: 28.95 | H5: 44.93 | I5: 47.98 | J5: 65.4 | N5: =SUM(H5:M5) | O5: 250.82
A7: Bio-Oil (WODO) — Output & Yield
A8: Bio-oil produced (MT) | C8: 20.928 | D8: 12.63 | E8: 14.227 | F8: 9.984 | G8: 6.481 | H8: 8.888 | I8: 10.966 | J8: 16.307 | N8: =SUM(H8:M8) | O8: 64.25
A9: Bio-oil carbon mass (tC) | C9: 10.353 | D9: 6.573 | E9: 8.247 | F9: 5.684 | G9: 3.157 | H9: 5.051 | I9: 5.744 | J9: 8.326 | N9: =SUM(H9:M9) | O9: 34.014
A10: Carbon yield: bio-oil C / biomass C input (%)
A12: Bio-Oil Carbon Intensity (tCO₂e / tCO₂ net CDR stored)
A13: Bio-oil CI | L13: 5.1435606
A15: Biochar — Output & Yield
A16: Biochar produced (MT) | C16: 9.186 | D16: 3.868 | E16: 8.085 | F16: 4.58 | G16: 4.074 | H16: 6.56 | I16: 6.766 | J16: 6.259 | N16: =SUM(H16:M16) | O16: 29.793
A17: Biochar carbon mass (tC) | C17: 7.931 | D17: 3.304 | E17: 7.399 | F17: 3.891 | G17: 3.619 | H17: 5.047 | I17: 5.228 | J17: 4.92 | N17: =SUM(H17:M17) | O17: 26.144
A18: Carbon yield: biochar C / biomass C input (%)
A20: Biochar Carbon Intensity (tCO₂e / tCO₂ net CDR stored)
A21: Biochar CI | L21: 1.8703963
A23: ℹ CI pending (needs net CDR from GHG statements). For final values use Charm MRV folder in RP packages.
A25: ▸ Chart: Production Volumes — Monthly (MT)
A51: ▸ Chart: Carbon Mass — Monthly (tC)

Sheet Source Mix
A1: Source Mix — Concentration & Efficiency by Oil Source
A2: Share of net CDR from each source + per-source efficiency roll-up
A3: Metric | B3: Jul-25 | C3: Aug-25 | D3: Sep-25 | E3: Oct-25 | F3: Nov-25 | G3: Dec-25 | H3: Jan-26 | I3: Feb-26 | J3: Mar-26 | K3: Apr-26 | L3: May-26 | M3: Jun-26 | N3: YTD 2026 | O3: FY 2025*
A4: Net CDR (tCO₂e) by Source — Absolute
A5: Total operation | C5: 555.95 | D5: 135.39 | E5: =166.40+291.85 | F5: 454.71 | I5: 43.47 | J5: 764.14 | K5: 612.99 | L5: 490.82 | N5: =SUM(H5:M5) | O5: 1604.3
A6: AECN | C6: 555.95 | D6: 0 | E6: =59.55+291.85 | F6: 454.71 | I6: 43.47 | J6: 764.14 | K6: 612.99 | L6: 475.09 | N6: =SUM(H6:M6) | O6: 1362.06
A7: Charm | C7: 0 | D7: 0 | E7: 0 | F7: 0 | G7: 0 | H7: 0 | I7: 0 | J7: 0 | K7: 0 | L7: 6.93 | N7: =SUM(H7:M7) | O7: 0
A8: Kerry | C8: 0 | D8: 135.39 | E8: 106.85 | F8: 0 | G8: 0 | H8: 0 | I8: 0 | J8: 0 | K8: 0 | L8: 8.8 | N8: =SUM(H8:M8) | O8: 242.24
A10: Net CDR Share by Source (% of total net CDR)
A11: AECN | B11: =IF(B5>0,B6/B5,"") | C11: =IF(C5>0,C6/C5,"") | D11: =IF(D5>0,D6/D5,"") | E11: =IF(E5>0,E6/E5,"") | F11: =IF(F5>0,F6/F5,"") | G11: =IF(G5>0,G6/G5,"") | H11: =IF(H5>0,H6/H5,"") | I11: =IF(I5>0,I6/I5,"") | ... M11: =IF(M5>0,M6/M5,"") | N11: =IF(SUM(H5:M5)>0,SUM(H6:M6)/SUM(H5:M5),"") | O11: 0.849
A12: Charm | B12: =IF(B5>0,B7/B5,"") | C12: =IF(C5>0,C7/C5,"") | D12: =IF(D5>0,D7/D5,"") | E12: =IF(E5>0,E7/E5,"") | F12: =IF(F5>0,F7/F5,"") | G12: =IF(G5>0,G7/G5,"") | H12: =IF(H5>0,H7/H5,"") | I12: =IF(I5>0,I7/I5,"") | ... M12: =IF(M5>0,M7/M5,"") | N12: =IF(SUM(H5:M5)>0,SUM(H7:M7)/SUM(H5:M5),"") | O12: 0
A13: Kerry | B13: =IF(B5>0,B8/B5,"") | C13: =IF(C5>0,C8/C5,"") | D13: =IF(D5>0,D8/D5,"") | E13: =IF(E5>0,E8/E5,"") | F13: =IF(F5>0,F8/F5,"") | G13: =IF(G5>0,G8/G5,"") | H13: =IF(H5>0,H8/H5,"") | I13: =IF(I5>0,I8/I5,"") | ... M13: =IF(M5>0,M8/M5,"") | N13: =IF(SUM(H5:M5)>0,SUM(H8:M8)/SUM(H5:M5),"") | O13: 0.151
A15: Gross CDR (tCO₂e) by Source — Absolute
A16: Total operation | C16: 804.551 | D16: 161.907 | E16: =285.139+351.170 | F16: 574.795 | I16: 157.052 | J16: 863.601 | K16: 702.779 | L16: 578.696 | N16: =SUM(H16:M16) | O16: 2177.562
A17: AECN | C17: 804.551 | D17: 0 | E17: =351.170+285.139*59.55/166.40 | F17: 574.795 | I17: 157.052 | J17: 863.601 | K17: 702.779 | L17: =578.696*475.09/490.82 | N17: =SUM(H17:M17) | O17: 1832.566
A18: Charm | B18: 0 | C18: 0 | D18: 0 | E18: 0 | F18: 0 | G18: 0 | H18: 0 | I18: 0 | J18: 0 | K18: 0 | L18: =578.696*6.93/490.82 | M18: 0 | N18: =SUM(H18:M18) | O18: 0
A19: Kerry | B19: 0 | C19: 0 | D19: 161.907 | E19: =285.139*106.85/166.40 | F19: 0 | G19: 0 | H19: 0 | I19: 0 | J19: 0 | K19: 0 | L19: =578.696*8.80/490.82 | M19: 0 | N19: =SUM(H19:M19) | O19: 344.987
A21: Efficiency Roll-Up by Source (Net / Gross CDR)
A22: Total operation | B22: =IF(B16>0,B5/B16,"") | C22: =IF(C16>0,C5/C16,"") | D22: =IF(D16>0,D5/D16,"") | E22: =IF(E16>0,E5/E16,"") | F22: =IF(F16>0,F5/F16,"") | G22: =IF(G16>0,G5/G16,"") | H22: =IF(H16>0,H5/H16,"") | I22: =IF(I16>0,I5/I16,"") | ... M22: =IF(M16>0,M5/M16,"") | N22: =IF(SUM(H16:M16)>0,SUM(H5:M5)/SUM(H16:M16),"") | O22: 0.7367
A23: AECN | B23: =IF(B17>0,B6/B17,"") | C23: =IF(C17>0,C6/C17,"") | D23: =IF(D17>0,D6/D17,"") | E23: =IF(E17>0,E6/E17,"") | F23: =IF(F17>0,F6/F17,"") | G23: =IF(G17>0,G6/G17,"") | H23: =IF(H17>0,H6/H17,"") | I23: =IF(I17>0,I6/I17,"") | ... M23: =IF(M17>0,M6/M17,"") | N23: =IF(SUM(H17:M17)>0,SUM(H6:M6)/SUM(H17:M17),"") | O23: 0.7433
A24: Charm | B24: =IF(B18>0,B7/B18,"") | C24: =IF(C18>0,C7/C18,"") | D24: =IF(D18>0,D7/D18,"") | E24: =IF(E18>0,E7/E18,"") | F24: =IF(F18>0,F7/F18,"") | G24: =IF(G18>0,G7/G18,"") | H24: =IF(H18>0,H7/H18,"") | I24: =IF(I18>0,I7/I18,"") | ... M24: =IF(M18>0,M7/M18,"") | N24: =IF(SUM(H18:M18)>0,SUM(H7:M7)/SUM(H18:M18),"")
A25: Kerry | B25: =IF(B19>0,B8/B19,"") | C25: =IF(C19>0,C8/C19,"") | D25: =IF(D19>0,D8/D19,"") | E25: =IF(E19>0,E8/E19,"") | F25: =IF(F19>0,F8/F19,"") | G25: =IF(G19>0,G8/G19,"") | H25: =IF(H19>0,H8/H19,"") | I25: =IF(I19>0,I8/I19,"") | ... M25: =IF(M19>0,M8/M19,"") | N25: =IF(SUM(H19:M19)>0,SUM(H8:M8)/SUM(H19:M19),"") | O25: 0.7022
A27: Concentration Risk
A28: Largest single-source share of net CDR (%) | B28: =IF(B5>0,MAX(B11,B12,B13),"") | C28: =IF(C5>0,MAX(C11,C12,C13),"") | D28: =IF(D5>0,MAX(D11,D12,D13),"") | E28: =IF(E5>0,MAX(E11,E12,E13),"") | F28: =IF(F5>0,MAX(F11,F12,F13),"") | G28: =IF(G5>0,MAX(G11,G12,G13),"") | H28: =IF(H5>0,MAX(H11,H12,H13),"") | I28: =IF(I5>0,MAX(I11,I12,I13),"") | ... M28: =IF(M5>0,MAX(M11,M12,M13),"") | N28: =IF(SUM(H5:M5)>0,MAX(SUM(H11:M11)/SUM(H5:M5),SUM(H12:M12)/SUM(H5:M5),SUM(H13:M13)/SUM(H5:M5)),"") | O28: 0.849
A29: Number of active sources this month | C29: 1 | D29: 1 | E29: 2 | F29: 1 | I29: 1 | J29: 1 | K29: 1 | L29: 3 | N29: 3 | O29: 2
A31: ℹ Share and efficiency: no YTD auto-sum — derive from YTD absolute rows.
A33: ▸ Chart: Net CDR by Source — Monthly (tCO₂e)
A59: ▸ Chart: Efficiency by Source — Monthly

Sheet Protocol Headroom
A1: ⚠ Protocol Headroom [WORK IN PROGRESS — thresholds not confirmed]
A2: Verify all thresholds against BSSE v1.2 and PDD before use.
A3: Parameter | B3: Protocol / Source | C3: Threshold (⚠ unconfirmed) | D3: Current Value | E3: Prior Period | F3: Trend | G3: Headroom | H3: Status
A4: Bio-oil H:C atomic ratio | B4: ⚠ confirm source | C4: ⚠ confirm threshold | D4: — | E4: — | F4: — | G4: — | H4: —
A5: Bio-oil carbon content (%) | B5: ⚠ confirm source | C5: ⚠ confirm threshold | D5: — | E5: — | F5: — | G5: — | H5: —
A6: Bio-oil oxygen content (%) | B6: ⚠ confirm source | C6: ⚠ confirm threshold | D6: — | E6: — | F6: — | G6: — | H6: —
A7: Biomass moisture at sampling (%) | B7: ⚠ confirm source | C7: ⚠ confirm threshold | D7: — | E7: — | F7: — | G7: — | H7: —
A8: Mass balance closure (%) | B8: ⚠ confirm source | C8: ⚠ confirm threshold | D8: — | E8: — | F8: — | G8: — | H8: —
A9: BOL vs. scale mass discrepancy (%) | B9: ⚠ confirm source | C9: ⚠ confirm threshold | D9: — | E9: — | F9: — | G9: — | H9: —
A10: Net CDR / Gross CDR ratio | B10: ⚠ confirm source | C10: ⚠ confirm threshold | D10: — | E10: — | F10: — | G10: — | H10: —
A11: Largest single penalty type (% gross CDR) | B11: ⚠ confirm source | C11: ⚠ confirm threshold | D11: — | E11: — | F11: — | G11: — | H11: —
A12: Biochar H:C atomic ratio | B12: ⚠ confirm source | C12: ⚠ confirm threshold | D12: — | E12: — | F12: — | G12: — | H12: —
A13: Biochar carbon content (%) | B13: ⚠ confirm source | C13: ⚠ confirm threshold | D13: — | E13: — | F13: — | G13: — | H13: —
A14: Biochar yield (% dry biomass mass) | B14: ⚠ confirm source | C14: ⚠ confirm threshold | D14: — | E14: — | F14: — | G14: — | H14: —
A16: ⚠ WiP — confirm thresholds against BSSE v1.2 and PDD before operational use.

Sheet Data Sources
A1: Data Sources — Wiring Guide
A2: Maps each metric to its primary source for live-feed connection
A3: Metric / Tab | B3: Source System | C3: Specific Location | D3: Update Frequency | E3: Notes
A4: Run Rate — net CDR total | B4: Certify GHG statements | C4: Statement list → Net CO₂e removed | D4: Each reporting close | E4: Credit issuance month attribution
A5: Run Rate — source breakdown | B5: Certify GHG statements | C5: Individual statement → removal detail by source | D5: Each reporting close | E5: AECN/Charm/Kerry split
A6: Run Rate — pipeline | B6: Certify removal data | C6: Drafts page — removal entries not in a closed statement | D6: Weekly | E6: Draft status = not yet submitted
A7: Efficiency ratios | B7: Derived | C7: From Run Rate volume memo rows | D7: Derived
A8: Penalties — Charm production | B8: Charm PP summary → RP Charm MRV folder | C8: Consolidated emissions inventory | D8: Each reporting close | E8: Use RP Charm MRV folder for final
A9: Penalties — Downstream transport | B9: Certify individual removals | C9: COBB calc sheet transport rows per batch | D9: Each reporting close | E9: Rail + final truck per source
A10: Penalties — AECN/Kerry production | B10: Certify GHG statements | C10: Individual statement removal detail | D10: Each reporting close
A11: Penalties — Well facility | B11: Certify GHG statements | C11: Site emissions batch | D11: Each reporting close | E11: Methanol well-specific
A12: Production — Charm | B12: PP summary → RP Charm MRV folder | C12: Output type table (WODO/Biochar/Aqueous) | D12: Each reporting close | E12: Use RP folder for final verified values
A13: Source Mix — tCDR by source | B13: Certify GHG statements | C13: Filter per-statement removals by source | D13: Each reporting close
A14: Protocol Headroom — thresholds | B14: BSSE v1.2 + PDD | C14: Verify manually from protocol text | D14: Static / on update | E14: WiP
