Workbook

Sheet BCU Inventory
A1: BCU Certificate ID | B1: BCU Certificate link | C1: Date of Issuance | D1: Renewable Diesel Mass (Metric tonnes) | E1: Diesel Production Date | F1: Final Carbon Intensity delivered to terminal (gCO2eq/MJ) | G1: Lower heating value (MJ/kg) | H1: Total CO2 Emissions Reduction (MT) | I1: Total Attributes Used | J1: Total Attributes Remaining
A2: Charm-A1-2024-10-24-59-1976 | B2: https://drive.google.com/file/d/1kT4Bqg06KC2rMl4ZDB7AvRzEY0WsHbKH/view?usp=drive_link | C2: 10-30-2024 | D2: 104.33 | E2: 45565 | F2: 16.77 | G2: 44 | H2: ='BCU AE Breakdown'!L2 -> 323.64418 | I2: =SUMIF('GHG Statement BCU Usage'!$F$2:$F$998,A2,'GHG Statement BCU Usage'!$D$2:$D$998) -> 323.64418 | J2: =H2-I2 -> 0
A3: Charm-A1-2024-10-24-60-1976 | B3: https://drive.google.com/file/d/1o2Wnc0DVVTAsJ0YsKfIa0uXVAA65GR6O/view?usp=sharing | C3: 10-30-2024 | D3: 88.53 | E3: 45569 | F3: 16.77 | G3: 44 | H3: ='BCU AE Breakdown'!L3 -> 274.63068 | I3: =SUMIF('GHG Statement BCU Usage'!$F$2:$F$998,A3,'GHG Statement BCU Usage'!$D$2:$D$998) -> 274.63068 | J3: =H3-I3 -> 0
A4: Charm-A1-2024-10-24-61-1976 | B4: https://drive.google.com/file/d/1gXuruCqLFDBQOSTWVTYJpu3yrn5zGWdv/view?usp=sharing | C4: 10-30-2024 | D4: 21.883 | E4: 45573 | F4: 16.77 | G4: 44 | H4: ='BCU AE Breakdown'!L4 -> 67.883692 | I4: =SUMIF('GHG Statement BCU Usage'!$F$2:$F$998,A4,'GHG Statement BCU Usage'!$D$2:$D$998) -> 67.883692 | J4: =H4-I4 -> 0
A5: Charm-A1-2024-10-24-62-1976 | B5: https://drive.google.com/file/d/1udloiIE_hu3q02ekc0FdaXnQ6CLwRvTO/view?usp=sharing | C5: 10-30-2024 | D5: 66.117 | E5: 45577 | F5: 16.77 | G5: 44 | H5: ='BCU AE Breakdown'!L5 -> 205.10287 | I5: =SUMIF('GHG Statement BCU Usage'!$F$2:$F$998,A5,'GHG Statement BCU Usage'!$D$2:$D$998) -> 205.10287 | J5: =H5-I5 -> 0
A6: Charm-A1-2024-10-24-63-1976 | B6: https://drive.google.com/file/d/1lDt1UMON2m07m-dK_6xPZycLdHGUx6j9/view?usp=sharing | C6: 10-30-2024 | D6: 111.725 | E6: 45577 | F6: 16.77 | G6: 44 | H6: ='BCU AE Breakdown'!L6 -> 346.58436 | I6: =SUMIF('GHG Statement BCU Usage'!$F$2:$F$998,A6,'GHG Statement BCU Usage'!$D$2:$D$998) -> 346.58436 | J6: =H6-I6 -> 0
A7: Charm-A1-2024-10-24-64-1976 | B7: https://drive.google.com/file/d/15WbJO456kfJT4HeTxnex5dSjS7o_5ImQ/view?usp=sharing | C7: 10-30-2024 | D7: 21.977 | E7: 45577 | F7: 16.77 | G7: 44 | H7: ='BCU AE Breakdown'!L7 -> 68.237334 | I7: =SUMIF('GHG Statement BCU Usage'!$F$2:$F$998,A7,'GHG Statement BCU Usage'!$D$2:$D$998) -> 68.237334 | J7: =H7-I7 -> 0
A8: Charm-A2-2024-10-24-63-1976 | B8: https://drive.google.com/file/d/1KIfeGT5sk2xhnRlHP3DNy24e8bOee8Ba/view?usp=sharing | C8: 10-30-2024 | D8: 66.763 | E8: 45577 | F8: 16.8 | G8: 44 | H8: ='BCU AE Breakdown'!L8 -> 207.01871 | I8: =SUMIF('GHG Statement BCU Usage'!$F$2:$F$998,A8,'GHG Statement BCU Usage'!$D$2:$D$998) -> 207.01789 | J8: =H8-I8 -> 0.00082424
A9: Charm-A2-2024-10-24-64-1976 | B9: https://drive.google.com/file/d/1uQde8IkftD3IM_1xPy5GU_tEiV03L00v/view?usp=sharing | C9: 10-30-2024 | D9: 39.526 | E9: 45577 | F9: 16.8 | G9: 44 | H9: ='BCU AE Breakdown'!L9 -> 122.56222 | I9: =SUMIF('GHG Statement BCU Usage'!$F$2:$F$998,A9,'GHG Statement BCU Usage'!$D$2:$D$998) -> 122.559 | J9: =H9-I9 -> 0.0032208
A10: Charm-A3-2024-10-24-63-1976 | B10: https://drive.google.com/file/d/1VfxfzLq5RdutTYHhAwfinLecn0p0HLp2/view?usp=sharing | C10: 10-30-2024 | D10: 44.089 | E10: 45577 | F10: 16.74 | G10: 44 | H10: ='BCU AE Breakdown'!L10 -> 136.82757 | I10: =SUMIF('GHG Statement BCU Usage'!$F$2:$F$998,A10,'GHG Statement BCU Usage'!$D$2:$D$998) -> 136.82757 | J10: =H10-I10 -> 0
A11: Charm-A3-2024-10-24-64-1976 | B11: https://drive.google.com/file/d/1HNOThlz15HCZkOvZCUnpLbke9IJ8PP9l/view?usp=sharing | C11: 10-30-2024 | D11: 21.927 | E11: 45577 | F11: 16.74 | G11: 44 | H11: ='BCU AE Breakdown'!L11 -> 68.049129 | I11: =SUMIF('GHG Statement BCU Usage'!$F$2:$F$998,A11,'GHG Statement BCU Usage'!$D$2:$D$998) -> 68.049129 | J11: =H11-I11 -> 0
A12: Charm-A4-2024-10-24-63-1976 | B12: https://drive.google.com/file/d/1I7f4R8BSLiNwaeXUovUJ2_3hYLKPkJ6T/view?usp=sharing | C12: 10-30-2024 | D12: 44.205 | E12: 45577 | F12: 16.78 | G12: 44 | H12: ='BCU AE Breakdown'!L12 -> 137.10976 | I12: =SUMIF('GHG Statement BCU Usage'!$F$2:$F$998,A12,'GHG Statement BCU Usage'!$D$2:$D$998) -> 137.10831 | J12: =H12-I12 -> 0.00145944
A13: Charm-A4-2024-10-24-64-1976 | B13: https://drive.google.com/file/d/1HVqRsWSrYA0XewicbGLv7kkSNktCYIB_/view?usp=sharing | C13: 10-30-2024 | D13: 22.304 | E13: 45577 | F13: 16.78 | G13: 44 | H13: ='BCU AE Breakdown'!L13 -> 69.179871 | I13: =SUMIF('GHG Statement BCU Usage'!$F$2:$F$998,A13,'GHG Statement BCU Usage'!$D$2:$D$998) -> 69.17987 | J13: =H13-I13 -> 7.2000002e-07
... A15: Charm-A5-2024-10-24-63-1976 | B15: https://drive.google.com/file/d/1uBkWBFnak5hkrHw8JI4Zq7LCXMrkpLJW/view?usp=sharing | C15: 10-30-2024 | D15: 21.912 | E15: 45577 | F15: 16.77 | G15: 44 | H15: ='BCU AE Breakdown'!L15 -> 67.973653 | I15: =SUMIF('GHG Statement BCU Usage'!$F$2:$F$998,A15,'GHG Statement BCU Usage'!$D$2:$D$998) -> 67.97365 | J15: =H15-I15 -> 3.44e-06
A16: 13-47206-50000 | B16: Charm-RetirementCertificate-RD-EACs-20251218.pdf | C16: 46009 | E16: 2024 | F16: 29.68 | G16: 44 | H16: ='BCU AE Breakdown'!L16 -> 2765.3612 | I16: =SUMIF('GHG Statement BCU Usage'!$F$2:$F$998,A16,'GHG Statement BCU Usage'!$D$2:$D$998) -> 414.92741 | J16: =H16-I16 -> 2350.4337

Sheet RECs Inventory
A1: RECs Certificate ID (Last 5 # of Serial) | B1: RECs Certificate link | C1: Date of Purchase | D1: Project | E1: Underlying - End Date | F1: Expiry Date | G1: Vintage | H1: Region | I1: Generation Type | J1: Volume (MWH) | K1: Volume Used | L1: Volume Remaining
A2: 22289 | B2: retirement-2024-12-30T16_05_38 - Charm Industrial Colorado 2024.pdf | C2: 45656 | D2: Hunter Solar, LLC (CO) | E2: 45413 | F2: =EDATE(E2,12) -> 45778 | G2: 45413 | H2: Colorado | I2: Solar | J2: 400 | K2: =SUMIF('GHG Statement RECs Usage'!$F$2:$F$1001,A2,'GHG Statement RECs Usage'!$E$2:$E$1001) -> 286.49529 | L2: =J2-K2 -> 113.50471
A3: 47906 | B3: KS RECs Supplementary Data.jpg | C3: 45656 | D3: Traverse Wind Energy | E3: 45473 | F3: =EDATE(E3,12) -> 45838 | G3: 45444 | H3: Kansas | I3: Wind | J3: 250 | K3: =SUMIF('GHG Statement RECs Usage'!$F$2:$F$1001,A3,'GHG Statement RECs Usage'!$E$2:$E$1001) -> 249.99992 | L3: =J3-K3 -> 8e-05
A4: 10916 | B4: Charm Industrial BH2024 CO Solar_retirement-2025-03-31T13_52_05.pdf | C4: 45747 | D4: Hunter Solar, LLC (CO) | E4: 45474 | F4: 45839 | G4: 45474 | H4: Colorado | I4: Solar | J4: 1250 | K4: =SUMIF('GHG Statement RECs Usage'!$F$2:$F$1001,A4,'GHG Statement RECs Usage'!$E$2:$E$1001) -> 88.62935 | L4: =J4-K4 -> 1161.3707
A5: 49437 | B5: Charm Industrial FH2025 OK CertificateOfRetirement_270484.pdf | C5: 45840 | D5: Traverse Wind Energy | E5: 45688 | F5: 46053 | G5: 45688 | H5: Kansas | I5: Wind | J5: 250 | K5: =SUMIF('GHG Statement RECs Usage'!$F$2:$F$1001,A5,'GHG Statement RECs Usage'!$E$2:$E$1001) -> 224.05679 | L5: =J5-K5 -> 25.94321
A6: 11906 | B6: Charm Industrial FH2025 CO Solar_retirement-2025-07-29T11_44_53.pdf | C6: 45867 | D6: Hunter Solar, LLC (CO) | E6: 45658 | F6: 46023 | G6: 45658 | H6: Colorado | I6: Solar | J6: 300 | K6: =SUMIF('GHG Statement RECs Usage'!$F$2:$F$1001,A6,'GHG Statement RECs Usage'!$E$2:$E$1001) -> 170.96529 | L6: =J6-K6 -> 129.03471
A7: 20879 | B7: Hunter Solar Gen 5/1/25 | C7: 46028 | D7: Hunter Solar, LLC (CO) | E7: 45778 | F7: 46143 | G7: 45778 | H7: Colorado | I7: Solar | J7: 284 | K7: =SUMIF('GHG Statement RECs Usage'!$F$2:$F$1001,A7,'GHG Statement RECs Usage'!$E$2:$E$1001) -> 206.78888 | L7: =J7-K7 -> 77.211122
A8: 16406 | B8: Charm Industrial Delta Region FH25 retirement-2026-01-06T13_45_40.pdf | C8: 46028 | D8: Searcy Water II | E8: 45748 | F8: 46113 | G8: 45748 | H8: Louisiana | I8: Solar | J8: 391 | K8: =SUMIF('GHG Statement RECs Usage'!$F$2:$F$1001,A8,'GHG Statement RECs Usage'!$E$2:$E$1001) -> 273.99774 | L8: =J8-K8 -> 117.00226
A9: 10845 | B9: retirement-2026-07-22T09_16_03.pdf | C9: 46213 | D9: Wildflower Solar | E9: 46023 | F9: 46388 | G9: 46023 | H9: Louisiana (Delta) | I9: Solar | J9: 100 | K9: =SUMIF('GHG Statement RECs Usage'!$F$2:$F$1001,A9,'GHG Statement RECs Usage'!$E$2:$E$1001) -> 100 | L9: =J9-K9 -> 0
A10: 10745 | B10: retirement-2026-07-22T09_16_04.pdf | C10: 46213 | D10: Wildflower Solar | E10: 46023 | F10: 46388 | G10: 46023 | H10: Louisiana (Delta) | I10: Solar | J10: 100 | K10: =SUMIF('GHG Statement RECs Usage'!$F$2:$F$1001,A10,'GHG Statement RECs Usage'!$E$2:$E$1001) -> 5.22958 | L10: =J10-K10 -> 94.77042
A11: 94-243 | B11: retirement-2026-07-27T10_53_15.pdf | C11: 46213 | D11: Pike Solar | E11: 46023 | F11: 46388 | G11: 46023 | H11: Colorado (Mountain) | I11: Solar | J11: 150 | K11: =SUMIF('GHG Statement RECs Usage'!$F$2:$F$1001,A11,'GHG Statement RECs Usage'!$E$2:$E$1001) -> 67.72206 | L11: =J11-K11 -> 82.27794

Sheet BCU AE Breakdown
A1: PoS ID Number | B1: BCU Certificate link | C1: RD WTT CI (kg CO2e/MJ) | D1: RD LHV (MJ/kg) | E1: RD WTT CI (kg CO2e/kg) | F1: RD TTW CI (kg CO2e/kg) | G1: RD WTW CI (kg CO2e/kg) | H1: CD WTW CI (kg CO2e/kg) | I1: AE RD (kg CO2e/kg) | J1: Mass of Batch (kg) | K1: AE of Batch (kg CO2e) | L1: AE of Batch (MT CO2e)
A2: Charm-A1-2024-10-24-59-1976 | B2: https://drive.google.com/file/d/1kT4Bqg06KC2rMl4ZDB7AvRzEY0WsHbKH/view?usp=drive_link | C2: =16.77/1000 -> 0.01677 | D2: 44 | E2: =C2*D2 -> 0.73788 | F2: 0.03 | G2: =SUM(E2:F2) -> 0.76788 | H2: 3.87 | I2: =H2-G2 -> 3.10212 | J2: =104.33*1000 -> 104330 | K2: =J2*I2 -> 323644.18 | L2: =K2/1000 -> 323.64418
A3: Charm-A1-2024-10-24-60-1976 | B3: https://drive.google.com/file/d/1o2Wnc0DVVTAsJ0YsKfIa0uXVAA65GR6O/view?usp=sharing | C3: =16.77/1000 -> 0.01677 | D3: 44 | E3: =C3*D3 -> 0.73788 | F3: 0.03 | G3: =SUM(E3:F3) -> 0.76788 | H3: 3.87 | I3: =H3-G3 -> 3.10212 | J3: =88.53*1000 -> 88530 | K3: =J3*I3 -> 274630.68 | L3: =K3/1000 -> 274.63068
A4: Charm-A1-2024-10-24-61-1976 | B4: https://drive.google.com/file/d/1gXuruCqLFDBQOSTWVTYJpu3yrn5zGWdv/view?usp=sharing | C4: =16.77/1000 -> 0.01677 | D4: 44 | E4: =C4*D4 -> 0.73788 | F4: 0.03 | G4: =SUM(E4:F4) -> 0.76788 | H4: 3.87 | I4: =H4-G4 -> 3.10212 | J4: =21.883*1000 -> 21883 | K4: =J4*I4 -> 67883.692 | L4: =K4/1000 -> 67.883692
A5: Charm-A1-2024-10-24-62-1976 | B5: https://drive.google.com/file/d/1udloiIE_hu3q02ekc0FdaXnQ6CLwRvTO/view?usp=sharing | C5: =16.77/1000 -> 0.01677 | D5: 44 | E5: =C5*D5 -> 0.73788 | F5: 0.03 | G5: =SUM(E5:F5) -> 0.76788 | H5: 3.87 | I5: =H5-G5 -> 3.10212 | J5: =66.117*1000 -> 66117 | K5: =J5*I5 -> 205102.87 | L5: =K5/1000 -> 205.10287
A6: Charm-A1-2024-10-24-63-1976 | B6: https://drive.google.com/file/d/1lDt1UMON2m07m-dK_6xPZycLdHGUx6j9/view?usp=sharing | C6: =16.77/1000 -> 0.01677 | D6: 44 | E6: =C6*D6 -> 0.73788 | F6: 0.03 | G6: =SUM(E6:F6) -> 0.76788 | H6: 3.87 | I6: =H6-G6 -> 3.10212 | J6: =111.725*1000 -> 111725 | K6: =J6*I6 -> 346584.36 | L6: =K6/1000 -> 346.58436
A7: Charm-A1-2024-10-24-64-1976 | B7: https://drive.google.com/file/d/15WbJO456kfJT4HeTxnex5dSjS7o_5ImQ/view?usp=sharing | C7: =16.77/1000 -> 0.01677 | D7: 44 | E7: =C7*D7 -> 0.73788 | F7: 0.03 | G7: =SUM(E7:F7) -> 0.76788 | H7: 3.87 | I7: =H7-G7 -> 3.10212 | J7: =21.997*1000 -> 21997 | K7: =J7*I7 -> 68237.334 | L7: =K7/1000 -> 68.237334
A8: Charm-A2-2024-10-24-63-1976 | B8: https://drive.google.com/file/d/1KIfeGT5sk2xhnRlHP3DNy24e8bOee8Ba/view?usp=sharing | C8: =16.8/1000 -> 0.0168 | D8: 44 | E8: =C8*D8 -> 0.7392 | F8: 0.03 | G8: =SUM(E8:F8) -> 0.7692 | H8: 3.87 | I8: =H8-G8 -> 3.1008 | J8: =66.763*1000 -> 66763 | K8: =J8*I8 -> 207018.71 | L8: =K8/1000 -> 207.01871
A9: Charm-A2-2024-10-24-64-1976 | B9: https://drive.google.com/file/d/1uQde8IkftD3IM_1xPy5GU_tEiV03L00v/view?usp=sharing | C9: =16.8/1000 -> 0.0168 | D9: 44 | E9: =C9*D9 -> 0.7392 | F9: 0.03 | G9: =SUM(E9:F9) -> 0.7692 | H9: 3.87 | I9: =H9-G9 -> 3.1008 | J9: =39.526*1000 -> 39526 | K9: =J9*I9 -> 122562.22 | L9: =K9/1000 -> 122.56222
A10: Charm-A3-2024-10-24-63-1976 | B10: https://drive.google.com/file/d/1VfxfzLq5RdutTYHhAwfinLecn0p0HLp2/view?usp=sharing | C10: =16.74/1000 -> 0.01674 | D10: 44 | E10: =C10*D10 -> 0.73656 | F10: 0.03 | G10: =SUM(E10:F10) -> 0.76656 | H10: 3.87 | I10: =H10-G10 -> 3.10344 | J10: =44.089*1000 -> 44089 | K10: =J10*I10 -> 136827.57 | L10: =K10/1000 -> 136.82757
A11: Charm-A3-2024-10-24-64-1976 | B11: https://drive.google.com/file/d/1HNOThlz15HCZkOvZCUnpLbke9IJ8PP9l/view?usp=sharing | C11: =16.74/1000 -> 0.01674 | D11: 44 | E11: =C11*D11 -> 0.73656 | F11: 0.03 | G11: =SUM(E11:F11) -> 0.76656 | H11: 3.87 | I11: =H11-G11 -> 3.10344 | J11: =21.927*1000 -> 21927 | K11: =J11*I11 -> 68049.129 | L11: =K11/1000 -> 68.049129
A12: Charm-A4-2024-10-24-63-1976 | B12: https://drive.google.com/file/d/1I7f4R8BSLiNwaeXUovUJ2_3hYLKPkJ6T/view?usp=sharing | C12: =16.78/1000 -> 0.01678 | D12: 44 | E12: =C12*D12 -> 0.73832 | F12: 0.03 | G12: =SUM(E12:F12) -> 0.76832 | H12: 3.87 | I12: =H12-G12 -> 3.10168 | J12: =44.205*1000 -> 44205 | K12: =J12*I12 -> 137109.76 | L12: =K12/1000 -> 137.10976
A13: Charm-A4-2024-10-24-64-1976 | B13: https://drive.google.com/file/d/1HVqRsWSrYA0XewicbGLv7kkSNktCYIB_/view?usp=sharing | C13: =16.78/1000 -> 0.01678 | D13: 44 | E13: =C13*D13 -> 0.73832 | F13: 0.03 | G13: =SUM(E13:F13) -> 0.76832 | H13: 3.87 | I13: =H13-G13 -> 3.10168 | J13: =22.304*1000 -> 22304 | K13: =J13*I13 -> 69179.871 | L13: =K13/1000 -> 69.179871
A14: Charm-A5-2024-10-24-62-1976 | B14: https://drive.google.com/file/d/1R3qzZzz4Y3jQ74o5PT4ephwRe0JwH3Sh/view?usp=sharing | C14: =16.77/1000 -> 0.01677 | D14: 44 | E14: =C14*D14 -> 0.73788 | F14: 0.03 | G14: =SUM(E14:F14) -> 0.76788 | H14: 3.87 | I14: =H14-G14 -> 3.10212 | J14: =22.31*1000 -> 22310 | K14: =J14*I14 -> 69208.297 | L14: =K14/1000 -> 69.208297
A15: Charm-A5-2024-10-24-63-1976 | B15: https://drive.google.com/file/d/1uBkWBFnak5hkrHw8JI4Zq7LCXMrkpLJW/view?usp=sharing | C15: =16.77/1000 -> 0.01677 | D15: 44 | E15: =C15*D15 -> 0.73788 | F15: 0.03 | G15: =SUM(E15:F15) -> 0.76788 | H15: 3.87 | I15: =H15-G15 -> 3.10212 | J15: =21.912*1000 -> 21912 | K15: =J15*I15 -> 67973.653 | L15: =K15/1000 -> 67.973653
A16: 13-47206-50000 | B16: Charm-RetirementCertificate-RD-EACs-20251218.pdf | C16: =29.68/1000 -> 0.02968 | D16: 44 | E16: =C16*D16 -> 1.30592 | F16: 0.03 | G16: =SUM(E16:F16) -> 1.33592 | H16: 3.87 | I16: =H16-G16 -> 2.53408 | J16: =48015804.84/44 -> 1091268.3 | K16: =J16*I16 -> 2765361.2 | L16: =K16/1000 -> 2765.3612

Sheet RECs Documentation
A1: EC # | B1: Documentation Required | C1: Documentation Provided (CO) | D1: Documentation Provided (KS) | E1: Additional Notes (CO) | F1: Additional Notes (KS)
A2: EC1 | B2: Documentation of Renewable Energy Certificate (REC) or Energy Attribution Certificate (EAC) purchase, including copy of contract and REC/EAC retirement certificates. | C2: retirement-2024-12-30T16_05_38 - Charm Industrial Colorado 2024.pdf | D2: KS RECs Retirement Certificate.pdf
A3: EC2 | B3: Documentation of REC or EAC retirement certificates. Documentation must also be provided of any relevant CES requirements and applicability to the project energy usage. | C3: retirement-2024-12-30T16_05_38 - Charm Industrial Colorado 2024.pdf | D3: KS RECs Retirement Certificate.pdf | E3: There are no relevant CES requirements in either jurisdiction RECs have been procured for | F3: There are no relevant CES requirements in either jurisdiction RECs have been procured for
A4: EC3 | B4: Evidence that the generating facilities identified in the RECs/EACs entered service no more than 36 months before The Project was initiated. | C4: CO RECs First Operational Date.jpg | D4: KS RECs Supplementary Data.jpg | E4: Approx. 2 months elapsed between the CO generator entering service (12/29/23) and the initiation of the project (3/1/24) | F4: 28 months elapsed between the KS generator entering service (11/1/21) and the initiation of the project (3/1/24)
A5: EC4 | B5: Provide the location of the generating facilities identified in the submitted RECs/EACs, and documentation from government or grid operators to justify that the generators are located within the same grid region as The Project. | C5: CO RECs Generator Location.jpg | D5: KS RECs Supplementary Data.jpg | E5: The generator's location in Bennett, CO demonstrates that it occupies the same Mountain 45v grid region that the project, located in Ft Lupton, CO, does | F5: The generator's location in Blaine, OK demonstrates that it occupies the same Plains 45v grid region that the project, located in El Dorado, KS, does
A6: EC5 | B6: Provide documentation of power procurement proving that generation of the claimed electricity occurred no more than one year prior to the point of consumption by The Project. | C6: retirement-2024-12-30T16_05_38 - Charm Industrial Colorado 2024.pdf | D6: KS RECs Supplementary Data.jpg | E6: The certificate vintage of 5/2024 is less than one year prior to the point of consumption by the Project | F6: The certificate vintage of 6/2024 is less than one year prior to the point of consumption by the Project
K17: =SUM(K1:K15) -> 0

Sheet RECs CI Calcs
A3: https://docs.google.com/spreadsheets/d/1Mpn0uXgtHSaZ-UWMRu1QyaqOSK6POtZ7cXIIXKJVu2Q/edit?gid=1720683910#gid=1720683910
A6: https://docs.google.com/spreadsheets/d/1OrNGikkNo5ZHVhEYsovtdBuh4m0BvaZJnCudP3GyHWE/edit?gid=0#gid=0
K17: =SUM(K1:K15) -> 0

Sheet GHG Statement BCU Usage
A1: GHG Statement dMRV Link | B1: GHG Statement Start Date | C1: GHG Statement End Date | D1: Total CO2e Abated in RP (MT CO2e) | E1: Total amount of BCU units used (Mass of RD - Metric tonnes) | F1: BCU Certificate IDs used | G1: Notes
A2: https://registry.isometric.com/account/certify/project/prj_1HZSSWBQM1S08H83/ghg-statement/ggs_1JHNY6WK41S0D1QJ | B2: 45297 | C2: 45455 | D2: 204.91 | E2: =D2/'BCU AE Breakdown'!I2 -> 66.054827 | F2: Charm-A1-2024-10-24-59-1976
A3: https://registry.isometric.com/account/certify/project/prj_1HZSSWBQM1S08H83/ghg-statement/ggs_1JQC60KVR1S0JS6Q | B3: 45633 | C3: 45688 | D3: 113.54 | E3: =D3/'BCU AE Breakdown'!I2 -> 36.600776 | F3: Charm-A1-2024-10-24-59-1976
A4: https://registry.isometric.com/account/certify/project/prj_1HZSSWBQM1S08H83/ghg-statement/ggs_1JQC60KVR1S0JS6Q | B4: 45633 | C4: 45688 | D4: 122.48 | E4: =D4/'BCU AE Breakdown'!I3 -> 39.482676 | F4: Charm-A1-2024-10-24-60-1976
A5: https://registry.isometric.com/account/certify/project/prj_1HZSSWBQM1S08H83/ghg-statement/ggs_1JQC60KVR1S0JS6Q | B5: 45633 | C5: 45688 | D5: 24.67 | E5: =D5/'BCU AE Breakdown'!I3 -> 7.9526259 | F5: Charm-A1-2024-10-24-60-1976 | G5: Charm Oil Production
B6: 45689 | C6: 45747 | D6: 22.02 | E6: =D6/'BCU AE Breakdown'!$I$4 -> 7.0983714 | F6: Charm-A1-2024-10-24-61-1976 | G6: Charm PP2 Oil Production
B7: 45689 | C7: 45747 | D7: 26.23 | E7: =D7/'BCU AE Breakdown'!$I$4 -> 8.4555078 | F7: Charm-A1-2024-10-24-61-1976 | G7: Charm PP3 Oil Production
B8: 45689 | C8: 45747 | D8: 15.7 | E8: =D8/'BCU AE Breakdown'!$I$4 -> 5.061055 | F8: Charm-A1-2024-10-24-61-1976 | G8: Charm PP4 Oil Production
B9: 45689 | C9: 45747 | D9: 205.10287 | E9: =D9/'BCU AE Breakdown'!$I$5 -> 66.117 | F9: Charm-A1-2024-10-24-62-1976 | G9: Non-Production Reporting Period Diesel
B10: 45689 | C10: 45747 | D10: =224.492-D9 -> 19.389132 | E10: =D10/'BCU AE Breakdown'!$I$6 -> 6.2502843 | F10: Charm-A1-2024-10-24-63-1976 | G10: Non-Production Reporting Period Diesel
B11: 45748 | C11: 45808 | D11: 228.562 | E11: =D11/'BCU AE Breakdown'!$I$6 -> 73.67929 | F11: Charm-A1-2024-10-24-63-1976 | G11: Non-Production Reporting Period Diesel
B12: 45748 | C12: 45808 | D12: 17.17 | E12: =D12/'BCU AE Breakdown'!$I$6 -> 5.5349245 | F12: Charm-A1-2024-10-24-63-1976 | G12: Charm PP5 Oil Production
B13: 45748 | C13: 45808 | D13: 8.42 | E13: =D13/'BCU AE Breakdown'!$I$6 -> 2.7142728 | F13: Charm-A1-2024-10-24-63-1976 | G13: Charm PP6 Oil Production
B14: 45809 | C14: 45869 | D14: 130.596 | E14: =D14/'BCU AE Breakdown'!I8 -> 42.116873 | F14: Charm-A2-2024-10-24-63-1976 | G14: Non-Production Reporting Period Diesel
B15: 45809 | C15: 45869 | D15: 59.759 | E15: =D15/'BCU AE Breakdown'!I7 -> 19.263923 | F15: Charm-A1-2024-10-24-64-1976 | G15: Non-Production Reporting Period Diesel
B16: 45809 | C16: 45869 | D16: 5.1941796 | E16: =D16/'BCU AE Breakdown'!I2 -> 1.6743967 | F16: Charm-A1-2024-10-24-59-1976 | G16: Charm PP7 Oil Production
B17: 45809 | C17: 45869 | D17: 3.933692 | E17: =D17/'BCU AE Breakdown'!I4 -> 1.2680657 | F17: Charm-A1-2024-10-24-61-1976 | G17: Charm PP7 Oil Production
B18: 45809 | C18: 45869 | D18: 8.4783336 | E18: =D18/'BCU AE Breakdown'!I7 -> 2.7330773 | F18: Charm-A1-2024-10-24-64-1976 | G18: Charm PP7 Oil Production
B19: 45809 | C19: 45869 | D19: 6.6937948 | E19: =D19/'BCU AE Breakdown'!$I$3 -> 2.157813 | F19: Charm-A1-2024-10-24-60-1976 | G19: Charm PP7 Oil Production
B20: 45809 | C20: 45869 | D20: 36.5 | E20: =D20/'BCU AE Breakdown'!$I$3 -> 11.766147 | F20: Charm-A1-2024-10-24-60-1976 | G20: Charm PP8 Oil Production
B21: 45870 | C21: 45884 | D21: 34.992 | E21: =D21/'BCU AE Breakdown'!$I$3 -> 11.280028 | F21: Charm-A1-2024-10-24-60-1976 | G21: Non-Production Reporting Period Diesel
B22: 45885 | C22: 45908 | D22: 49.294889 | E22: =D22/'BCU AE Breakdown'!$I$3 -> 15.89071 | F22: Charm-A1-2024-10-24-60-1976 | G22: Non-Production Reporting Period Diesel
B23: 45885 | C23: 45908 | D23: 73.043225 | E23: =D23/'BCU AE Breakdown'!$I$6 -> 23.546228 | F23: Charm-A1-2024-10-24-63-1976 | G23: Non-Production Reporting Period Diesel
B24: 45885 | C24: 45908 | D24: =145.083-SUM(D22:D23) -> 22.744886 | E24: =D24/'BCU AE Breakdown'!$I$8 -> 7.3351671 | F24: Charm-A2-2024-10-24-63-1976 | G24: Non-Production Reporting Period Diesel
B25: 45885 | C25: 45908 | D25: =round(24.81538993,3) -> 24.815 | E25: =D25/'BCU AE Breakdown'!$I$8 -> 8.0027735 | F25: Charm-A2-2024-10-24-63-1976 | G25: Charm August 25 Oil Production
B26: 45909 | C26: 45930 | D26: 28.862 | E26: =D26/'BCU AE Breakdown'!$I$8 -> 9.3079205 | F26: Charm-A2-2024-10-24-63-1976 | G26: Non-Production Reporting Period Diesel
B27: 45909 | C27: 45930 | D27: =79.161-D26 -> 50.299 | E27: =D27/'BCU AE Breakdown'!$I$9 -> 16.221298 | F27: Charm-A2-2024-10-24-64-1976 | G27: Non-Production Reporting Period Diesel
B28: 45909 | C28: 45930 | D28: 5.34 | E28: =D28/'BCU AE Breakdown'!$I$9 -> 1.7221362 | F28: Charm-A2-2024-10-24-64-1976 | G28: Charm Sept 25 Oil Production
B29: 45931 | C29: 45967 | D29: =round(16.85547791,2) -> 16.86 | E29: =D29/'BCU AE Breakdown'!$I$9 -> 5.4373065 | F29: Charm-A2-2024-10-24-64-1976 | G29: Charm Oct 25 Oil Production
B30: 45931 | C30: 45967 | D30: 50.06 | E30: =D30/'BCU AE Breakdown'!$I$9 -> 16.144221 | F30: Charm-A2-2024-10-24-64-1976 | G30: Non-Production Reporting Period Diesel
B31: 45931 | C31: 45967 | D31: 70.429 | E31: =D31/'BCU AE Breakdown'!$I$10 -> 22.693849 | F31: Charm-A3-2024-10-24-63-1976 | G31: Non-Production Reporting Period Diesel
B32: 45763 | C32: 45929 | D32: 6.939 | E32: =D32/'BCU AE Breakdown'!$I$10 -> 2.235906 | F32: Charm-A3-2024-10-24-63-1976 | G32: EO 2025 Biochar Reporting
B33: 45968 | C33: 46053 | D33: 54.305 | E33: =D33/'BCU AE Breakdown'!$I$10 -> 17.498324 | F33: Charm-A3-2024-10-24-63-1976 | G33: Non-Production Reporting Period Diesel
B34: 45689 | C34: 45718 | D34: 5.1545662 | E34: =D34/'BCU AE Breakdown'!$I$10 -> 1.6609202 | F34: Charm-A3-2024-10-24-63-1976 | G34: Non-Production Reporting Period Diesel
B35: 45689 | C35: 45718 | D35: 68.049129 | E35: =D35/'BCU AE Breakdown'!$I$11 -> 21.927 | F35: Charm-A3-2024-10-24-64-1976 | G35: Non-Production Reporting Period Diesel
B36: 45689 | C36: 45718 | D36: =126.542-D34-D35 -> 53.338305 | E36: =D36/'BCU AE Breakdown'!$I$12 -> 17.196585 | F36: Charm-A4-2024-10-24-63-1976 | G36: Non-Production Reporting Period Diesel
B37: 46084 | C37: 46112 | D37: =round(83.77146,2) -> 83.77 | E37: =D37/'BCU AE Breakdown'!$I$12 -> 27.007944 | F37: Charm-A4-2024-10-24-63-1976 | G37: Non-Production Reporting Period
B38: 46084 | C38: 46112 | D38: =round(52.6,2) -> 52.6 | E38: =D38/'BCU AE Breakdown'!$I$12 -> 16.958551 | F38: Charm-A4-2024-10-24-64-1976 | G38: Non-Production Reporting Period
B39: 46113 | C39: 46142 | D39: 62.261 | E39: =D39/'BCU AE Breakdown'!$I$12 -> 20.073315 | F39: Charm-A5-2024-10-24-62-1976 | G39: April 2026 RP Oil Production
B40: 45962 | C40: 45991 | D40: 16.57987 | E40: =D40/'BCU AE Breakdown'!$I$12 -> 5.3454483 | F40: Charm-A4-2024-10-24-64-1976 | G40: Charm Nov 2025 PP Oil Production
...

Sheet GHG Statement RECs Usage
A1: GHG Statement dMRV Link | B1: Activity | C1: GHG Statement Start Date | D1: GHG Statement End Date | E1: RECs Used (MWH) | F1: RECs Certificate IDs Used
A2: https://registry.isometric.com/account/certify/project/prj_1HZSSWBQM1S08H83/ghg-statement/ggs_1JQC60KVR1S0JS6Q | B2: Production | C2: 45633 | D2: 45688 | E2: 70.85819 | F2: 22289
A3: https://registry.isometric.com/account/certify/project/prj_1HZSSWBQM1S08H83/ghg-statement/ggs_1JQC60KVR1S0JS6Q | B3: Injection | C3: 45633 | D3: 45688 | E3: 94.948 | F3: 47906
B4: Production -- PP2 | C4: 45689 | D4: 45747 | E4: =76540.56/1000 -> 76.54056 | F4: 22289
B5: Production -- PP3 | C5: 45689 | D5: 45747 | E5: =36893.15/1000 -> 36.89315 | F5: 22289
B6: Production -- PP4 | C6: 45689 | D6: 45747 | E6: =45850.69/1000 -> 45.85069 | F6: 22289
B7: Injection -- El Dorado | C7: 45689 | D7: 45747 | E7: =98885.92/1000 -> 98.88592 | F7: 47906
B8: Injection -- Hutch | C8: 45689 | D8: 45747 | E8: =1213/1000 -> 1.213 | F8: 47906
B9: Production -- PP5 | C9: 45748 | D9: 45808 | E9: =56352.7/1000 -> 56.3527 | F9: 22289
B10: Production -- PP6 | C10: 45748 | D10: 45808 | E10: =45185.05/1000 -> 45.18505 | F10: 10916
B11: Injection -- El Dorado | C11: 45748 | D11: 45808 | E11: =50842/1000 -> 50.842 | F11: 47906
B12: Injection -- Hutch | C12: 45748 | D12: 45808 | E12: =4111/1000 -> 4.111 | F12: 47906
B13: Production -- PP7 | C13: 45809 | D13: 45869 | E13: =43444.3/1000 -> 43.4443 | F13: 10916
B14: Production -- PP8 | C14: 45809 | D14: 45869 | E14: =50821.57/1000 -> 50.82157 | F14: 11906
B15: Injection -- El Dorado | C15: 45809 | D15: 45869 | E15: =77084.34/1000 -> 77.08434 | F15: 49437
B16: Injection -- Hutch | C16: 45809 | D16: 45869 | E16: =3161.5/1000 -> 3.1615 | F16: 49437
B17: Injection -- El Dorado | C17: 45870 | D17: 45884 | E17: =17842.92/1000 -> 17.84292 | F17: 49437
B18: Production -- Aug 25 | C18: 45885 | D18: 45908 | E18: =45947.77/1000 -> 45.94777 | F18: 11906
B19: Injection -- El Dorado | C19: 45885 | D19: 45908 | E19: =39570.3/1000 -> 39.5703 | F19: 49437
B20: Production -- Sept 25 | C20: 45909 | D20: 45930 | E20: =35385.95/1000 -> 35.38595 | F20: 11906
B21: Injection -- El Dorado | C21: 45909 | D21: 45930 | E21: =29797.73/1000 -> 29.79773 | F21: 49437
B22: Production -- Oct 25 | C22: 45931 | D22: 45967 | E22: =round(38806.94/1000,2) -> 38.81 | F22: 11906
B23: Injection -- El Dorado | C23: 45931 | D23: 45967 | E23: =round(56599.5078/1000,2) -> 56.6 | F23: 49437
B24: Injection -- Basco | C24: 45968 | D24: 46053 | E24: =(33172.44+14345.8)/1000 -> 47.51824 | F24: 16406
B25: Injection -- Basco | C25: 46054 | D25: 46083 | E25: =(14742.5+52546.34)/1000 -> 67.28884 | F25: 16406
B26: Injection -- Basco | C26: 46084 | D26: 46112 | E26: 55.661 | F26: 16406
B27: Injection -- Basco | C27: 46113 | D27: 46142 | E27: 59.154 | F27: 16406
B28: Production -- Nov 25 | C28: 45962 | D28: 45991 | E28: 36.75105 | F28: 20879
B29: Production -- Dec 25 | C29: 45992 | D29: 46022 | E29: 25.04126 | F29: 20879
B30: Injection -- Basco | C30: 46143 | D30: 46173 | E30: 44.37566 | F30: 16406
B31: Production -- Jan 26 | C31: 46023 | D31: 46053 | E31: 35.161907 | F31: 20879
B32: Production -- Mar 26 | C32: 46082 | D32: 46112 | E32: 38.417002 | F32: 20879
B33: Production -- Apr 26 | C33: 46113 | D33: 46142 | E33: =35432.8436903225/1000 -> 35.432844 | F33: 20879
B34: Injection -- Basco | C34: 46204 | D34: 46234 | E34: =50484.34/1000 -> 50.48434 | F34: 10845
B35: Production -- Feb 26 | C35: 46054 | D35: 46081 | E35: =35984.8158709677/1000 -> 35.984816 | F35: 20879
B36: Production -- May 26 | C36: 46143 | D36: 46173 | E36: =32788.65/1000 -> 32.78865 | F36: 94-243
B37: Production -- June 26 | C37: 46174 | D37: 46203 | E37: =34933.41/1000 -> 34.93341 | F37: 94-243
B38: Injection -- Basco | C38: 46235 | D38: 46265 | E38: =49515.66/1000 -> 49.51566 | F38: 10845
B39: Injection -- Basco | C39: 46235 | D39: 46265 | E39: =54745.24/1000-E38 -> 5.22958 | F39: 10745
