Workbook

Sheet Summary
A1: BATCH SUMMARY
A2: Batch ID | B2: INJ-09-2026-W3
A3: Week Start (Sat) | B3: 46276
A4: Week End (Sat) | B4: 46283
A6: SECTION 1 - PER-TAB SUMMARY (each row pulls from its mode tab)
A7: Source Tab | B7: Σ Deliveries / Cargo (kg) | C7: Σ Uncertainty Adj (kg) | D7: Mass Used (kg) | E7: Sparging Loss (kg) | F7: Filtration Loss (kg) | G7: MOBI (kg) | H7: AECN→SOPOR EE (mi) | I7: Rail EE (mi) | J7: Opel→Basco EE (mi)
A8: AECN Rail | B8: ='AECN Rail'!A46 -> 197321.59 | C8: ='AECN Rail'!B46 -> 0 | D8: ='AECN Rail'!C46 -> 197321.59 | E8: ='AECN Rail'!D46 -> 2545.4485 | F8: ='AECN Rail'!E46 -> 381.76124 | G8: ='AECN Rail'!F46 -> 193491.94 | H8: ='AECN Rail'!L38 -> 818.79572 | I8: ='AECN Rail'!M38 -> 5588.3129 | J8: ='AECN Rail'!N38 -> 858
A9: AECN Truck | B9: ='AECN Truck'!A28 -> 0 | C9: ='AECN Truck'!F28 -> 0 | D9: ='AECN Truck'!C28 -> 0 | E9: ='AECN Truck'!D28 -> 0 | F9: ='AECN Truck'!E28 -> 0 | G9: ='AECN Truck'!G28 -> 0
A10: Charm WODO | B10: =WODO!A29 | C10: =WODO!A29-WODO!B29 -> 0 | D10: =WODO!B29 | E10: =WODO!C29 | F10: 0 | G10: =WODO!D29
A11: Kerry | B11: =Kerry!A17 -> 19168.798 | C11: 0 | D11: =Kerry!A17 -> 19168.798 | E11: 0 | F11: =Kerry!B17 -> 37.570844 | G11: =Kerry!C17 -> 19131.227
A12: QOWV | B12: =QOWV!B50 -> 37682 | C12: 0 | D12: =QOWV!D50 -> 35550.8 | E12: 0 | F12: 0 | G12: =QOWV!F50 -> 30808.5
A13: TOTAL | B13: =SUM(B8:B12) -> 254172.39 | C13: =SUM(C8:C12) -> 0 | D13: =SUM(D8:D12) -> 252041.19 | E13: =SUM(E8:E12) -> 2545.4485 | F13: =SUM(F8:F12) -> 419.33208 | G13: =SUM(G8:G12) -> 243431.67 | H13: =SUM(H8:H12) -> 818.79572 | I13: =SUM(I8:I12) -> 5588.3129 | J13: =SUM(J8:J12) -> 858
A15: SECTION 2 - PER-OIL-TYPE ROLLUP (composite C% per oil type per week)
A16: Oil Type | B16: MOBI (kg) | C16: Composite Sample ID | D16: Date Composited | E16: C % | F16: Lab COA Link | G16: C Content Uncertainty | H16: Testing Uncertainty
A17: AECN | B17: =G8+G9 -> 193491.94 | C17: SR26-05599.002 | D17: =DATE(2026,9,18) -> 46283 | E17: 0.397 | F17: =HYPERLINK("https://drive.google.com/file/d/1yHJCVooq9Fw5U4UR6qwQ1wvnfX2_saay/view","COA SR26-05599.002") -> COA SR26-05599.002 | G17: =E17*H17 -> 0.001588 | H17: 0.004
A18: WODO | B18: =G10
A19: Kerry | B19: =G11 -> 19131.227 | C19: SR26-05599.003 | D19: =DATE(2026,9,16) -> 46281 | E19: 0.579 | F19: =HYPERLINK("https://drive.google.com/file/d/1L85EGT9eN8McatUxpvLoRFABtaZXoci4/view","COA SR26-05599.003") -> COA SR26-05599.003 | G19: =E19*H19 -> 0.002316 | H19: 0.004
A20: QOWV | B20: =G12 -> 30808.5 | C20: SR26-05599.001 | D20: =DATE(2026,9,17) -> 46282 | E20: 0.08 | F20: =HYPERLINK("https://drive.google.com/file/d/1yHJCVooq9Fw5U4UR6qwQ1wvnfX2_saay/view","COA SR26-05599.001") -> COA SR26-05599.001 | G20: =E20*H20 -> 0.00032 | H20: 0.004
A21: TOTAL | B21: =SUM(B17:B20) -> 243431.67

Sheet AECN Rail
A1: BATCH HEADER — AECN Rail
A2: Batch ID (INJ-YYYY-WXX) | B2: INJ-09-2026-W3 | N2: Constants
A3: Week Start (Sat) | B3: 46276 | N3: Lbs/Kg | O3: 2.20462 | Q3: AECN Density (kg/L) | R3: =HYPERLINK("https://drive.google.com/file/d/1yHJCVooq9Fw5U4UR6qwQ1wvnfX2_saay/view",1.192) -> 1.192
A4: Week End (Sat) | B4: 46283 | N4: Kg/Lbs | O4: 0.453592 | Q4: Gallons removed | R4: 200
N5: Sparging Mass Loss | O5: 0.0129 | Q5: Litres per gallon | R5: 3.7854118
N6: pH range (target) | O6: 2.0 - 4.0
N7: Filtration Solids Content | O7: =HYPERLINK("https://docs.google.com/spreadsheets/d/1XhIwfVwGTl2T04CAlA-qee03gfqxNWwBmSCAeiSW548/edit?usp=sharing", 0.00196) -> 0.00196
A8: SECTION 1 - RAILCARS RECEIVED THIS WEEK (entity-level) | N8: BOL Trips (AECN→SOPOR) | O8: 3
A9: Railcar # | B9: Arrival Date at Opelousas | C9: Loading BOLs (comma-sep) | D9: Total Loaded (MT) | E9: Total Loaded (kg) | F9: Total Offloaded (kg, auto) | G9: Loss (kg) | H9: Previously Claimed (kg) | I9: Prior-RP Claimed (kg) | J9: AECN→SOPOR (mi) | K9: Rail (mi) | L9: Opel→Basco (mi) | M9: Notes | N9: Round Trip (Opel→Basco) | O9: 2 | P9: Full Railcar This Week?
A10: GPRX5102 | B10: 46239 | C10: 2456-R, 2457-R, 2458-R | D10: =E10/1000 -> 77.94 | E10: =SUMIF($C$17:$C$25,A10,$E$17:$E$25) -> 77940 | F10: =SUMIF($C$28:$C$43,A10,$F$28:$F$43)+H10 -> 77818.244 | G10: =IF(AND(E10<>"",F10<>"",F10>=0.95*E10),E10-F10,"") -> 121.75648 | H10: 0 | I10: 0 | J10: 107.5 | K10: 2199 | L10: 42.9 | M10: New arrival this RP. Loaded 8/3-8/4/2026 at SOPOR (BOLs 2456-R/2457-R/2458-R: 25,990+25,980+25,970 = 77,940 kg per BOL PDF page-2 Qty-shipped fields; 2457-R corrected 2026-09-19 from 25,990 to 25,980 kg -- BOL tanker tare was hand-corrected 19,282->19,290 lb on the form but the printed total was never recomputed; correct = 45,270-19,290 = 25,980 kg. This now disagrees with COBB origin_quantity_kg (77,950), which still carries the uncorrected BOL figure -- known break, not reconciled). All 4 offloads logged this week, CAT scale-ticket confirmed via live Gmail harvest (delta 0.00 kg vs COBB target on all 4). Mileage (AECN->SOPOR / Rail / Opel->Basco) intentionally left BLANK -- no independently sourced route-mileage reference found for this railcar; NOT copied from other cars. Prior-RP claimed: 0 kg. | P10: =IF(OR($E10="",$F10=""),"",IF(AND($H10=0,$F10>=0.95*$E10),"FULL","PARTIAL")) -> FULL
A11: SHPX215046 | B11: 46241 | C11: 2462-R, 2463-R, 2464-R | D11: =E11/1000 -> 77.68 | E11: =SUMIF($C$17:$C$25,A11,$E$17:$E$25) -> 77680 | F11: =SUMIF($C$28:$C$43,A11,$F$28:$F$43)+H11 -> 42047.978 | G11: =IF(AND(E11<>"",F11<>"",F11>=0.95*E11),E11-F11,"") | H11: 0 | I11: 0 | J11: 107.5 | K11: 2199 | L11: 42.9 | M11: Continuing railcar from prior RP week (W2 consumed offload_3/offload_4 from this same 8/5-8/6/2026 SOPOR loading; this week consumes offload_1/offload_2 from the SAME loading, BOLs 2462-R/2463-R/2464-R, 77,680 kg -- no double-count, different offload numbers). Mileage carried forward from this railcar's own W2 Section 1 entry (same physical car/route, not inferred from a different railcar). Prior-RP claimed: 0 kg. | P11: =IF(OR($E11="",$F11=""),"",IF(AND($H11=0,$F11>=0.95*$E11),"FULL","PARTIAL")) -> PARTIAL
A12: TILX200231 | B12: 46246 | C12: 2468-R, 2469-R, 2470-R | D12: =E12/1000 -> 77.52 | E12: =SUMIF($C$17:$C$25,A12,$E$17:$E$25) -> 77520 | F12: =SUMIF($C$28:$C$43,A12,$F$28:$F$43)+H12 -> 77455.37 | G12: =IF(AND(E12<>"",F12<>"",F12>=0.95*E12),E12-F12,"") -> 64.63008 | H12: 0 | I12: 0 | J12: 107.5 | K12: 2199 | L12: 42.9 | M12: New arrival this RP. Loaded 8/11/2026 at SOPOR (BOLs 2468-R/2469-R/2470-R: 25,920+25,900+25,700 = 77,520 kg per BOL PDF page-2 Qty-shipped fields, matches COBB origin_quantity_kg exactly). All 4 offloads logged this week, CAT scale-ticket confirmed via live Gmail harvest (delta 0.00 kg vs COBB target on 3 of 4; offload_3 auto-matcher paired the wrong tare -- manually corrected to ticket 1312226256537, 29,460 lb, exact match). Mileage (AECN->SOPOR / Rail / Opel->Basco) intentionally left BLANK -- no independently sourced route-mileage reference found for this railcar; NOT copied from other cars. Prior-RP claimed: 0 kg. | P12: =IF(OR($E12="",$F12=""),"",IF(AND($H12=0,$F12>=0.95*$E12),"FULL","PARTIAL")) -> FULL
G13: =IF(AND(E13<>"",F13<>"",F13>=0.95*E13),E13-F13,"") | P13: =IF(OR($E13="",$F13=""),"",IF(AND($H13=0,$F13>=0.95*$E13),"FULL","PARTIAL"))
G14: =IF(AND(E14<>"",F14<>"",F14>=0.95*E14),E14-F14,"") | P14: =IF(OR($E14="",$F14=""),"",IF(AND($H14=0,$F14>=0.95*$E14),"FULL","PARTIAL"))
A15: SECTION 2 - ORIGINS LEDGER (loading BOLs at SOPOR)
A16: Date | B16: BOL # | C16: Railcar # | D16: BOL Mass (MT) | E16: BOL Mass (kg)
A17: 46237 | B17: =HYPERLINK("https://drive.google.com/file/d/1xZJu8K3nomePjoSpICC9QdIGaZsG5yWA/view","2456-R") -> 2456-R | C17: GPRX5102 | D17: 25.99 | E17: =D17*1000 -> 25990
A18: 46238 | B18: =HYPERLINK("https://drive.google.com/file/d/13dMLL3VeyFdZeNK1OrQh7Sgs0a2s_OKS/view","2457-R") -> 2457-R | C18: GPRX5102 | D18: 25.98 | E18: =D18*1000 -> 25980
A19: 46238 | B19: =HYPERLINK("https://drive.google.com/file/d/1oyWuzdFY7ewlZ-JYvWSUSYQszYeGR1Nl/view","2458-R") -> 2458-R | C19: GPRX5102 | D19: 25.97 | E19: =D19*1000 -> 25970
A20: 46239 | B20: =HYPERLINK("https://drive.google.com/file/d/1dCSXmu7dtsVXb1lm03NoB703GWhQ4SoL/view","2462-R") -> 2462-R | C20: SHPX215046 | D20: 25.94 | E20: =D20*1000 -> 25940
A21: 46240 | B21: =HYPERLINK("https://drive.google.com/file/d/1dnRbhH5-6l1akkr2TOene6LVg_vIcbqy/view","2463-R") -> 2463-R | C21: SHPX215046 | D21: 25.9 | E21: =D21*1000 -> 25900
A22: 46240 | B22: =HYPERLINK("https://drive.google.com/file/d/1K229IOTPDOAGAckmNGMoLtQr9BUJo-tu/view","2464-R") -> 2464-R | C22: SHPX215046 | D22: 25.84 | E22: =D22*1000 -> 25840
A23: 46245 | B23: =HYPERLINK("https://drive.google.com/file/d/1V-tSOaaiew9uy7s0QLdDwcUShVMHUfrv/view","2468-R") -> 2468-R | C23: TILX200231 | D23: 25.92 | E23: =D23*1000 -> 25920
A24: 46245 | B24: =HYPERLINK("https://drive.google.com/file/d/1nIjj8CsN8hNswCjppq_y0ho_dyrV4RIh/view","2469-R") -> 2469-R | C24: TILX200231 | D24: 25.9 | E24: =D24*1000 -> 25900
A25: 46245 | B25: =HYPERLINK("https://drive.google.com/file/d/1COQDpzv_sGmrX2fqsUDq0XxHLQ6Sfc2o/view","2470-R") -> 2470-R | C25: TILX200231 | D25: 25.7 | E25: =D25*1000 -> 25700
A26: SECTION 3 - SCALE TICKTS + OFFLOAD WEIGHTS
D27: Full Scale Ticket (lb) | E27: Empty Scale Ticket (lb) | F27: Net Scaled Mass (kg) | G27: pH | H27: Sparging Loss (kg) | I27: Filtration Loss (kg) | J27: Uncertainty Adjustment (kg) | K27: MOBI (kg) | L27: AECN→SOPOR (mi, allocated ×3) | M27: Rail (mi, allocated) | N27: Opel→Basco (mi, full ×2) | O27: C Content
A28: 46283 | B28: Rail_GPRX5102_8.5.2026_offload_1 | C28: GPRX5102 | D28: 73140 | E28: 28760 | F28: =IF(OR(D28="",E28=""),"",(D28-E28)*$O$4) -> 20130.413 | H28: =IF(F28="","",(F28-J28)*$O$5) -> 259.68233 | I28: =IF(F28="","",(F28-J28)*(1-$O$5)*$O$7) -> 38.946632 | J28: {=IF(F28="","",IF(ROW()=MAX(IF($C$28:$C$37=C28,ROW($C$28:$C$37),0)),MAX(0,IFERROR(VLOOKUP(C28,$A$10:$L$14,6,FALSE)-VLOOKUP(C28,$A$10:$L$14,5,FALSE),0)),0))} -> 0 | K28: =IF(F28="","",F28-H28-I28-J28) -> 19831.784 | L28: =IF(F28="","",(F28-J28)/VLOOKUP(C28,$A$10:$L$14,5,FALSE)*VLOOKUP(C28,$A$10:$L$14,10,FALSE)*$O$8) -> 83.295589 | M28: {=IF(F28="","",IF(IFERROR(VLOOKUP(C28,$A$10:$P$14,16,FALSE),"")="FULL",IF(ROW()=MIN(IF($C$28:$C$37=C28,ROW($C$28:$C$37),10^9)),VLOOKUP(C28,$A$10:$P$14,11,FALSE),0),(F28-J28)/VLOOKUP(C28,$A$10:$P$14,5,FALSE)*VLOOKUP(C28,$A$10:$P$14,11,FALSE)))} -> 2199 | N28: =IF(F28="","",IFERROR(VLOOKUP(C28,$A$10:$L$14,12,FALSE),0)*$O$9) -> 85.8
A29: 46283 | B29: Rail_GPRX5102_8.5.2026_offload_2 | C29: GPRX5102 | D29: 71260 | E29: 29480 | F29: =IF(OR(D29="",E29=""),"",(D29-E29)*$O$4) -> 18951.074 | H29: =IF(F29="","",(F29-J29)*$O$5) -> 244.46885 | I29: =IF(F29="","",(F29-J29)*(1-$O$5)*$O$7) -> 36.664946 | J29: {=IF(F29="","",IF(ROW()=MAX(IF($C$28:$C$37=C29,ROW($C$28:$C$37),0)),MAX(0,IFERROR(VLOOKUP(C29,$A$10:$L$14,6,FALSE)-VLOOKUP(C29,$A$10:$L$14,5,FALSE),0)),0))} -> 0 | K29: =IF(F29="","",F29-H29-I29-J29) -> 18669.94 | L29: =IF(F29="","",(F29-J29)/VLOOKUP(C29,$A$10:$L$14,5,FALSE)*VLOOKUP(C29,$A$10:$L$14,10,FALSE)*$O$8) -> 78.415721 | M29: {=IF(F29="","",IF(IFERROR(VLOOKUP(C29,$A$10:$P$14,16,FALSE),"")="FULL",IF(ROW()=MIN(IF($C$28:$C$37=C29,ROW($C$28:$C$37),10^9)),VLOOKUP(C29,$A$10:$P$14,11,FALSE),0),(F29-J29)/VLOOKUP(C29,$A$10:$P$14,5,FALSE)*VLOOKUP(C29,$A$10:$P$14,11,FALSE)))} -> 0 | N29: =IF(F29="","",IFERROR(VLOOKUP(C29,$A$10:$L$14,12,FALSE),0)*$O$9) -> 85.8
A30: 46283 | B30: Rail_GPRX5102_8.5.2026_offload_3 | C30: GPRX5102 | D30: 73600 | E30: 28620 | F30: =IF(OR(D30="",E30=""),"",(D30-E30)*$O$4) -> 20402.568 | H30: =IF(F30="","",(F30-J30)*$O$5) -> 263.19313 | I30: =IF(F30="","",(F30-J30)*(1-$O$5)*$O$7) -> 39.473175 | J30: {=IF(F30="","",IF(ROW()=MAX(IF($C$28:$C$37=C30,ROW($C$28:$C$37),0)),MAX(0,IFERROR(VLOOKUP(C30,$A$10:$L$14,6,FALSE)-VLOOKUP(C30,$A$10:$L$14,5,FALSE),0)),0))} -> 0 | K30: =IF(F30="","",F30-H30-I30-J30) -> 20099.902 | L30: =IF(F30="","",(F30-J30)/VLOOKUP(C30,$A$10:$L$14,5,FALSE)*VLOOKUP(C30,$A$10:$L$14,10,FALSE)*$O$8) -> 84.421712 | M30: {=IF(F30="","",IF(IFERROR(VLOOKUP(C30,$A$10:$P$14,16,FALSE),"")="FULL",IF(ROW()=MIN(IF($C$28:$C$37=C30,ROW($C$28:$C$37),10^9)),VLOOKUP(C30,$A$10:$P$14,11,FALSE),0),(F30-J30)/VLOOKUP(C30,$A$10:$P$14,5,FALSE)*VLOOKUP(C30,$A$10:$P$14,11,FALSE)))} -> 0 | N30: =IF(F30="","",IFERROR(VLOOKUP(C30,$A$10:$L$14,12,FALSE),0)*$O$9) -> 85.8
A31: 46283 | B31: Rail_GPRX5102_8.5.2026_offload_4 | C31: GPRX5102 | D31: 69780 | E31: 29360 | F31: =IF(OR(D31="",E31=""),"",(D31-E31)*$O$4) -> 18334.189 | H31: =IF(F31="","",(F31-J31)*$O$5) -> 236.51103 | I31: =IF(F31="","",(F31-J31)*(1-$O$5)*$O$7) -> 35.471448 | J31: {=IF(F31="","",IF(ROW()=MAX(IF($C$28:$C$37=C31,ROW($C$28:$C$37),0)),MAX(0,IFERROR(VLOOKUP(C31,$A$10:$L$14,6,FALSE)-VLOOKUP(C31,$A$10:$L$14,5,FALSE),0)),0))} -> 0 | K31: =IF(F31="","",F31-H31-I31-J31) -> 18062.206 | L31: =IF(F31="","",(F31-J31)/VLOOKUP(C31,$A$10:$L$14,5,FALSE)*VLOOKUP(C31,$A$10:$L$14,10,FALSE)*$O$8) -> 75.863175 | M31: {=IF(F31="","",IF(IFERROR(VLOOKUP(C31,$A$10:$P$14,16,FALSE),"")="FULL",IF(ROW()=MIN(IF($C$28:$C$37=C31,ROW($C$28:$C$37),10^9)),VLOOKUP(C31,$A$10:$P$14,11,FALSE),0),(F31-J31)/VLOOKUP(C31,$A$10:$P$14,5,FALSE)*VLOOKUP(C31,$A$10:$P$14,11,FALSE)))} -> 0 | N31: =IF(F31="","",IFERROR(VLOOKUP(C31,$A$10:$L$14,12,FALSE),0)*$O$9) -> 85.8
A32: 46283 | B32: Rail_SHPX215046_8.7.2026_offload_1 | C32: SHPX215046 | D32: 75300 | E32: 28880 | F32: =IF(OR(D32="",E32=""),"",(D32-E32)*$O$4) -> 21055.741 | H32: =IF(F32="","",(F32-J32)*$O$5) -> 271.61905 | I32: =IF(F32="","",(F32-J32)*(1-$O$5)*$O$7) -> 40.736878 | J32: {=IF(F32="","",IF(ROW()=MAX(IF($C$28:$C$37=C32,ROW($C$28:$C$37),0)),MAX(0,IFERROR(VLOOKUP(C32,$A$10:$L$14,6,FALSE)-VLOOKUP(C32,$A$10:$L$14,5,FALSE),0)),0))} -> 0 | K32: =IF(F32="","",F32-H32-I32-J32) -> 20743.385 | L32: =IF(F32="","",(F32-J32)/VLOOKUP(C32,$A$10:$L$14,5,FALSE)*VLOOKUP(C32,$A$10:$L$14,10,FALSE)*$O$8) -> 87.416019 | M32: {=IF(F32="","",IF(IFERROR(VLOOKUP(C32,$A$10:$P$14,16,FALSE),"")="FULL",IF(ROW()=MIN(IF($C$28:$C$37=C32,ROW($C$28:$C$37),10^9)),VLOOKUP(C32,$A$10:$P$14,11,FALSE),0),(F32-J32)/VLOOKUP(C32,$A$10:$P$14,5,FALSE)*VLOOKUP(C32,$A$10:$P$14,11,FALSE)))} -> 596.05527 | N32: =IF(F32="","",IFERROR(VLOOKUP(C32,$A$10:$L$14,12,FALSE),0)*$O$9) -> 85.8
A33: 46283 | B33: Rail_SHPX215046_8.7.2026_offload_2 | C33: SHPX215046 | D33: 75020 | E33: 28740 | F33: =IF(OR(D33="",E33=""),"",(D33-E33)*$O$4) -> 20992.238 | H33: =IF(F33="","",(F33-J33)*$O$5) -> 270.79987 | I33: =IF(F33="","",(F33-J33)*(1-$O$5)*$O$7) -> 40.614018 | J33: {=IF(F33="","",IF(ROW()=MAX(IF($C$28:$C$37=C33,ROW($C$28:$C$37),0)),MAX(0,IFERROR(VLOOKUP(C33,$A$10:$L$14,6,FALSE)-VLOOKUP(C33,$A$10:$L$14,5,FALSE),0)),0))} -> 0 | K33: =IF(F33="","",F33-H33-I33-J33) -> 20680.824 | L33: =IF(F33="","",(F33-J33)/VLOOKUP(C33,$A$10:$L$14,5,FALSE)*VLOOKUP(C33,$A$10:$L$14,10,FALSE)*$O$8) -> 87.152377 | M33: {=IF(F33="","",IF(IFERROR(VLOOKUP(C33,$A$10:$P$14,16,FALSE),"")="FULL",IF(ROW()=MIN(IF($C$28:$C$37=C33,ROW($C$28:$C$37),10^9)),VLOOKUP(C33,$A$10:$P$14,11,FALSE),0),(F33-J33)/VLOOKUP(C33,$A$10:$P$14,5,FALSE)*VLOOKUP(C33,$A$10:$P$14,11,FALSE)))} -> 594.25761 | N33: =IF(F33="","",IFERROR(VLOOKUP(C33,$A$10:$L$14,12,FALSE),0)*$O$9) -> 85.8
A34: 46283 | B34: Rail_TILX200231_8.12.2026_offload_1 | C34: TILX200231 | D34: 72940 | E34: 28740 | F34: =IF(OR(D34="",E34=""),"",(D34-E34)*$O$4) -> 20048.766 | H34: =IF(F34="","",(F34-J34)*$O$5) -> 258.62909 | I34: =IF(F34="","",(F34-J34)*(1-$O$5)*$O$7) -> 38.788669 | J34: {=IF(F34="","",IF(ROW()=MAX(IF($C$28:$C$37=C34,ROW($C$28:$C$37),0)),MAX(0,IFERROR(VLOOKUP(C34,$A$10:$L$14,6,FALSE)-VLOOKUP(C34,$A$10:$L$14,5,FALSE),0)),0))} -> 0 | K34: =IF(F34="","",F34-H34-I34-J34) -> 19751.349 | L34: =IF(F34="","",(F34-J34)/VLOOKUP(C34,$A$10:$L$14,5,FALSE)*VLOOKUP(C34,$A$10:$L$14,10,FALSE)*$O$8) -> 83.407213 | M34: {=IF(F34="","",IF(IFERROR(VLOOKUP(C34,$A$10:$P$14,16,FALSE),"")="FULL",IF(ROW()=MIN(IF($C$28:$C$37=C34,ROW($C$28:$C$37),10^9)),VLOOKUP(C34,$A$10:$P$14,11,FALSE),0),(F34-J34)/VLOOKUP(C34,$A$10:$P$14,5,FALSE)*VLOOKUP(C34,$A$10:$P$14,11,FALSE)))} -> 2199 | N34: =IF(F34="","",IFERROR(VLOOKUP(C34,$A$10:$L$14,12,FALSE),0)*$O$9) -> 85.8
A35: 46283 | B35: Rail_TILX200231_8.12.2026_offload_2 | C35: TILX200231 | D35: 72640 | E35: 29640 | F35: =IF(OR(D35="",E35=""),"",(D35-E35)*$O$4) -> 19504.456 | H35: =IF(F35="","",(F35-J35)*$O$5) -> 251.60748 | I35: =IF(F35="","",(F35-J35)*(1-$O$5)*$O$7) -> 37.735583 | J35: {=IF(F35="","",IF(ROW()=MAX(IF($C$28:$C$37=C35,ROW($C$28:$C$37),0)),MAX(0,IFERROR(VLOOKUP(C35,$A$10:$L$14,6,FALSE)-VLOOKUP(C35,$A$10:$L$14,5,FALSE),0)),0))} -> 0 | K35: =IF(F35="","",F35-H35-I35-J35) -> 19215.113 | L35: =IF(F35="","",(F35-J35)/VLOOKUP(C35,$A$10:$L$14,5,FALSE)*VLOOKUP(C35,$A$10:$L$14,10,FALSE)*$O$8) -> 81.142764 | M35: {=IF(F35="","",IF(IFERROR(VLOOKUP(C35,$A$10:$P$14,16,FALSE),"")="FULL",IF(ROW()=MIN(IF($C$28:$C$37=C35,ROW($C$28:$C$37),10^9)),VLOOKUP(C35,$A$10:$P$14,11,FALSE),0),(F35-J35)/VLOOKUP(C35,$A$10:$P$14,5,FALSE)*VLOOKUP(C35,$A$10:$P$14,11,FALSE)))} -> 0 | N35: =IF(F35="","",IFERROR(VLOOKUP(C35,$A$10:$L$14,12,FALSE),0)*$O$9) -> 85.8
A36: 46283 | B36: Rail_TILX200231_8.12.2026_offload_3 | C36: TILX200231 | D36: 73280 | E36: 29460 | F36: =IF(OR(D36="",E36=""),"",(D36-E36)*$O$4) -> 19876.401 | H36: =IF(F36="","",(F36-J36)*$O$5) -> 256.40558 | I36: =IF(F36="","",(F36-J36)*(1-$O$5)*$O$7) -> 38.455192 | J36: {=IF(F36="","",IF(ROW()=MAX(IF($C$28:$C$37=C36,ROW($C$28:$C$37),0)),MAX(0,IFERROR(VLOOKUP(C36,$A$10:$L$14,6,FALSE)-VLOOKUP(C36,$A$10:$L$14,5,FALSE),0)),0))} -> 0 | K36: =IF(F36="","",F36-H36-I36-J36) -> 19581.541 | L36: =IF(F36="","",(F36-J36)/VLOOKUP(C36,$A$10:$L$14,5,FALSE)*VLOOKUP(C36,$A$10:$L$14,10,FALSE)*$O$8) -> 82.690138 | M36: {=IF(F36="","",IF(IFERROR(VLOOKUP(C36,$A$10:$P$14,16,FALSE),"")="FULL",IF(ROW()=MIN(IF($C$28:$C$37=C36,ROW($C$28:$C$37),10^9)),VLOOKUP(C36,$A$10:$P$14,11,FALSE),0),(F36-J36)/VLOOKUP(C36,$A$10:$P$14,5,FALSE)*VLOOKUP(C36,$A$10:$P$14,11,FALSE)))} -> 0 | N36: =IF(F36="","",IFERROR(VLOOKUP(C36,$A$10:$L$14,12,FALSE),0)*$O$9) -> 85.8
A37: 46283 | B37: Rail_TILX200231_8.12.2026_offload_4 | C37: TILX200231 | D37: 68080 | E37: 28340 | F37: =IF(OR(D37="",E37=""),"",(D37-E37)*$O$4) -> 18025.746 | H37: =IF(F37="","",(F37-J37)*$O$5) -> 232.53212 | I37: =IF(F37="","",(F37-J37)*(1-$O$5)*$O$7) -> 34.874699 | J37: {=IF(F37="","",IF(ROW()=MAX(IF($C$28:$C$37=C37,ROW($C$28:$C$37),0)),MAX(0,IFERROR(VLOOKUP(C37,$A$10:$L$14,6,FALSE)-VLOOKUP(C37,$A$10:$L$14,5,FALSE),0)),0))} -> 0 | K37: =IF(F37="","",F37-H37-I37-J37) -> 17758.339 | L37: =IF(F37="","",(F37-J37)/VLOOKUP(C37,$A$10:$L$14,5,FALSE)*VLOOKUP(C37,$A$10:$L$14,10,FALSE)*$O$8) -> 74.99101 | M37: {=IF(F37="","",IF(IFERROR(VLOOKUP(C37,$A$10:$P$14,16,FALSE),"")="FULL",IF(ROW()=MIN(IF($C$28:$C$37=C37,ROW($C$28:$C$37),10^9)),VLOOKUP(C37,$A$10:$P$14,11,FALSE),0),(F37-J37)/VLOOKUP(C37,$A$10:$P$14,5,FALSE)*VLOOKUP(C37,$A$10:$P$14,11,FALSE)))} -> 0 | N37: =IF(F37="","",IFERROR(VLOOKUP(C37,$A$10:$L$14,12,FALSE),0)*$O$9) -> 85.8
L38: =SUM(L28:L37) -> 818.79572 | M38: =SUM(M28:M37) -> 5588.3129 | N38: =SUM(N28:N37) -> 858
L39: =IF(F39="","",(F39-J39)/VLOOKUP(C39,$A$10:$L$14,5,FALSE)*VLOOKUP(C39,$A$10:$L$14,10,FALSE)*$O$8) | M39: =IF(F39="","",(F39-J39)/VLOOKUP(C39,$A$10:$L$14,5,FALSE)*VLOOKUP(C39,$A$10:$L$14,11,FALSE)) | N39: =IF(F39="","",IFERROR(VLOOKUP(C39,$A$10:$L$14,12,FALSE),0)*$O$9)
L40: =IF(F40="","",(F40-J40)/VLOOKUP(C40,$A$10:$L$14,5,FALSE)*VLOOKUP(C40,$A$10:$L$14,10,FALSE)*$O$8) | M40: =IF(F40="","",(F40-J40)/VLOOKUP(C40,$A$10:$L$14,5,FALSE)*VLOOKUP(C40,$A$10:$L$14,11,FALSE)) | N40: =IF(F40="","",IFERROR(VLOOKUP(C40,$A$10:$L$14,12,FALSE),0)*$O$9)
...

Sheet AECN Truck
A1: BATCH HEADER — AECN Truck (Direct from Fort Lupton)
A2: Batch ID (INJ-YYYY-WXX) | B2: INJ-09-2026-W3 | K2: Constants
A3: Week Start (Sat) | B3: 46276 | K3: Lbs/Kg | L3: 2.20462
A4: Week End (Sat) | B4: 46283 | K4: Kg/Lbs | L4: 0.453592
K5: Sparging Mass Loss | L5: 0.0129
K6: pH range (target) | L6: 2.0 - 4.0
K7: Filtration Solids Content | L7: 0.00196
A8: SECTION 1 - DELIVERIES LEDGER (one row per direct truck; BOL & scale ticket on same row)
A9: Date | B9: BOL # / SO # | C9: BOL Mass (MT) | D9: BOL Mass (kg) | E9: Scale Full (lb) | F9: Scale Empty (lb) | G9: Cargo (kg) | H9: pH | I9: Notes | J9: Sparging Loss (kg) | K9: Filtration Loss (kg) | L9: MOBI (kg) | M9: C Content | N9: EE Miles
J10: =IF(D10="","",D10*$L$5) | K10: =IF(D10="","",(D10-J10)*$L$7) | L10: =IF(D10="","",D10-J10-K10) | N10: 2197
J11: =IF(D11="","",D11*$L$5) | K11: =IF(D11="","",(D11-J11)*$L$7) | L11: =IF(D11="","",D11-J11-K11) | N11: 2197
J12: =IF(D12="","",D12*$L$5) | K12: =IF(D12="","",(D12-J12)*$L$7) | L12: =IF(D12="","",D12-J12-K12) | N12: 2197
J13: =IF(D13="","",D13*$L$5) | K13: =IF(D13="","",(D13-J13)*$L$7) | L13: =IF(D13="","",D13-J13-K13)
J14: =IF(D14="","",D14*$L$5) | K14: =IF(D14="","",(D14-J14)*$L$7) | L14: =IF(D14="","",D14-J14-K14)
J15: =IF(D15="","",D15*$L$5) | K15: =IF(D15="","",(D15-J15)*$L$7) | L15: =IF(D15="","",D15-J15-K15)
J16: =IF(D16="","",D16*$L$5) | K16: =IF(D16="","",(D16-J16)*$L$7) | L16: =IF(D16="","",D16-J16-K16)
J17: =IF(D17="","",D17*$L$5) | K17: =IF(D17="","",(D17-J17)*$L$7) | L17: =IF(D17="","",D17-J17-K17)
J18: =IF(D18="","",D18*$L$5) | K18: =IF(D18="","",(D18-J18)*$L$7) | L18: =IF(D18="","",D18-J18-K18)
J19: =IF(D19="","",D19*$L$5) | K19: =IF(D19="","",(D19-J19)*$L$7) | L19: =IF(D19="","",D19-J19-K19)
J20: =IF(D20="","",D20*$L$5) | K20: =IF(D20="","",(D20-J20)*$L$7) | L20: =IF(D20="","",D20-J20-K20)
J21: =IF(D21="","",D21*$L$5) | K21: =IF(D21="","",(D21-J21)*$L$7) | L21: =IF(D21="","",D21-J21-K21)
J22: =IF(D22="","",D22*$L$5) | K22: =IF(D22="","",(D22-J22)*$L$7) | L22: =IF(D22="","",D22-J22-K22)
J23: =IF(D23="","",D23*$L$5) | K23: =IF(D23="","",(D23-J23)*$L$7) | L23: =IF(D23="","",D23-J23-K23)
J24: =IF(D24="","",D24*$L$5) | K24: =IF(D24="","",(D24-J24)*$L$7) | L24: =IF(D24="","",D24-J24-K24)
N25: =sum(N10:N23) -> 6591
A26: SECTION 2 - ROLLUP (Mass Used = Σ BOL kg; scale tickets no longer required for direct trucks per 2026-05-26)
A27: Σ BOL (kg) | B27: Σ Cargo (kg) | C27: Mass Used (kg) | D27: Sparging Loss (kg) | E27: Filtration Loss (kg) | F27: Uncertainty Adjustment (kg) | G27: MOBI (kg) | H27: pH | I27: C Content | K27: Origins list (BOLs)
A28: =SUMIFS(D10:D24,B10:B24,"<>") -> 0 | B28: =SUMIFS(G10:G24,B10:B24,"<>") -> 0 | C28: =A28 -> 0 | D28: =C28*$L$5 -> 0 | E28: =(C28-D28)*$L$7 -> 0 | F28: 0 | G28: =C28-D28-E28-F28 -> 0 | H28: =IFERROR(AVERAGE(H10:H24),"") | K28: =IFERROR(__xludf.DUMMYFUNCTION("TRIM(TEXTJOIN("", "",TRUE,IFERROR(FILTER(B10:B24,B10:B24<>""""),"""")))"),"")

Sheet Kerry
A1: BATCH HEADER — Kerry (Calciner Waste Oil, Tankers)
A2: Batch ID (INJ-YYYY-WXX) | B2: INJ-09-2026-W3 | L2: Constants
A3: Week Start (Sat) | B3: 46276 | L3: Lbs/Kg | M3: 2.20462
A4: Week End (Sat) | B4: 46283 | L4: Kg/Lbs | M4: 0.453592
L5: Filtration Solids Content | M5: 0.00196
L6: pH range (target) | M6: 2.0 - 4.0
L7: Testing Uncertainty | M7: 0.004
A8: SECTION 1 - TANKER LEDGER (one row per Kerry tanker; scale mass is authoritative)
A9: Date | B9: UID | C9: Gross Mass (lb) — transport | D9: Empty Weight (lb) | E9: Net Oil (lb) | F9: Net Injected (kg) — MOBI | G9: pH | H9: Notes | I9: C Content | J9: C Content Uncertainty | K9: Mass Uncertainty (Scaling)
A10: 46283 | B10: KC-09 | C10: 76680 | D10: 34420 | E10: =C10-D10 -> 42260 | F10: =E10*M4 -> 19168.798
A15: SECTION 2 - ROLLUP
A16: Σ Net Injected (kg) | B16: Filtration Loss (kg) | C16: MOBI (kg) | D16: pH | E16: C Content (composite - see Summary) | G16: Origins list (Tanker UIDs)
A17: =SUMIFS(F9:F14,B9:B14,"<>") -> 19168.798 | B17: =A17*$M$5 -> 37.570844 | C17: =A17-B17 -> 19131.227 | D17: =IFERROR(AVERAGE(G9:G14),"") | G17: =IFERROR(__xludf.DUMMYFUNCTION("TRIM(TEXTJOIN("", "",TRUE,IFERROR(FILTER(B9:B14,B9:B14<>""""),"""")))"),"UID, KC-09") -> UID, KC-09

Sheet WODO
A1: BATCH HEADER — Charm WODO (IBC Totes)
A2: Batch ID (INJ-YYYY-WXX) | B2: INJ-09-2026-W3 | K2: Constants
A3: Week Start (Sat) | B3: 46276 | K3: Lbs/Kg | L3: 2.20462
A4: Week End (Sat) | B4: 46283 | K4: Kg/Lbs | L4: 0.453592
K5: Sparging Mass Loss | L5: 0.0129
K6: pH range (target) | L6: 2.0 - 4.0
K7: WODO 6-Mo CI (kg CO2e/kg), Jul-Dec 2026 | L7: 0.795241
A8: SECTION 1 - IBC LEDGER (one row per IBC tote; tote tag mass is authoritative) | K8: WODO Standard Loss (kg/tote), 2026 = Mean + 1 SD | L8: 7.84 | M8: =HYPERLINK("https://docs.google.com/spreadsheets/d/15fnYOYMmu-7a-p8Alst6mAOsV7X854y6HBDYwQRUm5s/edit","Tote Loss Dataset") -> Tote Loss Dataset
B9: Transport Emissions | D9: Pyrolysis Emissions Mass & Standard Loss | F9: MOBI | K9: Per-Production-Month CI (kg CO2e/kg) - PP Summary Output Type table, col T
J10: Scale Uncertainty | K10: PP#8 | L10: 0.71282902 | M10: =HYPERLINK("https://docs.google.com/spreadsheets/d/1L167k_JS3mnisFy3VpS-OXgI8U0cK-4nC6A9sxl-ozk/edit","PP Summary") -> PP Summary
K11: November 2025 | L11: 0.97484085 | M11: =HYPERLINK("https://docs.google.com/spreadsheets/d/1W8jWu3sp39WnSuds1Ja0FWDG5UuWN9v5NUmF6yh_WbI/edit","PP Summary") -> PP Summary
K12: December 2025 | L12: 0.97218282 | M12: =HYPERLINK("https://docs.google.com/spreadsheets/d/1-L6m2wYknC3o-yIts9KK7FrYAb5lZIv4AwaizK8FbMc/edit","PP Summary") -> PP Summary
K13: January 2026 | L13: 0.93199449 | M13: =HYPERLINK("https://docs.google.com/spreadsheets/d/1bPZ7pNsR5rv-om-BypF4lK3nczjn4HJNO2dzimwnx7E/edit","PP Summary") -> PP Summary
K14: February 2026 | L14: 0.84989612 | M14: =HYPERLINK("https://docs.google.com/spreadsheets/d/1vH7bborVnc-TCby3wEkpzi7GGMOI5jMJooEW0V-rOQ4/edit","PP Summary") -> PP Summary
K15: March 2026 | L15: 0.79006453 | M15: =HYPERLINK("https://docs.google.com/spreadsheets/d/1O7y30opa_u1_deqFm_w2qgVyxi_75X00xnzKuyVyh6o/edit","PP Summary") -> PP Summary
K16: April 2026 | L16: 0.78483234 | M16: =HYPERLINK("https://docs.google.com/spreadsheets/d/10Qwx7K6sUcOBrCebGUGVaVeLQnhzvcT8sHQ0Sy3VBBM/edit","PP Summary") -> PP Summary
K17: May 2026 | L17: 0.63284589 | M17: =HYPERLINK("https://docs.google.com/spreadsheets/d/1m66t1jsLGc4e6AWnCFMsFbkSceZ9IYC_-bfTsbP_OYc/edit","PP Summary") -> PP Summary
K18: June 2026 | L18: 1.1105356 | M18: =HYPERLINK("https://docs.google.com/spreadsheets/d/1MUQajDI2a_Cn9xWGPP7z4PhhphZnfl2_CSTnpB07Wgk/edit","PP Summary") -> PP Summary
K19: July 2026 and later (Jan-Jun 2026 rolling) | L19: =$L$7 -> 0.795241
J25: =SUM(J11:J23) -> 0

Sheet QOWV
A1: BATCH HEADER — QOWV (Aqueous Bio-Oil, IBC Totes)
A2: Batch ID (INJ-YYYY-WXX) | B2: INJ-09-2026-W3 | K2: Constants
A3: Week Start (Sat) | B3: 46276 | K3: Lbs/Kg | L3: 2.20462
A4: Week End (Sat) | B4: 46283 | K4: Kg/Lbs | L4: 0.453592
K5: Sparging Mass Loss | L5: 0.0129
K6: pH range (target) | L6: 2.0 - 4.0
K7: QOWV 6-Mo CI (kg CO2e/kg), Jul-Dec 2026 | L7: 0.120947
A8: SECTION 1 - IBC LEDGER (one row per QOWV tote; tote tag mass is authoritative)
B9: Transport Emissions | D9: Pyrolysis Emissions Mass | F9: MOBI | K9: Per-Production-Month CI (kg CO2e/kg) - PP Summary Output Type table, col T
A10: Tag | B10: Gross Mass (kg) | C10: Tote Mass (kg) | D10: Net Oil Produced (kg) | E10: Empty Tote Weight (kg) | F10: Net Oil Injected (kg) | G10: Production Period | H10: Carbon Intensity | I10: Production Emissions | J10: Scale Uncertainty | K10: PP#8 | L10: 0.15755534 | M10: =HYPERLINK("https://docs.google.com/spreadsheets/d/1L167k_JS3mnisFy3VpS-OXgI8U0cK-4nC6A9sxl-ozk/edit","PP Summary") -> PP Summary
A11: 301009 | B11: 1013 | C11: 57.6 | D11: =B11-C11 -> 955.4 | E11: 180.5 | F11: =IF(E11="","",B11-E11) -> 832.5 | G11: MFO Lot 301009 (LOT00301009), April 2026 | H11: =$L$16 -> 0.13141845 | I11: =H11*D11 -> 125.55719 | J11: =2.5*$L$4 -> 1.13398 | K11: 45962 | L11: 0.13921405 | M11: =HYPERLINK("https://docs.google.com/spreadsheets/d/1W8jWu3sp39WnSuds1Ja0FWDG5UuWN9v5NUmF6yh_WbI/edit","PP Summary") -> PP Summary
A12: 301082 | B12: 1066 | C12: 57.6 | D12: =B12-C12 -> 1008.4 | E12: 165 | F12: =IF(E12="","",B12-E12) -> 901 | G12: MFO Lot 301082 (LOT00301082), April 2026 | H12: =$L$16 -> 0.13141845 | I12: =H12*D12 -> 132.52237 | J12: =2.5*$L$4 -> 1.13398 | K12: 45992 | L12: 0.16306166 | M12: =HYPERLINK("https://docs.google.com/spreadsheets/d/1-L6m2wYknC3o-yIts9KK7FrYAb5lZIv4AwaizK8FbMc/edit","PP Summary") -> PP Summary
A13: 301103 | B13: 1014 | C13: 57.6 | D13: =B13-C13 -> 956.4 | E13: 151.5 | F13: =IF(E13="","",B13-E13) -> 862.5 | G13: MFO Lot 301103 (LOT00301103), April 2026 | H13: =$L$16 -> 0.13141845 | I13: =H13*D13 -> 125.68861 | J13: =2.5*$L$4 -> 1.13398 | K13: 46023 | L13: 0.15683402 | M13: =HYPERLINK("https://docs.google.com/spreadsheets/d/1bPZ7pNsR5rv-om-BypF4lK3nczjn4HJNO2dzimwnx7E/edit","PP Summary") -> PP Summary
A14: 301112 | B14: 1005 | C14: 57.6 | D14: =B14-C14 -> 947.4 | E14: 197 | F14: =IF(E14="","",B14-E14) -> 808 | G14: MFO Lot 301112 (LOT00301112), April 2026 | H14: =$L$16 -> 0.13141845 | I14: =H14*D14 -> 124.50584 | J14: =2.5*$L$4 -> 1.13398 | K14: 46054 | L14: 0.13304979 | M14: =HYPERLINK("https://docs.google.com/spreadsheets/d/1vH7bborVnc-TCby3wEkpzi7GGMOI5jMJooEW0V-rOQ4/edit","PP Summary") -> PP Summary
A15: 301114 | B15: 1027 | C15: 57.6 | D15: =B15-C15 -> 969.4 | E15: 195 | F15: =IF(E15="","",B15-E15) -> 832 | G15: MFO Lot 301114 (LOT00301114), April 2026 | H15: =$L$16 -> 0.13141845 | I15: =H15*D15 -> 127.39705 | J15: =2.5*$L$4 -> 1.13398 | K15: 46082 | L15: 0.11852515 | M15: =HYPERLINK("https://docs.google.com/spreadsheets/d/1O7y30opa_u1_deqFm_w2qgVyxi_75X00xnzKuyVyh6o/edit","PP Summary") -> PP Summary
A16: 301115 | B16: 1032 | C16: 57.6 | D16: =B16-C16 -> 974.4 | E16: 184 | F16: =IF(E16="","",B16-E16) -> 848 | G16: MFO Lot 301115 (LOT00301115), April 2026 | H16: =$L$16 -> 0.13141845 | I16: =H16*D16 -> 128.05414 | J16: =2.5*$L$4 -> 1.13398 | K16: 46113 | L16: 0.13141845 | M16: =HYPERLINK("https://docs.google.com/spreadsheets/d/10Qwx7K6sUcOBrCebGUGVaVeLQnhzvcT8sHQ0Sy3VBBM/edit","PP Summary") -> PP Summary
A17: 301121 | B17: 1027 | C17: 57.6 | D17: =B17-C17 -> 969.4 | E17: 174 | F17: =IF(E17="","",B17-E17) -> 853 | G17: MFO Lot 301121 (LOT00301121), April 2026 | H17: =$L$16 -> 0.13141845 | I17: =H17*D17 -> 127.39705 | J17: =2.5*$L$4 -> 1.13398 | K17: 46143 | L17: 0.11066158 | M17: =HYPERLINK("https://docs.google.com/spreadsheets/d/1m66t1jsLGc4e6AWnCFMsFbkSceZ9IYC_-bfTsbP_OYc/edit","PP Summary") -> PP Summary
A18: 301122 | B18: 996 | C18: 57.6 | D18: =B18-C18 -> 938.4 | E18: 205.5 | F18: =IF(E18="","",B18-E18) -> 790.5 | G18: MFO Lot 301122 (LOT00301122), April 2026 | H18: =$L$16 -> 0.13141845 | I18: =H18*D18 -> 123.32308 | J18: =2.5*$L$4 -> 1.13398 | K18: 46174 | L18: 0.12368967 | M18: =HYPERLINK("https://docs.google.com/spreadsheets/d/1MUQajDI2a_Cn9xWGPP7z4PhhphZnfl2_CSTnpB07Wgk/edit","PP Summary") -> PP Summary
A19: 301123 | B19: 1009 | C19: 57.6 | D19: =B19-C19 -> 951.4 | E19: 170.5 | F19: =IF(E19="","",B19-E19) -> 838.5 | G19: MFO Lot 301123 (LOT00301123), April 2026 | H19: =$L$16 -> 0.13141845 | I19: =H19*D19 -> 125.03152 | J19: =2.5*$L$4 -> 1.13398 | K19: July 2026 and later (Jan-Jun 2026 rolling) | L19: =$L$7 -> 0.120947
A20: 301126 | B20: 1043 | C20: 57.6 | D20: =B20-C20 -> 985.4 | E20: 145.5 | F20: =IF(E20="","",B20-E20) -> 897.5 | G20: MFO Lot 301126 (LOT00301126), April 2026 | H20: =$L$16 -> 0.13141845 | I20: =H20*D20 -> 129.49974 | J20: =2.5*$L$4 -> 1.13398 | K20: PP#7 | L20: 0.13736711 | M20: =HYPERLINK("https://docs.google.com/spreadsheets/d/1qPyS0H9Wx8z2vMl_3ANE1YLYahKLeL1Qo8OmZ_ol9aI/edit","PP Summary") -> PP Summary
A21: 301139 | B21: 1005 | C21: 57.6 | D21: =B21-C21 -> 947.4 | E21: 196 | F21: =IF(E21="","",B21-E21) -> 809 | G21: MFO Lot 301139 (LOT00301139), April 2026 | H21: =$L$16 -> 0.13141845 | I21: =H21*D21 -> 124.50584 | J21: =2.5*$L$4 -> 1.13398 | K21: =DATE(2025,9,1) -> 45901 | L21: 0.12868957 | M21: =HYPERLINK("https://docs.google.com/spreadsheets/d/1mojgzK0eWo2N7Lh4Xjc_mGHEtTdqNunHtR_a90ZNk7o/edit","PP Summary") -> PP Summary
A22: 301145 | B22: 1064 | C22: 57.6 | D22: =B22-C22 -> 1006.4 | E22: 164.5 | F22: =IF(E22="","",B22-E22) -> 899.5 | G22: MFO Lot 301145 (LOT00301145), April 2026 | H22: =$L$16 -> 0.13141845 | I22: =H22*D22 -> 132.25953 | J22: =2.5*$L$4 -> 1.13398
A23: 301150 | B23: 1035 | C23: 57.6 | D23: =B23-C23 -> 977.4 | E23: 172 | F23: =IF(E23="","",B23-E23) -> 863 | G23: MFO Lot 301150 (LOT00301150), April 2026 | H23: =$L$16 -> 0.13141845 | I23: =H23*D23 -> 128.4484 | J23: =2.5*$L$4 -> 1.13398
A24: 301154 | B24: 988 | C24: 57.6 | D24: =B24-C24 -> 930.4 | E24: 145 | F24: =IF(E24="","",B24-E24) -> 843 | G24: MFO Lot 301154 (LOT00301154), May 2026 | H24: =$L$17 -> 0.11066158 | I24: =H24*D24 -> 102.95953 | J24: =2.5*$L$4 -> 1.13398
A25: 301169 | B25: 1015 | C25: 57.6 | D25: =B25-C25 -> 957.4 | E25: 157 | F25: =IF(E25="","",B25-E25) -> 858 | G25: MFO Lot 301169 (LOT00301169), May 2026 | H25: =$L$17 -> 0.11066158 | I25: =H25*D25 -> 105.94739 | J25: =2.5*$L$4 -> 1.13398
A26: 301176 | B26: 996 | C26: 57.6 | D26: =B26-C26 -> 938.4 | E26: 194 | F26: =IF(E26="","",B26-E26) -> 802 | G26: MFO Lot 301176 (LOT00301176), April 2026 | H26: =$L$16 -> 0.13141845 | I26: =H26*D26 -> 123.32308 | J26: =2.5*$L$4 -> 1.13398
A27: 301179 | B27: 1029 | C27: 57.6 | D27: =B27-C27 -> 971.4 | E27: 185 | F27: =IF(E27="","",B27-E27) -> 844 | G27: MFO Lot 301179 (LOT00301179), April 2026 | H27: =$L$16 -> 0.13141845 | I27: =H27*D27 -> 127.65989 | J27: =2.5*$L$4 -> 1.13398
A28: 301198 | B28: 1035 | C28: 57.6 | D28: =B28-C28 -> 977.4 | E28: 177 | F28: =IF(E28="","",B28-E28) -> 858 | G28: MFO Lot 301198 (LOT00301198), April 2026 | H28: =$L$16 -> 0.13141845 | I28: =H28*D28 -> 128.4484 | J28: =2.5*$L$4 -> 1.13398
A29: 120509 | B29: 1019 | C29: 57.6 | D29: =B29-C29 -> 961.4 | E29: 169 | F29: =IF(E29="","",B29-E29) -> 850 | G29: MFO Lot 2830 (LOT00002830), July 2025 | H29: =$L$10 -> 0.15755534 | I29: =H29*D29 -> 151.4737 | J29: =2.5*$L$4 -> 1.13398
A30: 015178 | B30: 1049 | C30: 57.6 | D30: =B30-C30 -> 991.4 | E30: 202.5 | F30: =IF(E30="","",B30-E30) -> 846.5 | G30: MFO Lot 3131 (LOT00003131), July 2025 | H30: =$L$10 -> 0.15755534 | I30: =H30*D30 -> 156.20036 | J30: =2.5*$L$4 -> 1.13398
A31: 015152 | B31: 993 | C31: 57.6 | D31: =B31-C31 -> 935.4 | E31: 196 | F31: =IF(E31="","",B31-E31) -> 797 | G31: MFO Lot 3133 (LOT00003133), July 2025 | H31: =$L$10 -> 0.15755534 | I31: =H31*D31 -> 147.37726 | J31: =2.5*$L$4 -> 1.13398
A32: 120507 | B32: 1015 | C32: 57.6 | D32: =B32-C32 -> 957.4 | E32: 322 | F32: =IF(E32="","",B32-E32) -> 693 | G32: MFO Lot 3135 (LOT00003135), July 2025 | H32: =$L$10 -> 0.15755534 | I32: =H32*D32 -> 150.84348 | J32: =2.5*$L$4 -> 1.13398
A33: 015181 | B33: 960 | C33: 57.6 | D33: =B33-C33 -> 902.4 | E33: 163.5 | F33: =IF(E33="","",B33-E33) -> 796.5 | G33: MFO Lot 3137 (LOT00003137), July 2025 | H33: =$L$10 -> 0.15755534 | I33: =H33*D33 -> 142.17794 | J33: =2.5*$L$4 -> 1.13398
A34: 015185 | B34: 1055 | C34: 57.6 | D34: =B34-C34 -> 997.4 | E34: 168 | F34: =IF(E34="","",B34-E34) -> 887 | G34: MFO Lot 3163 (LOT00003163), July 2025 | H34: =$L$10 -> 0.15755534 | I34: =H34*D34 -> 157.1457 | J34: =2.5*$L$4 -> 1.13398
A35: 015176 | B35: 907 | C35: 57.6 | D35: =B35-C35 -> 849.4 | E35: 154 | F35: =IF(E35="","",B35-E35) -> 753 | G35: MFO Lot 3165 (LOT00003165), July 2025 | H35: =$L$10 -> 0.15755534 | I35: =H35*D35 -> 133.82751 | J35: =2.5*$L$4 -> 1.13398
A36: 015151 | B36: 943 | C36: 57.6 | D36: =B36-C36 -> 885.4 | E36: 178 | F36: =IF(E36="","",B36-E36) -> 765 | G36: MFO Lot 3243 (LOT00003243), July 2025 | H36: =$L$10 -> 0.15755534 | I36: =H36*D36 -> 139.4995 | J36: =2.5*$L$4 -> 1.13398
A37: 015175 | B37: 1006 | C37: 57.6 | D37: =B37-C37 -> 948.4 | E37: 169.5 | F37: =IF(E37="","",B37-E37) -> 836.5 | G37: MFO Lot 3247 (LOT00003247), July 2025 | H37: =$L$10 -> 0.15755534 | I37: =H37*D37 -> 149.42548 | J37: =2.5*$L$4 -> 1.13398
A38: 015164 | B38: 975 | C38: 57.6 | D38: =B38-C38 -> 917.4 | E38: 181 | F38: =IF(E38="","",B38-E38) -> 794 | G38: MFO Lot 3257 (LOT00003257), July 2025 | H38: =$L$10 -> 0.15755534 | I38: =H38*D38 -> 144.54127 | J38: =2.5*$L$4 -> 1.13398
A39: 015166 | B39: 1053 | C39: 57.6 | D39: =B39-C39 -> 995.4 | E39: 220 | F39: =IF(E39="","",B39-E39) -> 833 | G39: MFO Lot 3279 (LOT00003279), July 2025 | H39: =$L$10 -> 0.15755534 | I39: =H39*D39 -> 156.83058 | J39: =2.5*$L$4 -> 1.13398
A40: 015191 | B40: 1067 | C40: 57.6 | D40: =B40-C40 -> 1009.4 | E40: 187 | F40: =IF(E40="","",B40-E40) -> 880 | G40: MFO Lot 3292 (LOT00003292), July 2025 | H40: =$L$10 -> 0.15755534 | I40: =H40*D40 -> 159.03636 | J40: =2.5*$L$4 -> 1.13398
...

Sheet Whole Oil
A1: BATCH HEADER — Whole Oil (IBC Totes)
A2: Batch ID (INJ-YYYY-WXX) | B2: INJ-09-2026-W3 | K2: Constants
A3: Week Start (Sat) | B3: 46276 | K3: Lbs/Kg | L3: 2.20462
A4: Week End (Sat) | B4: 46283 | K4: Kg/Lbs | L4: 0.453592
K5: Sparging Mass Loss | L5: 0.0129
K6: pH range (target) | L6: 2.0 - 4.0
K7: WODO 6-Mo CI (kg CO2e/kg), Jul-Dec 2026 — BORROWED for Whole Oil (no DC Whole Oil CI yet) | L7: 0.795241
A8: SECTION 1 - IBC LEDGER (one row per IBC tote; tote tag mass is authoritative)
B9: Transport Emissions | D9: Pyrolysis Emissions Mass | F9: MOBI | K9: Per-Production-Month CI (kg CO2e/kg) - PP Summary Output Type table, col T
A10: Tag | B10: Gross Mass (kg) | C10: Tote Mass (kg) | D10: Net Oil Produced (kg) | E10: Empty Tote Weight (kg) | F10: Net Oil Injected (kg) | G10: Production Period | H10: Carbon Intensity | I10: Production Emissions | J10: Scale Uncertainty | K10: PP#8 | L10: 0.71282902 | M10: =HYPERLINK("https://docs.google.com/spreadsheets/d/1L167k_JS3mnisFy3VpS-OXgI8U0cK-4nC6A9sxl-ozk/edit","PP Summary") -> PP Summary
A11: 301352 | B11: 1473 | C11: 62.9 | D11: =B11-C11 -> 1410.1 | F11: =IF(E11="","",B11-E11) | G11: MFO Lot 301352 (LOT00301352), August 2026 | H11: =$L$19 -> 0.795241 | I11: =IF(H11="","",H11*D11) -> 1121.3693 | J11: =2.5*$L$4 -> 1.13398 | K11: November 2025 | L11: 0.97484085 | M11: =HYPERLINK("https://docs.google.com/spreadsheets/d/1W8jWu3sp39WnSuds1Ja0FWDG5UuWN9v5NUmF6yh_WbI/edit","PP Summary") -> PP Summary
A12: 301353 | B12: 1095 | C12: 57.6 | D12: =B12-C12 -> 1037.4 | F12: =IF(E12="","",B12-E12) | G12: MFO Lot 301353 (LOT00301353), August 2026 | H12: =$L$19 -> 0.795241 | I12: =IF(H12="","",H12*D12) -> 824.98301 | J12: =2.5*$L$4 -> 1.13398 | K12: December 2025 | L12: 0.97218282 | M12: =HYPERLINK("https://docs.google.com/spreadsheets/d/1-L6m2wYknC3o-yIts9KK7FrYAb5lZIv4AwaizK8FbMc/edit","PP Summary") -> PP Summary
A13: 301334 | B13: 1091 | C13: 57.6 | D13: =B13-C13 -> 1033.4 | F13: =IF(E13="","",B13-E13) | G13: MFO Lot 301334 (LOT00301334), August 2026 | H13: =$L$19 -> 0.795241 | I13: =IF(H13="","",H13*D13) -> 821.80205 | J13: =2.5*$L$4 -> 1.13398 | K13: January 2026 | L13: 0.93199449 | M13: =HYPERLINK("https://docs.google.com/spreadsheets/d/1bPZ7pNsR5rv-om-BypF4lK3nczjn4HJNO2dzimwnx7E/edit","PP Summary") -> PP Summary
A14: 301307 | B14: 1373 | C14: 62.9 | D14: =B14-C14 -> 1310.1 | F14: =IF(E14="","",B14-E14) | G14: MFO Lot 301307 (LOT00301307), August 2026 | H14: =$L$19 -> 0.795241 | I14: =IF(H14="","",H14*D14) -> 1041.8452 | J14: =2.5*$L$4 -> 1.13398 | K14: February 2026 | L14: 0.84989612 | M14: =HYPERLINK("https://docs.google.com/spreadsheets/d/1vH7bborVnc-TCby3wEkpzi7GGMOI5jMJooEW0V-rOQ4/edit","PP Summary") -> PP Summary
A15: 301328 | B15: 1102 | C15: 57.6 | D15: =B15-C15 -> 1044.4 | F15: =IF(E15="","",B15-E15) | G15: MFO Lot 301328 (LOT00301328), August 2026 | H15: =$L$19 -> 0.795241 | I15: =IF(H15="","",H15*D15) -> 830.5497 | J15: =2.5*$L$4 -> 1.13398 | K15: March 2026 | L15: 0.79006453 | M15: =HYPERLINK("https://docs.google.com/spreadsheets/d/1O7y30opa_u1_deqFm_w2qgVyxi_75X00xnzKuyVyh6o/edit","PP Summary") -> PP Summary
K16: April 2026 | L16: 0.78483234 | M16: =HYPERLINK("https://docs.google.com/spreadsheets/d/10Qwx7K6sUcOBrCebGUGVaVeLQnhzvcT8sHQ0Sy3VBBM/edit","PP Summary") -> PP Summary
K17: May 2026 | L17: 0.63284589 | M17: =HYPERLINK("https://docs.google.com/spreadsheets/d/1m66t1jsLGc4e6AWnCFMsFbkSceZ9IYC_-bfTsbP_OYc/edit","PP Summary") -> PP Summary
K18: June 2026 | L18: 1.1105356 | M18: =HYPERLINK("https://docs.google.com/spreadsheets/d/1MUQajDI2a_Cn9xWGPP7z4PhhphZnfl2_CSTnpB07Wgk/edit","PP Summary") -> PP Summary
K19: July 2026 and later (Jan-Jun 2026 rolling) | L19: =$L$7 -> 0.795241
A25: TOTAL | B25: =SUM(B11:B23) -> 6134 | C25: =SUM(C11:C23) -> 298.6 | D25: =SUM(D11:D23) -> 5835.4 | E25: =SUM(E11:E23) -> 0 | F25: =SUM(F11:F23) -> 0 | H25: =I25/D25 -> 0.795241 | I25: =SUM(I11:I23) -> 4640.5493 | J25: =SUM(J11:J23) -> 5.6699
A31: SECTION 2 - ROLLUP
A32: Transport Mass | B32: Σ Net Oil Produced (kg) | C32: Loss (kg) | D32: MOBI — Σ Net Oil Injected (kg)
A33: =B25 -> 6134 | B33: =SUM(D11:D23) -> 5835.4 | C33: =IF(D33=0,"",B33-D33) | D33: =SUM(F11:F23) -> 0

Sheet QOWV Shipments & EE Allocation
A1: INJ-09-2026-W3 - QOWV Shipments & EE Allocation
A4: BATCH SUMMARY
A5: Batch | B5: Fraction | C5: Inj. Week | D5: # Totes | E5: Shipping Orders (relevant to this batch)
A6: INJ-09-2026-W3 | B6: QOWV | C6: 2026-09-11 to 2026-09-18 | D6: =COUNTA(QOWV!A11:A48) -> 37 | E6: 4 shipping orders / trucks - see table A
A8: Charm CO -> Basco LA distance (one-way, mi) | B8: 1201 | C8: direct route
A10: EE ALLOCATION TABLE - A. DIRECT (Charm CO -> Basco LA)
A11: Truck (shipping order) | B11: Ship Date | C11: Total Totes on Truck | D11: Batch-Relevant Totes | E11: Batch Share of Truck | F11: Mileage (one-way) | G11: Allocated Miles
A12: Truck 1 (CO_AQUEOUS_12.01.25) | B12: 45992 | C12: 40 | D12: 9 | E12: =D12/C12 -> 0.225 | F12: =$B$8 -> 1201 | G12: =E12*F12 -> 270.225
A13: Truck 2 (CO_AQUEOUS_12.02.25) | B13: 45993 | C13: 36 | D13: 10 | E13: =D13/C13 -> 0.27777778 | F13: =$B$8 -> 1201 | G13: =E13*F13 -> 333.61111
A14: COLA-31 | B14: 46252 | C14: 20 | D14: 15 | E14: =D14/C14 -> 0.75 | F14: =$B$8 -> 1201 | G14: =E14*F14 -> 900.75
A15: COLA-32 | B15: 46254 | C15: 18 | D15: 3 | E15: =D15/C15 -> 0.16666667 | F15: =$B$8 -> 1201 | G15: =E15*F15 -> 200.16667
A17: TOTAL | C17: =SUM(C12:C15) -> 114 | D17: =SUM(D12:D15) -> 37 | G17: =SUM(G12:G15) -> 1704.7528
A58: --- Shipment 2025-12-10 --- (14 of 35 totes on this truck are W4-relevant)
A59: Metal Tag | B59: Fraction | C59: Production Period | D59: Date Loaded | E59: Batch
A60: 228427 | B60: QOWV | C60: October 2025 | D60: 46001 | E60: INJ-05-2026-W4
A61: 228408 | B61: QOWV | C61: September 2025 | D61: 46001 | E61: INJ-05-2026-W4
A62: 228465 | B62: QOWV | C62: October 2025 | D62: 46001 | E62: INJ-05-2026-W4
A63: 228496 | B63: QOWV | C63: October 2025 | D63: 46001 | E63: INJ-05-2026-W4
A64: 228431 | B64: QOWV | C64: October 2025 | D64: 46001 | E64: INJ-05-2026-W4
A65: 228455 | B65: QOWV | C65: October 2025 | D65: 46001 | E65: INJ-05-2026-W4
A66: 228458 | B66: QOWV | C66: October 2025 | D66: 46001 | E66: INJ-05-2026-W4
A67: 228422 | B67: QOWV | C67: October 2025 | D67: 46001 | E67: INJ-05-2026-W4
A68: 228466 | B68: QOWV | C68: October 2025 | D68: 46001 | E68: INJ-05-2026-W4
A69: 228462 | B69: QOWV | C69: October 2025 | D69: 46001 | E69: INJ-05-2026-W4
A70: 228494 | B70: QOWV | C70: October 2025 | D70: 46001 | E70: INJ-05-2026-W4
A71: 228438 | B71: QOWV | C71: October 2025 | D71: 46001 | E71: INJ-05-2026-W4
... A73: 228476 | B73: QOWV | C73: October 2025 | D73: 46001 | E73: INJ-05-2026-W4

Sheet WODO Shipments & EE Allocation
A1: INJ-09-2026-W2 - WODO Shipments & EE Mileage
A4: BATCH SUMMARY
A5: Batch | B5: Fraction | C5: Inj. Week | D5: # Totes | E5: Shipping Orders (relevant totes)
A6: INJ-09-2026-W2 | B6: WODO | C6: 2026-09-05 to 2026-09-12 | D6: =COUNTA(WODO!A11:A23) -> 0 | E6: 0 WODO totes this week - no shipping order to allocate
A8: Charm CO -> Basco LA distance (one-way mi) | B8: 1201
A10: EE ALLOCATION TABLE
A11: Truck (shipping order) | B11: Ship Date | C11: Total Totes on Truck | D11: Batch-Relevant Totes | E11: Batch Share of Truck | F11: Mileage (one-way) | G11: Allocated Miles
D12: =$D$6 -> 0 | E12: =IFERROR(D12/C12,"") | F12: =$B$8 -> 1201 | G12: =IFERROR(E12*F12,"") -> 0
A14: TOTAL | C14: =SUM(C12:C13) -> 0 | D14: =SUM(D12:D13) -> 0 | G14: =SUM(G12:G13) -> 0
A16: Check - every batch tote is allocated to a truck | B16: =IF($D$14=$D$6,"OK","MISMATCH") -> OK

Sheet Whole Oil Shipments & EE Alloca
A1: INJ-09-2026-W3 - Whole Oil Shipments & EE Mileage
A4: BATCH SUMMARY
A5: Batch | B5: Fraction | C5: Inj. Week | D5: # Totes | E5: Shipping Orders (relevant totes)
A6: INJ-09-2026-W3 | B6: Whole Oil | C6: 2026-09-11 to 2026-09-18 | D6: =COUNTA('Whole Oil'!A11:A23) -> 5 | E6: 1 shipping order(s) direct CO->LA: COLA_38 = 5 of 18 totes on the truck (12 DC Whole Oil + 6 BGN QOWV; the other 13 are not in this batch). Tier-1 resolution: Ship Status on Q4 2025-2026 Production Inventory Master.
A8: Charm CO -> Basco LA distance (one-way mi) | B8: 1201
A10: EE ALLOCATION TABLE
A11: Truck (shipping order) | B11: Ship Date | C11: Total Totes on Truck | D11: Batch-Relevant Totes | E11: Batch Share of Truck | F11: Mileage (one-way) | G11: Allocated Miles
A12: COLA_38 | B12: 46275 | C12: 18 | D12: =$D$6 -> 5 | E12: =IFERROR(D12/C12,"") -> 0.27777778 | F12: =$B$8 -> 1201 | G12: =IFERROR(E12*F12,"") -> 333.61111
A14: TOTAL | C14: =SUM(C12:C13) -> 18 | D14: =SUM(D12:D13) -> 5 | G14: =SUM(G12:G13) -> 333.61111
A16: Check - every batch tote is allocated to a truck | B16: =IF($D$14=$D$6,"OK","MISMATCH") -> OK
