Workbook

Sheet Summary
A1: BATCH SUMMARY
A2: Batch ID | B2: INJ-09-2026-W2
A3: Week Start (Sat) | B3: 46270
A4: Week End (Sat) | B4: 46277
A6: SECTION 1 - PER-TAB SUMMARY (each row pulls from its mode tab)
A7: Source Tab | B7: Σ Deliveries / Cargo (kg) | C7: Σ Uncertainty Adj (kg) | D7: Mass Used (kg) | E7: Sparging Loss (kg) | F7: Filtration Loss (kg) | G7: MOBI (kg) | H7: AECN→SOPOR EE (mi) | I7: Rail EE (mi) | J7: Opel→Basco EE (mi)
A8: AECN Rail | B8: ='AECN Rail'!A44 -> 155863.28 | C8: ='AECN Rail'!B44 -> 20.3096 | D8: ='AECN Rail'!C44 -> 155842.97 | E8: ='AECN Rail'!D44 -> 2010.3744 | F8: ='AECN Rail'!E44 -> 301.51189 | G8: ='AECN Rail'!F44 -> 153531.09 | H8: ='AECN Rail'!L36 -> 644.67407 | I8: ='AECN Rail'!M36 -> 8810.686 | J8: ='AECN Rail'!N36 -> 686.4
A9: AECN Truck | B9: ='AECN Truck'!A28 -> 58570 | C9: ='AECN Truck'!F28 -> 0 | D9: ='AECN Truck'!C28 -> 58570 | E9: ='AECN Truck'!D28 -> 755.553 | F9: ='AECN Truck'!E28 -> 113.31632 | G9: ='AECN Truck'!G28 -> 57701.131
A10: Charm WODO | B10: =WODO!A29 -> 0 | C10: =WODO!A29-WODO!B29 -> 0 | D10: =WODO!B29 -> 0 | E10: =WODO!C29 | F10: 0 | G10: =WODO!D29 -> 0
A11: Kerry | B11: =Kerry!A18 -> 18234.398 | C11: 0 | D11: =Kerry!A18 -> 18234.398 | E11: 0 | F11: =Kerry!B18 -> 12.946423 | G11: =Kerry!C18 -> 18221.452
A12: QOWV | B12: =QOWV!B50 -> 38830.4 | C12: 0 | D12: =QOWV!D50 -> 36641.6 | E12: 0 | F12: 0 | G12: =QOWV!F50 -> 31250.9
A13: TOTAL | B13: =SUM(B8:B12) -> 271498.08 | C13: =SUM(C8:C12) -> 20.3096 | D13: =SUM(D8:D12) -> 269288.97 | E13: =SUM(E8:E12) -> 2765.9274 | F13: =SUM(F8:F12) -> 427.77463 | G13: =SUM(G8:G12) -> 260704.57 | H13: =SUM(H8:H12) -> 644.67407 | I13: =SUM(I8:I12) -> 8810.686 | J13: =SUM(J8:J12) -> 686.4
A15: SECTION 2 - PER-OIL-TYPE ROLLUP (composite C% per oil type per week)
A16: Oil Type | B16: MOBI (kg) | C16: Composite Sample ID | D16: Date Composited | E16: C % | F16: Lab COA Link | G16: C Content Uncertainty | H16: Testing Uncertainty
A17: AECN | B17: =G8+G9 -> 211232.22 | C17: SR26-05494.002 | D17: 46277 | E17: 0.404 | F17: =HYPERLINK("https://drive.google.com/file/d/1E1uy1rtPtWOVK39JiIoe8RyE38Ob0NQo/view","COA SR26-05494.002") -> COA SR26-05494.002 | G17: =E17*H17 -> 0.001616 | H17: 0.004
A18: WODO | B18: =G10 -> 0
A19: Kerry | B19: =G11 -> 18221.452 | C19: SR26-05684.001 | D19: 46277 | E19: 0.625 | F19: =HYPERLINK("https://drive.google.com/file/d/11ORmEak4YjN6gnJSryd5lewLhjk1xHMC/view","COA SR26-05684.001") -> COA SR26-05684.001 | G19: =E19*H19 -> 0.0025 | H19: 0.004
A20: QOWV | B20: =G12 -> 31250.9 | C20: SR26-05494.001 | D20: 46270 | E20: 0.083 | F20: =HYPERLINK("https://drive.google.com/file/d/1E1uy1rtPtWOVK39JiIoe8RyE38Ob0NQo/view","COA SR26-05494.001") -> COA SR26-05494.001 | G20: =E20*H20 -> 0.000332 | H20: 0.004
A21: TOTAL | B21: =SUM(B17:B20) -> 260704.57

Sheet AECN Rail
A1: BATCH HEADER — AECN Rail
A2: Batch ID (INJ-YYYY-WXX) | B2: INJ-09-2026-W2 | N2: Constants
A3: Week Start (Sat) | B3: 46270 | N3: Lbs/Kg | O3: 2.20462
A4: Week End (Sat) | B4: 46277 | N4: Kg/Lbs | O4: 0.453592
N5: Sparging Mass Loss | O5: 0.0129
N6: pH range (target) | O6: 2.0 - 4.0
N7: Filtration Solids Content | O7: =HYPERLINK("https://docs.google.com/spreadsheets/d/1XhIwfVwGTl2T04CAlA-qee03gfqxNWwBmSCAeiSW548/edit?usp=sharing", 0.00196) -> 0.00196
A8: SECTION 1 - RAILCARS RECEIVED THIS WEEK (entity-level) | N8: BOL Trips (AECN→SOPOR) | O8: 3
A9: Railcar # | B9: Arrival Date at Opelousas | C9: Loading BOLs (comma-sep) | D9: Total Loaded (MT) | E9: Total Loaded (kg) | F9: Total Offloaded (kg, auto) | G9: Loss (kg) | H9: Previously Claimed (kg) | I9: Prior-RP Claimed (kg) | J9: AECN→SOPOR (mi) | K9: Rail (mi) | L9: Opel→Basco (mi) | M9: Notes | N9: Round Trip (Opel→Basco) | O9: 2 | P9: Full Railcar This Week? | Q9: Car Completes This Week?
A10: TIMX201060 | B10: 46234 | C10: 2450-R, 2451-R, 2452-R | D10: 78.14 | E10: 78140 | F10: =SUMIF($C$28:$C$41,A10,$F$28:$F$41)+H10 -> 77800.1 | G10: =IF(OR(E10="",F10=""),"",IF(Q10="Y",MAX(0,E10-F10),"")) -> 339.90016 | H10: 0 | I10: 0 | J10: 107.5 | K10: 2199 | L10: 42.9 | P10: =IF(OR($E10="",$F10=""),"",IF(AND($H10=0,$F10>=0.95*$E10),"FULL","PARTIAL")) -> FULL | Q10: Y
A11: SHPX215079 | B11: 46238 | C11: 2453-R, 2454-R, 2455-R | D11: 77.87 | E11: 77870 | F11: =SUMIF($C$28:$C$41,A11,$F$28:$F$41)+H11 -> 42410.852 | G11: =IF(OR(E11="",F11=""),"",IF(Q11="Y",MAX(0,E11-F11),"")) | H11: 0 | I11: 0 | J11: 107.5 | K11: 2199 | L11: 42.9 | P11: =IF(OR($E11="",$F11=""),"",IF(AND($H11=0,$F11>=0.95*$E11),"FULL","PARTIAL")) -> PARTIAL | Q11: N
A12: SHPX215046 | B12: 46241 | C12: 2462-R, 2463-R, 2464-R | D12: 77.68 | E12: 77680 | F12: =SUMIF($C$28:$C$41,A12,$F$28:$F$41)+H12 -> 35652.331 | G12: =IF(OR(E12="",F12=""),"",IF(Q12="Y",MAX(0,E12-F12),"")) | H12: 0 | I12: 0 | J12: 107.5 | K12: 2199 | L12: 42.9 | P12: =IF(OR($E12="",$F12=""),"",IF(AND($H12=0,$F12>=0.95*$E12),"FULL","PARTIAL")) -> PARTIAL | Q12: N
G13: =IF(AND(E13<>"",F13<>"",F13>=0.95*E13),E13-F13,"") | P13: =IF(OR($E13="",$F13=""),"",IF(AND($H13=0,$F13>=0.95*$E13),"FULL","PARTIAL"))
G14: =IF(AND(E14<>"",F14<>"",F14>=0.95*E14),E14-F14,"") | P14: =IF(OR($E14="",$F14=""),"",IF(AND($H14=0,$F14>=0.95*$E14),"FULL","PARTIAL"))
A15: SECTION 2 - ORIGINS LEDGER (loading BOLs at SOPOR)
A16: Date | B16: BOL # | C16: Railcar # | D16: BOL Mass (MT) | E16: BOL Mass (kg)
A17: 46232 | B17: =HYPERLINK("https://drive.google.com/file/d/1ZuURgQe3U1js-r_7RIKM4d-Jr6-F3zSs/view","2450-R") -> 2450-R | C17: TIMX201060 | D17: 26.06 | E17: 26060
A18: 46232 | B18: =HYPERLINK("https://drive.google.com/file/d/1k0djKC95Um_AqEAfJcyq2WU9rV9x6Eec/view","2451-R") -> 2451-R | C18: TIMX201060 | D18: 26.02 | E18: 26020
A19: 46233 | B19: =HYPERLINK("https://drive.google.com/file/d/1mVN2I6OeEMIGpFBE9wpZJC3yF2INqi7H/view","2452-R") -> 2452-R | C19: TIMX201060 | D19: 26.06 | E19: 26060
A20: 46233 | B20: =HYPERLINK("https://drive.google.com/file/d/1uf-uIbIK-w263t44Z7hPxz4V6TcOwkuj/view","2453-R") -> 2453-R | C20: SHPX215079 | D20: 25.99 | E20: 25990
A21: 46237 | B21: =HYPERLINK("https://drive.google.com/file/d/19tEV6CHDlw4IHdGf0eTcvgchBT5619z2/view","2454-R") -> 2454-R | C21: SHPX215079 | D21: 25.91 | E21: 25910
A22: 46237 | B22: =HYPERLINK("https://drive.google.com/file/d/1Ew57sSdaj0k_89WfzfXFYvHmdga4A3Yt/view","2455-R") -> 2455-R | C22: SHPX215079 | D22: 25.97 | E22: 25970
A23: 46239 | B23: =HYPERLINK("https://drive.google.com/file/d/1dCSXmu7dtsVXb1lm03NoB703GWhQ4SoL/view","2462-R") -> 2462-R | C23: SHPX215046 | D23: 25.94 | E23: 25940
A24: 46240 | B24: =HYPERLINK("https://drive.google.com/file/d/1dnRbhH5-6l1akkr2TOene6LVg_vIcbqy/view","2463-R") -> 2463-R | C24: SHPX215046 | D24: 25.9 | E24: 25900
A25: 46240 | B25: =HYPERLINK("https://drive.google.com/file/d/1K229IOTPDOAGAckmNGMoLtQr9BUJo-tu/view","2464-R") -> 2464-R | C25: SHPX215046 | D25: 25.84 | E25: 25840
A26: SECTION 3 - SCALE TICKTS + OFFLOAD WEIGHTS
D27: Full Scale Ticket (lb) | E27: Empty Scale Ticket (lb) | F27: Net Scaled Mass (kg) | G27: pH | H27: Sparging Loss (kg) | I27: Filtration Loss (kg) | J27: Uncertainty Adjustment (kg) | K27: MOBI (kg) | L27: AECN→SOPOR (mi, allocated ×3) | M27: Rail (mi, allocated) | N27: Opel→Basco (mi, full ×2) | O27: C Content
A28: 46276 | B28: Rail_SHPX215046_8.7.2026_offload_3 | C28: SHPX215046 | D28: =HYPERLINK("https://drive.google.com/file/d/1GisAZh42UfUeqGGvXLAVvExtnXfKTUs8/view",74320) -> 74320 | E28: =HYPERLINK("https://drive.google.com/file/d/1VZTOOgPaWtrG_CFLtozthC_v89fI-t5c/view",28440) -> 28440 | F28: =IF(OR(D28="",E28=""),"",(D28-E28)*$O$4) -> 20810.801 | G28: =$G$44 -> 2.92 | H28: =IF(F28="","",(F28-J28)*$O$5) -> 268.45933 | I28: =IF(F28="","",(F28-J28)*(1-$O$5)*$O$7) -> 40.26299 | J28: {=IF(F28="","",IF(ROW()=MAX(IF($C$28:$C$35=C28,ROW($C$28:$C$35),0)),MAX(0,IFERROR(VLOOKUP(C28,$A$10:$L$14,6,FALSE)-VLOOKUP(C28,$A$10:$L$14,5,FALSE),0)),0))} -> 0 | K28: =IF(F28="","",F28-H28-I28-J28) -> 20502.079 | L28: =IF(F28="","",(F28-J28)/VLOOKUP(C28,$A$10:$L$14,5,FALSE)*VLOOKUP(C28,$A$10:$L$14,10,FALSE)*$O$8) -> 86.399116 | M28: {=IF(F28="","",2*(IF(IFERROR(VLOOKUP(C28,$A$10:$P$14,16,FALSE),"")="FULL",IF(ROW()=MIN(IF($C$28:$C$35=C28,ROW($C$28:$C$35),10^9)),VLOOKUP(C28,$A$10:$P$14,11,FALSE),0),(F28-J28)/VLOOKUP(C28,$A$10:$P$14,5,FALSE)*VLOOKUP(C28,$A$10:$P$14,11,FALSE))))} -> 1178.2428 | N28: =IF(F28="","",IFERROR(VLOOKUP(C28,$A$10:$L$14,12,FALSE),0)*$O$9) -> 85.8
A29: 46276 | B29: Rail_SHPX215046_8.7.2026_offload_4 | C29: SHPX215046 | D29: =HYPERLINK("https://drive.google.com/file/d/1Ey8e0SGZWEeLyB3tSyfzmlK_x0MvYBgN/view",61980) -> 61980 | E29: =HYPERLINK("https://drive.google.com/file/d/1mx7n-RIuGDT5LdH69PYAfmmYKxB144P_/view",29260) -> 29260 | F29: =IF(OR(D29="",E29=""),"",(D29-E29)*$O$4) -> 14841.53 | G29: =$G$44 -> 2.92 | H29: =IF(F29="","",(F29-J29)*$O$5) -> 191.19375 | I29: =IF(F29="","",(F29-J29)*(1-$O$5)*$O$7) -> 28.674853 | J29: =IF(F29="","",MAX(0,SUMIF($C$28:$C$35,C29,$F$28:$F$35)+(21055.74064+20992.23776)-VLOOKUP(C29,$A$10:$L$14,5,FALSE))) -> 20.3096 | K29: =IF(F29="","",F29-H29-I29-J29) -> 14601.352 | L29: =IF(F29="","",(F29-J29)/VLOOKUP(C29,$A$10:$L$14,5,FALSE)*VLOOKUP(C29,$A$10:$L$14,10,FALSE)*$O$8) -> 61.532488 | M29: {=IF(F29="","",2*(IF(IFERROR(VLOOKUP(C29,$A$10:$P$14,16,FALSE),"")="FULL",IF(ROW()=MIN(IF($C$28:$C$35=C29,ROW($C$28:$C$35),10^9)),VLOOKUP(C29,$A$10:$P$14,11,FALSE),0),(F29-J29)/VLOOKUP(C29,$A$10:$P$14,5,FALSE)*VLOOKUP(C29,$A$10:$P$14,11,FALSE))))} -> 839.13142 | N29: =IF(F29="","",IFERROR(VLOOKUP(C29,$A$10:$L$14,12,FALSE),0)*$O$9) -> 85.8
A30: 46276 | B30: Rail_SHPX215079_8.4.2026_offload_1 | C30: SHPX215079 | D30: =HYPERLINK("https://drive.google.com/file/d/1XqCArIC7PnSrQ6kqwkAhpxNbBI05eBPP/view",76720) -> 76720 | E30: =HYPERLINK("https://drive.google.com/file/d/11t6R_4Gs-duPIqzwEQIX2N55hmOsPrGD/view",28660) -> 28660 | F30: =IF(OR(D30="",E30=""),"",(D30-E30)*$O$4) -> 21799.632 | G30: =$G$44 -> 2.92 | H30: =IF(F30="","",(F30-J30)*$O$5) -> 281.21525 | I30: =IF(F30="","",(F30-J30)*(1-$O$5)*$O$7) -> 42.176096 | J30: {=IF(F30="","",IF(ROW()=MAX(IF($C$28:$C$35=C30,ROW($C$28:$C$35),0)),MAX(0,IFERROR(VLOOKUP(C30,$A$10:$L$14,6,FALSE)-VLOOKUP(C30,$A$10:$L$14,5,FALSE),0)),0))} -> 0 | K30: =IF(F30="","",F30-H30-I30-J30) -> 21476.24 | L30: =IF(F30="","",(F30-J30)/VLOOKUP(C30,$A$10:$L$14,5,FALSE)*VLOOKUP(C30,$A$10:$L$14,10,FALSE)*$O$8) -> 90.283564 | M30: {=IF(F30="","",2*(IF(IFERROR(VLOOKUP(C30,$A$10:$P$14,16,FALSE),"")="FULL",IF(ROW()=MIN(IF($C$28:$C$35=C30,ROW($C$28:$C$35),10^9)),VLOOKUP(C30,$A$10:$P$14,11,FALSE),0),(F30-J30)/VLOOKUP(C30,$A$10:$P$14,5,FALSE)*VLOOKUP(C30,$A$10:$P$14,11,FALSE))))} -> 1231.2159 | N30: =IF(F30="","",IFERROR(VLOOKUP(C30,$A$10:$L$14,12,FALSE),0)*$O$9) -> 85.8
A31: 46276 | B31: Rail_SHPX215079_8.4.2026_offload_2 | C31: SHPX215079 | D31: =HYPERLINK("https://drive.google.com/file/d/1KFfyPOYLciZ2vsYZMviViwIHQM2cyEoP/view",73860) -> 73860 | E31: =HYPERLINK("https://drive.google.com/file/d/12MMZsVKKYdE0J4hgJTknIIsqHMAA9nQe/view",28420) -> 28420 | F31: =IF(OR(D31="",E31=""),"",(D31-E31)*$O$4) -> 20611.22 | G31: =$G$44 -> 2.92 | H31: =IF(F31="","",(F31-J31)*$O$5) -> 265.88474 | I31: =IF(F31="","",(F31-J31)*(1-$O$5)*$O$7) -> 39.876858 | J31: {=IF(F31="","",IF(ROW()=MAX(IF($C$28:$C$35=C31,ROW($C$28:$C$35),0)),MAX(0,IFERROR(VLOOKUP(C31,$A$10:$L$14,6,FALSE)-VLOOKUP(C31,$A$10:$L$14,5,FALSE),0)),0))} -> 0 | K31: =IF(F31="","",F31-H31-I31-J31) -> 20305.459 | L31: =IF(F31="","",(F31-J31)/VLOOKUP(C31,$A$10:$L$14,5,FALSE)*VLOOKUP(C31,$A$10:$L$14,10,FALSE)*$O$8) -> 85.361739 | M31: {=IF(F31="","",2*(IF(IFERROR(VLOOKUP(C31,$A$10:$P$14,16,FALSE),"")="FULL",IF(ROW()=MIN(IF($C$28:$C$35=C31,ROW($C$28:$C$35),10^9)),VLOOKUP(C31,$A$10:$P$14,11,FALSE),0),(F31-J31)/VLOOKUP(C31,$A$10:$P$14,5,FALSE)*VLOOKUP(C31,$A$10:$P$14,11,FALSE))))} -> 1164.0959 | N31: =IF(F31="","",IFERROR(VLOOKUP(C31,$A$10:$L$14,12,FALSE),0)*$O$9) -> 85.8
A32: 46276 | B32: Rail_TIMX201060_7.31.2026_offload_1 | C32: TIMX201060 | D32: =HYPERLINK("https://drive.google.com/file/d/1iih6baWdgvbgqhjYWEaIk9LdrDGBeRby/view",85100) -> 85100 | E32: =HYPERLINK("https://drive.google.com/file/d/181-3ASFhsekj8JYrjpVem8DW4rNxVpdA/view",29480) -> 29480 | F32: =IF(OR(D32="",E32=""),"",(D32-E32)*$O$4) -> 25228.787 | G32: =$G$44 -> 2.92 | H32: =IF(F32="","",(F32-J32)*$O$5) -> 325.45135 | I32: =IF(F32="","",(F32-J32)*(1-$O$5)*$O$7) -> 48.810538 | J32: {=IF(F32="","",IF(ROW()=MAX(IF($C$28:$C$35=C32,ROW($C$28:$C$35),0)),MAX(0,IFERROR(VLOOKUP(C32,$A$10:$L$14,6,FALSE)-VLOOKUP(C32,$A$10:$L$14,5,FALSE),0)),0))} -> 0 | K32: =IF(F32="","",F32-H32-I32-J32) -> 24854.525 | L32: =IF(F32="","",(F32-J32)/VLOOKUP(C32,$A$10:$L$14,5,FALSE)*VLOOKUP(C32,$A$10:$L$14,10,FALSE)*$O$8) -> 104.12444 | M32: {=IF(F32="","",2*(IF(IFERROR(VLOOKUP(C32,$A$10:$P$14,16,FALSE),"")="FULL",IF(ROW()=MIN(IF($C$28:$C$35=C32,ROW($C$28:$C$35),10^9)),VLOOKUP(C32,$A$10:$P$14,11,FALSE),0),(F32-J32)/VLOOKUP(C32,$A$10:$P$14,5,FALSE)*VLOOKUP(C32,$A$10:$P$14,11,FALSE))))} -> 4398 | N32: =IF(F32="","",IFERROR(VLOOKUP(C32,$A$10:$L$14,12,FALSE),0)*$O$9) -> 85.8
A33: 46276 | B33: Rail_TIMX201060_7.31.2026_offload_2 | C33: TIMX201060 | D33: =HYPERLINK("https://drive.google.com/file/d/1N6jMP4naYICOYrPGkqYaYnqq5FhKiVZU/view", 74420) -> 74420 | E33: =HYPERLINK("https://drive.google.com/file/d/1JhVupVG7-OHlIpAUWpjOVhSzUavcEYjL/view", 28760) -> 28760 | F33: =IF(OR(D33="",E33=""),"",(D33-E33)*$O$4) -> 20711.011 | G33: =$G$44 -> 2.92 | H33: =IF(F33="","",(F33-J33)*$O$5) -> 267.17204 | I33: =IF(F33="","",(F33-J33)*(1-$O$5)*$O$7) -> 40.069924 | J33: {=IF(F33="","",IF(ROW()=MAX(IF($C$28:$C$35=C33,ROW($C$28:$C$35),0)),MAX(0,IFERROR(VLOOKUP(C33,$A$10:$L$14,6,FALSE)-VLOOKUP(C33,$A$10:$L$14,5,FALSE),0)),0))} -> 0 | K33: =IF(F33="","",F33-H33-I33-J33) -> 20403.769 | L33: =IF(F33="","",(F33-J33)/VLOOKUP(C33,$A$10:$L$14,5,FALSE)*VLOOKUP(C33,$A$10:$L$14,10,FALSE)*$O$8) -> 85.47864 | M33: {=IF(F33="","",2*(IF(IFERROR(VLOOKUP(C33,$A$10:$P$14,16,FALSE),"")="FULL",IF(ROW()=MIN(IF($C$28:$C$35=C33,ROW($C$28:$C$35),10^9)),VLOOKUP(C33,$A$10:$P$14,11,FALSE),0),(F33-J33)/VLOOKUP(C33,$A$10:$P$14,5,FALSE)*VLOOKUP(C33,$A$10:$P$14,11,FALSE))))} -> 0 | N33: =IF(F33="","",IFERROR(VLOOKUP(C33,$A$10:$L$14,12,FALSE),0)*$O$9) -> 85.8
A34: 46276 | B34: Rail_TIMX201060_7.31.2026_offload_3 | C34: TIMX201060 | D34: =HYPERLINK("https://drive.google.com/file/d/15-txlOW4h4ZFEpOyYV_6TWeYMiEedZMX/view",73220) -> 73220 | E34: =HYPERLINK("https://drive.google.com/file/d/1s_Mn6t0K6XdPCX1WaNgq9YzQ2nyLyS9_/view",29860) -> 29860 | F34: =IF(OR(D34="",E34=""),"",(D34-E34)*$O$4) -> 19667.749 | G34: =$G$44 -> 2.92 | H34: =IF(F34="","",(F34-J34)*$O$5) -> 253.71396 | I34: =IF(F34="","",(F34-J34)*(1-$O$5)*$O$7) -> 38.051509 | J34: {=IF(F34="","",IF(ROW()=MAX(IF($C$28:$C$35=C34,ROW($C$28:$C$35),0)),MAX(0,IFERROR(VLOOKUP(C34,$A$10:$L$14,6,FALSE)-VLOOKUP(C34,$A$10:$L$14,5,FALSE),0)),0))} -> 0 | K34: =IF(F34="","",F34-H34-I34-J34) -> 19375.984 | L34: =IF(F34="","",(F34-J34)/VLOOKUP(C34,$A$10:$L$14,5,FALSE)*VLOOKUP(C34,$A$10:$L$14,10,FALSE)*$O$8) -> 81.172883 | M34: {=IF(F34="","",2*(IF(IFERROR(VLOOKUP(C34,$A$10:$P$14,16,FALSE),"")="FULL",IF(ROW()=MIN(IF($C$28:$C$35=C34,ROW($C$28:$C$35),10^9)),VLOOKUP(C34,$A$10:$P$14,11,FALSE),0),(F34-J34)/VLOOKUP(C34,$A$10:$P$14,5,FALSE)*VLOOKUP(C34,$A$10:$P$14,11,FALSE))))} -> 0 | N34: =IF(F34="","",IFERROR(VLOOKUP(C34,$A$10:$L$14,12,FALSE),0)*$O$9) -> 85.8
A35: 46276 | B35: Rail_TIMX201060_7.31.2026_offload_4 | C35: TIMX201060 | D35: =HYPERLINK("https://drive.google.com/file/d/10Rb7609pMhTK_nP5ptKDTzeOGvKrXlES/view",55660) -> 55660 | E35: =HYPERLINK("https://drive.google.com/file/d/1871HmRK7JHwcDzpA8J71aKcgWjWogfG7/view",28780) -> 28780 | F35: =IF(OR(D35="",E35=""),"",(D35-E35)*$O$4) -> 12192.553 | G35: =$G$44 -> 2.92 | H35: =IF(F35="","",(F35-J35)*$O$5) -> 157.28393 | I35: =IF(F35="","",(F35-J35)*(1-$O$5)*$O$7) -> 23.589127 | J35: {=IF(F35="","",IF(ROW()=MAX(IF($C$28:$C$35=C35,ROW($C$28:$C$35),0)),MAX(0,IFERROR(VLOOKUP(C35,$A$10:$L$14,6,FALSE)-VLOOKUP(C35,$A$10:$L$14,5,FALSE),0)),0))} -> 0 | K35: =IF(F35="","",F35-H35-I35-J35) -> 12011.68 | L35: =IF(F35="","",(F35-J35)/VLOOKUP(C35,$A$10:$L$14,5,FALSE)*VLOOKUP(C35,$A$10:$L$14,10,FALSE)*$O$8) -> 50.321197 | M35: {=IF(F35="","",2*(IF(IFERROR(VLOOKUP(C35,$A$10:$P$14,16,FALSE),"")="FULL",IF(ROW()=MIN(IF($C$28:$C$35=C35,ROW($C$28:$C$35),10^9)),VLOOKUP(C35,$A$10:$P$14,11,FALSE),0),(F35-J35)/VLOOKUP(C35,$A$10:$P$14,5,FALSE)*VLOOKUP(C35,$A$10:$P$14,11,FALSE))))} -> 0 | N35: =IF(F35="","",IFERROR(VLOOKUP(C35,$A$10:$L$14,12,FALSE),0)*$O$9) -> 85.8
L36: =SUM(L28:L35) -> 644.67407 | M36: =SUM(M28:M35) -> 8810.686 | N36: =SUM(N28:N35) -> 686.4
L37: =IF(F37="","",(F37-J37)/VLOOKUP(C37,$A$10:$L$14,5,FALSE)*VLOOKUP(C37,$A$10:$L$14,10,FALSE)*$O$8) | M37: =IF(F37="","",(F37-J37)/VLOOKUP(C37,$A$10:$L$14,5,FALSE)*VLOOKUP(C37,$A$10:$L$14,11,FALSE)) | N37: =IF(F37="","",IFERROR(VLOOKUP(C37,$A$10:$L$14,12,FALSE),0)*$O$9)
L38: =IF(F38="","",(F38-J38)/VLOOKUP(C38,$A$10:$L$14,5,FALSE)*VLOOKUP(C38,$A$10:$L$14,10,FALSE)*$O$8) | M38: =IF(F38="","",(F38-J38)/VLOOKUP(C38,$A$10:$L$14,5,FALSE)*VLOOKUP(C38,$A$10:$L$14,11,FALSE)) | N38: =IF(F38="","",IFERROR(VLOOKUP(C38,$A$10:$L$14,12,FALSE),0)*$O$9)
L39: =IF(F39="","",(F39-J39)/VLOOKUP(C39,$A$10:$L$14,5,FALSE)*VLOOKUP(C39,$A$10:$L$14,10,FALSE)*$O$8) | M39: =IF(F39="","",(F39-J39)/VLOOKUP(C39,$A$10:$L$14,5,FALSE)*VLOOKUP(C39,$A$10:$L$14,11,FALSE)) | N39: =IF(F39="","",IFERROR(VLOOKUP(C39,$A$10:$L$14,12,FALSE),0)*$O$9)
L40: =IF(F40="","",(F40-J40)/VLOOKUP(C40,$A$10:$L$14,5,FALSE)*VLOOKUP(C40,$A$10:$L$14,10,FALSE)*$O$8) | M40: =IF(F40="","",(F40-J40)/VLOOKUP(C40,$A$10:$L$14,5,FALSE)*VLOOKUP(C40,$A$10:$L$14,11,FALSE)) | N40: =IF(F40="","",IFERROR(VLOOKUP(C40,$A$10:$L$14,12,FALSE),0)*$O$9)
...

Sheet AECN Truck
A1: BATCH HEADER — AECN Truck (Direct from Fort Lupton)
A2: Batch ID (INJ-YYYY-WXX) | B2: INJ-09-2026-W2 | K2: Constants
A3: Week Start (Sat) | B3: 46270 | K3: Lbs/Kg | L3: 2.20462
A4: Week End (Sat) | B4: 46277 | K4: Kg/Lbs | L4: 0.453592
K5: Sparging Mass Loss | L5: 0.0129
K6: pH range (target) | L6: 2.0 - 4.0
K7: Filtration Solids Content | L7: 0.00196
A8: SECTION 1 - DELIVERIES LEDGER (one row per direct truck; BOL & scale ticket on same row)
A9: Date | B9: BOL # / SO # | C9: BOL Mass (MT) | D9: BOL Mass (kg) | E9: Scale Full (lb) | F9: Scale Empty (lb) | G9: Cargo (kg) | H9: pH | I9: Notes | J9: Sparging Loss (kg) | K9: Filtration Loss (kg) | L9: MOBI (kg) | M9: C Content | N9: EE Miles
A10: 46265 | B10: =HYPERLINK("https://drive.google.com/file/d/1e95euZUq0c64g0eo7Ehk8faLJSn-233w/view","2499-T") -> 2499-T | C10: 19.71 | D10: =IF(C10="","",C10*1000) -> 19710 | H10: =$H$28 -> 2.92 | J10: =IF(D10="","",D10*$L$5) -> 254.259 | K10: =IF(D10="","",(D10-J10)*$L$7) -> 38.133252 | L10: =IF(D10="","",D10-J10-K10) -> 19417.608 | N10: 2197
A11: 46266 | B11: =HYPERLINK("https://drive.google.com/file/d/1CG0ivzPlRELU1eR3benSKenshvwQrFZB/view","2503-T") -> 2503-T | C11: 19.19 | D11: =IF(C11="","",C11*1000) -> 19190 | H11: =$H$28 -> 2.92 | J11: =IF(D11="","",D11*$L$5) -> 247.551 | K11: =IF(D11="","",(D11-J11)*$L$7) -> 37.1272 | L11: =IF(D11="","",D11-J11-K11) -> 18905.322 | N11: 2197
A12: 46267 | B12: =HYPERLINK("https://drive.google.com/file/d/1XywE-kIo12ZeU7rw1v8BHbJk3CVE_o6E/view","2505-T") -> 2505-T | C12: 19.67 | D12: =IF(C12="","",C12*1000) -> 19670 | H12: =$H$28 -> 2.92 | J12: =IF(D12="","",D12*$L$5) -> 253.743 | K12: =IF(D12="","",(D12-J12)*$L$7) -> 38.055864 | L12: =IF(D12="","",D12-J12-K12) -> 19378.201 | N12: 2197
J13: =IF(D13="","",D13*$L$5) | K13: =IF(D13="","",(D13-J13)*$L$7) | L13: =IF(D13="","",D13-J13-K13)
J14: =IF(D14="","",D14*$L$5) | K14: =IF(D14="","",(D14-J14)*$L$7) | L14: =IF(D14="","",D14-J14-K14)
J15: =IF(D15="","",D15*$L$5) | K15: =IF(D15="","",(D15-J15)*$L$7) | L15: =IF(D15="","",D15-J15-K15)
J16: =IF(D16="","",D16*$L$5) | K16: =IF(D16="","",(D16-J16)*$L$7) | L16: =IF(D16="","",D16-J16-K16)
J17: =IF(D17="","",D17*$L$5) | K17: =IF(D17="","",(D17-J17)*$L$7) | L17: =IF(D17="","",D17-J17-K17)
J18: =IF(D18="","",D18*$L$5) | K18: =IF(D18="","",(D18-J18)*$L$7) | L18: =IF(D18="","",D18-J18-K18)
J19: =IF(D19="","",D19*$L$5) | K19: =IF(D19="","",(D19-J19)*$L$7) | L19: =IF(D19="","",D19-J19-K19)
J20: =IF(D20="","",D20*$L$5) | K20: =IF(D20="","",(D20-J20)*$L$7) | L20: =IF(D20="","",D20-J20-K20)
J21: =IF(D21="","",D21*$L$5) | K21: =IF(D21="","",(D21-J21)*$L$7) | L21: =IF(D21="","",D21-J21-K21)
J22: =IF(D22="","",D22*$L$5) | K22: =IF(D22="","",(D22-J22)*$L$7) | L22: =IF(D22="","",D22-J22-K22)
J23: =IF(D23="","",D23*$L$5) | K23: =IF(D23="","",(D23-J23)*$L$7) | L23: =IF(D23="","",D23-J23-K23)
J24: =IF(D24="","",D24*$L$5) | K24: =IF(D24="","",(D24-J24)*$L$7) | L24: =IF(D24="","",D24-J24-K24)
N25: =sum(N10:N23) -> 6591
A26: SECTION 2 - ROLLUP (Mass Used = Σ BOL kg; scale tickets no longer required for direct trucks per 2026-05-26)
A27: Σ BOL (kg) | B27: Σ Cargo (kg) | C27: Mass Used (kg) | D27: Sparging Loss (kg) | E27: Filtration Loss (kg) | F27: Uncertainty Adjustment (kg) | G27: MOBI (kg) | H27: pH | I27: C Content | K27: Origins list (BOLs)
A28: =SUMIFS(D10:D24,B10:B24,"<>") -> 58570 | B28: =SUMIFS(G10:G24,B10:B24,"<>") -> 0 | C28: =A28 -> 58570 | D28: =C28*$L$5 -> 755.553 | E28: =(C28-D28)*$L$7 -> 113.31632 | F28: 0 | G28: =C28-D28-E28-F28 -> 57701.131 | H28: 2.92 | K28: =IFERROR(__xludf.DUMMYFUNCTION("TRIM(TEXTJOIN("", "",TRUE,IFERROR(FILTER(B10:B24,B10:B24<>""""),"""")))"),"2499-T, 2503-T, 2505-T") -> 2499-T, 2503-T, 2505-T

Sheet WODO
A1: BATCH HEADER — Charm WODO (IBC Totes)
A2: Batch ID (INJ-YYYY-WXX) | B2: INJ-09-2026-W2 | K2: Constants
A3: Week Start (Sat) | B3: 46270 | K3: Lbs/Kg | L3: 2.20462
A4: Week End (Sat) | B4: 46277 | K4: Kg/Lbs | L4: 0.453592
K5: Sparging Mass Loss | L5: 0.0129
K6: pH range (target) | L6: 2.0 - 4.0
K7: WODO 6-Mo CI (kg CO2e/kg), Jul-Dec 2026 | L7: 0.795241
A8: SECTION 1 - IBC LEDGER (one row per IBC tote; tote tag mass is authoritative) | K8: WODO Standard Loss (kg/tote), 2026 = Mean + 1 SD | L8: 7.84 | M8: =HYPERLINK("https://docs.google.com/spreadsheets/d/15fnYOYMmu-7a-p8Alst6mAOsV7X854y6HBDYwQRUm5s/edit","Tote Loss Dataset") -> Tote Loss Dataset
B9: Transport Emissions | D9: Pyrolysis Emissions Mass & Standard Loss | F9: MOBI | K9: Per-Production-Month CI (kg CO2e/kg) - PP Summary Output Type table, col T
A10: Tag | B10: Gross Mass (kg) | C10: Tote Mass (kg) | D10: Net Oil Produced (kg) | E10: Standard Loss (kg) | F10: Net Oil Injected (kg) | G10: Production Period | H10: Carbon Intensity | I10: Production Emissions | J10: Scale Uncertainty | K10: PP#8 | L10: 0.71282902 | M10: =HYPERLINK("https://docs.google.com/spreadsheets/d/1L167k_JS3mnisFy3VpS-OXgI8U0cK-4nC6A9sxl-ozk/edit","PP Summary") -> PP Summary
K11: November 2025 | L11: 0.97484085 | M11: =HYPERLINK("https://docs.google.com/spreadsheets/d/1W8jWu3sp39WnSuds1Ja0FWDG5UuWN9v5NUmF6yh_WbI/edit","PP Summary") -> PP Summary
K12: December 2025 | L12: 0.97218282 | M12: =HYPERLINK("https://docs.google.com/spreadsheets/d/1-L6m2wYknC3o-yIts9KK7FrYAb5lZIv4AwaizK8FbMc/edit","PP Summary") -> PP Summary
K13: January 2026 | L13: 0.93199449 | M13: =HYPERLINK("https://docs.google.com/spreadsheets/d/1bPZ7pNsR5rv-om-BypF4lK3nczjn4HJNO2dzimwnx7E/edit","PP Summary") -> PP Summary
K14: February 2026 | L14: 0.84989612 | M14: =HYPERLINK("https://docs.google.com/spreadsheets/d/1vH7bborVnc-TCby3wEkpzi7GGMOI5jMJooEW0V-rOQ4/edit","PP Summary") -> PP Summary
K15: March 2026 | L15: 0.79006453 | M15: =HYPERLINK("https://docs.google.com/spreadsheets/d/1O7y30opa_u1_deqFm_w2qgVyxi_75X00xnzKuyVyh6o/edit","PP Summary") -> PP Summary
K16: April 2026 | L16: 0.78483234 | M16: =HYPERLINK("https://docs.google.com/spreadsheets/d/10Qwx7K6sUcOBrCebGUGVaVeLQnhzvcT8sHQ0Sy3VBBM/edit","PP Summary") -> PP Summary
K17: May 2026 | L17: 0.63284589 | M17: =HYPERLINK("https://docs.google.com/spreadsheets/d/1m66t1jsLGc4e6AWnCFMsFbkSceZ9IYC_-bfTsbP_OYc/edit","PP Summary") -> PP Summary
K18: June 2026 | L18: 1.1105356 | M18: =HYPERLINK("https://docs.google.com/spreadsheets/d/1MUQajDI2a_Cn9xWGPP7z4PhhphZnfl2_CSTnpB07Wgk/edit","PP Summary") -> PP Summary
K19: July 2026 and later (Jan-Jun 2026 rolling) | L19: =$L$7 -> 0.795241
A25: TOTAL | B25: =SUM(B11:B23) -> 0 | C25: =SUM(C11:C23) -> 0 | D25: =SUM(D11:D23) -> 0 | E25: =SUM(E11:E23) -> 0 | F25: =SUM(F11:F23) -> 0 | H25: =I25/D25 -> #DIV/0! | I25: =SUM(I11:I23) -> 0 | J25: =SUM(J11:J23) -> 0
A27: SECTION 2 - ROLLUP
A28: Transport Mass | B28: Σ Net Oil Produced (kg) | C28: Loss (kg) | D28: MOBI — Σ Net Oil Injected (kg)
A29: =B25 -> 0 | B29: =SUM(D11:D23) -> 0 | C29: =IF(D29=0,"",B29-D29) | D29: =SUM(F11:F23) -> 0

Sheet Kerry
A1: BATCH HEADER — Kerry (Calciner Waste Oil, Tankers)
A2: Batch ID (INJ-YYYY-WXX) | B2: INJ-09-2026-W2 | L2: Constants
A3: Week Start (Sat) | B3: 46270 | L3: Lbs/Kg | M3: 2.20462
A4: Week End (Sat) | B4: 46277 | L4: Kg/Lbs | M4: 0.453592
L5: Filtration Solids Content | M5: 0.00071
L6: pH range (target) | M6: 2.0 - 4.0
L7: Testing Uncertainty | M7: 0.004
A8: SECTION 1 - TANKER LEDGER (one row per Kerry tanker; scale mass is authoritative)
A9: Date | B9: UID | C9: Gross Mass (lb) — transport | D9: Empty Weight (lb) | E9: Net Oil (lb) | F9: Net Injected (kg) — MOBI | G9: pH | H9: Notes | I9: C Content | J9: C Content Uncertainty | K9: Mass Uncertainty (Scaling)
A10: 46274 | B10: WILA002 | C10: =HYPERLINK("https://drive.google.com/file/d/1btCtnc1rbtqxocWXm7n2UE64uul98WHY/view", 75520) -> 75520 | D10: =HYPERLINK("https://drive.google.com/file/d/1USAs0YoRNzymMk56RZBa70pYdhca1Sbc/view", 35320) -> 35320 | E10: =C10-D10 -> 40200 | F10: =E10*M4 -> 18234.398 | G10: 2.92
A16: SECTION 2 - ROLLUP
A17: Σ Net Injected (kg) | B17: Filtration Loss (kg) | C17: MOBI (kg) | D17: pH
A18: =SUMIFS(F10:F15,B10:B15,"<>") -> 18234.398 | B18: =A18*$M$5 -> 12.946423 | C18: =A18-B18 -> 18221.452 | D18: =IFERROR(AVERAGE(G10:G15),"") -> 2.92 | G18: =IFERROR(__xludf.DUMMYFUNCTION("TRIM(TEXTJOIN("", "",TRUE,IFERROR(FILTER(B10:B15,B10:B15<>""""),"""")))"),"WILA002") -> WILA002

Sheet QOWV
A1: BATCH HEADER — QOWV (Aqueous Bio-Oil, IBC Totes)
A2: Batch ID (INJ-YYYY-WXX) | B2: INJ-09-2026-W2 | K2: Constants
A3: Week Start (Sat) | B3: 46270 | K3: Lbs/Kg | L3: 2.20462
A4: Week End (Sat) | B4: 46277 | K4: Kg/Lbs | L4: 0.453592
K5: Sparging Mass Loss | L5: 0.0129
K6: pH range (target) | L6: 2.0 - 4.0
K7: QOWV 6-Mo CI (kg CO2e/kg), Jul-Dec 2026 | L7: 0.120947
A8: SECTION 1 - IBC LEDGER (one row per QOWV tote; tote tag mass is authoritative)
B9: Transport Emissions | D9: Pyrolysis Emissions Mass | F9: MOBI | K9: Per-Production-Month CI (kg CO2e/kg) - PP Summary Output Type table, col T
A10: Tag | B10: Gross Mass (kg) | C10: Tote Mass (kg) | D10: Net Oil Produced (kg) | E10: Empty Tote Weight (kg) | F10: Net Oil Injected (kg) | G10: Production Period | H10: Carbon Intensity | I10: Production Emissions | J10: Scale Uncertainty | K10: PP#8 | L10: 0.15755534 | M10: =HYPERLINK("https://docs.google.com/spreadsheets/d/1L167k_JS3mnisFy3VpS-OXgI8U0cK-4nC6A9sxl-ozk/edit","PP Summary") -> PP Summary
A11: 015162 | B11: 945.6 | C11: 57.6 | D11: =B11-C11 -> 888 | E11: 290 | F11: =IF(E11="","",B11-E11) -> 655.6 | G11: MFO Lot not assigned, July 2025 | H11: =$L$10 -> 0.15755534 | I11: =H11*D11 -> 139.90914 | J11: =2.5*$L$4 -> 1.13398 | K11: 45962 | L11: 0.13921405 | M11: =HYPERLINK("https://docs.google.com/spreadsheets/d/1W8jWu3sp39WnSuds1Ja0FWDG5UuWN9v5NUmF6yh_WbI/edit","PP Summary") -> PP Summary
A12: 228490 | B12: 1044 | C12: 57.6 | D12: =B12-C12 -> 986.4 | E12: 368 | F12: =IF(E12="","",B12-E12) -> 676 | G12: MFO Lot 3868 (LOT00003868), September 2025 | H12: =$L$21 -> 0.12868957 | I12: =H12*D12 -> 126.93939 | J12: =2.5*$L$4 -> 1.13398 | K12: 45992 | L12: 0.16306166 | M12: =HYPERLINK("https://docs.google.com/spreadsheets/d/1-L6m2wYknC3o-yIts9KK7FrYAb5lZIv4AwaizK8FbMc/edit","PP Summary") -> PP Summary
A13: 245103 | B13: 1071.6 | C13: 57.6 | D13: =B13-C13 -> 1014 | E13: 229 | F13: =IF(E13="","",B13-E13) -> 842.6 | G13: MFO Lot not assigned, September 2025 | H13: =$L$21 -> 0.12868957 | I13: =H13*D13 -> 130.49122 | J13: =2.5*$L$4 -> 1.13398 | K13: 46023 | L13: 0.15683402 | M13: =HYPERLINK("https://docs.google.com/spreadsheets/d/1bPZ7pNsR5rv-om-BypF4lK3nczjn4HJNO2dzimwnx7E/edit","PP Summary") -> PP Summary
A14: 245140 | B14: 1051.6 | C14: 57.6 | D14: =B14-C14 -> 994 | E14: 151 | F14: =IF(E14="","",B14-E14) -> 900.6 | G14: MFO Lot not assigned, August 2025 | H14: =$L$22 -> 0.11056982 | I14: =H14*D14 -> 109.90641 | J14: =2.5*$L$4 -> 1.13398 | K14: 46054 | L14: 0.13304979 | M14: =HYPERLINK("https://docs.google.com/spreadsheets/d/1vH7bborVnc-TCby3wEkpzi7GGMOI5jMJooEW0V-rOQ4/edit","PP Summary") -> PP Summary
A15: 245142 | B15: 1013.6 | C15: 57.6 | D15: =B15-C15 -> 956 | E15: 357 | F15: =IF(E15="","",B15-E15) -> 656.6 | G15: MFO Lot not assigned, September 2025 | H15: =$L$21 -> 0.12868957 | I15: =H15*D15 -> 123.02723 | J15: =2.5*$L$4 -> 1.13398 | K15: 46082 | L15: 0.11852515 | M15: =HYPERLINK("https://docs.google.com/spreadsheets/d/1O7y30opa_u1_deqFm_w2qgVyxi_75X00xnzKuyVyh6o/edit","PP Summary") -> PP Summary
A16: 301100 | B16: 987 | C16: 57.6 | D16: =B16-C16 -> 929.4 | E16: 180 | F16: =IF(E16="","",B16-E16) -> 807 | G16: MFO Lot 301100 (LOT00301100), May 2026 | H16: =$L$17 -> 0.11066158 | I16: =H16*D16 -> 102.84887 | J16: =2.5*$L$4 -> 1.13398 | K16: 46113 | L16: 0.13141845 | M16: =HYPERLINK("https://docs.google.com/spreadsheets/d/10Qwx7K6sUcOBrCebGUGVaVeLQnhzvcT8sHQ0Sy3VBBM/edit","PP Summary") -> PP Summary
A17: 301101 | B17: 1035 | C17: 57.6 | D17: =B17-C17 -> 977.4 | E17: 168 | F17: =IF(E17="","",B17-E17) -> 867 | G17: MFO Lot 301101 (LOT00301101), April 2026 | H17: =$L$16 -> 0.13141845 | I17: =H17*D17 -> 128.4484 | J17: =2.5*$L$4 -> 1.13398 | K17: 46143 | L17: 0.11066158 | M17: =HYPERLINK("https://docs.google.com/spreadsheets/d/1m66t1jsLGc4e6AWnCFMsFbkSceZ9IYC_-bfTsbP_OYc/edit","PP Summary") -> PP Summary
A18: 301102 | B18: 979 | C18: 57.6 | D18: =B18-C18 -> 921.4 | E18: 152.5 | F18: =IF(E18="","",B18-E18) -> 826.5 | G18: MFO Lot 301102 (LOT00301102), May 2026 | H18: =$L$17 -> 0.11066158 | I18: =H18*D18 -> 101.96358 | J18: =2.5*$L$4 -> 1.13398 | K18: 46174 | L18: 0.12368967 | M18: =HYPERLINK("https://docs.google.com/spreadsheets/d/1MUQajDI2a_Cn9xWGPP7z4PhhphZnfl2_CSTnpB07Wgk/edit","PP Summary") -> PP Summary
A19: 301108 | B19: 1047 | C19: 57.6 | D19: =B19-C19 -> 989.4 | E19: 205 | F19: =IF(E19="","",B19-E19) -> 842 | G19: MFO Lot 301108 (LOT00301108), May 2026 | H19: =$L$17 -> 0.11066158 | I19: =H19*D19 -> 109.48856 | J19: =2.5*$L$4 -> 1.13398 | K19: July 2026 and later (Jan-Jun 2026 rolling) | L19: =$L$7 -> 0.120947
A20: 301110 | B20: 1010 | C20: 57.6 | D20: =B20-C20 -> 952.4 | E20: 150 | F20: =IF(E20="","",B20-E20) -> 860 | G20: MFO Lot 301110 (LOT00301110), May 2026 | H20: =$L$17 -> 0.11066158 | I20: =H20*D20 -> 105.39409 | J20: =2.5*$L$4 -> 1.13398 | K20: PP#7 | L20: 0.13736711 | M20: =HYPERLINK("https://docs.google.com/spreadsheets/d/1qPyS0H9Wx8z2vMl_3ANE1YLYahKLeL1Qo8OmZ_ol9aI/edit","PP Summary") -> PP Summary
A21: 301116 | B21: 1034 | C21: 57.6 | D21: =B21-C21 -> 976.4 | E21: 161.5 | F21: =IF(E21="","",B21-E21) -> 872.5 | G21: MFO Lot 301116 (LOT00301116), April 2026 | H21: =$L$16 -> 0.13141845 | I21: =H21*D21 -> 128.31698 | J21: =2.5*$L$4 -> 1.13398 | K21: =DATE(2025,9,1) -> 45901 | L21: 0.12868957 | M21: =HYPERLINK("https://docs.google.com/spreadsheets/d/1ZSnVAnmV96Ux_GwEJ_1zeATDHlQlHr5rvKAh3NOG2s0/edit","PP Summary") -> PP Summary
A22: 301117 | B22: 976 | C22: 57.6 | D22: =B22-C22 -> 918.4 | E22: 157 | F22: =IF(E22="","",B22-E22) -> 819 | G22: MFO Lot 301117 (LOT00301117), May 2026 | H22: =$L$17 -> 0.11066158 | I22: =H22*D22 -> 101.63159 | J22: =2.5*$L$4 -> 1.13398 | K22: =DATE(2025,8,1) -> 45870 | L22: 0.11056982 | M22: =HYPERLINK("https://docs.google.com/spreadsheets/d/1Kt3H_bffKPxvyBHqOAdrhnGxRzwfAQXFnsLBczb9EKE/edit","PP Summary") -> PP Summary
A23: 301118 | B23: 1056 | C23: 57.6 | D23: =B23-C23 -> 998.4 | E23: 151 | F23: =IF(E23="","",B23-E23) -> 905 | G23: MFO Lot 301118 (LOT00301118), May 2026 | H23: =$L$17 -> 0.11066158 | I23: =H23*D23 -> 110.48452 | J23: =2.5*$L$4 -> 1.13398 | K23: =DATE(2025,10,1) -> 45931 | L23: 0.11101762 | M23: =HYPERLINK("https://docs.google.com/spreadsheets/d/1AZymoR1vHkfpH4ZKO5J6CklWiVlCfhVS872y-2LipDw/edit","PP Summary") -> PP Summary
A24: 301119 | B24: 990 | C24: 57.6 | D24: =B24-C24 -> 932.4 | E24: 169 | F24: =IF(E24="","",B24-E24) -> 821 | G24: MFO Lot 301119 (LOT00301119), May 2026 | H24: =$L$17 -> 0.11066158 | I24: =H24*D24 -> 103.18085 | J24: =2.5*$L$4 -> 1.13398
A25: 301120 | B25: 1039 | C25: 57.6 | D25: =B25-C25 -> 981.4 | E25: 158.5 | F25: =IF(E25="","",B25-E25) -> 880.5 | G25: MFO Lot 301120 (LOT00301120), May 2026 | H25: =$L$17 -> 0.11066158 | I25: =H25*D25 -> 108.60327 | J25: =2.5*$L$4 -> 1.13398
A26: 301129 | B26: 1074 | C26: 57.6 | D26: =B26-C26 -> 1016.4 | E26: 147 | F26: =IF(E26="","",B26-E26) -> 927 | G26: MFO Lot 301129 (LOT00301129), May 2026 | H26: =$L$17 -> 0.11066158 | I26: =H26*D26 -> 112.47643 | J26: =2.5*$L$4 -> 1.13398
A27: 301132 | B27: 960 | C27: 57.6 | D27: =B27-C27 -> 902.4 | E27: 192 | F27: =IF(E27="","",B27-E27) -> 768 | G27: MFO Lot 301132 (LOT00301132), April 2026 | H27: =$L$16 -> 0.13141845 | I27: =H27*D27 -> 118.59201 | J27: =2.5*$L$4 -> 1.13398
A28: 301133 | B28: 1054 | C28: 57.6 | D28: =B28-C28 -> 996.4 | E28: 157 | F28: =IF(E28="","",B28-E28) -> 897 | G28: MFO Lot 301133 (LOT00301133), April 2026 | H28: =$L$16 -> 0.13141845 | I28: =H28*D28 -> 130.94535 | J28: =2.5*$L$4 -> 1.13398
A29: 301148 | B29: 1039 | C29: 57.6 | D29: =B29-C29 -> 981.4 | E29: 156 | F29: =IF(E29="","",B29-E29) -> 883 | G29: MFO Lot 301148 (LOT00301148), May 2026 | H29: =$L$17 -> 0.11066158 | I29: =H29*D29 -> 108.60327 | J29: =2.5*$L$4 -> 1.13398
A30: 301153 | B30: 945 | C30: 57.6 | D30: =B30-C30 -> 887.4 | E30: 146 | F30: =IF(E30="","",B30-E30) -> 799 | G30: MFO Lot 301153 (LOT00301153), May 2026 | H30: =$L$17 -> 0.11066158 | I30: =H30*D30 -> 98.201083 | J30: =2.5*$L$4 -> 1.13398
A31: 301156 | B31: 1041 | C31: 57.6 | D31: =B31-C31 -> 983.4 | E31: 160 | F31: =IF(E31="","",B31-E31) -> 881 | G31: MFO Lot 301156 (LOT00301156), April 2026 | H31: =$L$16 -> 0.13141845 | I31: =H31*D31 -> 129.23691 | J31: =2.5*$L$4 -> 1.13398
A32: 301173 | B32: 1033 | C32: 57.6 | D32: =B32-C32 -> 975.4 | E32: 144 | F32: =IF(E32="","",B32-E32) -> 889 | G32: MFO Lot 301173 (LOT00301173), May 2026 | H32: =$L$17 -> 0.11066158 | I32: =H32*D32 -> 107.9393 | J32: =2.5*$L$4 -> 1.13398
A33: 301180 | B33: 1017 | C33: 57.6 | D33: =B33-C33 -> 959.4 | E33: 149 | F33: =IF(E33="","",B33-E33) -> 868 | G33: MFO Lot 301180 (LOT00301180), May 2026 | H33: =$L$17 -> 0.11066158 | I33: =H33*D33 -> 106.16872 | J33: =2.5*$L$4 -> 1.13398
A34: 301194 | B34: 944 | C34: 57.6 | D34: =B34-C34 -> 886.4 | E34: 162 | F34: =IF(E34="","",B34-E34) -> 782 | G34: MFO Lot 301194 (LOT00301194), May 2026 | H34: =$L$17 -> 0.11066158 | I34: =H34*D34 -> 98.090421 | J34: =2.5*$L$4 -> 1.13398
A35: 301195 | B35: 1030 | C35: 57.6 | D35: =B35-C35 -> 972.4 | E35: 154.5 | F35: =IF(E35="","",B35-E35) -> 875.5 | G35: MFO Lot 301195 (LOT00301195), April 2026 | H35: =$L$16 -> 0.13141845 | I35: =H35*D35 -> 127.7913 | J35: =2.5*$L$4 -> 1.13398
A36: 015170 | B36: 1012 | C36: 57.6 | D36: =B36-C36 -> 954.4 | E36: 215 | F36: =IF(E36="","",B36-E36) -> 797 | G36: MFO Lot 3255 (LOT00003255), July 2025 | H36: =$L$10 -> 0.15755534 | I36: =H36*D36 -> 150.37082 | J36: =2.5*$L$4 -> 1.13398
A37: 245144 | B37: 1018 | C37: 57.6 | D37: =B37-C37 -> 960.4 | E37: 181.5 | F37: =IF(E37="","",B37-E37) -> 836.5 | G37: MFO Lot 3696 (LOT00003696), September 2025 | H37: =$L$21 -> 0.12868957 | I37: =H37*D37 -> 123.59346 | J37: =2.5*$L$4 -> 1.13398
A38: 245164 | B38: 1020 | C38: 57.6 | D38: =B38-C38 -> 962.4 | E38: 314 | F38: =IF(E38="","",B38-E38) -> 706 | G38: MFO Lot 3702 (LOT00003702), September 2025 | H38: =$L$21 -> 0.12868957 | I38: =H38*D38 -> 123.85084 | J38: =2.5*$L$4 -> 1.13398
A39: 245121 | B39: 1003 | C39: 57.6 | D39: =B39-C39 -> 945.4 | E39: 190 | F39: =IF(E39="","",B39-E39) -> 813 | G39: MFO Lot 3746 (LOT00003746), September 2025 | H39: =$L$21 -> 0.12868957 | I39: =H39*D39 -> 121.66312 | J39: =2.5*$L$4 -> 1.13398
A40: 245112 | B40: 1051 | C40: 57.6 | D40: =B40-C40 -> 993.4 | E40: 210 | F40: =IF(E40="","",B40-E40) -> 841 | G40: MFO Lot 3748 (LOT00003748), September 2025 | H40: =$L$21 -> 0.12868957 | I40: =H40*D40 -> 127.84022 | J40: =2.5*$L$4 -> 1.13398
...

Sheet Whole Oil
A1: BATCH HEADER — Whole Oil (IBC Totes)
A2: Batch ID (INJ-YYYY-WXX) | B2: INJ-09-2026-W2 | K2: Constants
A3: Week Start (Sat) | B3: 46270 | K3: Lbs/Kg | L3: 2.20462
A4: Week End (Sat) | B4: 46277 | K4: Kg/Lbs | L4: 0.453592
K5: Sparging Mass Loss | L5: 0.0129
K6: pH range (target) | L6: 2.0 - 4.0
K7: WODO 6-Mo CI (kg CO2e/kg), Jul-Dec 2026 — BORROWED for Whole Oil (no DC Whole Oil CI yet) | L7: 0.795241
A8: SECTION 1 - IBC LEDGER (one row per IBC tote; tote tag mass is authoritative)
B9: Transport Emissions | D9: Pyrolysis Emissions Mass | F9: MOBI | K9: Per-Production-Month CI (kg CO2e/kg) - PP Summary Output Type table, col T
A10: Tag | B10: Gross Mass (kg) | C10: Tote Mass (kg) | D10: Net Oil Produced (kg) | E10: Empty Tote Weight (kg) | F10: Net Oil Injected (kg) | G10: Production Period | H10: Carbon Intensity | I10: Production Emissions | J10: Scale Uncertainty | K10: PP#8 | L10: 0.71282902 | M10: =HYPERLINK("https://docs.google.com/spreadsheets/d/1L167k_JS3mnisFy3VpS-OXgI8U0cK-4nC6A9sxl-ozk/edit","PP Summary") -> PP Summary
K11: November 2025 | L11: 0.97484085 | M11: =HYPERLINK("https://docs.google.com/spreadsheets/d/1W8jWu3sp39WnSuds1Ja0FWDG5UuWN9v5NUmF6yh_WbI/edit","PP Summary") -> PP Summary
K12: December 2025 | L12: 0.97218282 | M12: =HYPERLINK("https://docs.google.com/spreadsheets/d/1-L6m2wYknC3o-yIts9KK7FrYAb5lZIv4AwaizK8FbMc/edit","PP Summary") -> PP Summary
K13: January 2026 | L13: 0.93199449 | M13: =HYPERLINK("https://docs.google.com/spreadsheets/d/1bPZ7pNsR5rv-om-BypF4lK3nczjn4HJNO2dzimwnx7E/edit","PP Summary") -> PP Summary
K14: February 2026 | L14: 0.84989612 | M14: =HYPERLINK("https://docs.google.com/spreadsheets/d/1vH7bborVnc-TCby3wEkpzi7GGMOI5jMJooEW0V-rOQ4/edit","PP Summary") -> PP Summary
K15: March 2026 | L15: 0.79006453 | M15: =HYPERLINK("https://docs.google.com/spreadsheets/d/1O7y30opa_u1_deqFm_w2qgVyxi_75X00xnzKuyVyh6o/edit","PP Summary") -> PP Summary
K16: April 2026 | L16: 0.78483234 | M16: =HYPERLINK("https://docs.google.com/spreadsheets/d/10Qwx7K6sUcOBrCebGUGVaVeLQnhzvcT8sHQ0Sy3VBBM/edit","PP Summary") -> PP Summary
K17: May 2026 | L17: 0.63284589 | M17: =HYPERLINK("https://docs.google.com/spreadsheets/d/1m66t1jsLGc4e6AWnCFMsFbkSceZ9IYC_-bfTsbP_OYc/edit","PP Summary") -> PP Summary
K18: June 2026 | L18: 1.1105356 | M18: =HYPERLINK("https://docs.google.com/spreadsheets/d/1MUQajDI2a_Cn9xWGPP7z4PhhphZnfl2_CSTnpB07Wgk/edit","PP Summary") -> PP Summary
K19: July 2026 and later (Jan-Jun 2026 rolling) | L19: =$L$7 -> 0.795241
A25: TOTAL | B25: =SUM(B11:B23) -> 0 | C25: =SUM(C11:C23) -> 0 | D25: =SUM(D11:D23) -> 0 | E25: =SUM(E11:E23) -> 0 | F25: =SUM(F11:F23) -> 0 | H25: =I25/D25 -> #DIV/0! | I25: =SUM(I11:I23) -> 0 | J25: =SUM(J11:J23) -> 0
A31: SECTION 2 - ROLLUP
A32: Transport Mass | B32: Σ Net Oil Produced (kg) | C32: Loss (kg) | D32: MOBI — Σ Net Oil Injected (kg)
A33: =B25 -> 0 | B33: =SUM(D11:D23) -> 0 | C33: =IF(D33=0,"",B33-D33) | D33: =SUM(F11:F23) -> 0

Sheet QOWV Shipments & EE Allocation
A1: INJ-09-2026-W2 - QOWV Shipments & EE Allocation
A4: BATCH SUMMARY
A5: Batch | B5: Fraction | C5: Inj. Week | D5: # Totes | E5: Shipping Orders (relevant to this batch)
A6: INJ-09-2026-W2 | B6: QOWV | C6: 2026-09-05 to 2026-09-12 | D6: =COUNTA(QOWV!A11:A48) -> 38 | E6: 3 shipping orders / trucks - see table A
A8: Charm CO -> Basco LA distance (one-way, mi) | B8: 1201 | C8: direct route
A10: EE ALLOCATION TABLE - A. DIRECT (Charm CO -> Basco LA)
A11: Truck (shipping order) | B11: Ship Date | C11: Total Totes on Truck | D11: Batch-Relevant Totes | E11: Batch Share of Truck | F11: Mileage (one-way) | G11: Allocated Miles
A12: CO_AQUEOUS_12.01.25 | B12: 45992 | C12: 20 | D12: 9 | E12: =D12/C12 -> 0.45 | F12: =$B$8 -> 1201 | G12: =E12*F12 -> 540.45
A13: CO_AQUEOUS_12.1.25_T2 | B13: 45992 | C13: 20 | D13: 9 | E13: =D13/C13 -> 0.45 | F13: =$B$8 -> 1201 | G13: =E13*F13 -> 540.45
A14: COLA_34 | B14: 46260 | C14: 20 | D14: 20 | E14: =D14/C14 -> 1 | F14: =$B$8 -> 1201 | G14: =E14*F14 -> 1201
A16: TOTAL | C16: =SUM(C12:C14) -> 60 | D16: =SUM(D12:D14) -> 38 | G16: =SUM(G12:G14) -> 2281.9
A57: --- Shipment 2025-12-10 --- (14 of 35 totes on this truck are W4-relevant)
A58: Metal Tag | B58: Fraction | C58: Production Period | D58: Date Loaded | E58: Batch
A59: 228427 | B59: QOWV | C59: October 2025 | D59: 46001 | E59: INJ-05-2026-W4
A60: 228408 | B60: QOWV | C60: September 2025 | D60: 46001 | E60: INJ-05-2026-W4
A61: 228465 | B61: QOWV | C61: October 2025 | D61: 46001 | E61: INJ-05-2026-W4
A62: 228496 | B62: QOWV | C62: October 2025 | D62: 46001 | E62: INJ-05-2026-W4
A63: 228431 | B63: QOWV | C63: October 2025 | D63: 46001 | E63: INJ-05-2026-W4
A64: 228455 | B64: QOWV | C64: October 2025 | D64: 46001 | E64: INJ-05-2026-W4
A65: 228458 | B65: QOWV | C65: October 2025 | D65: 46001 | E65: INJ-05-2026-W4
A66: 228422 | B66: QOWV | C66: October 2025 | D66: 46001 | E66: INJ-05-2026-W4
A67: 228466 | B67: QOWV | C67: October 2025 | D67: 46001 | E67: INJ-05-2026-W4
A68: 228462 | B68: QOWV | C68: October 2025 | D68: 46001 | E68: INJ-05-2026-W4
A69: 228494 | B69: QOWV | C69: October 2025 | D69: 46001 | E69: INJ-05-2026-W4
A70: 228438 | B70: QOWV | C70: October 2025 | D70: 46001 | E70: INJ-05-2026-W4
... A72: 228476 | B72: QOWV | C72: October 2025 | D72: 46001 | E72: INJ-05-2026-W4

Sheet WODO Shipments & EE Allocation
A1: INJ-09-2026-W2 - WODO Shipments & EE Mileage
A4: BATCH SUMMARY
A5: Batch | B5: Fraction | C5: Inj. Week | D5: # Totes | E5: Shipping Orders (relevant totes)
A6: INJ-09-2026-W2 | B6: WODO | C6: 2026-09-05 to 2026-09-12 | D6: =COUNTA(WODO!A11:A23) -> 0 | E6: 0 WODO totes this week - no shipping order to allocate
A8: Charm CO -> Basco LA distance (one-way mi) | B8: 1201
A10: EE ALLOCATION TABLE
A11: Truck (shipping order) | B11: Ship Date | C11: Total Totes on Truck | D11: Batch-Relevant Totes | E11: Batch Share of Truck | F11: Mileage (one-way) | G11: Allocated Miles
D12: =$D$6 -> 0 | E12: =IFERROR(D12/C12,"") | F12: =$B$8 -> 1201 | G12: =IFERROR(E12*F12,"") -> 0
A14: TOTAL | C14: =SUM(C12:C13) -> 0 | D14: =SUM(D12:D13) -> 0 | G14: =SUM(G12:G13) -> 0
A16: Check - every batch tote is allocated to a truck | B16: =IF($D$14=$D$6,"OK","MISMATCH") -> OK

Sheet Whole Oil Shipments & EE Alloca
A1: INJ-09-2026-W2 - Whole Oil Shipments & EE Mileage
A4: BATCH SUMMARY
A5: Batch | B5: Fraction | C5: Inj. Week | D5: # Totes | E5: Shipping Orders (relevant totes)
A6: INJ-09-2026-W2 | B6: Whole Oil | C6: 2026-09-05 to 2026-09-12 | D6: =COUNTA('Whole Oil'!A11:A23) -> 0
A8: Charm CO -> Basco LA distance (one-way mi) | B8: 1201
A10: EE ALLOCATION TABLE
A11: Truck (shipping order) | B11: Ship Date | C11: Total Totes on Truck | D11: Batch-Relevant Totes | E11: Batch Share of Truck | F11: Mileage (one-way) | G11: Allocated Miles
A14: TOTAL | C14: =SUM(C12:C13) -> 0 | D14: =SUM(D12:D13) -> 0 | G14: =SUM(G12:G13) -> 0
A16: Check - every batch tote is allocated to a truck | B16: =IF($D$14=$D$6,"OK","MISMATCH") -> OK
