Workbook

Sheet Summary
A1: BATCH SUMMARY
A2: Batch ID | B2: INJ-08-2026-W2
A3: Week Start (Sat) | B3: 46235
A4: Week End (Sat) | B4: 46242
A6: SECTION 1 - PER-TAB SUMMARY (each row pulls from its mode tab)
A7: Source Tab | B7: Σ Deliveries / Cargo (kg) | C7: Σ Uncertainty Adj (kg) | D7: Mass Used (kg) | E7: Sparging Loss (kg) | F7: Filtration Loss (kg) | G7: MOBI (kg) | H7: AECN→SOPOR EE (mi) | I7: Rail EE (mi) | J7: Opel→Basco EE (mi)
A8: AECN Rail | B8: ='AECN Rail'!B52 -> 213351.53 | C8: ='AECN Rail'!C52 -> 204.41024 | D8: ='AECN Rail'!D52 -> 213147.12 | E8: ='AECN Rail'!E52 -> 2749.5979 | F8: ='AECN Rail'!F52 -> 410.27517 | G8: ='AECN Rail'!G52 -> 209987.25 | H8: =SUM('AECN Rail'!L32:L47) -> 882.56181 | I8: =SUM('AECN Rail'!M32:M47) -> 6019.8526 | J8: =SUM('AECN Rail'!N32:N47) -> 943.8
A9: AECN Truck | B9: ='AECN Truck'!B28 -> 0 | C9: ='AECN Truck'!F28 -> 0 | D9: ='AECN Truck'!C28 -> 0 | E9: ='AECN Truck'!D28 -> 0 | F9: ='AECN Truck'!E28 -> 0 | G9: ='AECN Truck'!G28 -> 0
A10: Charm WODO | B10: =WODO!A33 -> 19583 | C10: 0 | D10: =WODO!B33 -> 18603.8 | E10: =WODO!C33 -> 133.28 | F10: 0 | G10: =WODO!D33 -> 18470.52
A11: Kerry | B11: =Kerry!A33 -> 0 | C11: 0 | D11: =Kerry!A33 -> 0 | E11: 0 | F11: =Kerry!B33 -> 0 | G11: =Kerry!E33 -> 0
A12: QOWV | B12: =QOWV!B77 -> 0 | C12: 0 | D12: =QOWV!D77 -> 0 | E12: 0 | F12: 0 | G12: =QOWV!F77 -> 0
A13: TOTAL | B13: =SUM(B8:B12) -> 232934.53 | C13: =SUM(C8:C12) -> 204.41024 | D13: =SUM(D8:D12) -> 231750.92 | E13: =SUM(E8:E12) -> 2882.8779 | F13: =SUM(F8:F12) -> 410.27517 | G13: =SUM(G8:G12) -> 228457.77 | H13: =SUM(H8:H12) -> 882.56181 | I13: =SUM(I8:I12) -> 6019.8526 | J13: =SUM(J8:J12) -> 943.8
A15: SECTION 2 - PER-OIL-TYPE ROLLUP (composite C% per oil type per week)
A16: Oil Type | B16: Transport Mass - upstream (kg) | C16: Transport Mass - downstream Opel→Basco (kg) | D16: Pyrolysis Mass (kg) | E16: MOBI - sequestration (kg) | F16: Composite Sample ID | G16: C % | H16: Lab COA Link | I16: C Content Uncertainty | J16: Testing Uncertainty
A17: AECN | B17: =SUM('AECN Rail'!I10:I13)+'AECN Truck'!A28 -> 213351.53 | C17: ='AECN Rail'!B52 -> 213351.53 | D17: =SUM('AECN Rail'!I10:I13)+'AECN Truck'!A28 -> 213351.53 | E17: ='AECN Rail'!G52+'AECN Truck'!G28 -> 209987.25 | F17: 08-2026-W2 AECN | G17: 0.395 | H17: =HYPERLINK("https://drive.google.com/file/d/1i9i4TW5crSS5gKZuZ0JHc4Qo6BqdxQdu/view?usp=drivesdk", "COA SR26-04824.001") -> COA SR26-04824.001 | I17: =G17*J17 -> 0.00158 | J17: 0.004
A18: WODO | B18: =WODO!A33 -> 19583 | D18: =WODO!B33 -> 18603.8 | E18: =WODO!D33 -> 18470.52 | F18: 8-2026-W2 WODO | G18: 0.654 | H18: =HYPERLINK("https://drive.google.com/file/d/1Hch01snOOaW6D1tW16CkrfNti4D8L-F2/view?usp=drivesdk", "COA SR26-04856.001") -> COA SR26-04856.001 | I18: =G18*J18 -> 0.002616 | J18: 0.004
A19: Kerry | B19: =Kerry!A33 -> 0 | D19: =Kerry!A33 -> 0 | E19: =Kerry!E33 -> 0 | G19: =Kerry!G33 | I19: =G19*J19 -> 0 | J19: 0.004
A20: QOWV | B20: =QOWV!B77 -> 0 | D20: =QOWV!D77 -> 0 | E20: =QOWV!F77 -> 0 | I20: =G20*J20 -> 0 | J20: 0.004
A21: TOTAL | B21: =SUM(B17:B20) -> 232934.53 | C21: =SUM(C17:C20) -> 213351.53 | D21: =SUM(D17:D20) -> 231955.33 | E21: =SUM(E17:E20) -> 228457.77

Sheet AECN Rail
A1: BATCH HEADER — AECN Rail
A2: Batch ID (INJ-YYYY-WXX) | B2: INJ-08-2026-W2 | N2: Constants
A3: Week Start (Sat) | B3: 46235 | N3: Lbs/Kg | O3: 2.20462
A4: Week End (Sat) | B4: 46242 | N4: Kg/Lbs | O4: 0.453592
N5: Sparging Mass Loss | O5: 0.0129
N6: pH range (target) | O6: 2.0 - 4.0
N7: Filtration Solids Content | O7: =HYPERLINK("https://docs.google.com/spreadsheets/d/16shKoa1KP34kQJyQvzclBejW9L5-ubNSqPsMOVB7zDY/edit?usp=sharing", 0.00195) -> 0.00195
A8: SECTION 1 - RAILCARS RECEIVED THIS WEEK (entity-level) | I8: Pyrolysis Emissions Mass | N8: BOL Trips (AECN→SOPOR) | O8: 3
A9: Railcar # | B9: Arrival Date at Opelousas | C9: Loading BOLs (comma-sep) | D9: Total Loaded (MT) | E9: Total Loaded (kg) | F9: Total Offloaded (kg, auto) | G9: Loss (kg) | H9: Previously Claimed (kg) | I9: Claimed This Week (kg) | J9: AECN→SOPOR (mi) | K9: Rail (mi) | L9: Opel→Basco (mi) | M9: Full Railcar This Week? | N9: Round Trip (Opel→Basco) | O9: 2
A10: SHPX215082 | B10: 46230 | C10: 2418-R, 2419-R, 2423-R | D10: =SUMIF($C$17:$C$28,$A10,$D$17:$D$28) -> 78.13 | E10: =SUMIF($C$17:$C$28,$A10,$E$17:$E$28) -> 78130 | F10: =SUMIF($C$32:$C$47,A10,$F$32:$F$47)+H10 -> 38854.691 | G10: =IF(AND(E10<>"",F10<>"",F10>=0.95*E10),E10-F10,"") | H10: 0 | I10: =F10-H10 -> 38854.691 | J10: 107.5 | K10: 2199 | L10: 42.9 | M10: =IF(OR($E10="",$F10=""),"",IF(AND($H10=0,$F10>=0.95*$E10),"FULL","PARTIAL")) -> PARTIAL
A11: SHPX215090 | B11: 46230 | C11: 2421-R, 2422-R, 2420-R | D11: =SUMIF($C$17:$C$28,$A11,$D$17:$D$28) -> 78.14 | E11: =SUMIF($C$17:$C$28,$A11,$E$17:$E$28) -> 78140 | F11: =SUMIF($C$32:$C$47,A11,$F$32:$F$47)+H11 -> 78344.41 | G11: =IF(AND(E11<>"",F11<>"",F11>=0.95*E11),E11-F11,"") -> -204.41024 | H11: 0 | I11: =F11-H11 -> 78344.41 | J11: 107.5 | K11: 2199 | L11: 42.9 | M11: =IF(OR($E11="",$F11=""),"",IF(AND($H11=0,$F11>=0.95*$E11),"FULL","PARTIAL")) -> FULL
A12: TILX200228 | B12: 46231 | C12: 2412-R, 2413-R, 2414-R | D12: =SUMIF($C$17:$C$28,$A12,$D$17:$D$28) -> 77.98 | E12: =SUMIF($C$17:$C$28,$A12,$E$17:$E$28) -> 77980 | F12: =SUMIF($C$32:$C$47,A12,$F$32:$F$47)+H12 -> 76244.279 | G12: =IF(AND(E12<>"",F12<>"",F12>=0.95*E12),E12-F12,"") -> 1735.7207 | H12: =19041.79216+19563.42296+18905.71456 -> 57510.93 | I12: =F12-H12 -> 18733.35 | J12: 107.5 | K12: 2199 | L12: 42.9 | M12: =IF(OR($E12="",$F12=""),"",IF(AND($H12=0,$F12>=0.95*$E12),"FULL","PARTIAL")) -> PARTIAL
A13: SHPX215070 | B13: 46233 | C13: 2424-R, 2425-R, 2426-R | D13: =SUMIF($C$17:$C$28,$A13,$D$17:$D$28) -> 77.49 | E13: =SUMIF($C$17:$C$28,$A13,$E$17:$E$28) -> 77490 | F13: =SUMIF($C$32:$C$47,A13,$F$32:$F$47)+H13 -> 77419.083 | G13: =IF(AND(E13<>"",F13<>"",F13>=0.95*E13),E13-F13,"") -> 70.91744 | H13: 0 | I13: =F13-H13 -> 77419.083 | J13: 107.5 | K13: 2199 | L13: 42.9 | M13: =IF(OR($E13="",$F13=""),"",IF(AND($H13=0,$F13>=0.95*$E13),"FULL","PARTIAL")) -> FULL
A15: SECTION 2 - ORIGINS LEDGER (loading BOLs at SOPOR)
A16: Date | B16: BOL # | C16: Railcar # | D16: BOL Mass (MT) | E16: BOL Mass (kg)
A17: 46215 | B17: =HYPERLINK("https://drive.google.com/file/d/1G-sh8koOzOzOZyn1WSphudqvvZ9A5LOz/view","2418-R") -> 2418-R | C17: SHPX215082 | D17: 26.07 | E17: =D17*1000 -> 26070
A18: 46215 | B18: =HYPERLINK("https://drive.google.com/file/d/1YiHrTDjk51LD0Cw2_YONHIQDBo88oJlG/view","2419-R") -> 2419-R | C18: SHPX215082 | D18: 26.01 | E18: =D18*1000 -> 26010
A19: 46215 | B19: =HYPERLINK("https://drive.google.com/file/d/1VWJ6Xq2mKKK03Igs8E3bK3CT7VXIHHwu/view","2423-R") -> 2423-R | C19: SHPX215082 | D19: 26.05 | E19: =D19*1000 -> 26050
A20: 46215 | B20: =HYPERLINK("https://drive.google.com/file/d/1xk5aZFHU6vAcIiBfYTJUEtI0uZhK9AIQ/view","2421-R") -> 2421-R | C20: SHPX215090 | D20: 26.09 | E20: =D20*1000 -> 26090
A21: 46215 | B21: =HYPERLINK("https://drive.google.com/file/d/1fl-QMfw_uTHnv1kxK3inB7lWkmu6Lmwn/view","2422-R") -> 2422-R | C21: SHPX215090 | D21: 26.05 | E21: =D21*1000 -> 26050
A22: 46215 | B22: =HYPERLINK("https://drive.google.com/file/d/1jn0zn0HXXF9_nHgM7gd1ApNNB-SHD9aC/view","2420-R") -> 2420-R | C22: SHPX215090 | D22: 26 | E22: =D22*1000 -> 26000
A23: 46209 | B23: =HYPERLINK("https://drive.google.com/file/d/1T_cidCWZcJQad7tiAxoXefn7Lik3E_u0/view","2412-R") -> 2412-R | C23: TILX200228 | D23: 26.06 | E23: =D23*1000 -> 26060
A24: 46209 | B24: =HYPERLINK("https://drive.google.com/file/d/1620pQcmazK921XBe6oRAo3VzhpstXzGO/view","2413-R") -> 2413-R | C24: TILX200228 | D24: 25.81 | E24: =D24*1000 -> 25810
A25: 46209 | B25: =HYPERLINK("https://drive.google.com/file/d/18qPUmo4TetCABk-ZsruwkftJkdosdFPC/view","2414-R") -> 2414-R | C25: TILX200228 | D25: 26.11 | E25: =D25*1000 -> 26110
A26: 46220 | B26: =HYPERLINK("https://drive.google.com/file/d/1RHRziIbKma8rUHT9-ZwV09JK3GfLlFUa/view","2424-R") -> 2424-R | C26: SHPX215070 | D26: 25.83 | E26: =D26*1000 -> 25830
A27: 46220 | B27: =HYPERLINK("https://drive.google.com/file/d/1W0UltaBU5pzfCX2job9huHbj00Wjdns1/view","2425-R") -> 2425-R | C27: SHPX215070 | D27: 25.86 | E27: =D27*1000 -> 25860
A28: 46220 | B28: =HYPERLINK("https://drive.google.com/file/d/1Yw_1MEpgtfeVhsViS2beiC1PEtxuIJ90/view","2426-R") -> 2426-R | C28: SHPX215070 | D28: 25.8 | E28: =D28*1000 -> 25800
A30: SECTION 3 - SCALE TICKETS + OFFLOAD WEIGHTS
A31: Date | B31: Offload Key | C31: Railcar # | D31: Full Scale Ticket (lb) | E31: Empty Scale Ticket (lb) | F31: Net Scaled Mass (kg) | G31: pH | H31: Sparging Loss (kg) | I31: Filtration Loss (kg) | J31: Uncertainty Adjustment (kg) | K31: MOBI (kg) | L31: AECN→SOPOR (mi, x3 — full BOL) | M31: Rail (mi) — FULL railcar: flat 2199 on first offload; PARTIAL: offload-mass-basis allocation | N31: Opel→Basco (mi, x2 — downstream, per offload)
A32: 46242 | B32: Rail_SHPX215070_7.17.2026_offload_1 | C32: SHPX215070 | D32: =HYPERLINK("https://drive.google.com/file/d/1XY84XjOGpSV3ofZ8d7_sHnRcz17MuM7b/view?usp=drivesdk", 72180) -> 72180 | E32: =HYPERLINK("https://drive.google.com/file/d/1nNBuYdPyJo4OjQhfO46Rmk2eYGSHGzEp/view?usp=drivesdk", 28600) -> 28600 | F32: =IF(OR(D32="",E32=""),"",(D32-E32)*$O$4) -> 19767.539 | G32: 2.86 | H32: =IF(F32="","",(F32-J32)*$O$5) -> 255.00126 | I32: =IF(F32="","",(F32-J32)*(1-$O$5)*$O$7) -> 38.049449 | J32: {=IF(F32="","",IF(ROW()=MAX(IF($C$32:$C$47=C32,ROW($C$32:$C$47),0)),MAX(0,IFERROR(VLOOKUP(C32,$A$10:$L$13,6,FALSE)-VLOOKUP(C32,$A$10:$L$13,5,FALSE),0)),0))} -> 0 | K32: =IF(F32="","",F32-H32-I32-J32) -> 19474.489 | L32: =IF(F32="","",(F32-J32)/VLOOKUP(C32,$A$10:$L$13,5,FALSE)*VLOOKUP(C32,$A$10:$L$13,10,FALSE)*$O$8) -> 82.269086 | M32: {=IF(F32="","",IF(IFERROR(VLOOKUP(C32,$A$10:$M$13,13,FALSE),"")="FULL",IF(ROW()=MIN(IF($C$32:$C$47=C32,ROW($C$32:$C$47),10^9)),VLOOKUP(C32,$A$10:$M$13,11,FALSE),0),(F32-J32)/VLOOKUP(C32,$A$10:$M$13,5,FALSE)*VLOOKUP(C32,$A$10:$M$13,11,FALSE)))} -> 2199 | N32: =IF(F32="","",IFERROR(VLOOKUP(C32,$A$10:$L$13,12,FALSE),0)*$O$9) -> 85.8
A33: 46242 | B33: Rail_SHPX215070_7.17.2026_offload_2 | C33: SHPX215070 | D33: =HYPERLINK("https://drive.google.com/file/d/1kIC-InLywuEaJfkHKM36WgttpwEuw4F3/view?usp=drivesdk", 71240) -> 71240 | E33: =HYPERLINK("https://drive.google.com/file/d/10uIB57zQtc66iu9Gqel6jpR6JTKpFwOD/view?usp=drivesdk", 29220) -> 29220 | F33: =IF(OR(D33="",E33=""),"",(D33-E33)*$O$4) -> 19059.936 | G33: 2.86 | H33: =IF(F33="","",(F33-J33)*$O$5) -> 245.87317 | I33: =IF(F33="","",(F33-J33)*(1-$O$5)*$O$7) -> 36.687422 | J33: {=IF(F33="","",IF(ROW()=MAX(IF($C$32:$C$47=C33,ROW($C$32:$C$47),0)),MAX(0,IFERROR(VLOOKUP(C33,$A$10:$L$13,6,FALSE)-VLOOKUP(C33,$A$10:$L$13,5,FALSE),0)),0))} -> 0 | K33: =IF(F33="","",F33-H33-I33-J33) -> 18777.375 | L33: =IF(F33="","",(F33-J33)/VLOOKUP(C33,$A$10:$L$13,5,FALSE)*VLOOKUP(C33,$A$10:$L$13,10,FALSE)*$O$8) -> 79.324162 | M33: {=IF(F33="","",IF(IFERROR(VLOOKUP(C33,$A$10:$M$13,13,FALSE),"")="FULL",IF(ROW()=MIN(IF($C$32:$C$47=C33,ROW($C$32:$C$47),10^9)),VLOOKUP(C33,$A$10:$M$13,11,FALSE),0),(F33-J33)/VLOOKUP(C33,$A$10:$M$13,5,FALSE)*VLOOKUP(C33,$A$10:$M$13,11,FALSE)))} -> 0 | N33: =IF(F33="","",IFERROR(VLOOKUP(C33,$A$10:$L$13,12,FALSE),0)*$O$9) -> 85.8
A34: 46242 | B34: Rail_SHPX215070_7.17.2026_offload_4 | C34: SHPX215070 | D34: =HYPERLINK("https://drive.google.com/file/d/1-kgQyfQiqbYfqQZwcJYaRSDBaBRaAGQe/view?usp=drivesdk", 72160) -> 72160 | E34: =HYPERLINK("https://drive.google.com/file/d/1vUV1OFgVx_0XNg1If02S_FlC-pdQhFoI/view?usp=drivesdk", 29200) -> 29200 | F34: =IF(OR(D34="",E34=""),"",(D34-E34)*$O$4) -> 19486.312 | G34: 2.86 | H34: =IF(F34="","",(F34-J34)*$O$5) -> 251.37343 | I34: =IF(F34="","",(F34-J34)*(1-$O$5)*$O$7) -> 37.508131 | J34: {=IF(F34="","",IF(ROW()=MAX(IF($C$32:$C$47=C34,ROW($C$32:$C$47),0)),MAX(0,IFERROR(VLOOKUP(C34,$A$10:$L$13,6,FALSE)-VLOOKUP(C34,$A$10:$L$13,5,FALSE),0)),0))} -> 0 | K34: =IF(F34="","",F34-H34-I34-J34) -> 19197.431 | L34: =IF(F34="","",(F34-J34)/VLOOKUP(C34,$A$10:$L$13,5,FALSE)*VLOOKUP(C34,$A$10:$L$13,10,FALSE)*$O$8) -> 81.098667 | M34: {=IF(F34="","",IF(IFERROR(VLOOKUP(C34,$A$10:$M$13,13,FALSE),"")="FULL",IF(ROW()=MIN(IF($C$32:$C$47=C34,ROW($C$32:$C$47),10^9)),VLOOKUP(C34,$A$10:$M$13,11,FALSE),0),(F34-J34)/VLOOKUP(C34,$A$10:$M$13,5,FALSE)*VLOOKUP(C34,$A$10:$M$13,11,FALSE)))} -> 0 | N34: =IF(F34="","",IFERROR(VLOOKUP(C34,$A$10:$L$13,12,FALSE),0)*$O$9) -> 85.8
A35: 46242 | B35: Rail_SHPX215070_7.17.2026_offload_3 | C35: SHPX215070 | D35: =HYPERLINK("https://drive.google.com/file/d/1ZzNKPUJ-0Cf1hSemYBrdFrWJvNsLfwrS/view?usp=drivesdk", 70700) -> 70700 | E35: =HYPERLINK("https://drive.google.com/file/d/1ByTSgmXxkJr3bG0qzn9uM14L-R8u9rRH/view?usp=drivesdk", 28580) -> 28580 | F35: =IF(OR(D35="",E35=""),"",(D35-E35)*$O$4) -> 19105.295 | G35: 2.86 | H35: =IF(F35="","",(F35-J35)*$O$5) -> 246.45831 | I35: =IF(F35="","",(F35-J35)*(1-$O$5)*$O$7) -> 36.774732 | J35: {=IF(F35="","",IF(ROW()=MAX(IF($C$32:$C$47=C35,ROW($C$32:$C$47),0)),MAX(0,IFERROR(VLOOKUP(C35,$A$10:$L$13,6,FALSE)-VLOOKUP(C35,$A$10:$L$13,5,FALSE),0)),0))} -> 0 | K35: =IF(F35="","",F35-H35-I35-J35) -> 18822.062 | L35: =IF(F35="","",(F35-J35)/VLOOKUP(C35,$A$10:$L$13,5,FALSE)*VLOOKUP(C35,$A$10:$L$13,10,FALSE)*$O$8) -> 79.512939 | M35: {=IF(F35="","",IF(IFERROR(VLOOKUP(C35,$A$10:$M$13,13,FALSE),"")="FULL",IF(ROW()=MIN(IF($C$32:$C$47=C35,ROW($C$32:$C$47),10^9)),VLOOKUP(C35,$A$10:$M$13,11,FALSE),0),(F35-J35)/VLOOKUP(C35,$A$10:$M$13,5,FALSE)*VLOOKUP(C35,$A$10:$M$13,11,FALSE)))} -> 0 | N35: =IF(F35="","",IFERROR(VLOOKUP(C35,$A$10:$L$13,12,FALSE),0)*$O$9) -> 85.8
A36: 46242 | B36: Rail_SHPX215090_7.12.2026_offload_1 | C36: SHPX215090 | D36: =HYPERLINK("https://drive.google.com/file/d/11PVubNNfAQyMrxqrifpXqDdsWFWocnVE/view?usp=drivesdk", 73700) -> 73700 | E36: =HYPERLINK("https://drive.google.com/file/d/1rqhDqgFEO0nhNb4XFxe9VZmQ7TcbEi9j/view?usp=drivesdk", 28740) -> 28740 | F36: =IF(OR(D36="",E36=""),"",(D36-E36)*$O$4) -> 20393.496 | G36: 2.86 | H36: =IF(F36="","",(F36-J36)*$O$5) -> 263.0761 | I36: =IF(F36="","",(F36-J36)*(1-$O$5)*$O$7) -> 39.254319 | J36: {=IF(F36="","",IF(ROW()=MAX(IF($C$32:$C$47=C36,ROW($C$32:$C$47),0)),MAX(0,IFERROR(VLOOKUP(C36,$A$10:$L$13,6,FALSE)-VLOOKUP(C36,$A$10:$L$13,5,FALSE),0)),0))} -> 0 | K36: =IF(F36="","",F36-H36-I36-J36) -> 20091.166 | L36: =IF(F36="","",(F36-J36)/VLOOKUP(C36,$A$10:$L$13,5,FALSE)*VLOOKUP(C36,$A$10:$L$13,10,FALSE)*$O$8) -> 84.168193 | M36: {=IF(F36="","",IF(IFERROR(VLOOKUP(C36,$A$10:$M$13,13,FALSE),"")="FULL",IF(ROW()=MIN(IF($C$32:$C$47=C36,ROW($C$32:$C$47),10^9)),VLOOKUP(C36,$A$10:$M$13,11,FALSE),0),(F36-J36)/VLOOKUP(C36,$A$10:$M$13,5,FALSE)*VLOOKUP(C36,$A$10:$M$13,11,FALSE)))} -> 2199 | N36: =IF(F36="","",IFERROR(VLOOKUP(C36,$A$10:$L$13,12,FALSE),0)*$O$9) -> 85.8
A37: 46242 | B37: Rail_SHPX215090_7.12.2026_offload_2 | C37: SHPX215090 | D37: =HYPERLINK("https://drive.google.com/file/d/1Sr5jD6KKo1_rC1mypGcGbGnTVlBCLHaw/view?usp=drivesdk", 72040) -> 72040 | E37: =HYPERLINK("https://drive.google.com/file/d/1zES0Ij19QzDdjMb6qF4SRTaiVcT5SZHS/view?usp=drivesdk", 29160) -> 29160 | F37: =IF(OR(D37="",E37=""),"",(D37-E37)*$O$4) -> 19450.025 | G37: 2.86 | H37: =IF(F37="","",(F37-J37)*$O$5) -> 250.90532 | I37: =IF(F37="","",(F37-J37)*(1-$O$5)*$O$7) -> 37.438283 | J37: {=IF(F37="","",IF(ROW()=MAX(IF($C$32:$C$47=C37,ROW($C$32:$C$47),0)),MAX(0,IFERROR(VLOOKUP(C37,$A$10:$L$13,6,FALSE)-VLOOKUP(C37,$A$10:$L$13,5,FALSE),0)),0))} -> 0 | K37: =IF(F37="","",F37-H37-I37-J37) -> 19161.681 | L37: =IF(F37="","",(F37-J37)/VLOOKUP(C37,$A$10:$L$13,5,FALSE)*VLOOKUP(C37,$A$10:$L$13,10,FALSE)*$O$8) -> 80.27429 | M37: {=IF(F37="","",IF(IFERROR(VLOOKUP(C37,$A$10:$M$13,13,FALSE),"")="FULL",IF(ROW()=MIN(IF($C$32:$C$47=C37,ROW($C$32:$C$47),10^9)),VLOOKUP(C37,$A$10:$M$13,11,FALSE),0),(F37-J37)/VLOOKUP(C37,$A$10:$M$13,5,FALSE)*VLOOKUP(C37,$A$10:$M$13,11,FALSE)))} -> 0 | N37: =IF(F37="","",IFERROR(VLOOKUP(C37,$A$10:$L$13,12,FALSE),0)*$O$9) -> 85.8
A38: 46242 | B38: Rail_SHPX215090_7.12.2026_offload_3 | C38: SHPX215090 | D38: =HYPERLINK("https://drive.google.com/file/d/1UgV3XFcigs9O0NFfLGT6UXjTO-R_Gg-X/view?usp=drivesdk", 73080) -> 73080 | E38: =HYPERLINK("https://drive.google.com/file/d/1Pf_4eSBobOK-YSbjrM_m8Zzo6AsSG2rh/view?usp=drivesdk", 28480) -> 28480 | F38: =IF(OR(D38="",E38=""),"",(D38-E38)*$O$4) -> 20230.203 | G38: 2.86 | H38: =IF(F38="","",(F38-J38)*$O$5) -> 260.96962 | I38: =IF(F38="","",(F38-J38)*(1-$O$5)*$O$7) -> 38.940005 | J38: {=IF(F38="","",IF(ROW()=MAX(IF($C$32:$C$47=C38,ROW($C$32:$C$47),0)),MAX(0,IFERROR(VLOOKUP(C38,$A$10:$L$13,6,FALSE)-VLOOKUP(C38,$A$10:$L$13,5,FALSE),0)),0))} -> 0 | K38: =IF(F38="","",F38-H38-I38-J38) -> 19930.294 | L38: =IF(F38="","",(F38-J38)/VLOOKUP(C38,$A$10:$L$13,5,FALSE)*VLOOKUP(C38,$A$10:$L$13,10,FALSE)*$O$8) -> 83.494248 | M38: {=IF(F38="","",IF(IFERROR(VLOOKUP(C38,$A$10:$M$13,13,FALSE),"")="FULL",IF(ROW()=MIN(IF($C$32:$C$47=C38,ROW($C$32:$C$47),10^9)),VLOOKUP(C38,$A$10:$M$13,11,FALSE),0),(F38-J38)/VLOOKUP(C38,$A$10:$M$13,5,FALSE)*VLOOKUP(C38,$A$10:$M$13,11,FALSE)))} -> 0 | N38: =IF(F38="","",IFERROR(VLOOKUP(C38,$A$10:$L$13,12,FALSE),0)*$O$9) -> 85.8
A39: 46242 | B39: Rail_SHPX215090_7.12.2026_offload_4 | C39: SHPX215090 | D39: =HYPERLINK("https://drive.google.com/file/d/1xsNbU2vieH9HazUvy9q0XEy6pG4PAKsE/view?usp=drivesdk", 69760) -> 69760 | E39: =HYPERLINK("https://drive.google.com/file/d/14LgyTiWGR2U74LVQZvKYzzl8Gu9MXZQe/view?usp=drivesdk", 29480) -> 29480 | F39: =IF(OR(D39="",E39=""),"",(D39-E39)*$O$4) -> 18270.686 | G39: 2.86 | H39: =IF(F39="","",(F39-J39)*$O$5) -> 233.05495 | I39: =IF(F39="","",(F39-J39)*(1-$O$5)*$O$7) -> 34.77478 | J39: {=IF(F39="","",IF(ROW()=MAX(IF($C$32:$C$47=C39,ROW($C$32:$C$47),0)),MAX(0,IFERROR(VLOOKUP(C39,$A$10:$L$13,6,FALSE)-VLOOKUP(C39,$A$10:$L$13,5,FALSE),0)),0))} -> 204.41024 | K39: =IF(F39="","",F39-H39-I39-J39) -> 17798.446 | L39: =IF(F39="","",(F39-J39)/VLOOKUP(C39,$A$10:$L$13,5,FALSE)*VLOOKUP(C39,$A$10:$L$13,10,FALSE)*$O$8) -> 74.563269 | M39: {=IF(F39="","",IF(IFERROR(VLOOKUP(C39,$A$10:$M$13,13,FALSE),"")="FULL",IF(ROW()=MIN(IF($C$32:$C$47=C39,ROW($C$32:$C$47),10^9)),VLOOKUP(C39,$A$10:$M$13,11,FALSE),0),(F39-J39)/VLOOKUP(C39,$A$10:$M$13,5,FALSE)*VLOOKUP(C39,$A$10:$M$13,11,FALSE)))} -> 0 | N39: =IF(F39="","",IFERROR(VLOOKUP(C39,$A$10:$L$13,12,FALSE),0)*$O$9) -> 85.8
A40: 46242 | B40: Rail_SHPX215082_7.12.2026_offload_3 | C40: SHPX215082 | D40: =HYPERLINK("https://drive.google.com/file/d/1iSiIzj6TH3CPX1yoCdp75jBwV1rte0b5/view?usp=drivesdk", 71340) -> 71340 | E40: =HYPERLINK("https://drive.google.com/file/d/1fViqGX5svU8nyvNYwMkhtMPks0FkPl2n/view?usp=drivesdk", 29180) -> 29180 | F40: =IF(OR(D40="",E40=""),"",(D40-E40)*$O$4) -> 19123.439 | G40: 2.86 | H40: =IF(F40="","",(F40-J40)*$O$5) -> 246.69236 | I40: =IF(F40="","",(F40-J40)*(1-$O$5)*$O$7) -> 36.809655 | J40: {=IF(F40="","",IF(ROW()=MAX(IF($C$32:$C$47=C40,ROW($C$32:$C$47),0)),MAX(0,IFERROR(VLOOKUP(C40,$A$10:$L$13,6,FALSE)-VLOOKUP(C40,$A$10:$L$13,5,FALSE),0)),0))} -> 0 | K40: =IF(F40="","",F40-H40-I40-J40) -> 18839.937 | L40: =IF(F40="","",(F40-J40)/VLOOKUP(C40,$A$10:$L$13,5,FALSE)*VLOOKUP(C40,$A$10:$L$13,10,FALSE)*$O$8) -> 78.936503 | M40: {=IF(F40="","",IF(IFERROR(VLOOKUP(C40,$A$10:$M$13,13,FALSE),"")="FULL",IF(ROW()=MIN(IF($C$32:$C$47=C40,ROW($C$32:$C$47),10^9)),VLOOKUP(C40,$A$10:$M$13,11,FALSE),0),(F40-J40)/VLOOKUP(C40,$A$10:$M$13,5,FALSE)*VLOOKUP(C40,$A$10:$M$13,11,FALSE)))} -> 538.23681 | N40: =IF(F40="","",IFERROR(VLOOKUP(C40,$A$10:$L$13,12,FALSE),0)*$O$9) -> 85.8
A41: 46242 | B41: Rail_SHPX215082_7.12.2026_offload_4 | C41: SHPX215082 | D41: =HYPERLINK("https://drive.google.com/file/d/1GSX35ofsXYHhAoT2yowhrAJ8sGvuFocF/view?usp=drivesdk", 72100) -> 72100 | E41: =HYPERLINK("https://drive.google.com/file/d/1IVs8mKJTw_fuJj4Q4d_sCj4mvcs2upiM/view?usp=drivesdk", 28600) -> 28600 | F41: =IF(OR(D41="",E41=""),"",(D41-E41)*$O$4) -> 19731.252 | G41: 2.86 | H41: =IF(F41="","",(F41-J41)*$O$5) -> 254.53315 | I41: =IF(F41="","",(F41-J41)*(1-$O$5)*$O$7) -> 37.979602 | J41: {=IF(F41="","",IF(ROW()=MAX(IF($C$32:$C$47=C41,ROW($C$32:$C$47),0)),MAX(0,IFERROR(VLOOKUP(C41,$A$10:$L$13,6,FALSE)-VLOOKUP(C41,$A$10:$L$13,5,FALSE),0)),0))} -> 0 | K41: =IF(F41="","",F41-H41-I41-J41) -> 19438.739 | L41: =IF(F41="","",(F41-J41)/VLOOKUP(C41,$A$10:$L$13,5,FALSE)*VLOOKUP(C41,$A$10:$L$13,10,FALSE)*$O$8) -> 81.445396 | M41: {=IF(F41="","",IF(IFERROR(VLOOKUP(C41,$A$10:$M$13,13,FALSE),"")="FULL",IF(ROW()=MIN(IF($C$32:$C$47=C41,ROW($C$32:$C$47),10^9)),VLOOKUP(C41,$A$10:$M$13,11,FALSE),0),(F41-J41)/VLOOKUP(C41,$A$10:$M$13,5,FALSE)*VLOOKUP(C41,$A$10:$M$13,11,FALSE)))} -> 555.34395 | N41: =IF(F41="","",IFERROR(VLOOKUP(C41,$A$10:$L$13,12,FALSE),0)*$O$9) -> 85.8
A42: 46242 | B42: Rail_TILX200228_7.6.2026_offload_4 | C42: TILX200228 | D42: =HYPERLINK("https://drive.google.com/file/d/19jpCR1bBJHwxkjZrTsN5LMdTn0LaiWdq/view?usp=drivesdk", 70560) -> 70560 | E42: =HYPERLINK("https://drive.google.com/file/d/1EHL0A3ALBnT3cgcGJY7Xd3vLgSttuAIs/view?usp=drivesdk", 29260) -> 29260 | F42: =IF(OR(D42="",E42=""),"",(D42-E42)*$O$4) -> 18733.35 | G42: 2.86 | H42: =IF(F42="","",(F42-J42)*$O$5) -> 241.66021 | I42: =IF(F42="","",(F42-J42)*(1-$O$5)*$O$7) -> 36.058794 | J42: {=IF(F42="","",IF(ROW()=MAX(IF($C$32:$C$47=C42,ROW($C$32:$C$47),0)),MAX(0,IFERROR(VLOOKUP(C42,$A$10:$L$13,6,FALSE)-VLOOKUP(C42,$A$10:$L$13,5,FALSE),0)),0))} -> 0 | K42: =IF(F42="","",F42-H42-I42-J42) -> 18455.631 | L42: =IF(F42="","",(F42-J42)/VLOOKUP(C42,$A$10:$L$13,5,FALSE)*VLOOKUP(C42,$A$10:$L$13,10,FALSE)*$O$8) -> 77.475061 | M42: {=IF(F42="","",IF(IFERROR(VLOOKUP(C42,$A$10:$M$13,13,FALSE),"")="FULL",IF(ROW()=MIN(IF($C$32:$C$47=C42,ROW($C$32:$C$47),10^9)),VLOOKUP(C42,$A$10:$M$13,11,FALSE),0),(F42-J42)/VLOOKUP(C42,$A$10:$M$13,5,FALSE)*VLOOKUP(C42,$A$10:$M$13,11,FALSE)))} -> 528.27181 | N42: =IF(F42="","",IFERROR(VLOOKUP(C42,$A$10:$L$13,12,FALSE),0)*$O$9) -> 85.8
...

Sheet WODO
A1: BATCH HEADER — Charm WODO (IBC Totes)
A2: Batch ID (INJ-YYYY-WXX) | B2: INJ-08-2026-W2 | K2: Constants
A3: Week Start (Sat) | B3: 46235 | K3: Lbs/Kg | L3: 2.20462
A4: Week End (Sat) | B4: 46242 | K4: Kg/Lbs | L4: 0.453592
K5: Sparging Mass Loss | L5: 0.0129
K6: pH range (target) | L6: 2.0 - 4.0
K7: WODO 6-Mo CI (kg CO2e/kg), Jul-Dec 2026 | L7: 0.795241
A8: SECTION 1 - IBC LEDGER (one row per IBC tote; tote tag mass is authoritative) | K8: WODO Standard Loss (kg/tote), 2026 = Mean + 1 SD | L8: 7.84 | M8: =HYPERLINK("https://docs.google.com/spreadsheets/d/15fnYOYMmu-7a-p8Alst6mAOsV7X854y6HBDYwQRUm5s/edit","Tote Loss Dataset") -> Tote Loss Dataset
B9: Transport Emissions | D9: Pyrolysis Emissions Mass & Standard Loss | F9: MOBI | K9: Per-Production-Month CI (kg CO2e/kg) - PP Summary Output Type table, col T
A10: Tag | B10: Gross Mass (kg) | C10: Tote Mass (kg) | D10: Net Oil Produced (kg) | E10: Standard Loss (kg) | F10: Net Oil Injected (kg) | G10: Production Period | H10: Carbon Intensity | I10: Production Emissions | J10: Scale Uncertainty | K10: PP#8 | L10: 0.71282902 | M10: =HYPERLINK("https://docs.google.com/spreadsheets/d/1L167k_JS3mnisFy3VpS-OXgI8U0cK-4nC6A9sxl-ozk/edit","PP Summary") -> PP Summary
A11: 301011 | B11: 1229 | C11: 57.6 | D11: =B11-C11 -> 1171.4 | E11: =$L$8 -> 7.84 | F11: =D11-E11 -> 1163.56 | G11: MFO Lot 4768 (LOT00004768), February 2026 | H11: =$L$14 -> 0.84989612 | I11: =IF(H11="","",H11*D11) -> 995.56832 | J11: =2.5*$L$4 -> 1.13398 | K11: 45962 | L11: 0.97484085 | M11: =HYPERLINK("https://docs.google.com/spreadsheets/d/1W8jWu3sp39WnSuds1Ja0FWDG5UuWN9v5NUmF6yh_WbI/edit","PP Summary") -> PP Summary
A12: 300051 | B12: 1103 | C12: 57.6 | D12: =B12-C12 -> 1045.4 | E12: =$L$8 -> 7.84 | F12: =D12-E12 -> 1037.56 | G12: MFO Lot 4771 (LOT00004771), February 2026 | H12: =$L$14 -> 0.84989612 | I12: =IF(H12="","",H12*D12) -> 888.48141 | J12: =2.5*$L$4 -> 1.13398 | K12: 45992 | L12: 0.97218282 | M12: =HYPERLINK("https://docs.google.com/spreadsheets/d/1-L6m2wYknC3o-yIts9KK7FrYAb5lZIv4AwaizK8FbMc/edit","PP Summary") -> PP Summary
A13: 301031 | B13: 1151 | C13: 57.6 | D13: =B13-C13 -> 1093.4 | E13: =$L$8 -> 7.84 | F13: =D13-E13 -> 1085.56 | G13: MFO Lot 4793 (LOT00004793), February 2026 | H13: =$L$14 -> 0.84989612 | I13: =IF(H13="","",H13*D13) -> 929.27642 | J13: =2.5*$L$4 -> 1.13398 | K13: 46023 | L13: 0.93199449 | M13: =HYPERLINK("https://docs.google.com/spreadsheets/d/1bPZ7pNsR5rv-om-BypF4lK3nczjn4HJNO2dzimwnx7E/edit","PP Summary") -> PP Summary
A14: 301199 | B14: 1180 | C14: 57.6 | D14: =B14-C14 -> 1122.4 | E14: =$L$8 -> 7.84 | F14: =D14-E14 -> 1114.56 | G14: MFO Lot 301199 (LOT00301199), June 2026 | H14: =$L$18 -> 1.1105356 | I14: =IF(H14="","",H14*D14) -> 1246.4651 | J14: =2.5*$L$4 -> 1.13398 | K14: 46054 | L14: 0.84989612 | M14: =HYPERLINK("https://docs.google.com/spreadsheets/d/1vH7bborVnc-TCby3wEkpzi7GGMOI5jMJooEW0V-rOQ4/edit","PP Summary") -> PP Summary
A15: 301203 | B15: 1078 | C15: 57.6 | D15: =B15-C15 -> 1020.4 | E15: =$L$8 -> 7.84 | F15: =D15-E15 -> 1012.56 | G15: MFO Lot 301203 (LOT00301203), June 2026 | H15: =$L$18 -> 1.1105356 | I15: =IF(H15="","",H15*D15) -> 1133.1905 | J15: =2.5*$L$4 -> 1.13398 | K15: 46082 | L15: 0.79006453 | M15: =HYPERLINK("https://docs.google.com/spreadsheets/d/1O7y30opa_u1_deqFm_w2qgVyxi_75X00xnzKuyVyh6o/edit","PP Summary") -> PP Summary
A16: 301205 | B16: 1194 | C16: 57.6 | D16: =B16-C16 -> 1136.4 | E16: =$L$8 -> 7.84 | F16: =D16-E16 -> 1128.56 | G16: MFO Lot 301205 (LOT00301205), June 2026 | H16: =$L$18 -> 1.1105356 | I16: =IF(H16="","",H16*D16) -> 1262.0126 | J16: =2.5*$L$4 -> 1.13398 | K16: 46113 | L16: 0.78483234 | M16: =HYPERLINK("https://docs.google.com/spreadsheets/d/10Qwx7K6sUcOBrCebGUGVaVeLQnhzvcT8sHQ0Sy3VBBM/edit","PP Summary") -> PP Summary
A17: 301206 | B17: 1166 | C17: 57.6 | D17: =B17-C17 -> 1108.4 | E17: =$L$8 -> 7.84 | F17: =D17-E17 -> 1100.56 | G17: MFO Lot 301206 (LOT00301206), June 2026 | H17: =$L$18 -> 1.1105356 | I17: =IF(H17="","",H17*D17) -> 1230.9176 | J17: =2.5*$L$4 -> 1.13398 | K17: 46143 | L17: 0.63284589 | M17: =HYPERLINK("https://docs.google.com/spreadsheets/d/1m66t1jsLGc4e6AWnCFMsFbkSceZ9IYC_-bfTsbP_OYc/edit","PP Summary") -> PP Summary
A18: 301226 | B18: 1116 | C18: 57.6 | D18: =B18-C18 -> 1058.4 | E18: =$L$8 -> 7.84 | F18: =D18-E18 -> 1050.56 | G18: MFO Lot 301226 (LOT00301226), June 2026 | H18: =$L$18 -> 1.1105356 | I18: =IF(H18="","",H18*D18) -> 1175.3908 | J18: =2.5*$L$4 -> 1.13398 | K18: 46174 | L18: 1.1105356 | M18: =HYPERLINK("https://docs.google.com/spreadsheets/d/1MUQajDI2a_Cn9xWGPP7z4PhhphZnfl2_CSTnpB07Wgk/edit","PP Summary") -> PP Summary
A19: 301233 | B19: 1199 | C19: 57.6 | D19: =B19-C19 -> 1141.4 | E19: =$L$8 -> 7.84 | F19: =D19-E19 -> 1133.56 | G19: MFO Lot 301233 (LOT00301233), July 2026 | H19: =$L$19 -> 0.795241 | I19: =IF(H19="","",H19*D19) -> 907.68808 | J19: =2.5*$L$4 -> 1.13398 | K19: July 2026 and later (Jan-Jun 2026 rolling) | L19: =$L$7 -> 0.795241
A20: 301234 | B20: 1221 | C20: 57.6 | D20: =B20-C20 -> 1163.4 | E20: =$L$8 -> 7.84 | F20: =D20-E20 -> 1155.56 | G20: MFO Lot 301234 (LOT00301234), July 2026 | H20: =$L$19 -> 0.795241 | I20: =IF(H20="","",H20*D20) -> 925.18338 | J20: =2.5*$L$4 -> 1.13398
A21: 301235 | B21: 1149 | C21: 57.6 | D21: =B21-C21 -> 1091.4 | E21: =$L$8 -> 7.84 | F21: =D21-E21 -> 1083.56 | G21: MFO Lot 301235 (LOT00301235), July 2026 | H21: =$L$19 -> 0.795241 | I21: =IF(H21="","",H21*D21) -> 867.92603 | J21: =2.5*$L$4 -> 1.13398
A22: 301243 | B22: 1182 | C22: 57.6 | D22: =B22-C22 -> 1124.4 | E22: =$L$8 -> 7.84 | F22: =D22-E22 -> 1116.56 | G22: MFO Lot 301243 (LOT00301243), July 2026 | H22: =$L$19 -> 0.795241 | I22: =IF(H22="","",H22*D22) -> 894.16898 | J22: =2.5*$L$4 -> 1.13398
A23: 301248 | B23: 975 | C23: 57.6 | D23: =B23-C23 -> 917.4 | E23: =$L$8 -> 7.84 | F23: =D23-E23 -> 909.56 | G23: MFO Lot 301248 (LOT00301248), June 2026 | H23: =$L$18 -> 1.1105356 | I23: =IF(H23="","",H23*D23) -> 1018.8053 | J23: =2.5*$L$4 -> 1.13398
A24: 301256 | B24: 1154 | C24: 57.6 | D24: =B24-C24 -> 1096.4 | E24: =$L$8 -> 7.84 | F24: =D24-E24 -> 1088.56 | G24: MFO Lot 301256 (LOT00301256), June 2026 | H24: =$L$18 -> 1.1105356 | I24: =IF(H24="","",H24*D24) -> 1217.5912 | J24: =2.5*$L$4 -> 1.13398
A25: 301259 | B25: 1124 | C25: 57.6 | D25: =B25-C25 -> 1066.4 | E25: =$L$8 -> 7.84 | F25: =D25-E25 -> 1058.56 | G25: MFO Lot 301259 (LOT00301259), July 2026 | H25: =$L$19 -> 0.795241 | I25: =IF(H25="","",H25*D25) -> 848.045 | J25: =2.5*$L$4 -> 1.13398
A26: 301266 | B26: 1144 | C26: 57.6 | D26: =B26-C26 -> 1086.4 | E26: =$L$8 -> 7.84 | F26: =D26-E26 -> 1078.56 | G26: MFO Lot 301266 (LOT00301266), June 2026 | H26: =$L$18 -> 1.1105356 | I26: =IF(H26="","",H26*D26) -> 1206.4858 | J26: =2.5*$L$4 -> 1.13398
A27: 301293 | B27: 1218 | C27: 57.6 | D27: =B27-C27 -> 1160.4 | E27: =$L$8 -> 7.84 | F27: =D27-E27 -> 1152.56 | G27: MFO Lot 301293 (LOT00301293), June 2026 | H27: =$L$18 -> 1.1105356 | I27: =IF(H27="","",H27*D27) -> 1288.6655 | J27: =2.5*$L$4 -> 1.13398
A29: TOTAL | B29: =SUM(B11:B27) -> 19583 | C29: =SUM(C11:C27) -> 979.2 | D29: =SUM(D11:D27) -> 18603.8 | E29: =SUM(E11:E27) -> 133.28 | F29: =SUM(F11:F27) -> 18470.52 | H29: =IFERROR(SUMPRODUCT(D11:D27,H11:H27)/SUMIF(H11:H27,"<>",D11:D27),"") -> 0.96947194 | I29: =SUM(I11:I27) -> 18035.862 | J29: =SUM(J11:J27) -> 19.27766
A31: SECTION 2 - ROLLUP
A32: Transport Mass | B32: Σ Net Oil Produced (kg) | C32: Loss (kg) | D32: MOBI — Σ Net Oil Injected (kg) | E32: pH
A33: =B29 -> 19583 | B33: =SUM(D11:D27) -> 18603.8 | C33: =IF(D33=0,"",B33-D33) -> 133.28 | D33: =SUM(F11:F27) -> 18470.52 | E33: 2.86

Sheet AECN Truck
A1: BATCH HEADER — AECN Truck (Direct from Fort Lupton)
A2: Batch ID (INJ-YYYY-WXX) | B2: INJ-08-2026-W2 | K2: Constants
A3: Week Start (Sat) | B3: 46235 | K3: Lbs/Kg | L3: 2.20462
A4: Week End (Sat) | B4: 46242 | K4: Kg/Lbs | L4: 0.453592
K5: Sparging Mass Loss | L5: 0.0129
K6: pH range (target) | L6: 2.0 - 4.0
K7: Filtration Solids Content | L7: =HYPERLINK("https://docs.google.com/spreadsheets/d/16shKoa1KP34kQJyQvzclBejW9L5-ubNSqPsMOVB7zDY/edit?usp=sharing", 0.00195) -> 0.00195
A8: SECTION 1 - DELIVERIES LEDGER (one row per direct truck; BOL & scale ticket on same row)
A9: Date | B9: BOL # / SO # | C9: BOL Mass (MT) | D9: BOL Mass (kg) | E9: Scale Full (lb) | F9: Scale Empty (lb) | G9: Cargo (kg) | H9: pH | I9: Notes | J9: Sparging Loss (kg) | K9: Filtration Loss (kg) | L9: MOBI (kg) | M9: C Content
A26: SECTION 2 - ROLLUP (Mass Used = Σ BOL kg; scale tickets no longer required for direct trucks per 2026-05-26)
A27: Σ BOL (kg) | B27: Σ Cargo (kg) | C27: Mass Used (kg) | D27: Sparging Loss (kg) | E27: Filtration Loss (kg) | F27: Uncertainty Adjustment (kg) | G27: MOBI (kg) | H27: pH | I27: C Content (MOBI-wtd) | K27: Origins list (BOLs)
A28: =SUMIFS(D10:D24,B10:B24,"<>") -> 0 | B28: =SUMIFS(G10:G24,B10:B24,"<>") -> 0 | C28: =A28 -> 0 | D28: =C28*$L$5 -> 0 | E28: =(C28-D28)*$L$7 -> 0 | F28: 0 | G28: =C28-D28-E28-F28 -> 0 | H28: =IFERROR(AVERAGE(H10:H24),"") | I28: =IFERROR(SUMPRODUCT(L10:L24,M10:M24)/SUM(L10:L24),"") | K28: =IFERROR(__xludf.DUMMYFUNCTION("TRIM(TEXTJOIN("", "",TRUE,IFERROR(FILTER(B10:B24,B10:B24<>""""),"""")))"),"")

Sheet QOWV
A1: BATCH HEADER — QOWV (Aqueous Bio-Oil, IBC Totes)
A2: Batch ID (INJ-YYYY-WXX) | B2: INJ-08-2026-W2 | K2: Constants
A3: Week Start (Sat) | B3: 46235 | K3: Lbs/Kg | L3: 2.20462
A4: Week End (Sat) | B4: 46242 | K4: Kg/Lbs | L4: 0.453592
K5: Sparging Mass Loss | L5: 0.0129
K6: pH range (target) | L6: 2.0 - 4.0
K7: QOWV 6-Mo CI (kg CO2e/kg), Jul-Dec 2026 | L7: 0.120947
A8: SECTION 1 - IBC LEDGER (one row per IBC tote; tote tag mass is authoritative)
B9: Transport Emissions | D9: Pyrolysis Emissions Mass | F9: MOBI | K9: Per-Production-Month CI (kg CO2e/kg) - PP Summary Output Type table, col T
A10: Tag | B10: Gross Mass (kg) | C10: Tote Mass (kg) | D10: Net Oil Produced (kg) | E10: Empty Tote Weight (kg) | F10: Net Oil Injected (kg) | G10: Production Period | H10: Carbon Intensity | I10: Production Emissions | J10: Scale Uncertainty | K10: PP#8 | L10: 0.15755534 | M10: =HYPERLINK("https://docs.google.com/spreadsheets/d/1L167k_JS3mnisFy3VpS-OXgI8U0cK-4nC6A9sxl-ozk/edit","PP Summary") -> PP Summary
K11: 45962 | L11: 0.13921405 | M11: =HYPERLINK("https://docs.google.com/spreadsheets/d/1W8jWu3sp39WnSuds1Ja0FWDG5UuWN9v5NUmF6yh_WbI/edit","PP Summary") -> PP Summary
K12: 45992 | L12: 0.16306166 | M12: =HYPERLINK("https://docs.google.com/spreadsheets/d/1-L6m2wYknC3o-yIts9KK7FrYAb5lZIv4AwaizK8FbMc/edit","PP Summary") -> PP Summary
K13: 46023 | L13: 0.15683402 | M13: =HYPERLINK("https://docs.google.com/spreadsheets/d/1bPZ7pNsR5rv-om-BypF4lK3nczjn4HJNO2dzimwnx7E/edit","PP Summary") -> PP Summary
K14: 46054 | L14: 0.13304979 | M14: =HYPERLINK("https://docs.google.com/spreadsheets/d/1vH7bborVnc-TCby3wEkpzi7GGMOI5jMJooEW0V-rOQ4/edit","PP Summary") -> PP Summary
K15: 46082 | L15: 0.11852515 | M15: =HYPERLINK("https://docs.google.com/spreadsheets/d/1O7y30opa_u1_deqFm_w2qgVyxi_75X00xnzKuyVyh6o/edit","PP Summary") -> PP Summary
K16: 46113 | L16: 0.13141845 | M16: =HYPERLINK("https://docs.google.com/spreadsheets/d/10Qwx7K6sUcOBrCebGUGVaVeLQnhzvcT8sHQ0Sy3VBBM/edit","PP Summary") -> PP Summary
K17: 46143 | L17: 0.11066158 | M17: =HYPERLINK("https://docs.google.com/spreadsheets/d/1m66t1jsLGc4e6AWnCFMsFbkSceZ9IYC_-bfTsbP_OYc/edit","PP Summary") -> PP Summary
K18: 46174 | L18: 0.12368967 | M18: =HYPERLINK("https://docs.google.com/spreadsheets/d/1MUQajDI2a_Cn9xWGPP7z4PhhphZnfl2_CSTnpB07Wgk/edit","PP Summary") -> PP Summary
K19: July 2026 and later (Jan-Jun 2026 rolling) | L19: =$L$7 -> 0.120947
A77: TOTAL | B77: =SUM(B11:B75) -> 0 | C77: =SUM(C11:C75) -> 0 | D77: =SUM(D11:D75) -> 0 | E77: =SUM(E11:E75) -> 0 | F77: =SUM(F11:F75) -> 0 | H77: =IFERROR(SUMPRODUCT(D11:D75,H11:H75)/SUMIF(H11:H75,"<>",D11:D75),"") | I77: =SUM(I11:I75) -> 0 | J77: =SUM(J11:J75) -> 0

Sheet Kerry
A1: BATCH HEADER — Kerry (Calciner Waste Oil, IBC Totes)
A2: Batch ID (INJ-YYYY-WXX) | B2: INJ-08-2026-W2 | N2: Constants
A3: Week Start (Sat) | B3: 46235 | N3: Lbs/Kg | O3: 2.20462
A4: Week End (Sat) | B4: 46242 | N4: Kg/Lbs | O4: 0.453592
N5: Filtration Solids Content (Kerry Calciner) | O5: 0.00071
N6: pH range (target) | O6: 2.0 - 4.0
N7: Testing Uncertainty | O7: 0.004
A8: SECTION 1 - IBC LEDGER (one row per Kerry tote; tote tag mass is authoritative)
A9: Date | B9: UID | C9: Full Ticket (lb) | D9: Empty Ticket 2 (lb) | E9: Gross Mass (kg) — transport | F9: Net Oil (kg) | G9: Net Injected (kg) — MOBI | H9: pH | I9: Notes | J9: C Content | K9: C Content Uncertainty | L9: Mass Uncertainty (Scaling)
A31: SECTION 2 - ROLLUP
A32: Σ Net Oil — pre-filtration (kg) | B32: Filtration Loss (kg) | E32: MOBI (kg) | F32: pH | G32: C Content (MOBI-wtd) | I32: Origins list (Tote tags)
A33: =SUMIFS(F10:F29,B10:B29,"<>") -> 0 | B33: =A33*$O$5 -> 0 | E33: =A33-B33 -> 0 | F33: =IFERROR(AVERAGE(H10:H29),"") | G33: =IFERROR(__xludf.DUMMYFUNCTION("IFERROR(AVERAGE.WEIGHTED(J10:J29,G10:G29),"""")"),"") | I33: =IFERROR(__xludf.DUMMYFUNCTION("TRIM(TEXTJOIN("", "",TRUE,IFERROR(FILTER(B10:B29,B10:B29<>""""),"""")))"),"")

Sheet QOWV Shipments & EE Allocation
A1: INJ-08-2026-W2 — QOWV Shipments & EE Mileage Allocation
A4: BATCH SUMMARY
A5: Batch | B5: Fraction | C5: Inj. Week | D5: # Totes | E5: Shipping Orders (relevant totes)
A6: INJ-08-2026-W2 | B6: QOWV | C6: 2026-08-01 to 2026-08-08 | D6: =COUNTA(QOWV!A11:A75) -> 0 | E6: PENDING - no truck manifest yet
A8: Charm CO -> Basco LA distance (one-way mi) | B8: 1201
A10: EE ALLOCATION TABLE
A11: Truck (shipping order) | B11: Ship Date | C11: Total Totes on Truck | D11: Batch-Relevant Totes | E11: Batch Share of Truck | F11: Mileage (one-way) | G11: Allocated Miles

Sheet WODO Shipments & EE Allocation
A1: INJ-08-2026-W2 — WODO Shipments & EE Mileage Allocation
A4: BATCH SUMMARY
A5: Batch | B5: Fraction | C5: Inj. Week | D5: # Totes | E5: Shipping Orders (relevant totes)
A6: INJ-08-2026-W2 | B6: WODO | C6: 2026-08-01 to 2026-08-08 | D6: =COUNTA(WODO!A11:A27) -> 17 | E6: 1 shipping order(s): COLA28
A8: Charm CO -> Basco LA distance (one-way mi) | B8: 1201
A10: EE ALLOCATION TABLE
A11: Truck (shipping order) | B11: Ship Date | C11: Total Totes on Truck | D11: Batch-Relevant Totes | E11: Batch Share of Truck | F11: Mileage (one-way) | G11: Allocated Miles
A12: COLA28 | B12: 46230 | C12: 20 | D12: 17 | E12: =IFERROR(D12/C12,"") -> 0.85 | F12: =$B$8 -> 1201 | G12: =IFERROR(E12*F12,"") -> 1020.85
A14: TOTAL | C14: =SUM(C12) -> 20 | D14: =SUM(D12) -> 17 | G14: =SUM(G12) -> 1020.85
