Workbook

Sheet Summary
A1: BATCH SUMMARY
A2: Batch ID | B2: INJ-08-2026-W4
A3: Week Start (Sat) | B3: 46249
A4: Week End (Sat) | B4: 46256
A6: SECTION 1 - PER-TAB SUMMARY (each row pulls from its mode tab)
A7: Source Tab | B7: Σ Deliveries / Cargo (kg) | C7: Σ Uncertainty Adj (kg) | D7: Mass Used (kg) | E7: Sparging Loss (kg) | F7: Filtration Loss (kg) | G7: MOBI (kg) | H7: AECN→SOPOR EE (mi) | I7: Rail EE (mi) | J7: Opel→Basco EE (mi)
A8: AECN Rail | B8: ='AECN Rail'!B65 -> 77718.453 | C8: ='AECN Rail'!C65 -> 0 | D8: ='AECN Rail'!D65 -> 77718.453 | E8: ='AECN Rail'!E65 -> 1002.568 | F8: ='AECN Rail'!F65 -> 149.59598 | G8: ='AECN Rail'!G65 -> 76566.289 | H8: =SUM('AECN Rail'!L39:L60) -> 321.08892 | I8: =SUM('AECN Rail'!M39:M60) -> 2199 | J8: =SUM('AECN Rail'!N39:N60) -> 343.2
A9: AECN Truck | B9: ='AECN Truck'!A28 -> 78880 | C9: ='AECN Truck'!E28 -> 0 | D9: ='AECN Truck'!B28 -> 78880 | E9: ='AECN Truck'!C28 -> 1017.552 | F9: ='AECN Truck'!D28 -> 151.83177 | G9: ='AECN Truck'!F28 -> 77710.616
A10: Charm WODO | B10: =WODO!A33 -> 0 | C10: 0 | D10: =WODO!B33 -> 0 | E10: =WODO!C33 | F10: 0 | G10: =WODO!D33 -> 0
A11: Kerry | B11: =Kerry!A22 -> 0 | C11: 0 | D11: =Kerry!A22 -> 0 | E11: 0 | F11: =Kerry!B22 -> 0 | G11: =Kerry!C22 -> 0
A12: QOWV | B12: =QOWV!B55 -> 42850 | C12: 0 | D12: =QOWV!D55 -> 40430.8 | E12: 0 | F12: 0 | G12: =QOWV!F55 -> 36568.5
A13: TOTAL | B13: =SUM(B8:B12) -> 199448.45 | C13: =SUM(C8:C12) -> 0 | D13: =SUM(D8:D12) -> 197029.25 | E13: =SUM(E8:E12) -> 2020.12 | F13: =SUM(F8:F12) -> 301.42775 | G13: =SUM(G8:G12) -> 190845.41 | H13: =SUM(H8:H12) -> 321.08892 | I13: =SUM(I8:I12) -> 2199 | J13: =SUM(J8:J12) -> 343.2
A15: SECTION 2 - PER-OIL-TYPE ROLLUP (composite C% per oil type per week)
A16: Oil Type | B16: Transport Mass - upstream (kg) | C16: Transport Mass - downstream Opel→Basco (kg) | D16: Pyrolysis Mass (kg) | E16: MOBI - sequestration (kg) | F16: Composite Sample ID | G16: C % | H16: Lab COA Link | I16: C Content Uncertainty | J16: Testing Uncertainty
A17: AECN | B17: =SUM('AECN Rail'!I10:I15)+'AECN Truck'!A28 -> 156598.45 | C17: ='AECN Rail'!B65 -> 77718.453 | D17: =SUM('AECN Rail'!I10:I15)+'AECN Truck'!A28 -> 156598.45 | E17: ='AECN Rail'!G65+'AECN Truck'!F28 -> 154276.91 | F17: 08-2026-W4 AECN | G17: 0.404 | H17: =HYPERLINK("https://drive.google.com/file/d/1Mae3M6CniH9wjtb0iQmefJFZzMLBY8y7/view","COA SR26-05110.001") -> COA SR26-05110.001 | I17: =G17*J17 -> 0.001616 | J17: 0.004
A18: WODO | B18: =WODO!A33 -> 0 | D18: =WODO!B33 -> 0 | E18: =WODO!D33 -> 0 | I18: =G18*J18 -> 0 | J18: 0.004
A19: Kerry | B19: =Kerry!A22 -> 0 | D19: =Kerry!A22 -> 0 | E19: =Kerry!C22 -> 0 | G19: =IFERROR(__xludf.DUMMYFUNCTION("IFERROR(AVERAGE.WEIGHTED(Kerry!I10:I18,Kerry!F10:F18),"""")"),"") | I19: =G19*J19 -> 0 | J19: 0.004
A20: QOWV | B20: =QOWV!B55 -> 42850 | D20: =QOWV!D55 -> 40430.8 | E20: =QOWV!F55 -> 36568.5 | F20: 08-2026-W4 QOWV | G20: 0.081 | H20: =HYPERLINK("https://drive.google.com/file/d/1Mae3M6CniH9wjtb0iQmefJFZzMLBY8y7/view","COA SR26-05110.002") -> COA SR26-05110.002 | I20: =G20*J20 -> 0.000324 | J20: 0.004
A21: TOTAL | B21: =SUM(B17:B20) -> 199448.45 | C21: =SUM(C17:C20) -> 77718.453 | D21: =SUM(D17:D20) -> 197029.25 | E21: =SUM(E17:E20) -> 190845.41

Sheet AECN Rail
A1: BATCH HEADER — AECN Rail
A2: Batch ID (INJ-YYYY-WXX) | B2: INJ-08-2026-W4 | N2: Constants
A3: Week Start (Sat) | B3: 46249 | N3: Lbs/Kg | O3: 2.20462
A4: Week End (Sat) | B4: 46256 | N4: Kg/Lbs | O4: 0.453592
N5: Sparging Mass Loss | O5: 0.0129
N6: pH range (target) | O6: 2.0 - 4.0
N7: Filtration Solids Content | O7: =HYPERLINK("https://docs.google.com/spreadsheets/d/16shKoa1KP34kQJyQvzclBejW9L5-ubNSqPsMOVB7zDY/edit?usp=sharing", 0.00195) -> 0.00195
A8: SECTION 1 - RAILCARS RECEIVED THIS WEEK (entity-level) | I8: Pyrolysis Emissions Mass | N8: BOL Trips (AECN→SOPOR) | O8: 3
A9: Railcar # | B9: Arrival Date at Opelousas | C9: Loading BOLs (comma-sep) | D9: Total Loaded (MT) | E9: Total Loaded (kg) | F9: Total Offloaded (kg, auto) | G9: Loss (kg) | H9: Previously Claimed (kg) | I9: Claimed This Week (kg) | J9: AECN→SOPOR (mi) | K9: Rail (mi) | L9: Opel→Basco (mi) | M9: Full Railcar This Week? | N9: Round Trip (Opel→Basco) | O9: 2
A10: SHPX215076 | B10: 46256 | C10: 2402-R, 2403-R, 2404-R | D10: =SUMIF($C$19:$C$36,$A10,$D$19:$D$36) -> 78.06 | E10: =SUMIF($C$19:$C$36,$A10,$E$19:$E$36) -> 78060 | F10: =SUMIF($C$39:$C$60,A10,$F$39:$F$60)+H10 -> 77718.453 | G10: =IF(AND(E10<>"",F10<>"",F10>=0.95*E10),E10-F10,"") -> 341.54672 | H10: 0 | I10: =F10-H10 -> 77718.453 | J10: 107.5 | K10: 2199 | L10: 42.9 | M10: =IF(OR($E10="",$F10=""),"",IF(AND($H10=0,$F10>=0.95*$E10),"FULL","PARTIAL")) -> FULL
A17: SECTION 2 - ORIGINS LEDGER (loading BOLs at SOPOR)
A18: Date | B18: BOL # | C18: Railcar # | D18: BOL Mass (MT) | E18: BOL Mass (kg)
A19: 46198 | B19: =HYPERLINK("https://drive.google.com/file/d/1365pe_azW6UeuhrEeVETj3dLrYXTkgGH/view","2402-R") -> 2402-R | C19: SHPX215076 | D19: 26.04 | E19: =D19*1000 -> 26040
A20: 46199 | B20: =HYPERLINK("https://drive.google.com/file/d/1pj7sDlY7EnKLj9wcvy434XXHmplJiogi/view","2403-R") -> 2403-R | C20: SHPX215076 | D20: 26.04 | E20: =D20*1000 -> 26040
A21: 46199 | B21: =HYPERLINK("https://drive.google.com/file/d/1ji3cv2FKCP_K1ahxfXI7SyGBluiqw1Z-/view","2404-R") -> 2404-R | C21: SHPX215076 | D21: 25.98 | E21: =D21*1000 -> 25980
A37: SECTION 3 - SCALE TICKETS + OFFLOAD WEIGHTS
A38: Date | B38: Offload Key | C38: Railcar # | D38: Full Scale Ticket (lb) | E38: Empty Scale Ticket (lb) | F38: Net Scaled Mass (kg) | G38: pH | H38: Sparging Loss (kg) | I38: Filtration Loss (kg) | J38: Uncertainty Adjustment (kg) | K38: MOBI (kg) | L38: AECN→SOPOR (mi, x3 — full BOL) | M38: Rail (mi) — FULL railcar: flat 2199 on first offload; PARTIAL: offload-mass-basis allocation | N38: Opel→Basco (mi, x2 — downstream, per offload)
A39: 46256 | B39: Rail_SHPX215076_6.29.2026_offload_1 | C39: SHPX215076 | D39: =HYPERLINK("https://drive.google.com/file/d/1rdO2z0DvxK4FJuUFf1G1SzcUTIXm5cLU/view?usp=drivesdk", 71400) -> 71400 | E39: =HYPERLINK("https://drive.google.com/file/d/1JbALLHc5KIQtMtNo_TKIHEiHAhJFsJSG/view?usp=drivesdk", 28580) -> 28580 | F39: =IF(OR(D39="",E39=""),"",(D39-E39)*$O$4) -> 19422.809 | G39: 2.9 | H39: =IF(F39="","",(F39-J39)*$O$5) -> 250.55424 | I39: =IF(F39="","",(F39-J39)*(1-$O$5)*$O$7) -> 37.385898 | J39: {=IF(F39="","",IF(ROW()=MAX(IF($C$39:$C$60=C39,ROW($C$39:$C$60),0)),MAX(0,IFERROR(VLOOKUP(C39,$A$10:$L$15,6,FALSE)-VLOOKUP(C39,$A$10:$L$15,5,FALSE),0)),0))} -> 0 | K39: =IF(F39="","",F39-H39-I39-J39) -> 19134.869 | L39: =IF(F39="","",(F39-J39)/VLOOKUP(C39,$A$10:$L$15,5,FALSE)*VLOOKUP(C39,$A$10:$L$15,10,FALSE)*$O$8) -> 80.24412 | M39: {=IF(F39="","",IF(IFERROR(VLOOKUP(C39,$A$10:$M$15,13,FALSE),"")="FULL",IF(ROW()=MIN(IF($C$39:$C$60=C39,ROW($C$39:$C$60),10^9)),VLOOKUP(C39,$A$10:$M$15,11,FALSE),0),(F39-J39)/VLOOKUP(C39,$A$10:$M$15,5,FALSE)*VLOOKUP(C39,$A$10:$M$15,11,FALSE)))} -> 2199 | N39: =IF(F39="","",IFERROR(VLOOKUP(C39,$A$10:$L$15,12,FALSE),0)*$O$9) -> 85.8
A40: 46256 | B40: Rail_SHPX215076_6.29.2026_offload_2 | C40: SHPX215076 | D40: =HYPERLINK("https://drive.google.com/file/d/12dgYoF2RZ9sGSCKwlQIDHg_rxiemfjPs/view?usp=drivesdk", 73860) -> 73860 | E40: =HYPERLINK("https://drive.google.com/file/d/13kjXiHsc4i8WWkf9M7qb-lGQpTXqq-T9/view?usp=drivesdk", 29580) -> 29580 | F40: =IF(OR(D40="",E40=""),"",(D40-E40)*$O$4) -> 20085.054 | G40: 2.9 | H40: =IF(F40="","",(F40-J40)*$O$5) -> 259.09719 | I40: =IF(F40="","",(F40-J40)*(1-$O$5)*$O$7) -> 38.660615 | J40: {=IF(F40="","",IF(ROW()=MAX(IF($C$39:$C$60=C40,ROW($C$39:$C$60),0)),MAX(0,IFERROR(VLOOKUP(C40,$A$10:$L$15,6,FALSE)-VLOOKUP(C40,$A$10:$L$15,5,FALSE),0)),0))} -> 0 | K40: =IF(F40="","",F40-H40-I40-J40) -> 19787.296 | L40: =IF(F40="","",(F40-J40)/VLOOKUP(C40,$A$10:$L$15,5,FALSE)*VLOOKUP(C40,$A$10:$L$15,10,FALSE)*$O$8) -> 82.980141 | M40: {=IF(F40="","",IF(IFERROR(VLOOKUP(C40,$A$10:$M$15,13,FALSE),"")="FULL",IF(ROW()=MIN(IF($C$39:$C$60=C40,ROW($C$39:$C$60),10^9)),VLOOKUP(C40,$A$10:$M$15,11,FALSE),0),(F40-J40)/VLOOKUP(C40,$A$10:$M$15,5,FALSE)*VLOOKUP(C40,$A$10:$M$15,11,FALSE)))} -> 0 | N40: =IF(F40="","",IFERROR(VLOOKUP(C40,$A$10:$L$15,12,FALSE),0)*$O$9) -> 85.8
A41: 46256 | B41: Rail_SHPX215076_6.29.2026_offload_3 | C41: SHPX215076 | D41: =HYPERLINK("https://drive.google.com/file/d/1gkQEXgse9-QXHceQ_TVumEouT8tOz8fB/view?usp=drivesdk", 77960) -> 77960 | E41: =HYPERLINK("https://drive.google.com/file/d/1IlmShDZgS86aewv-cGbiK7gDK5I0xZWo/view?usp=drivesdk", 29400) -> 29400 | F41: =IF(OR(D41="",E41=""),"",(D41-E41)*$O$4) -> 22026.428 | G41: 2.9 | H41: =IF(F41="","",(F41-J41)*$O$5) -> 284.14092 | I41: =IF(F41="","",(F41-J41)*(1-$O$5)*$O$7) -> 42.397459 | J41: {=IF(F41="","",IF(ROW()=MAX(IF($C$39:$C$60=C41,ROW($C$39:$C$60),0)),MAX(0,IFERROR(VLOOKUP(C41,$A$10:$L$15,6,FALSE)-VLOOKUP(C41,$A$10:$L$15,5,FALSE),0)),0))} -> 0 | K41: =IF(F41="","",F41-H41-I41-J41) -> 21699.889 | L41: =IF(F41="","",(F41-J41)/VLOOKUP(C41,$A$10:$L$15,5,FALSE)*VLOOKUP(C41,$A$10:$L$15,10,FALSE)*$O$8) -> 91.000805 | M41: {=IF(F41="","",IF(IFERROR(VLOOKUP(C41,$A$10:$M$15,13,FALSE),"")="FULL",IF(ROW()=MIN(IF($C$39:$C$60=C41,ROW($C$39:$C$60),10^9)),VLOOKUP(C41,$A$10:$M$15,11,FALSE),0),(F41-J41)/VLOOKUP(C41,$A$10:$M$15,5,FALSE)*VLOOKUP(C41,$A$10:$M$15,11,FALSE)))} -> 0 | N41: =IF(F41="","",IFERROR(VLOOKUP(C41,$A$10:$L$15,12,FALSE),0)*$O$9) -> 85.8
A42: 46256 | B42: Rail_SHPX215076_6.29.2026_offload_4 | C42: SHPX215076 | D42: =HYPERLINK("https://drive.google.com/file/d/1NiwNUcVEev9zZjabMDJbTu_TzMkGJqHZ/view?usp=drivesdk", 64800) -> 64800 | E42: =HYPERLINK("https://drive.google.com/file/d/1Pds5AW0OcH7qqYP-Ku4mF3P3fU2vLQv1/view?usp=drivesdk", 29120) -> 29120 | F42: =IF(OR(D42="",E42=""),"",(D42-E42)*$O$4) -> 16184.163 | G42: 2.9 | H42: =IF(F42="","",(F42-J42)*$O$5) -> 208.7757 | I42: =IF(F42="","",(F42-J42)*(1-$O$5)*$O$7) -> 31.152004 | J42: {=IF(F42="","",IF(ROW()=MAX(IF($C$39:$C$60=C42,ROW($C$39:$C$60),0)),MAX(0,IFERROR(VLOOKUP(C42,$A$10:$L$15,6,FALSE)-VLOOKUP(C42,$A$10:$L$15,5,FALSE),0)),0))} -> 0 | K42: =IF(F42="","",F42-H42-I42-J42) -> 15944.235 | L42: =IF(F42="","",(F42-J42)/VLOOKUP(C42,$A$10:$L$15,5,FALSE)*VLOOKUP(C42,$A$10:$L$15,10,FALSE)*$O$8) -> 66.863854 | M42: {=IF(F42="","",IF(IFERROR(VLOOKUP(C42,$A$10:$M$15,13,FALSE),"")="FULL",IF(ROW()=MIN(IF($C$39:$C$60=C42,ROW($C$39:$C$60),10^9)),VLOOKUP(C42,$A$10:$M$15,11,FALSE),0),(F42-J42)/VLOOKUP(C42,$A$10:$M$15,5,FALSE)*VLOOKUP(C42,$A$10:$M$15,11,FALSE)))} -> 0 | N42: =IF(F42="","",IFERROR(VLOOKUP(C42,$A$10:$L$15,12,FALSE),0)*$O$9) -> 85.8
F43: =IF(OR(D43="",E43=""),"",(D43-E43)*$O$4) | H43: =IF(F43="","",(F43-J43)*$O$5) | I43: =IF(F43="","",(F43-J43)*(1-$O$5)*$O$7) | J43: {=IF(F43="","",IF(ROW()=MAX(IF($C$39:$C$60=C43,ROW($C$39:$C$60),0)),MAX(0,IFERROR(VLOOKUP(C43,$A$10:$L$15,6,FALSE)-VLOOKUP(C43,$A$10:$L$15,5,FALSE),0)),0))} | K43: =IF(F43="","",F43-H43-I43-J43) | L43: =IF(F43="","",(F43-J43)/VLOOKUP(C43,$A$10:$L$15,5,FALSE)*VLOOKUP(C43,$A$10:$L$15,10,FALSE)*$O$8) | M43: {=IF(F43="","",IF(IFERROR(VLOOKUP(C43,$A$10:$M$15,13,FALSE),"")="FULL",IF(ROW()=MIN(IF($C$39:$C$60=C43,ROW($C$39:$C$60),10^9)),VLOOKUP(C43,$A$10:$M$15,11,FALSE),0),(F43-J43)/VLOOKUP(C43,$A$10:$M$15,5,FALSE)*VLOOKUP(C43,$A$10:$M$15,11,FALSE)))} | N43: =IF(F43="","",IFERROR(VLOOKUP(C43,$A$10:$L$15,12,FALSE),0)*$O$9)
F44: =IF(OR(D44="",E44=""),"",(D44-E44)*$O$4) | H44: =IF(F44="","",(F44-J44)*$O$5) | I44: =IF(F44="","",(F44-J44)*(1-$O$5)*$O$7) | J44: {=IF(F44="","",IF(ROW()=MAX(IF($C$39:$C$60=C44,ROW($C$39:$C$60),0)),MAX(0,IFERROR(VLOOKUP(C44,$A$10:$L$15,6,FALSE)-VLOOKUP(C44,$A$10:$L$15,5,FALSE),0)),0))} | K44: =IF(F44="","",F44-H44-I44-J44) | L44: =IF(F44="","",(F44-J44)/VLOOKUP(C44,$A$10:$L$15,5,FALSE)*VLOOKUP(C44,$A$10:$L$15,10,FALSE)*$O$8) | M44: {=IF(F44="","",IF(IFERROR(VLOOKUP(C44,$A$10:$M$15,13,FALSE),"")="FULL",IF(ROW()=MIN(IF($C$39:$C$60=C44,ROW($C$39:$C$60),10^9)),VLOOKUP(C44,$A$10:$M$15,11,FALSE),0),(F44-J44)/VLOOKUP(C44,$A$10:$M$15,5,FALSE)*VLOOKUP(C44,$A$10:$M$15,11,FALSE)))} | N44: =IF(F44="","",IFERROR(VLOOKUP(C44,$A$10:$L$15,12,FALSE),0)*$O$9)
F45: =IF(OR(D45="",E45=""),"",(D45-E45)*$O$4) | H45: =IF(F45="","",(F45-J45)*$O$5) | I45: =IF(F45="","",(F45-J45)*(1-$O$5)*$O$7) | J45: {=IF(F45="","",IF(ROW()=MAX(IF($C$39:$C$60=C45,ROW($C$39:$C$60),0)),MAX(0,IFERROR(VLOOKUP(C45,$A$10:$L$15,6,FALSE)-VLOOKUP(C45,$A$10:$L$15,5,FALSE),0)),0))} | K45: =IF(F45="","",F45-H45-I45-J45) | L45: =IF(F45="","",(F45-J45)/VLOOKUP(C45,$A$10:$L$15,5,FALSE)*VLOOKUP(C45,$A$10:$L$15,10,FALSE)*$O$8) | M45: {=IF(F45="","",IF(IFERROR(VLOOKUP(C45,$A$10:$M$15,13,FALSE),"")="FULL",IF(ROW()=MIN(IF($C$39:$C$60=C45,ROW($C$39:$C$60),10^9)),VLOOKUP(C45,$A$10:$M$15,11,FALSE),0),(F45-J45)/VLOOKUP(C45,$A$10:$M$15,5,FALSE)*VLOOKUP(C45,$A$10:$M$15,11,FALSE)))} | N45: =IF(F45="","",IFERROR(VLOOKUP(C45,$A$10:$L$15,12,FALSE),0)*$O$9)
F46: =IF(OR(D46="",E46=""),"",(D46-E46)*$O$4) | H46: =IF(F46="","",(F46-J46)*$O$5) | I46: =IF(F46="","",(F46-J46)*(1-$O$5)*$O$7) | J46: {=IF(F46="","",IF(ROW()=MAX(IF($C$39:$C$60=C46,ROW($C$39:$C$60),0)),MAX(0,IFERROR(VLOOKUP(C46,$A$10:$L$15,6,FALSE)-VLOOKUP(C46,$A$10:$L$15,5,FALSE),0)),0))} | K46: =IF(F46="","",F46-H46-I46-J46) | L46: =IF(F46="","",(F46-J46)/VLOOKUP(C46,$A$10:$L$15,5,FALSE)*VLOOKUP(C46,$A$10:$L$15,10,FALSE)*$O$8) | M46: {=IF(F46="","",IF(IFERROR(VLOOKUP(C46,$A$10:$M$15,13,FALSE),"")="FULL",IF(ROW()=MIN(IF($C$39:$C$60=C46,ROW($C$39:$C$60),10^9)),VLOOKUP(C46,$A$10:$M$15,11,FALSE),0),(F46-J46)/VLOOKUP(C46,$A$10:$M$15,5,FALSE)*VLOOKUP(C46,$A$10:$M$15,11,FALSE)))} | N46: =IF(F46="","",IFERROR(VLOOKUP(C46,$A$10:$L$15,12,FALSE),0)*$O$9)
F47: =IF(OR(D47="",E47=""),"",(D47-E47)*$O$4) | H47: =IF(F47="","",(F47-J47)*$O$5) | I47: =IF(F47="","",(F47-J47)*(1-$O$5)*$O$7) | J47: {=IF(F47="","",IF(ROW()=MAX(IF($C$39:$C$60=C47,ROW($C$39:$C$60),0)),MAX(0,IFERROR(VLOOKUP(C47,$A$10:$L$15,6,FALSE)-VLOOKUP(C47,$A$10:$L$15,5,FALSE),0)),0))} | K47: =IF(F47="","",F47-H47-I47-J47) | L47: =IF(F47="","",(F47-J47)/VLOOKUP(C47,$A$10:$L$15,5,FALSE)*VLOOKUP(C47,$A$10:$L$15,10,FALSE)*$O$8) | M47: {=IF(F47="","",IF(IFERROR(VLOOKUP(C47,$A$10:$M$15,13,FALSE),"")="FULL",IF(ROW()=MIN(IF($C$39:$C$60=C47,ROW($C$39:$C$60),10^9)),VLOOKUP(C47,$A$10:$M$15,11,FALSE),0),(F47-J47)/VLOOKUP(C47,$A$10:$M$15,5,FALSE)*VLOOKUP(C47,$A$10:$M$15,11,FALSE)))} | N47: =IF(F47="","",IFERROR(VLOOKUP(C47,$A$10:$L$15,12,FALSE),0)*$O$9)
F48: =IF(OR(D48="",E48=""),"",(D48-E48)*$O$4) | H48: =IF(F48="","",(F48-J48)*$O$5) | I48: =IF(F48="","",(F48-J48)*(1-$O$5)*$O$7) | J48: {=IF(F48="","",IF(ROW()=MAX(IF($C$39:$C$60=C48,ROW($C$39:$C$60),0)),MAX(0,IFERROR(VLOOKUP(C48,$A$10:$L$15,6,FALSE)-VLOOKUP(C48,$A$10:$L$15,5,FALSE),0)),0))} | K48: =IF(F48="","",F48-H48-I48-J48) | L48: =IF(F48="","",(F48-J48)/VLOOKUP(C48,$A$10:$L$15,5,FALSE)*VLOOKUP(C48,$A$10:$L$15,10,FALSE)*$O$8) | M48: {=IF(F48="","",IF(IFERROR(VLOOKUP(C48,$A$10:$M$15,13,FALSE),"")="FULL",IF(ROW()=MIN(IF($C$39:$C$60=C48,ROW($C$39:$C$60),10^9)),VLOOKUP(C48,$A$10:$M$15,11,FALSE),0),(F48-J48)/VLOOKUP(C48,$A$10:$M$15,5,FALSE)*VLOOKUP(C48,$A$10:$M$15,11,FALSE)))} | N48: =IF(F48="","",IFERROR(VLOOKUP(C48,$A$10:$L$15,12,FALSE),0)*$O$9)
F49: =IF(OR(D49="",E49=""),"",(D49-E49)*$O$4) | H49: =IF(F49="","",(F49-J49)*$O$5) | I49: =IF(F49="","",(F49-J49)*(1-$O$5)*$O$7) | J49: {=IF(F49="","",IF(ROW()=MAX(IF($C$39:$C$60=C49,ROW($C$39:$C$60),0)),MAX(0,IFERROR(VLOOKUP(C49,$A$10:$L$15,6,FALSE)-VLOOKUP(C49,$A$10:$L$15,5,FALSE),0)),0))} | K49: =IF(F49="","",F49-H49-I49-J49) | L49: =IF(F49="","",(F49-J49)/VLOOKUP(C49,$A$10:$L$15,5,FALSE)*VLOOKUP(C49,$A$10:$L$15,10,FALSE)*$O$8) | M49: {=IF(F49="","",IF(IFERROR(VLOOKUP(C49,$A$10:$M$15,13,FALSE),"")="FULL",IF(ROW()=MIN(IF($C$39:$C$60=C49,ROW($C$39:$C$60),10^9)),VLOOKUP(C49,$A$10:$M$15,11,FALSE),0),(F49-J49)/VLOOKUP(C49,$A$10:$M$15,5,FALSE)*VLOOKUP(C49,$A$10:$M$15,11,FALSE)))} | N49: =IF(F49="","",IFERROR(VLOOKUP(C49,$A$10:$L$15,12,FALSE),0)*$O$9)
F50: =IF(OR(D50="",E50=""),"",(D50-E50)*$O$4) | H50: =IF(F50="","",(F50-J50)*$O$5) | I50: =IF(F50="","",(F50-J50)*(1-$O$5)*$O$7) | J50: {=IF(F50="","",IF(ROW()=MAX(IF($C$39:$C$60=C50,ROW($C$39:$C$60),0)),MAX(0,IFERROR(VLOOKUP(C50,$A$10:$L$15,6,FALSE)-VLOOKUP(C50,$A$10:$L$15,5,FALSE),0)),0))} | K50: =IF(F50="","",F50-H50-I50-J50) | L50: =IF(F50="","",(F50-J50)/VLOOKUP(C50,$A$10:$L$15,5,FALSE)*VLOOKUP(C50,$A$10:$L$15,10,FALSE)*$O$8) | M50: {=IF(F50="","",IF(IFERROR(VLOOKUP(C50,$A$10:$M$15,13,FALSE),"")="FULL",IF(ROW()=MIN(IF($C$39:$C$60=C50,ROW($C$39:$C$60),10^9)),VLOOKUP(C50,$A$10:$M$15,11,FALSE),0),(F50-J50)/VLOOKUP(C50,$A$10:$M$15,5,FALSE)*VLOOKUP(C50,$A$10:$M$15,11,FALSE)))} | N50: =IF(F50="","",IFERROR(VLOOKUP(C50,$A$10:$L$15,12,FALSE),0)*$O$9)
A61: EE Totals (rows 39-60) | L61: =SUM(L39:L60) -> 321.08892 | M61: =SUM(M39:M60) -> 2199 | N61: =SUM(N39:N60) -> 343.2
A63: SECTION 4 - ROLLUP (Mass Used = Deliveries - Uncertainty Adj)
A64: Pyrolysis + Upstream Transport (BOL, kg) | B64: Deliveries raw / Downstream Transport (scale tickets, kg) | C64: Uncertainty Adj (kg) | D64: Mass Used (post-adj) (kg) | E64: Sparging Loss (kg) | F64: Filtration Loss (kg) | G64: MOBI (kg) | H64: pH | N64: Origins list (BOLs)
A65: =SUM(I10:I15) -> 77718.453 | B65: =SUM(F39:F60) -> 77718.453 | C65: =SUM(J39:J60) -> 0 | D65: =B65-C65 -> 77718.453 | E65: =SUM(H39:H60) -> 1002.568 | F65: =SUM(I39:I60) -> 149.59598 | G65: =SUM(K39:K60) -> 76566.289 | H65: =IFERROR(AVERAGE(G39:G60),"") -> 2.9 | N65: =IFERROR(__xludf.DUMMYFUNCTION("TRIM(TEXTJOIN("", "",TRUE,IFERROR(FILTER(B19:B36,B19:B36<>""""),"""")))"),"2402-R, 2403-R, 2404-R") -> 2402-R, 2403-R, 2404-R

Sheet WODO
A1: BATCH HEADER — Charm WODO (IBC Totes)
A2: Batch ID (INJ-YYYY-WXX) | B2: INJ-08-2026-W4 | K2: Constants
A3: Week Start (Sat) | B3: 46249 | K3: Lbs/Kg | L3: 2.20462
A4: Week End (Sat) | B4: 46256 | K4: Kg/Lbs | L4: 0.453592
K5: Sparging Mass Loss | L5: 0.0129
K6: pH range (target) | L6: 2.0 - 4.0
K7: WODO 6-Mo CI (kg CO2e/kg), Jul-Dec 2026 | L7: 0.795241
A8: SECTION 1 - IBC LEDGER (one row per IBC tote; tote tag mass is authoritative) | K8: WODO Standard Loss (kg/tote), 2026 = Mean + 1 SD | L8: 7.84 | M8: =HYPERLINK("https://docs.google.com/spreadsheets/d/15fnYOYMmu-7a-p8Alst6mAOsV7X854y6HBDYwQRUm5s/edit","Tote Loss Dataset") -> Tote Loss Dataset
B9: Transport Emissions | D9: Pyrolysis Emissions Mass & Standard Loss | F9: MOBI | K9: Per-Production-Month CI (kg CO2e/kg) - PP Summary Output Type table, col T
A10: Tag | B10: Gross Mass (kg) | C10: Tote Mass (kg) | D10: Net Oil Produced (kg) | E10: Standard Loss (kg) | F10: Net Oil Injected (kg) | G10: Production Period | H10: Carbon Intensity | I10: Production Emissions | J10: Scale Uncertainty | K10: PP#8 | L10: 0.71282902 | M10: =HYPERLINK("https://docs.google.com/spreadsheets/d/1L167k_JS3mnisFy3VpS-OXgI8U0cK-4nC6A9sxl-ozk/edit","PP Summary") -> PP Summary
K11: 45962 | L11: 0.97484085 | M11: =HYPERLINK("https://docs.google.com/spreadsheets/d/1W8jWu3sp39WnSuds1Ja0FWDG5UuWN9v5NUmF6yh_WbI/edit","PP Summary") -> PP Summary
K12: 45992 | L12: 0.97218282 | M12: =HYPERLINK("https://docs.google.com/spreadsheets/d/1-L6m2wYknC3o-yIts9KK7FrYAb5lZIv4AwaizK8FbMc/edit","PP Summary") -> PP Summary
K13: 46023 | L13: 0.93199449 | M13: =HYPERLINK("https://docs.google.com/spreadsheets/d/1bPZ7pNsR5rv-om-BypF4lK3nczjn4HJNO2dzimwnx7E/edit","PP Summary") -> PP Summary
K14: 46054 | L14: 0.84989612 | M14: =HYPERLINK("https://docs.google.com/spreadsheets/d/1vH7bborVnc-TCby3wEkpzi7GGMOI5jMJooEW0V-rOQ4/edit","PP Summary") -> PP Summary
K15: 46082 | L15: 0.79006453 | M15: =HYPERLINK("https://docs.google.com/spreadsheets/d/1O7y30opa_u1_deqFm_w2qgVyxi_75X00xnzKuyVyh6o/edit","PP Summary") -> PP Summary
K16: 46113 | L16: 0.78483234 | M16: =HYPERLINK("https://docs.google.com/spreadsheets/d/10Qwx7K6sUcOBrCebGUGVaVeLQnhzvcT8sHQ0Sy3VBBM/edit","PP Summary") -> PP Summary
K17: 46143 | L17: 0.63284589 | M17: =HYPERLINK("https://docs.google.com/spreadsheets/d/1m66t1jsLGc4e6AWnCFMsFbkSceZ9IYC_-bfTsbP_OYc/edit","PP Summary") -> PP Summary
K18: 46174 | L18: 1.1105356 | M18: =HYPERLINK("https://docs.google.com/spreadsheets/d/1MUQajDI2a_Cn9xWGPP7z4PhhphZnfl2_CSTnpB07Wgk/edit","PP Summary") -> PP Summary
K19: July 2026 and later (Jan-Jun 2026 rolling) | L19: =$L$7 -> 0.795241
A29: TOTAL | B29: =SUM(B11:B27) -> 0 | C29: =SUM(C11:C27) -> 0 | D29: =SUM(D11:D27) -> 0 | E29: =SUM(E11:E27) -> 0 | F29: =SUM(F11:F27) -> 0 | H29: =IFERROR(SUMPRODUCT(D11:D27,H11:H27)/SUMIF(H11:H27,"<>",D11:D27),"") | I29: =SUM(I11:I27) -> 0 | J29: =SUM(J11:J27) -> 0
A31: SECTION 2 - ROLLUP
A32: Transport Mass | B32: Σ Net Oil Produced (kg) | C32: Loss (kg) | D32: MOBI — Σ Net Oil Injected (kg)
A33: =B29 -> 0 | B33: =SUM(D11:D27) -> 0 | C33: =IF(D33=0,"",B33-D33) | D33: =SUM(F11:F27) -> 0

Sheet AECN Truck
A1: BATCH HEADER — AECN Truck (Direct from Fort Lupton)
A2: Batch ID (INJ-YYYY-WXX) | B2: INJ-08-2026-W4 | K2: Constants
A3: Week Start (Sat) | B3: 46249 | K3: Lbs/Kg | L3: 2.20462
A4: Week End (Sat) | B4: 46256 | K4: Kg/Lbs | L4: 0.453592
K5: Sparging Mass Loss | L5: 0.0129
K6: pH range (target) | L6: 2.0 - 4.0
K7: Filtration Solids Content | L7: =HYPERLINK("https://docs.google.com/spreadsheets/d/16shKoa1KP34kQJyQvzclBejW9L5-ubNSqPsMOVB7zDY/edit?usp=sharing", 0.00195) -> 0.00195
A8: SECTION 1 - DELIVERIES LEDGER (one row per direct truck; BOL & scale ticket on same row)
A9: Date | B9: BOL # / SO # | C9: BOL Mass (MT) | D9: BOL Mass (kg) | E9: pH | F9: Notes | G9: Sparging Loss (kg) | H9: Filtration Loss (kg) | I9: MOBI (kg) | J9: EE
A10: 46256 | B10: =HYPERLINK("https://drive.google.com/file/d/1ZpVgshBO80bfKUnwVnMaMb_P_k6cUyPD/view","2471-T") -> 2471-T | C10: 19.56 | D10: =IF(C10="","",C10*1000) -> 19560 | E10: 2.9 | F10: AECN delivery 8/19/2026 | G10: =IF(D10="","",D10*$L$5) -> 252.324 | H10: =IF(D10="","",(D10-G10)*$L$7) -> 37.649968 | I10: =IF(D10="","",D10-G10-H10) -> 19270.026 | J10: 2197
A11: 46256 | B11: =HYPERLINK("https://drive.google.com/file/d/1Ui6mWOJa690VxgftBfLGtKZJ8r02z2y-/view","2472-T") -> 2472-T | C11: 19.87 | D11: =IF(C11="","",C11*1000) -> 19870 | E11: 2.9 | F11: AECN delivery 8/19/2026 | G11: =IF(D11="","",D11*$L$5) -> 256.323 | H11: =IF(D11="","",(D11-G11)*$L$7) -> 38.24667 | I11: =IF(D11="","",D11-G11-H11) -> 19575.43 | J11: 2197
A12: 46256 | B12: =HYPERLINK("https://drive.google.com/file/d/1VD4WRabpMMe_jtqlx0njI3KKdDWkkozz/view","2474-T") -> 2474-T | C12: 19.4 | D12: =IF(C12="","",C12*1000) -> 19400 | E12: 2.9 | F12: AECN delivery 8/22/2026 | G12: =IF(D12="","",D12*$L$5) -> 250.26 | H12: =IF(D12="","",(D12-G12)*$L$7) -> 37.341993 | I12: =IF(D12="","",D12-G12-H12) -> 19112.398 | J12: 2197
A13: 46256 | B13: =HYPERLINK("https://drive.google.com/file/d/1XWBZg6ynbPx0CVe_wkEG8uJzTpvz1V6c/view","2477-T") -> 2477-T | C13: 20.05 | D13: =IF(C13="","",C13*1000) -> 20050 | E13: 2.9 | F13: AECN delivery 8/21/2026 | G13: =IF(D13="","",D13*$L$5) -> 258.645 | H13: =IF(D13="","",(D13-G13)*$L$7) -> 38.593142 | I13: =IF(D13="","",D13-G13-H13) -> 19752.762 | J13: 2197
D14: =IF(C14="","",C14*1000) | G14: =IF(D14="","",D14*$L$5) | H14: =IF(D14="","",(D14-G14)*$L$7) | I14: =IF(D14="","",D14-G14-H14)
D15: =IF(C15="","",C15*1000) | G15: =IF(D15="","",D15*$L$5) | H15: =IF(D15="","",(D15-G15)*$L$7) | I15: =IF(D15="","",D15-G15-H15)
D16: =IF(C16="","",C16*1000) | G16: =IF(D16="","",D16*$L$5) | H16: =IF(D16="","",(D16-G16)*$L$7) | I16: =IF(D16="","",D16-G16-H16)
D17: =IF(C17="","",C17*1000) | G17: =IF(D17="","",D17*$L$5) | H17: =IF(D17="","",(D17-G17)*$L$7) | I17: =IF(D17="","",D17-G17-H17)
D18: =IF(C18="","",C18*1000) | G18: =IF(D18="","",D18*$L$5) | H18: =IF(D18="","",(D18-G18)*$L$7) | I18: =IF(D18="","",D18-G18-H18)
D19: =IF(C19="","",C19*1000) | G19: =IF(D19="","",D19*$L$5) | H19: =IF(D19="","",(D19-G19)*$L$7) | I19: =IF(D19="","",D19-G19-H19)
D20: =IF(C20="","",C20*1000) | G20: =IF(D20="","",D20*$L$5) | H20: =IF(D20="","",(D20-G20)*$L$7) | I20: =IF(D20="","",D20-G20-H20)
D21: =IF(C21="","",C21*1000) | G21: =IF(D21="","",D21*$L$5) | H21: =IF(D21="","",(D21-G21)*$L$7) | I21: =IF(D21="","",D21-G21-H21)
D22: =IF(C22="","",C22*1000) | G22: =IF(D22="","",D22*$L$5) | H22: =IF(D22="","",(D22-G22)*$L$7) | I22: =IF(D22="","",D22-G22-H22)
D23: =IF(C23="","",C23*1000) | G23: =IF(D23="","",D23*$L$5) | H23: =IF(D23="","",(D23-G23)*$L$7) | I23: =IF(D23="","",D23-G23-H23)
D24: =IF(C24="","",C24*1000) | G24: =IF(D24="","",D24*$L$5) | H24: =IF(D24="","",(D24-G24)*$L$7) | I24: =IF(D24="","",D24-G24-H24)
J25: =SUM(J10:J13) -> 8788
A26: SECTION 2 - ROLLUP (Mass Used = Σ BOL kg; scale tickets no longer required for direct trucks per 2026-05-26)
A27: Σ BOL (kg) | B27: Mass Used (kg) | C27: Sparging Loss (kg) | D27: Filtration Loss (kg) | E27: Uncertainty Adjustment (kg) | F27: MOBI (kg) | G27: pH
A28: =SUMIFS(D10:D24,B10:B24,"<>") -> 78880 | B28: =A28 -> 78880 | C28: =B28*$L$5 -> 1017.552 | D28: =(B28-C28)*$L$7 -> 151.83177 | E28: 0 | F28: =B28-C28-D28-E28 -> 77710.616 | G28: =IFERROR(AVERAGE(E10:E24),"") -> 2.9

Sheet Kerry
A1: BATCH HEADER — Kerry (Calciner Waste Oil, IBC Totes)
A2: Batch ID (INJ-YYYY-WXX) | B2: INJ-08-2026-W4 | N2: Constants
A3: Week Start (Sat) | B3: 46249 | N3: Lbs/Kg | O3: 2.20462
A4: Week End (Sat) | B4: 46256 | N4: Kg/Lbs | O4: 0.453592
N5: Filtration Solids Content (Kerry Calciner) | O5: =HYPERLINK("https://drive.google.com/file/d/1twIf0H9Ma4crVsPgD0Iq6eFDwxQIC-ni/view",0.00071) -> 0.00071
N6: pH range (target) | O6: 2.0 - 4.0
N7: Testing Uncertainty | O7: 0.004
A8: SECTION 1 - IBC LEDGER (one row per Kerry tote; tote tag mass is authoritative)
A9: Date | B9: Full Ticket (lb) | C9: Empty Ticket 2 (lb) | D9: Gross Mass (kg) — transport | E9: Net Oil (kg) | F9: Net Injected (kg) — MOBI | G9: pH | H9: Notes | I9: C Content | J9: C Content Uncertainty | K9: Mass Uncertainty (kg)
A20: SECTION 2 - ROLLUP
A21: Σ Net Oil — pre-filtration (kg) | B21: Filtration Loss (kg) | C21: MOBI (kg) | D21: pH
A22: =SUMIFS(E10:E18,A10:A18,"<>") -> 0 | B22: =A22*$O$5 -> 0 | C22: =A22-B22 -> 0 | D22: =IFERROR(AVERAGE(G10:G18),"")

Sheet QOWV
A1: BATCH HEADER — QOWV (Aqueous Bio-Oil, IBC Totes)
A2: Batch ID (INJ-YYYY-WXX) | B2: INJ-08-2026-W4 | K2: Constants
A3: Week Start (Sat) | B3: 46249 | K3: Lbs/Kg | L3: 2.20462
A4: Week End (Sat) | B4: 46256 | K4: Kg/Lbs | L4: 0.453592
K5: Sparging Mass Loss | L5: 0.0129
K6: pH range (target) | L6: 2.0 - 4.0
K7: QOWV 6-Mo CI (kg CO2e/kg), Jul-Dec 2026 | L7: 0.120947
A8: SECTION 1 - IBC LEDGER (one row per IBC tote; tote tag mass is authoritative)
B9: Transport Emissions | D9: Pyrolysis Emissions Mass | F9: MOBI | K9: Per-Production-Month CI (kg CO2e/kg) - PP Summary Output Type table, col T
A10: Tag | B10: Gross Mass (kg) | C10: Tote Mass (kg) | D10: Net Oil Produced (kg) | E10: Empty Tote Weight (kg) | F10: Net Oil Injected (kg) | G10: Production Period | H10: Carbon Intensity | I10: Production Emissions | J10: Scale Uncertainty | K10: PP#8 | L10: 0.15755534 | M10: =HYPERLINK("https://docs.google.com/spreadsheets/d/1L167k_JS3mnisFy3VpS-OXgI8U0cK-4nC6A9sxl-ozk/edit","PP Summary") -> PP Summary
A11: 301000 | B11: 952 | C11: 57.6 | D11: =B11-C11 -> 894.4 | E11: 147.5 | F11: =IF(E11="","",B11-E11) -> 804.5 | G11: MFO Lot 301000 (LOT00301000), March 2026 | H11: =$L$15 -> 0.11852515 | I11: =IF(H11="","",H11*D11) -> 106.0089 | J11: =2.5*$L$4 -> 1.13398 | K11: 45962 | L11: 0.13921405 | M11: =HYPERLINK("https://docs.google.com/spreadsheets/d/1W8jWu3sp39WnSuds1Ja0FWDG5UuWN9v5NUmF6yh_WbI/edit","PP Summary") -> PP Summary
A12: 301005 | B12: 1001 | C12: 57.6 | D12: =B12-C12 -> 943.4 | E12: 171 | F12: =IF(E12="","",B12-E12) -> 830 | G12: MFO Lot 301005 (LOT00301005), April 2026 | H12: =$L$16 -> 0.13141845 | I12: =IF(H12="","",H12*D12) -> 123.98017 | J12: =2.5*$L$4 -> 1.13398 | K12: 45992 | L12: 0.16306166 | M12: =HYPERLINK("https://docs.google.com/spreadsheets/d/1-L6m2wYknC3o-yIts9KK7FrYAb5lZIv4AwaizK8FbMc/edit","PP Summary") -> PP Summary
A13: 301008 | B13: 1014 | C13: 57.6 | D13: =B13-C13 -> 956.4 | E13: 153.5 | F13: =IF(E13="","",B13-E13) -> 860.5 | G13: MFO Lot 301008 (LOT00301008), April 2026 | H13: =$L$16 -> 0.13141845 | I13: =IF(H13="","",H13*D13) -> 125.68861 | J13: =2.5*$L$4 -> 1.13398 | K13: 46023 | L13: 0.15683402 | M13: =HYPERLINK("https://docs.google.com/spreadsheets/d/1bPZ7pNsR5rv-om-BypF4lK3nczjn4HJNO2dzimwnx7E/edit","PP Summary") -> PP Summary
A14: 301013 | B14: 1019 | C14: 57.6 | D14: =B14-C14 -> 961.4 | E14: 142.5 | F14: =IF(E14="","",B14-E14) -> 876.5 | G14: MFO Lot 301013 (LOT00301013), March 2026 | H14: =$L$15 -> 0.11852515 | I14: =IF(H14="","",H14*D14) -> 113.95008 | J14: =2.5*$L$4 -> 1.13398 | K14: 46054 | L14: 0.13304979 | M14: =HYPERLINK("https://docs.google.com/spreadsheets/d/1vH7bborVnc-TCby3wEkpzi7GGMOI5jMJooEW0V-rOQ4/edit","PP Summary") -> PP Summary
A15: 301015 | B15: 995 | C15: 57.6 | D15: =B15-C15 -> 937.4 | E15: 138 | F15: =IF(E15="","",B15-E15) -> 857 | G15: MFO Lot 301015 (LOT00301015), March 2026 | H15: =$L$15 -> 0.11852515 | I15: =IF(H15="","",H15*D15) -> 111.10548 | J15: =2.5*$L$4 -> 1.13398 | K15: 46082 | L15: 0.11852515 | M15: =HYPERLINK("https://docs.google.com/spreadsheets/d/1O7y30opa_u1_deqFm_w2qgVyxi_75X00xnzKuyVyh6o/edit","PP Summary") -> PP Summary
A16: 301019 | B16: 1031 | C16: 57.6 | D16: =B16-C16 -> 973.4 | E16: 158.5 | F16: =IF(E16="","",B16-E16) -> 872.5 | G16: MFO Lot 301019 (LOT00301019), March 2026 | H16: =$L$15 -> 0.11852515 | I16: =IF(H16="","",H16*D16) -> 115.37238 | J16: =2.5*$L$4 -> 1.13398 | K16: 46113 | L16: 0.13141845 | M16: =HYPERLINK("https://docs.google.com/spreadsheets/d/10Qwx7K6sUcOBrCebGUGVaVeLQnhzvcT8sHQ0Sy3VBBM/edit","PP Summary") -> PP Summary
A17: 301021 | B17: 1074 | C17: 57.6 | D17: =B17-C17 -> 1016.4 | E17: 166 | F17: =IF(E17="","",B17-E17) -> 908 | G17: MFO Lot 301021 (LOT00301021), April 2026 | H17: =$L$16 -> 0.13141845 | I17: =IF(H17="","",H17*D17) -> 133.57372 | J17: =2.5*$L$4 -> 1.13398 | K17: 46143 | L17: 0.11066158 | M17: =HYPERLINK("https://docs.google.com/spreadsheets/d/1m66t1jsLGc4e6AWnCFMsFbkSceZ9IYC_-bfTsbP_OYc/edit","PP Summary") -> PP Summary
A18: 301022 | B18: 1041 | C18: 57.6 | D18: =B18-C18 -> 983.4 | E18: 154 | F18: =IF(E18="","",B18-E18) -> 887 | G18: MFO Lot 301022 (LOT00301022), April 2026 | H18: =$L$16 -> 0.13141845 | I18: =IF(H18="","",H18*D18) -> 129.23691 | J18: =2.5*$L$4 -> 1.13398 | K18: 46174 | L18: 0.12368967 | M18: =HYPERLINK("https://docs.google.com/spreadsheets/d/1MUQajDI2a_Cn9xWGPP7z4PhhphZnfl2_CSTnpB07Wgk/edit","PP Summary") -> PP Summary
A19: 301029 | B19: 941 | C19: 57.6 | D19: =B19-C19 -> 883.4 | E19: 148 | F19: =IF(E19="","",B19-E19) -> 793 | G19: MFO Lot 301029 (LOT00301029), March 2026 | H19: =$L$15 -> 0.11852515 | I19: =IF(H19="","",H19*D19) -> 104.70512 | J19: =2.5*$L$4 -> 1.13398 | K19: July 2026 and later (Jan-Jun 2026 rolling) | L19: =$L$7 -> 0.120947
A20: 301038 | B20: 1031 | C20: 57.6 | D20: =B20-C20 -> 973.4 | E20: 156.5 | F20: =IF(E20="","",B20-E20) -> 874.5 | G20: MFO Lot 301038 (LOT00301038), March 2026 | H20: =$L$15 -> 0.11852515 | I20: =IF(H20="","",H20*D20) -> 115.37238 | J20: =2.5*$L$4 -> 1.13398 | K20: PP#7 | L20: 0.13736711 | M20: =HYPERLINK("https://docs.google.com/spreadsheets/d/1qPyS0H9Wx8z2vMl_3ANE1YLYahKLeL1Qo8OmZ_ol9aI/edit","PP Summary") -> PP Summary
A21: 301044 | B21: 1067 | C21: 57.6 | D21: =B21-C21 -> 1009.4 | E21: 145 | F21: =IF(E21="","",B21-E21) -> 922 | G21: MFO Lot 301044 (LOT00301044), March 2026 | H21: =$L$15 -> 0.11852515 | I21: =IF(H21="","",H21*D21) -> 119.63929 | J21: =2.5*$L$4 -> 1.13398
A22: 301045 | B22: 1166 | C22: 57.6 | D22: =B22-C22 -> 1108.4 | E22: 145.5 | F22: =IF(E22="","",B22-E22) -> 1020.5 | G22: MFO Lot 301045 (LOT00301045), March 2026 | H22: =$L$15 -> 0.11852515 | I22: =IF(H22="","",H22*D22) -> 131.37328 | J22: =2.5*$L$4 -> 1.13398
A23: 301046 | B23: 1053 | C23: 57.6 | D23: =B23-C23 -> 995.4 | E23: 166.5 | F23: =IF(E23="","",B23-E23) -> 886.5 | G23: MFO Lot 301046 (LOT00301046), March 2026 | H23: =$L$15 -> 0.11852515 | I23: =IF(H23="","",H23*D23) -> 117.97994 | J23: =2.5*$L$4 -> 1.13398
A24: 301048 | B24: 855 | C24: 57.6 | D24: =B24-C24 -> 797.4 | E24: 172 | F24: =IF(E24="","",B24-E24) -> 683 | G24: MFO Lot 301048 (LOT00301048), April 2026 | H24: =$L$16 -> 0.13141845 | I24: =IF(H24="","",H24*D24) -> 104.79307 | J24: =2.5*$L$4 -> 1.13398
A25: 301049 | B25: 957 | C25: 57.6 | D25: =B25-C25 -> 899.4 | E25: 148.5 | F25: =IF(E25="","",B25-E25) -> 808.5 | G25: MFO Lot 301049 (LOT00301049), March 2026 | H25: =$L$15 -> 0.11852515 | I25: =IF(H25="","",H25*D25) -> 106.60152 | J25: =2.5*$L$4 -> 1.13398
A26: 301056 | B26: 1018 | C26: 57.6 | D26: =B26-C26 -> 960.4 | E26: 90 | F26: =IF(E26="","",B26-E26) -> 928 | G26: MFO Lot 301056 (LOT00301056), April 2026 | H26: =$L$16 -> 0.13141845 | I26: =IF(H26="","",H26*D26) -> 126.21428 | J26: =2.5*$L$4 -> 1.13398
A27: 301059 | B27: 1022 | C27: 57.6 | D27: =B27-C27 -> 964.4 | E27: 145.5 | F27: =IF(E27="","",B27-E27) -> 876.5 | G27: MFO Lot 301059 (LOT00301059), March 2026 | H27: =$L$15 -> 0.11852515 | I27: =IF(H27="","",H27*D27) -> 114.30566 | J27: =2.5*$L$4 -> 1.13398
A28: 301061 | B28: 1023 | C28: 57.6 | D28: =B28-C28 -> 965.4 | E28: 148.5 | F28: =IF(E28="","",B28-E28) -> 874.5 | G28: MFO Lot 301061 (LOT00301061), March 2026 | H28: =$L$15 -> 0.11852515 | I28: =IF(H28="","",H28*D28) -> 114.42418 | J28: =2.5*$L$4 -> 1.13398
A29: 301069 | B29: 985 | C29: 57.6 | D29: =B29-C29 -> 927.4 | E29: 152 | F29: =IF(E29="","",B29-E29) -> 833 | G29: MFO Lot 301069 (LOT00301069), March 2026 | H29: =$L$15 -> 0.11852515 | I29: =IF(H29="","",H29*D29) -> 109.92023 | J29: =2.5*$L$4 -> 1.13398
A30: 301071 | B30: 1026 | C30: 57.6 | D30: =B30-C30 -> 968.4 | E30: 153 | F30: =IF(E30="","",B30-E30) -> 873 | G30: MFO Lot 301071 (LOT00301071), March 2026 | H30: =$L$15 -> 0.11852515 | I30: =IF(H30="","",H30*D30) -> 114.77976 | J30: =2.5*$L$4 -> 1.13398
A31: 301073 | B31: 1058 | C31: 57.6 | D31: =B31-C31 -> 1000.4 | E31: 139 | F31: =IF(E31="","",B31-E31) -> 919 | G31: MFO Lot 301073 (LOT00301073), March 2026 | H31: =$L$15 -> 0.11852515 | I31: =IF(H31="","",H31*D31) -> 118.57256 | J31: =2.5*$L$4 -> 1.13398
A32: 301077 | B32: 1075 | C32: 57.6 | D32: =B32-C32 -> 1017.4 | E32: 158.5 | F32: =IF(E32="","",B32-E32) -> 916.5 | G32: MFO Lot 301077 (LOT00301077), March 2026 | H32: =$L$15 -> 0.11852515 | I32: =IF(H32="","",H32*D32) -> 120.58749 | J32: =2.5*$L$4 -> 1.13398
A33: 301079 | B33: 1072 | C33: 57.6 | D33: =B33-C33 -> 1014.4 | E33: 160 | F33: =IF(E33="","",B33-E33) -> 912 | G33: MFO Lot 301079 (LOT00301079), April 2026 | H33: =$L$16 -> 0.13141845 | I33: =IF(H33="","",H33*D33) -> 133.31088 | J33: =2.5*$L$4 -> 1.13398
A34: 301084 | B34: 1030 | C34: 57.6 | D34: =B34-C34 -> 972.4 | E34: 140 | F34: =IF(E34="","",B34-E34) -> 890 | G34: MFO Lot 301084 (LOT00301084), March 2026 | H34: =$L$15 -> 0.11852515 | I34: =IF(H34="","",H34*D34) -> 115.25386 | J34: =2.5*$L$4 -> 1.13398
A35: 301094 | B35: 1140 | C35: 57.6 | D35: =B35-C35 -> 1082.4 | E35: 167.5 | F35: =IF(E35="","",B35-E35) -> 972.5 | G35: MFO Lot 301094 (LOT00301094), March 2026 | H35: =$L$15 -> 0.11852515 | I35: =IF(H35="","",H35*D35) -> 128.29163 | J35: =2.5*$L$4 -> 1.13398
A36: 301099 | B36: 917 | C36: 57.6 | D36: =B36-C36 -> 859.4 | E36: 158.5 | F36: =IF(E36="","",B36-E36) -> 758.5 | G36: MFO Lot 301099 (LOT00301099), March 2026 | H36: =$L$15 -> 0.11852515 | I36: =IF(H36="","",H36*D36) -> 101.86052 | J36: =2.5*$L$4 -> 1.13398
A37: 120534 | B37: 1033 | C37: 57.6 | D37: =B37-C37 -> 975.4 | E37: 109.5 | F37: =IF(E37="","",B37-E37) -> 923.5 | G37: MFO Lot 2892 (LOT00002892), PP#8 | H37: =$L$10 -> 0.15755534 | I37: =IF(H37="","",H37*D37) -> 153.67948 | J37: =2.5*$L$4 -> 1.13398
A38: 15188 | B38: 1044 | C38: 57.6 | D38: =B38-C38 -> 986.4 | E38: 179 | F38: =IF(E38="","",B38-E38) -> 865 | G38: MFO Lot 3235 (LOT00003235), PP#8 | H38: =$L$10 -> 0.15755534 | I38: =IF(H38="","",H38*D38) -> 155.41259 | J38: =2.5*$L$4 -> 1.13398
A39: 228428 | B39: 1017 | C39: 57.6 | D39: =B39-C39 -> 959.4 | E39: 166 | F39: =IF(E39="","",B39-E39) -> 851 | G39: MFO Lot 4336 (LOT00004336), November 2025 | H39: =$L$11 -> 0.13921405 | I39: =IF(H39="","",H39*D39) -> 133.56196 | J39: =2.5*$L$4 -> 1.13398
A40: 228439 | B40: 925 | C40: 57.6 | D40: =B40-C40 -> 867.4 | E40: 142.5 | F40: =IF(E40="","",B40-E40) -> 782.5 | G40: MFO Lot 4338 (LOT00004338), November 2025 | H40: =$L$11 -> 0.13921405 | I40: =IF(H40="","",H40*D40) -> 120.75427 | J40: =2.5*$L$4 -> 1.13398
...

Sheet QOWV Shipments & EE Allocation
A1: INJ-08-2026-W4 - QOWV Shipments & EE Mileage Allocation
A4: BATCH SUMMARY
A5: Batch | B5: Fraction | C5: Inj. Week | D5: # Totes | E5: Shipping Orders (relevant totes)
A6: INJ-08-2026-W4 | B6: QOWV | C6: 2026-08-15 to 2026-08-22 | D6: =COUNTA(QOWV!A11:A53) -> 42 | E6: 6 shipping order(s) direct CO->LA: COLA_27, COLA_30, COLA21, COLA_29, COLA_25, Truck 2 (by Date Shipped) = 41 totes. Totals-on-truck counted from BGN master Ship Status. Plus 1 Kansas tote (118846) routed CO -> Charm KS -> Basco LA, allocated in table B below. 41 + 1 = 42.
A8: Charm CO -> Basco LA distance (one-way mi) | B8: 1201
A10: EE ALLOCATION TABLE - A. Direct Charm CO -> Basco LA
A11: Truck (shipping order) | B11: Ship Date | C11: Total Totes on Truck | D11: Batch-Relevant Totes | E11: Batch Share of Truck | F11: Mileage (one-way) | G11: Allocated Miles
A12: COLA_27 | B12: 46227 | C12: 20 | D12: 18 | E12: =IFERROR(D12/C12,"") -> 0.9 | F12: =$B$8 -> 1201 | G12: =IFERROR(E12*F12,"") -> 1080.9
A13: COLA_30 | B13: 46238 | C13: 20 | D13: 11 | E13: =IFERROR(D13/C13,"") -> 0.55 | F13: =$B$8 -> 1201 | G13: =IFERROR(E13*F13,"") -> 660.55
A14: COLA21 | C14: 20 | D14: 6 | E14: =IFERROR(D14/C14,"") -> 0.3 | F14: =$B$8 -> 1201 | G14: =IFERROR(E14*F14,"") -> 360.3
A15: COLA_29 | B15: 46237 | C15: 20 | D15: 2 | E15: =IFERROR(D15/C15,"") -> 0.1 | F15: =$B$8 -> 1201 | G15: =IFERROR(E15*F15,"") -> 120.1
A16: COLA_25 | B16: 46219 | C16: 20 | D16: 2 | E16: =IFERROR(D16/C16,"") -> 0.1 | F16: =$B$8 -> 1201 | G16: =IFERROR(E16*F16,"") -> 120.1
A17: Truck 2 (by Date Shipped) | B17: 45993 | C17: 36 | D17: 2 | E17: =IFERROR(D17/C17,"") -> 0.055555556 | F17: =$B$8 -> 1201 | G17: =IFERROR(E17*F17,"") -> 66.722222
A18: SUBTOTAL A - Direct | C18: =SUM(C12:C17) -> 136 | D18: =SUM(D12:D17) -> 41 | G18: =SUM(G12:G17) -> 2408.6722
A20: EE ALLOCATION TABLE - B. Via Kansas (Charm CO -> Charm KS -> Basco LA) tote tag(s): 118846
A21: Charm CO -> Charm KS distance (one-way mi) | B21: 537 | C21: =HYPERLINK("https://drive.google.com/file/d/17DLmRf2gOawFmCywpNFa-iReA4BzVVMu/view","Charm CO to Charm KS route map") -> Charm CO to Charm KS route map
A22: Charm KS -> Basco LA distance (one-way mi) | B22: 684 | C22: =HYPERLINK("https://drive.google.com/file/d/1fTT5YTSzi0Xc_7m-j21lb6Us_w9dZIa5/view","Charm KS to Charm LA route map") -> Charm KS to Charm LA route map
A23: Via-KS route total (one-way mi) | B23: =B21+B22 -> 1221 | C23: ="vs "&TEXT($B$8,"#,##0")&" mi direct ("&TEXT((B23-$B$8)/$B$8,"+0.0%")&")" -> vs 1,201 mi direct (+1.7%)
A25: Leg | B25: Ship Date | C25: Total Totes on Truck(s) | D25: Batch-Relevant Totes | E25: Batch Share of Truck(s) | F25: Mileage (one-way x trucks) | G25: Allocated Miles | H25: Trucks
A26: Leg 1 - Shipment #32/#33: Charm CO -> Charm KS | B26: 45951 | C26: 34 | D26: 1 | E26: =IFERROR(D26/C26,"") -> 0.029411765 | F26: =$B$21*H26 -> 1074 | G26: =IFERROR(E26*F26,"") -> 31.588235 | H26: 2
A27: Leg 2 - Charm KS -> Basco LA (repositioning) | B27: 2025 | C27: 6 | D27: 1 | E27: =IFERROR(D27/C27,"") -> 0.16666667 | F27: =$B$22*H27 -> 684 | G27: =IFERROR(E27*F27,"") -> 114 | H27: 1
A28: SUBTOTAL B - Via Kansas | G28: =SUM(G26:G27) -> 145.58824
A30: GRAND TOTAL ALLOCATED MILES (A + B) | G30: =G18+G28 -> 2554.2605
A32: Reconciliation - totes allocated vs QOWV ledger | B32: =D18+D27 -> 42 | C32: =COUNTA(QOWV!A11:A53) -> 42 | D32: =IF(B32=C32,"OK - every tote allocated","MISMATCH - check tote counts") -> OK - every tote allocated
A34: NOTES - Kansas-routed totes
A35: 1. Basis: these totes shipped Charm CO -> Charm KS on Shipment #32/#33 (2 trucks, 34 QOWV totes, shipped 2025-10-21; BGN master tab "QOWV totes to KS Shipment #32&33"), were stored at Charm KS, then repositioned Charm KS -> Basco LA. They never rode a direct CO->LA truck, so they are excluded from table A and allocated their actual two-leg route here.
A36: 2. Precedent: INJ-05-2026-W1 "KS Rail" tab charges KS-routed material the actual via-KS path ("Rail via Maize" 3,380 mi vs 2,199 mi direct). Dropping the KS legs would understate transport. The via-KS truck route (1,221 mi) is 1.7% longer than direct (1,201 mi), so this is also the conservative treatment.
A37: 3. Leg 1 denominator: 34 totes across 2 trucks. The #32 vs #33 membership split is not recorded, but n/34 x 2 trucks = n/17 x 1 truck, so the split does not change the allocated miles.
A38: 4. Leg 2 denominator: 6 totes = the Kansas totes recreated at LA per the QOWV_32_33 tracker (118811, 118837, 118872, 118886, 118846, 120584). Tag 197262 was removed from scope 2026-08-25; had it ridden this truck the denominator would be 7, which allocates fewer miles - 6 is the conservative choice.
A39: 5. Distance sources: filed route maps linked at B21:C22 - "Charm CO to Charm KS.png" (537 mi, I-70 E) and "Charm KS to Charm LA.png" (684 mi, I-49 S). Attach both to the Certify transport-distance datapoints for these removals.
A40: 6. Carbon intensity is unaffected: CI stays keyed to the tote production month (PP#7), not the route.

Sheet WODO Shipments & EE Allocation
A1: INJ-08-2026-W4 - WODO Shipments & EE Mileage Allocation
A4: BATCH SUMMARY
A5: Batch | B5: Fraction | C5: Inj. Week | D5: # Totes | E5: Shipping Orders (relevant totes)
A6: INJ-08-2026-W4 | B6: WODO | C6: 2026-08-15 to 2026-08-22 | D6: =COUNTA(WODO!A11:A27) -> 0 | E6: N/A - no WODO totes injected this week
A8: Charm CO -> Basco LA distance (one-way mi) | B8: 1201
A10: EE ALLOCATION TABLE
A11: Truck (shipping order) | B11: Ship Date | C11: Total Totes on Truck | D11: Batch-Relevant Totes | E11: Batch Share of Truck | F11: Mileage (one-way) | G11: Allocated Miles
