Workbook

Sheet Summary
A1: BATCH SUMMARY
A2: Batch ID | B2: INJ-08-2026-W3
A3: Week Start (Sat) | B3: 46242
A4: Week End (Sat) | B4: 46249
A6: SECTION 1 - PER-TAB SUMMARY (each row pulls from its mode tab)
A7: Source Tab | B7: Σ Deliveries / Cargo (kg) | C7: Σ Uncertainty Adj (kg) | D7: Mass Used (kg) | E7: Sparging Loss (kg) | F7: Filtration Loss (kg) | G7: MOBI (kg) | H7: AECN→SOPOR EE (mi) | I7: Rail EE (mi) | J7: Opel→Basco EE (mi)
A8: AECN Rail | B8: ='AECN Rail'!B65 -> 423710.27 | C8: ='AECN Rail'!C65 -> 148.34336 | D8: ='AECN Rail'!D65 -> 423561.92 | E8: ='AECN Rail'!E65 -> 5463.9488 | F8: ='AECN Rail'!F65 -> 815.29105 | G8: ='AECN Rail'!G65 -> 417282.68 | H8: =SUM('AECN Rail'!L39:L60) -> 1757.4728 | I8: =SUM('AECN Rail'!M39:M60) -> 12099.049 | J8: =SUM('AECN Rail'!N39:N60) -> 1887.6
A9: AECN Truck | B9: ='AECN Truck'!B28 -> 0 | C9: ='AECN Truck'!F28 -> 0 | D9: ='AECN Truck'!C28 -> 0 | E9: ='AECN Truck'!D28 -> 0 | F9: ='AECN Truck'!E28 -> 0 | G9: ='AECN Truck'!G28 -> 0
A10: Charm WODO | B10: =WODO!A33 -> 0 | C10: 0 | D10: =WODO!B33 -> 0 | E10: =WODO!C33 | F10: 0 | G10: =WODO!D33 -> 0
A11: Kerry | B11: =Kerry!A22 -> 10949.711 | C11: 0 | D11: =Kerry!A22 -> 10949.711 | E11: 0 | F11: =Kerry!B22 -> 7.7742947 | G11: =Kerry!C22 -> 10941.937
A12: QOWV | B12: =QOWV!B50 -> 38152 | C12: 0 | D12: =QOWV!D50 -> 36020.8 | E12: 0 | F12: 0 | G12: =QOWV!F50 -> 32333.5
A13: TOTAL | B13: =SUM(B8:B12) -> 472811.98 | C13: =SUM(C8:C12) -> 148.34336 | D13: =SUM(D8:D12) -> 470532.43 | E13: =SUM(E8:E12) -> 5463.9488 | F13: =SUM(F8:F12) -> 823.06534 | G13: =SUM(G8:G12) -> 460558.12 | H13: =SUM(H8:H12) -> 1757.4728 | I13: =SUM(I8:I12) -> 12099.049 | J13: =SUM(J8:J12) -> 1887.6
A15: SECTION 2 - PER-OIL-TYPE ROLLUP (composite C% per oil type per week)
A16: Oil Type | B16: Transport Mass - upstream (kg) | C16: Transport Mass - downstream Opel→Basco (kg) | D16: Pyrolysis Mass (kg) | E16: MOBI - sequestration (kg) | F16: Composite Sample ID | G16: C % | H16: Lab COA Link | I16: C Content Uncertainty | J16: Testing Uncertainty
A17: AECN | B17: =SUM('AECN Rail'!I10:I15)+'AECN Truck'!A28 -> 423710.27 | C17: ='AECN Rail'!B65 -> 423710.27 | D17: =SUM('AECN Rail'!I10:I15)+'AECN Truck'!A28 -> 423710.27 | E17: ='AECN Rail'!G65+'AECN Truck'!G28 -> 417282.68 | F17: 08-2026-W3 AECN | G17: 0.406 | H17: =HYPERLINK("https://drive.google.com/file/d/1FUXbzpufADdK1EhePR2gVlzKhtHw4g9m/view","COA SR26-05021.001") -> COA SR26-05021.001 | I17: =G17*J17 -> 0.001624 | J17: 0.004
A18: WODO | B18: =WODO!A33 -> 0 | D18: =WODO!B33 -> 0 | E18: =WODO!D33 -> 0 | I18: =G18*J18 -> 0 | J18: 0.004
A19: Kerry | B19: =Kerry!A22 -> 10949.711 | D19: =Kerry!A22 -> 10949.711 | E19: =Kerry!C22 -> 10941.937 | F19: 08-2026-W3 Kerry | G19: =IFERROR(__xludf.DUMMYFUNCTION("IFERROR(AVERAGE.WEIGHTED(Kerry!I10:I18,Kerry!F10:F18),"""")"),0.538) -> 0.538 | H19: =HYPERLINK("https://drive.google.com/file/d/1FUXbzpufADdK1EhePR2gVlzKhtHw4g9m/view","COA SR26-05021.003") -> COA SR26-05021.003 | I19: =G19*J19 -> 0.002152 | J19: 0.004
A20: QOWV | B20: =QOWV!B50 -> 38152 | D20: =QOWV!D50 -> 36020.8 | E20: =QOWV!F50 -> 32333.5 | F20: 08-2026-W3 QOWV | G20: 0.082 | H20: =HYPERLINK("https://drive.google.com/file/d/1FUXbzpufADdK1EhePR2gVlzKhtHw4g9m/view","COA SR26-05021.002") -> COA SR26-05021.002 | I20: =G20*J20 -> 0.000328 | J20: 0.004
A21: TOTAL | B21: =SUM(B17:B20) -> 472811.98 | C21: =SUM(C17:C20) -> 423710.27 | D21: =SUM(D17:D20) -> 470680.78 | E21: =SUM(E17:E20) -> 460558.12

Sheet AECN Rail
A1: BATCH HEADER — AECN Rail
A2: Batch ID (INJ-YYYY-WXX) | B2: INJ-08-2026-W3 | N2: Constants
A3: Week Start (Sat) | B3: 46242 | N3: Lbs/Kg | O3: 2.20462
A4: Week End (Sat) | B4: 46249 | N4: Kg/Lbs | O4: 0.453592
N5: Sparging Mass Loss | O5: 0.0129
N6: pH range (target) | O6: 2.0 - 4.0
N7: Filtration Solids Content | O7: =HYPERLINK("https://docs.google.com/spreadsheets/d/16shKoa1KP34kQJyQvzclBejW9L5-ubNSqPsMOVB7zDY/edit?usp=sharing", 0.00195) -> 0.00195
A8: SECTION 1 - RAILCARS RECEIVED THIS WEEK (entity-level) | I8: Pyrolysis Emissions Mass | N8: BOL Trips (AECN→SOPOR) | O8: 3
A9: Railcar # | B9: Arrival Date at Opelousas | C9: Loading BOLs (comma-sep) | D9: Total Loaded (MT) | E9: Total Loaded (kg) | F9: Total Offloaded (kg, auto) | G9: Loss (kg) | H9: Previously Claimed (kg) | I9: Claimed This Week (kg) | J9: AECN→SOPOR (mi) | K9: Rail (mi) | L9: Opel→Basco (mi) | M9: Full Railcar This Week? | N9: Round Trip (Opel→Basco) | O9: 2
A10: SHPX215068 | B10: 46249 | C10: 2436-R, 2437-R, 2438-R | D10: =SUMIF($C$19:$C$36,$A10,$D$19:$D$36) -> 77.78 | E10: =SUMIF($C$19:$C$36,$A10,$E$19:$E$36) -> 77780 | F10: =SUMIF($C$39:$C$60,A10,$F$39:$F$60)+H10 -> 77881.746 | G10: =IF(AND(E10<>"",F10<>"",F10>=0.95*E10),E10-F10,"") -> -101.7464 | H10: 0 | I10: =F10-H10 -> 77881.746 | J10: 107.5 | K10: 2199 | L10: 42.9 | M10: =IF(OR($E10="",$F10=""),"",IF(AND($H10=0,$F10>=0.95*$E10),"FULL","PARTIAL")) -> FULL
A11: SHPX215078 | B11: 46249 | C11: 2427-R, 2428-R, 2429-R | D11: =SUMIF($C$19:$C$36,$A11,$D$19:$D$36) -> 77.69 | E11: =SUMIF($C$19:$C$36,$A11,$E$19:$E$36) -> 77690 | F11: =SUMIF($C$39:$C$60,A11,$F$39:$F$60)+H11 -> 77736.597 | G11: =IF(AND(E11<>"",F11<>"",F11>=0.95*E11),E11-F11,"") -> -46.59696 | H11: 0 | I11: =F11-H11 -> 77736.597 | J11: 107.5 | K11: 2199 | L11: 42.9 | M11: =IF(OR($E11="",$F11=""),"",IF(AND($H11=0,$F11>=0.95*$E11),"FULL","PARTIAL")) -> FULL
A12: GPRX5082 | B12: 46249 | C12: 2433-R, 2434-R, 2435-R | D12: =SUMIF($C$19:$C$36,$A12,$D$19:$D$36) -> 77.84 | E12: =SUMIF($C$19:$C$36,$A12,$E$19:$E$36) -> 77840 | F12: =SUMIF($C$39:$C$60,A12,$F$39:$F$60)+H12 -> 77654.95 | G12: =IF(AND(E12<>"",F12<>"",F12>=0.95*E12),E12-F12,"") -> 185.0496 | H12: 0 | I12: =F12-H12 -> 77654.95 | J12: 107.5 | K12: 2199 | L12: 42.9 | M12: =IF(OR($E12="",$F12=""),"",IF(AND($H12=0,$F12>=0.95*$E12),"FULL","PARTIAL")) -> FULL
A13: GPRX5098 | B13: 46249 | C13: 2405-R, 2439-R, 2440-R | D13: =SUMIF($C$19:$C$36,$A13,$D$19:$D$36) -> 77.31 | E13: =SUMIF($C$19:$C$36,$A13,$E$19:$E$36) -> 77310 | F13: =SUMIF($C$39:$C$60,A13,$F$39:$F$60)+H13 -> 76829.413 | G13: =IF(AND(E13<>"",F13<>"",F13>=0.95*E13),E13-F13,"") -> 480.58704 | H13: 0 | I13: =F13-H13 -> 76829.413 | J13: 107.5 | K13: 2199 | L13: 42.9 | M13: =IF(OR($E13="",$F13=""),"",IF(AND($H13=0,$F13>=0.95*$E13),"FULL","PARTIAL")) -> FULL
A14: GPRX5139 | B14: 46249 | C14: 2406-R, 2407-R, 2408-R | D14: =SUMIF($C$19:$C$36,$A14,$D$19:$D$36) -> 77.8 | E14: =SUMIF($C$19:$C$36,$A14,$E$19:$E$36) -> 77800 | F14: =SUMIF($C$39:$C$60,A14,$F$39:$F$60)+H14 -> 74380.923 | G14: =IF(AND(E14<>"",F14<>"",F14>=0.95*E14),E14-F14,"") -> 3419.0767 | H14: 0 | I14: =F14-H14 -> 74380.923 | J14: 107.5 | K14: 2199 | L14: 42.9 | M14: =IF(OR($E14="",$F14=""),"",IF(AND($H14=0,$F14>=0.95*$E14),"FULL","PARTIAL")) -> FULL
A15: SHPX215082 | B15: 46249 | C15: 2418-R, 2419-R, 2423-R | D15: =SUMIF($C$19:$C$36,$A15,$D$19:$D$36) -> 78.13 | E15: =SUMIF($C$19:$C$36,$A15,$E$19:$E$36) -> 78130 | F15: =SUMIF($C$39:$C$60,A15,$F$39:$F$60)+H15 -> 78081.327 | G15: =IF(AND(E15<>"",F15<>"",F15>=0.95*E15),E15-F15,"") -> 48.67312 | H15: =19123.43872+19731.252 -> 38854.691 | I15: =F15-H15 -> 39226.636 | J15: 107.5 | K15: 2199 | L15: 42.9 | M15: =IF(OR($E15="",$F15=""),"",IF(AND($H15=0,$F15>=0.95*$E15),"FULL","PARTIAL")) -> PARTIAL
A17: SECTION 2 - ORIGINS LEDGER (loading BOLs at SOPOR)
A18: Date | B18: BOL # | C18: Railcar # | D18: BOL Mass (MT) | E18: BOL Mass (kg)
A19: 46224 | B19: =HYPERLINK("https://drive.google.com/file/d/1x1w35SZbqG09tl8elqgxFLXNT79UdPr0/view","2436-R") -> 2436-R | C19: SHPX215068 | D19: 26.06 | E19: =D19*1000 -> 26060
A20: 46225 | B20: =HYPERLINK("https://drive.google.com/file/d/1KIWmdL2JHbn9tuAS7m_YcvC7BA1YemwY/view","2437-R") -> 2437-R | C20: SHPX215068 | D20: 25.76 | E20: =D20*1000 -> 25760
A21: 46225 | B21: =HYPERLINK("https://drive.google.com/file/d/1HNrUx92n0bvIwhsMnvYXV57kIDxMEMPu/view","2438-R") -> 2438-R | C21: SHPX215068 | D21: 25.96 | E21: =D21*1000 -> 25960
A22: 46217 | B22: =HYPERLINK("https://drive.google.com/file/d/1-fb-Fu4hLbpj4-zXZHpIKmUA-ivk2RC-/view","2427-R") -> 2427-R | C22: SHPX215078 | D22: 25.85 | E22: =D22*1000 -> 25850
A23: 46217 | B23: =HYPERLINK("https://drive.google.com/file/d/1UTDkSGdNPe0p2BnTlP-xwb0cBkHlJ3do/view","2428-R") -> 2428-R | C23: SHPX215078 | D23: 25.85 | E23: =D23*1000 -> 25850
A24: 46218 | B24: =HYPERLINK("https://drive.google.com/file/d/1LYsFu-L706J6r9AMwhsXhX4ZB7Bo__g4/view","2429-R") -> 2429-R | C24: SHPX215078 | D24: 25.99 | E24: =D24*1000 -> 25990
A25: 46223 | B25: =HYPERLINK("https://drive.google.com/file/d/1K-2tWdBk6l5TBLaByFLydKP8oZN7nn0K/view","2433-R") -> 2433-R | C25: GPRX5082 | D25: 26.06 | E25: =D25*1000 -> 26060
A26: 46223 | B26: =HYPERLINK("https://drive.google.com/file/d/1QMtwOLkREdblHkil2gydPsxPf-m3wxBI/view","2434-R") -> 2434-R | C26: GPRX5082 | D26: 25.88 | E26: =D26*1000 -> 25880
A27: 46224 | B27: =HYPERLINK("https://drive.google.com/file/d/17SJ5oQEhgvWyDTYIJbcR9n4AOOKPJG-6/view","2435-R") -> 2435-R | C27: GPRX5082 | D27: 25.9 | E27: =D27*1000 -> 25900
A28: 46202 | B28: =HYPERLINK("https://drive.google.com/file/d/1i7FsRNJawXRJZ1GWxwbMLKZ6oH5JBfsc/view","2405-R") -> 2405-R | C28: GPRX5098 | D28: 27.31 | E28: =D28*1000 -> 27310
A29: 46226 | B29: =HYPERLINK("https://drive.google.com/file/d/1gYdyyV3eT6a1Ih99VJ9uX4jecqRZtf2s/view","2439-R") -> 2439-R | C29: GPRX5098 | D29: 25.69 | E29: =D29*1000 -> 25690
A30: 46227 | B30: =HYPERLINK("https://drive.google.com/file/d/1zxbJ3po8Wc_i1J0ltZumpu0LX4n-15Or/view","2440-R") -> 2440-R | C30: GPRX5098 | D30: 24.31 | E30: =D30*1000 -> 24310
A31: 46202 | B31: =HYPERLINK("https://drive.google.com/file/d/1_D0xK19GleVf_EAOb6DI06Tzeb_xtwuS/view","2406-R") -> 2406-R | C31: GPRX5139 | D31: 25.98 | E31: =D31*1000 -> 25980
A32: 46203 | B32: =HYPERLINK("https://drive.google.com/file/d/1-Tn8hbgdr5Ul9PR5iEsZyYtEH99NByt8/view","2407-R") -> 2407-R | C32: GPRX5139 | D32: 25.99 | E32: =D32*1000 -> 25990
A33: 46204 | B33: =HYPERLINK("https://drive.google.com/file/d/1Qv245VmJha0JehmEudgfio6nDCr6HEFn/view","2408-R") -> 2408-R | C33: GPRX5139 | D33: 25.83 | E33: =D33*1000 -> 25830
A34: 46211 | B34: =HYPERLINK("https://drive.google.com/file/d/1G-sh8koOzOzOZyn1WSphudqvvZ9A5LOz/view","2418-R") -> 2418-R | C34: SHPX215082 | D34: 26.07 | E34: =D34*1000 -> 26070
A35: 46211 | B35: =HYPERLINK("https://drive.google.com/file/d/1YiHrTDjk51LD0Cw2_YONHIQDBo88oJlG/view","2419-R") -> 2419-R | C35: SHPX215082 | D35: 26.01 | E35: =D35*1000 -> 26010
A36: 46215 | B36: =HYPERLINK("https://drive.google.com/file/d/1VWJ6Xq2mKKK03Igs8E3bK3CT7VXIHHwu/view","2423-R") -> 2423-R | C36: SHPX215082 | D36: 26.05 | E36: =D36*1000 -> 26050
A37: SECTION 3 - SCALE TICKETS + OFFLOAD WEIGHTS
A38: Date | B38: Offload Key | C38: Railcar # | D38: Full Scale Ticket (lb) | E38: Empty Scale Ticket (lb) | F38: Net Scaled Mass (kg) | G38: pH | H38: Sparging Loss (kg) | I38: Filtration Loss (kg) | J38: Uncertainty Adjustment (kg) | K38: MOBI (kg) | L38: AECN→SOPOR (mi, x3 — full BOL) | M38: Rail (mi) — FULL railcar: flat 2199 on first offload; PARTIAL: offload-mass-basis allocation | N38: Opel→Basco (mi, x2 — downstream, per offload)
A39: 46249 | B39: Rail_SHPX215068_7.23.26_offload_1 | C39: SHPX215068 | D39: =HYPERLINK("https://drive.google.com/file/d/1bFnI4x40KKyp7U1GS3BL4AyzTMAphXpo/view?usp=drivesdk", 79160) -> 79160 | E39: =HYPERLINK("https://drive.google.com/file/d/1U__8I0RzNO2nO670xVFCTq3pWkCqHHDy/view?usp=drivesdk", 28700) -> 28700 | F39: =IF(OR(D39="",E39=""),"",(D39-E39)*$O$4) -> 22888.252 | G39: 2.87 | H39: =IF(F39="","",(F39-J39)*$O$5) -> 295.25845 | I39: =IF(F39="","",(F39-J39)*(1-$O$5)*$O$7) -> 44.056338 | J39: {=IF(F39="","",IF(ROW()=MAX(IF($C$39:$C$60=C39,ROW($C$39:$C$60),0)),MAX(0,IFERROR(VLOOKUP(C39,$A$10:$L$15,6,FALSE)-VLOOKUP(C39,$A$10:$L$15,5,FALSE),0)),0))} -> 0 | K39: =IF(F39="","",F39-H39-I39-J39) -> 22548.938 | L39: =IF(F39="","",(F39-J39)/VLOOKUP(C39,$A$10:$L$15,5,FALSE)*VLOOKUP(C39,$A$10:$L$15,10,FALSE)*$O$8) -> 94.901792 | M39: {=IF(F39="","",IF(IFERROR(VLOOKUP(C39,$A$10:$M$15,13,FALSE),"")="FULL",IF(ROW()=MIN(IF($C$39:$C$60=C39,ROW($C$39:$C$60),10^9)),VLOOKUP(C39,$A$10:$M$15,11,FALSE),0),(F39-J39)/VLOOKUP(C39,$A$10:$M$15,5,FALSE)*VLOOKUP(C39,$A$10:$M$15,11,FALSE)))} -> 2199 | N39: =IF(F39="","",IFERROR(VLOOKUP(C39,$A$10:$L$15,12,FALSE),0)*$O$9) -> 85.8
A40: 46249 | B40: Rail_SHPX215068_7.23.26_offload_2 | C40: SHPX215068 | D40: =HYPERLINK("https://drive.google.com/file/d/19iBT2AU3U1u8yv_M51Zzm7j3RwjvGoyE/view?usp=drivesdk", 70920) -> 70920 | E40: =HYPERLINK("https://drive.google.com/file/d/1c0mYhD87ca1tgongk7G0tcjlUq5gHjsr/view?usp=drivesdk", 29300) -> 29300 | F40: =IF(OR(D40="",E40=""),"",(D40-E40)*$O$4) -> 18878.499 | G40: 2.87 | H40: =IF(F40="","",(F40-J40)*$O$5) -> 243.53264 | I40: =IF(F40="","",(F40-J40)*(1-$O$5)*$O$7) -> 36.338184 | J40: {=IF(F40="","",IF(ROW()=MAX(IF($C$39:$C$60=C40,ROW($C$39:$C$60),0)),MAX(0,IFERROR(VLOOKUP(C40,$A$10:$L$15,6,FALSE)-VLOOKUP(C40,$A$10:$L$15,5,FALSE),0)),0))} -> 0 | K40: =IF(F40="","",F40-H40-I40-J40) -> 18598.628 | L40: =IF(F40="","",(F40-J40)/VLOOKUP(C40,$A$10:$L$15,5,FALSE)*VLOOKUP(C40,$A$10:$L$15,10,FALSE)*$O$8) -> 78.276111 | M40: {=IF(F40="","",IF(IFERROR(VLOOKUP(C40,$A$10:$M$15,13,FALSE),"")="FULL",IF(ROW()=MIN(IF($C$39:$C$60=C40,ROW($C$39:$C$60),10^9)),VLOOKUP(C40,$A$10:$M$15,11,FALSE),0),(F40-J40)/VLOOKUP(C40,$A$10:$M$15,5,FALSE)*VLOOKUP(C40,$A$10:$M$15,11,FALSE)))} -> 0 | N40: =IF(F40="","",IFERROR(VLOOKUP(C40,$A$10:$L$15,12,FALSE),0)*$O$9) -> 85.8
A41: 46249 | B41: Rail_SHPX215068_7.23.26_offload_3 | C41: SHPX215068 | D41: =HYPERLINK("https://drive.google.com/file/d/1Y_Xm4ECp7k8rk3Uz83fp4Pw2tmE_9O1d/view?usp=drivesdk", 73640) -> 73640 | E41: =HYPERLINK("https://drive.google.com/file/d/1eH_P6cYrPy5Wm0lpy_-1JFet6t6rZsEg/view?usp=drivesdk", 28420) -> 28420 | F41: =IF(OR(D41="",E41=""),"",(D41-E41)*$O$4) -> 20511.43 | G41: 2.87 | H41: =IF(F41="","",(F41-J41)*$O$5) -> 264.59745 | I41: =IF(F41="","",(F41-J41)*(1-$O$5)*$O$7) -> 39.481324 | J41: {=IF(F41="","",IF(ROW()=MAX(IF($C$39:$C$60=C41,ROW($C$39:$C$60),0)),MAX(0,IFERROR(VLOOKUP(C41,$A$10:$L$15,6,FALSE)-VLOOKUP(C41,$A$10:$L$15,5,FALSE),0)),0))} -> 0 | K41: =IF(F41="","",F41-H41-I41-J41) -> 20207.351 | L41: =IF(F41="","",(F41-J41)/VLOOKUP(C41,$A$10:$L$15,5,FALSE)*VLOOKUP(C41,$A$10:$L$15,10,FALSE)*$O$8) -> 85.04675 | M41: {=IF(F41="","",IF(IFERROR(VLOOKUP(C41,$A$10:$M$15,13,FALSE),"")="FULL",IF(ROW()=MIN(IF($C$39:$C$60=C41,ROW($C$39:$C$60),10^9)),VLOOKUP(C41,$A$10:$M$15,11,FALSE),0),(F41-J41)/VLOOKUP(C41,$A$10:$M$15,5,FALSE)*VLOOKUP(C41,$A$10:$M$15,11,FALSE)))} -> 0 | N41: =IF(F41="","",IFERROR(VLOOKUP(C41,$A$10:$L$15,12,FALSE),0)*$O$9) -> 85.8
...

Sheet WODO
A1: BATCH HEADER — Charm WODO (IBC Totes)
A2: Batch ID (INJ-YYYY-WXX) | B2: INJ-08-2026-W3 | K2: Constants
A3: Week Start (Sat) | B3: 46242 | K3: Lbs/Kg | L3: 2.20462
A4: Week End (Sat) | B4: 46249 | K4: Kg/Lbs | L4: 0.453592
K5: Sparging Mass Loss | L5: 0.0129
K6: pH range (target) | L6: 2.0 - 4.0
K7: WODO 6-Mo CI (kg CO2e/kg), Jul-Dec 2026 | L7: 0.795241
A8: SECTION 1 - IBC LEDGER (one row per IBC tote; tote tag mass is authoritative) | K8: WODO Standard Loss (kg/tote), 2026 = Mean + 1 SD | L8: 7.84 | M8: =HYPERLINK("https://docs.google.com/spreadsheets/d/15fnYOYMmu-7a-p8Alst6mAOsV7X854y6HBDYwQRUm5s/edit","Tote Loss Dataset") -> Tote Loss Dataset
B9: Transport Emissions | D9: Pyrolysis Emissions Mass & Standard Loss | F9: MOBI | K9: Per-Production-Month CI (kg CO2e/kg) - PP Summary Output Type table, col T
A10: Tag | B10: Gross Mass (kg) | C10: Tote Mass (kg) | D10: Net Oil Produced (kg) | E10: Standard Loss (kg) | F10: Net Oil Injected (kg) | G10: Production Period | H10: Carbon Intensity | I10: Production Emissions | J10: Scale Uncertainty | K10: PP#8 | L10: 0.71282902 | M10: =HYPERLINK("https://docs.google.com/spreadsheets/d/1L167k_JS3mnisFy3VpS-OXgI8U0cK-4nC6A9sxl-ozk/edit","PP Summary") -> PP Summary
K11: 45962 | L11: 0.97484085 | M11: =HYPERLINK("https://docs.google.com/spreadsheets/d/1W8jWu3sp39WnSuds1Ja0FWDG5UuWN9v5NUmF6yh_WbI/edit","PP Summary") -> PP Summary
K12: 45992 | L12: 0.97218282 | M12: =HYPERLINK("https://docs.google.com/spreadsheets/d/1-L6m2wYknC3o-yIts9KK7FrYAb5lZIv4AwaizK8FbMc/edit","PP Summary") -> PP Summary
K13: 46023 | L13: 0.93199449 | M13: =HYPERLINK("https://docs.google.com/spreadsheets/d/1bPZ7pNsR5rv-om-BypF4lK3nczjn4HJNO2dzimwnx7E/edit","PP Summary") -> PP Summary
K14: 46054 | L14: 0.84989612 | M14: =HYPERLINK("https://docs.google.com/spreadsheets/d/1vH7bborVnc-TCby3wEkpzi7GGMOI5jMJooEW0V-rOQ4/edit","PP Summary") -> PP Summary
K15: 46082 | L15: 0.79006453 | M15: =HYPERLINK("https://docs.google.com/spreadsheets/d/1O7y30opa_u1_deqFm_w2qgVyxi_75X00xnzKuyVyh6o/edit","PP Summary") -> PP Summary
K16: 46113 | L16: 0.78483234 | M16: =HYPERLINK("https://docs.google.com/spreadsheets/d/10Qwx7K6sUcOBrCebGUGVaVeLQnhzvcT8sHQ0Sy3VBBM/edit","PP Summary") -> PP Summary
K17: 46143 | L17: 0.63284589 | M17: =HYPERLINK("https://docs.google.com/spreadsheets/d/1m66t1jsLGc4e6AWnCFMsFbkSceZ9IYC_-bfTsbP_OYc/edit","PP Summary") -> PP Summary
K18: 46174 | L18: 1.1105356 | M18: =HYPERLINK("https://docs.google.com/spreadsheets/d/1MUQajDI2a_Cn9xWGPP7z4PhhphZnfl2_CSTnpB07Wgk/edit","PP Summary") -> PP Summary
K19: July 2026 and later (Jan-Jun 2026 rolling) | L19: =$L$7 -> 0.795241
A29: TOTAL | B29: =SUM(B11:B27) -> 0 | C29: =SUM(C11:C27) -> 0 | D29: =SUM(D11:D27) -> 0 | E29: =SUM(E11:E27) -> 0 | F29: =SUM(F11:F27) -> 0 | H29: =IFERROR(SUMPRODUCT(D11:D27,H11:H27)/SUMIF(H11:H27,"<>",D11:D27),"") | I29: =SUM(I11:I27) -> 0 | J29: =SUM(J11:J27) -> 0
A31: SECTION 2 - ROLLUP
A32: Transport Mass | B32: Σ Net Oil Produced (kg) | C32: Loss (kg) | D32: MOBI — Σ Net Oil Injected (kg)
A33: =B29 -> 0 | B33: =SUM(D11:D27) -> 0 | C33: =IF(D33=0,"",B33-D33) | D33: =SUM(F11:F27) -> 0

Sheet AECN Truck
A1: BATCH HEADER — AECN Truck (Direct from Fort Lupton)
A2: Batch ID (INJ-YYYY-WXX) | B2: INJ-08-2026-W3 | K2: Constants
A3: Week Start (Sat) | B3: 46242 | K3: Lbs/Kg | L3: 2.20462
A4: Week End (Sat) | B4: 46249 | K4: Kg/Lbs | L4: 0.453592
K5: Sparging Mass Loss | L5: 0.0129
K6: pH range (target) | L6: 2.0 - 4.0
K7: Filtration Solids Content | L7: =HYPERLINK("https://docs.google.com/spreadsheets/d/16shKoa1KP34kQJyQvzclBejW9L5-ubNSqPsMOVB7zDY/edit?usp=sharing", 0.00195) -> 0.00195
A8: SECTION 1 - DELIVERIES LEDGER (one row per direct truck; BOL & scale ticket on same row)
A9: Date | B9: BOL # / SO # | C9: BOL Mass (MT) | D9: BOL Mass (kg) | E9: Scale Full (lb) | F9: Scale Empty (lb) | G9: Cargo (kg) | H9: pH | I9: Notes | J9: Sparging Loss (kg) | K9: Filtration Loss (kg) | L9: MOBI (kg) | M9: C Content
A26: SECTION 2 - ROLLUP (Mass Used = Σ BOL kg; scale tickets no longer required for direct trucks per 2026-05-26)
A27: Σ BOL (kg) | B27: Σ Cargo (kg) | C27: Mass Used (kg) | D27: Sparging Loss (kg) | E27: Filtration Loss (kg) | F27: Uncertainty Adjustment (kg) | G27: MOBI (kg) | H27: pH | I27: C Content (MOBI-wtd) | K27: Origins list (BOLs)
A28: =SUMIFS(D10:D24,B10:B24,"<>") -> 0 | B28: =SUMIFS(G10:G24,B10:B24,"<>") -> 0 | C28: =A28 -> 0 | D28: =C28*$L$5 -> 0 | E28: =(C28-D28)*$L$7 -> 0 | F28: 0 | G28: =C28-D28-E28-F28 -> 0 | H28: =IFERROR(AVERAGE(H10:H24),"") | I28: =IFERROR(SUMPRODUCT(L10:L24,M10:M24)/SUM(L10:L24),"") | K28: =IFERROR(__xludf.DUMMYFUNCTION("TRIM(TEXTJOIN("", "",TRUE,IFERROR(FILTER(B10:B24,B10:B24<>""""),"""")))"),"")

Sheet Kerry
A1: BATCH HEADER — Kerry (Calciner Waste Oil, IBC Totes)
A2: Batch ID (INJ-YYYY-WXX) | B2: INJ-08-2026-W3 | N2: Constants
A3: Week Start (Sat) | B3: 46242 | N3: Lbs/Kg | O3: 2.20462
A4: Week End (Sat) | B4: 46249 | N4: Kg/Lbs | O4: 0.453592
N5: Filtration Solids Content (Kerry Calciner) | O5: =HYPERLINK("https://drive.google.com/file/d/1twIf0H9Ma4crVsPgD0Iq6eFDwxQIC-ni/view",0.00071) -> 0.00071
N6: pH range (target) | O6: 2.0 - 4.0
N7: Testing Uncertainty | O7: 0.004
A8: SECTION 1 - IBC LEDGER (one row per Kerry tote; tote tag mass is authoritative)
A9: Date | B9: Full Ticket (lb) | C9: Empty Ticket 2 (lb) | D9: Gross Mass (kg) — transport | E9: Net Oil (kg) | F9: Net Injected (kg) — MOBI | G9: pH | H9: Notes | I9: C Content | J9: C Content Uncertainty | K9: Mass Uncertainty (kg)
A10: 46246 | B10: =HYPERLINK("https://drive.google.com/file/d/1m9mO3zsWev11uDcj8vPgfnfxG6qaTvWE/view?usp=drivesdk", 58480) -> 58480 | C10: =HYPERLINK("https://drive.google.com/file/d/1UpTCf72W2-HKAg0Vp1n7tw1I92xC3NuU/view?usp=drivesdk", 34340) -> 34340 | D10: =IF(B10="","",(B10-C10)*$O$4) -> 10949.711 | E10: =D10 -> 10949.711 | F10: =IF(E10="","",E10*(1-$O$5)) -> 10941.937 | G10: 2.87 | H10: Bulk tanker, Kerry calciner waste oil. FULL CAT ticket 1189526222006 (weigh 2006), 2026-08-10 13:19, Loves #1895 Wilson Township WI, gross 58480 lb. EMPTY CAT ticket 1312226224954 (weigh 4954), 2026-08-12, Pilot #3122 Bunkie LA, gross 34340 lb. Carrier Freiburger, tractor 07, trailer 1013 (same unit both weighings). No pH taken. | I10: 0.538 | J10: =I10*$O$7 -> 0.002152 | K10: 72.57
A20: SECTION 2 - ROLLUP
A21: Σ Net Oil — pre-filtration (kg) | B21: Filtration Loss (kg) | C21: MOBI (kg) | D21: pH
A22: =SUMIFS(E10:E18,A10:A18,"<>") -> 10949.711 | B22: =A22*$O$5 -> 7.7742947 | C22: =A22-B22 -> 10941.937 | D22: =IFERROR(AVERAGE(G10:G18),"") -> 2.87

Sheet QOWV
A1: BATCH HEADER — QOWV (Aqueous Bio-Oil, IBC Totes)
A2: Batch ID (INJ-YYYY-WXX) | B2: INJ-08-2026-W3 | K2: Constants | M2: pH | N2: 2.91
A3: Week Start (Sat) | B3: 46242 | K3: Lbs/Kg | L3: 2.20462
A4: Week End (Sat) | B4: 46249 | K4: Kg/Lbs | L4: 0.453592
K5: Sparging Mass Loss | L5: 0.0129
K6: pH range (target) | L6: 2.0 - 4.0
K7: QOWV 6-Mo CI (kg CO2e/kg), Jul-Dec 2026 | L7: 0.120947
A8: SECTION 1 - IBC LEDGER (one row per IBC tote; tote tag mass is authoritative)
B9: Transport Emissions | D9: Pyrolysis Emissions Mass | F9: MOBI | K9: Per-Production-Month CI (kg CO2e/kg) - PP Summary Output Type table, col T
A10: Tag | B10: Gross Mass (kg) | C10: Tote Mass (kg) | D10: Net Oil Produced (kg) | E10: Empty Tote Weight (kg) | F10: Net Oil Injected (kg) | G10: Production Period | H10: Carbon Intensity | I10: Production Emissions | J10: Scale Uncertainty | K10: PP#8 | L10: 0.15755534 | M10: =HYPERLINK("https://docs.google.com/spreadsheets/d/1L167k_JS3mnisFy3VpS-OXgI8U0cK-4nC6A9sxl-ozk/edit","PP Summary") -> PP Summary
A11: 120554 | B11: 1050 | C11: 57.6 | D11: =B11-C11 -> 992.4 | E11: 164 | F11: =IF(E11="","",B11-E11) -> 886 | G11: MFO Lot 3082 (LOT00003082), PP#8 | H11: =$L$10 -> 0.15755534 | I11: =IF(H11="","",H11*D11) -> 156.35792 | J11: =2.5*$L$4 -> 1.13398 | K11: 45962 | L11: 0.13921405 | M11: =HYPERLINK("https://docs.google.com/spreadsheets/d/1W8jWu3sp39WnSuds1Ja0FWDG5UuWN9v5NUmF6yh_WbI/edit","PP Summary") -> PP Summary
A12: 228057 | B12: 1025 | C12: 57.6 | D12: =B12-C12 -> 967.4 | E12: 189 | F12: =IF(E12="","",B12-E12) -> 836 | G12: MFO Lot 4350 (LOT00004350), November 2025 | H12: =$L$11 -> 0.13921405 | I12: =IF(H12="","",H12*D12) -> 134.67568 | J12: =2.5*$L$4 -> 1.13398 | K12: 45992 | L12: 0.16306166 | M12: =HYPERLINK("https://docs.google.com/spreadsheets/d/1-L6m2wYknC3o-yIts9KK7FrYAb5lZIv4AwaizK8FbMc/edit","PP Summary") -> PP Summary
A13: 300066 | B13: 962 | C13: 57.6 | D13: =B13-C13 -> 904.4 | E13: 257.5 | F13: =IF(E13="","",B13-E13) -> 704.5 | G13: MFO Lot 4728 (LOT00004728), February 2026 | H13: =$L$14 -> 0.13304979 | I13: =IF(H13="","",H13*D13) -> 120.33023 | J13: =2.5*$L$4 -> 1.13398 | K13: 46023 | L13: 0.15683402 | M13: =HYPERLINK("https://docs.google.com/spreadsheets/d/1bPZ7pNsR5rv-om-BypF4lK3nczjn4HJNO2dzimwnx7E/edit","PP Summary") -> PP Summary
A14: 301003 | B14: 1007 | C14: 57.6 | D14: =B14-C14 -> 949.4 | E14: 153 | F14: =IF(E14="","",B14-E14) -> 854 | G14: MFO Lot 4765 (LOT00004765), February 2026 | H14: =$L$14 -> 0.13304979 | I14: =IF(H14="","",H14*D14) -> 126.31747 | J14: =2.5*$L$4 -> 1.13398 | K14: 46054 | L14: 0.13304979 | M14: =HYPERLINK("https://docs.google.com/spreadsheets/d/1vH7bborVnc-TCby3wEkpzi7GGMOI5jMJooEW0V-rOQ4/edit","PP Summary") -> PP Summary
A15: 301002 | B15: 1051 | C15: 57.6 | D15: =B15-C15 -> 993.4 | E15: 142 | F15: =IF(E15="","",B15-E15) -> 909 | G15: MFO Lot 4766 (LOT00004766), February 2026 | H15: =$L$14 -> 0.13304979 | I15: =IF(H15="","",H15*D15) -> 132.17167 | J15: =2.5*$L$4 -> 1.13398 | K15: 46082 | L15: 0.11852515 | M15: =HYPERLINK("https://docs.google.com/spreadsheets/d/1O7y30opa_u1_deqFm_w2qgVyxi_75X00xnzKuyVyh6o/edit","PP Summary") -> PP Summary
A16: 300067 | B16: 1024 | C16: 57.6 | D16: =B16-C16 -> 966.4 | E16: 154 | F16: =IF(E16="","",B16-E16) -> 870 | G16: MFO Lot 4772 (LOT00004772), February 2026 | H16: =$L$14 -> 0.13304979 | I16: =IF(H16="","",H16*D16) -> 128.57932 | J16: =2.5*$L$4 -> 1.13398 | K16: 46113 | L16: 0.13141845 | M16: =HYPERLINK("https://docs.google.com/spreadsheets/d/10Qwx7K6sUcOBrCebGUGVaVeLQnhzvcT8sHQ0Sy3VBBM/edit","PP Summary") -> PP Summary
A17: 300097 | B17: 991 | C17: 57.6 | D17: =B17-C17 -> 933.4 | E17: 153 | F17: =IF(E17="","",B17-E17) -> 838 | G17: MFO Lot 4774 (LOT00004774), February 2026 | H17: =$L$14 -> 0.13304979 | I17: =IF(H17="","",H17*D17) -> 124.18868 | J17: =2.5*$L$4 -> 1.13398 | K17: 46143 | L17: 0.11066158 | M17: =HYPERLINK("https://docs.google.com/spreadsheets/d/1m66t1jsLGc4e6AWnCFMsFbkSceZ9IYC_-bfTsbP_OYc/edit","PP Summary") -> PP Summary
A18: 301026 | B18: 1034 | C18: 57.6 | D18: =B18-C18 -> 976.4 | E18: 154 | F18: =IF(E18="","",B18-E18) -> 880 | G18: MFO Lot 4776 (LOT00004776), February 2026 | H18: =$L$14 -> 0.13304979 | I18: =IF(H18="","",H18*D18) -> 129.90982 | J18: =2.5*$L$4 -> 1.13398 | K18: 46174 | L18: 0.12368967 | M18: =HYPERLINK("https://docs.google.com/spreadsheets/d/1MUQajDI2a_Cn9xWGPP7z4PhhphZnfl2_CSTnpB07Wgk/edit","PP Summary") -> PP Summary
A19: 301004 | B19: 1058 | C19: 57.6 | D19: =B19-C19 -> 1000.4 | E19: 154 | F19: =IF(E19="","",B19-E19) -> 904 | G19: MFO Lot 4817 (LOT00004817), March 2026 | H19: =$L$15 -> 0.11852515 | I19: =IF(H19="","",H19*D19) -> 118.57256 | J19: =2.5*$L$4 -> 1.13398 | K19: July 2026 and later (Jan-Jun 2026 rolling) | L19: =$L$7 -> 0.120947
A20: 301006 | B20: 1038 | C20: 57.6 | D20: =B20-C20 -> 980.4 | E20: 116 | F20: =IF(E20="","",B20-E20) -> 922 | G20: MFO Lot 301006 (LOT00301006), March 2026 | H20: =$L$15 -> 0.11852515 | I20: =IF(H20="","",H20*D20) -> 116.20206 | J20: =2.5*$L$4 -> 1.13398 | K20: PP#7 | L20: 0.13736711 | M20: =HYPERLINK("https://docs.google.com/spreadsheets/d/1qPyS0H9Wx8z2vMl_3ANE1YLYahKLeL1Qo8OmZ_ol9aI/edit","PP Summary") -> PP Summary
A21: 301018 | B21: 1051 | C21: 57.6 | D21: =B21-C21 -> 993.4 | E21: 134.5 | F21: =IF(E21="","",B21-E21) -> 916.5 | G21: MFO Lot 301018 (LOT00301018), March 2026 | H21: =$L$15 -> 0.11852515 | I21: =IF(H21="","",H21*D21) -> 117.74289 | J21: =2.5*$L$4 -> 1.13398
A22: 301024 | B22: 1076 | C22: 57.6 | D22: =B22-C22 -> 1018.4 | E22: 167 | F22: =IF(E22="","",B22-E22) -> 909 | G22: MFO Lot 301024 (LOT00301024), April 2026 | H22: =$L$16 -> 0.13141845 | I22: =IF(H22="","",H22*D22) -> 133.83655 | J22: =2.5*$L$4 -> 1.13398
A23: 301037 | B23: 1153 | C23: 57.6 | D23: =B23-C23 -> 1095.4 | E23: 134.5 | F23: =IF(E23="","",B23-E23) -> 1018.5 | G23: MFO Lot 301037 (LOT00301037), March 2026 | H23: =$L$15 -> 0.11852515 | I23: =IF(H23="","",H23*D23) -> 129.83245 | J23: =2.5*$L$4 -> 1.13398
A24: 301039 | B24: 1051 | C24: 57.6 | D24: =B24-C24 -> 993.4 | E24: 145.5 | F24: =IF(E24="","",B24-E24) -> 905.5 | G24: MFO Lot 301039 (LOT00301039), March 2026 | H24: =$L$15 -> 0.11852515 | I24: =IF(H24="","",H24*D24) -> 117.74289 | J24: =2.5*$L$4 -> 1.13398
A25: 301040 | B25: 1059 | C25: 57.6 | D25: =B25-C25 -> 1001.4 | E25: 82.5 | F25: =IF(E25="","",B25-E25) -> 976.5 | G25: MFO Lot 301040 (LOT00301040), March 2026 | H25: =$L$15 -> 0.11852515 | I25: =IF(H25="","",H25*D25) -> 118.69109 | J25: =2.5*$L$4 -> 1.13398
A26: 301051 | B26: 1152 | C26: 57.6 | D26: =B26-C26 -> 1094.4 | E26: 183 | F26: =IF(E26="","",B26-E26) -> 969 | G26: MFO Lot 301051 (LOT00301051), April 2026 | H26: =$L$16 -> 0.13141845 | I26: =IF(H26="","",H26*D26) -> 143.82436 | J26: =2.5*$L$4 -> 1.13398
A27: 301054 | B27: 1107 | C27: 57.6 | D27: =B27-C27 -> 1049.4 | E27: 148 | F27: =IF(E27="","",B27-E27) -> 959 | G27: MFO Lot 301054 (LOT00301054), April 2026 | H27: =$L$16 -> 0.13141845 | I27: =IF(H27="","",H27*D27) -> 137.91052 | J27: =2.5*$L$4 -> 1.13398
A28: 301057 | B28: 1040 | C28: 57.6 | D28: =B28-C28 -> 982.4 | E28: 170.5 | F28: =IF(E28="","",B28-E28) -> 869.5 | G28: MFO Lot 301057 (LOT00301057), March 2026 | H28: =$L$15 -> 0.11852515 | I28: =IF(H28="","",H28*D28) -> 116.43911 | J28: =2.5*$L$4 -> 1.13398
A29: 301060 | B29: 1067 | C29: 57.6 | D29: =B29-C29 -> 1009.4 | E29: 165 | F29: =IF(E29="","",B29-E29) -> 902 | G29: MFO Lot 301060 (LOT00301060), April 2026 | H29: =$L$16 -> 0.13141845 | I29: =IF(H29="","",H29*D29) -> 132.65379 | J29: =2.5*$L$4 -> 1.13398
A30: 301063 | B30: 1008 | C30: 57.6 | D30: =B30-C30 -> 950.4 | E30: 157 | F30: =IF(E30="","",B30-E30) -> 851 | G30: MFO Lot 301063 (LOT00301063), March 2026 | H30: =$L$15 -> 0.11852515 | I30: =IF(H30="","",H30*D30) -> 112.64631 | J30: =2.5*$L$4 -> 1.13398
A31: 301065 | B31: 1084 | C31: 57.6 | D31: =B31-C31 -> 1026.4 | E31: 178 | F31: =IF(E31="","",B31-E31) -> 906 | G31: MFO Lot 301065 (LOT00301065), March 2026 | H31: =$L$15 -> 0.11852515 | I31: =IF(H31="","",H31*D31) -> 121.65422 | J31: =2.5*$L$4 -> 1.13398
A32: 301067 | B32: 985 | C32: 57.6 | D32: =B32-C32 -> 927.4 | E32: 153 | F32: =IF(E32="","",B32-E32) -> 832 | G32: MFO Lot 301067 (LOT00301067), March 2026 | H32: =$L$15 -> 0.11852515 | I32: =IF(H32="","",H32*D32) -> 109.92023 | J32: =2.5*$L$4 -> 1.13398
A33: 301070 | B33: 1011 | C33: 57.6 | D33: =B33-C33 -> 953.4 | E33: 142 | F33: =IF(E33="","",B33-E33) -> 869 | G33: MFO Lot 301070 (LOT00301070), March 2026 | H33: =$L$15 -> 0.11852515 | I33: =IF(H33="","",H33*D33) -> 113.00188 | J33: =2.5*$L$4 -> 1.13398
A34: 301074 | B34: 940 | C34: 57.6 | D34: =B34-C34 -> 882.4 | E34: 167 | F34: =IF(E34="","",B34-E34) -> 773 | G34: MFO Lot 301074 (LOT00301074), March 2026 | H34: =$L$15 -> 0.11852515 | I34: =IF(H34="","",H34*D34) -> 104.5866 | J34: =2.5*$L$4 -> 1.13398
A35: 301075 | B35: 832 | C35: 57.6 | D35: =B35-C35 -> 774.4 | E35: 130.5 | F35: =IF(E35="","",B35-E35) -> 701.5 | G35: MFO Lot 301075 (LOT00301075), March 2026 | H35: =$L$15 -> 0.11852515 | I35: =IF(H35="","",H35*D35) -> 91.785879 | J35: =2.5*$L$4 -> 1.13398
A36: 301080 | B36: 1061 | C36: 57.6 | D36: =B36-C36 -> 1003.4 | E36: 140.5 | F36: =IF(E36="","",B36-E36) -> 920.5 | G36: MFO Lot 301080 (LOT00301080), March 2026 | H36: =$L$15 -> 0.11852515 | I36: =IF(H36="","",H36*D36) -> 118.92814 | J36: =2.5*$L$4 -> 1.13398
A37: 301083 | B37: 1068 | C37: 57.6 | D37: =B37-C37 -> 1010.4 | E37: 138 | F37: =IF(E37="","",B37-E37) -> 930 | G37: MFO Lot 301083 (LOT00301083), March 2026 | H37: =$L$15 -> 0.11852515 | I37: =IF(H37="","",H37*D37) -> 119.75781 | J37: =2.5*$L$4 -> 1.13398
A38: 301086 | B38: 992 | C38: 57.6 | D38: =B38-C38 -> 934.4 | E38: 170.5 | F38: =IF(E38="","",B38-E38) -> 821.5 | G38: MFO Lot 301086 (LOT00301086), April 2026 | H38: =$L$16 -> 0.13141845 | I38: =IF(H38="","",H38*D38) -> 122.7974 | J38: =2.5*$L$4 -> 1.13398
A39: 301087 | B39: 1067 | C39: 57.6 | D39: =B39-C39 -> 1009.4 | E39: 134 | F39: =IF(E39="","",B39-E39) -> 933 | G39: MFO Lot 301087 (LOT00301087), March 2026 | H39: =$L$15 -> 0.11852515 | I39: =IF(H39="","",H39*D39) -> 119.63929 | J39: =2.5*$L$4 -> 1.13398
A40: 301088 | B40: 1053 | C40: 57.6 | D40: =B40-C40 -> 995.4 | E40: 191 | F40: =IF(E40="","",B40-E40) -> 862 | G40: MFO Lot 301088 (LOT00301088), March 2026 | H40: =$L$15 -> 0.11852515 | I40: =IF(H40="","",H40*D40) -> 117.97994 | J40: =2.5*$L$4 -> 1.13398
...

Sheet QOWV Shipments & EE Allocation
A1: INJ-08-2026-W3 — QOWV Shipments & EE Mileage Allocation
A4: BATCH SUMMARY
A5: Batch | B5: Fraction | C5: Inj. Week | D5: # Totes | E5: Shipping Orders (relevant totes)
A6: INJ-08-2026-W3 | B6: QOWV | C6: 2026-08-08 to 2026-08-15 | D6: =COUNTA(QOWV!A11:A48) -> 37 | E6: 5 shipping order(s) direct CO->LA: COLA21, COLA25, COLA29, COLA30, Truck 2 (by Date Shipped) = 33 totes. Plus 4 Kansas totes (118811, 118837, 118872, 118886) routed CO -> Charm KS -> Basco LA, allocated in table B below. 33 + 4 = 37.
A8: Charm CO -> Basco LA distance (one-way mi) | B8: 1201
A10: EE ALLOCATION TABLE - A. Direct Charm CO -> Basco LA
A11: Truck (shipping order) | B11: Ship Date | C11: Total Totes on Truck | D11: Batch-Relevant Totes | E11: Batch Share of Truck | F11: Mileage (one-way) | G11: Allocated Miles
A12: COLA21 | B12: 46195 | C12: 40 | D12: 1 | E12: =IFERROR(D12/C12,"") -> 0.025 | F12: =$B$8 -> 1201 | G12: =IFERROR(E12*F12,"") -> 30.025
A13: COLA25 | B13: 46219 | C13: 40 | D13: 6 | E13: =IFERROR(D13/C13,"") -> 0.15 | F13: =$B$8 -> 1201 | G13: =IFERROR(E13*F13,"") -> 180.15
A14: COLA29 | B14: 46237 | C14: 21 | D14: 18 | E14: =IFERROR(D14/C14,"") -> 0.85714286 | F14: =$B$8 -> 1201 | G14: =IFERROR(E14*F14,"") -> 1029.4286
A15: COLA30 | B15: 46238 | C15: 20 | D15: 7 | E15: =IFERROR(D15/C15,"") -> 0.35 | F15: =$B$8 -> 1201 | G15: =IFERROR(E15*F15,"") -> 420.35
A16: Truck 2 (by Date Shipped) | B16: 45993 | C16: 36 | D16: 1 | E16: =IFERROR(D16/C16,"") -> 0.027777778 | F16: =$B$8 -> 1201 | G16: =IFERROR(E16*F16,"") -> 33.361111
A18: SUBTOTAL A - Direct | C18: =SUM(C12:C16) -> 157 | D18: =SUM(D12:D16) -> 33 | G18: =SUM(G12:G16) -> 1693.3147
A20: EE ALLOCATION TABLE - B. Via Kansas (Charm CO -> Charm KS -> Basco LA) tote tag(s): 118811, 118837, 118872, 118886
A21: Charm CO -> Charm KS distance (one-way mi) | B21: 537 | C21: =HYPERLINK("https://drive.google.com/file/d/17DLmRf2gOawFmCywpNFa-iReA4BzVVMu/view","Charm CO to Charm KS route map") -> Charm CO to Charm KS route map
A22: Charm KS -> Basco LA distance (one-way mi) | B22: 684 | C22: =HYPERLINK("https://drive.google.com/file/d/1fTT5YTSzi0Xc_7m-j21lb6Us_w9dZIa5/view","Charm KS to Charm LA route map") -> Charm KS to Charm LA route map
A23: Via-KS route total (one-way mi) | B23: =B21+B22 -> 1221 | C23: ="vs "&TEXT($B$8,"#,##0")&" mi direct ("&TEXT((B23-$B$8)/$B$8,"+0.0%")&")" -> vs 1,201 mi direct (+1.7%)
A25: Leg | B25: Ship Date | C25: Total Totes on Truck(s) | D25: Batch-Relevant Totes | E25: Batch Share of Truck(s) | F25: Mileage (one-way x trucks) | G25: Allocated Miles | H25: Trucks
A26: Leg 1 - Shipment #32/#33: Charm CO -> Charm KS | B26: 45951 | C26: 34 | D26: 4 | E26: =IFERROR(D26/C26,"") -> 0.11764706 | F26: =$B$21*H26 -> 1074 | G26: =IFERROR(E26*F26,"") -> 126.35294 | H26: 2
A27: Leg 2 - Charm KS -> Basco LA (repositioning) | B27: not recorded | C27: 6 | D27: 4 | E27: =IFERROR(D27/C27,"") -> 0.66666667 | F27: =$B$22*H27 -> 684 | G27: =IFERROR(E27*F27,"") -> 456 | H27: 1
A28: SUBTOTAL B - Via Kansas | G28: =SUM(G26:G27) -> 582.35294
A30: GRAND TOTAL ALLOCATED MILES (A + B) | G30: =G18+G28 -> 2275.6676
A32: Reconciliation - totes allocated vs QOWV ledger | B32: =D18+D27 -> 37 | C32: =COUNTA(QOWV!A11:A48) -> 37 | D32: =IF(B32=C32,"OK - every tote allocated","MISMATCH - check tote counts") -> OK - every tote allocated
A34: NOTES - Kansas-routed totes
A35: 1. Basis: these totes shipped Charm CO -> Charm KS on Shipment #32/#33 (2 trucks, 34 QOWV totes, shipped 2025-10-21; BGN master tab "QOWV totes to KS Shipment #32&33"), were stored at Charm KS, then repositioned Charm KS -> Basco LA. They never rode a direct CO->LA truck, so they are excluded from table A and allocated their actual two-leg route here.
A36: 2. Precedent: INJ-05-2026-W1 "KS Rail" tab charges KS-routed material the actual via-KS path ("Rail via Maize" 3,380 mi vs 2,199 mi direct). Dropping the KS legs would understate transport. The via-KS truck route (1,221 mi) is 1.7% longer than direct (1,201 mi), so this is also the conservative treatment.
A37: 3. Leg 1 denominator: 34 totes across 2 trucks. The #32 vs #33 membership split is not recorded, but n/34 x 2 trucks = n/17 x 1 truck, so the split does not change the allocated miles.
A38: 4. Leg 2 denominator: 6 totes = the Kansas totes recreated at LA per the QOWV_32_33 tracker (118811, 118837, 118872, 118886, 118846, 120584). Tag 197262 was removed from scope 2026-08-25; had it ridden this truck the denominator would be 7, which allocates fewer miles - 6 is the conservative choice.
A39: 5. Distance sources: filed route maps linked at B21:C22 - "Charm CO to Charm KS.png" (537 mi, I-70 E) and "Charm KS to Charm LA.png" (684 mi, I-49 S). Attach both to the Certify transport-distance datapoints for these removals.
A40: 6. Carbon intensity is unaffected: CI stays keyed to the tote production month (PP#7), not the route.

Sheet WODO Shipments & EE Allocation
A1: INJ-08-2026-W3 — WODO Shipments & EE Mileage Allocation
A4: BATCH SUMMARY
A5: Batch | B5: Fraction | C5: Inj. Week | D5: # Totes | E5: Shipping Orders (relevant totes)
A6: INJ-08-2026-W3 | B6: WODO | C6: 2026-08-08 to 2026-08-15 | D6: =COUNTA(WODO!A11:A27) -> 0 | E6: PENDING - no truck manifest yet
A8: Charm CO -> Basco LA distance (one-way mi) | B8: 1201
A10: EE ALLOCATION TABLE
A11: Truck (shipping order) | B11: Ship Date | C11: Total Totes on Truck | D11: Batch-Relevant Totes | E11: Batch Share of Truck | F11: Mileage (one-way) | G11: Allocated Miles
