Workbook

Sheet Stats & Charts
A1: Isometric Findings Log – Summary Stats & Analysis
A2: Source: isometric-log-of-issues | Findings ISS-16 through ISS-30 | Generated 2026-04-27
A4: Total findings | B4: Legitimate | C4: Misunderstanding | D4: Pending FAR | E4: % Legitimate | F4: Recurring causes (≥2 hits)
A5: =COUNTA(Data!A2:A15) -> 14 | B5: =COUNTIF(Data!D2:D15,"Legitimate") -> 9 | C5: =COUNTIF(Data!D2:D15,"Misunderstanding") -> 4 | D5: =COUNTIF(Data!D2:D15,"Pending FAR") -> 1 | E5: =COUNTIF(Data!D2:D15,"Legitimate")/COUNTA(Data!A2:A15) -> 0.64285714 | F5: =COUNTIF(D40:D45,"YES") -> 2
A7: 1. Findings classification (each finding bucketed)
A8: Code | B8: Type | C8: Bucket | D8: Root cause group | E8: Post-mortem cause (summary)
A9: ISS-30 | B9: Omission | C9: Misunderstanding | D9: 350 misunderstanding | E9: Erroneous -- 350 misunderstanding (LDENR monthly report not required)
A10: ISS-29 | B10: Clarification Request | C10: Misunderstanding | D10: 350 misunderstanding | E10: Erroneous -- 350 misunderstanding (mass discrepancy / conservatism)
A11: ISS-27 | B11: Error | C11: Legitimate | D11: EF versioning | E11: Legitimate -- Deprecated EF version used (railcar embodied)
A12: ISS-26 | B12: Omission | C12: Legitimate | D12: Component evidence | E12: Legitimate -- Component evidence missing (methanol invoice/delivery)
A13: ISS-25 | B13: Omission | C13: Legitimate | D13: Component evidence | E13: Legitimate -- Source file corrupted/blank on Certify
A14: ISS-24 | B14: Error | C14: Legitimate | D14: EF versioning | E14: Legitimate -- Deprecated EF version (value mismatch vs source)
A15: ISS-23 | B15: Omission | C15: Legitimate | D15: Component evidence | E15: Legitimate -- Component evidence missing (gasoline tracker not uploaded)
A16: ISS-22 | B16: Error | C16: Legitimate | D16: BCU quant mismatch | E16: Legitimate -- BCU kg CO2e mismatch vs RP quant sheet (root cause TBD)
A17: ISS-21 | B17: Omission | C17: Legitimate | D17: New verifier requirement | E17: Sort of legitimate -- New verifier requirement (BCU tracking sheet upload)
A18: ISS-20 | B18: Clarification Request | C18: Misunderstanding | D18: 350 misunderstanding | E18: Erroneous -- 350 misunderstanding (AECN CI factor incl. uncertainty)
A19: ISS-19 | B19: Clarification Request | C19: Legitimate | D19: Multi-day batch transport leg | E19: Legitimate -- Missed extra transport leg (multi-day injection batch)
... A22: ISS-16 | B22: Clarification Request | C22: Legitimate | D22: Documentation/labeling human error | E22: Legitimate -- Human error: spreadsheet header not relabeled (GREET vs GLEC)
A24: 2. By finding type
A25: Type | B25: Count | C25: % of total
A26: Omission | B26: =COUNTIF(Data!B2:B15,"Omission") -> 6 | C26: =B26/COUNTA(Data!A2:A15) -> 0.42857143
A27: Error | B27: =COUNTIF(Data!B2:B15,"Error") -> 3 | C27: =B27/COUNTA(Data!A2:A15) -> 0.21428571
A28: Clarification Request | B28: =COUNTIF(Data!B2:B15,"Clarification Request") -> 5 | C28: =B28/COUNTA(Data!A2:A15) -> 0.35714286
A29: Total | B29: =SUM(B26:B28) -> 14 | C29: =SUM(C26:C28) -> 1
A31: 3. Legitimate vs misunderstanding
A32: Bucket | B32: Count | C32: % of total
A33: Legitimate | B33: =COUNTIF(Data!D2:D15,"Legitimate") -> 9 | C33: =B33/COUNTA(Data!A2:A15) -> 0.64285714
A34: Misunderstanding | B34: =COUNTIF(Data!D2:D15,"Misunderstanding") -> 4 | C34: =B34/COUNTA(Data!A2:A15) -> 0.28571429
A35: Pending FAR | B35: =COUNTIF(Data!D2:D15,"Pending FAR") -> 1 | C35: =B35/COUNTA(Data!A2:A15) -> 0.071428571
A36: Total | B36: =SUM(B33:B35) -> 14 | C36: =SUM(C33:C35) -> 1
A38: 4. Root-cause groups within Legitimate findings
A39: Root cause group | B39: Count | C39: % of legitimate | D39: Recurring? (≥2)
A40: Component evidence | B40: =COUNTIFS(Data!D2:D15,"Legitimate",Data!E2:E15,"Component evidence") -> 3 | C40: =B40/COUNTIF(Data!D2:D15,"Legitimate") -> 0.33333333 | D40: =IF(B40>=2,"YES","") -> YES
A41: EF versioning | B41: =COUNTIFS(Data!D2:D15,"Legitimate",Data!E2:E15,"EF versioning") -> 2 | C41: =B41/COUNTIF(Data!D2:D15,"Legitimate") -> 0.22222222 | D41: =IF(B41>=2,"YES","") -> YES
A42: BCU quant mismatch | B42: =COUNTIFS(Data!D2:D15,"Legitimate",Data!E2:E15,"BCU quant mismatch") -> 1 | C42: =B42/COUNTIF(Data!D2:D15,"Legitimate") -> 0.11111111 | D42: =IF(B42>=2,"YES","")
A43: New verifier requirement | B43: =COUNTIFS(Data!D2:D15,"Legitimate",Data!E2:E15,"New verifier requirement") -> 1 | C43: =B43/COUNTIF(Data!D2:D15,"Legitimate") -> 0.11111111 | D43: =IF(B43>=2,"YES","")
A44: Multi-day batch transport leg | B44: =COUNTIFS(Data!D2:D15,"Legitimate",Data!E2:E15,"Multi-day batch transport leg") -> 1 | C44: =B44/COUNTIF(Data!D2:D15,"Legitimate") -> 0.11111111 | D44: =IF(B44>=2,"YES","")
A45: Documentation/labeling human error | B45: =COUNTIFS(Data!D2:D15,"Legitimate",Data!E2:E15,"Documentation/labeling human error") -> 1 | C45: =B45/COUNTIF(Data!D2:D15,"Legitimate") -> 0.11111111 | D45: =IF(B45>=2,"YES","")
A46: Total | B46: =SUM(B40:B45) -> 9 | C46: =SUM(C40:C45) -> 1
A48: 5. Notes — what the findings indicate
...

Sheet Data
A1: Code | B1: Type | C1: PM Cause Text | D1: Bucket | E1: Root cause group
A2: ISS-30 | B2: Omission | C2: Erroneous -- 350 misunderstanding (LDENR monthly report not required) | D2: Misunderstanding | E2: 350 misunderstanding
A3: ISS-29 | B3: Clarification Request | C3: Erroneous -- 350 misunderstanding (mass discrepancy / conservatism) | D3: Misunderstanding | E3: 350 misunderstanding
A4: ISS-27 | B4: Error | C4: Legitimate -- Deprecated EF version used (railcar embodied) | D4: Legitimate | E4: EF versioning
A5: ISS-26 | B5: Omission | C5: Legitimate -- Component evidence missing (methanol invoice/delivery) | D5: Legitimate | E5: Component evidence
A6: ISS-25 | B6: Omission | C6: Legitimate -- Source file corrupted/blank on Certify | D6: Legitimate | E6: Component evidence
A7: ISS-24 | B7: Error | C7: Legitimate -- Deprecated EF version (value mismatch vs source) | D7: Legitimate | E7: EF versioning
A8: ISS-23 | B8: Omission | C8: Legitimate -- Component evidence missing (gasoline tracker not uploaded) | D8: Legitimate | E8: Component evidence
A9: ISS-22 | B9: Error | C9: Legitimate -- BCU kg CO2e mismatch vs RP quant sheet (root cause TBD) | D9: Legitimate | E9: BCU quant mismatch
A10: ISS-21 | B10: Omission | C10: Sort of legitimate -- New verifier requirement (BCU tracking sheet upload) | D10: Legitimate | E10: New verifier requirement
A11: ISS-20 | B11: Clarification Request | C11: Erroneous -- 350 misunderstanding (AECN CI factor incl. uncertainty) | D11: Misunderstanding | E11: 350 misunderstanding
A12: ISS-19 | B12: Clarification Request | C12: Legitimate -- Missed extra transport leg (multi-day injection batch) | D12: Legitimate | E12: Multi-day batch transport leg
... A15: ISS-16 | B15: Clarification Request | C15: Legitimate -- Human error: spreadsheet header not relabeled (GREET vs GLEC) | D15: Legitimate | E15: Documentation/labeling human error
