Workbook

Sheet Apr 26 PP Summary
A1: Process Emissions | H1: Embodied Emissions | M1: Output Type | N1: Mass of Output (kg) | O1: % Output Mass | P1: C Content (%) | Q1: C Content Mass (kg) | R1: % C Content Mass | S1: Total Emissions Allocated to Fraction (MT CO2e) | T1: Kg Emissions/Kg Material
M2: WODO | N2: 17580.4 | O2: =N2/($N$2+$N$3+$N$4) -> 0.26550961 | P2: 0.4694 | Q2: =P2*N2 -> 8252.2398 | R2: =Q2/(SUM($Q$2+$Q$3+$Q$4)) -> 0.53634931 | S2: =R2*$I$32 -> 13.797666 | T2: =(S2*1000)/N2 -> 0.78483234
A3: Biomass Transport | E3: Pyrolyzer Up-Time | H3: Equipment Amortization | M3: Biochar | N3: 4721.4 | O3: =N3/($N$2+$N$3+$N$4) -> 0.071305377 | P3: 0.7799 | Q3: =P3*N3 -> 3682.2199 | R3: =Q3/(SUM($Q$2+$Q$3+$Q$4)) -> 0.23932364 | S3: =R3*$I$32 -> 6.1566366 | T3: =(S3*1000)/N3 -> 1.3039854
B4: New Pile | E4: Total Operating Hours | F4: 1966.7 | I4: Total Biomass Consumed (kg) | J4: 62244.55 | M4: Aqueous | N4: 43912 | O4: =N4/($N$2+$N$3+$N$4) -> 0.66318502 | P4: 0.0786 | Q4: =P4*N4 -> 3451.4832 | R4: =Q4/(SUM($Q$2+$Q$3+$Q$4)) -> 0.22432705 | S4: =R4*$I$32 -> 5.7708471 | T4: =(S4*1000)/N4 -> 0.13141845
B5: Process Emissions | C5: 0.7605 | E5: Production Operating Hours | F5: =F4-F6 -> 1966.7 | I5: Total Biomass Consumed (MT) | J5: =J4/1000 -> 62.24455
B6: Embodied Emissions | C6: 0.0524 | E6: R+D Operating Hours | F6: 0 | I6: Biomass Amortization Factor for PP (kg Co2e/MT biomass) | J6: 66.43
B7: Log Handling Emissions | C7: 0.1534 | E7: % Production | F7: =F5/F4 -> 1 | I7: Total Amortized Embodied Emissions (kg) | J7: =J6*J5 -> 4134.9055
E8: % R+D | F8: =F6/F4 -> 0 | I8: Total Amortized Embodied Emissions (MT) | J8: =J7/1000 -> 4.1349055
B9: Total Emissions | C9: =SUM(C5:C7) -> 0.9663 | H9: Spare Parts and Consumables
B10: BCU's Applied | C10: =SUM(C5,C7) -> 0.9139 | E10: Total Procured Renewables | I10: EE Estimate per Pyrolyzer Operating Hour (kgCO2e) | J10: 0.83351
B11: Remaining Emissions to Allocate | C11: =C9-C10 -> 0.0524 | E11: RD BCUs (MT CO2e) | F11: =Sum(C10,C39,C81,C89) -> 6.7350733 | I11: Spare Parts and Consumables Estimate for Period (kg) | J11: =J10*(F5*(1.01)) -> 1655.6568
E12: RECs (kWh) | F12: =C62 -> 35432.844 | I12: Spare Parts and Consumables Estimate for Period (MT) | J12: =J11/1000 -> 1.6556568
B13: Tonnes | C13: 101.01
B14: Miles | C14: 272
B15: Tonne-Miles | C15: 5494.77
A17: Propane Combustion
B18: Total PP Deliveries (L) | C18: 9978.3408 | H18: Consolidated Emissions Inventory (No GHG Neutralization) | I18: Total Emissions (MT) | J18: % of Total
B19: Tank Level at PP Close (%) | C19: 0.75 | H19: Biomass Transport | I19: =C9*F7 -> 0.9663 | J19: =I19/$I$32 -> 0.037562463
B20: Tank Level at PP Close (L) | C20: 2838.75 | H20: Propane | I20: =C27*F7 -> 16.981586 | J20: =I20/$I$32 -> 0.6601161
B21: Total Propane Consumption for PP (L) | C21: 9145.6408 | H21: Diesel | I21: =C40*F7 -> 0 | J21: =I21/$I$32 -> 0
B22: Total Propane Consumption for PP (Gal) | C22: 2416.0238 | H22: Gasoline | I22: =C48*F7 -> 0.48668986 | J22: =I22/$I$32 -> 0.018918835
B23: Total Propane Consumption for PP (kg) | C23: 4618.5436 | H23: Electricity | I23: =C64*F7 -> 1.2983142 | J23: =I23/$I$32 -> 0.050468672
B24: Fuel Meter Uncertainty | C24: 0.0129 | H24: Tailgas | I24: =C69*F7 -> 0.12021179 | J24: =I24/$I$32 -> 0.0046729286
B25: Uncertainty Adjusted Total | C25: =C23*(1+C24) -> 4678.1228 | H25: Water | I25: =C75*F7 -> 0.0142204 | J25: =I25/$I$32 -> 0.00055278198
B26: Propane Combustion Emission Factor (kg CO2e/kg) | C26: ='Emission Factors'!E15*1000 -> 3.63 | H26: Consumables Delivery | I26: =C82*F7 -> 0.067265859 | J26: =I26/$I$32 -> 0.0026147898
B27: Total Propane Emissions (MT CO2e) | C27: =(C25*C26)/1000 -> 16.981586 | H27: Waste Disposal | I27: =C90*F7 -> 0 | J27: =I27/$I$32 -> 0
H28: Capital Goods EE | I28: =J8*F7 -> 4.1349055 | J28: =I28/$I$32 -> 0.16073397
A29: Diesel Combustion | H29: SP+C EE | I29: =J12*F7 -> 1.6556568 | J29: =I29/$I$32 -> 0.064359459
B30: Total Diesel Consumption for PP (L) | C30: 1737.5032
B31: Total Diesel Consumption for PP (Gal) | C31: 459
B32: Total Diesel Fills in Office Generator for PP (Gal) | C32: 0 | H32: Total | I32: =SUM(I19:I29) -> 25.72515
B33: Total Production Diesel Consumption for PP (Gal) | C33: 459
B34: Total Production Diesel Consumption for PP (kg) | C34: 1476.7178
B35: Fuel Meter Uncertainty | C35: 0.0129
B36: Uncertainty Adjusted Total | C36: =C34*(1+C35) -> 1495.7674
B37: Diesel Combustion Emission Factor (kg CO2e/kg) | C37: ='Emission Factors'!E14*1000 -> 3.87
B38: Total Diesel Emissions (MT CO2e) | C38: =(C37*C36)/1000 -> 5.7886199
B39: BCUs Applied (MT CO2e) | C39: =C38 -> 5.7886199
B40: Remaining Emissions to Allocate (MT CO2e) | C40: =C38-C39 -> 0
A42: Gasoline Combustion
...

Sheet Emission Factors
A1: Emission Factors
A2: Emissions Factor | B2: Unit | C2: Baseline Quantity | D2: Uncertainty Factor | E2: Final Quantity | F2: Source
A3: Truck Transport Fuel Use (Well to Wheel) -- Flatbed Truck | B3: MT CO2e/t-mi | C3: 0.0001384 | E3: 0.0001384 | F3: GLEC V3.2 2025
A4: Truck Transport Fuel Use (Well to Wheel) -- Tanker Truck | B4: MT CO2e/t-mi | C4: 0.0001143 | D4: 0 | E4: 0.0001143 | F4: GLEC V3.2 2025
A5: Vehicle Embodied Emissions --Tanker Truck | B5: MT CO2e/mi | C5: 0.00023756059 | E5: 0.00023756059 | F5: GLEC V3.2 2025
A6: Vehicle Embodied Emissions --Non-Tanker Truck | B6: MT CO2e/mi | C6: 0.00019279083 | E6: 0.00019279083 | F6: GLEC V3.2 2025
A8: Grid Electricity Use -- Kansas | B8: MTCO2e/kWh | C8: 0.00046555169 | E8: 0.00046555169 | F8: Green-E,USEPA, GREET 2025
A9: Wind RECs Use -- Kansas | B9: MTCO2e/kWh | C9: 1.0027197e-05 | E9: 1.0027197e-05 | F9: Green-E,USEPA, GREET 2025
A10: Grid Electricity Use -- Colorado | B10: MTCO2e/kWh | C10: 0.00048902383 | E10: 0.00048902383 | F10: Green-E,USEPA, GREET 2025
A11: Solar RECs Use -- Colorado | B11: MTCO2e/kWh | C11: 3.6641546e-05 | E11: 3.6641546e-05 | F11: Green-E,USEPA, GREET 2025
A12: Vaulted Equipment Embodied Emissions | B12: MT CO2e/MT Injectate | C12: 0.00010343352 | D12: N/A | E12: =C12 -> 0.00010343352 | F12: Vaulted PDD
A13: Self-Loading Truck Lumber Handling (No Transport) | B13: MT CO2e/MT logs | C13: 0.0015187908 | D13: N/A | E13: =C13 -> 0.0015187908 | F13: Auburn University
A14: Diesel Fuel Combustion (Total WTW) | B14: MTCO2e/kg fuel | C14: 0.00387 | D14: N/A | E14: =C14 -> 0.00387 | F14: GLEC V3.2 2025
A15: LPG Consumption (Total WTW) | B15: MTCO2e/kg fuel | C15: 0.00363 | D15: N/A | E15: =C15 -> 0.00363 | F15: GLEC V3.2 2025
A16: Gasoline Consumption (Total WTW) | B16: MTCO2e/kg fuel | C16: 0.00374 | D16: N/A | E16: =C16 -> 0.00374 | F16: GLEC V3.2 2025
A17: Drinking Water -- US | B17: MTCO2e/gal water | C17: 1.7412898e-06 | D17: N/A | E17: =C17 -> 1.7412898e-06 | F17: https://www.sciencedirect.com/science/article/abs/pii/S0959652621030110

Sheet DataTable
B2: ='Apr 26 PP Summary'!E5 -> Production Operating Hours | C2: ='Apr 26 PP Summary'!F5 -> 1966.7
B3: ='Apr 26 PP Summary'!I5 -> Total Biomass Consumed (MT) | C3: ='Apr 26 PP Summary'!J5 -> 62.24455
B4: =#REF! -> #REF! | C4: =#REF! -> #REF!
A5: Propane (kg) | B5: ='Apr 26 PP Summary'!B25 -> Uncertainty Adjusted Total | C5: ='Apr 26 PP Summary'!C25 -> 4678.1228
A6: Diesel (kg) | B6: ='Apr 26 PP Summary'!B36 -> Uncertainty Adjusted Total | C6: ='Apr 26 PP Summary'!C36 -> 1495.7674
A7: Gasoline (kg) | B7: ='Apr 26 PP Summary'!B46 -> Uncertainty Adjusted Total
B10: ='Apr 26 PP Summary'!H19 -> Biomass Transport | C10: ='Apr 26 PP Summary'!I19 -> 0.9663
B11: ='Apr 26 PP Summary'!H20 -> Propane | C11: ='Apr 26 PP Summary'!I20 -> 16.981586
B12: ='Apr 26 PP Summary'!H21 -> Diesel | C12: ='Apr 26 PP Summary'!I21 -> 0
B13: ='Apr 26 PP Summary'!H22 -> Gasoline | C13: ='Apr 26 PP Summary'!I22 -> 0.48668986
B14: ='Apr 26 PP Summary'!H23 -> Electricity | C14: ='Apr 26 PP Summary'!I23 -> 1.2983142
B15: ='Apr 26 PP Summary'!H24 -> Tailgas | C15: ='Apr 26 PP Summary'!I24 -> 0.12021179
B16: ='Apr 26 PP Summary'!H25 -> Water | C16: ='Apr 26 PP Summary'!I25 -> 0.0142204
B17: ='Apr 26 PP Summary'!H26 -> Consumables Delivery | C17: ='Apr 26 PP Summary'!I26 -> 0.067265859
B18: ='Apr 26 PP Summary'!H27 -> Waste Disposal | C18: ='Apr 26 PP Summary'!I27 -> 0
B19: ='Apr 26 PP Summary'!H28 -> Capital Goods EE | C19: ='Apr 26 PP Summary'!I28 -> 4.1349055
B20: ='Apr 26 PP Summary'!H29 -> SP+C EE | C20: ='Apr 26 PP Summary'!I29 -> 1.6556568
B21: ='Apr 26 PP Summary'!H32 -> Total | C21: ='Apr 26 PP Summary'!I32 -> 25.72515

Sheet DataCollection
A1: Production Operating Hours | B1: ='Apr 26 PP Summary'!F5 -> 1966.7
A2: Total BM Consumed | B2: ='Apr 26 PP Summary'!J5 -> 62.24455
A3: WODO Yield | B3: ='Apr 26 PP Summary'!N2 -> 17580.4
A4: WODO wt%C | B4: ='Apr 26 PP Summary'!P2 -> 0.4694
A5: Biochar Yield | B5: ='Apr 26 PP Summary'!N3 -> 4721.4
A6: Biochar wt%C | B6: ='Apr 26 PP Summary'!P3 -> 0.7799
A7: Biomass Transport | B7: ='Apr 26 PP Summary'!I19 -> 0.9663
A8: Propane | B8: ='Apr 26 PP Summary'!I20 -> 16.981586
A9: Diesel | B9: ='Apr 26 PP Summary'!I21 -> 0
A10: Gasoline | B10: ='Apr 26 PP Summary'!I22 -> 0.48668986
A11: Electricity | B11: ='Apr 26 PP Summary'!I23 -> 1.2983142
A12: Tailgas | B12: ='Apr 26 PP Summary'!I24 -> 0.12021179
A13: Water | B13: ='Apr 26 PP Summary'!I25 -> 0.0142204
A14: Consumables Delivery | B14: ='Apr 26 PP Summary'!I26 -> 0.067265859
A15: Waste Disposal | B15: ='Apr 26 PP Summary'!I27 -> 0
A16: Capital Goods EE | B16: ='Apr 26 PP Summary'!I28 -> 4.1349055
A17: SP+C EE | B17: ='Apr 26 PP Summary'!I29 -> 1.6556568
A18: Injection Emissions
A19: Aqueous Yield | B19: 75500
A20: [MRV] Biomass Miles | B20: ='Apr 26 PP Summary'!C14 -> 272
A21: [MRV] Raw Biomass Tonnes | B21: ='Apr 26 PP Summary'!C13 -> 101.01
A22: [MRV] Linear Feet Consumed | B22: --
A23: [MRV] Uncertainty Adjusted Propane Used | B23: ='Apr 26 PP Summary'!C25 -> 4678.1228
A24: [MRV] Uncertainty Adjusted Diesel Used | B24: ='Apr 26 PP Summary'!C36 -> 1495.7674
A25: [MRV] Uncertainty Adjusted Gasoline Used | B25: ='Apr 26 PP Summary'!C46 -> 130.13098
A26: [MRV] Uncertainty Adjusted Electricity | B26: ='Apr 26 PP Summary'!C59 -> 35432.844
A27: [MRV] Total Water Used | B27: ='Apr 26 PP Summary'!C73 -> 30951.38
