Workbook

Sheet December PP Summary
A1: Process Emissions | H1: Embodied Emissions | M1: Output Type | N1: Mass of Output (kg) | O1: % Output Mass | P1: C Content (%) | Q1: C Content Mass (kg) | R1: % C Content Mass | S1: Total Emissions Allocated to Fraction (MT CO2e) | T1: Kg Emissions/Kg Material
M2: WODO | N2: 6481 | O2: =N2/($N$2+$N$3+$N$4) -> 0.21809799 | P2: 0.4871 | Q2: =P2*N2 -> 3156.8951 | R2: =Q2/(SUM($Q$2+$Q$3+$Q$4)) -> 0.37848486 | S2: =R2*$I$32 -> 6.3007169 | T2: =(S2*1000)/N2 -> 0.97218282
A3: Biomass Transport | E3: Pyrolyzer Up-Time | H3: Equipment Amortization | M3: Biochar | N3: 4074 | O3: =N3/($N$2+$N$3+$N$4) -> 0.13709786 | P3: 0.8882 | Q3: =P3*N3 -> 3618.5268 | R3: =Q3/(SUM($Q$2+$Q$3+$Q$4)) -> 0.43383057 | S3: =R3*$I$32 -> 7.2220686 | T3: =(S3*1000)/N3 -> 1.7727218
B4: New Pile | E4: Total Operating Hours | F4: 964.8 | I4: Total Biomass Consumed (kg) | J4: =C67 -> 28947 | M4: Aqueous | N4: 19161 | O4: =N4/($N$2+$N$3+$N$4) -> 0.64480415 | P4: 0.0817 | Q4: =P4*N4 -> 1565.4537 | R4: =Q4/(SUM($Q$2+$Q$3+$Q$4)) -> 0.18768458 | S4: =R4*$I$32 -> 3.1244246 | T4: =(S4*1000)/N4 -> 0.16306166
B5: Process Emissions | C5: 1.7639 | E5: Production Operating Hours | F5: 964.8 | I5: Total Biomass Consumed (MT) | J5: =J4/1000 -> 28.947
B6: Embodied Emissions | C6: 0.038592432 | E6: R+D Operating Hours | F6: 0 | I6: Biomass Amortization Factor for PP (kg Co2e/MT biomass) | J6: 65.1
B7: Log Handling Emissions | C7: 0.36438 | E7: % Production | F7: =F5/F4 -> 1 | I7: Total Amortized Embodied Emissions (kg) | J7: =J6*J5 -> 1884.4497
E8: % R+D | F8: =F6/F4 -> 0 | I8: Total Amortized Embodied Emissions (MT) | J8: =J7/1000 -> 1.8844497
B9: Total Emissions | C9: =SUM(C5:C7) -> 2.1668724 | H9: Spare Parts and Consumables
B10: BCU's Applied | C10: =SUM(C5,C7) -> 2.12828 | E10: Total Procured Renewables | I10: EE Estimate per Pyrolyzer Operating Hour (kgCO2e) | J10: 0.83351
B11: Remaining Emissions to Allocate | C11: =C9-C10 -> 0.038592432 | E11: RD BCUs (MT CO2e) | F11: =Sum(C10,C39,C81,C89) -> 22.13319 | I11: Spare Parts and Consumables Estimate for Period (kg) | J11: =J10*(F5*(1.01)) -> 812.21215
E12: RECs (kWh) | F12: =C62 -> 25041.263 | I12: Spare Parts and Consumables Estimate for Period (MT) | J12: =J11/1000 -> 0.81221215
B13: Tonnes | C13: 239.92
B14: Miles | C14: 598.4
B15: Tonne-Miles | C15: 13051.56
A17: Propane Combustion
B18: Total PP Deliveries (L) | C18: 5477.87 | H18: Consolidated Emissions Inventory (No GHG Neutralization) | I18: Total Emissions (MT) | J18: % of Total
B19: Tank Level at PP Close (%) | C19: 0.78 | H19: Biomass Transport | I19: =C9*F7 -> 2.1668724 | J19: =I19/$I$32 -> 0.1301643
B20: Tank Level at PP Close (L) | C20: 2952.3 | H20: Propane | I20: =C27*F7 -> 10.101016 | J20: =I20/$I$32 -> 0.6067693
B21: Total Propane Consumption for PP (L) | C21: 5440.02 | H21: Diesel | I21: =C40*F7 -> 0 | J21: =I21/$I$32 -> 0
B22: Total Propane Consumption for PP (Gal) | C22: 1437.1 | H22: Gasoline | I22: =C48*F7 -> 0.36514903 | J22: =I22/$I$32 -> 0.021934548
B23: Total Propane Consumption for PP (kg) | C23: 2747.21 | H23: Electricity | I23: =C64*F7 -> 0.92025138 | J23: =I23/$I$32 -> 0.055279616
B24: Fuel Meter Uncertainty | C24: 0.0129 | H24: Tailgas | I24: =C69*F7 -> 0.055904825 | J24: =I24/$I$32 -> 0.0033582099
B25: Uncertainty Adjusted Total | C25: =C23*(1+C24) -> 2782.649 | H25: Water | I25: =C75*F7 -> 0.0079183759 | J25: =I25/$I$32 -> 0.00047565784
B26: Propane Combustion Emission Factor (kg CO2e/kg) | C26: ='Emission Factors'!E15*1000 -> 3.63 | H26: Consumables Delivery | I26: =C82*F7 -> 0.028 | J26: =I26/$I$32 -> 0.0016819635
B27: Total Propane Emissions (MT CO2e) | C27: =(C25*C26)/1000 -> 10.101016 | H27: Waste Disposal | I27: =C90*F7 -> 0.30543621 | J27: =I27/$I$32 -> 0.018347592
H28: Capital Goods EE | I28: =J8*F7 -> 1.8844497 | J28: =I28/$I$32 -> 0.11319913
A29: Diesel Combustion | H29: SP+C EE | I29: =J12*F7 -> 0.81221215 | J29: =I29/$I$32 -> 0.048789686 | K29: =SUM(J20,J28,J29) -> 0.76875811
B30: Total Diesel Consumption for PP (L) | C30: 5935.52
B31: Total Diesel Consumption for PP (Gal) | C31: 1568
B32: Total Diesel Fills in Office Generator for PP (Gal) | C32: 0 | H32: Total | I32: =SUM(I19:I30) -> 16.64721
B33: Total Production Diesel Consumption for PP (Gal) | C33: 1568
B34: Total Production Diesel Consumption for PP (kg) | C34: 5044.65
B35: Fuel Meter Uncertainty | C35: 0.0129
B36: Uncertainty Adjusted Total | C36: =C34*(1+C35) -> 5109.726
B37: Diesel Combustion Emission Factor (kg CO2e/kg) | C37: ='Emission Factors'!E14*1000 -> 3.87
B38: Total Diesel Emissions (MT CO2e) | C38: =(C37*C36)/1000 -> 19.77464
B39: BCUs Applied (MT CO2e) | C39: =C38 -> 19.77464
B40: Remaining Emissions to Allocate (MT CO2e) | C40: =C38-C39 -> 0
A42: Gasoline Combustion
...

Sheet Emission Factors
A1: Emission Factors
A2: Emissions Factor | B2: Unit | C2: Baseline Quantity | D2: Uncertainty Factor | E2: Final Quantity | F2: Source
A3: Truck Transport Fuel Use (Well to Wheel) -- Flatbed Truck | B3: MT CO2e/t-mi | C3: 0.000135156 | D3: N/A | E3: =C3 -> 0.000135156 | F3: GLEC V3.0 2024
A4: Truck Transport Fuel Use (Well to Wheel) -- Tanker Truck | B4: MT CO2e/t-mi | C4: 0.00011263 | D4: N/A | E4: =C4 -> 0.00011263 | F4: GLEC V3.0 2024
A5: Vehicle Embodied Emissions --Tanker Truck | B5: MT CO2e/mi | C5: 7.8799528e-05 | D5: N/A | E5: =C5 -> 7.8799528e-05 | F5: USEPA/GREET 2024
A6: Vehicle Embodied Emissions --Non-Tanker Truck | B6: MT CO2e/mi | C6: 6.44927e-05 | D6: N/A | E6: =C6 -> 6.44927e-05 | F6: USEPA/GREET 2024
A7: Embodied Emissions -- Liquid Caustic Soda (50% NaOH) | B7: MTCO2e/T LCS | C7: 0.89272 | D7: 0.0012002604 | E7: =D7+C7 -> 0.89392026 | F7: GREET 2024
A8: Electricity Use -- Kansas | B8: MTCO2e/kWh | C8: 0.00051089347 | D8: N/A | E8: =C8 -> 0.00051089347 | F8: Green-E,USEPA, GREET 2024
A9: Electricity Use -- Kansas w/ Wind RECs | B9: MTCO2e/kWh | C9: =0.01004415071/1000 -> 1.0044151e-05 | D9: N/A | E9: =C9 -> 1.0044151e-05 | F9: Green-E,USEPA, GREET 2024
A10: Electricity Use -- Colorado | B10: MTCO2e/kWh | C10: 0.00052490069 | D10: N/A | E10: =C10 -> 0.00052490069 | F10: Green-E,USEPA, GREET 2024
A11: Electricity Use -- Colorado w/ Solar RECs | B11: MTCO2e/kWh | C11: =0.03674940003/1000 -> 3.67494e-05 | D11: N/A | E11: =C11 -> 3.67494e-05 | F11: Green-E,USEPA, GREET 2024
A12: Vaulted Equipment Embodied Emissions | B12: MT CO2e/MT Injectate | C12: 0.00010343352 | D12: N/A | E12: =C12 -> 0.00010343352 | F12: Vaulted PDD
A13: Self-Loading Truck Lumber Handling (No Transport) | B13: MT CO2e/MT logs | C13: 0.0015187908 | D13: N/A | E13: =C13 -> 0.0015187908 | F13: Auburn University
A14: Diesel Fuel Combustion (Total WTW) | B14: MTCO2e/kg fuel | C14: 0.00387 | D14: N/A | E14: =C14 -> 0.00387 | F14: GLEC V3.0 2024
A15: LPG Consumption (Total WTW) | B15: MTCO2e/kg fuel | C15: 0.00363 | D15: N/A | E15: =C15 -> 0.00363 | F15: GLEC V3.0 2024
A16: Gasoline Consumption (Total WTW) | B16: MTCO2e/kg fuel | C16: 0.00374 | D16: N/A | E16: =C16 -> 0.00374 | F16: GLEC V3.0 2024
A17: Drinking Water -- US | B17: MTCO2e/gal water | C17: 1.7412898e-06 | D17: N/A | E17: =C17 -> 1.7412898e-06 | F17: https://www.sciencedirect.com/science/article/abs/pii/S0959652621030110

Sheet DataTable
B2: ='December PP Summary'!E5 -> Production Operating Hours | C2: ='December PP Summary'!F5 -> 964.8
B3: ='December PP Summary'!I5 -> Total Biomass Consumed (MT) | C3: ='December PP Summary'!J5 -> 28.947
B4: =#REF! -> #REF! | C4: =#REF! -> #REF!
A5: Propane (kg) | B5: ='December PP Summary'!B25 -> Uncertainty Adjusted Total | C5: ='December PP Summary'!C25 -> 2782.649
A6: Diesel (kg) | B6: ='December PP Summary'!B36 -> Uncertainty Adjusted Total | C6: ='December PP Summary'!C36 -> 5109.726
A7: Gasoline (kg) | B7: ='December PP Summary'!B46 -> Uncertainty Adjusted Total
B10: ='December PP Summary'!H19 -> Biomass Transport | C10: ='December PP Summary'!I19 -> 2.1668724
B11: ='December PP Summary'!H20 -> Propane | C11: ='December PP Summary'!I20 -> 10.101016
B12: ='December PP Summary'!H21 -> Diesel | C12: ='December PP Summary'!I21 -> 0
B13: ='December PP Summary'!H22 -> Gasoline | C13: ='December PP Summary'!I22 -> 0.36514903
B14: ='December PP Summary'!H23 -> Electricity | C14: ='December PP Summary'!I23 -> 0.92025138
B15: ='December PP Summary'!H24 -> Tailgas | C15: ='December PP Summary'!I24 -> 0.055904825
B16: ='December PP Summary'!H25 -> Water | C16: ='December PP Summary'!I25 -> 0.0079183759
B17: ='December PP Summary'!H26 -> Consumables Delivery | C17: ='December PP Summary'!I26 -> 0.028
B18: ='December PP Summary'!H27 -> Waste Disposal | C18: ='December PP Summary'!I27 -> 0.30543621
B19: ='December PP Summary'!H28 -> Capital Goods EE | C19: ='December PP Summary'!I28 -> 1.8844497
B20: ='December PP Summary'!H29 -> SP+C EE | C20: ='December PP Summary'!I29 -> 0.81221215
B21: ='December PP Summary'!H32 -> Total | C21: ='December PP Summary'!I32 -> 16.64721

Sheet DataCollection
A1: Production Operating Hours | B1: ='December PP Summary'!F5 -> 964.8
A2: Total BM Consumed | B2: ='December PP Summary'!J5 -> 28.947
A3: WODO Yield | B3: ='December PP Summary'!N2 -> 6481
A4: WODO wt%C | B4: ='December PP Summary'!P2 -> 0.4871
A5: Biochar Yield | B5: ='December PP Summary'!N3 -> 4074
A6: Biochar wt%C | B6: ='December PP Summary'!P3 -> 0.8882
A7: Biomass Transport | B7: ='December PP Summary'!I19 -> 2.1668724
A8: Propane | B8: ='December PP Summary'!I20 -> 10.101016
A9: Diesel | B9: ='December PP Summary'!I21 -> 0
A10: Gasoline | B10: ='December PP Summary'!I22 -> 0.36514903
A11: Electricity | B11: ='December PP Summary'!I23 -> 0.92025138
A12: Tailgas | B12: ='December PP Summary'!I24 -> 0.055904825
A13: Water | B13: ='December PP Summary'!I25 -> 0.0079183759
A14: Consumables Delivery | B14: ='December PP Summary'!I26 -> 0.028
A15: Waste Disposal | B15: ='December PP Summary'!I27 -> 0.30543621
A16: Capital Goods EE | B16: ='December PP Summary'!I28 -> 1.8844497
A17: SP+C EE | B17: ='December PP Summary'!I29 -> 0.81221215
A18: Injection Emissions
A19: Aqueous Yield | B19: 75500
A20: [MRV] Biomass Miles | B20: ='December PP Summary'!C14 -> 598.4
A21: [MRV] Raw Biomass Tonnes | B21: ='December PP Summary'!C13 -> 239.92
A22: [MRV] Linear Feet Consumed | B22: --
A23: [MRV] Uncertainty Adjusted Propane Used | B23: ='December PP Summary'!C25 -> 2782.649
A24: [MRV] Uncertainty Adjusted Diesel Used | B24: ='December PP Summary'!C36 -> 5109.726
A25: [MRV] Uncertainty Adjusted Gasoline Used | B25: ='December PP Summary'!C46 -> 97.633431
A26: [MRV] Uncertainty Adjusted Electricity | B26: ='December PP Summary'!C59 -> 25041.263
A27: [MRV] Total Water Used | B27: ='December PP Summary'!C73 -> 17234.72
