Workbook

Sheet PP7 Summary
A1: Process Emissions | H1: Embodied Emissions | M1: Output Type | N1: Mass of Output (kg) | O1: % Output Mass | P1: C Content (%) | Q1: C Content Mass (kg) | R1: % C Content Mass | S1: Total Emissions Allocated to Fraction (MT CO2e) | T1: Kg Emissions/Kg Material
M2: WODO | N2: 16899 | O2: =N2/($N$2+$N$3+$N$4) -> 0.16781029 | P2: 0.5052 | Q2: =P2*N2 -> 8537.3748 | R2: =Q2/(SUM($Q$2+$Q$3+$Q$4)) -> 0.35227621 | S2: =R2*$I$40 -> 12.733491 | T2: =(S2*1000)/N2 -> 0.7535056
A3: Biomass Transport | E3: Pyrolyzer Up-Time | H3: Equipment Amortization | M3: Biochar | N3: 10309 | O3: =N3/($N$2+$N$3+$N$4) -> 0.10237034 | P3: 0.8661 | Q3: =P3*N3 -> 8928.6249 | R3: =Q3/(SUM($Q$2+$Q$3+$Q$4)) -> 0.36842029 | S3: =R3*$I$40 -> 13.31704 | T3: =(S3*1000)/N3 -> 1.2917878
B4: Miles | C4: 7420.5 | E4: Total Operating Hours | F4: 3307.6 | I4: Total Biomass Consumed (kg) | J4: =C75 -> 116090 | M4: Aqueous | N4: 73495 | O4: =N4/($N$2+$N$3+$N$4) -> 0.72981937 | P4: 0.0921 | Q4: =P4*N4 -> 6768.8895 | R4: =Q4/(SUM($Q$2+$Q$3+$Q$4)) -> 0.27930351 | S4: =R4*$I$40 -> 10.095796 | T4: =(S4*1000)/N4 -> 0.13736711
B5: Tonnes | C5: 1787.92 | E5: Production Operating Hours | F5: =F4-F6 -> 3307.6 | I5: Total Biomass Consumed (MT) | J5: =J4/1000 -> 116.09
B6: Tonne-Miles | C6: 136775.76 | E6: R+D Operating Hours | F6: 0 | I6: Biomass Amortization Factor for PP (kg Co2e/MT biomass) | J6: 60.8
B7: Flatbed Truck Process Emissions Factor (MT CO2e/t-mi) | C7: 0.0001367939 | E7: % Production | F7: =F5/F4 -> 1 | I7: Total Amortized Embodied Emissions (kg) | J7: =J6*J5 -> 7058.272
B8: Non-Tanker Truck Embodied Emissions Factor (MT CO2e/mi) | C8: 6.2814439e-05 | E8: % R+D | F8: =F6/F4 -> 0 | I8: Total Amortized Embodied Emissions (MT) | J8: =J7/1000 -> 7.058272
B9: Log Handling Emissions Factor (MT CO2e/MT logs) | C9: 0.0015187908 | H9: Spare Parts and Consumables
B10: Delivery Process Emissions (MT CO2e) | C10: 18.71 | E10: Total Procured Renewables | I10: EE Estimate per Pyrolyzer Operating Hour (kgCO2e) | J10: 0.83105
B11: Delivery Embodied Emissions (MT CO2e) | C11: 0.47 | E11: RD BCUs (MT CO2e) | F11: =SUM(C22,C47,C89,C97,F23) -> 24.295943 | I11: Spare Parts and Consumables Estimate for Period (kg) | J11: =J10*(F5*(1.01)) -> 2776.2688
B12: Delivery Log Handling Emissions (MT CO2e) | C12: 2.72 | E12: RECs (kWh) | F12: =C70 -> 43444.301 | I12: Spare Parts and Consumables Estimate for Period (MT) | J12: =J11/1000 -> 2.7762688
B13: Total Delivery Emissions (MT CO2e) | C13: 21.89
B15: Starting Linear Feet Measurement | C15: 359.17
B17: Production Period 7 | E17: New Pile
B18: Ending Linear Feet Measurement | C18: 0 | E18: Process Emissions | F18: 1.5
B19: Linear Feet Consumed | C19: 40.5 | E19: Embodied Emissions | F19: 0.69
B20: Proportion of Total Linear Feet | C20: 0.11 | E20: Log Handling Emissions | F20: 0.36
B21: Total Emissions Allocated (MT CO2e) | C21: 2.47
B22: BCUs Applied (MT CO2e) | C22: =(C10+C12)*C20 -> 2.3573 | E22: Total Emissions | F22: =SUM(F18:F20) -> 2.55
B23: Remaining Emissions to Allocate -- Net of New Pile (MT CO2e) | C23: =C21-C22+F24 -> 0.8027 | E23: BCU's Applied | F23: =SUM(F18,F20) -> 1.86
E24: Remaining Emissiosn to Allocate | F24: =F22-F23 -> 0.69
A25: Propane Combustion
B26: Total PP Deliveries (L) | C26: 11021.6 | H26: Consolidated Emissions Inventory (No GHG Neutralization) | I26: Total Emissions (MT) | J26: % of Total
B27: Tank Level at PP Close (%) | C27: 0.23 | H27: Biomass Transport | I27: =C23*F7 -> 0.8027 | J27: =I27/$I$40 -> 0.022206959
B28: Tank Level at PP Close (L) | C28: 870.55 | H28: Propane | I28: =C35*F7 -> 22.924649 | J28: =I28/$I$40 -> 0.63421792
B29: Total Propane Consumption for PP (L) | C29: 12346.35 | H29: Diesel | I29: =C48*F7 -> 0 | J29: =I29/$I$40 -> 0
B30: Total Propane Consumption for PP (Gal) | C30: 3261.56 | H30: Gasoline | I30: =C56*F7 -> 0.61047584 | J30: =I30/$I$40 -> 0.016889014
B31: Total Propane Consumption for PP (kg) | C31: 6234.9 | H31: Electricity | I31: =C72*F7 -> 1.596552 | J31: =I31/$I$40 -> 0.044169135
B32: Fuel Meter Uncertainty | C32: 0.0129 | H32: Tailgas | I32: =C77*F7 -> 0.22420255 | J32: =I32/$I$40 -> 0.006202637
B33: Uncertainty Adjusted Total | C33: =C31*(1+C32) -> 6315.3302 | H33: Water | I33: =C83*F7 -> 0.033813357 | J33: =I33/$I$40 -> 0.00093545761
B34: Propane Combustion Emission Factor (kg CO2e/kg) | C34: ='Emission Factors'!E15*1000 -> 3.63 | H34: Consumables Delivery | I34: =C90*F7 -> 0.041 | J34: =I34/$I$40 -> 0.0011342784
B35: Total Propane Emissions (MT CO2e) | C35: =(C33*C34)/1000 -> 22.924649 | H35: Waste Disposal | I35: =C98*F7 -> 0.078394255 | J35: =I35/$I$40 -> 0.0021688028
H36: Capital Goods EE | I36: =J8*F7 -> 7.058272 | J36: =I36/$I$40 -> 0.19526941
A37: Diesel Combustion | H37: SP+C EE | I37: =J12*F7 -> 2.7762688 | J37: =I37/$I$40 -> 0.076806386
B38: Total Diesel Consumption for PP (L) | C38: 6942.44
B39: Total Diesel Consumption for PP (Gal) | C39: 1834
B40: Total Diesel Fills in Office Generator for PP (Gal) | C40: 250 | H40: Total | I40: =SUM(I27:I38) -> 36.146327
B41: Total Production Diesel Consumption for PP (Gal) | C41: 1584
B42: Total Production Diesel Consumption for PP (kg) | C42: 5096.12
...

Sheet Emission Factors
A1: Emission Factors
A2: Emissions Factor | B2: Unit | C2: Baseline Quantity | D2: Uncertainty Factor | E2: Final Quantity | F2: Source
A3: Truck Transport Fuel Use (Well to Wheel) -- Flatbed Truck | B3: MT CO2e/t-mi | C3: 0.000135156 | D3: N/A | E3: =C3 -> 0.000135156 | F3: GLEC V3.0 2024
A4: Truck Transport Fuel Use (Well to Wheel) -- Tanker Truck | B4: MT CO2e/t-mi | C4: 0.00011263 | D4: N/A | E4: =C4 -> 0.00011263 | F4: GLEC V3.0 2024
A5: Vehicle Embodied Emissions --Tanker Truck | B5: MT CO2e/mi | C5: 7.8799528e-05 | D5: N/A | E5: =C5 -> 7.8799528e-05 | F5: USEPA/GREET 2024
A6: Vehicle Embodied Emissions --Non-Tanker Truck | B6: MT CO2e/mi | C6: 6.44927e-05 | D6: N/A | E6: =C6 -> 6.44927e-05 | F6: USEPA/GREET 2024
A7: Embodied Emissions -- Liquid Caustic Soda (50% NaOH) | B7: MTCO2e/T LCS | C7: 0.89272 | D7: 0.0012002604 | E7: =D7+C7 -> 0.89392026 | F7: GREET 2024
A8: Electricity Use -- Kansas | B8: MTCO2e/kWh | C8: 0.00051089347 | D8: N/A | E8: =C8 -> 0.00051089347 | F8: Green-E,USEPA, GREET 2024
A9: Electricity Use -- Kansas w/ Wind RECs | B9: MTCO2e/kWh | C9: =0.01004415071/1000 -> 1.0044151e-05 | D9: N/A | E9: =C9 -> 1.0044151e-05 | F9: Green-E,USEPA, GREET 2024
A10: Electricity Use -- Colorado | B10: MTCO2e/kWh | C10: 0.00052490069 | D10: N/A | E10: =C10 -> 0.00052490069 | F10: Green-E,USEPA, GREET 2024
A11: Electricity Use -- Colorado w/ Solar RECs | B11: MTCO2e/kWh | C11: =0.03674940003/1000 -> 3.67494e-05 | D11: N/A | E11: =C11 -> 3.67494e-05 | F11: Green-E,USEPA, GREET 2024
A12: Vaulted Equipment Embodied Emissions | B12: MT CO2e/MT Injectate | C12: 0.00010343352 | D12: N/A | E12: =C12 -> 0.00010343352 | F12: Vaulted PDD
A13: Self-Loading Truck Lumber Handling (No Transport) | B13: MT CO2e/MT logs | C13: 0.0015187908 | D13: N/A | E13: =C13 -> 0.0015187908 | F13: Auburn University
A14: Diesel Fuel Combustion (Total WTW) | B14: MTCO2e/kg fuel | C14: 0.00387 | D14: N/A | E14: =C14 -> 0.00387 | F14: GLEC V3.0 2024
A15: LPG Consumption (Total WTW) | B15: MTCO2e/kg fuel | C15: 0.00363 | D15: N/A | E15: =C15 -> 0.00363 | F15: GLEC V3.0 2024
A16: Gasoline Consumption (Total WTW) | B16: MTCO2e/kg fuel | C16: 0.00374 | D16: N/A | E16: =C16 -> 0.00374 | F16: GLEC V3.0 2024
A17: Drinking Water -- US | B17: MTCO2e/gal water | C17: 1.7412898e-06 | D17: N/A | E17: =C17 -> 1.7412898e-06 | F17: https://www.sciencedirect.com/science/article/abs/pii/S0959652621030110

Sheet DataTable
B2: ='PP7 Summary'!E5 -> Production Operating Hours | C2: ='PP7 Summary'!F5 -> 3307.6
B3: ='PP7 Summary'!I5 -> Total Biomass Consumed (MT) | C3: ='PP7 Summary'!J5 -> 116.09
B4: ='PP7 Summary'!B19 -> Linear Feet Consumed | C4: ='PP7 Summary'!C19 -> 40.5
A5: Propane (kg) | B5: ='PP7 Summary'!B33 -> Uncertainty Adjusted Total | C5: ='PP7 Summary'!C33 -> 6315.3302
A6: Diesel (kg) | B6: ='PP7 Summary'!B44 -> Uncertainty Adjusted Total | C6: ='PP7 Summary'!C44 -> 5161.8599
A7: Gasoline (kg) | B7: ='PP7 Summary'!B54 -> Uncertainty Adjusted Total
B10: ='PP7 Summary'!H27 -> Biomass Transport | C10: ='PP7 Summary'!I27 -> 0.8027
B11: ='PP7 Summary'!H28 -> Propane | C11: ='PP7 Summary'!I28 -> 22.924649
B12: ='PP7 Summary'!H29 -> Diesel | C12: ='PP7 Summary'!I29 -> 0
B13: ='PP7 Summary'!H30 -> Gasoline | C13: ='PP7 Summary'!I30 -> 0.61047584
B14: ='PP7 Summary'!H31 -> Electricity | C14: ='PP7 Summary'!I31 -> 1.596552
B15: ='PP7 Summary'!H32 -> Tailgas | C15: ='PP7 Summary'!I32 -> 0.22420255
B16: ='PP7 Summary'!H33 -> Water | C16: ='PP7 Summary'!I33 -> 0.033813357
B17: ='PP7 Summary'!H34 -> Consumables Delivery | C17: ='PP7 Summary'!I34 -> 0.041
B18: ='PP7 Summary'!H35 -> Waste Disposal | C18: ='PP7 Summary'!I35 -> 0.078394255
B19: ='PP7 Summary'!H36 -> Capital Goods EE | C19: ='PP7 Summary'!I36 -> 7.058272
B20: ='PP7 Summary'!H37 -> SP+C EE | C20: ='PP7 Summary'!I37 -> 2.7762688
B21: ='PP7 Summary'!H40 -> Total | C21: ='PP7 Summary'!I40 -> 36.146327

Sheet DataCollection
A1: Production Operating Hours | B1: ='PP7 Summary'!F5 -> 3307.6
A2: Total BM Consumed | B2: ='PP7 Summary'!J5 -> 116.09
A3: WODO Yield | B3: ='PP7 Summary'!N2 -> 16899
A4: WODO wt%C | B4: ='PP7 Summary'!P2 -> 0.5052
A5: Biochar Yield | B5: ='PP7 Summary'!N3 -> 10309
A6: Biochar wt%C | B6: ='PP7 Summary'!P3 -> 0.8661
A7: Biomass Transport | B7: ='PP7 Summary'!I27 -> 0.8027
A8: Propane | B8: ='PP7 Summary'!I28 -> 22.924649
A9: Diesel | B9: ='PP7 Summary'!I29 -> 0
A10: Gasoline | B10: ='PP7 Summary'!I30 -> 0.61047584
A11: Electricity | B11: ='PP7 Summary'!I31 -> 1.596552
A12: Tailgas | B12: ='PP7 Summary'!I32 -> 0.22420255
A13: Water | B13: ='PP7 Summary'!I33 -> 0.033813357
A14: Consumables Delivery | B14: ='PP7 Summary'!I34 -> 0.041
A15: Waste Disposal | B15: ='PP7 Summary'!I35 -> 0.078394255
A16: Capital Goods EE | B16: ='PP7 Summary'!I36 -> 7.058272
A17: SP+C EE | B17: ='PP7 Summary'!I37 -> 2.7762688
A18: Injection Emissions
A19: Aqueous Yield | B19: 75500
A20: [MRV] Biomass Miles | B20: ='PP7 Summary'!C4 -> 7420.5
A21: [MRV] Raw Biomass Tonnes | B21: ='PP7 Summary'!C5 -> 1787.92
A22: [MRV] Linear Feet Consumed | B22: ='PP7 Summary'!C19 -> 40.5
A23: [MRV] Uncertainty Adjusted Propane Used | B23: ='PP7 Summary'!C33 -> 6315.3302
A24: [MRV] Uncertainty Adjusted Diesel Used | B24: ='PP7 Summary'!C44 -> 5161.8599
A25: [MRV] Uncertainty Adjusted Gasoline Used | B25: ='PP7 Summary'!C54 -> 163.22884
A26: [MRV] Uncertainty Adjusted Electricity | B26: ='PP7 Summary'!C67 -> 43444.301
A27: [MRV] Total Water Used | B27: ='PP7 Summary'!C81 -> 73596.38
