Workbook
Name coeff_d_e3570590_c0c7_48ab_99fe_9199863db98b: #REF!
Name coeff_d_f6c87698_8b8a_4580_8187_533f99afdba0: #REF!
Name coeff_d_742bd4bf_4fb9_4c16_be4b_074d0687253b: 'Basco Injection -- COBB'!$A$2:$M$89
Name coeff_d_e3cac388_7988_4f67_95ad_68fda5a4d14e: 'Basco Injection -- SOBB'!$A$2:$D$58
Name coeff_d_310c7906_ecbd_41fd_815e_ce444f066fc6: 'COBB (with offload info)'!$A$2:$I$38
Name coeff_d_7575b06d_36ad_4354_9105_86221b23853b: #REF!
Name coeff_d_dce31f25_6a50_4ef2_8731_48e4fc48dfc3: 'Basco Injection -- Main'!$A$2:$G$6
Name coeff_d_396fa8a6_9922_43fe_9fc6_0833ac761b3e: #REF!

Sheet PickupInjection Timeline

Sheet Naming Conventions
A1: PO Naming Convention
A3: Any load from AECN will have the following PO convention
A5: 001T1R0 | B5: - (001) | C5: This refers to the total number of POs, and will increase with each new PO generated
A6: truck to rail | B6: - T1 | C6: This refers to the truck that is being loaded at AECN, and for long haul truck loads, this will always be T1, for loads going rail, this will increase with the number of trucks it takes to fill a railcar
B7: - R1 | C7: This refers to the number railcar that we are filling with trucks, and will increase with each railload starting at 1
A9: Any load from Maize, KS to any site will have the following PO convention
A11: 001R1T1 | B11: - (001) | C11: This refers to the total number of POs, and will increase with each new PO generated
A12: rail to truck | B12: - R1 | C12: This refers to the number railcar that we are unloading with trucks, and will increase with each railload starting at 1
B13: - T1 | C13: This refers to the truck that is being loaded at Maize, KS location, and for loads coming from rail, this will increase with the number of trucks it takes to empty a railcar
A15: Any load from any location directly to Vaulted will have the following PO convention
A17: 001V | B17: - (001) | C17: This refers to the total number of POs, and will increase with each new PO generated
B18: - V | C18: This refers to the load going to Vauled
A21: Month | B21: January | C21: February | D21: March | E21: April | F21: May | G21: June | H21: July | I21: August | J21: September | K21: October | L21: November | M21: December | N21: 2024
A22: Total Metric Tons by Rail | B22: 80 | C22: 240 | D22: 320 | E22: 240 | F22: 560 | G22: 720 | H22: 640 | I22: 560 | J22: 720 | K22: 960 | L22: 240 | M22: 960 | N22: 6240
A23: Total Liters by Rail | B23: =B22*$A$25 -> 80000 | C23: =C22*$A$25 -> 240000 | D23: =D22*$A$25 -> 320000 | E23: =E22*$A$25 -> 240000 | F23: =F22*$A$25 -> 560000 | G23: =G22*$A$25 -> 720000 | H23: =H22*$A$25 -> 640000 | I23: =I22*$A$25 -> 560000 | ... N23: =N22*$A$25 -> 6240000
A25: 1000

Sheet Loads
A1: load_id | B1: PO # | C1: BOL | D1: COA | E1: PCB Invoices (Receipt Received | F1: Invoice (Payment to AECN) | G1: Customs Document Sent (Rail) | H1: Supplier | I1: Mode | J1: Delivery Location | K1: Carrier | L1: ID | M1: Forecasted Asset ID | N1: Pickup Date | O1: Delivery Date | P1: MFO PO # | Q1: Actual Loaded (metric tons) | R1: Gallons Loaded | S1: Single-Blend %C | T1: Carbon Content (%) | U1: Gross (t CO₂e) | V1: Pyrolysis (t CO₂e ) | W1: KAG Transport Distance (mi) | X1: KAG Transport (t CO₂e) | Y1: TBC Transport Distance | Z1: TBC Transport (t CO₂e) | AA1: Train Transport Distance | AB1: Train Transport (t CO₂e) | AC1: Maize Transport Distance | AD1: Maize Transport (t CO₂e) | AE1: Bio-oil Treatment (t CO₂e) | AF1: Hutch Transport Distance | AG1: Hutch Transport (t CO₂e) | AH1: Injection (t CO₂e) | AI1: Emitted (t CO₂e) | AJ1: Net (t CO₂e) | AK1: 2024 t CO₂e | AL1: t CO₂e / t bio-oil | AN1: Blend Count | AO1: PO # | AP1: Chip | AQ1: Link | AR1: BOL Text
A2: 1 | B2: 033T1R0 | D2: RS2-240221 | F2: paid | G2: NA | H2: AECN | I2: truck | K2: KAG | L2: Guy | N2: 45352 | O2: 45355 | Q2: 20.07 | S2: =iferror(if(AN2=1,VLOOKUP(B2, Blends!H$4:AK$1004,32,0), ""), "") | T2: 0.4483 | U2: =Q2*T2*(44.01/12.011) -> 32.967674 | V2: =$Q2*('MRV Calcs'!$E$3+'MRV Calcs'!$E$4) -> 2.9691947 | W2: =IF(H2="AECN",2030,"ERROR") -> 2030 | X2: =IF($I2="truck",($Q2*$W2*'MRV Calcs'!$E$7)+($W2*'MRV Calcs'!$E$8),0) -> 5.4012318 | Y2: =IF($I2="train",'MRV Calcs'!$E$24,0) -> 0 | Z2: =IF($I2="train",($Q2*$Y2*'MRV Calcs'!$E$7)+($Y2*'MRV Calcs'!$E$8),0) -> 0 | AA2: =IF($I2="train",'MRV Calcs'!$E$25,0) -> 0 | AB2: =IF($I2="train",($Q2*$AA2*'MRV Calcs'!$E$11)+($AA2*'MRV Calcs'!$E$12),0) -> 0 | AC2: =IF($I2="train",'MRV Calcs'!$E$26,0) -> 0 | AD2: =IF($I2="train",($Q2*$AC2*'MRV Calcs'!$E$7)+($AC2*'MRV Calcs'!$E$8),0) -> 0 | AE2: =($Q2/30)*SUM('MRV Calcs'!$E$15:$E$16) -> 3.038107 | AF2: ='MRV Calcs'!$E$27 -> 71.2 | AG2: =(($Q2*1.1)*$AF2*'MRV Calcs'!$E$7)+($AF2*'MRV Calcs'!$E$8) -> 0.20783999 | AH2: =(($Q2*1.1)/20)*SUM('MRV Calcs'!$E$19:$E$20) -> 0.02825856 | AI2: =SUM(AH2,AG2,AE2,AD2,AB2,Z2,X2,V2) -> 11.644632 | AJ2: =U2-AI2 -> 21.323042 | AK2: =AJ2 -> 21.323042 | AL2: =AJ2/Q2 -> 1.0624336 | AN2: =COUNTIF(Blends!H$4:H$1007,B2)+COUNTIF(Blends!J$4:J$1007,B2)+COUNTIF(#REF!,B2) -> 0 | AO2: =B2 -> 033T1R0 | AP2: Billing Camion 1117.pdf | AQ2: =IFERROR(__xludf.DUMMYFUNCTION("AP2.url"),"https://drive.google.com/file/d/19_rylkSc1iflh2fzW0GYdWbK3nkiW5OP/view?usp=drive_link") -> https://drive.google.com/file/d/19_rylkSc1iflh2fzW0GYdWbK3nkiW5OP/view?usp=drive_link
A3: 2 | B3: 034T1R0 | D3: RS2-240221 | F3: paid | G3: NA | H3: AECN | I3: truck | K3: KAG | L3: Darryl | N3: 45373 | O3: 45376 | Q3: 19.63 | S3: =iferror(if(AN3=1,VLOOKUP(B3, Blends!H$4:AK$1004,32,0), ""), "") | T3: 0.4257 | U3: =Q3*T3*(44.01/12.011) -> 30.619363 | V3: =$Q3*('MRV Calcs'!$E$3+'MRV Calcs'!$E$4) -> 2.9041002 | W3: =IF(H3="AECN",2030,"ERROR") -> 2030 | X3: =IF($I3="truck",($Q3*$W3*'MRV Calcs'!$E$7)+($W3*'MRV Calcs'!$E$8),0) -> 5.2862348 | Y3: =IF($I3="train",'MRV Calcs'!$E$24,0) -> 0 | Z3: =IF($I3="train",($Q3*$Y3*'MRV Calcs'!$E$7)+($Y3*'MRV Calcs'!$E$8),0) -> 0 | AA3: =IF($I3="train",'MRV Calcs'!$E$25,0) -> 0 | AB3: =IF($I3="train",($Q3*$AA3*'MRV Calcs'!$E$11)+($AA3*'MRV Calcs'!$E$12),0) -> 0 | AC3: =IF($I3="train",'MRV Calcs'!$E$26,0) -> 0 | AD3: =IF($I3="train",($Q3*$AC3*'MRV Calcs'!$E$7)+($AC3*'MRV Calcs'!$E$8),0) -> 0 | AE3: =($Q3/30)*SUM('MRV Calcs'!$E$15:$E$16) -> 2.9715017 | AF3: ='MRV Calcs'!$E$27 -> 71.2 | AG3: =(($Q3*1.1)*$AF3*'MRV Calcs'!$E$7)+($AF3*'MRV Calcs'!$E$8) -> 0.20340326 | AH3: =(($Q3*1.1)/20)*SUM('MRV Calcs'!$E$19:$E$20) -> 0.02763904 | AI3: =SUM(AH3,AG3,AE3,AD3,AB3,Z3,X3,V3) -> 11.392879 | AJ3: =U3-AI3 -> 19.226484 | AK3: =AJ3+AK2 -> 40.549526 | AL3: =AJ3/Q3 -> 0.97944391 | AN3: =COUNTIF(Blends!H$4:H$1007,B3)+COUNTIF(Blends!J$4:J$1007,B3)+COUNTIF(#REF!,B3) -> 1 | AO3: =B3 -> 034T1R0 | AP3: Envoi des documents camion 1178.pdf | AQ3: =IFERROR(__xludf.DUMMYFUNCTION("AP3.url"),"https://drive.google.com/file/d/1Fg9KFgPqKmiJN0v3nSsbov1HhxBi6Wr_/view?usp=drive_link") -> https://drive.google.com/file/d/1Fg9KFgPqKmiJN0v3nSsbov1HhxBi6Wr_/view?usp=drive_link
A4: 3 | B4: 035T1R0 | D4: RS3-240322 | F4: paid | G4: NA | H4: AECN | I4: truck | K4: KAG | L4: Gus/Darryl | N4: 45380 | O4: 45383 | Q4: 21.03 | S4: =iferror(if(AN4=1,VLOOKUP(B4, Blends!H$4:AK$1004,32,0), ""), "") | T4: 0.42 | U4: =Q4*T4*(44.01/12.011) -> 32.363894 | V4: =$Q4*('MRV Calcs'!$E$3+'MRV Calcs'!$E$4) -> 3.1112189 | W4: =IF(H4="AECN",2030,"ERROR") -> 2030 | X4: =IF($I4="truck",($Q4*$W4*'MRV Calcs'!$E$7)+($W4*'MRV Calcs'!$E$8),0) -> 5.6521343 | Y4: =IF($I4="train",'MRV Calcs'!$E$24,0) -> 0 | Z4: =IF($I4="train",($Q4*$Y4*'MRV Calcs'!$E$7)+($Y4*'MRV Calcs'!$E$8),0) -> 0 | AA4: =IF($I4="train",'MRV Calcs'!$E$25,0) -> 0 | AB4: =IF($I4="train",($Q4*$AA4*'MRV Calcs'!$E$11)+($AA4*'MRV Calcs'!$E$12),0) -> 0 | AC4: =IF($I4="train",'MRV Calcs'!$E$26,0) -> 0 | AD4: =IF($I4="train",($Q4*$AC4*'MRV Calcs'!$E$7)+($AC4*'MRV Calcs'!$E$8),0) -> 0 | AE4: =($Q4/30)*SUM('MRV Calcs'!$E$15:$E$16) -> 3.1834275 | AF4: ='MRV Calcs'!$E$27 -> 71.2 | AG4: =(($Q4*1.1)*$AF4*'MRV Calcs'!$E$7)+($AF4*'MRV Calcs'!$E$8) -> 0.21752013 | AH4: =(($Q4*1.1)/20)*SUM('MRV Calcs'!$E$19:$E$20) -> 0.02961024 | AI4: =SUM(AH4,AG4,AE4,AD4,AB4,Z4,X4,V4) -> 12.193911 | AJ4: =U4-AI4 -> 20.169982 | AK4: =AJ4+AK3 -> 60.719509 | AL4: =AJ4/Q4 -> 0.95910521 | AN4: =COUNTIF(Blends!H$4:H$1007,B4)+COUNTIF(Blends!J$4:J$1007,B4)+COUNTIF(#REF!,B4) -> 1 | AO4: =B4 -> 035T1R0 | AP4: Envoi des documents Camion 1192.pdf | AQ4: =IFERROR(__xludf.DUMMYFUNCTION("AP4.url"),"https://drive.google.com/file/d/1OLnsDJWSPWqo9cQ28dNO0ypTjupeCahJ/view?usp=drive_link") -> https://drive.google.com/file/d/1OLnsDJWSPWqo9cQ28dNO0ypTjupeCahJ/view?usp=drive_link
A5: 4 | B5: 036T1R0 | D5: RS3-240322 | F5: paid | G5: NA | H5: AECN | I5: truck | K5: KAG | L5: Guy | N5: 45380 | O5: 45383 | Q5: 20.04 | S5: =iferror(if(AN5=1,VLOOKUP(B5, Blends!H$4:AK$1004,32,0), ""), "") | T5: 0.431 | U5: =Q5*T5*(44.01/12.011) -> 31.648067 | V5: =$Q5*('MRV Calcs'!$E$3+'MRV Calcs'!$E$4) -> 2.9647564 | W5: =IF(H5="AECN",2030,"ERROR") -> 2030 | X5: =IF($I5="truck",($Q5*$W5*'MRV Calcs'!$E$7)+($W5*'MRV Calcs'!$E$8),0) -> 5.3933911 | Y5: =IF($I5="train",'MRV Calcs'!$E$24,0) -> 0 | Z5: =IF($I5="train",($Q5*$Y5*'MRV Calcs'!$E$7)+($Y5*'MRV Calcs'!$E$8),0) -> 0 | AA5: =IF($I5="train",'MRV Calcs'!$E$25,0) -> 0 | AB5: =IF($I5="train",($Q5*$AA5*'MRV Calcs'!$E$11)+($AA5*'MRV Calcs'!$E$12),0) -> 0 | AC5: =IF($I5="train",'MRV Calcs'!$E$26,0) -> 0 | AD5: =IF($I5="train",($Q5*$AC5*'MRV Calcs'!$E$7)+($AC5*'MRV Calcs'!$E$8),0) -> 0 | AE5: =($Q5/30)*SUM('MRV Calcs'!$E$15:$E$16) -> 3.0335657 | AF5: ='MRV Calcs'!$E$27 -> 71.2 | AG5: =(($Q5*1.1)*$AF5*'MRV Calcs'!$E$7)+($AF5*'MRV Calcs'!$E$8) -> 0.20753748 | AH5: =(($Q5*1.1)/20)*SUM('MRV Calcs'!$E$19:$E$20) -> 0.02821632 | AI5: =SUM(AH5,AG5,AE5,AD5,AB5,Z5,X5,V5) -> 11.627467 | AJ5: =U5-AI5 -> 20.0206 | AK5: =AJ5+AK4 -> 80.740109 | AL5: =AJ5/Q5 -> 0.99903193 | AN5: =COUNTIF(Blends!H$4:H$1007,B5)+COUNTIF(Blends!J$4:J$1007,B5)+COUNTIF(#REF!,B5) -> 2 | AO5: =B5 -> 036T1R0 | AP5: Envoi des documents Camion 1193.pdf | AQ5: =IFERROR(__xludf.DUMMYFUNCTION("AP5.url"),"https://drive.google.com/file/d/14-2vZnVgWzlhAjdYzHmLknoAv_PIlC0y/view?usp=drive_link") -> https://drive.google.com/file/d/14-2vZnVgWzlhAjdYzHmLknoAv_PIlC0y/view?usp=drive_link
A6: 5 | B6: 037T1R0 | D6: RS2-240401 | F6: paid | G6: NA | H6: AECN | I6: truck | K6: KAG | L6: Gaston | N6: 45387 | O6: 45390 | Q6: 21 | S6: =iferror(if(AN6=1,VLOOKUP(B6, Blends!H$4:AK$1004,32,0), ""), "") | T6: 0.424 | U6: =Q6*T6*(44.01/12.011) -> 32.625513 | V6: =$Q6*('MRV Calcs'!$E$3+'MRV Calcs'!$E$4) -> 3.1067807 | W6: =IF(H6="AECN",2030,"ERROR") -> 2030 | X6: =IF($I6="truck",($Q6*$W6*'MRV Calcs'!$E$7)+($W6*'MRV Calcs'!$E$8),0) -> 5.6442936 | Y6: =IF($I6="train",'MRV Calcs'!$E$24,0) -> 0 | Z6: =IF($I6="train",($Q6*$Y6*'MRV Calcs'!$E$7)+($Y6*'MRV Calcs'!$E$8),0) -> 0 | AA6: =IF($I6="train",'MRV Calcs'!$E$25,0) -> 0 | AB6: =IF($I6="train",($Q6*$AA6*'MRV Calcs'!$E$11)+($AA6*'MRV Calcs'!$E$12),0) -> 0 | AC6: =IF($I6="train",'MRV Calcs'!$E$26,0) -> 0 | AD6: =IF($I6="train",($Q6*$AC6*'MRV Calcs'!$E$7)+($AC6*'MRV Calcs'!$E$8),0) -> 0 | AE6: =($Q6/30)*SUM('MRV Calcs'!$E$15:$E$16) -> 3.1788862 | AF6: ='MRV Calcs'!$E$27 -> 71.2 | AG6: =(($Q6*1.1)*$AF6*'MRV Calcs'!$E$7)+($AF6*'MRV Calcs'!$E$8) -> 0.21721762 | AH6: =(($Q6*1.1)/20)*SUM('MRV Calcs'!$E$19:$E$20) -> 0.029568 | AI6: =SUM(AH6,AG6,AE6,AD6,AB6,Z6,X6,V6) -> 12.176746 | AJ6: =U6-AI6 -> 20.448767 | AK6: =AJ6+AK5 -> 101.18888 | AL6: =AJ6/Q6 -> 0.97375082 | AN6: =COUNTIF(Blends!H$4:H$1007,B6)+COUNTIF(Blends!J$4:J$1007,B6)+COUNTIF(#REF!,B6) -> 1 | AO6: =B6 -> 037T1R0 | AP6: Billing doc 1211.pdf | AQ6: =IFERROR(__xludf.DUMMYFUNCTION("AP6.url"),"https://drive.google.com/file/d/1xJYGaRC0-HFs2Q7LNvDIHKvQNJx2rQ6l/view?usp=drive_link") -> https://drive.google.com/file/d/1xJYGaRC0-HFs2Q7LNvDIHKvQNJx2rQ6l/view?usp=drive_link
A7: 6 | B7: 041T1R0 | D7: RS1-240407 | F7: paid | G7: NA | H7: AECN | I7: truck | K7: KAG | L7: Guy | N7: 45394 | O7: 45397 | Q7: 20.2 | S7: =iferror(if(AN7=1,VLOOKUP(B7, Blends!H$4:AK$1004,32,0), ""), "") | T7: 0.42 | U7: =Q7*T7*(44.01/12.011) -> 31.086574 | V7: =$Q7*('MRV Calcs'!$E$3+'MRV Calcs'!$E$4) -> 2.9884271 | W7: =IF(H7="AECN",2030,"ERROR") -> 2030 | X7: =IF($I7="truck",($Q7*$W7*'MRV Calcs'!$E$7)+($W7*'MRV Calcs'!$E$8),0) -> 5.4352082 | Y7: =IF($I7="train",'MRV Calcs'!$E$24,0) -> 0 | Z7: =IF($I7="train",($Q7*$Y7*'MRV Calcs'!$E$7)+($Y7*'MRV Calcs'!$E$8),0) -> 0 | AA7: =IF($I7="train",'MRV Calcs'!$E$25,0) -> 0 | AB7: =IF($I7="train",($Q7*$AA7*'MRV Calcs'!$E$11)+($AA7*'MRV Calcs'!$E$12),0) -> 0 | AC7: =IF($I7="train",'MRV Calcs'!$E$26,0) -> 0 | AD7: =IF($I7="train",($Q7*$AC7*'MRV Calcs'!$E$7)+($AC7*'MRV Calcs'!$E$8),0) -> 0 | AE7: =($Q7/30)*SUM('MRV Calcs'!$E$15:$E$16) -> 3.0577858 | AF7: ='MRV Calcs'!$E$27 -> 71.2 | AG7: =(($Q7*1.1)*$AF7*'MRV Calcs'!$E$7)+($AF7*'MRV Calcs'!$E$8) -> 0.20915084 | AH7: =(($Q7*1.1)/20)*SUM('MRV Calcs'!$E$19:$E$20) -> 0.0284416 | AI7: =SUM(AH7,AG7,AE7,AD7,AB7,Z7,X7,V7) -> 11.719014 | AJ7: =U7-AI7 -> 19.36756 | AK7: =AJ7+AK6 -> 120.55644 | AL7: =AJ7/Q7 -> 0.95879012 | AN7: =COUNTIF(Blends!H$4:H$1007,B7)+COUNTIF(Blends!J$4:J$1007,B7)+COUNTIF(#REF!,B7) -> 2 | AO7: =B7 -> 041T1R0 | AP7: documents camion 1233.pdf | AQ7: =IFERROR(__xludf.DUMMYFUNCTION("AP7.url"),"https://drive.google.com/file/d/1MwHEXkZETjEuIxHNwgrns8tM2lLY7C59/view?usp=drive_link") -> https://drive.google.com/file/d/1MwHEXkZETjEuIxHNwgrns8tM2lLY7C59/view?usp=drive_link
A8: 7 | B8: 042T1R0 | D8: RS1-240407 | F8: paid | G8: NA | H8: AECN | I8: truck | K8: KAG | L8: Darryl | N8: 45394 | O8: 45397 | Q8: 20.63 | S8: =iferror(if(AN8=1,VLOOKUP(B8, Blends!H$4:AK$1004,32,0), ""), "") | T8: 0.4163 | U8: =Q8*T8*(44.01/12.011) -> 31.46863 | V8: =$Q8*('MRV Calcs'!$E$3+'MRV Calcs'!$E$4) -> 3.0520422 | W8: =IF(H8="AECN",2030,"ERROR") -> 2030 | X8: =IF($I8="truck",($Q8*$W8*'MRV Calcs'!$E$7)+($W8*'MRV Calcs'!$E$8),0) -> 5.5475916 | Y8: =IF($I8="train",'MRV Calcs'!$E$24,0) -> 0 | Z8: =IF($I8="train",($Q8*$Y8*'MRV Calcs'!$E$7)+($Y8*'MRV Calcs'!$E$8),0) -> 0 | AA8: =IF($I8="train",'MRV Calcs'!$E$25,0) -> 0 | AB8: =IF($I8="train",($Q8*$AA8*'MRV Calcs'!$E$11)+($AA8*'MRV Calcs'!$E$12),0) -> 0 | AC8: =IF($I8="train",'MRV Calcs'!$E$26,0) -> 0 | AD8: =IF($I8="train",($Q8*$AC8*'MRV Calcs'!$E$7)+($AC8*'MRV Calcs'!$E$8),0) -> 0 | AE8: =($Q8/30)*SUM('MRV Calcs'!$E$15:$E$16) -> 3.1228773 | AF8: ='MRV Calcs'!$E$27 -> 71.2 | AG8: =(($Q8*1.1)*$AF8*'MRV Calcs'!$E$7)+($AF8*'MRV Calcs'!$E$8) -> 0.21348674 | AH8: =(($Q8*1.1)/20)*SUM('MRV Calcs'!$E$19:$E$20) -> 0.02904704 | AI8: =SUM(AH8,AG8,AE8,AD8,AB8,Z8,X8,V8) -> 11.965045 | AJ8: =U8-AI8 -> 19.503586 | AK8: =AJ8+AK7 -> 140.06002 | AL8: =AJ8/Q8 -> 0.9453992 | AN8: =COUNTIF(Blends!H$4:H$1007,B8)+COUNTIF(Blends!J$4:J$1007,B8)+COUNTIF(#REF!,B8) -> 1 | AO8: =B8 -> 042T1R0 | AP8: Billing Docs 1234 Corrected PO number.pdf | AQ8: =IFERROR(__xludf.DUMMYFUNCTION("AP8.url"),"https://drive.google.com/file/d/1lGvPefgsd3yKrbNNNClUpWnFQLNXBxPm/view?usp=drive_link") -> https://drive.google.com/file/d/1lGvPefgsd3yKrbNNNClUpWnFQLNXBxPm/view?usp=drive_link
A9: 8 | B9: 038-040T2R1 | D9: RS3-240404 | F9: paid | G9: NA | H9: AECN | I9: train | K9: Transport Baie-Comeau | L9: STPX 094926 | N9: 45394 | O9: 45415 | Q9: =25.95+26.08+25.82 -> 77.85 | S9: =iferror(if(AN9=1,VLOOKUP(B9, Blends!H$4:AK$1004,32,0), ""), "") | T9: 0.42 | U9: =Q9*T9*(44.01/12.011) -> 119.80642 | V9: =$Q9*('MRV Calcs'!$E$3+'MRV Calcs'!$E$4) -> 11.51728 | W9: =IF(H9="AECN",2030,"ERROR") -> 2030 | X9: =IF($I9="truck",($Q9*$W9*'MRV Calcs'!$E$7)+($W9*'MRV Calcs'!$E$8),0) -> 0 | Y9: =IF($I9="train",'MRV Calcs'!$E$24,0) -> 107.497 | Z9: =IF($I9="train",($Q9*$Y9*'MRV Calcs'!$E$7)+($Y9*'MRV Calcs'!$E$8),0) -> 1.0856894 | AA9: =IF($I9="train",'MRV Calcs'!$E$25,0) -> 2087 | AB9: =IF($I9="train",($Q9*$AA9*'MRV Calcs'!$E$11)+($AA9*'MRV Calcs'!$E$12),0) -> 4.351363 | AC9: =IF($I9="train",'MRV Calcs'!$E$26,0) -> 32.6 | AD9: =IF($I9="train",($Q9*$AC9*'MRV Calcs'!$E$7)+($AC9*'MRV Calcs'!$E$8),0) -> 0.32925082 | AE9: =($Q9/30)*SUM('MRV Calcs'!$E$15:$E$16) -> 11.784585 | AF9: ='MRV Calcs'!$E$27 -> 71.2 | AG9: =(($Q9*1.1)*$AF9*'MRV Calcs'!$E$7)+($AF9*'MRV Calcs'!$E$8) -> 0.7904635 | AH9: =(($Q9*1.1)/20)*SUM('MRV Calcs'!$E$19:$E$20) -> 0.1096128 | AI9: =SUM(AH9,AG9,AE9,AD9,AB9,Z9,X9,V9) -> 29.968245 | AJ9: =U9-AI9 -> 89.83818 | AK9: =AJ9+AK8 -> 229.8982 | AL9: =AJ9/Q9 -> 1.1539908 | AN9: =COUNTIF(Blends!H$4:H$1007,B9)+COUNTIF(Blends!J$4:J$1007,B9)+COUNTIF(#REF!,B9) -> 7 | AO9: =B9 -> 038-040T2R1 | AP9: 038T2R1 + 039T2R1 + 040T2R1 Apr 8 & 9 Pickups STPX094926 | AQ9: =IFERROR(__xludf.DUMMYFUNCTION("AP9.url"),"https://drive.google.com/drive/folders/1K2G-UQhB-Pi95Ro7G7E5VoZyDn0EL1AH?usp=drive_link") -> https://drive.google.com/drive/folders/1K2G-UQhB-Pi95Ro7G7E5VoZyDn0EL1AH?usp=drive_link
A10: 9 | B10: 043T1R0 | D10: RS3-240429 | F10: paid | G10: NA | H10: AECN | I10: truck | K10: KAG | L10: Gaston | N10: 45414 | O10: =IF(I10="truck",N10+4,IF(I10="train",N10+16,"")) -> 45418 | Q10: 20.83 | S10: =iferror(if(AN10=1,VLOOKUP(B10, Blends!H$4:AK$1004,32,0), ""), "") | U10: =Q10*T10*(44.01/12.011) -> 0 | V10: =$Q10*('MRV Calcs'!$E$3+'MRV Calcs'!$E$4) -> 3.0816306 | W10: =IF(H10="AECN",2030,"ERROR") -> 2030 | X10: =IF($I10="truck",($Q10*$W10*'MRV Calcs'!$E$7)+($W10*'MRV Calcs'!$E$8),0) -> 5.599863 | Y10: =IF($I10="train",'MRV Calcs'!$E$24,0) -> 0 | Z10: =IF($I10="train",($Q10*$Y10*'MRV Calcs'!$E$7)+($Y10*'MRV Calcs'!$E$8),0) -> 0 | AA10: =IF($I10="train",'MRV Calcs'!$E$25,0) -> 0 | AB10: =IF($I10="train",($Q10*$AA10*'MRV Calcs'!$E$11)+($AA10*'MRV Calcs'!$E$12),0) -> 0 | AC10: =IF($I10="train",'MRV Calcs'!$E$26,0) -> 0 | AD10: =IF($I10="train",($Q10*$AC10*'MRV Calcs'!$E$7)+($AC10*'MRV Calcs'!$E$8),0) -> 0 | AE10: =($Q10/30)*SUM('MRV Calcs'!$E$15:$E$16) -> 3.1531524 | AF10: ='MRV Calcs'!$E$27 -> 71.2 | AG10: =(($Q10*1.1)*$AF10*'MRV Calcs'!$E$7)+($AF10*'MRV Calcs'!$E$8) -> 0.21550343 | AH10: =(($Q10*1.1)/20)*SUM('MRV Calcs'!$E$19:$E$20) -> 0.02932864 | AI10: =SUM(AH10,AG10,AE10,AD10,AB10,Z10,X10,V10) -> 12.079478 | AJ10: =U10-AI10 -> -12.079478 | AK10: =AJ10+AK9 -> 217.81872 | AL10: =AJ10/Q10 -> -0.57990773 | AN10: =COUNTIF(Blends!H$4:H$1007,B10)+COUNTIF(Blends!J$4:J$1007,B10)+COUNTIF(#REF!,B10) -> 2 | AO10: =B10 -> 043T1R0 | AP10: Envoi des documents 1301.pdf | AQ10: =IFERROR(__xludf.DUMMYFUNCTION("AP10.url"),"https://drive.google.com/file/d/10v6SP-oQueAyjXGma8rXybbakBKllOga/view?usp=drive_link") -> https://drive.google.com/file/d/10v6SP-oQueAyjXGma8rXybbakBKllOga/view?usp=drive_link
A11: 10 | B11: 044T1R0 | D11: RS3-240429 | F11: paid | G11: NA | H11: AECN | I11: truck | K11: KAG | L11: Darryl | N11: 45414 | O11: =IF(I11="truck",N11+4,IF(I11="train",N11+16,"")) -> 45418 | Q11: 20.14 | S11: =iferror(if(AN11=1,VLOOKUP(B11, Blends!H$4:AK$1004,32,0), ""), "") | U11: =Q11*T11*(44.01/12.011) -> 0 | V11: =$Q11*('MRV Calcs'!$E$3+'MRV Calcs'!$E$4) -> 2.9795506 | W11: =IF(H11="AECN",2030,"ERROR") -> 2030 | X11: =IF($I11="truck",($Q11*$W11*'MRV Calcs'!$E$7)+($W11*'MRV Calcs'!$E$8),0) -> 5.4195268 | Y11: =IF($I11="train",'MRV Calcs'!$E$24,0) -> 0 | Z11: =IF($I11="train",($Q11*$Y11*'MRV Calcs'!$E$7)+($Y11*'MRV Calcs'!$E$8),0) -> 0 | AA11: =IF($I11="train",'MRV Calcs'!$E$25,0) -> 0 | AB11: =IF($I11="train",($Q11*$AA11*'MRV Calcs'!$E$11)+($AA11*'MRV Calcs'!$E$12),0) -> 0 | AC11: =IF($I11="train",'MRV Calcs'!$E$26,0) -> 0 | AD11: =IF($I11="train",($Q11*$AC11*'MRV Calcs'!$E$7)+($AC11*'MRV Calcs'!$E$8),0) -> 0 | AE11: =($Q11/30)*SUM('MRV Calcs'!$E$15:$E$16) -> 3.0487032 | AF11: ='MRV Calcs'!$E$27 -> 71.2 | AG11: =(($Q11*1.1)*$AF11*'MRV Calcs'!$E$7)+($AF11*'MRV Calcs'!$E$8) -> 0.20854583 | AH11: =(($Q11*1.1)/20)*SUM('MRV Calcs'!$E$19:$E$20) -> 0.02835712 | AI11: =SUM(AH11,AG11,AE11,AD11,AB11,Z11,X11,V11) -> 11.684684 | AJ11: =U11-AI11 -> -11.684684 | AK11: =AJ11+AK10 -> 206.13404 | AL11: =AJ11/Q11 -> -0.58017297 | AN11: =COUNTIF(Blends!H$4:H$1007,B11)+COUNTIF(Blends!J$4:J$1007,B11)+COUNTIF(#REF!,B11) -> 1 | AO11: =B11 -> 044T1R0 | AP11: Envoi des documents 1302.pdf | AQ11: =IFERROR(__xludf.DUMMYFUNCTION("AP11.url"),"https://drive.google.com/file/d/1vMftkmGRJGBWUkariuCQUCy8BvqpKsF3/view?usp=drive_link") -> https://drive.google.com/file/d/1vMftkmGRJGBWUkariuCQUCy8BvqpKsF3/view?usp=drive_link
A12: 11 | B12: 045-047T2R2 | D12: RS2-240428 | F12: paid | G12: TRUE | H12: AECN | I12: train | K12: Transport Baie-Comeau | L12: STPX 094627 | N12: 45415 | O12: 45433 | Q12: 78.8 | S12: =iferror(if(AN12=1,VLOOKUP(B12, Blends!H$4:AK$1004,32,0), ""), "") | U12: =Q12*T12*(44.01/12.011) -> 0 | V12: =$Q12*('MRV Calcs'!$E$3+'MRV Calcs'!$E$4) -> 11.657825 | W12: =IF(H12="AECN",2030,"ERROR") -> 2030 | X12: =IF($I12="truck",($Q12*$W12*'MRV Calcs'!$E$7)+($W12*'MRV Calcs'!$E$8),0) -> 0 | Y12: =IF($I12="train",'MRV Calcs'!$E$24,0) -> 107.497 | Z12: =IF($I12="train",($Q12*$Y12*'MRV Calcs'!$E$7)+($Y12*'MRV Calcs'!$E$8),0) -> 1.0988374 | AA12: =IF($I12="train",'MRV Calcs'!$E$25,0) -> 2087 | AB12: =IF($I12="train",($Q12*$AA12*'MRV Calcs'!$E$11)+($AA12*'MRV Calcs'!$E$12),0) -> 4.4030533 | AC12: =IF($I12="train",'MRV Calcs'!$E$26,0) -> 32.6 | AD12: =IF($I12="train",($Q12*$AC12*'MRV Calcs'!$E$7)+($AC12*'MRV Calcs'!$E$8),0) -> 0.33323812 | AE12: =($Q12/30)*SUM('MRV Calcs'!$E$15:$E$16) -> 11.928392 | AF12: ='MRV Calcs'!$E$27 -> 71.2 | AG12: =(($Q12*1.1)*$AF12*'MRV Calcs'!$E$7)+($AF12*'MRV Calcs'!$E$8) -> 0.80004281 | AH12: =(($Q12*1.1)/20)*SUM('MRV Calcs'!$E$19:$E$20) -> 0.1109504 | AI12: =SUM(AH12,AG12,AE12,AD12,AB12,Z12,X12,V12) -> 30.332339 | AJ12: =U12-AI12 -> -30.332339 | AK12: =AJ12+AK11 -> 175.8017 | AL12: =AJ12/Q12 -> -0.38492816 | AN12: =COUNTIF(Blends!H$4:H$1007,B12)+COUNTIF(Blends!J$4:J$1007,B12)+COUNTIF(#REF!,B12) -> 5 | AO12: =B12 -> 045-047T2R2 | AP12: 045T2R2 - 047T2R2 4/30-5/1 Pickups STPX094627 | AQ12: =IFERROR(__xludf.DUMMYFUNCTION("AP12.url"),"https://drive.google.com/drive/folders/10huZjk9PmQavkXzqdPxfaL7r9y57q9KA?usp=drive_link") -> https://drive.google.com/drive/folders/10huZjk9PmQavkXzqdPxfaL7r9y57q9KA?usp=drive_link
A13: 12 | B13: 048-050T2R3 | D13: RS3-240429 | F13: paid | G13: TRUE | H13: AECN | I13: train | K13: Transport Baie-Comeau | L13: STPX 094625 | N13: 45419 | O13: 45434 | Q13: 79.09 | S13: =iferror(if(AN13=1,VLOOKUP(B13, Blends!H$4:AK$1004,32,0), ""), "") | U13: =Q13*T13*(44.01/12.011) -> 0 | V13: =$Q13*('MRV Calcs'!$E$3+'MRV Calcs'!$E$4) -> 11.700728 | W13: =IF(H13="AECN",2030,"ERROR") -> 2030 | X13: =IF($I13="truck",($Q13*$W13*'MRV Calcs'!$E$7)+($W13*'MRV Calcs'!$E$8),0) -> 0 | Y13: =IF($I13="train",'MRV Calcs'!$E$24,0) -> 107.497 | Z13: =IF($I13="train",($Q13*$Y13*'MRV Calcs'!$E$7)+($Y13*'MRV Calcs'!$E$8),0) -> 1.102851 | AA13: =IF($I13="train",'MRV Calcs'!$E$25,0) -> 2087 | AB13: =IF($I13="train",($Q13*$AA13*'MRV Calcs'!$E$11)+($AA13*'MRV Calcs'!$E$12),0) -> 4.4188324 | AC13: =IF($I13="train",'MRV Calcs'!$E$26,0) -> 32.6 | AD13: =IF($I13="train",($Q13*$AC13*'MRV Calcs'!$E$7)+($AC13*'MRV Calcs'!$E$8),0) -> 0.3344553 | AE13: =($Q13/30)*SUM('MRV Calcs'!$E$15:$E$16) -> 11.972291 | AF13: ='MRV Calcs'!$E$27 -> 71.2 | AG13: =(($Q13*1.1)*$AF13*'MRV Calcs'!$E$7)+($AF13*'MRV Calcs'!$E$8) -> 0.80296702 | AH13: =(($Q13*1.1)/20)*SUM('MRV Calcs'!$E$19:$E$20) -> 0.11135872 | AI13: =SUM(AH13,AG13,AE13,AD13,AB13,Z13,X13,V13) -> 30.443483 | AJ13: =U13-AI13 -> -30.443483 | AK13: =AJ13+AK12 -> 145.35822 | AL13: =AJ13/Q13 -> -0.38492203 | AN13: =COUNTIF(Blends!H$4:H$1007,B13)+COUNTIF(Blends!J$4:J$1007,B13)+COUNTIF(#REF!,B13) -> 5 | AO13: =B13 -> 048-050T2R3 | AP13: 048-050T2R3 5/1-5/2 Pickups STPX094625 | AQ13: =IFERROR(__xludf.DUMMYFUNCTION("AP13.url"),"https://drive.google.com/drive/folders/1R4l6-xHvtaH9yTtFG5n7b7zrpn1Layex?usp=drive_link") -> https://drive.google.com/drive/folders/1R4l6-xHvtaH9yTtFG5n7b7zrpn1Layex?usp=drive_link
A14: 13 | B14: 051-053T2R4 | D14: RS3-240429 and RS1-240501 | F14: paid | G14: TRUE | H14: AECN | I14: train | K14: Transport Baie-Comeau | L14: STPX 094624 | N14: 45419 | O14: 45434 | Q14: 78.98 | S14: =iferror(if(AN14=1,VLOOKUP(B14, Blends!H$4:AK$1004,32,0), ""), "") | U14: =Q14*T14*(44.01/12.011) -> 0 | V14: =$Q14*('MRV Calcs'!$E$3+'MRV Calcs'!$E$4) -> 11.684454 | W14: =IF(H14="AECN",2030,"ERROR") -> 2030 | X14: =IF($I14="truck",($Q14*$W14*'MRV Calcs'!$E$7)+($W14*'MRV Calcs'!$E$8),0) -> 0 | Y14: =IF($I14="train",'MRV Calcs'!$E$24,0) -> 107.497 | Z14: =IF($I14="train",($Q14*$Y14*'MRV Calcs'!$E$7)+($Y14*'MRV Calcs'!$E$8),0) -> 1.1013286 | AA14: =IF($I14="train",'MRV Calcs'!$E$25,0) -> 2087 | AB14: =IF($I14="train",($Q14*$AA14*'MRV Calcs'!$E$11)+($AA14*'MRV Calcs'!$E$12),0) -> 4.4128472 | AC14: =IF($I14="train",'MRV Calcs'!$E$26,0) -> 32.6 | AD14: =IF($I14="train",($Q14*$AC14*'MRV Calcs'!$E$7)+($AC14*'MRV Calcs'!$E$8),0) -> 0.33399361 | AE14: =($Q14/30)*SUM('MRV Calcs'!$E$15:$E$16) -> 11.95564 | AF14: ='MRV Calcs'!$E$27 -> 71.2 | AG14: =(($Q14*1.1)*$AF14*'MRV Calcs'!$E$7)+($AF14*'MRV Calcs'!$E$8) -> 0.80185784 | AH14: =(($Q14*1.1)/20)*SUM('MRV Calcs'!$E$19:$E$20) -> 0.11120384 | AI14: =SUM(AH14,AG14,AE14,AD14,AB14,Z14,X14,V14) -> 30.401325 | AJ14: =U14-AI14 -> -30.401325 | AK14: =AJ14+AK13 -> 114.95689 | AL14: =AJ14/Q14 -> -0.38492435 | AN14: =COUNTIF(Blends!H$4:H$1007,B14)+COUNTIF(Blends!J$4:J$1007,B14)+COUNTIF(#REF!,B14) -> 5 | AO14: =B14 -> 051-053T2R4 | AP14: 051-053T2R4 5/3-5/6 Pickups SPTX94624 | AQ14: =IFERROR(__xludf.DUMMYFUNCTION("AP14.url"),"https://drive.google.com/drive/folders/1bnmztyCdUq_Q2U5fZsp4bCg9iSuPS1rG?usp=drive_link") -> https://drive.google.com/drive/folders/1bnmztyCdUq_Q2U5fZsp4bCg9iSuPS1rG?usp=drive_link
A15: 14 | B15: 054T1R0 | D15: RS1-240501 | F15: paid | G15: NA | H15: AECN | I15: truck | K15: KAG | L15: Guy | N15: 45422 | O15: =IF(I15="truck",N15+4,IF(I15="train",N15+21,"")) -> 45426 | Q15: 20.11 | S15: =iferror(if(AN15=1,VLOOKUP(B15, Blends!H$4:AK$1004,32,0), ""), "") | T15: 0.408 | U15: =Q15*T15*(44.01/12.011) -> 30.063839 | V15: =$Q15*('MRV Calcs'!$E$3+'MRV Calcs'!$E$4) -> 2.9751124 | W15: =IF(H15="AECN",2030,"ERROR") -> 2030 | X15: =IF($I15="truck",($Q15*$W15*'MRV Calcs'!$E$7)+($W15*'MRV Calcs'!$E$8),0) -> 5.4116861 | Y15: =IF($I15="train",'MRV Calcs'!$E$24,0) -> 0 | Z15: =IF($I15="train",($Q15*$Y15*'MRV Calcs'!$E$7)+($Y15*'MRV Calcs'!$E$8),0) -> 0 | AA15: =IF($I15="train",'MRV Calcs'!$E$25,0) -> 0 | AB15: =IF($I15="train",($Q15*$AA15*'MRV Calcs'!$E$11)+($AA15*'MRV Calcs'!$E$12),0) -> 0 | AC15: =IF($I15="train",'MRV Calcs'!$E$26,0) -> 0 | AD15: =IF($I15="train",($Q15*$AC15*'MRV Calcs'!$E$7)+($AC15*'MRV Calcs'!$E$8),0) -> 0 | AE15: =($Q15/30)*SUM('MRV Calcs'!$E$15:$E$16) -> 3.044162 | AF15: ='MRV Calcs'!$E$27 -> 71.2 | AG15: =(($Q15*1.1)*$AF15*'MRV Calcs'!$E$7)+($AF15*'MRV Calcs'!$E$8) -> 0.20824333 | AH15: =(($Q15*1.1)/20)*SUM('MRV Calcs'!$E$19:$E$20) -> 0.02831488 | AI15: =SUM(AH15,AG15,AE15,AD15,AB15,Z15,X15,V15) -> 11.667519 | AJ15: =U15-AI15 -> 18.39632 | AK15: =AJ15+AK14 -> 133.35321 | AL15: =AJ15/Q15 -> 0.9147847 | AN15: =COUNTIF(Blends!H$4:H$1007,B15)+COUNTIF(Blends!J$4:J$1007,B15)+COUNTIF(#REF!,B15) -> 1 | AO15: =B15 -> 054T1R0 | AP15: Documents camion 1305.pdf | AQ15: =IFERROR(__xludf.DUMMYFUNCTION("AP15.url"),"https://drive.google.com/file/d/1nH0plpMTNbfetKZCbvTSiG46-7yYj3CY/view?usp=drive_link") -> https://drive.google.com/file/d/1nH0plpMTNbfetKZCbvTSiG46-7yYj3CY/view?usp=drive_link
A16: 15 | B16: 055T1R0 | D16: RS1-240501 | F16: paid | G16: NA | H16: AECN | I16: truck | K16: KAG | L16: Darryl | N16: 45423 | O16: =IF(I16="truck",N16+4,IF(I16="train",N16+21,"")) -> 45427 | Q16: 20.56 | S16: =iferror(if(AN16=1,VLOOKUP(B16, Blends!H$4:AK$1004,32,0), ""), "") | T16: 0.398 | U16: =Q16*T16*(44.01/12.011) -> 29.983228 | V16: =$Q16*('MRV Calcs'!$E$3+'MRV Calcs'!$E$4) -> 3.0416862 | W16: =IF(H16="AECN",2030,"ERROR") -> 2030 | X16: =IF($I16="truck",($Q16*$W16*'MRV Calcs'!$E$7)+($W16*'MRV Calcs'!$E$8),0) -> 5.5292966 | Y16: =IF($I16="train",'MRV Calcs'!$E$24,0) -> 0 | Z16: =IF($I16="train",($Q16*$Y16*'MRV Calcs'!$E$7)+($Y16*'MRV Calcs'!$E$8),0) -> 0 | AA16: =IF($I16="train",'MRV Calcs'!$E$25,0) -> 0 | AB16: =IF($I16="train",($Q16*$AA16*'MRV Calcs'!$E$11)+($AA16*'MRV Calcs'!$E$12),0) -> 0 | AC16: =IF($I16="train",'MRV Calcs'!$E$26,0) -> 0 | AD16: =IF($I16="train",($Q16*$AC16*'MRV Calcs'!$E$7)+($AC16*'MRV Calcs'!$E$8),0) -> 0 | AE16: =($Q16/30)*SUM('MRV Calcs'!$E$15:$E$16) -> 3.112281 | AF16: ='MRV Calcs'!$E$27 -> 71.2 | AG16: =(($Q16*1.1)*$AF16*'MRV Calcs'!$E$7)+($AF16*'MRV Calcs'!$E$8) -> 0.21278089 | AH16: =(($Q16*1.1)/20)*SUM('MRV Calcs'!$E$19:$E$20) -> 0.02894848 | AI16: =SUM(AH16,AG16,AE16,AD16,AB16,Z16,X16,V16) -> 11.924993 | AJ16: =U16-AI16 -> 18.058235 | AK16: =AJ16+AK15 -> 151.41145 | AL16: =AJ16/Q16 -> 0.8783188 | AN16: =COUNTIF(Blends!H$4:H$1007,B16)+COUNTIF(Blends!J$4:J$1007,B16)+COUNTIF(#REF!,B16) -> 1 | AO16: =B16 -> 055T1R0 | AP16: Documents camion 1306.pdf | AQ16: =IFERROR(__xludf.DUMMYFUNCTION("AP16.url"),"https://drive.google.com/file/d/1zQMVk78NOnW672_OvCACXe114oXe7eFO/view?usp=drive_link") -> https://drive.google.com/file/d/1zQMVk78NOnW672_OvCACXe114oXe7eFO/view?usp=drive_link
A17: 16 | B17: 056T1R0 | D17: RS1-240501 | F17: paid | G17: NA | H17: AECN | I17: truck | K17: KAG | L17: Gaston | N17: 45423 | O17: =IF(I17="truck",N17+4,IF(I17="train",N17+21,"")) -> 45427 | Q17: 21.29 | S17: =iferror(if(AN17=1,VLOOKUP(B17, Blends!H$4:AK$1004,32,0), ""), "") | T17: 0.3993 | U17: =Q17*T17*(44.01/12.011) -> 31.14922 | V17: =$Q17*('MRV Calcs'!$E$3+'MRV Calcs'!$E$4) -> 3.1496839 | W17: =IF(H17="AECN",2030,"ERROR") -> 2030 | X17: =IF($I17="truck",($Q17*$W17*'MRV Calcs'!$E$7)+($W17*'MRV Calcs'!$E$8),0) -> 5.7200871 | Y17: =IF($I17="train",'MRV Calcs'!$E$24,0) -> 0 | Z17: =IF($I17="train",($Q17*$Y17*'MRV Calcs'!$E$7)+($Y17*'MRV Calcs'!$E$8),0) -> 0 | AA17: =IF($I17="train",'MRV Calcs'!$E$25,0) -> 0 | AB17: =IF($I17="train",($Q17*$AA17*'MRV Calcs'!$E$11)+($AA17*'MRV Calcs'!$E$12),0) -> 0 | AC17: =IF($I17="train",'MRV Calcs'!$E$26,0) -> 0 | AD17: =IF($I17="train",($Q17*$AC17*'MRV Calcs'!$E$7)+($AC17*'MRV Calcs'!$E$8),0) -> 0 | AE17: =($Q17/30)*SUM('MRV Calcs'!$E$15:$E$16) -> 3.2227851 | AF17: ='MRV Calcs'!$E$27 -> 71.2 | AG17: =(($Q17*1.1)*$AF17*'MRV Calcs'!$E$7)+($AF17*'MRV Calcs'!$E$8) -> 0.22014183 | AH17: =(($Q17*1.1)/20)*SUM('MRV Calcs'!$E$19:$E$20) -> 0.02997632 | AI17: =SUM(AH17,AG17,AE17,AD17,AB17,Z17,X17,V17) -> 12.342674 | AJ17: =U17-AI17 -> 18.806546 | AK17: =AJ17+AK16 -> 170.21799 | AL17: =AJ17/Q17 -> 0.88335113 | AN17: =COUNTIF(Blends!H$4:H$1007,B17)+COUNTIF(Blends!J$4:J$1007,B17)+COUNTIF(#REF!,B17) -> 2 | AO17: =B17 -> 056T1R0 | AP17: Billing Documents 1307.pdf | AQ17: =IFERROR(__xludf.DUMMYFUNCTION("AP17.url"),"https://drive.google.com/file/d/1q-y_-Zz7QXAH6pd6LoSRhWO0xFXZ1WQM/view?usp=drive_link") -> https://drive.google.com/file/d/1q-y_-Zz7QXAH6pd6LoSRhWO0xFXZ1WQM/view?usp=drive_link
A18: 17 | B18: 057T1R0 | D18: RS1-240501 | F18: paid | G18: NA | H18: AECN | I18: truck | K18: KAG | L18: Guy | N18: 45431 | O18: 45434 | Q18: 20.53 | S18: =iferror(if(AN18=1,VLOOKUP(B18, Blends!H$4:AK$1004,32,0), ""), "") | T18: 0.388 | U18: =Q18*T18*(44.01/12.011) -> 29.18723 | V18: =$Q18*('MRV Calcs'!$E$3+'MRV Calcs'!$E$4) -> 3.037248 | W18: =IF(H18="AECN",2030,"ERROR") -> 2030 | X18: =IF($I18="truck",($Q18*$W18*'MRV Calcs'!$E$7)+($W18*'MRV Calcs'!$E$8),0) -> 5.5214559 | Y18: =IF($I18="train",'MRV Calcs'!$E$24,0) -> 0 | Z18: =IF($I18="train",($Q18*$Y18*'MRV Calcs'!$E$7)+($Y18*'MRV Calcs'!$E$8),0) -> 0 | AA18: =IF($I18="train",'MRV Calcs'!$E$25,0) -> 0 | AB18: =IF($I18="train",($Q18*$AA18*'MRV Calcs'!$E$11)+($AA18*'MRV Calcs'!$E$12),0) -> 0 | AC18: =IF($I18="train",'MRV Calcs'!$E$26,0) -> 0 | AD18: =IF($I18="train",($Q18*$AC18*'MRV Calcs'!$E$7)+($AC18*'MRV Calcs'!$E$8),0) -> 0 | AE18: =($Q18/30)*SUM('MRV Calcs'!$E$15:$E$16) -> 3.1077397 | AF18: ='MRV Calcs'!$E$27 -> 71.2 | AG18: =(($Q18*1.1)*$AF18*'MRV Calcs'!$E$7)+($AF18*'MRV Calcs'!$E$8) -> 0.21247839 | AH18: =(($Q18*1.1)/20)*SUM('MRV Calcs'!$E$19:$E$20) -> 0.02890624 | AI18: =SUM(AH18,AG18,AE18,AD18,AB18,Z18,X18,V18) -> 11.907828 | AJ18: =U18-AI18 -> 17.279402 | AK18: =AJ18+AK17 -> 187.4974 | AL18: =AJ18/Q18 -> 0.84166593 | AN18: =COUNTIF(Blends!H$4:H$1007,B18)+COUNTIF(Blends!J$4:J$1007,B18)+COUNTIF(#REF!,B18) -> 1 | AO18: =B18 -> 057T1R0 | AP18: Billing Docs 1308 PO 057T1R0.pdf | AQ18: =IFERROR(__xludf.DUMMYFUNCTION("AP18.url"),"https://drive.google.com/file/d/1UEOFYoPTkf0IlkSlvbOQqGIlJOvKWIWQ/view?usp=drive_link") -> https://drive.google.com/file/d/1UEOFYoPTkf0IlkSlvbOQqGIlJOvKWIWQ/view?usp=drive_link
A19: 18 | B19: 058T1R0 | D19: RS1-240501 | F19: paid | G19: NA | H19: AECN | I19: truck | K19: Queensway Transport | L19: Furgusson | N19: 45431 | O19: 45435 | Q19: 19.91 | S19: =iferror(if(AN19=1,VLOOKUP(B19, Blends!H$4:AK$1004,32,0), ""), "") | T19: 0.407 | U19: =Q19*T19*(44.01/12.011) -> 29.691892 | V19: =$Q19*('MRV Calcs'!$E$3+'MRV Calcs'!$E$4) -> 2.945524 | W19: =IF(H19="AECN",2030,"ERROR") -> 2030 | X19: =IF($I19="truck",($Q19*$W19*'MRV Calcs'!$E$7)+($W19*'MRV Calcs'!$E$8),0) -> 5.3594147 | Y19: =IF($I19="train",'MRV Calcs'!$E$24,0) -> 0 | Z19: =IF($I19="train",($Q19*$Y19*'MRV Calcs'!$E$7)+($Y19*'MRV Calcs'!$E$8),0) -> 0 | AA19: =IF($I19="train",'MRV Calcs'!$E$25,0) -> 0 | AB19: =IF($I19="train",($Q19*$AA19*'MRV Calcs'!$E$11)+($AA19*'MRV Calcs'!$E$12),0) -> 0 | AC19: =IF($I19="train",'MRV Calcs'!$E$26,0) -> 0 | AD19: =IF($I19="train",($Q19*$AC19*'MRV Calcs'!$E$7)+($AC19*'MRV Calcs'!$E$8),0) -> 0 | AE19: =($Q19/30)*SUM('MRV Calcs'!$E$15:$E$16) -> 3.0138869 | AF19: ='MRV Calcs'!$E$27 -> 71.2 | AG19: =(($Q19*1.1)*$AF19*'MRV Calcs'!$E$7)+($AF19*'MRV Calcs'!$E$8) -> 0.20622663 | AH19: =(($Q19*1.1)/20)*SUM('MRV Calcs'!$E$19:$E$20) -> 0.02803328 | AI19: =SUM(AH19,AG19,AE19,AD19,AB19,Z19,X19,V19) -> 11.553085 | AJ19: =U19-AI19 -> 18.138806 | AK19: =AJ19+AK18 -> 205.6362 | AL19: =AJ19/Q19 -> 0.91104 | AN19: =COUNTIF(Blends!H$4:H$1007,B19)+COUNTIF(Blends!J$4:J$1007,B19)+COUNTIF(#REF!,B19) -> 1 | AO19: =B19 -> 058T1R0 | AP19: Billing Docs Load 1309 PO 058T1R0.pdf | AQ19: =IFERROR(__xludf.DUMMYFUNCTION("AP19.url"),"https://drive.google.com/file/d/1riHpjmeVLgezFQv02eG1NhmUi8A_C8fG/view?usp=drive_link") -> https://drive.google.com/file/d/1riHpjmeVLgezFQv02eG1NhmUi8A_C8fG/view?usp=drive_link
A20: 19 | B20: 059T1R0 | D20: RS1-240501 | F20: paid | G20: NA | H20: AECN | I20: truck | K20: KAG | L20: Gus | N20: 45432 | O20: 45435 | Q20: 21.05 | S20: =iferror(if(AN20=1,VLOOKUP(B20, Blends!H$4:AK$1004,32,0), ""), "") | T20: 0.39 | U20: =Q20*T20*(44.01/12.011) -> 30.080767 | V20: =$Q20*('MRV Calcs'!$E$3+'MRV Calcs'!$E$4) -> 3.1141778 | W20: =IF(H20="AECN",2030,"ERROR") -> 2030 | X20: =IF($I20="truck",($Q20*$W20*'MRV Calcs'!$E$7)+($W20*'MRV Calcs'!$E$8),0) -> 5.6573615 | Y20: =IF($I20="train",'MRV Calcs'!$E$24,0) -> 0 | Z20: =IF($I20="train",($Q20*$Y20*'MRV Calcs'!$E$7)+($Y20*'MRV Calcs'!$E$8),0) -> 0 | AA20: =IF($I20="train",'MRV Calcs'!$E$25,0) -> 0 | AB20: =IF($I20="train",($Q20*$AA20*'MRV Calcs'!$E$11)+($AA20*'MRV Calcs'!$E$12),0) -> 0 | AC20: =IF($I20="train",'MRV Calcs'!$E$26,0) -> 0 | AD20: =IF($I20="train",($Q20*$AC20*'MRV Calcs'!$E$7)+($AC20*'MRV Calcs'!$E$8),0) -> 0 | AE20: =($Q20/30)*SUM('MRV Calcs'!$E$15:$E$16) -> 3.186455 | AF20: ='MRV Calcs'!$E$27 -> 71.2 | AG20: =(($Q20*1.1)*$AF20*'MRV Calcs'!$E$7)+($AF20*'MRV Calcs'!$E$8) -> 0.2177218 | AH20: =(($Q20*1.1)/20)*SUM('MRV Calcs'!$E$19:$E$20) -> 0.0296384 | AI20: =SUM(AH20,AG20,AE20,AD20,AB20,Z20,X20,V20) -> 12.205354 | AJ20: =U20-AI20 -> 17.875413 | AK20: =AJ20+AK19 -> 223.51162 | AL20: =AJ20/Q20 -> 0.84918826 | AN20: =COUNTIF(Blends!H$4:H$1007,B20)+COUNTIF(Blends!J$4:J$1007,B20)+COUNTIF(#REF!,B20) -> 1 | AO20: =B20 -> 059T1R0 | AP20: Billing documents 1310.pdf | AQ20: =IFERROR(__xludf.DUMMYFUNCTION("AP20.url"),"https://drive.google.com/file/d/1ShFxfOkxJobQHF9eu77bH2FUYq_iPV-s/view?usp=drive_link") -> https://drive.google.com/file/d/1ShFxfOkxJobQHF9eu77bH2FUYq_iPV-s/view?usp=drive_link
A21: 20 | B21: 070T1R0 | D21: RS1-240501 | F21: paid | G21: NA | H21: AECN | I21: truck | K21: Queensway Transport | L21: Paul/Stephen | N21: 45434 | O21: 45441 | Q21: 19.47 | S21: =iferror(if(AN21=1,VLOOKUP(B21, Blends!H$4:AK$1004,32,0), ""), "") | T21: 0.4017 | U21: =Q21*T21*(44.01/12.011) -> 28.657611 | V21: =$Q21*('MRV Calcs'!$E$3+'MRV Calcs'!$E$4) -> 2.8804295 | W21: =IF(H21="AECN",2030,"ERROR") -> 2030 | X21: =IF($I21="truck",($Q21*$W21*'MRV Calcs'!$E$7)+($W21*'MRV Calcs'!$E$8),0) -> 5.2444177 | Y21: =IF($I21="train",'MRV Calcs'!$E$24,0) -> 0 | Z21: =IF($I21="train",($Q21*$Y21*'MRV Calcs'!$E$7)+($Y21*'MRV Calcs'!$E$8),0) -> 0 | AA21: =IF($I21="train",'MRV Calcs'!$E$25,0) -> 0 | AB21: =IF($I21="train",($Q21*$AA21*'MRV Calcs'!$E$11)+($AA21*'MRV Calcs'!$E$12),0) -> 0 | AC21: =IF($I21="train",'MRV Calcs'!$E$26,0) -> 0 | AD21: =IF($I21="train",($Q21*$AC21*'MRV Calcs'!$E$7)+($AC21*'MRV Calcs'!$E$8),0) -> 0 | AE21: =($Q21/30)*SUM('MRV Calcs'!$E$15:$E$16) -> 2.9472816 | AF21: ='MRV Calcs'!$E$27 -> 71.2 | AG21: =(($Q21*1.1)*$AF21*'MRV Calcs'!$E$7)+($AF21*'MRV Calcs'!$E$8) -> 0.2017899 | AH21: =(($Q21*1.1)/20)*SUM('MRV Calcs'!$E$19:$E$20) -> 0.02741376 | AI21: =SUM(AH21,AG21,AE21,AD21,AB21,Z21,X21,V21) -> 11.301333 | AJ21: =U21-AI21 -> 17.356279 | AK21: =AJ21+AK20 -> 240.86789 | AL21: =AJ21/Q21 -> 0.89143701 | AN21: =COUNTIF(Blends!H$4:H$1007,B21)+COUNTIF(Blends!J$4:J$1007,B21)+COUNTIF(#REF!,B21) -> 1 | AO21: =B21 -> 070T1R0 | AP21: Billing Docs 1311 PO 070T1R0.pdf | AQ21: =IFERROR(__xludf.DUMMYFUNCTION("AP21.url"),"https://drive.google.com/file/d/12n_BN4HJhUWJHv4D6MPDmQFR5PZf9N0x/view?usp=drive_link") -> https://drive.google.com/file/d/12n_BN4HJhUWJHv4D6MPDmQFR5PZf9N0x/view?usp=drive_link
A22: 21 | B22: 069T1R0 | D22: RS1-240501 | F22: paid | G22: NA | H22: AECN | I22: truck | K22: KAG | L22: Darryl | N22: 45437 | O22: =IF(I22="truck",N22+4,IF(I22="train",N22+21,"")) -> 45441 | Q22: 20.25 | S22: =iferror(if(AN22=1,VLOOKUP(B22, Blends!H$4:AK$1004,32,0), ""), "") | T22: 0.4017 | U22: =Q22*T22*(44.01/12.011) -> 29.805682 | V22: =$Q22*('MRV Calcs'!$E$3+'MRV Calcs'!$E$4) -> 2.9958242 | W22: =IF(H22="AECN",2030,"ERROR") -> 2030 | X22: =IF($I22="truck",($Q22*$W22*'MRV Calcs'!$E$7)+($W22*'MRV Calcs'!$E$8),0) -> 5.448276 | Y22: =IF($I22="train",'MRV Calcs'!$E$24,0) -> 0 | Z22: =IF($I22="train",($Q22*$Y22*'MRV Calcs'!$E$7)+($Y22*'MRV Calcs'!$E$8),0) -> 0 | AA22: =IF($I22="train",'MRV Calcs'!$E$25,0) -> 0 | AB22: =IF($I22="train",($Q22*$AA22*'MRV Calcs'!$E$11)+($AA22*'MRV Calcs'!$E$12),0) -> 0 | AC22: =IF($I22="train",'MRV Calcs'!$E$26,0) -> 0 | AD22: =IF($I22="train",($Q22*$AC22*'MRV Calcs'!$E$7)+($AC22*'MRV Calcs'!$E$8),0) -> 0 | AE22: =($Q22/30)*SUM('MRV Calcs'!$E$15:$E$16) -> 3.0653545 | AF22: ='MRV Calcs'!$E$27 -> 71.2 | AG22: =(($Q22*1.1)*$AF22*'MRV Calcs'!$E$7)+($AF22*'MRV Calcs'!$E$8) -> 0.20965501 | AH22: =(($Q22*1.1)/20)*SUM('MRV Calcs'!$E$19:$E$20) -> 0.028512 | AI22: =SUM(AH22,AG22,AE22,AD22,AB22,Z22,X22,V22) -> 11.747622 | AJ22: =U22-AI22 -> 18.05806 | AK22: =AJ22+AK21 -> 258.92595 | AL22: =AJ22/Q22 -> 0.89175605 | AN22: =COUNTIF(Blends!H$4:H$1007,B22)+COUNTIF(Blends!J$4:J$1007,B22)+COUNTIF(#REF!,B22) -> 2 | AO22: =B22 -> 069T1R0 | AP22: Billing docs 1313.pdf | AQ22: =IFERROR(__xludf.DUMMYFUNCTION("AP22.url"),"https://drive.google.com/file/d/1IhkCrEpY71mN-XeHobUQ0SRvN5W_pdEX/view?usp=drive_link") -> https://drive.google.com/file/d/1IhkCrEpY71mN-XeHobUQ0SRvN5W_pdEX/view?usp=drive_link
A23: 22 | B23: 071T1R0 | D23: RS1-240501 | F23: paid | G23: NA | H23: AECN | I23: truck | K23: KAG | L23: Guy | N23: 45439 | O23: =IF(I23="truck",N23+4,IF(I23="train",N23+21,"")) -> 45443 | Q23: 19.98 | S23: =iferror(if(AN23=1,VLOOKUP(B23, Blends!H$4:AK$1004,32,0), ""), "") | U23: =Q23*T23*(44.01/12.011) -> 0 | V23: =$Q23*('MRV Calcs'!$E$3+'MRV Calcs'!$E$4) -> 2.9558799 | W23: =IF(H23="AECN",2030,"ERROR") -> 2030 | X23: =IF($I23="truck",($Q23*$W23*'MRV Calcs'!$E$7)+($W23*'MRV Calcs'!$E$8),0) -> 5.3777097 | Y23: =IF($I23="train",'MRV Calcs'!$E$24,0) -> 0 | Z23: =IF($I23="train",($Q23*$Y23*'MRV Calcs'!$E$7)+($Y23*'MRV Calcs'!$E$8),0) -> 0 | AA23: =IF($I23="train",'MRV Calcs'!$E$25,0) -> 0 | AB23: =IF($I23="train",($Q23*$AA23*'MRV Calcs'!$E$11)+($AA23*'MRV Calcs'!$E$12),0) -> 0 | AC23: =IF($I23="train",'MRV Calcs'!$E$26,0) -> 0 | AD23: =IF($I23="train",($Q23*$AC23*'MRV Calcs'!$E$7)+($AC23*'MRV Calcs'!$E$8),0) -> 0 | AE23: =($Q23/30)*SUM('MRV Calcs'!$E$15:$E$16) -> 3.0244832 | AF23: ='MRV Calcs'!$E$27 -> 71.2 | AG23: =(($Q23*1.1)*$AF23*'MRV Calcs'!$E$7)+($AF23*'MRV Calcs'!$E$8) -> 0.20693247 | AH23: =(($Q23*1.1)/20)*SUM('MRV Calcs'!$E$19:$E$20) -> 0.02813184 | AI23: =SUM(AH23,AG23,AE23,AD23,AB23,Z23,X23,V23) -> 11.593137 | AJ23: =U23-AI23 -> -11.593137 | AK23: =AJ23+AK22 -> 247.33282 | AL23: =AJ23/Q23 -> -0.58023709 | AN23: =COUNTIF(Blends!H$4:H$1007,B23)+COUNTIF(Blends!J$4:J$1007,B23)+COUNTIF(#REF!,B23) -> 0 | AO23: =B23 -> 071T1R0 | AP23: Billing docs 1313.pdf | AQ23: =IFERROR(__xludf.DUMMYFUNCTION("AP23.url"),"https://drive.google.com/file/d/1IhkCrEpY71mN-XeHobUQ0SRvN5W_pdEX/view?usp=drive_link") -> https://drive.google.com/file/d/1IhkCrEpY71mN-XeHobUQ0SRvN5W_pdEX/view?usp=drive_link
A24: 23 | B24: 072T1R0 | D24: RS1-240501 | F24: paid | G24: NA | H24: AECN | I24: truck | K24: Cherylann | L24: Renee/Mac | N24: 45440 | O24: 45447 | Q24: 20.21 | S24: =iferror(if(AN24=1,VLOOKUP(B24, Blends!H$4:AK$1004,32,0), ""), "") | U24: =Q24*T24*(44.01/12.011) -> 0 | V24: =$Q24*('MRV Calcs'!$E$3+'MRV Calcs'!$E$4) -> 2.9899066 | W24: =IF(H24="AECN",2030,"ERROR") -> 2030 | X24: =IF($I24="truck",($Q24*$W24*'MRV Calcs'!$E$7)+($W24*'MRV Calcs'!$E$8),0) -> 5.4378217 | Y24: =IF($I24="train",'MRV Calcs'!$E$24,0) -> 0 | Z24: =IF($I24="train",($Q24*$Y24*'MRV Calcs'!$E$7)+($Y24*'MRV Calcs'!$E$8),0) -> 0 | AA24: =IF($I24="train",'MRV Calcs'!$E$25,0) -> 0 | AB24: =IF($I24="train",($Q24*$AA24*'MRV Calcs'!$E$11)+($AA24*'MRV Calcs'!$E$12),0) -> 0 | AC24: =IF($I24="train",'MRV Calcs'!$E$26,0) -> 0 | AD24: =IF($I24="train",($Q24*$AC24*'MRV Calcs'!$E$7)+($AC24*'MRV Calcs'!$E$8),0) -> 0 | AE24: =($Q24/30)*SUM('MRV Calcs'!$E$15:$E$16) -> 3.0592995 | AF24: ='MRV Calcs'!$E$27 -> 71.2 | AG24: =(($Q24*1.1)*$AF24*'MRV Calcs'!$E$7)+($AF24*'MRV Calcs'!$E$8) -> 0.20925167 | AH24: =(($Q24*1.1)/20)*SUM('MRV Calcs'!$E$19:$E$20) -> 0.02845568 | AI24: =SUM(AH24,AG24,AE24,AD24,AB24,Z24,X24,V24) -> 11.724735 | AJ24: =U24-AI24 -> -11.724735 | AK24: =AJ24+AK23 -> 235.60808 | AL24: =AJ24/Q24 -> -0.58014523 | AN24: =COUNTIF(Blends!H$4:H$1007,B24)+COUNTIF(Blends!J$4:J$1007,B24)+COUNTIF(#REF!,B24) -> 1 | AO24: =B24 -> 072T1R0 | AP24: documents camion 1314.pdf | AQ24: =IFERROR(__xludf.DUMMYFUNCTION("AP24.url"),"https://drive.google.com/file/d/13NxUMAxcctmTThByx394I91302dhsO2P/view?usp=drive_link") -> https://drive.google.com/file/d/13NxUMAxcctmTThByx394I91302dhsO2P/view?usp=drive_link
A25: 24 | B25: 073T1R0 | D25: RS2-240504 | F25: paid | G25: NA | H25: AECN | I25: truck | K25: Cherylann | L25: Paul/Patrick | N25: 45442 | O25: 45448 | Q25: 20.18 | S25: =iferror(if(AN25=1,VLOOKUP(B25, Blends!H$4:AK$1004,32,0), ""), "") | U25: =Q25*T25*(44.01/12.011) -> 0 | V25: =$Q25*('MRV Calcs'!$E$3+'MRV Calcs'!$E$4) -> 2.9854683 | W25: =IF(H25="AECN",2030,"ERROR") -> 2030 | X25: =IF($I25="truck",($Q25*$W25*'MRV Calcs'!$E$7)+($W25*'MRV Calcs'!$E$8),0) -> 5.429981 | Y25: =IF($I25="train",'MRV Calcs'!$E$24,0) -> 0 | Z25: =IF($I25="train",($Q25*$Y25*'MRV Calcs'!$E$7)+($Y25*'MRV Calcs'!$E$8),0) -> 0 | AA25: =IF($I25="train",'MRV Calcs'!$E$25,0) -> 0 | AB25: =IF($I25="train",($Q25*$AA25*'MRV Calcs'!$E$11)+($AA25*'MRV Calcs'!$E$12),0) -> 0 | AC25: =IF($I25="train",'MRV Calcs'!$E$26,0) -> 0 | AD25: =IF($I25="train",($Q25*$AC25*'MRV Calcs'!$E$7)+($AC25*'MRV Calcs'!$E$8),0) -> 0 | AE25: =($Q25/30)*SUM('MRV Calcs'!$E$15:$E$16) -> 3.0547583 | AF25: ='MRV Calcs'!$E$27 -> 71.2 | AG25: =(($Q25*1.1)*$AF25*'MRV Calcs'!$E$7)+($AF25*'MRV Calcs'!$E$8) -> 0.20894917 | AH25: =(($Q25*1.1)/20)*SUM('MRV Calcs'!$E$19:$E$20) -> 0.02841344 | AI25: =SUM(AH25,AG25,AE25,AD25,AB25,Z25,X25,V25) -> 11.70757 | AJ25: =U25-AI25 -> -11.70757 | AK25: =AJ25+AK24 -> 223.90051 | AL25: =AJ25/Q25 -> -0.5801571 | AN25: =COUNTIF(Blends!H$4:H$1007,B25)+COUNTIF(Blends!J$4:J$1007,B25)+COUNTIF(#REF!,B25) -> 0 | AO25: =B25 -> 073T1R0 | AP25: Billing Documents 1315 Corrected P3.pdf | AQ25: =IFERROR(__xludf.DUMMYFUNCTION("AP25.url"),"https://drive.google.com/file/d/1-C_dWMhablbSrqyYqX8F-DUjV6eqze82/view?usp=drive_link") -> https://drive.google.com/file/d/1-C_dWMhablbSrqyYqX8F-DUjV6eqze82/view?usp=drive_link
A26: 25 | B26: 074T1R0 | D26: RS2-240504 | F26: paid | G26: NA | H26: AECN | I26: truck | K26: KAG | L26: Gus | N26: 45445 | O26: 45448 | Q26: 21.8 | S26: =iferror(if(AN26=1,VLOOKUP(B26, Blends!H$4:AK$1004,32,0), ""), "") | T26: 0.3907 | U26: =Q26*T26*(44.01/12.011) -> 31.208443 | V26: =$Q26*('MRV Calcs'!$E$3+'MRV Calcs'!$E$4) -> 3.2251342 | W26: =IF(H26="AECN",2030,"ERROR") -> 2030 | X26: =IF($I26="truck",($Q26*$W26*'MRV Calcs'!$E$7)+($W26*'MRV Calcs'!$E$8),0) -> 5.8533791 | Y26: =IF($I26="train",'MRV Calcs'!$E$24,0) -> 0 | Z26: =IF($I26="train",($Q26*$Y26*'MRV Calcs'!$E$7)+($Y26*'MRV Calcs'!$E$8),0) -> 0 | AA26: =IF($I26="train",'MRV Calcs'!$E$25,0) -> 0 | AB26: =IF($I26="train",($Q26*$AA26*'MRV Calcs'!$E$11)+($AA26*'MRV Calcs'!$E$12),0) -> 0 | AC26: =IF($I26="train",'MRV Calcs'!$E$26,0) -> 0 | AD26: =IF($I26="train",($Q26*$AC26*'MRV Calcs'!$E$7)+($AC26*'MRV Calcs'!$E$8),0) -> 0 | AE26: =($Q26/30)*SUM('MRV Calcs'!$E$15:$E$16) -> 3.2999866 | AF26: ='MRV Calcs'!$E$27 -> 71.2 | AG26: =(($Q26*1.1)*$AF26*'MRV Calcs'!$E$7)+($AF26*'MRV Calcs'!$E$8) -> 0.22528441 | AH26: =(($Q26*1.1)/20)*SUM('MRV Calcs'!$E$19:$E$20) -> 0.0306944 | AI26: =SUM(AH26,AG26,AE26,AD26,AB26,Z26,X26,V26) -> 12.634479 | AJ26: =U26-AI26 -> 18.573965 | AK26: =AJ26+AK25 -> 242.47448 | AL26: =AJ26/Q26 -> 0.85201672 | AN26: =COUNTIF(Blends!H$4:H$1007,B26)+COUNTIF(Blends!J$4:J$1007,B26)+COUNTIF(#REF!,B26) -> 2 | AO26: =B26 -> 074T1R0 | AP26: Billing documents Truck 1316.pdf | AQ26: =IFERROR(__xludf.DUMMYFUNCTION("AP26.url"),"https://drive.google.com/file/d/17uNOF88hLvhphw_1Diqh39l3RiRs7Sgw/view?usp=drive_link") -> https://drive.google.com/file/d/17uNOF88hLvhphw_1Diqh39l3RiRs7Sgw/view?usp=drive_link
A27: 26 | B27: 075T1R0 | D27: RS2-240504 | F27: paid | G27: NA | H27: AECN | I27: truck | K27: KAG | L27: Darryl | N27: 45446 | O27: 45449 | Q27: 20.42 | S27: =iferror(if(AN27=1,VLOOKUP(B27, Blends!H$4:AK$1004,32,0), ""), "") | T27: 0.3907 | U27: =Q27*T27*(44.01/12.011) -> 29.232863 | V27: =$Q27*('MRV Calcs'!$E$3+'MRV Calcs'!$E$4) -> 3.0209744 | W27: =IF(H27="AECN",2030,"ERROR") -> 2030 | X27: =IF($I27="truck",($Q27*$W27*'MRV Calcs'!$E$7)+($W27*'MRV Calcs'!$E$8),0) -> 5.4927067 | Y27: =IF($I27="train",'MRV Calcs'!$E$24,0) -> 0 | Z27: =IF($I27="train",($Q27*$Y27*'MRV Calcs'!$E$7)+($Y27*'MRV Calcs'!$E$8),0) -> 0 | AA27: =IF($I27="train",'MRV Calcs'!$E$25,0) -> 0 | AB27: =IF($I27="train",($Q27*$AA27*'MRV Calcs'!$E$11)+($AA27*'MRV Calcs'!$E$12),0) -> 0 | AC27: =IF($I27="train",'MRV Calcs'!$E$26,0) -> 0 | AD27: =IF($I27="train",($Q27*$AC27*'MRV Calcs'!$E$7)+($AC27*'MRV Calcs'!$E$8),0) -> 0 | AE27: =($Q27/30)*SUM('MRV Calcs'!$E$15:$E$16) -> 3.0910884 | AF27: ='MRV Calcs'!$E$27 -> 71.2 | AG27: =(($Q27*1.1)*$AF27*'MRV Calcs'!$E$7)+($AF27*'MRV Calcs'!$E$8) -> 0.21136921 | AH27: =(($Q27*1.1)/20)*SUM('MRV Calcs'!$E$19:$E$20) -> 0.02875136 | AI27: =SUM(AH27,AG27,AE27,AD27,AB27,Z27,X27,V27) -> 11.84489 | AJ27: =U27-AI27 -> 17.387973 | AK27: =AJ27+AK26 -> 259.86245 | AL27: =AJ27/Q27 -> 0.8515168 | AN27: =COUNTIF(Blends!H$4:H$1007,B27)+COUNTIF(Blends!J$4:J$1007,B27)+COUNTIF(#REF!,B27) -> 1 | AO27: =B27 -> 075T1R0 | AP27: Envoi des documents Camion 1317 Correction.pdf | AQ27: =IFERROR(__xludf.DUMMYFUNCTION("AP27.url"),"https://drive.google.com/file/d/1ixRHHTl7zI-DRoGQ6CfWJxFksCBt2eCm/view?usp=drive_link") -> https://drive.google.com/file/d/1ixRHHTl7zI-DRoGQ6CfWJxFksCBt2eCm/view?usp=drive_link
A28: 27 | B28: 076T1R0 | D28: RS2-240504 | F28: paid | G28: NA | H28: AECN | I28: truck | K28: KAG | L28: Raymond | N28: 45446 | O28: 45449 | Q28: 20.9 | S28: =iferror(if(AN28=1,VLOOKUP(B28, Blends!H$4:AK$1004,32,0), ""), "") | T28: 0.3907 | U28: =Q28*T28*(44.01/12.011) -> 29.920021 | V28: =$Q28*('MRV Calcs'!$E$3+'MRV Calcs'!$E$4) -> 3.0919865 | W28: =IF(H28="AECN",2030,"ERROR") -> 2030 | X28: =IF($I28="truck",($Q28*$W28*'MRV Calcs'!$E$7)+($W28*'MRV Calcs'!$E$8),0) -> 5.6181579 | Y28: =IF($I28="train",'MRV Calcs'!$E$24,0) -> 0 | Z28: =IF($I28="train",($Q28*$Y28*'MRV Calcs'!$E$7)+($Y28*'MRV Calcs'!$E$8),0) -> 0 | AA28: =IF($I28="train",'MRV Calcs'!$E$25,0) -> 0 | AB28: =IF($I28="train",($Q28*$AA28*'MRV Calcs'!$E$11)+($AA28*'MRV Calcs'!$E$12),0) -> 0 | AC28: =IF($I28="train",'MRV Calcs'!$E$26,0) -> 0 | AD28: =IF($I28="train",($Q28*$AC28*'MRV Calcs'!$E$7)+($AC28*'MRV Calcs'!$E$8),0) -> 0 | AE28: =($Q28/30)*SUM('MRV Calcs'!$E$15:$E$16) -> 3.1637486 | AF28: ='MRV Calcs'!$E$27 -> 71.2 | AG28: =(($Q28*1.1)*$AF28*'MRV Calcs'!$E$7)+($AF28*'MRV Calcs'!$E$8) -> 0.21620928 | AH28: =(($Q28*1.1)/20)*SUM('MRV Calcs'!$E$19:$E$20) -> 0.0294272 | AI28: =SUM(AH28,AG28,AE28,AD28,AB28,Z28,X28,V28) -> 12.11953 | AJ28: =U28-AI28 -> 17.800492 | AK28: =AJ28+AK27 -> 277.66294 | AL28: =AJ28/Q28 -> 0.85169817 | AN28: =COUNTIF(Blends!H$4:H$1007,B28)+COUNTIF(Blends!J$4:J$1007,B28)+COUNTIF(#REF!,B28) -> 1 | AO28: =B28 -> 076T1R0 | AP28: Envoi des documents Camion 1318 Correction.pdf | AQ28: =IFERROR(__xludf.DUMMYFUNCTION("AP28.url"),"https://drive.google.com/file/d/1MnFOnCrAD8vGM8g1RB_9LKq-SHYJp4NA/view?usp=drive_link") -> https://drive.google.com/file/d/1MnFOnCrAD8vGM8g1RB_9LKq-SHYJp4NA/view?usp=drive_link
A29: 28 | B29: 077T1R0 | D29: RS3-240607 | F29: paid | G29: NA | H29: AECN | I29: truck | K29: KAG | L29: Guy | N29: 45453 | O29: 45456 | Q29: 20.33 | S29: =iferror(if(AN29=1,VLOOKUP(B29, Blends!H$4:AK$1004,32,0), ""), "") | T29: 0.409 | U29: =Q29*T29*(44.01/12.011) -> 30.467224 | V29: =$Q29*('MRV Calcs'!$E$3+'MRV Calcs'!$E$4) -> 3.0076596 | W29: =IF(H29="AECN",2030,"ERROR") -> 2030 | X29: =IF($I29="truck",($Q29*$W29*'MRV Calcs'!$E$7)+($W29*'MRV Calcs'!$E$8),0) -> 5.4691846 | Y29: =IF($I29="train",'MRV Calcs'!$E$24,0) -> 0 | Z29: =IF($I29="train",($Q29*$Y29*'MRV Calcs'!$E$7)+($Y29*'MRV Calcs'!$E$8),0) -> 0 | AA29: =IF($I29="train",'MRV Calcs'!$E$25,0) -> 0 | AB29: =IF($I29="train",($Q29*$AA29*'MRV Calcs'!$E$11)+($AA29*'MRV Calcs'!$E$12),0) -> 0 | AC29: =IF($I29="train",'MRV Calcs'!$E$26,0) -> 0 | AD29: =IF($I29="train",($Q29*$AC29*'MRV Calcs'!$E$7)+($AC29*'MRV Calcs'!$E$8),0) -> 0 | AE29: =($Q29/30)*SUM('MRV Calcs'!$E$15:$E$16) -> 3.0774646 | AF29: ='MRV Calcs'!$E$27 -> 71.2 | AG29: =(($Q29*1.1)*$AF29*'MRV Calcs'!$E$7)+($AF29*'MRV Calcs'!$E$8) -> 0.21046169 | AH29: =(($Q29*1.1)/20)*SUM('MRV Calcs'!$E$19:$E$20) -> 0.02862464 | AI29: =SUM(AH29,AG29,AE29,AD29,AB29,Z29,X29,V29) -> 11.793395 | AJ29: =U29-AI29 -> 18.673829 | AK29: =AJ29+AK28 -> 296.33677 | AL29: =AJ29/Q29 -> 0.91853562 | AN29: =COUNTIF(Blends!H$4:H$1007,B29)+COUNTIF(Blends!J$4:J$1007,B29)+COUNTIF(#REF!,B29) -> 1 | AO29: =B29 -> 077T1R0 | AP29: Envoi des documents camion 1332.pdf | AQ29: =IFERROR(__xludf.DUMMYFUNCTION("AP29.url"),"https://drive.google.com/file/d/1X2Gy2qtnYVwewlcLSlqXQQ4tsNpo4ngZ/view?usp=drive_link") -> https://drive.google.com/file/d/1X2Gy2qtnYVwewlcLSlqXQQ4tsNpo4ngZ/view?usp=drive_link
A30: 29 | B30: 078T1R0 | D30: RS3-240607 | F30: paid | G30: NA | H30: AECN | I30: truck | K30: KAG | L30: Gus | N30: 45453 | O30: 45457 | Q30: 21.35 | S30: =iferror(if(AN30=1,VLOOKUP(B30, Blends!H$4:AK$1004,32,0), ""), "") | U30: =Q30*T30*(44.01/12.011) -> 0 | V30: =$Q30*('MRV Calcs'!$E$3+'MRV Calcs'!$E$4) -> 3.1585604 | W30: =IF(H30="AECN",2030,"ERROR") -> 2030 | X30: =IF($I30="truck",($Q30*$W30*'MRV Calcs'!$E$7)+($W30*'MRV Calcs'!$E$8),0) -> 5.7357685 | Y30: =IF($I30="train",'MRV Calcs'!$E$24,0) -> 0 | Z30: =IF($I30="train",($Q30*$Y30*'MRV Calcs'!$E$7)+($Y30*'MRV Calcs'!$E$8),0) -> 0 | AA30: =IF($I30="train",'MRV Calcs'!$E$25,0) -> 0 | AB30: =IF($I30="train",($Q30*$AA30*'MRV Calcs'!$E$11)+($AA30*'MRV Calcs'!$E$12),0) -> 0 | AC30: =IF($I30="train",'MRV Calcs'!$E$26,0) -> 0 | AD30: =IF($I30="train",($Q30*$AC30*'MRV Calcs'!$E$7)+($AC30*'MRV Calcs'!$E$8),0) -> 0 | AE30: =($Q30/30)*SUM('MRV Calcs'!$E$15:$E$16) -> 3.2318676 | AF30: ='MRV Calcs'!$E$27 -> 71.2 | AG30: =(($Q30*1.1)*$AF30*'MRV Calcs'!$E$7)+($AF30*'MRV Calcs'!$E$8) -> 0.22074684 | AH30: =(($Q30*1.1)/20)*SUM('MRV Calcs'!$E$19:$E$20) -> 0.0300608 | AI30: =SUM(AH30,AG30,AE30,AD30,AB30,Z30,X30,V30) -> 12.377004 | AJ30: =U30-AI30 -> -12.377004 | AK30: =AJ30+AK29 -> 283.95977 | AL30: =AJ30/Q30 -> -0.57971916 | AN30: =COUNTIF(Blends!H$4:H$1007,B30)+COUNTIF(Blends!J$4:J$1007,B30)+COUNTIF(#REF!,B30) -> 2 | AO30: =B30 -> 078T1R0 | AP30: Envoi des documents camion 1333.pdf | AQ30: =IFERROR(__xludf.DUMMYFUNCTION("AP30.url"),"https://drive.google.com/file/d/1O4pLKPKPg7vfYcejoZyapVlunJfHYmhq/view?usp=drive_link") -> https://drive.google.com/file/d/1O4pLKPKPg7vfYcejoZyapVlunJfHYmhq/view?usp=drive_link
A31: 30 | B31: 079T1R0 | D31: RS1-240609 | F31: paid | G31: NA | H31: AECN | I31: truck | K31: KAG | L31: Darryl | N31: 45454 | O31: 45457 | Q31: 20.64 | S31: =iferror(if(AN31=1,VLOOKUP(B31, Blends!H$4:AK$1004,32,0), ""), "") | U31: =Q31*T31*(44.01/12.011) -> 0 | V31: =$Q31*('MRV Calcs'!$E$3+'MRV Calcs'!$E$4) -> 3.0535216 | W31: =IF(H31="AECN",2030,"ERROR") -> 2030 | X31: =IF($I31="truck",($Q31*$W31*'MRV Calcs'!$E$7)+($W31*'MRV Calcs'!$E$8),0) -> 5.5502052 | Y31: =IF($I31="train",'MRV Calcs'!$E$24,0) -> 0 | Z31: =IF($I31="train",($Q31*$Y31*'MRV Calcs'!$E$7)+($Y31*'MRV Calcs'!$E$8),0) -> 0 | AA31: =IF($I31="train",'MRV Calcs'!$E$25,0) -> 0 | AB31: =IF($I31="train",($Q31*$AA31*'MRV Calcs'!$E$11)+($AA31*'MRV Calcs'!$E$12),0) -> 0 | AC31: =IF($I31="train",'MRV Calcs'!$E$26,0) -> 0 | AD31: =IF($I31="train",($Q31*$AC31*'MRV Calcs'!$E$7)+($AC31*'MRV Calcs'!$E$8),0) -> 0 | AE31: =($Q31/30)*SUM('MRV Calcs'!$E$15:$E$16) -> 3.124391 | AF31: ='MRV Calcs'!$E$27 -> 71.2 | AG31: =(($Q31*1.1)*$AF31*'MRV Calcs'!$E$7)+($AF31*'MRV Calcs'!$E$8) -> 0.21358757 | AH31: =(($Q31*1.1)/20)*SUM('MRV Calcs'!$E$19:$E$20) -> 0.02906112 | AI31: =SUM(AH31,AG31,AE31,AD31,AB31,Z31,X31,V31) -> 11.970766 | AJ31: =U31-AI31 -> -11.970766 | AK31: =AJ31+AK30 -> 271.989 | AL31: =AJ31/Q31 -> -0.579979 | AN31: =COUNTIF(Blends!H$4:H$1007,B31)+COUNTIF(Blends!J$4:J$1007,B31)+COUNTIF(#REF!,B31) -> 2 | AO31: =B31 -> 079T1R0 | AP31: Billing documents 1336.pdf | AQ31: =IFERROR(__xludf.DUMMYFUNCTION("AP31.url"),"https://drive.google.com/file/d/1PMm4mPO6wTzuSfG50ZJYwKVCSfMj7Ld9/view?usp=drive_link") -> https://drive.google.com/file/d/1PMm4mPO6wTzuSfG50ZJYwKVCSfMj7Ld9/view?usp=drive_link
A32: 31 | B32: 080T1R0 | D32: RS1-240609 | F32: paid | G32: NA | H32: AECN | I32: truck | K32: KAG | L32: Raymond | N32: 45454 | O32: 45457 | Q32: 20.55 | S32: =iferror(if(AN32=1,VLOOKUP(B32, Blends!H$4:AK$1004,32,0), ""), "") | U32: =Q32*T32*(44.01/12.011) -> 0 | V32: =$Q32*('MRV Calcs'!$E$3+'MRV Calcs'!$E$4) -> 3.0402068 | W32: =IF(H32="AECN",2030,"ERROR") -> 2030 | X32: =IF($I32="truck",($Q32*$W32*'MRV Calcs'!$E$7)+($W32*'MRV Calcs'!$E$8),0) -> 5.5266831 | Y32: =IF($I32="train",'MRV Calcs'!$E$24,0) -> 0 | Z32: =IF($I32="train",($Q32*$Y32*'MRV Calcs'!$E$7)+($Y32*'MRV Calcs'!$E$8),0) -> 0 | AA32: =IF($I32="train",'MRV Calcs'!$E$25,0) -> 0 | AB32: =IF($I32="train",($Q32*$AA32*'MRV Calcs'!$E$11)+($AA32*'MRV Calcs'!$E$12),0) -> 0 | AC32: =IF($I32="train",'MRV Calcs'!$E$26,0) -> 0 | AD32: =IF($I32="train",($Q32*$AC32*'MRV Calcs'!$E$7)+($AC32*'MRV Calcs'!$E$8),0) -> 0 | AE32: =($Q32/30)*SUM('MRV Calcs'!$E$15:$E$16) -> 3.1107672 | AF32: ='MRV Calcs'!$E$27 -> 71.2 | AG32: =(($Q32*1.1)*$AF32*'MRV Calcs'!$E$7)+($AF32*'MRV Calcs'!$E$8) -> 0.21268006 | AH32: =(($Q32*1.1)/20)*SUM('MRV Calcs'!$E$19:$E$20) -> 0.0289344 | AI32: =SUM(AH32,AG32,AE32,AD32,AB32,Z32,X32,V32) -> 11.919272 | AJ32: =U32-AI32 -> -11.919272 | AK32: =AJ32+AK31 -> 260.06973 | AL32: =AJ32/Q32 -> -0.58001321 | AN32: =COUNTIF(Blends!H$4:H$1007,B32)+COUNTIF(Blends!J$4:J$1007,B32)+COUNTIF(#REF!,B32) -> 2 | AO32: =B32 -> 080T1R0 | AP32: Envoi des documents truck 1338.pdf | AQ32: =IFERROR(__xludf.DUMMYFUNCTION("AP32.url"),"https://drive.google.com/file/d/1hfTxljZLrN-NZoaiI1t659WvYefkqYun/view?usp=drive_link") -> https://drive.google.com/file/d/1hfTxljZLrN-NZoaiI1t659WvYefkqYun/view?usp=drive_link
A33: 32 | B33: 081T1R0 | D33: RS1-240617 | F33: paid | G33: NA | H33: AECN | I33: truck | K33: KAG | L33: Gus | N33: 45464 | O33: 45468 | Q33: 21.26 | S33: =iferror(if(AN33=1,VLOOKUP(B33, Blends!H$4:AK$1004,32,0), ""), "") | U33: =Q33*T33*(44.01/12.011) -> 0 | V33: =$Q33*('MRV Calcs'!$E$3+'MRV Calcs'!$E$4) -> 3.1452456 | W33: =IF(H33="AECN",2030,"ERROR") -> 2030 | X33: =IF($I33="truck",($Q33*$W33*'MRV Calcs'!$E$7)+($W33*'MRV Calcs'!$E$8),0) -> 5.7122464 | Y33: =IF($I33="train",'MRV Calcs'!$E$24,0) -> 0 | Z33: =IF($I33="train",($Q33*$Y33*'MRV Calcs'!$E$7)+($Y33*'MRV Calcs'!$E$8),0) -> 0 | AA33: =IF($I33="train",'MRV Calcs'!$E$25,0) -> 0 | AB33: =IF($I33="train",($Q33*$AA33*'MRV Calcs'!$E$11)+($AA33*'MRV Calcs'!$E$12),0) -> 0 | AC33: =IF($I33="train",'MRV Calcs'!$E$26,0) -> 0 | AD33: =IF($I33="train",($Q33*$AC33*'MRV Calcs'!$E$7)+($AC33*'MRV Calcs'!$E$8),0) -> 0 | AE33: =($Q33/30)*SUM('MRV Calcs'!$E$15:$E$16) -> 3.2182438 | AF33: ='MRV Calcs'!$E$27 -> 71.2 | AG33: =(($Q33*1.1)*$AF33*'MRV Calcs'!$E$7)+($AF33*'MRV Calcs'!$E$8) -> 0.21983933 | AH33: =(($Q33*1.1)/20)*SUM('MRV Calcs'!$E$19:$E$20) -> 0.02993408 | AI33: =SUM(AH33,AG33,AE33,AD33,AB33,Z33,X33,V33) -> 12.325509 | AJ33: =U33-AI33 -> -12.325509 | AK33: =AJ33+AK32 -> 247.74422 | AL33: =AJ33/Q33 -> -0.57975114 | AN33: =COUNTIF(Blends!H$4:H$1007,B33)+COUNTIF(Blends!J$4:J$1007,B33)+COUNTIF(#REF!,B33) -> 0 | AO33: =B33 -> 081T1R0 | AP33: Envoi des documents Camion 1370.pdf | AQ33: =IFERROR(__xludf.DUMMYFUNCTION("AP33.url"),"https://drive.google.com/file/d/1qc0SfU6CrYEqCOUyi2dSwZrlTyg0eq_m/view?usp=drive_link") -> https://drive.google.com/file/d/1qc0SfU6CrYEqCOUyi2dSwZrlTyg0eq_m/view?usp=drive_link
A34: 33 | B34: 060-62T2R6 | D34: RS1-240617; RS3-240613 | F34: paid | G34: TRUE | H34: AECN | I34: train | K34: Watco | L34: GATX 032974 | N34: 45471 | O34: 45530 | Q34: =26.34+27.51+27.44 -> 81.29 | S34: =iferror(if(AN34=1,VLOOKUP(B34, Blends!H$4:AK$1004,32,0), ""), "") | T34: 0.3933 | U34: =Q34*T34*(44.01/12.011) -> 117.14757 | V34: =$Q34*('MRV Calcs'!$E$3+'MRV Calcs'!$E$4) -> 12.0262 | W34: =IF(H34="AECN",2030,"ERROR") -> 2030 | X34: =IF($I34="truck",($Q34*$W34*'MRV Calcs'!$E$7)+($W34*'MRV Calcs'!$E$8),0) -> 0 | Y34: =IF($I34="train",'MRV Calcs'!$E$24,0) -> 107.497 | Z34: =IF($I34="train",($Q34*$Y34*'MRV Calcs'!$E$7)+($Y34*'MRV Calcs'!$E$8),0) -> 1.1332988 | AA34: =IF($I34="train",'MRV Calcs'!$E$25,0) -> 2087 | AB34: =IF($I34="train",($Q34*$AA34*'MRV Calcs'!$E$11)+($AA34*'MRV Calcs'!$E$12),0) -> 4.5385362 | AC34: =IF($I34="train",'MRV Calcs'!$E$26,0) -> 32.6 | AD34: =IF($I34="train",($Q34*$AC34*'MRV Calcs'!$E$7)+($AC34*'MRV Calcs'!$E$8),0) -> 0.34368905 | AE34: =($Q34/30)*SUM('MRV Calcs'!$E$15:$E$16) -> 12.305317 | AF34: ='MRV Calcs'!$E$27 -> 71.2 | AG34: =(($Q34*1.1)*$AF34*'MRV Calcs'!$E$7)+($AF34*'MRV Calcs'!$E$8) -> 0.82515068 | AH34: =(($Q34*1.1)/20)*SUM('MRV Calcs'!$E$19:$E$20) -> 0.11445632 | AI34: =SUM(AH34,AG34,AE34,AD34,AB34,Z34,X34,V34) -> 31.286648 | AJ34: =U34-AI34 -> 85.860918 | AK34: =AJ34+AK33 -> 333.60514 | AL34: =AJ34/Q34 -> 1.0562298 | AN34: =COUNTIF(Blends!H$4:H$1007,B34)+COUNTIF(Blends!J$4:J$1007,B34)+COUNTIF(#REF!,B34) -> 6 | AO34: =B34 -> 060-62T2R6 | AP34: 060T2R1-062T2R1 6/20-6/21 Pickups GATX032974 | AQ34: =IFERROR(__xludf.DUMMYFUNCTION("AP34.url"),"https://drive.google.com/drive/folders/1PH2j_8KGpG5VSyDZlozK_yuQSUTJUWtL?usp=drive_link") -> https://drive.google.com/drive/folders/1PH2j_8KGpG5VSyDZlozK_yuQSUTJUWtL?usp=drive_link
