Workbook

Sheet Summary
A1: BATCH SUMMARY
A2: Batch ID | B2: INJ-05-2026-W4
A3: Week Start (Sat) | B3: 46165
A4: Week End (Sat) | B4: 46172
A6: SECTION 1 - PER-TAB SUMMARY (each row pulls from its mode tab)
A7: Source Tab | B7: Σ Deliveries / Cargo (kg) | C7: Σ Uncertainty Adj (kg) | D7: Mass Used (kg) | E7: Sparging Loss (kg) | F7: Filtration Loss (kg) | G7: MOBI (kg) | H7: AECN→SOPOR EE (mi) | I7: Rail EE (mi) | J7: Opel→Basco EE (mi)
A8: AECN Rail | B8: ='AECN Rail'!A44 -> 146361.95 | C8: ='AECN Rail'!B44 -> 86.416056 | D8: ='AECN Rail'!C44 -> 146275.53 | E8: ='AECN Rail'!D44 -> 1886.9544 | F8: ='AECN Rail'!E44 -> 284.74003 | G8: ='AECN Rail'!F44 -> 144103.84 | H8: =SUM('AECN Rail'!L28:L40) -> 1213.1183 | I8: =SUM('AECN Rail'!M28:M40) -> 8271.7744 | J8: =SUM('AECN Rail'!N28:N40) -> 1201.2
A9: AECN Truck | B9: ='AECN Truck'!B28 -> 0 | C9: ='AECN Truck'!F28 -> 0 | D9: ='AECN Truck'!C28 -> 0 | E9: ='AECN Truck'!D28 -> 0 | F9: ='AECN Truck'!E28 -> 0 | G9: ='AECN Truck'!G28 -> 0
A10: Charm WODO | B10: =WODO!A33 -> 0 | C10: 0 | D10: =WODO!A33 -> 0 | E10: =WODO!B33 -> 0 | F10: 0 | G10: =WODO!C33 -> 0
A11: Kerry | B11: =Kerry!A33 -> 0 | C11: 0 | D11: =Kerry!A33 -> 0 | E11: =Kerry!B33 -> 0 | F11: 0 | G11: =Kerry!C33 -> 0
A12: QOWV | B12: =QOWV!B53 -> 42084 | C12: 0 | D12: =QOWV!D53 -> 39657.4 | E12: 0 | F12: 0 | G12: =QOWV!F53 -> 33977
A13: TOTAL | B13: =SUM(B8:B12) -> 188445.95 | C13: =SUM(C8:C12) -> 86.416056 | D13: =SUM(D8:D12) -> 185932.93 | E13: =SUM(E8:E12) -> 1886.9544 | F13: =SUM(F8:F12) -> 284.74003 | G13: =SUM(G8:G12) -> 178080.84 | H13: =SUM(H8:H12) -> 1213.1183 | I13: =SUM(I8:I12) -> 8271.7744 | J13: =SUM(J8:J12) -> 1201.2
A15: SECTION 2 - PER-OIL-TYPE ROLLUP (composite C% per oil type per week)
A16: Oil Type | B16: MOBI (kg) | C16: Composite Sample ID | D16: Date Composited | E16: C % | F16: Lab COA Link | G16: C Content Uncertainty | H16: Testing Uncertainty
A17: AECN | B17: =G8+G9 -> 144103.84 | C17: INJ-05-2026 W4 AECN QOWV | D17: 46171 | E17: 0.412 | F17: INJ-05-2026 W4 AECN QOWV.pdf | G17: =E17*H17 -> 0.001648 | H17: 0.004
A18: WODO | B18: =G10 -> 0
A19: Kerry | B19: =G11 -> 0
A20: QOWV | B20: =G12 -> 33977 | C20: INJ-05-2026 W4 AECN QOWV | D20: 46171 | E20: 0.084 | F20: INJ-05-2026 W4 AECN QOWV.pdf | G20: =E20*H20 -> 0.000336 | H20: 0.004
A21: TOTAL | B21: =SUM(B17:B20) -> 178080.84

Sheet AECN Rail
A1: BATCH HEADER — AECN Rail
A2: Batch ID (INJ-YYYY-WXX) | B2: INJ-05-2026-W4 | N2: Constants
A3: Week Start (Sat) | B3: 46165 | N3: Lbs/Kg | O3: 2.20462
A4: Week End (Sat) | B4: 46172 | N4: Kg/Lbs | O4: 0.453592
N5: Sparging Mass Loss | O5: 0.0129
N6: pH range (target) | O6: 2.0 - 4.0
N7: Filtration Solids Content | O7: =HYPERLINK("https://docs.google.com/spreadsheets/d/1XhIwfVwGTl2T04CAlA-qee03gfqxNWwBmSCAeiSW548/edit?usp=sharing", 0.00196) -> 0.00196
A8: SECTION 1 - RAILCARS RECEIVED THIS WEEK (entity-level) | N8: BOL Trips (AECN→SOPOR) | O8: 3
A9: Railcar # | B9: Arrival Date at Opelousas | C9: Loading BOLs (comma-sep) | D9: Total Loaded (MT) | E9: Total Loaded (kg) | F9: Total Offloaded (kg, auto) | G9: Loss (kg) | H9: Prior Period Mass | I9: Prior-RP Claimed (kg) | J9: AECN→SOPOR (mi) | K9: Rail (mi) | L9: Opel→Basco (mi) | M9: Notes | N9: Round Trip (Opel→Basco) | O9: 2
A10: GPRX5188 | B10: 46143 | C10: 2353-R, 2354-R, 2355-R | D10: 77.52 | E10: 77520 | F10: =SUMIF($C$28:$C$41,A10,$F$28:$F$41)+H10 -> 77606.416 | G10: =IF(AND(E10<>"",F10<>"",F10>=0.95*E10),E10-F10,"") -> -86.416056 | H10: 0 | I10: 0 | J10: 107.5 | K10: 2199 | L10: 42.9 | M10: All 4 offloads complete. Prior-RP claimed: 0 kg. Total offloaded = Total loaded (77,520.00 kg). Loss = 0 kg. | Offload 4 note: BOL-cap rule applied: scale total 77,616.60 kg exceeded BOL total 77,520 kg by 96.60 kg; overage removed from offload 4 via Uncertainty Adjustment per May VVB Guidance.
A11: TIMX201060 | B11: 46147 | C11: 2362-R, 2363-R, 2364-R | D11: 78.06 | E11: 78060 | F11: =SUMIF($C$28:$C$41,A11,$F$28:$F$41)+H11 -> 68755.531 | G11: =IF(AND(E11<>"",F11<>"",F11>=0.95*E11),E11-F11,"") | H11: 0 | I11: 0 | J11: 107.5 | K11: 2199 | L11: 42.9 | M11: W4 loading (5.7.2026, BOLs 2362-R/2363-R/2364-R, 78.06 MT). 3 offloads this week; Loss suppressed until closed (>=95%). NOTE: prior TIMX201060 lots (2.27.26 loading, BOLs 2314-R/2316-R/2317-R) were a separate trip; prior-RP claimed = 0 for this loading.
G12: =IF(AND(E12<>"",F12<>"",F12>=0.95*E12),E12-F12,"")
G13: =IF(AND(E13<>"",F13<>"",F13>=0.95*E13),E13-F13,"")
G14: =IF(AND(E14<>"",F14<>"",F14>=0.95*E14),E14-F14,"")
A15: SECTION 2 - ORIGINS LEDGER (loading BOLs at SOPOR)
A16: Date | B16: BOL # | C16: Railcar # | D16: BOL Mass (MT) | E16: BOL Mass (kg)
A17: 46133 | B17: =HYPERLINK("https://drive.google.com/file/d/1M3O92rYavJukD4YRUM7PM8r7stXMl3XK/view","2353-R") -> 2353-R | C17: GPRX5188 | D17: 25.74 | E17: 25740
A18: 46141 | B18: =HYPERLINK("https://drive.google.com/file/d/1UsKW1xTYqeqwEtLGGNVNgmcugHd387R-/view","2354-R") -> 2354-R | C18: GPRX5188 | D18: 26.05 | E18: 26050
A19: 46141 | B19: =HYPERLINK("https://drive.google.com/file/d/1zRgT3mpEADUDO3pftEpfLNHJojDEiLaB/view","2355-R") -> 2355-R | C19: GPRX5188 | D19: 25.73 | E19: 25730
A21: 46149 | B21: =HYPERLINK("https://drive.google.com/file/d/1Um9E1NQews5Inm6ysaq30SFsT9zXFmz1/view","2362-R") -> 2362-R | C21: TIMX201060 | D21: 26.1 | E21: 26100
A22: 46149 | B22: =HYPERLINK("https://drive.google.com/file/d/1j7xFwzfyVz2daf4v_MtvZEPE3DLorOUN/view","2363-R") -> 2363-R | C22: TIMX201060 | D22: 25.86 | E22: 25860
A23: 46149 | B23: =HYPERLINK("https://drive.google.com/file/d/1UobR4PRCtoomUGWDxv9YTZ3m6UwiT9vN/view","2364-R") -> 2364-R | C23: TIMX201060 | D23: 26.1 | E23: 26100
A26: SECTION 3 - SCALE TICKTS + OFFLOAD WEIGHTS
D27: Full Scale Ticket (lb) | E27: Empty Scale Ticket (lb) | F27: Net Scaled Mass (kg) | G27: pH | H27: Sparging Loss (kg) | I27: Filtration Loss (kg) | J27: Uncertainty Adjustment (kg) | K27: MOBI (kg) | L27: AECN→SOPOR (mi, allocated ×3) | M27: Rail (mi, allocated) | N27: Opel→Basco (mi, full ×2)
A28: 46169 | B28: Rail_GPRX5188_5.1.2026_offload_1 | C28: GPRX5188 | D28: 81140 | E28: 29780 | F28: =(D28-E28)*O4 -> 23296.485 | G28: 2.99 | H28: =IF(F28="","",(F28-J28)*$O$5) -> 300.52466 | I28: =IF(F28="","",(F28-J28)*(1-$O$5)*$O$7) -> 45.072083 | J28: {=IF(F28="","",IF(ROW()=MAX(IF($C$28:$C$41=C28,ROW($C$28:$C$41),0)),MAX(0,IFERROR(VLOOKUP(C28,$A$10:$L$14,6,FALSE)-VLOOKUP(C28,$A$10:$L$14,5,FALSE),0)),0))} -> 0 | K28: =IF(F28="","",F28-H28-I28-J28) -> 22950.888 | L28: =IF(F28="","",(F28-J28)/VLOOKUP(C28,$A$10:$L$14,5,FALSE)*VLOOKUP(C28,$A$10:$L$14,10,FALSE)*$O$8) -> 96.918427 | M28: =IF(F28="","",(F28-J28)/VLOOKUP(C28,$A$10:$L$14,5,FALSE)*VLOOKUP(C28,$A$10:$L$14,11,FALSE)) -> 660.84844 | N28: =IF(F28="","",IFERROR(VLOOKUP(C28,$A$10:$L$14,12,FALSE),0)*$O$9) -> 85.8
A29: 46167 | B29: Rail_GPRX5188_5.1.2026_offload_2 | C29: GPRX5188 | D29: 80500 | E29: 29560 | F29: =(D29-E29)*O4 -> 23105.976 | G29: 2.99 | H29: =IF(F29="","",(F29-J29)*$O$5) -> 298.0671 | I29: =IF(F29="","",(F29-J29)*(1-$O$5)*$O$7) -> 44.703502 | J29: 0 | K29: =IF(F29="","",F29-H29-I29-J29) -> 22763.206 | L29: =IF(F29="","",(F29-J29)/VLOOKUP(C29,$A$10:$L$14,5,FALSE)*VLOOKUP(C29,$A$10:$L$14,10,FALSE)*$O$8) -> 96.12587 | M29: =IF(F29="","",(F29-J29)/VLOOKUP(C29,$A$10:$L$14,5,FALSE)*VLOOKUP(C29,$A$10:$L$14,11,FALSE)) -> 655.4443 | N29: =IF(F29="","",IFERROR(VLOOKUP(C29,$A$10:$L$14,12,FALSE),0)*$O$9) -> 85.8
A30: 46167 | B30: Rail_GPRX5188_5.1.2026_offload_3 | C30: GPRX5188 | D30: 80320 | E30: 29767 | F30: =(D30-E30)*O4 -> 22930.436 | G30: 2.99 | H30: =IF(F30="","",(F30-J30)*$O$5) -> 295.80263 | I30: =IF(F30="","",(F30-J30)*(1-$O$5)*$O$7) -> 44.363882 | J30: 0 | K30: =IF(F30="","",F30-H30-I30-J30) -> 22590.27 | L30: =IF(F30="","",(F30-J30)/VLOOKUP(C30,$A$10:$L$14,5,FALSE)*VLOOKUP(C30,$A$10:$L$14,10,FALSE)*$O$8) -> 95.395585 | M30: =IF(F30="","",(F30-J30)/VLOOKUP(C30,$A$10:$L$14,5,FALSE)*VLOOKUP(C30,$A$10:$L$14,11,FALSE)) -> 650.46478 | N30: =IF(F30="","",IFERROR(VLOOKUP(C30,$A$10:$L$14,12,FALSE),0)*$O$9) -> 85.8
A31: 46167 | B31: Rail_GPRX5188_5.1.2026_offload_4 | C31: GPRX5188 | D31: 47700 | E31: 29460 | F31: =(D31-E31)*$O$4 -> 8273.5181 | G31: 2.99 | H31: =IF(F31="","",(F31-J31)*$O$5) -> 105.61362 | I31: =IF(F31="","",(F31-J31)*(1-$O$5)*$O$7) -> 15.839717 | J31: =F10-E10 -> 86.416056 | K31: =IF(F31="","",F31-H31-I31-J31) -> 8065.6487 | L31: =IF(F31="","",(F31-J31)/VLOOKUP(C31,$A$10:$L$14,5,FALSE)*VLOOKUP(C31,$A$10:$L$14,10,FALSE)*$O$8) -> 34.060119 | M31: =IF(F31="","",(F31-J31)/VLOOKUP(C31,$A$10:$L$14,5,FALSE)*VLOOKUP(C31,$A$10:$L$14,11,FALSE)) -> 232.24248 | N31: =IF(F31="","",IFERROR(VLOOKUP(C31,$A$10:$L$14,12,FALSE),0)*$O$9) -> 85.8
A32: 46172 | B32: Rail_TIMX201060_5.7.2026_offload_1 | C32: TIMX201060 | D32: 79780 | E32: 29540 | F32: 22788.481 | G32: 2.99 | H32: 293.9714 | I32: 44.665422 | J32: 0 | K32: 22449.844 | L32: =IF(F32="","",(F32-J32)/VLOOKUP(C32,$A$10:$L$14,5,FALSE)*VLOOKUP(C32,$A$10:$L$14,10,FALSE)*$O$8) -> 94.14918 | M32: =IF(F32="","",(F32-J32)/VLOOKUP(C32,$A$10:$L$14,5,FALSE)*VLOOKUP(C32,$A$10:$L$14,11,FALSE)) -> 641.96604 | N32: =IF(F32="","",IFERROR(VLOOKUP(C32,$A$10:$L$14,12,FALSE),0)*$O$9) -> 85.8
A33: 46172 | B33: Rail_TIMX201060_5.7.2026_offload_2 | C33: TIMX201060 | D33: 81120 | E33: 29500 | F33: 23414.438 | G33: 2.99 | H33: 302.04625 | I33: 45.892299 | J33: 0 | K33: 23066.5 | L33: =IF(F33="","",(F33-J33)/VLOOKUP(C33,$A$10:$L$14,5,FALSE)*VLOOKUP(C33,$A$10:$L$14,10,FALSE)*$O$8) -> 96.735284 | M33: =IF(F33="","",(F33-J33)/VLOOKUP(C33,$A$10:$L$14,5,FALSE)*VLOOKUP(C33,$A$10:$L$14,11,FALSE)) -> 659.59966 | N33: =IF(F33="","",IFERROR(VLOOKUP(C33,$A$10:$L$14,12,FALSE),0)*$O$9) -> 85.8
A34: 46172 | B34: Rail_TIMX201060_5.7.2026_offload_3 | C34: TIMX201060 | D34: 79100 | E34: 29380 | F34: 22552.613 | G34: 2.99 | H34: 290.9287 | I34: 44.203121 | J34: 0 | K34: 22217.481 | L34: =IF(F34="","",(F34-J34)/VLOOKUP(C34,$A$10:$L$14,5,FALSE)*VLOOKUP(C34,$A$10:$L$14,10,FALSE)*$O$8) -> 93.174706 | M34: =IF(F34="","",(F34-J34)/VLOOKUP(C34,$A$10:$L$14,5,FALSE)*VLOOKUP(C34,$A$10:$L$14,11,FALSE)) -> 635.32149 | N34: =IF(F34="","",IFERROR(VLOOKUP(C34,$A$10:$L$14,12,FALSE),0)*$O$9) -> 85.8
L35: =IF(F35="","",(F35-J35)/VLOOKUP(C35,$A$10:$L$14,5,FALSE)*VLOOKUP(C35,$A$10:$L$14,10,FALSE)*$O$8) | M35: =IF(F35="","",(F35-J35)/VLOOKUP(C35,$A$10:$L$14,5,FALSE)*VLOOKUP(C35,$A$10:$L$14,11,FALSE)) | N35: =IF(F35="","",IFERROR(VLOOKUP(C35,$A$10:$L$14,12,FALSE),0)*$O$9)
L36: =SUM(L27:L34) -> 606.55917 | M36: =SUM(M27:M34) -> 4135.8872 | N36: =SUM(N27:N34) -> 600.6
L37: =IF(F37="","",(F37-J37)/VLOOKUP(C37,$A$10:$L$14,5,FALSE)*VLOOKUP(C37,$A$10:$L$14,10,FALSE)*$O$8) | M37: =IF(F37="","",(F37-J37)/VLOOKUP(C37,$A$10:$L$14,5,FALSE)*VLOOKUP(C37,$A$10:$L$14,11,FALSE)) | N37: =IF(F37="","",IFERROR(VLOOKUP(C37,$A$10:$L$14,12,FALSE),0)*$O$9)
L38: =IF(F38="","",(F38-J38)/VLOOKUP(C38,$A$10:$L$14,5,FALSE)*VLOOKUP(C38,$A$10:$L$14,10,FALSE)*$O$8) | M38: =IF(F38="","",(F38-J38)/VLOOKUP(C38,$A$10:$L$14,5,FALSE)*VLOOKUP(C38,$A$10:$L$14,11,FALSE)) | N38: =IF(F38="","",IFERROR(VLOOKUP(C38,$A$10:$L$14,12,FALSE),0)*$O$9)
L39: =IF(F39="","",(F39-J39)/VLOOKUP(C39,$A$10:$L$14,5,FALSE)*VLOOKUP(C39,$A$10:$L$14,10,FALSE)*$O$8) | M39: =IF(F39="","",(F39-J39)/VLOOKUP(C39,$A$10:$L$14,5,FALSE)*VLOOKUP(C39,$A$10:$L$14,11,FALSE)) | N39: =IF(F39="","",IFERROR(VLOOKUP(C39,$A$10:$L$14,12,FALSE),0)*$O$9)
L40: =IF(F40="","",(F40-J40)/VLOOKUP(C40,$A$10:$L$14,5,FALSE)*VLOOKUP(C40,$A$10:$L$14,10,FALSE)*$O$8) | M40: =IF(F40="","",(F40-J40)/VLOOKUP(C40,$A$10:$L$14,5,FALSE)*VLOOKUP(C40,$A$10:$L$14,11,FALSE)) | N40: =IF(F40="","",IFERROR(VLOOKUP(C40,$A$10:$L$14,12,FALSE),0)*$O$9)
A42: SECTION 4 - ROLLUP (Mass Used = Σ Deliveries – Uncertainty Adj)
A43: Σ Deliveries raw (kg) | B43: Σ Uncertainty Adj (kg) | C43: Mass Used (post-adj) (kg) | D43: Sparging Loss (kg) | E43: Filtration Loss (kg) | F43: MOBI (kg) | G43: pH | H43: C Content | M43: Origins list (BOLs)
A44: =SUM(F28:F40) -> 146361.95 | B44: =SUM(J28:J40) -> 86.416056 | C44: =A44-B44 -> 146275.53 | D44: =SUM(H28:H40) -> 1886.9544 | E44: =SUM(I28:I40) -> 284.74003 | F44: =SUM(K28:K40) -> 144103.84 | G44: =IFERROR(AVERAGE(G28:G40),"") -> 2.99 | H44: =IFERROR(SUMPRODUCT(K28:K40,O28:O40)/SUM(K28:K40),"") -> 0 | M44: =IFERROR(__xludf.DUMMYFUNCTION("TRIM(TEXTJOIN("", "",TRUE,IFERROR(FILTER(B17:B25,B17:B25<>""""),"""")))"),"2353-R, 2354-R, 2355-R, 2362-R, 2363-R, 2364-R") -> 2353-R, 2354-R, 2355-R, 2362-R, 2363-R, 2364-R

Sheet AECN Truck
A1: BATCH HEADER — AECN Truck (Direct from Fort Lupton)
A2: Batch ID (INJ-YYYY-WXX) | B2: INJ-05-2026-W4 | K2: Constants
A3: Week Start (Sat) | B3: 46165 | K3: Lbs/Kg | L3: 2.20462
A4: Week End (Sat) | B4: 46172 | K4: Kg/Lbs | L4: 0.453592
K5: Sparging Mass Loss | L5: 0.0129
K6: pH range (target) | L6: 2.0 - 4.0
K7: Filtration Solids Content | L7: 0.00196
A8: SECTION 1 - DELIVERIES LEDGER (one row per direct truck; BOL & scale ticket on same row)
A9: Date | B9: BOL # / SO # | C9: BOL Mass (MT) | D9: BOL Mass (kg) | E9: Scale Full (lb) | F9: Scale Empty (lb) | G9: Cargo (kg) | H9: pH | I9: Notes | J9: Sparging Loss (kg) | K9: Filtration Loss (kg) | L9: MOBI (kg) | M9: C Content
D10: =IF(C10="","",C10*1000) | G10: =IF(AND(E10<>"",F10<>""),(E10-F10)*$L$4,"") | J10: =IF(D10="","",D10*$L$5) | K10: =IF(D10="","",(D10-J10)*$L$7) | L10: =IF(D10="","",D10-J10-K10)
D11: =IF(C11="","",C11*1000) | G11: =IF(AND(E11<>"",F11<>""),(E11-F11)*$L$4,"") | J11: =IF(D11="","",D11*$L$5) | K11: =IF(D11="","",(D11-J11)*$L$7) | L11: =IF(D11="","",D11-J11-K11)
D12: =IF(C12="","",C12*1000) | G12: =IF(AND(E12<>"",F12<>""),(E12-F12)*$L$4,"") | J12: =IF(D12="","",D12*$L$5) | K12: =IF(D12="","",(D12-J12)*$L$7) | L12: =IF(D12="","",D12-J12-K12)
D13: =IF(C13="","",C13*1000) | G13: =IF(AND(E13<>"",F13<>""),(E13-F13)*$L$4,"") | J13: =IF(D13="","",D13*$L$5) | K13: =IF(D13="","",(D13-J13)*$L$7) | L13: =IF(D13="","",D13-J13-K13)
D14: =IF(C14="","",C14*1000) | G14: =IF(AND(E14<>"",F14<>""),(E14-F14)*$L$4,"") | J14: =IF(D14="","",D14*$L$5) | K14: =IF(D14="","",(D14-J14)*$L$7) | L14: =IF(D14="","",D14-J14-K14)
D15: =IF(C15="","",C15*1000) | G15: =IF(AND(E15<>"",F15<>""),(E15-F15)*$L$4,"") | J15: =IF(D15="","",D15*$L$5) | K15: =IF(D15="","",(D15-J15)*$L$7) | L15: =IF(D15="","",D15-J15-K15)
D16: =IF(C16="","",C16*1000) | G16: =IF(AND(E16<>"",F16<>""),(E16-F16)*$L$4,"") | J16: =IF(D16="","",D16*$L$5) | K16: =IF(D16="","",(D16-J16)*$L$7) | L16: =IF(D16="","",D16-J16-K16)
D17: =IF(C17="","",C17*1000) | G17: =IF(AND(E17<>"",F17<>""),(E17-F17)*$L$4,"") | J17: =IF(D17="","",D17*$L$5) | K17: =IF(D17="","",(D17-J17)*$L$7) | L17: =IF(D17="","",D17-J17-K17)
D18: =IF(C18="","",C18*1000) | G18: =IF(AND(E18<>"",F18<>""),(E18-F18)*$L$4,"") | J18: =IF(D18="","",D18*$L$5) | K18: =IF(D18="","",(D18-J18)*$L$7) | L18: =IF(D18="","",D18-J18-K18)
D19: =IF(C19="","",C19*1000) | G19: =IF(AND(E19<>"",F19<>""),(E19-F19)*$L$4,"") | J19: =IF(D19="","",D19*$L$5) | K19: =IF(D19="","",(D19-J19)*$L$7) | L19: =IF(D19="","",D19-J19-K19)
D20: =IF(C20="","",C20*1000) | G20: =IF(AND(E20<>"",F20<>""),(E20-F20)*$L$4,"") | J20: =IF(D20="","",D20*$L$5) | K20: =IF(D20="","",(D20-J20)*$L$7) | L20: =IF(D20="","",D20-J20-K20)
D21: =IF(C21="","",C21*1000) | G21: =IF(AND(E21<>"",F21<>""),(E21-F21)*$L$4,"") | J21: =IF(D21="","",D21*$L$5) | K21: =IF(D21="","",(D21-J21)*$L$7) | L21: =IF(D21="","",D21-J21-K21)
... D24: =IF(C24="","",C24*1000) | G24: =IF(AND(E24<>"",F24<>""),(E24-F24)*$L$4,"") | J24: =IF(D24="","",D24*$L$5) | K24: =IF(D24="","",(D24-J24)*$L$7) | L24: =IF(D24="","",D24-J24-K24)
A26: SECTION 2 - ROLLUP (Mass Used = Σ BOL kg; scale tickets no longer required for direct trucks per 2026-05-26)
A27: Σ BOL (kg) | B27: Σ Cargo (kg) | C27: Mass Used (kg) | D27: Sparging Loss (kg) | E27: Filtration Loss (kg) | F27: Uncertainty Adjustment (kg) | G27: MOBI (kg) | H27: pH | I27: C Content (MOBI-wtd) | K27: Origins list (BOLs)
A28: =SUMIFS(D10:D24,B10:B24,"<>") -> 0 | B28: =SUMIFS(G10:G24,B10:B24,"<>") -> 0 | C28: =A28 -> 0 | D28: =C28*$L$5 -> 0 | E28: =(C28-D28)*$L$7 -> 0 | F28: 0 | G28: =C28-D28-E28-F28 -> 0 | H28: =IFERROR(AVERAGE(H10:H24),"") | I28: =IFERROR(SUMPRODUCT(L10:L24,M10:M24)/SUM(L10:L24),"") | K28: =IFERROR(__xludf.DUMMYFUNCTION("TRIM(TEXTJOIN("", "",TRUE,IFERROR(FILTER(B10:B24,B10:B24<>""""),"""")))"),"")

Sheet WODO
A1: BATCH HEADER — Charm WODO (IBC Totes)
A2: Batch ID (INJ-YYYY-WXX) | B2: INJ-05-2026-W4 | K2: Constants
A3: Week Start (Sat) | B3: 46165 | K3: Lbs/Kg | L3: 2.20462
A4: Week End (Sat) | B4: 46172 | K4: Kg/Lbs | L4: 0.453592
K5: Sparging Mass Loss | L5: 0.0129
K6: pH range (target) | L6: 2.0 - 4.0
A8: SECTION 1 - IBC LEDGER (one row per IBC tote; tote tag mass is authoritative)
A9: Date | B9: Tote Tag # | C9: Tote Full (lb) | D9: Tote Empty (lb) | E9: Gross Mass (kg) — transport | F9: Net Oil (kg) — production | G9: Net Injected (kg) — MOBI | H9: pH | I9: Notes
A31: SECTION 2 - ROLLUP
A32: Σ Net Injected (kg) | B32: Sparging Loss (kg) | C32: MOBI (kg) | D32: pH | G32: Origins list (Tote tags)
A33: =SUMIFS(G10:G29,B10:B29,"<>") -> 0 | B33: =A33*$L$5 -> 0 | C33: =A33-B33 -> 0 | D33: =IFERROR(AVERAGE(H10:H29),"") | G33: =IFERROR(__xludf.DUMMYFUNCTION("TRIM(TEXTJOIN("", "",TRUE,IFERROR(FILTER(B10:B29,B10:B29<>""""),"""")))"),"")

Sheet Kerry
A1: BATCH HEADER — Kerry (Calciner Waste Oil, IBC Totes)
A2: Batch ID (INJ-YYYY-WXX) | B2: INJ-05-2026-W4 | L2: Constants
A3: Week Start (Sat) | B3: 46165 | L3: Lbs/Kg | M3: 2.20462
A4: Week End (Sat) | B4: 46172 | L4: Kg/Lbs | M4: 0.453592
L5: Sparging Mass Loss | M5: 0.0129
L6: pH range (target) | M6: 2.0 - 4.0
L7: Testing Uncertainty | M7: 0.004
A8: SECTION 1 - IBC LEDGER (one row per Kerry tote; tote tag mass is authoritative)
A9: Date | B9: Tote Tag # | C9: Gross Mass (kg) — transport | D9: Tote Empty (kg) | E9: Net Oil (kg) — production | F9: Net Injected (kg) — MOBI | G9: pH | H9: Notes | I9: C Content | J9: C Content Uncertainty | K9: Mass Uncertainty (Scaling)
A31: SECTION 2 - ROLLUP
A32: Σ Net Injected (kg) | B32: Sparging Loss (kg) | C32: MOBI (kg) | D32: pH | E32: C Content (MOBI-wtd) | G32: Origins list (Tote tags)
A33: =SUMIFS(F10:F29,B10:B29,"<>") -> 0 | B33: =A33*$M$5 -> 0 | C33: =A33-B33 -> 0 | D33: =IFERROR(AVERAGE(G10:G29),"") | E33: =IFERROR(__xludf.DUMMYFUNCTION("IFERROR(AVERAGE.WEIGHTED(I10:I29,F10:F29),"""")"),"") | G33: =IFERROR(__xludf.DUMMYFUNCTION("TRIM(TEXTJOIN("", "",TRUE,IFERROR(FILTER(B10:B29,B10:B29<>""""),"""")))"),"")

Sheet QOWV
A1: BATCH HEADER — QOWV (Aqueous Bio-Oil, IBC Totes)
A2: Batch ID (INJ-YYYY-WXX) | B2: INJ-05-2026-W4 | K2: Constants
A3: Week Start (Sat) | B3: 46165 | K3: Lbs/Kg | L3: 2.20462
A4: Week End (Sat) | B4: 46172 | K4: Kg/Lbs | L4: 0.453592
K5: Sparging Mass Loss | L5: 0.0129
K6: pH range (target) | L6: 2.0 - 4.0
A8: SECTION 1 - IBC LEDGER (one row per QOWV tote; tote tag mass is authoritative)
B9: Transport Emissions | D9: Pyrolysis Emissions Mass | F9: MOBI
A10: Tag | B10: Gross Mass (kg) | C10: Tote Mass (kg) | D10: Net Oil Produced (kg) | E10: Empty Tote Weight (kg) | F10: Net Oil Injected (kg) | G10: Production Period | H10: Carbon Intensity | I10: Production Emissions | J10: Scale Uncertainty
A11: 120591 | B11: 993 | C11: 57.6 | D11: =B11-C11 -> 935.4 | E11: 228.1 | F11: =B11-E11 -> 764.9 | G11: MFO Lot 2812 (LOT00002812), PP#8 | H11: 0.15755534 | I11: =H11*D11 -> 147.37726 | J11: =2.5*$L$4 -> 1.13398
A12: 120548 | B12: 1024 | C12: 57.6 | D12: 901.4 | E12: 122.6 | F12: =B12-E12 -> 901.4 | G12: MFO Lot 2816 (LOT00002816), PP#8 | H12: 0.15755534 | I12: =H12*D12 -> 142.02038 | J12: =2.5*$L$4 -> 1.13398
A13: 120568 | B13: 1056 | C13: 57.6 | D13: =B13-C13 -> 998.4 | E13: 576.1 | F13: =B13-E13 -> 479.9 | G13: MFO Lot 2818 (LOT00002818), PP#8 | H13: 0.15755534 | I13: =H13*D13 -> 157.30325 | J13: =2.5*$L$4 -> 1.13398
A14: 120564 | B14: 1014 | C14: 57.6 | D14: =B14-C14 -> 956.4 | E14: 214.6 | F14: =B14-E14 -> 799.4 | G14: MFO Lot 2820 (LOT00002820), PP#8 | H14: 0.15755534 | I14: =H14*D14 -> 150.68593 | J14: =2.5*$L$4 -> 1.13398
A15: 120528 | B15: 1082 | C15: 57.6 | D15: =B15-C15 -> 1024.4 | E15: 294.1 | F15: =B15-E15 -> 787.9 | G15: MFO Lot 2910 (LOT00002910), PP#8 | H15: 0.15755534 | I15: =H15*D15 -> 161.39969 | J15: =2.5*$L$4 -> 1.13398
A16: 120531 | B16: 1015 | C16: 57.6 | D16: =B16-C16 -> 957.4 | E16: 149.6 | F16: =B16-E16 -> 865.4 | G16: MFO Lot 2980 (LOT00002980), PP#8 | H16: 0.15755534 | I16: =H16*D16 -> 150.84348 | J16: =2.5*$L$4 -> 1.13398
A17: 120513 | B17: 942 | C17: 57.6 | D17: =B17-C17 -> 884.4 | E17: 230.1 | F17: =B17-E17 -> 711.9 | G17: MFO Lot 2982 (LOT00002982), PP#8 | H17: 0.15755534 | I17: =H17*D17 -> 139.34194 | J17: =2.5*$L$4 -> 1.13398
A18: 120576 | B18: 1010 | C18: 57.6 | D18: =B18-C18 -> 952.4 | E18: 181.6 | F18: =B18-E18 -> 828.4 | G18: MFO Lot 2984 (LOT00002984), PP#8 | H18: 0.15755534 | I18: =H18*D18 -> 150.05571 | J18: =2.5*$L$4 -> 1.13398
A19: 120517 | B19: 977 | C19: 57.6 | D19: =B19-C19 -> 919.4 | E19: 219.1 | F19: =B19-E19 -> 757.9 | G19: MFO Lot 2988 (LOT00002988), PP#8 | H19: 0.15755534 | I19: =H19*D19 -> 144.85638 | J19: =2.5*$L$4 -> 1.13398
A20: 120558 | B20: 993 | C20: 57.6 | D20: =B20-C20 -> 935.4 | E20: 122.6 | F20: =B20-E20 -> 870.4 | G20: MFO Lot 3032 (LOT00003032), PP#8 | H20: 0.15755534 | I20: =H20*D20 -> 147.37726 | J20: =2.5*$L$4 -> 1.13398
A21: 120515 | B21: 1088 | C21: 57.6 | D21: =B21-C21 -> 1030.4 | E21: 257.6 | F21: =B21-E21 -> 830.4 | G21: MFO Lot 3034 (LOT00003034), PP#8 | H21: 0.15755534 | I21: =H21*D21 -> 162.34502 | J21: =2.5*$L$4 -> 1.13398
A22: 120544 | B22: 1053 | C22: 57.6 | D22: =B22-C22 -> 995.4 | E22: 172.6 | F22: =B22-E22 -> 880.4 | G22: MFO Lot 3036 (LOT00003036), PP#8 | H22: 0.15755534 | I22: =H22*D22 -> 156.83058 | J22: =2.5*$L$4 -> 1.13398
A23: 120573 | B23: 1015 | C23: 57.6 | D23: =B23-C23 -> 957.4 | E23: 200.1 | F23: =B23-E23 -> 814.9 | G23: MFO Lot 3044 (LOT00003044), PP#8 | H23: 0.15755534 | I23: =H23*D23 -> 150.84348 | J23: =2.5*$L$4 -> 1.13398
A24: 120561 | B24: 1055 | C24: 57.6 | D24: =B24-C24 -> 997.4 | E24: 146.1 | F24: =B24-E24 -> 908.9 | G24: MFO Lot 3048 (LOT00003048), PP#8 | H24: 0.15755534 | I24: =H24*D24 -> 157.1457 | J24: =2.5*$L$4 -> 1.13398
... A51: 228403 | B51: 1062 | C51: 57.6 | D51: =B51-C51 -> 1004.4 | E51: 214.1 | F51: =B51-E51 -> 847.9 | G51: MFO Lot 4138 (LOT00004138), October 2025 | H51: 0.11101762 | I51: =H51*D51 -> 111.5061 | J51: =2.5*$L$4 -> 1.13398
G52: =IF(AND(D52<>"",F52<>""),(D52-F52)*$L$4,"") | H52: =IF(G52="","",G52*(1-$L$5))
B53: =SUM(B10:B51) -> 42084 | D53: =SUM(D10:D51) -> 39657.4 | F53: =SUM(F9:F51) -> 33977 | H53: =SUMPRODUCT(D11:D51,H11:H51)/SUM(D11:D51) -> 0.13052042 | I53: =sum(I11:I51) -> 5176.1004 | J53: =SUM(J9:J51) -> 46.49318
G54: =IF(AND(D54<>"",F54<>""),(D54-F54)*$L$4,"") | H54: =IF(G54="","",G54*(1-$L$5))
G55: =IF(AND(D55<>"",F55<>""),(D55-F55)*$L$4,"") | H55: =IF(G55="","",G55*(1-$L$5))
G56: =IF(AND(D56<>"",F56<>""),(D56-F56)*$L$4,"") | H56: =IF(G56="","",G56*(1-$L$5))
G57: =IF(AND(D57<>"",F57<>""),(D57-F57)*$L$4,"") | H57: =IF(G57="","",G57*(1-$L$5))
G58: =IF(AND(D58<>"",F58<>""),(D58-F58)*$L$4,"") | H58: =IF(G58="","",G58*(1-$L$5))
G59: =IF(AND(D59<>"",F59<>""),(D59-F59)*$L$4,"") | H59: =IF(G59="","",G59*(1-$L$5))
G60: =IF(AND(D60<>"",F60<>""),(D60-F60)*$L$4,"") | H60: =IF(G60="","",G60*(1-$L$5))
G61: =IF(AND(D61<>"",F61<>""),(D61-F61)*$L$4,"") | H61: =IF(G61="","",G61*(1-$L$5))
G62: =IF(AND(D62<>"",F62<>""),(D62-F62)*$L$4,"") | H62: =IF(G62="","",G62*(1-$L$5))
G63: =IF(AND(D63<>"",F63<>""),(D63-F63)*$L$4,"") | H63: =IF(G63="","",G63*(1-$L$5))
G64: =IF(AND(D64<>"",F64<>""),(D64-F64)*$L$4,"") | H64: =IF(G64="","",G64*(1-$L$5))
G65: =IF(AND(D65<>"",F65<>""),(D65-F65)*$L$4,"") | H65: =IF(G65="","",G65*(1-$L$5))
... G73: =IF(AND(D73<>"",F73<>""),(D73-F73)*$L$4,"") | H73: =IF(G73="","",G73*(1-$L$5))

Sheet QOWV Shipments & EE Allocation
A1: INJ-05-2026-W4 — QOWV Shipments & EE Mileage Allocation
A4: BATCH SUMMARY
A5: Batch | B5: Fraction | C5: Inj. Week | D5: # Totes | E5: Ship Date(s)
A6: INJ-05-2026-W4 | B6: QOWV | C6: 2026-05-23 to 2026-05-30 | D6: 41 | E6: 2025-12-05 (10), 2025-12-09 (17), 2025-12-10 (14)
A8: Charm CO -> Basco LA distance (one-way miles): | B8: 1201
A10: EE ALLOCATION TABLE
A11: Truck (shipment) | B11: Ship Date | C11: Total Totes on Truck | D11: Batch-Relevant Totes | E11: Batch Share of Truck | F11: Mileage (one-way) | G11: Allocated Miles
A12: Shipment 12-05 | B12: 45996 | C12: 36 | D12: 10 | E12: =D12/C12 -> 0.27777778 | F12: =$B$8 -> 1201 | G12: =E12*F12 -> 333.61111
A13: Shipment 12-09 | B13: 46000 | C13: 36 | D13: 17 | E13: =D13/C13 -> 0.47222222 | F13: =$B$8 -> 1201 | G13: =E13*F13 -> 567.13889
A14: Shipment 12-10 | B14: 46001 | C14: 35 | D14: 14 | E14: =D14/C14 -> 0.4 | F14: =$B$8 -> 1201 | G14: =E14*F14 -> 480.4
A15: TOTAL | C15: =SUM(C12:C14) -> 107 | D15: =SUM(D12:D14) -> 41 | G15: =SUM(G12:G14) -> 1381.15
A17: BATCH MILEAGE ALLOCATION
A18: Batch | B18: Per-Truck Allocation (relevant/total) | C18: Allocated Miles | D18: # Totes
A19: INJ-05-2026-W4 | B19: 12-05 (10/36), 12-09 (17/36), 12-10 (14/35) | C19: =G15 -> 1381.15 | D19: =D15 -> 41
A21: --- Shipment 2025-12-05 --- (10 of 36 totes on this truck are W4-relevant)
A22: Metal Tag | B22: Fraction | C22: Production Period | D22: Date Loaded | E22: Batch
A23: 15186 | B23: QOWV | C23: August 2025 | D23: 45996 | E23: INJ-05-2026-W4
A24: 245123 | B24: QOWV | C24: August 2025 | D24: 45996 | E24: INJ-05-2026-W4
A25: 245122 | B25: QOWV | C25: August 2025 | D25: 45996 | E25: INJ-05-2026-W4
A26: 245151 | B26: QOWV | C26: August 2025 | D26: 45996 | E26: INJ-05-2026-W4
A27: 245181 | B27: QOWV | C27: August 2025 | D27: 45996 | E27: INJ-05-2026-W4
A28: 245155 | B28: QOWV | C28: August 2025 | D28: 45996 | E28: INJ-05-2026-W4
A29: 245162 | B29: QOWV | C29: August 2025 | D29: 45996 | E29: INJ-05-2026-W4
A30: 245170 | B30: QOWV | C30: August 2025 | D30: 45996 | E30: INJ-05-2026-W4
A31: 245159 | B31: QOWV | C31: August 2025 | D31: 45996 | E31: INJ-05-2026-W4
A32: 245146 | B32: QOWV | C32: August 2025 | D32: 45996 | E32: INJ-05-2026-W4
A35: --- Shipment 2025-12-09 --- (17 of 36 totes on this truck are W4-relevant)
A36: Metal Tag | B36: Fraction | C36: Production Period | D36: Date Loaded | E36: Batch
A37: 120591 | B37: QOWV | C37: PP#8 | D37: 46000 | E37: INJ-05-2026-W4
A38: 120548 | B38: QOWV | C38: PP#8 | D38: 46000 | E38: INJ-05-2026-W4
A39: 120568 | B39: QOWV | C39: PP#8 | D39: 46000 | E39: INJ-05-2026-W4
A40: 120564 | B40: QOWV | C40: PP#8 | D40: 46000 | E40: INJ-05-2026-W4
A41: 120528 | B41: QOWV | C41: PP#8 | D41: 46000 | E41: INJ-05-2026-W4
A42: 120531 | B42: QOWV | C42: PP#8 | D42: 46000 | E42: INJ-05-2026-W4
A43: 120513 | B43: QOWV | C43: PP#8 | D43: 46000 | E43: INJ-05-2026-W4
A44: 120576 | B44: QOWV | C44: PP#8 | D44: 46000 | E44: INJ-05-2026-W4
A45: 120517 | B45: QOWV | C45: PP#8 | D45: 46000 | E45: INJ-05-2026-W4
A46: 120558 | B46: QOWV | C46: PP#8 | D46: 46000 | E46: INJ-05-2026-W4
A47: 120515 | B47: QOWV | C47: PP#8 | D47: 46000 | E47: INJ-05-2026-W4
A48: 120544 | B48: QOWV | C48: PP#8 | D48: 46000 | E48: INJ-05-2026-W4
...
