Workbook

Sheet Summary
A1: BATCH SUMMARY
A2: Batch ID | B2: INJ-06-2026-W1
A3: Week Start (Sat) | B3: 46172
A4: Week End (Sat) | B4: 46179
A6: SECTION 1 - PER-TAB SUMMARY (each row pulls from its mode tab)
A7: Source Tab | B7: Σ Deliveries / Cargo (kg) | C7: Σ Uncertainty Adj (kg) | D7: Mass Used (kg) | E7: Sparging Loss (kg) | F7: Filtration Loss (kg) | G7: MOBI (kg) | H7: AECN→SOPOR EE (mi) | I7: Rail EE (mi) | J7: Opel→Basco EE (mi)
A8: AECN Rail | B8: ='AECN Rail'!A44 -> 167965.12 | C8: ='AECN Rail'!B44 -> 2160.593 | D8: ='AECN Rail'!C44 -> 165804.52 | E8: ='AECN Rail'!D44 -> 2138.8784 | F8: ='AECN Rail'!E44 -> 319.14801 | G8: ='AECN Rail'!F44 -> 163346.5 | H8: =SUM('AECN Rail'!L28:L36) -> 683.44106 | I8: =SUM('AECN Rail'!M28:M36) -> 4660.1144 | J8: =SUM('AECN Rail'!N28:N36) -> 772.2
A9: AECN Truck | B9: ='AECN Truck'!B28 -> 0 | C9: ='AECN Truck'!F28 -> 0 | D9: ='AECN Truck'!C28 -> 0 | E9: ='AECN Truck'!D28 -> 0 | F9: ='AECN Truck'!E28 -> 0 | G9: ='AECN Truck'!G28 -> 0
A10: Charm WODO | B10: =WODO!B33 -> 11181 | C10: 0 | D10: =WODO!B33 -> 11181 | E10: =WODO!C33 -> 56.307248 | F10: 0 | G10: =WODO!D33 -> 11124.693
A11: Kerry | B11: =Kerry!A33 -> 0 | C11: 0 | D11: =Kerry!A33 -> 0 | E11: =Kerry!B33 -> 0 | F11: 0 | G11: =Kerry!C33 -> 0
A12: QOWV | B12: =QOWV!B53 -> 0 | C12: 0 | D12: =QOWV!D53 -> 0 | E12: 0 | F12: 0 | G12: =QOWV!F53 -> 0
A13: TOTAL | B13: =SUM(B8:B12) -> 179146.12 | C13: =SUM(C8:C12) -> 2160.593 | D13: =SUM(D8:D12) -> 176985.52 | E13: =SUM(E8:E12) -> 2195.1856 | F13: =SUM(F8:F12) -> 319.14801 | G13: =SUM(G8:G12) -> 174471.19 | H13: =SUM(H8:H12) -> 683.44106 | I13: =SUM(I8:I12) -> 4660.1144 | J13: =SUM(J8:J12) -> 772.2
A15: SECTION 2 - PER-OIL-TYPE ROLLUP (composite C% per oil type per week)
A16: Oil Type | B16: MOBI (kg) | C16: Composite Sample ID | D16: C % | E16: Lab COA Link | F16: C Content Uncertainty | G16: Testing Uncertainty
A17: AECN | B17: =G8+G9 -> 163346.5 | C17: 6-2026-W1 AECN | D17: 0.422 | E17: https://acrobat.adobe.com/id/urn:aaid:sc:US:44c9fb3a-51a1-486f-9220-231d0ebf1554 | F17: =D17*G17 -> 0.001688 | G17: 0.004
A18: WODO | B18: =G10 -> 11124.693 | C18: 6-2026-W1 WODO | D18: 0.518 | E18: CHARM INDUSTRIAL - 6-2026-W1 WODO.pdf | F18: =D18*G18 -> 0.002072 | G18: 0.004
A19: Kerry | B19: =G11 -> 0
A20: QOWV | B20: =G12 -> 0
A21: TOTAL | B21: =SUM(B17:B20) -> 174471.19

Sheet AECN Rail
A1: BATCH HEADER — AECN Rail
A2: Batch ID (INJ-YYYY-WXX) | B2: INJ-06-2026-W1 | N2: Constants
A3: Week Start (Sat) | B3: 46172 | N3: Lbs/Kg | O3: 2.20462
A4: Week End (Sat) | B4: 46179 | N4: Kg/Lbs | O4: 0.453592
N5: Sparging Mass Loss | O5: 0.0129
N6: pH range (target) | O6: 2.0 - 4.0
N7: Filtration Solids Content | O7: =HYPERLINK("https://docs.google.com/spreadsheets/d/16shKoa1KP34kQJyQvzclBejW9L5-ubNSqPsMOVB7zDY/edit?usp=sharing", 0.00195) -> 0.00195
A8: SECTION 1 - RAILCARS RECEIVED THIS WEEK (entity-level) | N8: BOL Trips (AECN→SOPOR) | O8: 3
A9: Railcar # | B9: Arrival Date at Opelousas | C9: Loading BOLs (comma-sep) | D9: Total Loaded (MT) | E9: Total Loaded (kg) | F9: Total Offloaded (kg, auto) | G9: Loss (kg) | H9: Prior Period Mass | I9: Prior-RP Claimed (kg) | J9: AECN→SOPOR (mi) | K9: Rail (mi) | L9: Opel→Basco (mi) | M9: Notes | N9: Round Trip (Opel→Basco) | O9: 2
A10: TIMX201060 | B10: 46164 | C10: 2362-R, 2363-R, 2364-R | D10: 78.06 | E10: 78060 | F10: =SUMIF($C$28:$C$41,A10,$F$28:$F$41)+H10 -> 78099.471 | G10: =IF(AND(E10<>"",F10<>"",F10>=0.95*E10),E10-F10,"") -> -39.4706 | H10: 68755.475 | I10: =E10-H10 -> 9304.5246 | J10: 107.5 | K10: 2199 | L10: 42.9 | M10: Prior-RP claimed: 68,755.48 kg (offloads 1-3 of 5.7.2026 loading, INJ-05-2026-W4)
A11: GPRX5102 | B11: 46164 | C11: 2359-R, 2360-R, 2361-R | D11: 78.25 | E11: 78250 | F11: =SUMIF($C$28:$C$41,A11,$F$28:$F$41)+H11 -> 79922.91 | G11: =IF(AND(E11<>"",F11<>"",F11>=0.95*E11),E11-F11,"") -> -1672.9104 | H11: 0 | I11: =E11-H11 -> 78250 | J11: 107.5 | K11: 2199 | L11: 42.9
A12: TILX200231 | B12: 46164 | C12: 2368-R, 2369-R, 2370-R | D12: 78.25 | E12: 78250 | F12: =SUMIF($C$28:$C$41,A12,$F$28:$F$41)+H12 -> 78698.212 | G12: =IF(AND(E12<>"",F12<>"",F12>=0.95*E12),E12-F12,"") -> -448.212 | H12: 0 | I12: =E12-H12 -> 78250 | J12: 107.5 | K12: 2199 | L12: 42.9
G13: =IF(AND(E13<>"",F13<>"",F13>=0.95*E13),E13-F13,"")
G14: =IF(AND(E14<>"",F14<>"",F14>=0.95*E14),E14-F14,"")
A15: SECTION 2 - ORIGINS LEDGER (loading BOLs at SOPOR)
A16: Date | B16: BOL # | C16: Railcar # | D16: BOL Mass (MT) | E16: BOL Mass (kg)
A17: 46149 | B17: =HYPERLINK("https://drive.google.com/file/d/1bEBOvdGCj3-GWgTHgwcotVPLXfDi3pzz/view","2362-R") -> 2362-R | C17: TIMX201060 | D17: 26.1 | E17: 26100
A18: 46149 | B18: =HYPERLINK("https://drive.google.com/file/d/1ezSVinao2J6bkk7m9OxMY4NQ064jq3bv/view","2363-R") -> 2363-R | C18: TIMX201060 | D18: 25.86 | E18: 25860
A19: 46149 | B19: =HYPERLINK("https://drive.google.com/file/d/15yGNk9MNwTtrU_ueQe948hpN-7ia7XeW/view","2364-R") -> 2364-R | C19: TIMX201060 | D19: 26.1 | E19: 26100
A20: 46149 | B20: =HYPERLINK("https://drive.google.com/file/d/19J0RSWnhj_VSL5B-OFYEgyh4-yJnQzWB/view","2359-R") -> 2359-R | C20: GPRX5102 | D20: 26.05 | E20: 26050
A21: 46149 | B21: =HYPERLINK("https://drive.google.com/file/d/1q-3ZtSvgD7VyYZ-Qtt_M_4sGT_3P9k40/view","2360-R") -> 2360-R | C21: GPRX5102 | D21: 26.09 | E21: 26090
A22: 46149 | B22: =HYPERLINK("https://drive.google.com/file/d/1zIVICZYdFQuTKbfG1kr6xlpqc8NedLVh/view","2361-R") -> 2361-R | C22: GPRX5102 | D22: 26.11 | E22: 26110
A23: 46153 | B23: =HYPERLINK("https://drive.google.com/file/d/1xLBYmWy3_voYvnNsgyjKWZ8kPdCPHU-5/view","2368-R") -> 2368-R | C23: TILX200231 | D23: 26.16 | E23: 26160
A24: 46153 | B24: =HYPERLINK("https://drive.google.com/file/d/1VQGPK0De8SRCmCIVHagfl7eb6dO0gqc0/view","2369-R") -> 2369-R | C24: TILX200231 | D24: 26.2 | E24: 26200
A25: 46153 | B25: =HYPERLINK("https://drive.google.com/file/d/15efXqZb399_NtTjiq817mVTqXjemPe6l/view","2370-R") -> 2370-R | C25: TILX200231 | D25: 25.89 | E25: 25890
A26: SECTION 3 - SCALE TICKTS + OFFLOAD WEIGHTS
D27: Full Scale Ticket (lb) | E27: Empty Scale Ticket (lb) | F27: Net Scaled Mass (kg) | G27: pH | H27: Sparging Loss (kg) | I27: Filtration Loss (kg) | J27: Uncertainty Adjustment (kg) | K27: MOBI (kg) | L27: AECN→SOPOR (mi, allocated ×3) | M27: Rail (mi, allocated) | N27: Opel→Basco (mi, full ×2)
A28: 46178 | B28: Rail_TIMX201060_5.7.2026_offload_4 | C28: TIMX201060 | D28: =HYPERLINK("https://drive.google.com/file/d/1bwBajf7vbVhcs0WUHvsaaq-3ryFt5glt/view",53920) -> 53920 | E28: =HYPERLINK("https://drive.google.com/file/d/1b_Hlhtl4QICSYEZIh9InZMOH5LawS6ss/view",33320) -> 33320 | F28: =(D28-E28)*$O$4 -> 9343.9952 | G28: 2.1 | H28: =IF(F28="","",(F28-J28)*$O$5) -> 120.02837 | I28: =IF(F28="","",(F28-J28)*(1-$O$5)*$O$7) -> 17.909768 | J28: {=IF(F28="","",IF(ROW()=MAX(IF($C$28:$C$41=C28,ROW($C$28:$C$41),0)),MAX(0,IFERROR(VLOOKUP(C28,$A$10:$L$14,6,FALSE)-VLOOKUP(C28,$A$10:$L$14,5,FALSE),0)),0))} -> 39.4706 | K28: =IF(F28="","",F28-H28-I28-J28) -> 9166.5865 | L28: =IF(F28="","",(F28-J28)/VLOOKUP(C28,$A$10:$L$14,5,FALSE)*VLOOKUP(C28,$A$10:$L$14,10,FALSE)*$O$8) -> 38.441061 | M28: =IF(F28="","",(F28-J28)/VLOOKUP(C28,$A$10:$L$14,5,FALSE)*VLOOKUP(C28,$A$10:$L$14,11,FALSE)) -> 262.11439 | N28: =IF(F28="","",IFERROR(VLOOKUP(C28,$A$10:$L$14,12,FALSE),0)*$O$9) -> 85.8
A29: 46178 | B29: Rail_GPRX5102_5.7.2026_offload_1 | C29: GPRX5102 | D29: =HYPERLINK("https://drive.google.com/file/d/1BBXrICtrRUsOKUjJsMfheqfcb9aAWO6S/view",81420) -> 81420 | E29: =HYPERLINK("https://drive.google.com/file/d/18b3o8jXQ5-VK7ZjXvnQqfZFfXaNnYCfO/view",29080) -> 29080 | F29: =(D29-E29)*$O$4 -> 23741.005 | G29: 2.1 | H29: =IF(F29="","",(F29-J29)*$O$5) -> 306.25897 | I29: =IF(F29="","",(F29-J29)*(1-$O$5)*$O$7) -> 45.697755 | J29: {=IF(F29="","",IF(ROW()=MAX(IF($C$28:$C$41=C29,ROW($C$28:$C$41),0)),MAX(0,IFERROR(VLOOKUP(C29,$A$10:$L$14,6,FALSE)-VLOOKUP(C29,$A$10:$L$14,5,FALSE),0)),0))} -> 0 | K29: =IF(F29="","",F29-H29-I29-J29) -> 23389.049 | L29: =IF(F29="","",(F29-J29)/VLOOKUP(C29,$A$10:$L$14,5,FALSE)*VLOOKUP(C29,$A$10:$L$14,10,FALSE)*$O$8) -> 97.846316 | M29: =IF(F29="","",(F29-J29)/VLOOKUP(C29,$A$10:$L$14,5,FALSE)*VLOOKUP(C29,$A$10:$L$14,11,FALSE)) -> 667.17534 | N29: =IF(F29="","",IFERROR(VLOOKUP(C29,$A$10:$L$14,12,FALSE),0)*$O$9) -> 85.8
A30: 46178 | B30: Rail_GPRX5102_5.7.2026_offload_2 | C30: GPRX5102 | D30: =HYPERLINK("https://drive.google.com/file/d/1lGctwkG62h0mjtVul1LkBXPWvTWyP6xb/view",81560) -> 81560 | E30: =HYPERLINK("https://drive.google.com/file/d/1KX8sizegDwGVTYLbteCL4CzVqsbivd0J/view",29400) -> 29400 | F30: =(D30-E30)*$O$4 -> 23659.359 | G30: 2.1 | H30: =IF(F30="","",(F30-J30)*$O$5) -> 305.20573 | I30: =IF(F30="","",(F30-J30)*(1-$O$5)*$O$7) -> 45.540598 | J30: {=IF(F30="","",IF(ROW()=MAX(IF($C$28:$C$41=C30,ROW($C$28:$C$41),0)),MAX(0,IFERROR(VLOOKUP(C30,$A$10:$L$14,6,FALSE)-VLOOKUP(C30,$A$10:$L$14,5,FALSE),0)),0))} -> 0 | K30: =IF(F30="","",F30-H30-I30-J30) -> 23308.612 | L30: =IF(F30="","",(F30-J30)/VLOOKUP(C30,$A$10:$L$14,5,FALSE)*VLOOKUP(C30,$A$10:$L$14,10,FALSE)*$O$8) -> 97.509817 | M30: =IF(F30="","",(F30-J30)/VLOOKUP(C30,$A$10:$L$14,5,FALSE)*VLOOKUP(C30,$A$10:$L$14,11,FALSE)) -> 664.88089 | N30: =IF(F30="","",IFERROR(VLOOKUP(C30,$A$10:$L$14,12,FALSE),0)*$O$9) -> 85.8
A31: 46178 | B31: Rail_GPRX5102_5.7.2026_offload_3 | C31: GPRX5102 | D31: =HYPERLINK("https://drive.google.com/file/d/1vuoWfwOcKUdnnvzn3Jm5ABfpZJZ9qj44/view",79260) -> 79260 | E31: =HYPERLINK("https://drive.google.com/file/d/1hEZGcVCUcVLzKGXKFWfn7a0K8LIjkFYw/view",29500) -> 29500 | F31: =(D31-E31)*$O$4 -> 22570.738 | G31: 2.1 | H31: =IF(F31="","",(F31-J31)*$O$5) -> 291.16252 | I31: =IF(F31="","",(F31-J31)*(1-$O$5)*$O$7) -> 43.445172 | J31: {=IF(F31="","",IF(ROW()=MAX(IF($C$28:$C$41=C31,ROW($C$28:$C$41),0)),MAX(0,IFERROR(VLOOKUP(C31,$A$10:$L$14,6,FALSE)-VLOOKUP(C31,$A$10:$L$14,5,FALSE),0)),0))} -> 0 | K31: =IF(F31="","",F31-H31-I31-J31) -> 22236.13 | L31: =IF(F31="","",(F31-J31)/VLOOKUP(C31,$A$10:$L$14,5,FALSE)*VLOOKUP(C31,$A$10:$L$14,10,FALSE)*$O$8) -> 93.023169 | M31: =IF(F31="","",(F31-J31)/VLOOKUP(C31,$A$10:$L$14,5,FALSE)*VLOOKUP(C31,$A$10:$L$14,11,FALSE)) -> 634.28821 | N31: =IF(F31="","",IFERROR(VLOOKUP(C31,$A$10:$L$14,12,FALSE),0)*$O$9) -> 85.8
A32: 46178 | B32: Rail_GPRX5102_5.7.2026_offload_4 | C32: GPRX5102 | D32: =HYPERLINK("https://drive.google.com/file/d/11htviAi2RWokZcClkWUYZDFFRJvcM_d0/view",51240) -> 51240 | E32: =HYPERLINK("https://drive.google.com/file/d/1bw-Ntk1fL4vut9Vqr3cUbb8p_tKumu7I/view",29300) -> 29300 | F32: =(D32-E32)*$O$4 -> 9951.8085 | G32: 2.1 | H32: =IF(F32="","",(F32-J32)*$O$5) -> 106.79779 | I32: =IF(F32="","",(F32-J32)*(1-$O$5)*$O$7) -> 15.935596 | J32: {=IF(F32="","",IF(ROW()=MAX(IF($C$28:$C$41=C32,ROW($C$28:$C$41),0)),MAX(0,IFERROR(VLOOKUP(C32,$A$10:$L$14,6,FALSE)-VLOOKUP(C32,$A$10:$L$14,5,FALSE),0)),0))} -> 1672.9104 | K32: =IF(F32="","",F32-H32-I32-J32) -> 8156.1647 | L32: =IF(F32="","",(F32-J32)/VLOOKUP(C32,$A$10:$L$14,5,FALSE)*VLOOKUP(C32,$A$10:$L$14,10,FALSE)*$O$8) -> 34.120698 | M32: =IF(F32="","",(F32-J32)/VLOOKUP(C32,$A$10:$L$14,5,FALSE)*VLOOKUP(C32,$A$10:$L$14,11,FALSE)) -> 232.65555 | N32: =IF(F32="","",IFERROR(VLOOKUP(C32,$A$10:$L$14,12,FALSE),0)*$O$9) -> 85.8
A33: 46178 | B33: Rail_TILX200231_5.11.2026_offload_1 | C33: TILX200231 | D33: =HYPERLINK("https://drive.google.com/file/d/1rB6VmOih3azYzWasRheqUOZXWNmRAgBI/view",78660) -> 78660 | E33: =HYPERLINK("https://drive.google.com/file/d/1djqJVTC9h0XSrM1GK60MvTbChWAEl4-L/view",29140) -> 29140 | F33: =(D33-E33)*$O$4 -> 22461.876 | G33: 2.1 | H33: =IF(F33="","",(F33-J33)*$O$5) -> 289.7582 | I33: =IF(F33="","",(F33-J33)*(1-$O$5)*$O$7) -> 43.235629 | J33: {=IF(F33="","",IF(ROW()=MAX(IF($C$28:$C$41=C33,ROW($C$28:$C$41),0)),MAX(0,IFERROR(VLOOKUP(C33,$A$10:$L$14,6,FALSE)-VLOOKUP(C33,$A$10:$L$14,5,FALSE),0)),0))} -> 0 | K33: =IF(F33="","",F33-H33-I33-J33) -> 22128.882 | L33: =IF(F33="","",(F33-J33)/VLOOKUP(C33,$A$10:$L$14,5,FALSE)*VLOOKUP(C33,$A$10:$L$14,10,FALSE)*$O$8) -> 92.574504 | M33: =IF(F33="","",(F33-J33)/VLOOKUP(C33,$A$10:$L$14,5,FALSE)*VLOOKUP(C33,$A$10:$L$14,11,FALSE)) -> 631.22895 | N33: =IF(F33="","",IFERROR(VLOOKUP(C33,$A$10:$L$14,12,FALSE),0)*$O$9) -> 85.8
A34: 46178 | B34: Rail_TILX200231_5.11.2026_offload_2 | C34: TILX200231 | D34: =HYPERLINK("https://drive.google.com/file/d/1qPBc3I2XZG_rsyHOl_e96taBxJ1bJCyl/view",74820) -> 74820 | E34: =HYPERLINK("https://drive.google.com/file/d/1UOQ2SqnlquaWQrXfK-iWLtTql1rMzCB4/view",29640) -> 29640 | F34: =(D34-E34)*$O$4 -> 20493.287 | G34: 2.1 | H34: =IF(F34="","",(F34-J34)*$O$5) -> 264.3634 | I34: =IF(F34="","",(F34-J34)*(1-$O$5)*$O$7) -> 39.4464 | J34: {=IF(F34="","",IF(ROW()=MAX(IF($C$28:$C$41=C34,ROW($C$28:$C$41),0)),MAX(0,IFERROR(VLOOKUP(C34,$A$10:$L$14,6,FALSE)-VLOOKUP(C34,$A$10:$L$14,5,FALSE),0)),0))} -> 0 | K34: =IF(F34="","",F34-H34-I34-J34) -> 20189.477 | L34: =IF(F34="","",(F34-J34)/VLOOKUP(C34,$A$10:$L$14,5,FALSE)*VLOOKUP(C34,$A$10:$L$14,10,FALSE)*$O$8) -> 84.461149 | M34: =IF(F34="","",(F34-J34)/VLOOKUP(C34,$A$10:$L$14,5,FALSE)*VLOOKUP(C34,$A$10:$L$14,11,FALSE)) -> 575.90718 | N34: =IF(F34="","",IFERROR(VLOOKUP(C34,$A$10:$L$14,12,FALSE),0)*$O$9) -> 85.8
A35: 46178 | B35: Rail_TILX200231_5.11.2026_offload_3 | C35: TILX200231 | D35: =HYPERLINK("https://drive.google.com/file/d/1KSJrJfqLcF275q28UZ35JkfoYG8UR6to/view",82020) -> 82020 | E35: =HYPERLINK("https://drive.google.com/file/d/1Dlkd7BrKjwTBpV3MHh0Vqp1AFBXqJ8Ce/view",29220) -> 29220 | F35: =(D35-E35)*$O$4 -> 23949.658 | G35: 2.1 | H35: =IF(F35="","",(F35-J35)*$O$5) -> 308.95058 | I35: =IF(F35="","",(F35-J35)*(1-$O$5)*$O$7) -> 46.099379 | J35: {=IF(F35="","",IF(ROW()=MAX(IF($C$28:$C$41=C35,ROW($C$28:$C$41),0)),MAX(0,IFERROR(VLOOKUP(C35,$A$10:$L$14,6,FALSE)-VLOOKUP(C35,$A$10:$L$14,5,FALSE),0)),0))} -> 0 | K35: =IF(F35="","",F35-H35-I35-J35) -> 23594.608 | L35: =IF(F35="","",(F35-J35)/VLOOKUP(C35,$A$10:$L$14,5,FALSE)*VLOOKUP(C35,$A$10:$L$14,10,FALSE)*$O$8) -> 98.706257 | M35: =IF(F35="","",(F35-J35)/VLOOKUP(C35,$A$10:$L$14,5,FALSE)*VLOOKUP(C35,$A$10:$L$14,11,FALSE)) -> 673.03894 | N35: =IF(F35="","",IFERROR(VLOOKUP(C35,$A$10:$L$14,12,FALSE),0)*$O$9) -> 85.8
A36: 46178 | B36: Rail_TILX200231_5.11.2026_offload_4 | C36: TILX200231 | D36: =HYPERLINK("https://drive.google.com/file/d/1R9IXRmgheLyiUtsztpBVmoznFjXPkBzI/view",58780) -> 58780 | E36: =HYPERLINK("https://drive.google.com/file/d/1wqP_XPCZEmTlG_qwE2gCndEUJqn2ewJK/view",32780) -> 32780 | F36: =(D36-E36)*$O$4 -> 11793.392 | G36: 2.1 | H36: =IF(F36="","",(F36-J36)*$O$5) -> 146.35282 | I36: =IF(F36="","",(F36-J36)*(1-$O$5)*$O$7) -> 21.837713 | J36: {=IF(F36="","",IF(ROW()=MAX(IF($C$28:$C$41=C36,ROW($C$28:$C$41),0)),MAX(0,IFERROR(VLOOKUP(C36,$A$10:$L$14,6,FALSE)-VLOOKUP(C36,$A$10:$L$14,5,FALSE),0)),0))} -> 448.212 | K36: =IF(F36="","",F36-H36-I36-J36) -> 11176.989 | L36: =IF(F36="","",(F36-J36)/VLOOKUP(C36,$A$10:$L$14,5,FALSE)*VLOOKUP(C36,$A$10:$L$14,10,FALSE)*$O$8) -> 46.75809 | M36: =IF(F36="","",(F36-J36)/VLOOKUP(C36,$A$10:$L$14,5,FALSE)*VLOOKUP(C36,$A$10:$L$14,11,FALSE)) -> 318.82493 | N36: =IF(F36="","",IFERROR(VLOOKUP(C36,$A$10:$L$14,12,FALSE),0)*$O$9) -> 85.8
L37: =SUM(L28:L36) -> 683.44106 | M37: =SUM(M28:M36) -> 4660.1144 | N37: =SUM(N28:N36) -> 772.2
M38: =IF(F38="","",(F38-J38)/VLOOKUP(C38,$A$10:$L$14,5,FALSE)*VLOOKUP(C38,$A$10:$L$14,11,FALSE)) | N38: =IF(F38="","",IFERROR(VLOOKUP(C38,$A$10:$L$14,12,FALSE),0)*$O$9)
L39: =IF(F39="","",(F39-J39)/VLOOKUP(C39,$A$10:$L$14,5,FALSE)*VLOOKUP(C39,$A$10:$L$14,10,FALSE)*$O$8) | M39: =IF(F39="","",(F39-J39)/VLOOKUP(C39,$A$10:$L$14,5,FALSE)*VLOOKUP(C39,$A$10:$L$14,11,FALSE)) | N39: =IF(F39="","",IFERROR(VLOOKUP(C39,$A$10:$L$14,12,FALSE),0)*$O$9)
L40: =IF(F40="","",(F40-J40)/VLOOKUP(C40,$A$10:$L$14,5,FALSE)*VLOOKUP(C40,$A$10:$L$14,10,FALSE)*$O$8) | M40: =IF(F40="","",(F40-J40)/VLOOKUP(C40,$A$10:$L$14,5,FALSE)*VLOOKUP(C40,$A$10:$L$14,11,FALSE)) | N40: =IF(F40="","",IFERROR(VLOOKUP(C40,$A$10:$L$14,12,FALSE),0)*$O$9)
...

Sheet AECN Truck
A1: BATCH HEADER — AECN Truck (Direct from Fort Lupton)
A2: Batch ID (INJ-YYYY-WXX) | B2: INJ-06-2026-W1 | K2: Constants
A3: Week Start (Sat) | B3: 46172 | K3: Lbs/Kg | L3: 2.20462
A4: Week End (Sat) | B4: 46179 | K4: Kg/Lbs | L4: 0.453592
K5: Sparging Mass Loss | L5: 0.0129
K6: pH range (target) | L6: 2.0 - 4.0
K7: Filtration Solids Content | L7: =HYPERLINK("https://docs.google.com/spreadsheets/d/16shKoa1KP34kQJyQvzclBejW9L5-ubNSqPsMOVB7zDY/edit?usp=sharing", 0.00195) -> 0.00195
A8: SECTION 1 - DELIVERIES LEDGER (one row per direct truck; BOL & scale ticket on same row)
A9: Date | B9: BOL # / SO # | C9: BOL Mass (MT) | D9: BOL Mass (kg) | E9: Scale Full (lb) | F9: Scale Empty (lb) | G9: Cargo (kg) | H9: pH | J9: Sparging Loss (kg) | K9: Filtration Loss (kg) | L9: MOBI (kg) | M9: C Content
J10: =IF(D10="","",D10*$L$5) | K10: =IF(D10="","",(D10-J10)*$L$7) | L10: =IF(D10="","",D10-J10-K10)
J11: =IF(D11="","",D11*$L$5) | K11: =IF(D11="","",(D11-J11)*$L$7) | L11: =IF(D11="","",D11-J11-K11)
J12: =IF(D12="","",D12*$L$5) | K12: =IF(D12="","",(D12-J12)*$L$7) | L12: =IF(D12="","",D12-J12-K12)
J13: =IF(D13="","",D13*$L$5) | K13: =IF(D13="","",(D13-J13)*$L$7) | L13: =IF(D13="","",D13-J13-K13)
J14: =IF(D14="","",D14*$L$5) | K14: =IF(D14="","",(D14-J14)*$L$7) | L14: =IF(D14="","",D14-J14-K14)
J15: =IF(D15="","",D15*$L$5) | K15: =IF(D15="","",(D15-J15)*$L$7) | L15: =IF(D15="","",D15-J15-K15)
J16: =IF(D16="","",D16*$L$5) | K16: =IF(D16="","",(D16-J16)*$L$7) | L16: =IF(D16="","",D16-J16-K16)
J17: =IF(D17="","",D17*$L$5) | K17: =IF(D17="","",(D17-J17)*$L$7) | L17: =IF(D17="","",D17-J17-K17)
J18: =IF(D18="","",D18*$L$5) | K18: =IF(D18="","",(D18-J18)*$L$7) | L18: =IF(D18="","",D18-J18-K18)
J19: =IF(D19="","",D19*$L$5) | K19: =IF(D19="","",(D19-J19)*$L$7) | L19: =IF(D19="","",D19-J19-K19)
J20: =IF(D20="","",D20*$L$5) | K20: =IF(D20="","",(D20-J20)*$L$7) | L20: =IF(D20="","",D20-J20-K20)
J21: =IF(D21="","",D21*$L$5) | K21: =IF(D21="","",(D21-J21)*$L$7) | L21: =IF(D21="","",D21-J21-K21)
... J24: =IF(D24="","",D24*$L$5) | K24: =IF(D24="","",(D24-J24)*$L$7) | L24: =IF(D24="","",D24-J24-K24)
A26: SECTION 2 - ROLLUP (Mass Used = Σ BOL kg; scale tickets no longer required for direct trucks per 2026-05-26)
A27: Σ BOL (kg) | B27: Σ Cargo (kg) | C27: Mass Used (kg) | D27: Sparging Loss (kg) | E27: Filtration Loss (kg) | F27: Uncertainty Adjustment (kg) | G27: MOBI (kg) | H27: pH | I27: C Content (MOBI-wtd) | K27: Origins list (BOLs)
A28: =SUMIFS(D10:D24,B10:B24,"<>") -> 0 | B28: =SUMIFS(G10:G24,B10:B24,"<>") -> 0 | C28: =A28 -> 0 | D28: =C28*$L$5 -> 0 | E28: =(C28-D28)*$L$7 -> 0 | F28: 0 | G28: =C28-D28-E28-F28 -> 0 | H28: =IFERROR(AVERAGE(H10:H24),"") | I28: =IFERROR(SUMPRODUCT(L10:L24,M10:M24)/SUM(L10:L24),"") | K28: =IFERROR(__xludf.DUMMYFUNCTION("TRIM(TEXTJOIN("", "",TRUE,IFERROR(FILTER(B10:B24,B10:B24<>""""),"""")))"),"")

Sheet WODO
A1: BATCH HEADER — Charm WODO (IBC Totes)
A2: Batch ID (INJ-YYYY-WXX) | B2: INJ-06-2026-W1 | K2: Constants
A3: Week Start (Sat) | B3: 46172 | K3: Lbs/Kg | L3: 2.20462
A4: Week End (Sat) | B4: 46179 | K4: Kg/Lbs | L4: 0.453592
K5: Sparging Mass Loss | L5: 0.0129
K6: pH range (target) | L6: 2.0 - 4.0
A8: SECTION 1 - IBC LEDGER (one row per IBC tote; tote tag mass is authoritative)
B9: Transport Emissions | D9: Pyrolysis Emissions Mass | F9: MOBI
A10: Tag | B10: Gross Mass (kg) | C10: Tote Mass (kg) | D10: Net Oil Produced (kg) | E10: Empty Tote Weight (kg) | F10: Net Oil Injected (kg) | G10: Production Period | H10: Carbon Intensity | I10: Production Emissions | J10: Scale Uncertainty
A11: 228026 | B11: 1178 | C11: 57.6 | D11: =B11-C11 -> 1120.4 | E11: =134*L4 -> 60.781328 | F11: =B11-E11 -> 1117.2187 | G11: MFO Lot 4384 (LOT00004384), November 2025 PP | H11: 0.97484085 | I11: =H11*D11 -> 1092.2117 | J11: =2.5*$L$4 -> 1.13398
A12: 228459 | B12: 1201 | C12: 57.6 | D12: =B12-C12 -> 1143.4 | E12: =138*$L$4 -> 62.595696 | F12: =B12-E12 -> 1138.4043 | G12: MFO Lot 4288 (LOT00004288), November 2025 PP | H12: 0.97484085 | I12: =H12*D12 -> 1114.633 | J12: =2.5*$L$4 -> 1.13398
A13: 228051 | B13: 1141 | C13: 57.6 | D13: =B13-C13 -> 1083.4 | E13: =130*$L$4 -> 58.96696 | F13: =B13-E13 -> 1082.033 | G13: MFO Lot 4386 (LOT00004386), November 2025 PP | H13: 0.97484085 | I13: =H13*D13 -> 1056.1426 | J13: =2.5*$L$4 -> 1.13398
A14: 228065 | B14: 1233 | C14: 57.6 | D14: =B14-C14 -> 1175.4 | E14: =137*$L$4 -> 62.142104 | F14: =B14-E14 -> 1170.8579 | G14: MFO Lot 4408 (LOT00004408), November 2025 PP | H14: 0.97484085 | I14: =H14*D14 -> 1145.8279 | J14: =2.5*$L$4 -> 1.13398
A15: 228077 | B15: 1078 | C15: 57.6 | D15: =B15-C15 -> 1020.4 | E15: =141*$L$4 -> 63.956472 | F15: =B15-E15 -> 1014.0435 | G15: MFO Lot 4430 (LOT00004430), November 2025 PP | H15: 0.97484085 | I15: =H15*D15 -> 994.72761 | J15: =2.5*$L$4 -> 1.13398
A16: 228021 | B16: 1120 | C16: 57.6 | D16: =B16-C16 -> 1062.4 | E16: =150*$L$4 -> 68.0388 | F16: =B16-E16 -> 1051.9612 | G16: MFO Lot 4458 (LOT00004458), November 2025 PP | H16: 0.97484085 | I16: =H16*D16 -> 1035.6709 | J16: =2.5*$L$4 -> 1.13398
A17: 228032 | B17: 1140 | C17: 57.6 | D17: =B17-C17 -> 1082.4 | E17: =134*$L$4 -> 60.781328 | F17: =B17-E17 -> 1079.2187 | G17: MFO Lot 4462 (LOT00004462), November 2025 PP | H17: 0.97484085 | I17: =H17*D17 -> 1055.1677 | J17: =2.5*$L$4 -> 1.13398
A18: 300018 | B18: 1244 | C18: 57.6 | D18: =B18-C18 -> 1186.4 | E18: =140*$L$4 -> 63.50288 | F18: =B18-E18 -> 1180.4971 | G18: MFO Lot 4502 (LOT00004502), December 2025 PP | H18: 0.97218282 | I18: =H18*D18 -> 1153.3977 | J18: =2.5*$L$4 -> 1.13398
A19: 300014 | B19: 1225 | C19: 57.6 | D19: =B19-C19 -> 1167.4 | E19: =142*$L$4 -> 64.410064 | F19: =B19-E19 -> 1160.5899 | G19: MFO Lot 4518 (LOT00004518), December 2025 PP | H19: 0.97218282 | I19: =H19*D19 -> 1134.9262 | J19: =2.5*$L$4 -> 1.13398
A20: 300010 | B20: 1197 | C20: 57.6 | D20: =B20-C20 -> 1139.4 | E20: =148*$L$4 -> 67.131616 | F20: =B20-E20 -> 1129.8684 | G20: MFO Lot 4621 (LOT00004621), January 2026 PP | H20: 0.92046373 | I20: =H20*D20 -> 1048.7764 | J20: =2.5*$L$4 -> 1.13398
B22: =SUM(B11:B20) -> 11757 | C22: =SUM(C11:C20) -> 576 | D22: =SUM(D11:D20) -> 11181 | E22: =SUM(E11:E20) -> 632.30725 | F22: =SUM(F11:F20) -> 11124.693 | H22: =I22/D22 -> 0.96873999 | I22: =SUM(I11:I20) -> 10831.482 | J22: =SUM(J11:J20) -> 11.3398
A31: SECTION 2 - ROLLUP
A32: Transport Mass | B32: Σ Net Oil Produced (kg) | C32: Loss (kg) | D32: MOBI — Σ Net Oil Injected (kg) | E32: Σ Production Emissions (kg)
A33: =SUM(B11:B20) -> 11757 | B33: =SUM(D11:D20) -> 11181 | C33: =B33-D33 -> 56.307248 | D33: =SUM(F11:F20) -> 11124.693 | E33: =SUM(I11:I20) -> 10831.482

Sheet Kerry
A1: BATCH HEADER — Kerry (Calciner Waste Oil, IBC Totes)
A2: Batch ID (INJ-YYYY-WXX) | B2: INJ-06-2026-W1 | L2: Constants
A3: Week Start (Sat) | B3: 46172 | L3: Lbs/Kg | M3: 2.20462
A4: Week End (Sat) | B4: 46179 | L4: Kg/Lbs | M4: 0.453592
L5: Sparging Mass Loss | M5: 0.0129
L6: pH range (target) | M6: 2.0 - 4.0
L7: Testing Uncertainty | M7: 0.004
A8: SECTION 1 - IBC LEDGER (one row per Kerry tote; tote tag mass is authoritative)
A9: Date | B9: Tote Tag # | C9: Gross Mass (kg) — transport | D9: Tote Empty (kg) | E9: Net Oil (kg) — production | F9: Net Injected (kg) — MOBI | G9: pH | I9: C Content | J9: C Content Uncertainty | K9: Mass Uncertainty (Scaling)
A31: SECTION 2 - ROLLUP
A32: Σ Net Injected (kg) | B32: Sparging Loss (kg) | C32: MOBI (kg) | D32: pH | E32: C Content (MOBI-wtd) | G32: Origins list (Tote tags)
A33: =SUMIFS(F10:F29,B10:B29,"<>") -> 0 | B33: =A33*$M$5 -> 0 | C33: =A33-B33 -> 0 | D33: =IFERROR(AVERAGE(G10:G29),"") | E33: =IFERROR(__xludf.DUMMYFUNCTION("IFERROR(AVERAGE.WEIGHTED(I10:I29,F10:F29),"""")"),"") | G33: =IFERROR(__xludf.DUMMYFUNCTION("TRIM(TEXTJOIN("", "",TRUE,IFERROR(FILTER(B10:B29,B10:B29<>""""),"""")))"),"")

Sheet QOWV
A1: BATCH HEADER — QOWV (Aqueous Bio-Oil, IBC Totes)
A2: Batch ID (INJ-YYYY-WXX) | B2: INJ-06-2026-W1 | K2: Constants
A3: Week Start (Sat) | B3: 46172 | K3: Lbs/Kg | L3: 2.20462
A4: Week End (Sat) | B4: 46179 | K4: Kg/Lbs | L4: 0.453592
K5: Sparging Mass Loss | L5: 0.0129
K6: pH range (target) | L6: 2.0 - 4.0
A8: SECTION 1 - IBC LEDGER (one row per QOWV tote; tote tag mass is authoritative)
B9: Transport Emissions | D9: Pyrolysis Emissions Mass | F9: MOBI
A10: Tag | B10: Gross Mass (kg) | C10: Tote Mass (kg) | D10: Net Oil Produced (kg) | E10: Empty Tote Weight (kg) | F10: Net Oil Injected (kg) | G10: Production Period | H10: Carbon Intensity | I10: Production Emissions | J10: Scale Uncertainty
G52: =IF(AND(D52<>"",F52<>""),(D52-F52)*$L$4,"") | H52: =IF(G52="","",G52*(1-$L$5))
B53: =SUM(B10:B51) -> 0 | D53: =SUM(D10:D51) -> 0 | F53: =SUM(F9:F51) -> 0 | H53: =SUMPRODUCT(D11:D51,H11:H51)/SUM(D11:D51) -> #DIV/0! | I53: =sum(I11:I51) -> 0 | J53: =SUM(J9:J51) -> 0
G54: =IF(AND(D54<>"",F54<>""),(D54-F54)*$L$4,"") | H54: =IF(G54="","",G54*(1-$L$5))
G55: =IF(AND(D55<>"",F55<>""),(D55-F55)*$L$4,"") | H55: =IF(G55="","",G55*(1-$L$5))
G56: =IF(AND(D56<>"",F56<>""),(D56-F56)*$L$4,"") | H56: =IF(G56="","",G56*(1-$L$5))
G57: =IF(AND(D57<>"",F57<>""),(D57-F57)*$L$4,"") | H57: =IF(G57="","",G57*(1-$L$5))
G58: =IF(AND(D58<>"",F58<>""),(D58-F58)*$L$4,"") | H58: =IF(G58="","",G58*(1-$L$5))
G59: =IF(AND(D59<>"",F59<>""),(D59-F59)*$L$4,"") | H59: =IF(G59="","",G59*(1-$L$5))
G60: =IF(AND(D60<>"",F60<>""),(D60-F60)*$L$4,"") | H60: =IF(G60="","",G60*(1-$L$5))
G61: =IF(AND(D61<>"",F61<>""),(D61-F61)*$L$4,"") | H61: =IF(G61="","",G61*(1-$L$5))
G62: =IF(AND(D62<>"",F62<>""),(D62-F62)*$L$4,"") | H62: =IF(G62="","",G62*(1-$L$5))
G63: =IF(AND(D63<>"",F63<>""),(D63-F63)*$L$4,"") | H63: =IF(G63="","",G63*(1-$L$5))
G64: =IF(AND(D64<>"",F64<>""),(D64-F64)*$L$4,"") | H64: =IF(G64="","",G64*(1-$L$5))
G65: =IF(AND(D65<>"",F65<>""),(D65-F65)*$L$4,"") | H65: =IF(G65="","",G65*(1-$L$5))
... G73: =IF(AND(D73<>"",F73<>""),(D73-F73)*$L$4,"") | H73: =IF(G73="","",G73*(1-$L$5))

Sheet WODO Shipments & EE Allocation
A1: INJ-06-2026-W1 — WODO Shipments & EE Mileage Allocation
A4: BATCH SUMMARY
A5: Batch | B5: Fraction | C5: Inj. Week | D5: # Totes | E5: Ship Date(s)
A6: INJ-06-2026-W1 | B6: WODO | C6: 2026-05-30 to 2026-06-06 | D6: 10 | E6: 2026-03-20 (10 of 17 on truck)
A8: Charm CO -> Basco LA distance (one-way miles): | B8: 1201
A10: EE ALLOCATION TABLE
A11: Truck (shipment) | B11: Ship Date | C11: Total Totes on Truck | D11: Batch-Relevant Totes | E11: Batch Share of Truck | F11: Mileage (one-way) | G11: Allocated Miles
A12: Shipment 03-20 | B12: 46101 | C12: 17 | D12: 10 | E12: =D12/C12 -> 0.58823529 | F12: =$B$8 -> 1201 | G12: =E12*F12 -> 706.47059
A13: TOTAL | C13: =SUM(C12) -> 17 | D13: =SUM(D12) -> 10 | G13: =SUM(G12) -> 706.47059
A15: BATCH MILEAGE ALLOCATION
A16: Batch | B16: Per-Truck Allocation (relevant/total) | C16: Allocated Miles | D16: # Totes
A17: INJ-06-2026-W1 | B17: 03-20 (10/17) | C17: =G13 -> 706.47059 | D17: =D13 -> 10
A19: --- Shipment 2026-03-20 --- (10 of 17 totes on this truck are W1-relevant)
A20: Metal Tag | B20: Fraction | C20: Production Period | D20: Date Loaded | E20: Batch
A21: 228026 | B21: WODO | C21: Nov 2025 PP | D21: 46101 | E21: INJ-06-2026-W1
A22: 228459 | B22: WODO | C22: Nov 2025 PP | D22: 46101 | E22: INJ-06-2026-W1
A23: 228051 | B23: WODO | C23: Nov 2025 PP | D23: 46101 | E23: INJ-06-2026-W1
A24: 228065 | B24: WODO | C24: Nov 2025 PP | D24: 46101 | E24: INJ-06-2026-W1
A25: 228077 | B25: WODO | C25: Nov 2025 PP | D25: 46101 | E25: INJ-06-2026-W1
A26: 228021 | B26: WODO | C26: Nov 2025 PP | D26: 46101 | E26: INJ-06-2026-W1
A27: 228032 | B27: WODO | C27: Nov 2025 PP | D27: 46101 | E27: INJ-06-2026-W1
A28: 300018 | B28: WODO | C28: Dec 2025 PP | D28: 46101 | E28: INJ-06-2026-W1
A29: 300014 | B29: WODO | C29: Dec 2025 PP | D29: 46101 | E29: INJ-06-2026-W1
A30: 300010 | B30: WODO | C30: Jan 2026 PP | D30: 46101 | E30: INJ-06-2026-W1
