Workbook

Sheet Jun 26 PP Summary
A1: Process Emissions | H1: Embodied Emissions | M1: Output Type | N1: Mass of Output (kg) | O1: % Output Mass | P1: C Content (%) | Q1: C Content Mass (kg) | R1: % C Content Mass | S1: Total Emissions Allocated to Fraction (MT CO2e) | T1: Kg Emissions/Kg Material
M2: WODO | N2: 10778 | O2: =N2/($N$2+$N$3+$N$4) -> 0.16935437 | P2: 0.59446 | Q2: =P2*N2 -> 6407.0899 | R2: =Q2/(SUM($Q$2+$Q$3+$Q$4)) -> 0.43696432 | S2: =R2*$I$32 -> 11.349938 | T2: =(S2*1000)/N2 -> 1.0530654
A3: Biomass Transport | E3: Pyrolyzer Up-Time | H3: Equipment Amortization | M3: Biochar | N3: 6247.5 | O3: =N3/($N$2+$N$3+$N$4) -> 0.098166768 | P3: 0.8274 | Q3: =P3*N3 -> 5169.1815 | R3: =Q3/(SUM($Q$2+$Q$3+$Q$4)) -> 0.35253882 | S3: =R3*$I$32 -> 9.1570265 | T3: =(S3*1000)/N3 -> 1.4657105
B4: New Pile | E4: Total Operating Hours | F4: 2006.8 | I4: Total Biomass Consumed (kg) | J4: 44544.754 | M4: Aqueous | N4: 46616.2 | O4: =N4/($N$2+$N$3+$N$4) -> 0.73247886 | P4: 0.06621 | Q4: =P4*N4 -> 3086.4586 | R4: =Q4/(SUM($Q$2+$Q$3+$Q$4)) -> 0.21049686 | S4: =R4*$I$32 -> 5.4675548 | T4: =(S4*1000)/N4 -> 0.11728873
B5: Process Emissions | C5: =C15*'Emission Factors'!E3 -> 1.0699026 | E5: Production Operating Hours | F5: =F4-F6 -> 2006.8 | I5: Total Biomass Consumed (MT) | J5: =J4/1000 -> 44.544754
B6: Embodied Emissions | C6: =C14*'Emission Factors'!E6 -> 0.068344348 | E6: R+D Operating Hours | F6: 0 | I6: Biomass Amortization Factor for PP (kg Co2e/MT biomass) | J6: 66.810902
B7: Log Handling Emissions | C7: =C13*'Emission Factors'!E13 -> 0.16559376 | E7: % Production | F7: =F5/F4 -> 1 | I7: Total Amortized Embodied Emissions (kg) | J7: =J6*J5 -> 2976.0752
E8: % R+D | F8: =F6/F4 -> 0 | I8: Total Amortized Embodied Emissions (MT) | J8: =J7/1000 -> 2.9760752
B9: Total Emissions | C9: =SUM(C5:C7) -> 1.3038407 | H9: Spare Parts and Consumables
B10: BCU's Applied | C10: =SUM(C5,C7) -> 1.2354963 | E10: Total Procured Renewables | I10: EE Estimate per Pyrolyzer Operating Hour (kgCO2e) | J10: 0.83351
B11: Remaining Emissions to Allocate | C11: =C9-C10 -> 0.068344348 | E11: RD BCUs (MT CO2e) | F11: =Sum(C10,C39,C81,C89) -> 5.1763147 | I11: Spare Parts and Consumables Estimate for Period (kg) | J11: =J10*(F5*(1.01)) -> 1689.4147
E12: RECs (kWh) | F12: =C62 -> 34933.411 | I12: Spare Parts and Consumables Estimate for Period (MT) | J12: =J11/1000 -> 1.6894147
B13: Tonnes | C13: 109.03
B14: Miles | C14: 354.5
B15: Tonne-Miles | C15: 7730.51
A17: Propane Combustion
B18: Total PP Deliveries (L) | C18: 10553.345 | H18: Consolidated Emissions Inventory | I18: Total Emissions (MT) | J18: % of Total
B19: Tank Level at PP Close (%) | C19: 0.68 | H19: Biomass Transport | I19: =C11*F7 -> 0.068344348 | J19: =I19/$I$32 -> 0.0026312074
B20: Tank Level at PP Close (L) | C20: 2573.8 | H20: Propane | I20: =C27*F7 -> 19.314285 | J20: =I20/$I$32 -> 0.74358585
B21: Total Propane Consumption for PP (L) | C21: 10401.945 | H21: Diesel | I21: =C40*F7 -> 0 | J21: =I21/$I$32 -> 0
B22: Total Propane Consumption for PP (Gal) | C22: 2747.9043 | H22: Gasoline | I22: =C48*F7 -> 0.4580906 | J22: =I22/$I$32 -> 0.017636153
B23: Total Propane Consumption for PP (kg) | C23: 5252.9764 | H23: Electricity | I23: =C64*F7 -> 1.2800142 | J23: =I23/$I$32 -> 0.049279609
B24: Fuel Meter Uncertainty | C24: 0.0129 | H24: Tailgas | I24: =C69*F7 -> 0.08602849 | J24: =I24/$I$32 -> 0.0033120339
B25: Uncertainty Adjusted Total | C25: =C23*(1+C24) -> 5320.7398 | H25: Water | I25: =C75*F7 -> 0.015448531 | J25: =I25/$I$32 -> 0.00059475715
B26: Propane Combustion Emission Factor (kg CO2e/kg) | C26: ='Emission Factors'!E15*1000 -> 3.63 | H26: Consumables Delivery | I26: =C82*F7 -> 0.0868183 | J26: =I26/$I$32 -> 0.003342441
B27: Total Propane Emissions (MT CO2e) | C27: =(C25*C26)/1000 -> 19.314285 | H27: Waste Disposal | I27: =C90*F7 -> 0 | J27: =I27/$I$32 -> 0
H28: Capital Goods EE | I28: =J8*F7 -> 2.9760752 | J28: =I28/$I$32 -> 0.11457672
A29: Diesel Combustion | H29: SP+C EE | I29: =J12*F7 -> 1.6894147 | J29: =I29/$I$32 -> 0.065041231
B30: Total Diesel Consumption for PP (L) | C30: 1173.4771
B31: Total Diesel Consumption for PP (Gal) | C31: 310
B32: Total Diesel Fills in Office Generator for PP (Gal) | C32: 0 | H32: Total | I32: =SUM(I19:I29) -> 25.97452
B33: Total Production Diesel Consumption for PP (Gal) | C33: 310
B34: Total Production Diesel Consumption for PP (kg) | C34: 997.3475
B35: Fuel Meter Uncertainty | C35: 0.0129
B36: Uncertainty Adjusted Total | C36: =C34*(1+C35) -> 1010.2133
B37: Diesel Combustion Emission Factor (kg CO2e/kg) | C37: ='Emission Factors'!E14*1000 -> 3.87
B38: Total Diesel Emissions (MT CO2e) | C38: =(C37*C36)/1000 -> 3.9095254
B39: BCUs Applied (MT CO2e) | C39: =C38 -> 3.9095254
B40: Remaining Emissions to Allocate (MT CO2e) | C40: =C38-C39 -> 0
A42: Gasoline Combustion
...

Sheet Emission Factors
A1: Emission Factors
A2: Emissions Factor | B2: Unit | C2: Baseline Quantity | D2: Uncertainty Factor | E2: Final Quantity | F2: Source
A3: Truck Transport Fuel Use (Well to Wheel) -- Flatbed Truck | B3: MT CO2e/t-mi | C3: 0.0001384 | E3: 0.0001384 | F3: GLEC V3.2 2025
A4: Truck Transport Fuel Use (Well to Wheel) -- Tanker Truck | B4: MT CO2e/t-mi | C4: 0.0001143 | D4: 0 | E4: 0.0001143 | F4: GLEC V3.2 2025
A5: Vehicle Embodied Emissions --Tanker Truck | B5: MT CO2e/mi | C5: 0.00023756059 | E5: 0.00023756059 | F5: GLEC V3.2 2025
A6: Vehicle Embodied Emissions --Non-Tanker Truck | B6: MT CO2e/mi | C6: 0.00019279083 | E6: 0.00019279083 | F6: GLEC V3.2 2025
A8: Grid Electricity Use -- Kansas | B8: MTCO2e/kWh | C8: 0.00046555169 | E8: 0.00046555169 | F8: Green-E,USEPA, GREET 2025
A9: Wind RECs Use -- Kansas | B9: MTCO2e/kWh | C9: 1.0027197e-05 | E9: 1.0027197e-05 | F9: Green-E,USEPA, GREET 2025
A10: Grid Electricity Use -- Colorado | B10: MTCO2e/kWh | C10: 0.00048902383 | E10: 0.00048902383 | F10: Green-E,USEPA, GREET 2025
A11: Solar RECs Use -- Colorado | B11: MTCO2e/kWh | C11: 3.6641546e-05 | E11: 3.6641546e-05 | F11: Green-E,USEPA, GREET 2025
A12: Vaulted Equipment Embodied Emissions | B12: MT CO2e/MT Injectate | C12: 0.00010343352 | D12: N/A | E12: =C12 -> 0.00010343352 | F12: Vaulted PDD
A13: Self-Loading Truck Lumber Handling (No Transport) | B13: MT CO2e/MT logs | C13: 0.0015187908 | D13: N/A | E13: =C13 -> 0.0015187908 | F13: Auburn University
A14: Diesel Fuel Combustion (Total WTW) | B14: MTCO2e/kg fuel | C14: 0.00387 | D14: N/A | E14: =C14 -> 0.00387 | F14: GLEC V3.2 2025
A15: LPG Consumption (Total WTW) | B15: MTCO2e/kg fuel | C15: 0.00363 | D15: N/A | E15: =C15 -> 0.00363 | F15: GLEC V3.2 2025
A16: Gasoline Consumption (Total WTW) | B16: MTCO2e/kg fuel | C16: 0.00374 | D16: N/A | E16: =C16 -> 0.00374 | F16: GLEC V3.2 2025
A17: Drinking Water -- US | B17: MTCO2e/gal water | C17: 1.7412898e-06 | D17: N/A | E17: =C17 -> 1.7412898e-06 | F17: https://www.sciencedirect.com/science/article/abs/pii/S0959652621030110

Sheet DataTable
B2: ='Jun 26 PP Summary'!E5 -> Production Operating Hours | C2: ='Jun 26 PP Summary'!F5 -> 2006.8
B3: ='Jun 26 PP Summary'!I5 -> Total Biomass Consumed (MT) | C3: ='Jun 26 PP Summary'!J5 -> 44.544754
B4: =#REF! -> #REF! | C4: =#REF! -> #REF!
A5: Propane (kg) | B5: ='Jun 26 PP Summary'!B25 -> Uncertainty Adjusted Total | C5: ='Jun 26 PP Summary'!C25 -> 5320.7398
A6: Diesel (kg) | B6: ='Jun 26 PP Summary'!B36 -> Uncertainty Adjusted Total | C6: ='Jun 26 PP Summary'!C36 -> 1010.2133
A7: Gasoline (kg) | B7: ='Jun 26 PP Summary'!B46 -> Uncertainty Adjusted Total
B10: ='Jun 26 PP Summary'!H19 -> Biomass Transport | C10: ='Jun 26 PP Summary'!I19 -> 0.068344348
B11: ='Jun 26 PP Summary'!H20 -> Propane | C11: ='Jun 26 PP Summary'!I20 -> 19.314285
B12: ='Jun 26 PP Summary'!H21 -> Diesel | C12: ='Jun 26 PP Summary'!I21 -> 0
B13: ='Jun 26 PP Summary'!H22 -> Gasoline | C13: ='Jun 26 PP Summary'!I22 -> 0.4580906
B14: ='Jun 26 PP Summary'!H23 -> Electricity | C14: ='Jun 26 PP Summary'!I23 -> 1.2800142
B15: ='Jun 26 PP Summary'!H24 -> Tailgas | C15: ='Jun 26 PP Summary'!I24 -> 0.08602849
B16: ='Jun 26 PP Summary'!H25 -> Water | C16: ='Jun 26 PP Summary'!I25 -> 0.015448531
B17: ='Jun 26 PP Summary'!H26 -> Consumables Delivery | C17: ='Jun 26 PP Summary'!I26 -> 0.0868183
B18: ='Jun 26 PP Summary'!H27 -> Waste Disposal | C18: ='Jun 26 PP Summary'!I27 -> 0
B19: ='Jun 26 PP Summary'!H28 -> Capital Goods EE | C19: ='Jun 26 PP Summary'!I28 -> 2.9760752
B20: ='Jun 26 PP Summary'!H29 -> SP+C EE | C20: ='Jun 26 PP Summary'!I29 -> 1.6894147
B21: ='Jun 26 PP Summary'!H32 -> Total | C21: ='Jun 26 PP Summary'!I32 -> 25.97452

Sheet DataCollection
A1: Production Operating Hours | B1: ='Jun 26 PP Summary'!F5 -> 2006.8
A2: Total BM Consumed | B2: ='Jun 26 PP Summary'!J5 -> 44.544754
A3: WODO Yield | B3: ='Jun 26 PP Summary'!N2 -> 10778
A4: WODO wt%C | B4: ='Jun 26 PP Summary'!P2 -> 0.59446
A5: Biochar Yield | B5: ='Jun 26 PP Summary'!N3 -> 6247.5
A6: Biochar wt%C | B6: ='Jun 26 PP Summary'!P3 -> 0.8274
A7: Biomass Transport | B7: ='Jun 26 PP Summary'!I19 -> 0.068344348
A8: Propane | B8: ='Jun 26 PP Summary'!I20 -> 19.314285
A9: Diesel | B9: ='Jun 26 PP Summary'!I21 -> 0
A10: Gasoline | B10: ='Jun 26 PP Summary'!I22 -> 0.4580906
A11: Electricity | B11: ='Jun 26 PP Summary'!I23 -> 1.2800142
A12: Tailgas | B12: ='Jun 26 PP Summary'!I24 -> 0.08602849
A13: Water | B13: ='Jun 26 PP Summary'!I25 -> 0.015448531
A14: Consumables Delivery | B14: ='Jun 26 PP Summary'!I26 -> 0.0868183
A15: Waste Disposal | B15: ='Jun 26 PP Summary'!I27 -> 0
A16: Capital Goods EE | B16: ='Jun 26 PP Summary'!I28 -> 2.9760752
A17: SP+C EE | B17: ='Jun 26 PP Summary'!I29 -> 1.6894147
A18: Injection Emissions
A19: Aqueous Yield | B19: 75500
A20: [MRV] Biomass Miles | B20: ='Jun 26 PP Summary'!C14 -> 354.5
A21: [MRV] Raw Biomass Tonnes | B21: ='Jun 26 PP Summary'!C13 -> 109.03
A22: [MRV] Linear Feet Consumed | B22: --
A23: [MRV] Uncertainty Adjusted Propane Used | B23: ='Jun 26 PP Summary'!C25 -> 5320.7398
A24: [MRV] Uncertainty Adjusted Diesel Used | B24: ='Jun 26 PP Summary'!C36 -> 1010.2133
A25: [MRV] Uncertainty Adjusted Gasoline Used | B25: ='Jun 26 PP Summary'!C46 -> 122.48412
A26: [MRV] Uncertainty Adjusted Electricity | B26: ='Jun 26 PP Summary'!C59 -> 34933.411
A27: [MRV] Total Water Used | B27: ='Jun 26 PP Summary'!C73 -> 33624.463
