Workbook

Sheet Feb 26 PP Summary
A1: Process Emissions | H1: Embodied Emissions | M1: Output Type | N1: Mass of Output (kg) | O1: % Output Mass | P1: C Content (%) | Q1: C Content Mass (kg) | R1: % C Content Mass | S1: Total Emissions Allocated to Fraction (MT CO2e) | T1: Kg Emissions/Kg Material
M2: WODO | N2: 10966 | O2: =N2/($N$2+$N$3+$N$4) -> 0.19989843 | P2: 0.5238 | Q2: =P2*N2 -> 5743.9908 | R2: =Q2/(SUM($Q$2+$Q$3+$Q$4)) -> 0.40981955 | S2: =R2*$I$32 -> 9.3199609 | T2: =(S2*1000)/N2 -> 0.84989612
A3: Biomass Transport | E3: Pyrolyzer Up-Time | H3: Equipment Amortization | M3: Biochar | N3: 6766.26 | O3: =N3/($N$2+$N$3+$N$4) -> 0.12334167 | P3: 0.7726 | Q3: =P3*N3 -> 5227.6125 | R3: =Q3/(SUM($Q$2+$Q$3+$Q$4)) -> 0.37297723 | S3: =R3*$I$32 -> 8.4821069 | T3: =(S3*1000)/N3 -> 1.2535887
B4: New Pile | E4: Total Operating Hours | F4: 1502.7 | I4: Total Biomass Consumed (kg) | J4: 47976 | M4: Aqueous | N4: 37125.6 | O4: =N4/($N$2+$N$3+$N$4) -> 0.6767599 | P4: 0.082 | Q4: =P4*N4 -> 3044.2992 | R4: =Q4/(SUM($Q$2+$Q$3+$Q$4)) -> 0.21720322 | S4: =R4*$I$32 -> 4.9395534 | T4: =(S4*1000)/N4 -> 0.13304979
B5: Process Emissions | C5: 1.41722 | E5: Production Operating Hours | F5: 1502.7 | I5: Total Biomass Consumed (MT) | J5: =J4/1000 -> 47.976
B6: Embodied Emissions | C6: 0.094390388 | E6: R+D Operating Hours | F6: 0 | I6: Biomass Amortization Factor for PP (kg Co2e/MT biomass) | J6: 65.48
B7: Log Handling Emissions | C7: 0.28589085 | E7: % Production | F7: =F5/F4 -> 1 | I7: Total Amortized Embodied Emissions (kg) | J7: =J6*J5 -> 3141.4685
E8: % R+D | F8: =F6/F4 -> 0 | I8: Total Amortized Embodied Emissions (MT) | J8: =J7/1000 -> 3.1414685
B9: Total Emissions | C9: =SUM(C5:C7) -> 1.7975013 | H9: Spare Parts and Consumables
B10: BCU's Applied | C10: =SUM(C5,C7) -> 1.7031109 | E10: Total Procured Renewables | I10: EE Estimate per Pyrolyzer Operating Hour (kgCO2e) | J10: 0.83351
B11: Remaining Emissions to Allocate | C11: =C9-C10 -> 0.094390388 | E11: RD BCUs (MT CO2e) | F11: =Sum(C10,C39,C81,C89) -> 14.302908 | I11: Spare Parts and Consumables Estimate for Period (kg) | J11: =J10*(F5*(1.01)) -> 1265.0406
E12: RECs (kWh) | F12: =C62 -> 35984.816 | I12: Spare Parts and Consumables Estimate for Period (MT) | J12: =J11/1000 -> 1.2650406
B13: Tonnes | C13: 188.23583
B14: Miles | C14: 489.6
B15: Tonne-Miles | C15: 10240.029
A17: Propane Combustion
B18: Total PP Deliveries (L) | C18: 8648.53 | H18: Consolidated Emissions Inventory (No GHG Neutralization) | I18: Total Emissions (MT) | J18: % of Total
B19: Tank Level at PP Close (%) | C19: 0.49 | H19: Biomass Transport | I19: =C9*F7 -> 1.7975013 | J19: =I19/$I$32 -> 0.079040155
B20: Tank Level at PP Close (L) | C20: 1854.65 | H20: Propane | I20: =C27*F7 -> 14.30157 | J20: =I20/$I$32 -> 0.62887206
B21: Total Propane Consumption for PP (L) | C21: 7702.28 | H21: Diesel | I21: =C40*F7 -> 0 | J21: =I21/$I$32 -> 0
B22: Total Propane Consumption for PP (Gal) | C22: 2034.78 | H22: Gasoline | I22: =C48*F7 -> 0.5235356 | J22: =I22/$I$32 -> 0.023021032
B23: Total Propane Consumption for PP (kg) | C23: 3889.65 | H23: Electricity | I23: =C64*F7 -> 1.3224204 | J23: =I23/$I$32 -> 0.058149786
B24: Fuel Meter Uncertainty | C24: 0.0129 | H24: Tailgas | I24: =C69*F7 -> 0.092655194 | J24: =I24/$I$32 -> 0.0040742563
B25: Uncertainty Adjusted Total | C25: =C23*(1+C24) -> 3939.8265 | H25: Water | I25: =C75*F7 -> 0.011968964 | J25: =I25/$I$32 -> 0.00052630215
B26: Propane Combustion Emission Factor (kg CO2e/kg) | C26: ='Emission Factors'!E15*1000 -> 3.63 | H26: Consumables Delivery | I26: =C82*F7 -> 0.031 | J26: =I26/$I$32 -> 0.0013631394
B27: Total Propane Emissions (MT CO2e) | C27: =(C25*C26)/1000 -> 14.30157 | H27: Waste Disposal | I27: =C90*F7 -> 0.25446052 | J27: =I27/$I$32 -> 0.011189199
H28: Capital Goods EE | I28: =J8*F7 -> 3.1414685 | J28: =I28/$I$32 -> 0.1381374
A29: Diesel Combustion | H29: SP+C EE | I29: =J12*F7 -> 1.2650406 | J29: =I29/$I$32 -> 0.055626669
B30: Total Diesel Consumption for PP (L) | C30: 3721.06
B31: Total Diesel Consumption for PP (Gal) | C31: 983
B32: Total Diesel Fills in Office Generator for PP (Gal) | C32: 0 | H32: Total | I32: =SUM(I19:I30) -> 22.741621
B33: Total Production Diesel Consumption for PP (Gal) | C33: 983
B34: Total Production Diesel Consumption for PP (kg) | C34: 3162.56
B35: Fuel Meter Uncertainty | C35: 0.0129
B36: Uncertainty Adjusted Total | C36: =C34*(1+C35) -> 3203.357
B37: Diesel Combustion Emission Factor (kg CO2e/kg) | C37: ='Emission Factors'!E14*1000 -> 3.87
B38: Total Diesel Emissions (MT CO2e) | C38: =(C37*C36)/1000 -> 12.396992
B39: BCUs Applied (MT CO2e) | C39: =C38 -> 12.396992
B40: Remaining Emissions to Allocate (MT CO2e) | C40: =C38-C39 -> 0
A42: Gasoline Combustion
...

Sheet Emission Factors
A1: Emission Factors
A2: Emissions Factor | B2: Unit | C2: Baseline Quantity | D2: Uncertainty Factor | E2: Final Quantity | F2: Source
A3: Truck Transport Fuel Use (Well to Wheel) -- Flatbed Truck | B3: MT CO2e/t-mi | C3: 0.000135156 | D3: N/A | E3: =C3 -> 0.000135156 | F3: GLEC V3.0 2024
A4: Truck Transport Fuel Use (Well to Wheel) -- Tanker Truck | B4: MT CO2e/t-mi | C4: 0.00011263 | D4: N/A | E4: =C4 -> 0.00011263 | F4: GLEC V3.0 2024
A5: Vehicle Embodied Emissions --Tanker Truck | B5: MT CO2e/mi | C5: 7.8799528e-05 | D5: N/A | E5: =C5 -> 7.8799528e-05 | F5: USEPA/GREET 2024
A6: Vehicle Embodied Emissions --Non-Tanker Truck | B6: MT CO2e/mi | C6: 6.44927e-05 | D6: N/A | E6: =C6 -> 6.44927e-05 | F6: USEPA/GREET 2024
A7: Embodied Emissions -- Liquid Caustic Soda (50% NaOH) | B7: MTCO2e/T LCS | C7: 0.89272 | D7: 0.0012002604 | E7: =D7+C7 -> 0.89392026 | F7: GREET 2024
A8: Electricity Use -- Kansas | B8: MTCO2e/kWh | C8: 0.00051089347 | D8: N/A | E8: =C8 -> 0.00051089347 | F8: Green-E,USEPA, GREET 2024
A9: Electricity Use -- Kansas w/ Wind RECs | B9: MTCO2e/kWh | C9: =0.01004415071/1000 -> 1.0044151e-05 | D9: N/A | E9: =C9 -> 1.0044151e-05 | F9: Green-E,USEPA, GREET 2024
A10: Electricity Use -- Colorado | B10: MTCO2e/kWh | C10: 0.00052490069 | D10: N/A | E10: =C10 -> 0.00052490069 | F10: Green-E,USEPA, GREET 2024
A11: Electricity Use -- Colorado w/ Solar RECs | B11: MTCO2e/kWh | C11: =0.03674940003/1000 -> 3.67494e-05 | D11: N/A | E11: =C11 -> 3.67494e-05 | F11: Green-E,USEPA, GREET 2024
A12: Vaulted Equipment Embodied Emissions | B12: MT CO2e/MT Injectate | C12: 0.00010343352 | D12: N/A | E12: =C12 -> 0.00010343352 | F12: Vaulted PDD
A13: Self-Loading Truck Lumber Handling (No Transport) | B13: MT CO2e/MT logs | C13: 0.0015187908 | D13: N/A | E13: =C13 -> 0.0015187908 | F13: Auburn University
A14: Diesel Fuel Combustion (Total WTW) | B14: MTCO2e/kg fuel | C14: 0.00387 | D14: N/A | E14: =C14 -> 0.00387 | F14: GLEC V3.0 2024
A15: LPG Consumption (Total WTW) | B15: MTCO2e/kg fuel | C15: 0.00363 | D15: N/A | E15: =C15 -> 0.00363 | F15: GLEC V3.0 2024
A16: Gasoline Consumption (Total WTW) | B16: MTCO2e/kg fuel | C16: 0.00374 | D16: N/A | E16: =C16 -> 0.00374 | F16: GLEC V3.0 2024
A17: Drinking Water -- US | B17: MTCO2e/gal water | C17: 1.7412898e-06 | D17: N/A | E17: =C17 -> 1.7412898e-06 | F17: https://www.sciencedirect.com/science/article/abs/pii/S0959652621030110

Sheet DataTable
B2: ='Feb 26 PP Summary'!E5 -> Production Operating Hours | C2: ='Feb 26 PP Summary'!F5 -> 1502.7
B3: ='Feb 26 PP Summary'!I5 -> Total Biomass Consumed (MT) | C3: ='Feb 26 PP Summary'!J5 -> 47.976
B4: =#REF! -> #REF! | C4: =#REF! -> #REF!
A5: Propane (kg) | B5: ='Feb 26 PP Summary'!B25 -> Uncertainty Adjusted Total | C5: ='Feb 26 PP Summary'!C25 -> 3939.8265
A6: Diesel (kg) | B6: ='Feb 26 PP Summary'!B36 -> Uncertainty Adjusted Total | C6: ='Feb 26 PP Summary'!C36 -> 3203.357
A7: Gasoline (kg) | B7: ='Feb 26 PP Summary'!B46 -> Uncertainty Adjusted Total
B10: ='Feb 26 PP Summary'!H19 -> Biomass Transport | C10: ='Feb 26 PP Summary'!I19 -> 1.7975013
B11: ='Feb 26 PP Summary'!H20 -> Propane | C11: ='Feb 26 PP Summary'!I20 -> 14.30157
B12: ='Feb 26 PP Summary'!H21 -> Diesel | C12: ='Feb 26 PP Summary'!I21 -> 0
B13: ='Feb 26 PP Summary'!H22 -> Gasoline | C13: ='Feb 26 PP Summary'!I22 -> 0.5235356
B14: ='Feb 26 PP Summary'!H23 -> Electricity | C14: ='Feb 26 PP Summary'!I23 -> 1.3224204
B15: ='Feb 26 PP Summary'!H24 -> Tailgas | C15: ='Feb 26 PP Summary'!I24 -> 0.092655194
B16: ='Feb 26 PP Summary'!H25 -> Water | C16: ='Feb 26 PP Summary'!I25 -> 0.011968964
B17: ='Feb 26 PP Summary'!H26 -> Consumables Delivery | C17: ='Feb 26 PP Summary'!I26 -> 0.031
B18: ='Feb 26 PP Summary'!H27 -> Waste Disposal | C18: ='Feb 26 PP Summary'!I27 -> 0.25446052
B19: ='Feb 26 PP Summary'!H28 -> Capital Goods EE | C19: ='Feb 26 PP Summary'!I28 -> 3.1414685
B20: ='Feb 26 PP Summary'!H29 -> SP+C EE | C20: ='Feb 26 PP Summary'!I29 -> 1.2650406
B21: ='Feb 26 PP Summary'!H32 -> Total | C21: ='Feb 26 PP Summary'!I32 -> 22.741621

Sheet DataCollection
A1: Production Operating Hours | B1: ='Feb 26 PP Summary'!F5 -> 1502.7
A2: Total BM Consumed | B2: ='Feb 26 PP Summary'!J5 -> 47.976
A3: WODO Yield | B3: ='Feb 26 PP Summary'!N2 -> 10966
A4: WODO wt%C | B4: ='Feb 26 PP Summary'!P2 -> 0.5238
A5: Biochar Yield | B5: ='Feb 26 PP Summary'!N3 -> 6766.26
A6: Biochar wt%C | B6: ='Feb 26 PP Summary'!P3 -> 0.7726
A7: Biomass Transport | B7: ='Feb 26 PP Summary'!I19 -> 1.7975013
A8: Propane | B8: ='Feb 26 PP Summary'!I20 -> 14.30157
A9: Diesel | B9: ='Feb 26 PP Summary'!I21 -> 0
A10: Gasoline | B10: ='Feb 26 PP Summary'!I22 -> 0.5235356
A11: Electricity | B11: ='Feb 26 PP Summary'!I23 -> 1.3224204
A12: Tailgas | B12: ='Feb 26 PP Summary'!I24 -> 0.092655194
A13: Water | B13: ='Feb 26 PP Summary'!I25 -> 0.011968964
A14: Consumables Delivery | B14: ='Feb 26 PP Summary'!I26 -> 0.031
A15: Waste Disposal | B15: ='Feb 26 PP Summary'!I27 -> 0.25446052
A16: Capital Goods EE | B16: ='Feb 26 PP Summary'!I28 -> 3.1414685
A17: SP+C EE | B17: ='Feb 26 PP Summary'!I29 -> 1.2650406
A18: Injection Emissions
A19: Aqueous Yield | B19: 75500
A20: [MRV] Biomass Miles | B20: ='Feb 26 PP Summary'!C14 -> 489.6
A21: [MRV] Raw Biomass Tonnes | B21: ='Feb 26 PP Summary'!C13 -> 188.23583
A22: [MRV] Linear Feet Consumed | B22: --
A23: [MRV] Uncertainty Adjusted Propane Used | B23: ='Feb 26 PP Summary'!C25 -> 3939.8265
A24: [MRV] Uncertainty Adjusted Diesel Used | B24: ='Feb 26 PP Summary'!C36 -> 3203.357
A25: [MRV] Uncertainty Adjusted Gasoline Used | B25: ='Feb 26 PP Summary'!C46 -> 139.98278
A26: [MRV] Uncertainty Adjusted Electricity | B26: ='Feb 26 PP Summary'!C59 -> 35984.816
A27: [MRV] Total Water Used | B27: ='Feb 26 PP Summary'!C73 -> 26051.02
