Workbook

Sheet Usage Guide
A1: Tab | B1: Tab purpose
A2: Summary | B2: Overall metrics on all the GHG entries in this data download | J2: highlighted columns indicate the primary value for a sheet
A3: GHG Entry | B3: A list of high level metrics for individual GHG entries that are part of this data download
A4: GHG Entry Component | B4: A list of the GHG entry components that are attributed to GHG entries
A5: Component | B5: A list of the components used to create GHG entry components
A6: Expression | B6: A list of the formulae used to calculate components from selected datapoints
A7: Datapoint | B7: All scalar datapoints used as part of expressions in GHG entry quantification
A8: Source | B8: A list of sources evidencing datapoints
A9: List Values | B9: All list datapoints used as part of expressions in GHG entry quantification
A10: Measurement Locations | B10: A list of measurement locations used in datapoints

Sheet Summary
A1: This is an export from the Isometric Certify platform
A2: Go to your account at https://registry.isometric.com/ to see this data live in the platform
A4: Exported generated at | B4: 46241.806
A6: Supplier name | B6: Charm Industrial
A7: Project name | B7: Charm Range & Plains Biochar
A8: Project ID | B8: prj_1JN6XNWDQ1S0BSN7
A9: Project url | B9: https://to.isometric.com/prj_1JN6XNWDQ1S0BSN7
A11: Number of GHG entries | B11: 31
A12: Total CO₂e removed being claimed (t) | B12: =SUM('GHG Entry'!G2:G33)/1000
A13: For further information on uncertainty, counterfactuals and LCA assumptions see the associated Project Design Document.

Sheet GHG Entry
A1: GHG Entry ID | B1: Supplier reference ID | C1: Date GHG entry started | D1: Date GHG entry completed | E1: GHG Entry Status | F1: Feedstock type | G1: Discounted CO₂e net removed, rounded (kg) | H1: Discounted CO₂e net removed (kg) | I1: CO₂e net removed before discount (kg) | J1: CO₂e uncertainty discount (kg) | K1: CO₂e gross removed (kg) | L1: CO₂e emitted (kg) | M1: Counterfactual CO₂e flux (kg) | N1: Loss CO₂e flux (kg) | O1: Reductions CO₂e flux (kg) | P1: Manually applied uncertainty discount CO₂e flux (kg)
A3: rmv_1KWCC0FY31S0QD5T | B3: ba_qmYrgSRZl4GSSb1G | C3: 46172 | D3: 46172 | E3: draft | G3: =ROUND(H3, -1) | H3: =I3 - J3 | I3: =K3 - L3 - M3 - N3 + O3 - P3 | J3: 0 | K3: ='GHG Entry Component'!I4 | L3: ='GHG Entry Component'!I3+'GHG Entry Component'!I7+'GHG Entry Component'!I5+'GHG Entry Component'!I6+'GHG Entry Component'!I9 | M3: 0 | N3: 0 | O3: ='GHG Entry Component'!I8 | P3: 0
A4: rmv_1KWCSDFQF1S0CSCB | B4: ba_9kP9SwYZMlGNTqqx | C4: 46172 | D4: 46172 | E4: draft | G4: =ROUND(H4, -1) | H4: =I4 - J4 | I4: =K4 - L4 - M4 - N4 + O4 - P4 | J4: 0 | K4: ='GHG Entry Component'!I13 | L4: ='GHG Entry Component'!I12+'GHG Entry Component'!I11+'GHG Entry Component'!I14+'GHG Entry Component'!I10 | M4: 0 | N4: 0 | O4: ='GHG Entry Component'!I15 | P4: 0
A5: rmv_1KWCY0G8W1S0931T | B5: ba_tHRLhKtxK34N9epQ | C5: 46172 | D5: 46172 | E5: draft | G5: =ROUND(H5, -1) | H5: =I5 - J5 | I5: =K5 - L5 - M5 - N5 + O5 - P5 | J5: 0 | K5: ='GHG Entry Component'!I19 | L5: ='GHG Entry Component'!I18+'GHG Entry Component'!I17+'GHG Entry Component'!I20+'GHG Entry Component'!I16 | M5: 0 | N5: 0 | O5: ='GHG Entry Component'!I21 | P5: 0
A6: rmv_1KWCZP1M61S02KMH | B6: ba_T8zfcMUbDDHUruuA | C6: 46172 | D6: 46172 | E6: draft | G6: =ROUND(H6, -1) | H6: =I6 - J6 | I6: =K6 - L6 - M6 - N6 + O6 - P6 | J6: 0 | K6: ='GHG Entry Component'!I23 | L6: ='GHG Entry Component'!I22+'GHG Entry Component'!I26+'GHG Entry Component'!I24+'GHG Entry Component'!I25 | M6: 0 | N6: 0 | O6: ='GHG Entry Component'!I27 | P6: 0
A7: rmv_1KXE4AHAG1S0AK0A | B7: ba_lwnWhNsjh8WoV53l | C7: 46172 | D7: 46172 | E7: draft | G7: =ROUND(H7, -1) | H7: =I7 - J7 | I7: =K7 - L7 - M7 - N7 + O7 - P7 | J7: 0 | K7: ='GHG Entry Component'!I31 | L7: ='GHG Entry Component'!I30+'GHG Entry Component'!I29+'GHG Entry Component'!I32+'GHG Entry Component'!I28 | M7: 0 | N7: 0 | O7: ='GHG Entry Component'!I33 | P7: 0
A8: rmv_1KXEA1TH21S04EG0 | B8: ba_Z9EfWkX89iM3ii1v | C8: 46172 | D8: 46172 | E8: draft | G8: =ROUND(H8, -1) | H8: =I8 - J8 | I8: =K8 - L8 - M8 - N8 + O8 - P8 | J8: 0 | K8: ='GHG Entry Component'!I36 | L8: ='GHG Entry Component'!I35+'GHG Entry Component'!I34+'GHG Entry Component'!I37+'GHG Entry Component'!I38 | M8: 0 | N8: 0 | O8: ='GHG Entry Component'!I39 | P8: 0
A9: rmv_1KXEBV2PW1S0A79A | B9: ba_VWf4sxkY2EscDW5o | C9: 46172 | D9: 46172 | E9: draft | G9: =ROUND(H9, -1) | H9: =I9 - J9 | I9: =K9 - L9 - M9 - N9 + O9 - P9 | J9: 0 | K9: ='GHG Entry Component'!I43 | L9: ='GHG Entry Component'!I42+'GHG Entry Component'!I41+'GHG Entry Component'!I44+'GHG Entry Component'!I40 | M9: 0 | N9: 0 | O9: ='GHG Entry Component'!I45 | P9: 0
A10: rmv_1KXECAV741S0SM2Q | B10: ba_oE4jAK80l7BJyFMg | C10: 46172 | D10: 46172 | E10: draft | G10: =ROUND(H10, -1) | H10: =I10 - J10 | I10: =K10 - L10 - M10 - N10 + O10 - P10 | J10: 0 | K10: ='GHG Entry Component'!I49 | L10: ='GHG Entry Component'!I48+'GHG Entry Component'!I47+'GHG Entry Component'!I50+'GHG Entry Component'!I46 | M10: 0 | N10: 0 | O10: ='GHG Entry Component'!I51 | P10: 0
A11: rmv_1KXEHAAVZ1S0VXRD | B11: ba_yYdKOBIvyBMfCOdf | C11: 46179 | D11: 46179 | E11: draft | G11: =ROUND(H11, -1) | H11: =I11 - J11 | I11: =K11 - L11 - M11 - N11 + O11 - P11 | J11: 0 | K11: ='GHG Entry Component'!I53 | L11: ='GHG Entry Component'!I52+'GHG Entry Component'!I56+'GHG Entry Component'!I54+'GHG Entry Component'!I55 | M11: 0 | N11: 0 | O11: ='GHG Entry Component'!I57 | P11: 0
A12: rmv_1KXEJCGYM1S09J0R | B12: ba_ZmHB6yt6Jtzs0PTW | C12: 46179 | D12: 46179 | E12: draft | G12: =ROUND(H12, -1) | H12: =I12 - J12 | I12: =K12 - L12 - M12 - N12 + O12 - P12 | J12: 0 | K12: ='GHG Entry Component'!I61 | L12: ='GHG Entry Component'!I60+'GHG Entry Component'!I59+'GHG Entry Component'!I62+'GHG Entry Component'!I58 | M12: 0 | N12: 0 | O12: ='GHG Entry Component'!I63 | P12: 0
A13: rmv_1KXEJD28G1S07DZM | B13: ba_Sm5nzKG9gj21Dxl1 | C13: 46179 | D13: 46179 | E13: draft | G13: =ROUND(H13, -1) | H13: =I13 - J13 | I13: =K13 - L13 - M13 - N13 + O13 - P13 | J13: 0 | K13: ='GHG Entry Component'!I66 | L13: ='GHG Entry Component'!I65+'GHG Entry Component'!I64+'GHG Entry Component'!I67+'GHG Entry Component'!I68 | M13: 0 | N13: 0 | O13: ='GHG Entry Component'!I69 | P13: 0
A14: rmv_1KXERCP431S0TG4A | B14: ba_7FH3EjYwQp16ttVc | C14: 46179 | D14: 46179 | E14: draft | G14: =ROUND(H14, -1) | H14: =I14 - J14 | I14: =K14 - L14 - M14 - N14 + O14 - P14 | J14: 0 | K14: ='GHG Entry Component'!I71 | L14: ='GHG Entry Component'!I70+'GHG Entry Component'!I74+'GHG Entry Component'!I72+'GHG Entry Component'!I73 | M14: 0 | N14: 0 | O14: ='GHG Entry Component'!I75 | P14: 0
A15: rmv_1KXERD7151S0RC36 | B15: ba_bVEAvO9legIMhHcD | C15: 46179 | D15: 46179 | E15: draft | G15: =ROUND(H15, -1) | H15: =I15 - J15 | I15: =K15 - L15 - M15 - N15 + O15 - P15 | J15: 0 | K15: ='GHG Entry Component'!I77 | L15: ='GHG Entry Component'!I76+'GHG Entry Component'!I80+'GHG Entry Component'!I78+'GHG Entry Component'!I79 | M15: 0 | N15: 0 | O15: ='GHG Entry Component'!I81 | P15: 0
A16: rmv_1KXGK2Y3V1S0HT4A | B16: ba_fcqDPyfocSyfS0ba | C16: 46179 | D16: 46179 | E16: draft | G16: =ROUND(H16, -1) | H16: =I16 - J16 | I16: =K16 - L16 - M16 - N16 + O16 - P16 | J16: 0 | K16: ='GHG Entry Component'!I86 | L16: ='GHG Entry Component'!I85+'GHG Entry Component'!I84+'GHG Entry Component'!I82+'GHG Entry Component'!I83 | M16: 0 | N16: 0 | O16: ='GHG Entry Component'!I87 | P16: 0
A17: rmv_1KXGK3HP81S0FP36 | B17: ba_R4Vr8Bfn1uspC4R1 | C17: 46179 | D17: 46179 | E17: draft | G17: =ROUND(H17, -1) | H17: =I17 - J17 | I17: =K17 - L17 - M17 - N17 + O17 - P17 | J17: 0 | K17: ='GHG Entry Component'!I92 | L17: ='GHG Entry Component'!I91+'GHG Entry Component'!I90+'GHG Entry Component'!I88+'GHG Entry Component'!I89 | M17: 0 | N17: 0 | O17: ='GHG Entry Component'!I93 | P17: 0
A18: rmv_1KXGK45BZ1S0DJ22 | B18: ba_OPir9NJcYGrhzD92 | C18: 46179 | D18: 46179 | E18: draft | G18: =ROUND(H18, -1) | H18: =I18 - J18 | I18: =K18 - L18 - M18 - N18 + O18 - P18 | J18: 0 | K18: ='GHG Entry Component'!I97 | L18: ='GHG Entry Component'!I96+'GHG Entry Component'!I95+'GHG Entry Component'!I98+'GHG Entry Component'!I94 | M18: 0 | N18: 0 | O18: ='GHG Entry Component'!I99 | P18: 0
A19: rmv_1KXGK4R131S095PN | B19: ba_SEeVg0i26QTA0MGj | C19: 46179 | D19: 46179 | E19: draft | G19: =ROUND(H19, -1) | H19: =I19 - J19 | I19: =K19 - L19 - M19 - N19 + O19 - P19 | J19: 0 | K19: ='GHG Entry Component'!I102 | L19: ='GHG Entry Component'!I105+'GHG Entry Component'!I101+'GHG Entry Component'!I100+'GHG Entry Component'!I103 | M19: 0 | N19: 0 | O19: ='GHG Entry Component'!I104 | P19: 0
A20: rmv_1KXGK5BMT1S0H4FK | B20: ba_Ab0wKI6z4meTsSHJ | C20: 46179 | D20: 46179 | E20: draft | G20: =ROUND(H20, -1) | H20: =I20 - J20 | I20: =K20 - L20 - M20 - N20 + O20 - P20 | J20: 0 | K20: ='GHG Entry Component'!I109 | L20: ='GHG Entry Component'!I111+'GHG Entry Component'!I108+'GHG Entry Component'!I107+'GHG Entry Component'!I106 | M20: 0 | N20: 0 | O20: ='GHG Entry Component'!I110 | P20: 0
A21: rmv_1KXKGW8131S0DAD9 | B21: manual-charm-biochar-D2-254 | C21: 46172 | D21: 46172 | E21: draft | G21: =ROUND(H21, -1) | H21: =I21 - J21 | I21: =K21 - L21 - M21 - N21 + O21 - P21 | J21: 0 | K21: ='GHG Entry Component'!I115 | L21: ='GHG Entry Component'!I114+'GHG Entry Component'!I112+'GHG Entry Component'!I116 | M21: 0 | N21: 0 | O21: ='GHG Entry Component'!I113 | P21: 0
A22: rmv_1KXKGXJB61S01MAJ | B22: manual-charm-biochar-D3-254 | C22: 46179 | D22: 46179 | E22: draft | G22: =ROUND(H22, -1) | H22: =I22 - J22 | I22: =K22 - L22 - M22 - N22 + O22 - P22 | J22: 0 | K22: ='GHG Entry Component'!I118 | L22: ='GHG Entry Component'!I117+'GHG Entry Component'!I120+'GHG Entry Component'!I119 | M22: 0 | N22: 0 | O22: ='GHG Entry Component'!I121 | P22: 0
A23: rmv_1KXKP77Q21S08Q74 | B23: manual-charm-biochar-D3-252 | C23: 46179 | D23: 46179 | E23: draft | G23: =ROUND(H23, -1) | H23: =I23 - J23 | I23: =K23 - L23 - M23 - N23 + O23 - P23 | J23: 0 | K23: ='GHG Entry Component'!I125 | L23: ='GHG Entry Component'!I124+'GHG Entry Component'!I123+'GHG Entry Component'!I126+'GHG Entry Component'!I122 | M23: 0 | N23: 0 | O23: ='GHG Entry Component'!I127 | P23: 0
A24: rmv_1KY02PC6H1S0D393 | B24: ba_WhokCybTDfXx5J9b | C24: 46042 | D24: 46042 | E24: draft | G24: =ROUND(H24, -1) | H24: =I24 - J24 | I24: =K24 - L24 - M24 - N24 + O24 - P24 | J24: 0 | K24: ='GHG Entry Component'!I130 | L24: ='GHG Entry Component'!I133+'GHG Entry Component'!I129+'GHG Entry Component'!I128+'GHG Entry Component'!I131+'GHG Entry Component'!I134 | M24: 0 | N24: 0 | O24: ='GHG Entry Component'!I132 | P24: 0
A25: rmv_1KY02PYB11S0N221 | B25: ba_KgcBuWQUZqU1iIh0 | C25: 46042 | D25: 46042 | E25: draft | G25: =ROUND(H25, -1) | H25: =I25 - J25 | I25: =K25 - L25 - M25 - N25 + O25 - P25 | J25: 0 | K25: ='GHG Entry Component'!I135 | L25: ='GHG Entry Component'!I140+'GHG Entry Component'!I138+'GHG Entry Component'!I137+'GHG Entry Component'!I136 | M25: 0 | N25: 0 | O25: ='GHG Entry Component'!I139 | P25: 0
A26: rmv_1KY38KE1C1S03T2H | B26: ba_ouUP380dPZPm3TwY | C26: 46101 | D26: 46101 | E26: draft | G26: =ROUND(H26, -1) | H26: =I26 - J26 | I26: =K26 - L26 - M26 - N26 + O26 - P26 | J26: 0 | K26: ='GHG Entry Component'!I143 | L26: ='GHG Entry Component'!I146+'GHG Entry Component'!I142+'GHG Entry Component'!I141+'GHG Entry Component'!I144 | M26: 0 | N26: 0 | O26: ='GHG Entry Component'!I145 | P26: 0
A27: rmv_1KY57M9F81S03MK6 | B27: ba_TMAR7Xx3vwC16Jan | C27: 46092 | D27: 46092 | E27: draft | G27: =ROUND(H27, -1) | H27: =I27 - J27 | I27: =K27 - L27 - M27 - N27 + O27 - P27 | J27: 0 | K27: ='GHG Entry Component'!I149 | L27: ='GHG Entry Component'!I152+'GHG Entry Component'!I148+'GHG Entry Component'!I147+'GHG Entry Component'!I150 | M27: 0 | N27: 0 | O27: ='GHG Entry Component'!I151 | P27: 0
A28: rmv_1KY57MT101S0BKC4 | B28: ba_tyHD61LKMjHX0tm8 | C28: 46092 | D28: 46092 | E28: draft | G28: =ROUND(H28, -1) | H28: =I28 - J28 | I28: =K28 - L28 - M28 - N28 + O28 - P28 | J28: 0 | K28: ='GHG Entry Component'!I155 | L28: ='GHG Entry Component'!I158+'GHG Entry Component'!I154+'GHG Entry Component'!I153+'GHG Entry Component'!I156 | M28: 0 | N28: 0 | O28: ='GHG Entry Component'!I157 | P28: 0
A29: rmv_1KY57NCC21S0TVWC | B29: ba_k5O479XvMebZlTY5 | C29: 46092 | D29: 46092 | E29: draft | G29: =ROUND(H29, -1) | H29: =I29 - J29 | I29: =K29 - L29 - M29 - N29 + O29 - P29 | J29: 0 | K29: ='GHG Entry Component'!I160 | L29: ='GHG Entry Component'!I159+'GHG Entry Component'!I163+'GHG Entry Component'!I161+'GHG Entry Component'!I162 | M29: 0 | N29: 0 | O29: ='GHG Entry Component'!I164 | P29: 0
A30: rmv_1KY5G7F3N1S0MPZX | B30: ba_STp6R7r1eTkvhMC4 | C30: 46092 | D30: 46092 | E30: draft | G30: =ROUND(H30, -1) | H30: =I30 - J30 | I30: =K30 - L30 - M30 - N30 + O30 - P30 | J30: 0 | K30: ='GHG Entry Component'!I165 | L30: ='GHG Entry Component'!I170+'GHG Entry Component'!I168+'GHG Entry Component'!I167+'GHG Entry Component'!I166 | M30: 0 | N30: 0 | O30: ='GHG Entry Component'!I169 | P30: 0
A31: rmv_1KYA6ANEE1S0PW7F | B31: ba_Mnyp1ajWTFoo2VkH | C31: 46042 | D31: 46042 | E31: draft | G31: =ROUND(H31, -1) | H31: =I31 - J31 | I31: =K31 - L31 - M31 - N31 + O31 - P31 | J31: 0 | K31: ='GHG Entry Component'!I172 | L31: ='GHG Entry Component'!I171+'GHG Entry Component'!I175+'GHG Entry Component'!I173+'GHG Entry Component'!I174+'GHG Entry Component'!I177 | M31: 0 | N31: 0 | O31: ='GHG Entry Component'!I176 | P31: 0
A32: rmv_1KYA74ZX41S0H0D1 | B32: ba_MFRsmroFCOLTWOv7 | C32: 46101 | D32: 46101 | E32: draft | G32: =ROUND(H32, -1) | H32: =I32 - J32 | I32: =K32 - L32 - M32 - N32 + O32 - P32 | J32: 0 | K32: ='GHG Entry Component'!I181 | L32: ='GHG Entry Component'!I180+'GHG Entry Component'!I179+'GHG Entry Component'!I178 | M32: 0 | N32: 0 | O32: ='GHG Entry Component'!I182 | P32: 0
A33: rmv_1KYA75EW41S07JMK | B33: ba_SK3Nd0wgGunGqQLh | C33: 46101 | D33: 46101 | E33: draft | G33: =ROUND(H33, -1) | H33: =I33 - J33 | I33: =K33 - L33 - M33 - N33 + O33 - P33 | J33: 0 | K33: ='GHG Entry Component'!I185 | L33: ='GHG Entry Component'!I184+'GHG Entry Component'!I183+'GHG Entry Component'!I186+'GHG Entry Component'!I188 | M33: 0 | N33: 0 | O33: ='GHG Entry Component'!I187 | P33: 0

Sheet GHG Entry Component
A1: GHG Entry Component ID | B1: Component ID | C1: Component name | D1: Component description | E1: Blueprint Key | F1: Blueprint Name | G1: GHG Entry ID | H1: GHG Entry Component Group Name | I1: Attributed Carbon Flux in kg | J1: CO₂e uncertainty (kg) | K1: Component Carbon Flux in kg | L1: Attribution Type | M1: Attribution Factor | N1: Attribution Factor Datapoint ID | O1: GHG Entry Component Type | P1: Date Activity Started | Q1: Date Activity Completed
A3: rvc_1KWCC0FY31S01TGP | B3: =Component!A3 | C3: Biochar Spreading Emissions | E3: mass_based_ci_emissions | F3: Mass-based CI emissions | G3: ='GHG Entry'!A3 | H3: Biochar storage | I3: =Component!D3 * Datapoint!E18 | J3: =Component!E3 * Datapoint!E18 | K3: =Component!D3 | L3: partial | M3: =Datapoint!E18 | N3: =Datapoint!A18 | O3: activity
A4: rvc_1KWCC0FY31S042TZ | B4: =Component!A4 | C4: Biochar sequestration, 200 year durability | E4: biochar_sequestration_200_year_c_org | F4: Biochar sequestration, 200 year durability | G4: ='GHG Entry'!A3 | H4: Biochar storage | I4: =Component!D4 * Datapoint!E19 | J4: =Component!E4 * Datapoint!E19 | K4: =Component!D4 | L4: partial | M4: =Datapoint!E19 | N4: =Datapoint!A19 | O4: sequestration
A5: rvc_1KWCC0FY31S09480 | B5: =Component!A5 | C5: CO Flatbed Truck Transport Embodied Emissions | E5: distance_based_ci_emissions | F5: Distance-based emissions | G5: ='GHG Entry'!A3 | H5: Biochar transportation | I5: =Component!D5 * Datapoint!E20 | J5: =Component!E5 * Datapoint!E20 | K5: =Component!D5 | L5: partial | M5: =Datapoint!E20 | N5: =Datapoint!A20 | O5: activity
A6: rvc_1KWCC0FY31S0GDZA | B6: =Component!A6 | C6: Biochar Production Emission (A) | E6: mass_based_ci_emissions | F6: Mass-based CI emissions | G6: ='GHG Entry'!A3 | H6: Biochar production | I6: =Component!D6 * Datapoint!E16 | J6: =Component!E6 * Datapoint!E16 | K6: =Component!D6 | L6: partial | M6: =Datapoint!E16 | N6: =Datapoint!A16 | O6: activity
A7: rvc_1KWCC0FY31S0NFCB | B7: =Component!A7 | C7: CO Flatbed Truck Transport Process Emissions | E7: transport | F7: Transport emissions | G7: ='GHG Entry'!A3 | H7: Biochar transportation | I7: =Component!D7 * Datapoint!E17 | J7: =Component!E7 * Datapoint!E17 | K7: =Component!D7 | L7: partial | M7: =Datapoint!E17 | N7: =Datapoint!A17 | O7: activity
A8: rvc_1KYA8BW1Q1S04Z4W | B8: =Component!A166 | C8: BCU - Transport Process | E8: constant_reduction | F8: Constant CO₂ reduction | G8: ='GHG Entry'!A3 | H8: Biochar storage | I8: =Component!D166 * Datapoint!E596 | J8: =Component!E166 * Datapoint!E596 | K8: =Component!D166 | L8: partial | M8: =Datapoint!E596 | N8: =Datapoint!A596 | O8: adjustment | P8: 46172 | Q8: 46172
A9: rvc_1KYN471V91S019ZQ | B9: =Component!A188 | C9: Over Allocated Emissions | E9: constant_activity_emissions | F9: Constant emissions | G9: ='GHG Entry'!A3 | H9: Biochar production | I9: =Component!D188 * Datapoint!E649 | J9: =Component!E188 * Datapoint!E649 | K9: =Component!D188 | L9: partial | M9: =Datapoint!E649 | N9: =Datapoint!A649 | O9: activity
A10: rvc_1KWCSDFQF1S05T5V | B10: =Component!A8 | C10: Biochar Production Emission (A) | E10: mass_based_ci_emissions | F10: Mass-based CI emissions | G10: ='GHG Entry'!A4 | H10: Biochar production | I10: =Component!D8 * Datapoint!E37 | J10: =Component!E8 * Datapoint!E37 | K10: =Component!D8 | L10: partial | M10: =Datapoint!E37 | N10: =Datapoint!A37 | O10: activity
A11: rvc_1KWCSDFQF1S0AVJW | B11: =Component!A9 | C11: CO Flatbed Truck Transport Process Emissions | E11: transport | F11: Transport emissions | G11: ='GHG Entry'!A4 | H11: Biochar transportation | I11: =Component!D9 * Datapoint!E38 | J11: =Component!E9 * Datapoint!E38 | K11: =Component!D9 | L11: partial | M11: =Datapoint!E38 | N11: =Datapoint!A38 | O11: activity
A12: rvc_1KWCSDFQF1S0Q6Q7 | B12: =Component!A10 | C12: Biochar Spreading Emissions | E12: mass_based_ci_emissions | F12: Mass-based CI emissions | G12: ='GHG Entry'!A4 | H12: Biochar storage | I12: =Component!D10 * Datapoint!E34 | J12: =Component!E10 * Datapoint!E34 | K12: =Component!D10 | L12: partial | M12: =Datapoint!E34 | N12: =Datapoint!A34 | O12: activity
A13: rvc_1KWCSDFQF1S0SF1G | B13: =Component!A11 | C13: Biochar sequestration, 200 year durability | E13: biochar_sequestration_200_year_c_org | F13: Biochar sequestration, 200 year durability | G13: ='GHG Entry'!A4 | H13: Biochar storage | I13: =Component!D11 * Datapoint!E35 | J13: =Component!E11 * Datapoint!E35 | K13: =Component!D11 | L13: partial | M13: =Datapoint!E35 | N13: =Datapoint!A35 | O13: sequestration
A14: rvc_1KWCSDFQF1S0YGEH | B14: =Component!A12 | C14: CO Flatbed Truck Transport Embodied Emissions | E14: distance_based_ci_emissions | F14: Distance-based emissions | G14: ='GHG Entry'!A4 | H14: Biochar transportation | I14: =Component!D12 * Datapoint!E36 | J14: =Component!E12 * Datapoint!E36 | K14: =Component!D12 | L14: partial | M14: =Datapoint!E36 | N14: =Datapoint!A36 | O14: activity
A15: rvc_1KYA8BNC31S0JBT5 | B15: =Component!A165 | C15: BCU - Transport Process | E15: constant_reduction | F15: Constant CO₂ reduction | G15: ='GHG Entry'!A4 | H15: Biochar storage | I15: =Component!D165 * Datapoint!E594 | J15: =Component!E165 * Datapoint!E594 | K15: =Component!D165 | L15: partial | M15: =Datapoint!E594 | N15: =Datapoint!A594 | O15: adjustment | P15: 46172 | Q15: 46172
A16: rvc_1KWCY0G8W1S023VA | B16: =Component!A13 | C16: Biochar Production Emission (A) | E16: mass_based_ci_emissions | F16: Mass-based CI emissions | G16: ='GHG Entry'!A5 | H16: Biochar production | I16: =Component!D13 * Datapoint!E55 | J16: =Component!E13 * Datapoint!E55 | K16: =Component!D13 | L16: partial | M16: =Datapoint!E55 | N16: =Datapoint!A55 | O16: activity
A17: rvc_1KWCY0G8W1S0758B | B17: =Component!A14 | C17: CO Flatbed Truck Transport Process Emissions | E17: transport | F17: Transport emissions | G17: ='GHG Entry'!A5 | H17: Biochar transportation | I17: =Component!D14 * Datapoint!E56 | J17: =Component!E14 * Datapoint!E56 | K17: =Component!D14 | L17: partial | M17: =Datapoint!E56 | N17: =Datapoint!A56 | O17: activity
A18: rvc_1KWCY0G8W1S0KGCP | B18: =Component!A15 | C18: Biochar Spreading Emissions | E18: mass_based_ci_emissions | F18: Mass-based CI emissions | G18: ='GHG Entry'!A5 | H18: Biochar storage | I18: =Component!D15 * Datapoint!E52 | J18: =Component!E15 * Datapoint!E52 | K18: =Component!D15 | L18: partial | M18: =Datapoint!E52 | N18: =Datapoint!A52 | O18: activity
A19: rvc_1KWCY0G8W1S0NRPZ | B19: =Component!A16 | C19: Biochar sequestration, 200 year durability | E19: biochar_sequestration_200_year_c_org | F19: Biochar sequestration, 200 year durability | G19: ='GHG Entry'!A5 | H19: Biochar storage | I19: =Component!D16 * Datapoint!E53 | J19: =Component!E16 * Datapoint!E53 | K19: =Component!D16 | L19: partial | M19: =Datapoint!E53 | N19: =Datapoint!A53 | O19: sequestration
A20: rvc_1KWCY0G8W1S0TT40 | B20: =Component!A17 | C20: CO Flatbed Truck Transport Embodied Emissions | E20: distance_based_ci_emissions | F20: Distance-based emissions | G20: ='GHG Entry'!A5 | H20: Biochar transportation | I20: =Component!D17 * Datapoint!E54 | J20: =Component!E17 * Datapoint!E54 | K20: =Component!D17 | L20: partial | M20: =Datapoint!E54 | N20: =Datapoint!A54 | O20: activity
A21: rvc_1KXEB42X91S0XRV2 | B21: =Component!A35 | C21: BCU - Transport Process | E21: constant_reduction | F21: Constant CO₂ reduction | G21: ='GHG Entry'!A5 | H21: Biochar transportation | I21: =Component!D35 * Datapoint!E119 | J21: =Component!E35 * Datapoint!E119 | K21: =Component!D35 | L21: partial | M21: =Datapoint!E119 | N21: =Datapoint!A119 | O21: adjustment
A22: rvc_1KWCZP1M61S0D0ZD | B22: =Component!A18 | C22: Biochar Spreading Emissions | E22: mass_based_ci_emissions | F22: Mass-based CI emissions | G22: ='GHG Entry'!A6 | H22: Biochar storage | I22: =Component!D18 * Datapoint!E70 | J22: =Component!E18 * Datapoint!E70 | K22: =Component!D18 | L22: partial | M22: =Datapoint!E70 | N22: =Datapoint!A70 | O22: activity
A23: rvc_1KWCZP1M61S0F99P | B23: =Component!A19 | C23: Biochar sequestration, 200 year durability | E23: biochar_sequestration_200_year_c_org | F23: Biochar sequestration, 200 year durability | G23: ='GHG Entry'!A6 | H23: Biochar storage | I23: =Component!D19 * Datapoint!E71 | J23: =Component!E19 * Datapoint!E71 | K23: =Component!D19 | L23: partial | M23: =Datapoint!E71 | N23: =Datapoint!A71 | O23: sequestration
A24: rvc_1KWCZP1M61S0MAPQ | B24: =Component!A20 | C24: CO Flatbed Truck Transport Embodied Emissions | E24: distance_based_ci_emissions | F24: Distance-based emissions | G24: ='GHG Entry'!A6 | H24: Biochar transportation | I24: =Component!D20 * Datapoint!E72 | J24: =Component!E20 * Datapoint!E72 | K24: =Component!D20 | L24: partial | M24: =Datapoint!E72 | N24: =Datapoint!A72 | O24: activity
A25: rvc_1KWCZP1M61S0VME1 | B25: =Component!A21 | C25: Biochar Production Emission (A) | E25: mass_based_ci_emissions | F25: Mass-based CI emissions | G25: ='GHG Entry'!A6 | H25: Biochar production | I25: =Component!D21 * Datapoint!E73 | J25: =Component!E21 * Datapoint!E73 | K25: =Component!D21 | L25: partial | M25: =Datapoint!E73 | N25: =Datapoint!A73 | O25: activity
A26: rvc_1KWCZP1M61S00NV2 | B26: =Component!A22 | C26: CO Flatbed Truck Transport Process Emissions | E26: transport | F26: Transport emissions | G26: ='GHG Entry'!A6 | H26: Biochar transportation | I26: =Component!D22 * Datapoint!E74 | J26: =Component!E22 * Datapoint!E74 | K26: =Component!D22 | L26: partial | M26: =Datapoint!E74 | N26: =Datapoint!A74 | O26: activity
A27: rvc_1KYA8C1QC1S0QJFK | B27: =Component!A167 | C27: BCU - Transport Process | E27: constant_reduction | F27: Constant CO₂ reduction | G27: ='GHG Entry'!A6 | H27: Biochar storage | I27: =Component!D167 * Datapoint!E598 | J27: =Component!E167 * Datapoint!E598 | K27: =Component!D167 | L27: partial | M27: =Datapoint!E598 | N27: =Datapoint!A598 | O27: adjustment | P27: 46172 | Q27: 46172
A28: rvc_1KXE4AHAG1S03KST | B28: =Component!A23 | C28: Biochar Production Emission (A) | E28: mass_based_ci_emissions | F28: Mass-based CI emissions | G28: ='GHG Entry'!A7 | H28: Biochar production | I28: =Component!D23 * Datapoint!E92 | J28: =Component!E23 * Datapoint!E92 | K28: =Component!D23 | L28: partial | M28: =Datapoint!E92 | N28: =Datapoint!A92 | O28: activity
A29: rvc_1KXE4AHAG1S08N6V | B29: =Component!A24 | C29: CO Flatbed Truck Transport Process Emissions | E29: transport | F29: Transport emissions | G29: ='GHG Entry'!A7 | H29: Biochar transportation | I29: =Component!D24 * Datapoint!E93 | J29: =Component!E24 * Datapoint!E93 | K29: =Component!D24 | L29: partial | M29: =Datapoint!E93 | N29: =Datapoint!A93 | O29: activity
A30: rvc_1KXE4AHAG1S0N0B6 | B30: =Component!A25 | C30: Biochar Spreading Emissions | E30: mass_based_ci_emissions | F30: Mass-based CI emissions | G30: ='GHG Entry'!A7 | H30: Biochar storage | I30: =Component!D25 * Datapoint!E89 | J30: =Component!E25 * Datapoint!E89 | K30: =Component!D25 | L30: partial | M30: =Datapoint!E89 | N30: =Datapoint!A89 | O30: activity
A31: rvc_1KXE4AHAG1S0Q8NF | B31: =Component!A26 | C31: Biochar sequestration, 200 year durability | E31: biochar_sequestration_200_year_c_org | F31: Biochar sequestration, 200 year durability | G31: ='GHG Entry'!A7 | H31: Biochar storage | I31: =Component!D26 * Datapoint!E90 | J31: =Component!E26 * Datapoint!E90 | K31: =Component!D26 | L31: partial | M31: =Datapoint!E90 | N31: =Datapoint!A90 | O31: sequestration
A32: rvc_1KXE4AHAG1S0WA2G | B32: =Component!A27 | C32: CO Flatbed Truck Transport Embodied Emissions | E32: distance_based_ci_emissions | F32: Distance-based emissions | G32: ='GHG Entry'!A7 | H32: Biochar transportation | I32: =Component!D27 * Datapoint!E91 | J32: =Component!E27 * Datapoint!E91 | K32: =Component!D27 | L32: partial | M32: =Datapoint!E91 | N32: =Datapoint!A91 | O32: activity
A33: rvc_1KYMS0Q121S08WWE | B33: =Component!A28 | C33: BCU - Transport Process | E33: constant_reduction | F33: Constant CO₂ reduction | G33: ='GHG Entry'!A7 | H33: Biochar transportation | I33: =Component!D28 * Datapoint!E644 | J33: =Component!E28 * Datapoint!E644 | K33: =Component!D28 | L33: partial | M33: =Datapoint!E644 | N33: =Datapoint!A644 | O33: adjustment
A34: rvc_1KXEA1TH21S02GPH | B34: =Component!A29 | C34: CO Flatbed Truck Transport Process Emissions | E34: transport | F34: Transport emissions | G34: ='GHG Entry'!A8 | H34: Biochar transportation | I34: =Component!D29 * Datapoint!E113 | J34: =Component!E29 * Datapoint!E113 | K34: =Component!D29 | L34: partial | M34: =Datapoint!E113 | N34: =Datapoint!A113 | O34: activity
A35: rvc_1KXEA1TH21S0EVTW | B35: =Component!A30 | C35: Biochar Spreading Emissions | E35: mass_based_ci_emissions | F35: Mass-based CI emissions | G35: ='GHG Entry'!A8 | H35: Biochar storage | I35: =Component!D30 * Datapoint!E109 | J35: =Component!E30 * Datapoint!E109 | K35: =Component!D30 | L35: partial | M35: =Datapoint!E109 | N35: =Datapoint!A109 | O35: activity
A36: rvc_1KXEA1TH21S0H455 | B36: =Component!A31 | C36: Biochar sequestration, 200 year durability | E36: biochar_sequestration_200_year_c_org | F36: Biochar sequestration, 200 year durability | G36: ='GHG Entry'!A8 | H36: Biochar storage | I36: =Component!D31 * Datapoint!E110 | J36: =Component!E31 * Datapoint!E110 | K36: =Component!D31 | L36: partial | M36: =Datapoint!E110 | N36: =Datapoint!A110 | O36: sequestration
A37: rvc_1KXEA1TH21S0P5J6 | B37: =Component!A32 | C37: CO Flatbed Truck Transport Embodied Emissions | E37: distance_based_ci_emissions | F37: Distance-based emissions | G37: ='GHG Entry'!A8 | H37: Biochar transportation | I37: =Component!D32 * Datapoint!E111 | J37: =Component!E32 * Datapoint!E111 | K37: =Component!D32 | L37: partial | M37: =Datapoint!E111 | N37: =Datapoint!A111 | O37: activity
A38: rvc_1KXEA1TH21S0XF9G | B38: =Component!A33 | C38: Biochar Production Emission (A) | E38: mass_based_ci_emissions | F38: Mass-based CI emissions | G38: ='GHG Entry'!A8 | H38: Biochar production | I38: =Component!D33 * Datapoint!E112 | J38: =Component!E33 * Datapoint!E112 | K38: =Component!D33 | L38: partial | M38: =Datapoint!E112 | N38: =Datapoint!A112 | O38: activity
A39: rvc_1KXEA3E4Q1S0XMHX | B39: =Component!A34 | C39: BCU - Transport Process | E39: constant_reduction | F39: Constant CO₂ reduction | G39: ='GHG Entry'!A8 | H39: Biochar transportation | I39: =Component!D34 * Datapoint!E114 | J39: =Component!E34 * Datapoint!E114 | K39: =Component!D34 | L39: partial | M39: =Datapoint!E114 | N39: =Datapoint!A114 | O39: adjustment
A40: rvc_1KXEBV2PW1S0382T | B40: =Component!A36 | C40: Biochar Production Emission (A) | E40: mass_based_ci_emissions | F40: Mass-based CI emissions | G40: ='GHG Entry'!A9 | H40: Biochar production | I40: =Component!D36 * Datapoint!E139 | J40: =Component!E36 * Datapoint!E139 | K40: =Component!D36 | L40: partial | M40: =Datapoint!E139 | N40: =Datapoint!A139 | O40: activity
A41: rvc_1KXEBV2PW1S089FV | B41: =Component!A37 | C41: CO Flatbed Truck Transport Process Emissions | E41: transport | F41: Transport emissions | G41: ='GHG Entry'!A9 | H41: Biochar transportation | I41: =Component!D37 * Datapoint!E140 | J41: =Component!E37 * Datapoint!E140 | K41: =Component!D37 | L41: partial | M41: =Datapoint!E140 | N41: =Datapoint!A140 | O41: activity
...

Sheet Component
A1: Component ID | B1: Blueprint Key | C1: Blueprint Name | D1: CO2 Flux in kg | E1: CO₂e uncertainty (kg) | F1: Component Type | G1: Component Scope | H1: Display Name | I1: Description | J1: Date Activity Started | K1: Date Activity Completed | L1: Supplier reference ID
A3: cmp_1KWCC0FY31S00Z7D | B3: mass_based_ci_emissions | C3: Mass-based CI emissions | D3: =Expression!E464 | E3: =Expression!F464 | F3: activity | G3: removal | H3: Biochar Spreading Emissions
A4: cmp_1KWCC0FY31S037HP | B4: biochar_sequestration_200_year_c_org | C4: Biochar sequestration, 200 year durability | D4: =Expression!E475 | E4: =Expression!F475 | F4: sequestration | G4: removal | H4: Biochar sequestration, 200 year durability
A5: cmp_1KWCC0FY31S088YQ | B5: distance_based_ci_emissions | C5: Distance-based emissions | D5: =Expression!E196 | E5: =Expression!F196 | F5: activity | G5: removal | H5: CO Flatbed Truck Transport Embodied Emissions
A6: cmp_1KWCC0FY31S0FJP1 | B6: mass_based_ci_emissions | C6: Mass-based CI emissions | D6: =Expression!E257 | E6: =Expression!F257 | F6: activity | G6: removal | H6: Biochar Production Emission (A)
A7: cmp_1KWCC0FY31S0MM32 | B7: transport | C7: Transport emissions | D7: =Expression!E157 | E7: =Expression!F157 | F7: activity | G7: removal | H7: CO Flatbed Truck Transport Process Emissions
A8: cmp_1KWCSDFQF1S04YWJ | B8: mass_based_ci_emissions | C8: Mass-based CI emissions | D8: =Expression!E155 | E8: =Expression!F155 | F8: activity | G8: removal | H8: Biochar Production Emission (A)
A9: cmp_1KWCSDFQF1S0A09K | B9: transport | C9: Transport emissions | D9: =Expression!E23 | E9: =Expression!F23 | F9: activity | G9: removal | H9: CO Flatbed Truck Transport Process Emissions
A10: cmp_1KWCSDFQF1S0PBDY | B10: mass_based_ci_emissions | C10: Mass-based CI emissions | D10: =Expression!E123 | E10: =Expression!F123 | F10: activity | G10: removal | H10: Biochar Spreading Emissions
A11: cmp_1KWCSDFQF1S0RKR7 | B11: biochar_sequestration_200_year_c_org | C11: Biochar sequestration, 200 year durability | D11: =Expression!E397 | E11: =Expression!F397 | F11: sequestration | G11: removal | H11: Biochar sequestration, 200 year durability
A12: cmp_1KWCSDFQF1S0XN58 | B12: distance_based_ci_emissions | C12: Distance-based emissions | D12: =Expression!E365 | E12: =Expression!F365 | F12: activity | G12: removal | H12: CO Flatbed Truck Transport Embodied Emissions
A13: cmp_1KWCY0G8W1S018J1 | B13: mass_based_ci_emissions | C13: Mass-based CI emissions | D13: =Expression!E442 | E13: =Expression!F442 | F13: activity | G13: removal | H13: Biochar Production Emission (A)
A14: cmp_1KWCY0G8W1S069Z2 | B14: transport | C14: Transport emissions | D14: =Expression!E336 | E14: =Expression!F336 | F14: activity | G14: removal | H14: CO Flatbed Truck Transport Process Emissions
A15: cmp_1KWCY0G8W1S0JN3D | B15: mass_based_ci_emissions | C15: Mass-based CI emissions | D15: =Expression!E220 | E15: =Expression!F220 | F15: activity | G15: removal | H15: Biochar Spreading Emissions
A16: cmp_1KWCY0G8W1S0MXDP | B16: biochar_sequestration_200_year_c_org | C16: Biochar sequestration, 200 year durability | D16: =Expression!E529 | E16: =Expression!F529 | F16: sequestration | G16: removal | H16: Biochar sequestration, 200 year durability
A17: cmp_1KWCY0G8W1S0SYTQ | B17: distance_based_ci_emissions | C17: Distance-based emissions | D17: =Expression!E270 | E17: =Expression!F270 | F17: activity | G17: removal | H17: CO Flatbed Truck Transport Embodied Emissions
A18: cmp_1KWCZP1M61S0C5P4 | B18: mass_based_ci_emissions | C18: Mass-based CI emissions | D18: =Expression!E89 | E18: =Expression!F89 | F18: activity | G18: removal | H18: Biochar Spreading Emissions
A19: cmp_1KWCZP1M61S0EE0D | B19: biochar_sequestration_200_year_c_org | C19: Biochar sequestration, 200 year durability | D19: =Expression!E120 | E19: =Expression!F120 | F19: sequestration | G19: removal | H19: Biochar sequestration, 200 year durability
A20: cmp_1KWCZP1M61S0KFDE | B20: distance_based_ci_emissions | C20: Distance-based emissions | D20: =Expression!E428 | E20: =Expression!F428 | F20: activity | G20: removal | H20: CO Flatbed Truck Transport Embodied Emissions
A21: cmp_1KWCZP1M61S0TS4R | B21: mass_based_ci_emissions | C21: Mass-based CI emissions | D21: =Expression!E22 | E21: =Expression!F22 | F21: activity | G21: removal | H21: Biochar Production Emission (A)
A22: cmp_1KWCZP1M61S0ZTHS | B22: transport | C22: Transport emissions | D22: =Expression!E66 | E22: =Expression!F66 | F22: activity | G22: removal | H22: CO Flatbed Truck Transport Process Emissions
A23: cmp_1KXE4AHAG1S02RGH | B23: mass_based_ci_emissions | C23: Mass-based CI emissions | D23: =Expression!E156 | E23: =Expression!F156 | F23: activity | G23: removal | H23: Biochar Production Emission (A)
A24: cmp_1KXE4AHAG1S07SXJ | B24: transport | C24: Transport emissions | D24: =Expression!E510 | E24: =Expression!F510 | F24: activity | G24: removal | H24: CO Flatbed Truck Transport Process Emissions
A25: cmp_1KXE4AHAG1S0M51X | B25: mass_based_ci_emissions | C25: Mass-based CI emissions | D25: =Expression!E350 | E25: =Expression!F350 | F25: activity | G25: removal | H25: Biochar Spreading Emissions
A26: cmp_1KXE4AHAG1S0PDC6 | B26: biochar_sequestration_200_year_c_org | C26: Biochar sequestration, 200 year durability | D26: =Expression!E168 | E26: =Expression!F168 | F26: sequestration | G26: removal | H26: Biochar sequestration, 200 year durability
A27: cmp_1KXE4AHAG1S0VES7 | B27: distance_based_ci_emissions | C27: Distance-based emissions | D27: =Expression!E213 | E27: =Expression!F213 | F27: activity | G27: removal | H27: CO Flatbed Truck Transport Embodied Emissions
A28: cmp_1KXE9RCXD1S0GF3H | B28: constant_reduction | C28: Constant CO₂ reduction | D28: =Expression!E6 | E28: =Expression!F6 | F28: adjustment | G28: removal | H28: BCU - Transport Process
A29: cmp_1KXEA1TH21S01ND8 | B29: transport | C29: Transport emissions | D29: =Expression!E477 | E29: =Expression!F477 | F29: activity | G29: removal | H29: CO Flatbed Truck Transport Process Emissions
A30: cmp_1KXEA1TH21S0E0HK | B30: mass_based_ci_emissions | C30: Mass-based CI emissions | D30: =Expression!E209 | E30: =Expression!F209 | F30: activity | G30: removal | H30: Biochar Spreading Emissions
A31: cmp_1KXEA1TH21S0G8VW | B31: biochar_sequestration_200_year_c_org | C31: Biochar sequestration, 200 year durability | D31: =Expression!E347 | E31: =Expression!F347 | F31: sequestration | G31: removal | H31: Biochar sequestration, 200 year durability
A32: cmp_1KXEA1TH21S0NA8X | B32: distance_based_ci_emissions | C32: Distance-based emissions | D32: =Expression!E87 | E32: =Expression!F87 | F32: activity | G32: removal | H32: CO Flatbed Truck Transport Embodied Emissions
A33: cmp_1KXEA1TH21S0WM07 | B33: mass_based_ci_emissions | C33: Mass-based CI emissions | D33: =Expression!E449 | E33: =Expression!F449 | F33: activity | G33: removal | H33: Biochar Production Emission (A)
A34: cmp_1KXEA3E4Q1S0VC7M | B34: constant_reduction | C34: Constant CO₂ reduction | D34: =Expression!E426 | E34: =Expression!F426 | F34: adjustment | G34: removal | H34: BCU - Transport Process
A35: cmp_1KXEB42X91S0VGGS | B35: constant_reduction | C35: Constant CO₂ reduction | D35: =Expression!E169 | E35: =Expression!F169 | F35: adjustment | G35: removal | H35: BCU - Transport Process
A36: cmp_1KXEBV2PW1S02CSH | B36: mass_based_ci_emissions | C36: Mass-based CI emissions | D36: =Expression!E181 | E36: =Expression!F181 | F36: activity | G36: removal | H36: Biochar Production Emission (A)
A37: cmp_1KXEBV2PW1S07E6J | B37: transport | C37: Transport emissions | D37: =Expression!E452 | E37: =Expression!F452 | F37: activity | G37: removal | H37: CO Flatbed Truck Transport Process Emissions
A38: cmp_1KXEBV2PW1S0KSAX | B38: mass_based_ci_emissions | C38: Mass-based CI emissions | D38: =Expression!E372 | E38: =Expression!F372 | F38: activity | G38: removal | H38: Biochar Spreading Emissions
A39: cmp_1KXEBV2PW1S0P1N6 | B39: biochar_sequestration_200_year_c_org | C39: Biochar sequestration, 200 year durability | D39: =Expression!E463 | E39: =Expression!F463 | F39: sequestration | G39: removal | H39: Biochar sequestration, 200 year durability
A40: cmp_1KXEBV2PW1S0V327 | B40: distance_based_ci_emissions | C40: Distance-based emissions | D40: =Expression!E108 | E40: =Expression!F108 | F40: activity | G40: removal | H40: CO Flatbed Truck Transport Embodied Emissions
A41: cmp_1KXEBZVFK1S00M8F | B41: constant_reduction | C41: Constant CO₂ reduction | D41: =Expression!E515 | E41: =Expression!F515 | F41: adjustment | G41: removal | H41: BCU - Transport Process
...

Sheet Expression
A1: Expression ID | B1: Component ID | C1: Result Name | D1: Expression Template | E1: Result in SI Units | F1: Standard deviation in SI Units | G1: SI Units
A3: cmp_1KXGK45BZ1S0YDTZ_output | B3: =Component!A90 | C3: Distance-based emissions | D3: {cmp_1KXGK45BZ1S0YDTZ_distance} * {cmp_1KXGK45BZ1S0YDTZ_carbon_intensity} | E3: =Datapoint!E316 * Datapoint!E315 | F3: 0 | G3: kg
A4: cmp_1KXGK45BZ1S0YDTZ_component_root | B4: =Component!A90 | C4: CO Flatbed Truck Transport Embodied Emissions | D4: {cmp_1KXGK45BZ1S0YDTZ_output} | E4: =Expression!E3 | F4: 0 | G4: kg
A5: cmp_1KYA8BFJ71S0EWPH_component_root | B5: =Component!A164 | C5: BCU - Transport Process | D5: {cmp_1KYA8BFJ71S0EWPH_constant_reduction} | E5: =Datapoint!E591 | F5: 0 | G5: kg
A6: cmp_1KXE9RCXD1S0GF3H_component_root | B6: =Component!A28 | C6: BCU - Transport Process | D6: {cmp_1KXE9RCXD1S0GF3H_constant_reduction} | E6: =Datapoint!E94 | F6: 0 | G6: kg
A7: cmp_1KXKP77Q21S05Y4C_component_root | B7: =Component!A112 | C7: CO Flatbed Truck Transport Process Emissions | D7: {cmp_1KXKP77Q21S05Y4C_mass} * {cmp_1KXKP77Q21S05Y4C_distance} * {cmp_1KXKP77Q21S05Y4C_carbon_intensity} | E7: =Datapoint!E405 * Datapoint!E404 * Datapoint!E403 | F7: 0 | G7: kg
A8: cmp_1KXERCP431S06AG6_soil_temp_delta | B8: =Component!A66 | C8: Difference in soil temp from 0 celsius | D8: {cmp_1KXERCP431S06AG6_soil_temp} - {cmp_1KXERCP431S06AG6_zero_degrees_celsius} | E8: =Datapoint!E230 - 273.15 | F8: 0 | G8: K
A9: cmp_1KXERCP431S06AG6_normalized_mean_soil_temp | B9: =Component!A66 | C9: Mean soil temperature in dimensionless units | D9: {cmp_1KXERCP431S06AG6_soil_temp_delta} / {cmp_1KXERCP431S06AG6_one_degree_celsius_delta} | E9: =Expression!E8 / 1.0 | F9: 0
A10: cmp_1KXERCP431S06AG6_log_mean_soil_temp | B10: =Component!A66 | C10: Natural log of mean soil temperature in dimensionless units | D10: ln({cmp_1KXERCP431S06AG6_normalized_mean_soil_temp}) | E10: 2.3887628 | F10: 0
A11: cmp_1KXERCP431S06AG6_h_c_ratio | B11: =Component!A66 | C11: H:C ratio | D11: mean({[cmp_1KXERCP431S06AG6_h_c_molar_ratios]}) | E11: 0.46333 | F11: 0
A12: cmp_1KXERCP431S06AG6_non_durable_fraction_calc | B12: =Component!A66 | C12: Non-durable fraction | D12: {cmp_1KXERCP431S06AG6_woolf_parameter_c} + ({cmp_1KXERCP431S06AG6_woolf_parameter_a} + {cmp_1KXERCP431S06AG6_woolf_parameter_b} * {cmp_1KXERCP431S06AG6_log_mean_soil_temp}) * {cmp_1KXERCP431S06AG6_h_c_ratio} | E12: =-0.048 + (-0.383 + 0.35 * Expression!E10) * Expression!E11 | F12: 0
A13: cmp_1KXERCP431S06AG6_durable_fraction_calc | B13: =Component!A66 | C13: Durable fraction | D13: complement_of({cmp_1KXERCP431S06AG6_non_durable_fraction_calc}) | E13: 0.83808048 | F13: 0
A14: cmp_1KXERCP431S06AG6_carbon_contents | B14: =Component!A66 | C14: Carbon content of biochar | D14: {[cmp_1KXERCP431S06AG6_total_carbon_contents]} - {[cmp_1KXERCP431S06AG6_inorganic_carbon_contents]} | E14: 85.66000000000001 | F14: 0 | G14: %
A15: cmp_1KXERCP431S06AG6_durable_fraction | B15: =Component!A66 | C15: Durable fraction | D15: min({cmp_1KXERCP431S06AG6_durable_fraction_calc}, {cmp_1KXERCP431S06AG6_max_durable_fraction}) | E15: 0.83808048 | F15: 0
A16: cmp_1KXERCP431S06AG6_mean_carbon_content | B16: =Component!A66 | C16: Mean carbon content | D16: mean({[cmp_1KXERCP431S06AG6_carbon_contents]}) | E16: 0.8566 | F16: 0
A17: cmp_1KXERCP431S06AG6_output | B17: =Component!A66 | C17: Biochar sequestration, 200 year durability | D17: {cmp_1KXERCP431S06AG6_product_mass} * {cmp_1KXERCP431S06AG6_mean_carbon_content} * {cmp_1KXERCP431S06AG6_durable_fraction} * {cmp_1KXERCP431S06AG6_co2e_of_carbon} | E17: =Datapoint!E229 * Expression!E16 * Expression!E15 * 3.667 | F17: 0 | G17: kg
A18: cmp_1KXERCP431S06AG6_component_root | B18: =Component!A66 | C18: Biochar sequestration, 200 year durability | D18: {cmp_1KXERCP431S06AG6_output} | E18: =Expression!E17 | F18: 0 | G18: kg
A19: cmp_1KXERD7151S097W3_output | B19: =Component!A72 | C19: Distance-based emissions | D19: {cmp_1KXERD7151S097W3_distance} * {cmp_1KXERD7151S097W3_carbon_intensity} | E19: =Datapoint!E257 * Datapoint!E256 | F19: 0 | G19: kg
A20: cmp_1KXERD7151S097W3_component_root | B20: =Component!A72 | C20: CO Flatbed Truck Transport Embodied Emissions | D20: {cmp_1KXERD7151S097W3_output} | E20: =Expression!E19 | F20: 0 | G20: kg
A21: cmp_1KY02PYB11S0YM3M_component_root | B21: =Component!A123 | C21: Biochar Spreading Emissions | D21: {cmp_1KY02PYB11S0YM3M_mass} * {cmp_1KY02PYB11S0YM3M_carbon_intensity} | E21: =Datapoint!E430 * Datapoint!E429 | F21: 0 | G21: kg
A22: cmp_1KWCZP1M61S0TS4R_component_root | B22: =Component!A21 | C22: Biochar Production Emission (A) | D22: {cmp_1KWCZP1M61S0TS4R_mass} * {cmp_1KWCZP1M61S0TS4R_carbon_intensity} | E22: =Datapoint!E65 * Datapoint!E64 | F22: 0 | G22: kg
A23: cmp_1KWCSDFQF1S0A09K_component_root | B23: =Component!A9 | C23: CO Flatbed Truck Transport Process Emissions | D23: {cmp_1KWCSDFQF1S0A09K_mass} * {cmp_1KWCSDFQF1S0A09K_distance} * {cmp_1KWCSDFQF1S0A09K_carbon_intensity} | E23: =Datapoint!E32 * Datapoint!E31 * Datapoint!E30 | F23: 0 | G23: kg
A24: cmp_1KXERCP431S0JNMH_component_root | B24: =Component!A68 | C24: Biochar Production Emission (A) | D24: {cmp_1KXERCP431S0JNMH_mass} * {cmp_1KXERCP431S0JNMH_carbon_intensity} | E24: =Datapoint!E233 * Datapoint!E232 | F24: 0 | G24: kg
A25: cmp_1KXEJD28G1S0ZKFV_component_root | B25: =Component!A63 | C25: Biochar Production Emission (A) | D25: {cmp_1KXEJD28G1S0ZKFV_mass} * {cmp_1KXEJD28G1S0ZKFV_carbon_intensity} | E25: =Datapoint!E212 * Datapoint!E211 | F25: 0 | G25: kg
A26: cmp_1KXEJCGYM1S0NCCM_soil_temp_delta | B26: =Component!A57 | C26: Difference in soil temp from 0 celsius | D26: {cmp_1KXEJCGYM1S0NCCM_soil_temp} - {cmp_1KXEJCGYM1S0NCCM_zero_degrees_celsius} | E26: =Datapoint!E190 - 273.15 | F26: 0 | G26: K
A27: cmp_1KXEJCGYM1S0NCCM_normalized_mean_soil_temp | B27: =Component!A57 | C27: Mean soil temperature in dimensionless units | D27: {cmp_1KXEJCGYM1S0NCCM_soil_temp_delta} / {cmp_1KXEJCGYM1S0NCCM_one_degree_celsius_delta} | E27: =Expression!E26 / 1.0 | F27: 0
A28: cmp_1KXEJCGYM1S0NCCM_log_mean_soil_temp | B28: =Component!A57 | C28: Natural log of mean soil temperature in dimensionless units | D28: ln({cmp_1KXEJCGYM1S0NCCM_normalized_mean_soil_temp}) | E28: 2.3887628 | F28: 0
A29: cmp_1KXEJCGYM1S0NCCM_h_c_ratio | B29: =Component!A57 | C29: H:C ratio | D29: mean({[cmp_1KXEJCGYM1S0NCCM_h_c_molar_ratios]}) | E29: 0.46 | F29: 0
A30: cmp_1KXEJCGYM1S0NCCM_non_durable_fraction_calc | B30: =Component!A57 | C30: Non-durable fraction | D30: {cmp_1KXEJCGYM1S0NCCM_woolf_parameter_c} + ({cmp_1KXEJCGYM1S0NCCM_woolf_parameter_a} + {cmp_1KXEJCGYM1S0NCCM_woolf_parameter_b} * {cmp_1KXEJCGYM1S0NCCM_log_mean_soil_temp}) * {cmp_1KXEJCGYM1S0NCCM_h_c_ratio} | E30: =-0.048 + (-0.383 + 0.35 * Expression!E28) * Expression!E29 | F30: 0
A31: cmp_1KXEJCGYM1S0NCCM_durable_fraction_calc | B31: =Component!A57 | C31: Durable fraction | D31: complement_of({cmp_1KXEJCGYM1S0NCCM_non_durable_fraction_calc}) | E31: 0.83958919 | F31: 0
A32: cmp_1KXEJCGYM1S0NCCM_carbon_contents | B32: =Component!A57 | C32: Carbon content of biochar | D32: {[cmp_1KXEJCGYM1S0NCCM_total_carbon_contents]} - {[cmp_1KXEJCGYM1S0NCCM_inorganic_carbon_contents]} | E32: 83.93299999999999 | F32: 0 | G32: %
A33: cmp_1KXEJCGYM1S0NCCM_durable_fraction | B33: =Component!A57 | C33: Durable fraction | D33: min({cmp_1KXEJCGYM1S0NCCM_durable_fraction_calc}, {cmp_1KXEJCGYM1S0NCCM_max_durable_fraction}) | E33: 0.83958919 | F33: 0
A34: cmp_1KXEJCGYM1S0NCCM_mean_carbon_content | B34: =Component!A57 | C34: Mean carbon content | D34: mean({[cmp_1KXEJCGYM1S0NCCM_carbon_contents]}) | E34: 0.83933 | F34: 0
A35: cmp_1KXEJCGYM1S0NCCM_output | B35: =Component!A57 | C35: Biochar sequestration, 200 year durability | D35: {cmp_1KXEJCGYM1S0NCCM_product_mass} * {cmp_1KXEJCGYM1S0NCCM_mean_carbon_content} * {cmp_1KXEJCGYM1S0NCCM_durable_fraction} * {cmp_1KXEJCGYM1S0NCCM_co2e_of_carbon} | E35: =Datapoint!E189 * Expression!E34 * Expression!E33 * 3.667 | F35: 0 | G35: kg
A36: cmp_1KXEJCGYM1S0NCCM_component_root | B36: =Component!A57 | C36: Biochar sequestration, 200 year durability | D36: {cmp_1KXEJCGYM1S0NCCM_output} | E36: =Expression!E35 | F36: 0 | G36: kg
A37: cmp_1KYABSMDG1S05BSD_component_root | B37: =Component!A181 | C37: Biochar Production Emission (A) | D37: {cmp_1KYABSMDG1S05BSD_mass} * {cmp_1KYABSMDG1S05BSD_carbon_intensity} | E37: =Datapoint!E630 * Datapoint!E629 | F37: 0 | G37: kg
A38: cmp_1KXKP77Q21S0J98Q_component_root | B38: =Component!A113 | C38: Biochar Spreading Emissions | D38: {cmp_1KXKP77Q21S0J98Q_mass} * {cmp_1KXKP77Q21S0J98Q_carbon_intensity} | E38: =Datapoint!E402 * Datapoint!E401 | F38: 0 | G38: kg
A39: cmp_1KY57M9F81S0MGC3_output | B39: =Component!A131 | C39: Distance-based emissions | D39: {cmp_1KY57M9F81S0MGC3_distance} * {cmp_1KY57M9F81S0MGC3_carbon_intensity} | E39: =Datapoint!E472 * Datapoint!E471 | F39: 0 | G39: kg
A40: cmp_1KY57M9F81S0MGC3_component_root | B40: =Component!A131 | C40: CO Flatbed Truck Transport Embodied Emissions | D40: {cmp_1KY57M9F81S0MGC3_output} | E40: =Expression!E39 | F40: 0 | G40: kg
A41: cmp_1KYA6ANEE1S0M34Q_component_root | B41: =Component!A149 | C41: CO Flatbed Truck Transport Process Emissions | D41: {cmp_1KYA6ANEE1S0M34Q_mass} * {cmp_1KYA6ANEE1S0M34Q_distance} * {cmp_1KYA6ANEE1S0M34Q_carbon_intensity} | E41: =Datapoint!E539 * Datapoint!E538 * Datapoint!E537 | F41: 0 | G41: kg
...

Sheet Datapoint
A1: Datapoint ID | B1: Type | C1: Name | D1: Description | E1: Value in SI units | F1: Standard deviation in SI units | G1: SI Units | H1: Value in original units | I1: Standard deviation in original units | J1: Original units | K1: Source 1 ID | L1: Source 1 Name | M1: Source 2 ID | N1: Source 2 Name | O1: Source 3 ID | P1: Source 3 Name | Q1: Supplier reference ID | R1: Measurement Location ID
A3: dtp_1KWCBZZR41S0QRNW | B3: derived | C3: Emissions Factor - Biochar Spreading | D3: Emissions Factor - Biochar Spreading | E3: 0.004 | F3: 0 | H3: 0.004 | I3: 0 | J3: kgCO₂e/kg | K3: =Source!A4 | L3: Biochar Offtake Calculations.xlsx | Q3: mr_1QbNvQcgmQ7HDCbM-out_KY0ptolvtmtBTtKx-0
A4: dtp_1KWCC01B81S0T105 | B4: derived | C4: Biochar Applied (wet mass) (Spreading) - Applied | D4: Biochar Applied (wet mass) (Spreading) - Applied | E4: 7258.3 | F4: 0 | G4: kg | H4: 7258.3 | I4: 0 | J4: kg | K4: =Source!A43 | L4: Chris Craig 5.30.26 Scale Tickets.heic | M4: =Source!A50 | N4: Chris Craig Delivery Notes.xlsx | O4: =Source!A5 | P4: Production Period 3 Summary.xlsx | Q4: mr_1QbNvQcgmQ7HDCbM-out_0qzaoA3uAPye3IRS-0
A5: dtp_1KWCC06301S0Q7XD | B5: derived | C5: Biochar - H/C_org - Applied | D5: Biochar - H/C_org - Applied | E5: 0.35 | F5: 0 | H5: 0.35 | I5: 0 | K5: =Source!A48 | L5: McCreath Analysis - BGN CHAR 252 (H26050602).pdf | Q5: mr_GXesJch3wFv1CGE9-out_SlgcaWsappr9ZCL6-0
A6: dtp_1KWCC06EJ1S0VRHZ | B6: derived | C6: Inorganic Carbon Content % - Applied | D6: Inorganic Carbon Content % - Applied | E6: 0.0018 | F6: 0 | H6: 0.18 | I6: 0 | J6: % | K6: =Source!A6 | L6: 252 - Combined Lab Analyses.pdf | Q6: mr_GXesJch3wFv1CGE9-out_RrRijQ8NSCwAInka-0
A7: dtp_1KWCC08021S0PQ4Y | B7: derived | C7: Biochar Dry Weight (kg) (CO2 stored) - Applied | D7: Biochar Dry Weight (kg) (CO2 stored) - Applied | E7: 4689.9984 | F7: 0 | G7: kg | H7: 4689.9984 | I7: 0 | J7: kg | K7: =Source!A43 | L7: Chris Craig 5.30.26 Scale Tickets.heic | M7: =Source!A48 | N7: McCreath Analysis - BGN CHAR 252 (H26050602).pdf | O7: =Source!A50 | P7: Chris Craig Delivery Notes.xlsx | Q7: mr_1QbNvQcgmQ7HDCbM-out_jzrTws5de3Txjsxr-0
A8: dtp_1KWCC08HW1S0CMAW | B8: derived | C8: Biochar Applied - Soil Temperature (Cel) | D8: Biochar Applied - Soil Temperature (Cel) | E8: 284.05 | F8: 0 | G8: K | H8: 10.9 | I8: 0 | J8: °C | K8: =Source!A41 | L8: soil_temperature_chris_craig.csv | Q8: mr_GXesJch3wFv1CGE9-out_WFEo3VxmWt0N3Yhc-0
A9: dtp_1KWCC08RQ1S0KY26 | B9: derived | C9: Organic Carbon Content % - Applied | D9: Organic Carbon Content % - Applied | E9: 0.80126 | F9: 0 | H9: 80.126 | I9: 0 | J9: % | K9: =Source!A48 | L9: McCreath Analysis - BGN CHAR 252 (H26050602).pdf | Q9: mr_1QbNvQcgmQ7HDCbM-out_9VwHrqELDkqKvfgu-0
A10: dtp_1KWCC0A8Y1S0C3JD | B10: derived | C10: Biochar Output - Carbon Intensity - Applied | D10: Biochar Output - Carbon Intensity - Applied | E10: 1.0351 | F10: 0 | H10: 1.0351 | I10: 0 | J10: kgCO₂e/kg | K10: =Source!A38 | L10: Biochar CI Summary — All Production Periods.xlsx | M10: =Source!A5 | N10: Production Period 3 Summary.xlsx | Q10: mr_1QbNvQcgmQ7HDCbM-out_p2t83fe8Xb0UnDuc-0
A11: dtp_1KWCC0ASJ1S0TQ11 | B11: derived | C11: Biochar Dry Product Weight (kg) (Pyrolysis) - Applied | D11: Biochar Dry Product Weight (kg) (Pyrolysis) - Applied | E11: 5437.9 | F11: 0 | G11: kg | H11: 5437.9 | I11: 0 | J11: kg | K11: =Source!A43 | L11: Chris Craig 5.30.26 Scale Tickets.heic | M11: =Source!A50 | N11: Chris Craig Delivery Notes.xlsx | O11: =Source!A5 | P11: Production Period 3 Summary.xlsx | Q11: mr_1QbNvQcgmQ7HDCbM-out_flFayO1sB5WijeRd-0
A12: dtp_1KWCC0CDQ1S0WZBA | B12: derived | C12: Copy - Truck EF | D12: Copy - Truck EF | E12: 8.5997773e-08 | F12: 0 | G12: 1/m | H12: 0.1384 | I12: 0 | J12: kgCO₂e/(t⋅mi) | K12: =Source!A8 | L12: GLEC NA Road Transport.png | Q12: mr_1QbNvQcgmQ7HDCbM-out_SUXhidR4MsQBPF0H-0
A13: dtp_1KWCC0DY81S0Z7NK | B13: reported | C13: Biochar Applied - Delivery Distance (km) | D13: Biochar Applied - Delivery Distance (km) | E13: 278416.51 | F13: 0 | G13: m | H13: 278.41651 | I13: 0 | J13: km | K13: =Source!A18 | L13: CO to Chris Craig Distance (1).png | Q13: mr_1QbNvQcgmQ7HDCbM-out_40WLB0U4vl7JHA8h-0
A14: dtp_1KWCC0EFJ1S0DV47 | B14: derived | C14: Biochar Transported (kg) - Applied | D14: Biochar Transported (kg) - Applied | E14: 7704.15 | F14: 0 | G14: kg | H14: 7704.15 | I14: 0 | J14: kg | K14: =Source!A43 | L14: Chris Craig 5.30.26 Scale Tickets.heic | M14: =Source!A50 | N14: Chris Craig Delivery Notes.xlsx | O14: =Source!A5 | P14: Production Period 3 Summary.xlsx | Q14: mr_1QbNvQcgmQ7HDCbM-out_OA0wdc8MuB45f6At-0
A15: dtp_1KWCC0EYQ1S0WEJV | B15: reported | C15: Emissions Factor - Flatbed Truck Transport Embodied Emissions (2025, CO) | D15: Emissions Factor - Flatbed Truck Transport Embodied Emissions (2025, CO) | E15: 0.00011979496 | F15: 0 | G15: kg/m | H15: 0.11979496 | I15: 0 | J15: kgCO₂e/km | K15: =Source!A17 | L15: Standard Emission Factors + Calculations (8).xlsx | Q15: mr_1QbNvQcgmQ7HDCbM-out_hDkBvHUGZxuneDx7-0
A16: dtp_1KWCC0FY31S04KKE | B16: reported | C16: Attribution factor | E16: 1 | F16: 0 | H16: 1 | I16: 0
A17: dtp_1KWCC0FY31S09N0F | B17: reported | C17: Attribution factor | E17: 1 | F17: 0 | H17: 1 | I17: 0
A18: dtp_1KWCC0FY31S0P04T | B18: reported | C18: Attribution factor | E18: 1 | F18: 0 | H18: 1 | I18: 0
A19: dtp_1KWCC0FY31S0R8F3 | B19: reported | C19: Attribution factor | E19: 1 | F19: 0 | H19: 1 | I19: 0
A20: dtp_1KWCC0FY31S0X9W4 | B20: reported | C20: Attribution factor | E20: 1 | F20: 0 | H20: 1 | I20: 0
A21: dtp_1KWCSB56R1S0MEKQ | B21: derived | C21: Emissions Factor - Biochar Spreading | D21: Emissions Factor - Biochar Spreading | E21: 0.004 | F21: 0 | H21: 0.004 | I21: 0 | J21: kgCO₂e/kg | K21: =Source!A4 | L21: Biochar Offtake Calculations.xlsx | Q21: mr_KZKzNxsJesEYlNhr-out_KY0ptolvtmtBTtKx-0
A22: dtp_1KWCSB9AV1S0PPY0 | B22: derived | C22: Biochar Applied (wet mass) (Spreading) - Applied | D22: Biochar Applied (wet mass) (Spreading) - Applied | E22: 196.17 | F22: 0 | G22: kg | H22: 196.17 | I22: 0 | J22: kg | K22: =Source!A43 | L22: Chris Craig 5.30.26 Scale Tickets.heic | M22: =Source!A50 | N22: Chris Craig Delivery Notes.xlsx | O22: =Source!A9 | P22: Production Period 1 Summary -- Final Submission (Updated 4_25).xlsx | Q22: mr_KZKzNxsJesEYlNhr-out_0qzaoA3uAPye3IRS-0
A23: dtp_1KWCSBRBT1S008ZK | B23: derived | C23: Biochar - H/C_org - Applied | D23: Biochar - H/C_org - Applied | E23: 0.44 | F23: 0 | H23: 0.44 | I23: 0 | K23: =Source!A3 | L23: 123 - Combined Lab Analyses.pdf | Q23: mr_zCuyoqisqKNAgjn5-out_SlgcaWsappr9ZCL6-0
A24: dtp_1KWCSBYF71S0XFWV | B24: derived | C24: Inorganic Carbon Content % - Applied | D24: Inorganic Carbon Content % - Applied | E24: 0.00267 | F24: 0 | H24: 0.267 | I24: 0 | J24: % | K24: =Source!A3 | L24: 123 - Combined Lab Analyses.pdf | Q24: mr_zCuyoqisqKNAgjn5-out_RrRijQ8NSCwAInka-0
A25: dtp_1KWCSCK6V1S0REFT | B25: derived | C25: Biochar Dry Weight (kg) (CO2 stored) - Applied | D25: Biochar Dry Weight (kg) (CO2 stored) - Applied | E25: 126.04853 | F25: 0 | G25: kg | H25: 126.04853 | I25: 0 | J25: kg | K25: =Source!A43 | L25: Chris Craig 5.30.26 Scale Tickets.heic | M25: =Source!A3 | N25: 123 - Combined Lab Analyses.pdf | O25: =Source!A50 | P25: Chris Craig Delivery Notes.xlsx | Q25: mr_KZKzNxsJesEYlNhr-out_jzrTws5de3Txjsxr-0
A26: dtp_1KWCSCTWH1S0EBNR | B26: derived | C26: Biochar Applied - Soil Temperature (Cel) | D26: Biochar Applied - Soil Temperature (Cel) | E26: 284.05 | F26: 0 | G26: K | H26: 10.9 | I26: 0 | J26: °C | K26: =Source!A41 | L26: soil_temperature_chris_craig.csv | Q26: mr_zCuyoqisqKNAgjn5-out_WFEo3VxmWt0N3Yhc-0
A27: dtp_1KWCSCV4Q1S0NND2 | B27: derived | C27: Organic Carbon Content % - Applied | D27: Organic Carbon Content % - Applied | E27: 0.852 | F27: 0 | H27: 85.2 | I27: 0 | J27: % | K27: =Source!A3 | L27: 123 - Combined Lab Analyses.pdf | Q27: mr_KZKzNxsJesEYlNhr-out_9VwHrqELDkqKvfgu-0
A28: dtp_1KWCSCWHA1S06H5Z | B28: derived | C28: Biochar Output - Carbon Intensity - Applied | D28: Biochar Output - Carbon Intensity - Applied | E28: 0.842 | F28: 0 | H28: 0.842 | I28: 0 | J28: kgCO₂e/kg | K28: =Source!A38 | L28: Biochar CI Summary — All Production Periods.xlsx | M28: =Source!A9 | N28: Production Period 1 Summary -- Final Submission (Updated 4_25).xlsx | O28: =Source!A11 | P28: Production Period 1 Summary -- Final Submission (Updated 4_25) (1).xlsx | Q28: mr_KZKzNxsJesEYlNhr-out_p2t83fe8Xb0UnDuc-0
A29: dtp_1KWCSCX3G1S0N4MK | B29: derived | C29: Biochar Dry Product Weight (kg) (Pyrolysis) - Applied | D29: Biochar Dry Product Weight (kg) (Pyrolysis) - Applied | E29: 146.97 | F29: 0 | G29: kg | H29: 146.97 | I29: 0 | J29: kg | K29: =Source!A43 | L29: Chris Craig 5.30.26 Scale Tickets.heic | M29: =Source!A50 | N29: Chris Craig Delivery Notes.xlsx | O29: =Source!A9 | P29: Production Period 1 Summary -- Final Submission (Updated 4_25).xlsx | Q29: mr_KZKzNxsJesEYlNhr-out_flFayO1sB5WijeRd-0
A30: dtp_1KWCSD8131S0QCYW | B30: derived | C30: Copy - Truck EF | D30: Copy - Truck EF | E30: 8.5997773e-08 | F30: 0 | G30: 1/m | H30: 0.1384 | I30: 0 | J30: kgCO₂e/(t⋅mi) | K30: =Source!A8 | L30: GLEC NA Road Transport.png | Q30: mr_KZKzNxsJesEYlNhr-out_SUXhidR4MsQBPF0H-0
A31: dtp_1KWCSDDGZ1S0DA4T | B31: reported | C31: Biochar Applied - Delivery Distance (km) | D31: Biochar Applied - Delivery Distance (km) | E31: 278416.51 | F31: 0 | G31: m | H31: 278.41651 | I31: 0 | J31: km | K31: =Source!A18 | L31: CO to Chris Craig Distance (1).png | Q31: mr_KZKzNxsJesEYlNhr-out_40WLB0U4vl7JHA8h-0
A32: dtp_1KWCSDDYP1S037AR | B32: derived | C32: Biochar Transported (kg) - Applied | D32: Biochar Transported (kg) - Applied | E32: 208.22 | F32: 0 | G32: kg | H32: 208.22 | I32: 0 | J32: kg | K32: =Source!A43 | L32: Chris Craig 5.30.26 Scale Tickets.heic | M32: =Source!A50 | N32: Chris Craig Delivery Notes.xlsx | O32: =Source!A9 | P32: Production Period 1 Summary -- Final Submission (Updated 4_25).xlsx | Q32: mr_KZKzNxsJesEYlNhr-out_OA0wdc8MuB45f6At-0
A33: dtp_1KWCSDEE41S0HTSC | B33: reported | C33: Emissions Factor - Flatbed Truck Transport Embodied Emissions (2025, CO) | D33: Emissions Factor - Flatbed Truck Transport Embodied Emissions (2025, CO) | E33: 0.00011979496 | F33: 0 | G33: kg/m | H33: 0.11979496 | I33: 0 | J33: kgCO₂e/km | K33: =Source!A17 | L33: Standard Emission Factors + Calculations (8).xlsx | Q33: mr_KZKzNxsJesEYlNhr-out_hDkBvHUGZxuneDx7-0
A34: dtp_1KWCSDFQF1S0BCBB | B34: reported | C34: Attribution factor | E34: 1 | F34: 0 | H34: 1 | I34: 0
A35: dtp_1KWCSDFQF1S0DMNM | B35: reported | C35: Attribution factor | E35: 1 | F35: 0 | H35: 1 | I35: 0
A36: dtp_1KWCSDFQF1S0JP2N | B36: reported | C36: Attribution factor | E36: 1 | F36: 0 | H36: 1 | I36: 0
A37: dtp_1KWCSDFQF1S0SZSZ | B37: reported | C37: Attribution factor | E37: 1 | F37: 0 | H37: 1 | I37: 0
A38: dtp_1KWCSDFQF1S0Z170 | B38: reported | C38: Attribution factor | E38: 1 | F38: 0 | H38: 1 | I38: 0
A39: dtp_1KWCY026S1S0BPW5 | B39: derived | C39: Emissions Factor - Biochar Spreading | D39: Emissions Factor - Biochar Spreading | E39: 0.004 | F39: 0 | H39: 0.004 | I39: 0 | J39: kgCO₂e/kg | K39: =Source!A4 | L39: Biochar Offtake Calculations.xlsx | Q39: mr_4icjZaj2fiznwqRp-out_KY0ptolvtmtBTtKx-0
A40: dtp_1KWCY03FG1S0DZ6E | B40: derived | C40: Biochar Applied (wet mass) (Spreading) - Applied | D40: Biochar Applied (wet mass) (Spreading) - Applied | E40: 392.34 | F40: 0 | G40: kg | H40: 392.34 | I40: 0 | J40: kg | K40: =Source!A43 | L40: Chris Craig 5.30.26 Scale Tickets.heic | M40: =Source!A50 | N40: Chris Craig Delivery Notes.xlsx | O40: =Source!A12 | P40: Production Period 2 Summary.xlsx | Q40: mr_4icjZaj2fiznwqRp-out_0qzaoA3uAPye3IRS-0
A41: dtp_1KWCY06XD1S0QH81 | B41: derived | C41: Biochar - H/C_org - Applied | D41: Biochar - H/C_org - Applied | E41: 0.46333 | F41: 0 | H41: 0.46333 | I41: 0 | K41: =Source!A47 | L41: 251 - Combined Lab Analyses.pdf | Q41: mr_UzmQ79t9v2yVzxqR-out_SlgcaWsappr9ZCL6-0
...

Sheet Source
A1: Source ID | B1: Type | C1: Display Name | D1: Published at | E1: Isometric URL | F1: Supplier reference ID
A3: src_1KCMCJKCR1S0ZHKZ | B3: document | C3: 123 - Combined Lab Analyses.pdf | D3: 46002 | E3: https://to.isometric.com/certify/src_1KCMCJKCR1S0ZHKZ | F3: 66713
A4: src_1KW06BDA81S0TE9E | B4: document | C4: Biochar Offtake Calculations.xlsx | D4: 45987 | E4: https://to.isometric.com/certify/src_1KW06BDA81S0TE9E | F4: ev_IUcU9bvdrQ2OsdXV-prj_1JN6XNWDQ1S0BSN7
