Workbook

Sheet Removals
A1: Internal Tracking | B1: Customer | C1: Delivery | D1: PP | E1: Certify Removal ID | F1: Supplier Ref (join key) | G1: Completed On | H1: Net CO₂e (kg) | I1: Status | J1: Notes | K1: Overdraft flag - over-inventory product at 0 pyrolysis emissions (kg) | L1: Certify prod mass (kg) | M1: Attribution factor | N1: Prod CI applied | O1: Charged production draw (kg)
A2: Brenner - Jan20 - PP256 | B2: Brenner | C2: 46042 | D2: 256 | E2: rmv_1KYA6ANEE1S0PW7F | F2: ba_Mnyp1ajWTFoo2VkH | G2: 46042 | H2: 129.88 | I2: Draft (no GHG statement) | J2: Cap MG draw at 1,731; Certify top-up @ 0 prod emissions. MG event evt_zkIhMem9OwDeyWVU. Pushed to Certify; net draft/actively edited. | PP256 over-inventory: capped to 1,174.3 of 2,160.9 kg (moisture-adj); excess 0 CI. Ceiling = Produced 10,309. | K2: 1174.35/2654.35 | L2: 1174.35 | M2: 1 | N2: 1.2918 | O2: =IF(N2>0,L2*M2,0) -> 1174.35
A3: Brenner - Jan20 - PP257 | B3: Brenner | C3: 46042 | D3: 257 | E3: rmv_1KY02PC6H1S0D393 | F3: ba_WhokCybTDfXx5J9b | G3: 46042 | H3: 743.58 | I3: Draft (no GHG statement) | L3: 5157.3261 | M3: 1 | N3: 1.2926 | O3: =IF(N3>0,L3*M3,0) -> 5157.3261
A4: Brenner - Jan20 - PP258 | B4: Brenner | C4: 46042 | D4: 258 | E4: rmv_1KY02PYB11S0N221 | F4: ba_KgcBuWQUZqU1iIh0 | G4: 46042 | H4: 1204.08 | I4: Draft (no GHG statement) | L4: 821.7107 | M4: 1 | N4: 1.1815 | O4: =IF(N4>0,L4*M4,0) -> 821.7107
A5: Brenner - Mar11 - PP256 | B5: Brenner | C5: 46092 | D5: 256 | E5: rmv_1KY57NCC21S0TVWC | F5: ba_k5O479XvMebZlTY5 | G5: 46092 | H5: 309.54 | I5: Draft (no GHG statement) | J5: PP256 over-inventory: fully over (30.1 kg); CI 0. | K5: 0/123.75 | L5: 0 | M5: 1 | N5: 0 | O5: =IF(N5>0,L5*M5,0) -> 0
A6: Brenner - Mar11 - PP257 | B6: Brenner | C6: 46092 | D6: 257 | E6: rmv_1KY57M9F81S03MK6 | F6: ba_TMAR7Xx3vwC16Jan | G6: 46092 | H6: 822.08 | I6: Draft (no GHG statement) | L6: 618.73875 | M6: 1 | N6: 1.2926 | O6: =IF(N6>0,L6*M6,0) -> 618.73875
A7: Brenner - Mar11 - PP258 | B7: Brenner | C7: 46092 | D7: 258 | E7: rmv_1KY57MT101S0BKC4 | F7: ba_tyHD61LKMjHX0tm8 | G7: 46092 | H7: 1272.05 | I7: Draft (no GHG statement) | L7: 866.23425 | M7: 1 | N7: 1.1815 | O7: =IF(N7>0,L7*M7,0) -> 866.23425
A8: Brenner - Mar11 - PP259 | B8: Brenner | C8: 46092 | D8: 259 | E8: rmv_1KY5G7F3N1S0MPZX | F8: ba_STp6R7r1eTkvhMC4 | G8: 46092 | H8: 4137.65 | I8: Draft (no GHG statement) | J8: PP259 now over-inventory on volumetric bag-mass basis: delivered 4,084 kg green-in (33 bags x 141.75 x (1-0.127)) vs produced 3,868 kg -> production mass CAPPED at 3,868 (FIFO); excess ~216 kg carries 0 production CI, sequestration credit retained. Applied 2026-07-28. | K8: 3868/4083.68 | L8: 3868 | M8: 1 | N8: 1.4278 | O8: =IF(N8>0,L8*M8,0) -> 3868
A9: Brenner - Mar20 - PP257 | B9: Brenner | C9: 46101 | D9: 257 | E9: rmv_1KY38KE1C1S03T2H | F9: ba_ouUP380dPZPm3TwY | G9: 46101 | H9: 332.28 | I9: Draft (no GHG statement) | L9: 249.7208 | M9: 1 | N9: 1.2926 | O9: =IF(N9>0,L9*M9,0) -> 249.7208
A10: Brenner - Mar20 - PP258 | B10: Brenner | C10: 46101 | D10: 258 | E10: rmv_1KYA75EW41S07JMK | H10: 4950 | L10: 3395.2191 | M10: 1 | N10: 1.1815 | O10: =IF(N10>0,L10*M10,0) -> 3395.2191
A11: Brenner - Mar20 - PP254 | B11: Brenner | C11: 46101 | D11: 254 | E11: rmv_1KYA74ZX41S0H0D1 | H11: 640.42 | J11: PP254: fully within production (495.0 kg moisture-adj, no cap). | K11: 0/516.68 | L11: 0 | M11: 1 | N11: 1.4579 | O11: =IF(N11>0,L11*M11,0) -> 0
A12: D1 - Chris Craig - PP123 | B12: Chris Craig | C12: D1 - May 30 | D12: 123 | E12: rmv_1KWCSDFQF1S0CSCB | F12: ba_9kP9SwYZMlGNTqqx | G12: 46172 | H12: 213.04 | I12: Draft (no GHG statement) | L12: 146.97 | M12: 1 | N12: 0.842 | O12: =IF(N12>0,L12*M12,0) -> 146.97
A13: D1 - Chris Craig - PP251 | B13: Chris Craig | C13: D1 - May 30 | D13: 251 | E13: rmv_1KWCY0G8W1S0931T | F13: ba_tHRLhKtxK34N9epQ | G13: 46172 | H13: 363.23 | I13: Draft (no GHG statement) | L13: 293.94 | M13: 1 | N13: 1.1178 | O13: =IF(N13>0,L13*M13,0) -> 293.94
A14: D1 - Chris Craig - PP252 | B14: Chris Craig | C14: D1 - May 30 | D14: 252 | E14: rmv_1KWCC0FY31S0QD5T | H14: 1842.59 | L14: 5437.9 | M14: 1 | N14: 1.0351 | O14: =IF(N14>0,L14*M14,0) -> 5437.9
A15: D1 - Chris Craig - PP255 | B15: Chris Craig | C15: D1 - May 30 | D15: 255 | E15: rmv_1KWCZP1M61S02KMH | F15: ba_T8zfcMUbDDHUruuA | G15: 46172 | H15: 298.65 | I15: Draft (no GHG statement) | J15: PP255: fully within production (286.3 kg moisture-adj); CI 1.2936. | L15: 293.94 | M15: 1 | N15: 1.2936 | O15: =IF(N15>0,L15*M15,0) -> 293.94
A16: D2 - Chris Craig - PP123 | B16: Chris Craig | C16: D2 - May 30 | D16: 123 | E16: rmv_1KXE4AHAG1S0AK0A | F16: ba_lwnWhNsjh8WoV53l | G16: 46172 | H16: 213.36 | I16: Draft (no GHG statement) | L16: 147.19 | M16: 1 | N16: 0.842 | O16: =IF(N16>0,L16*M16,0) -> 147.19
A17: D2 - Chris Craig - PP251 | B17: Chris Craig | C17: D2 - May 30 | D17: 251 | E17: rmv_1KXEA1TH21S04EG0 | F17: ba_Z9EfWkX89iM3ii1v | G17: 46172 | H17: 4183.34 | I17: Draft (no GHG statement) | L17: 3385.29 | M17: 1 | N17: 1.1178 | O17: =IF(N17>0,L17*M17,0) -> 3385.29
A18: D2 - Chris Craig - PP252 | B18: Chris Craig | C18: D2 - May 30 | D18: 252 | E18: rmv_1KXEBV2PW1S0A79A | F18: ba_VWf4sxkY2EscDW5o | G18: 46172 | H18: 2593.19 | I18: Draft (no GHG statement) | L18: 2060.61 | M18: 1 | N18: 1.0351 | O18: =IF(N18>0,L18*M18,0) -> 2060.61
A19: D2 - Chris Craig - PP253 | B19: Chris Craig | C19: D2 - May 30 | D19: 253 | E19: rmv_1KXECAV741S0SM2Q | F19: ba_oE4jAK80l7BJyFMg | G19: 46172 | H19: 345.08 | I19: Draft (no GHG statement) | L19: 294.37 | M19: 1 | N19: 1.1003 | O19: =IF(N19>0,L19*M19,0) -> 294.37
A20: D2 - Chris Craig - PP254 | B20: Chris Craig | C20: D2 - May 30 | D20: 254 | E20: rmv_1KXKGW8131S0DAD9 | F20: manual-charm-biochar-D2-254 | G20: 46172 | H20: 641.07 | I20: Draft (no GHG statement) | J20: PP254 over-inventory: production capped to in-inventory 93.9 of 282.0 kg (moisture-adjusted); excess at 0 CI. FIFO ceiling = Produced 11,426. | K20: 0/294.37 | L20: 0 | M20: 1 | N20: 1.4579 | O20: =IF(N20>0,L20*M20,0) -> 0
A21: D3 - Chris Craig - PP123 | B21: Chris Craig | C21: D3 - June 6 | D21: 123 | E21: rmv_1KXEHAAVZ1S0VXRD | F21: ba_yYdKOBIvyBMfCOdf | G21: 46179 | H21: 630.97 | I21: Draft (no GHG statement) | L21: 434.77 | M21: 1 | N21: 0.842 | O21: =IF(N21>0,L21*M21,0) -> 434.77
A22: D3 - Chris Craig - PP252 | B22: Chris Craig | C22: D3 - June 6 | D22: 252 | E22: rmv_1KXKP77Q21S08Q74 | F22: manual-charm-biochar-D3-252 | G22: 46179 | H22: 547.89 | I22: Draft (no GHG statement) | J22: Corrected D3-252 (PP252 characterization + CI) | L22: 434.77 | M22: 1 | N22: 1.0351 | O22: =IF(N22>0,L22*M22,0) -> 434.77
A23: D3 - Chris Craig - PP253 | B23: Chris Craig | C23: D3 - June 6 | D23: 253 | E23: rmv_1KXEJCGYM1S09J0R | F23: ba_ZmHB6yt6Jtzs0PTW | G23: 46179 | H23: 5628.03 | I23: Draft (no GHG statement) | L23: 5217.24 | M23: 1 | N23: 1.1003 | O23: =IF(N23>0,L23*M23,0) -> 5217.24
A24: D3-Chris Craig - PP254 | B24: Chris Craig | C24: D3 - June 6 | D24: 254 | E24: rmv_1KXKGXJB61S01MAJ | F24: manual-charm-biochar-D3-254 | G24: 46179 | H24: 3449.36 | I24: Draft (no GHG statement) | J24: Hand-built in Certify (MG blocked) | PP254 over-inventory: fully over (1,249.5 kg moisture-adj); production CI 0. | K24: 0/1304.31 | O24: =IF(N24>0,L24*M24,0) -> 0
A25: D3 - Chris Craig - PP255 | B25: Chris Craig | C25: D3 - June 6 | D25: 255 | E25: rmv_1KXEJD28G1S07DZM | F25: ba_Sm5nzKG9gj21Dxl1 | G25: 46179 | H25: 2907.3 | I25: Draft (no GHG statement) | J25: PP255 over-inventory: capped to 559.98 of 1,693.9 kg (moisture-adj); excess 0 CI; CI 1.2936. Ceiling = Produced 10,357; FIFO headroom after EO (9,503.08) + D1 (293.94). | K25: 559.98/1739.08 | L25: 559.98 | M25: 1 | N25: 1.2936 | O25: =IF(N25>0,L25*M25,0) -> 559.98
A26: D4 - Chris Craig - PP251 | B26: Chris Craig | C26: D4 - June 6 | D26: 251 | E26: rmv_1KXERCP431S0TG4A | F26: ba_7FH3EjYwQp16ttVc | G26: 46179 | H26: 2574.83 | I26: Draft (no GHG statement) | L26: 2080.97 | M26: 1 | N26: 1.1178 | O26: =IF(N26>0,L26*M26,0) -> 2080.97
A27: D4 - Chris Craig - PP252 | B27: Chris Craig | C27: D4 - June 6 | D27: 252 | E27: rmv_1KXERD7151S0RC36 | F27: ba_bVEAvO9legIMhHcD | G27: 46179 | H27: 524.42 | I27: Draft (no GHG statement) | K27: 50.72/416.19 | L27: 50.72 | M27: 1 | N27: 1.0351 | O27: =IF(N27>0,L27*M27,0) -> 50.72
A28: D4 - Chris Craig - PP253 | B28: Chris Craig | C28: D4 - June 6 | D28: 253 | E28: rmv_1KXGK2Y3V1S0HT4A | F28: ba_fcqDPyfocSyfS0ba | G28: 46179 | H28: 4299.77 | I28: Draft (no GHG statement) | L28: 3953.85 | M28: 1 | N28: 1.1003 | O28: =IF(N28>0,L28*M28,0) -> 3953.85
A29: D4 - Chris Craig - PP255 | B29: Chris Craig | C29: D4 - June 6 | D29: 255 | E29: rmv_1KXGK3HP81S0FP36 | F29: ba_R4Vr8Bfn1uspC4R1 | G29: 46179 | H29: 473.97 | I29: Draft (no GHG statement) | J29: PP255 over-inventory: fully over (202.7 kg); CI 0. | K29: 0/208.09 | L29: 0 | M29: 1 | N29: 0 | O29: =IF(N29>0,L29*M29,0) -> 0
A30: D4 - Chris Craig - PP256 | B30: Chris Craig | C30: D4 - June 6 | D30: 256 | E30: rmv_1KXGK45BZ1S0DJ22 | F30: ba_OPir9NJcYGrhzD92 | G30: 46179 | H30: 381.36 | I30: Draft (no GHG statement) | J30: PP256 over-inventory: fully over (122.8 kg moisture-adj); production CI 0. Ceiling = Produced 10,309, fully consumed by EO (9,134.65) + Brenner Jan-20 (1,174.35). | K30: 0/151.8 | L30: 0 | M30: 1 | N30: 0 | O30: =IF(N30>0,L30*M30,0) -> 0
A31: D4 - Chris Craig - PP257 | B31: Chris Craig | C31: D4 - June 6 | D31: 257 | E31: rmv_1KXGK4R131S095PN | F31: ba_SEeVg0i26QTA0MGj | G31: 46179 | H31: 1400.74 | I31: Draft (no GHG statement) | L31: 1044.6268 | M31: 1 | N31: 1.2926 | O31: =IF(N31>0,L31*M31,0) -> 1044.6268
A32: D4 - Chris Craig - PP258 | B32: Chris Craig | C32: D4 - June 6 | D32: 258 | E32: rmv_1KXGK5BMT1S0H4FK | F32: ba_Ab0wKI6z4meTsSHJ | G32: 46179 | H32: 521.3 | I32: Draft (no GHG statement) | L32: 355.0702 | M32: 1 | N32: 1.1815 | O32: =IF(N32>0,L32*M32,0) -> 355.0702
A33: 123-Chris Hamman 20250829 | B33: Chris Hamman | C33: EO | D33: 123 | E33: rmv_1KCTBF69Z1S0XHTB | F33: ba_fUeZ1eLibeF6O4cE | G33: 45898 | H33: 6503.83 | I33: Submitted (Apr–Sep 2025 GHG statement) | L33: 5487.679 | M33: 1 | N33: 0.842 | O33: =IF(N33>0,L33*M33,0) -> 5487.679
A34: 123-Chris Hamman 20250916 | B34: Chris Hamman | C34: EO | D34: 123 | E34: rmv_1KCTBHBK11S0SP7D | F34: ba_1Oq53uWjtTwFNYk3 | G34: 45916 | H34: 4128.26 | I34: Submitted (Apr–Sep 2025 GHG statement) | L34: 3479.9939 | M34: 1 | N34: 0.842 | O34: =IF(N34>0,L34*M34,0) -> 3479.9939
A35: 254-Chris Hamman 20250916 | B35: Chris Hamman | C35: EO | D35: 254 | E35: rmv_1KCTBKXGC1S0X4BS | F35: ba_4FPvu3C6mBX9xuE5 | G35: 45916 | H35: 2616.49 | I35: Submitted (Apr–Sep 2025 GHG statement) | L35: 2551.9955 | M35: 1 | N35: 1.4579 | O35: =IF(N35>0,L35*M35,0) -> 2551.9955
A36: 123-Chris Hamman 20250918 | B36: Chris Hamman | C36: EO | D36: 123 | E36: rmv_1KCTBP4DY1S0Q0EJ | F36: ba_eyW02BeG1N1jgEWy | G36: 45918 | H36: 2546.1 | I36: Submitted (Apr–Sep 2025 GHG statement) | L36: 2142.3443 | M36: 1 | N36: 0.842 | O36: =IF(N36>0,L36*M36,0) -> 2142.3443
A37: 254-Chris Hamman 20250918 | B37: Chris Hamman | C37: EO | D37: 254 | E37: rmv_1KCTBR95H1S0BV4A | F37: ba_bdzRMTASXSJB2JfZ | G37: 45918 | H37: 5869.64 | I37: Submitted (Apr–Sep 2025 GHG statement) | L37: 5712.9182 | M37: 1 | N37: 1.4579 | O37: =IF(N37>0,L37*M37,0) -> 5712.9182
A38: 254-Chris Hamman 20250923 | B38: Chris Hamman | C38: EO | D38: 254 | E38: rmv_1KCTBTHWT1S05Q73 | F38: ba_KEnxJerCkCe7I2By | G38: 45923 | H38: 568.85 | I38: Submitted (Apr–Sep 2025 GHG statement) | L38: 554.0779 | M38: 1 | N38: 1.4579 | O38: =IF(N38>0,L38*M38,0) -> 554.0779
A39: 255-Chris Hamman 20250923 | B39: Chris Hamman | C39: EO | D39: 255 | E39: rmv_1KCTB8JVM1S031N6 | F39: ba_GwJpGqft6MCOFNan | G39: 45923 | H39: 4466.25 | I39: Submitted (Apr–Sep 2025 GHG statement) | L39: 6094.857 | M39: 1 | N39: 1.2936 | O39: =IF(N39>0,L39*M39,0) -> 6094.857
A40: 254-Chris Hamman 20250929 | B40: Chris Hamman | C40: EO | D40: 254 | E40: rmv_1KCTBWPM91S0V2NA | F40: ba_YC3RbkXOz1WiikZe | G40: 45929 | H40: 2181.11 | I40: Submitted (Apr–Sep 2025 GHG statement) | L40: 2130.1407 | M40: 1 | N40: 1.4579 | O40: =IF(N40>0,L40*M40,0) -> 2130.1407
...

Sheet Biochar Period Reconciliation
A1: Production Period | B1: Produced (kg) — PP Summary | C1: Production draw (kg) | D1: Surplus / (Deficit) kg | E1: Prod CI (kgCO2e/kg) | F1: Production emissions (kgCO2e) | G1: (K) Emissions on undelivered surplus
A2: PP123 | B2: 16184 | C2: =SUMIF(Removals!$D:$D,VALUE(SUBSTITUTE($A2,"PP","")),Removals!$O:$O) -> 15041.647 | D2: =B2-C2 -> 1142.3528 | E2: 0.842 | F2: =B2*E2 -> 13626.928 | G2: =IF(D2>0,D2*E2,0) -> 961.86103
A3: PP251 | B3: 12516.3 | C3: =SUMIF(Removals!$D:$D,VALUE(SUBSTITUTE($A3,"PP","")),Removals!$O:$O) -> 6864.6 | D3: =B3-C3 -> 5651.7 | E3: 1.1178 | F3: =B3*E3 -> 13990.72 | G3: =IF(D3>0,D3*E3,0) -> 6317.4703
A4: PP252 | B4: 7984 | C4: =SUMIF(Removals!$D:$D,VALUE(SUBSTITUTE($A4,"PP","")),Removals!$O:$O) -> 7984 | D4: =B4-C4 -> 0 | E4: 1.0351 | F4: =B4*E4 -> 8264.2384 | G4: =IF(D4>0,D4*E4,0) -> 0
A5: PP253 | B5: 16144.6 | C5: =SUMIF(Removals!$D:$D,VALUE(SUBSTITUTE($A5,"PP","")),Removals!$O:$O) -> 9789.211 | D5: =B5-C5 -> 6355.389 | E5: 1.1003 | F5: =B5*E5 -> 17763.903 | G5: =IF(D5>0,D5*E5,0) -> 6992.8345
A6: PP254 | B6: 11426 | C6: =SUMIF(Removals!$D:$D,VALUE(SUBSTITUTE($A6,"PP","")),Removals!$O:$O) -> 11426.002 | D6: =B6-C6 -> -0.00233 | E6: 1.4579 | F6: =B6*E6 -> 16657.965 | G6: =IF(D6>0,D6*E6,0) -> 0
A7: PP255 | B7: 10357 | C7: =SUMIF(Removals!$D:$D,VALUE(SUBSTITUTE($A7,"PP","")),Removals!$O:$O) -> 10357.002 | D7: =B7-C7 -> -0.0022 | E7: 1.2936 | F7: =B7*E7 -> 13397.815 | G7: =IF(D7>0,D7*E7,0) -> 0
A8: PP256 | B8: 10309 | C8: =SUMIF(Removals!$D:$D,VALUE(SUBSTITUTE($A8,"PP","")),Removals!$O:$O) -> 10309.002 | D8: =B8-C8 -> -0.002 | E8: 1.2918 | F8: =B8*E8 -> 13317.166 | G8: =IF(D8>0,D8*E8,0) -> 0
A9: PP259 | B9: 3868 | C9: =SUMIF(Removals!$D:$D,VALUE(SUBSTITUTE($A9,"PP","")),Removals!$O:$O) -> 3868 | D9: =B9-C9 -> 0 | E9: 1.4278 | F9: =B9*E9 -> 5522.7304 | G9: =IF(D9>0,D9*E9,0) -> 0
A10: TOTAL | B10: =SUM(B2:B9) -> 88788.9 | C10: =SUM(C2:C9) -> 75639.465 | D10: =SUM(D2:D9) -> 13149.435 | F10: =SUM(F2:F9) -> 102541.47 | G10: =SUM(G2:G9) -> 14272.166
A11: Note — PP257 and PP258 are excluded from this reconciliation: those periods still have bags in inventory and are not yet being drawn down, so no production emissions are outstanding on them. PP256 is included because it is fully drawn (over-drawn), i.e. complete. Draw column C sums Removals!O (= mass x attribution factor, charged legs only) and ties to live Certify for all periods.
B13: Period is Completed | F13: Production emissions OUTSTANDING | G13: =SUM(G2:G9) -> 14272.166
A18: Removals Burdened | B18: Kg of burden | C18: Total Burden after Removal | D18: Total Burden
A19: rmv_1KY02PC6H1S0D393 | B19: 6135 | C19: =D19-B19 -> 8137.1658 | D19: =G13 -> 14272.166
A20: rmv_1KYA6ANEE1S0PW7F | B20: 5000 | C20: =C19-B20 -> 3137.1658
A21: rmv_1KWCC0FY31S0QD5T | B21: =D19-B19-B20 -> 3137.1658 | C21: =C20-B21 -> 0

Sheet PP Summary Name Key
A1: MRV PP Name | B1: Ops PP Number | C1: Actual Time Period
A2: Production Period 1 | B2: 123 | C2: 8/12-12/5
A3: Production Period 2 | B3: 251 | C3: 12/6-1/31
A4: Production Period 3 | B4: 252 | C4: 2/1-2/28
A5: Production Period 4 | B5: 253 | C5: 3/1-3/31
A6: Production Period 5 | B6: 254 | C6: 4/1-4/30
A7: Production Period 6 | B7: 255 | C7: 5/1-5/31
A8: Production Period 7 | B8: 256 | C8: 6/1-6/30
A9: Production Period 8 | B9: 257 | C9: 7/1-7/31
A10: August 2025 Production Period | B10: 258 | C10: 8/1-8/31
A11: September 2025 Production Period | B11: 259 | C11: 9/1-9/30
A12: October 2025 Production Period | B12: 2510 | C12: 10/1-10/31
A13: November 2025 Production Period | B13: 2511 | C13: 11/1-11/30
A14: December 2025 Production Period | B14: 2512 | C14: 12/1-12/31
