Workbook

Sheet Summary
A1: BATCH SUMMARY
A2: Batch ID | B2: INJ-07-2026-W2
A3: Week Start (Sat) | B3: 46207
A4: Week End (Sat) | B4: 46214
A6: SECTION 1 - PER-TAB SUMMARY (each row pulls from its mode tab)
A7: Source Tab | B7: Σ Deliveries / Cargo (kg) | C7: Σ Uncertainty Adj (kg) | D7: Mass Used (kg) | E7: Sparging Loss (kg) | F7: Filtration Loss (kg) | G7: MOBI (kg) | H7: AECN→SOPOR EE (mi) | J7: Opel→Basco EE (mi) | K7: CO -> LA (EE)
A8: AECN Rail | B8: ='AECN Rail'!B52 -> 98093.806 | C8: ='AECN Rail'!C52 -> 80.27808 | D8: ='AECN Rail'!D52 -> 98013.528 | E8: ='AECN Rail'!E52 -> 1264.3745 | F8: ='AECN Rail'!F52 -> 188.66085 | G8: ='AECN Rail'!G52 -> 96560.492 | H8: =SUM('AECN Rail'!L32:L47) -> 402.84103 | J8: =SUM('AECN Rail'!N32:N47) -> 429
A9: AECN Truck | B9: ='AECN Truck'!B28 -> 0 | C9: ='AECN Truck'!F28 -> 0 | D9: ='AECN Truck'!C28 -> 0 | E9: ='AECN Truck'!D28 -> 0 | F9: ='AECN Truck'!E28 -> 0 | G9: ='AECN Truck'!G28 -> 0
A10: Charm WODO | B10: =WODO!A33 -> 3246 | C10: 0 | D10: =WODO!B33 -> 3073.2 | E10: =WODO!C33 -> 5.2 | F10: 0 | G10: =WODO!D33 -> 3068 | K10: ='WODO Shipments & EE Allocation'!G13 -> 1201
A11: Kerry | B11: =Kerry!A33 -> 0 | C11: 0 | D11: =Kerry!A33 -> 0 | E11: =Kerry!B33 -> 0 | F11: 0 | G11: =Kerry!C33 -> 0
A12: QOWV | B12: =QOWV!B53 -> 31529 | C12: 0 | D12: =QOWV!D53 -> 29455.4 | E12: 0 | F12: 0 | G12: =QOWV!F53 -> 25521 | K12: ='QOWV Shipments & EE Allocation'!G18 -> 3028.1974
A13: TOTAL | B13: =SUM(B8:B12) -> 132868.81 | C13: =SUM(C8:C12) -> 80.27808 | D13: =SUM(D8:D12) -> 130542.13 | E13: =SUM(E8:E12) -> 1269.5745 | F13: =SUM(F8:F12) -> 188.66085 | G13: =SUM(G8:G12) -> 125149.49
A15: SECTION 2 - PER-OIL-TYPE ROLLUP (composite C% per oil type per week)
A16: Oil Type | B16: Transport Mass - upstream (kg) | C16: Transport Mass - downstream Opel→Basco (kg) | D16: Pyrolysis Mass (kg) | E16: MOBI - sequestration (kg) | F16: Composite Sample ID | G16: C % | H16: Lab COA Link | I16: C Content Uncertainty | J16: Testing Uncertainty
A17: AECN | B17: =SUM('AECN Rail'!I10:I13)+'AECN Truck'!A28 -> 98013.528 | C17: ='AECN Rail'!B52 -> 98093.806 | D17: =SUM('AECN Rail'!I10:I13)+'AECN Truck'!A28 -> 98013.528 | E17: ='AECN Rail'!G52+'AECN Truck'!G28 -> 96560.492 | F17: AECN 7-2026-W2 | G17: 0.416 | H17: =HYPERLINK("https://drive.google.com/file/d/1BCWgPB03ksOBbkCZFxaUgDYR7FuPJQ2t/view","COA SR26-04370.001") -> COA SR26-04370.001 | I17: =G17*J17 -> 0.001664 | J17: 0.004
A18: WODO | B18: =WODO!A33 -> 3246 | D18: =WODO!B33 -> 3073.2 | E18: =WODO!D33 -> 3068 | F18: 7-2026-W2 WODO | G18: 0.489 | H18: =HYPERLINK("https://drive.google.com/file/d/1ksAacSokglR1yDkEgjM1Y2Q1l4xtdsA2/view","COA SR26-04432.001") -> COA SR26-04432.001 | I18: =G18*J18 -> 0.001956 | J18: 0.004
A19: Kerry | B19: =Kerry!A33 -> 0 | D19: =Kerry!A33 -> 0 | E19: =Kerry!C33 -> 0
A20: QOWV | B20: =QOWV!B53 -> 31529 | D20: =QOWV!D53 -> 29455.4 | E20: =QOWV!F53 -> 25521 | F20: QOWV 7-2026-W2 | G20: 0.084 | H20: =HYPERLINK("https://drive.google.com/file/d/12ApjLt22Wk0k4hsdKO99Ibq_MslVXDQX/view","COA SR26-04220.002") -> COA SR26-04220.002 | I20: =G20*J20 -> 0.000336 | J20: 0.004
A21: TOTAL | B21: =SUM(B17:B20) -> 132788.53 | C21: =SUM(C17:C20) -> 98093.806 | D21: =SUM(D17:D20) -> 130542.13 | E21: =SUM(E17:E20) -> 125149.49

Sheet AECN Rail
A1: BATCH HEADER — AECN Rail
A2: Batch ID (INJ-YYYY-WXX) | B2: INJ-07-2026-W2 | N2: Constants
A3: Week Start (Sat) | B3: 46207 | N3: Lbs/Kg | O3: 2.20462
A4: Week End (Sat) | B4: 46214 | N4: Kg/Lbs | O4: 0.453592
N5: Sparging Mass Loss | O5: 0.0129
N6: pH range (target) | O6: 2.0 - 4.0
N7: Filtration Solids Content | O7: =HYPERLINK("https://docs.google.com/spreadsheets/d/16shKoa1KP34kQJyQvzclBejW9L5-ubNSqPsMOVB7zDY/edit?usp=sharing", 0.00195) -> 0.00195
A8: SECTION 1 - RAILCARS RECEIVED THIS WEEK (entity-level) | I8: Pyrolysis Emissions Mass | N8: BOL Trips (AECN→SOPOR) | O8: 3
A9: Railcar # | B9: Arrival Date at Opelousas | C9: Loading BOLs (comma-sep) | D9: Total Loaded (MT) | E9: Total Loaded (kg) | F9: Total Offloaded (kg, auto) | G9: Loss (kg) | H9: Previously Claimed (kg) | I9: Claimed This Week (kg) | J9: AECN→SOPOR (mi) | K9: Rail (mi) | L9: Opel→Basco (mi) | N9: Round Trip (Opel→Basco) | O9: 2
A10: SHPX215079 | B10: 46191 | C10: 2389-R, 2390-R, 2391-R | D10: =SUMIF($C$17:$C$28,$A10,$D$17:$D$28) -> 78.33 | E10: =SUMIF($C$17:$C$28,$A10,$E$17:$E$28) -> 78330 | F10: =SUMIF($C$32:$C$47,A10,$F$32:$F$47)+H10 -> 19513.528 | G10: =IF(AND(E10<>"",F10<>"",F10>=0.95*E10),E10-F10,"") | H10: 0 | I10: =F10-H10 -> 19513.528 | J10: 107.5 | K10: 2199 | L10: 42.9
A11: TIMX201060 | B11: 46195 | C11: 2392-R, 2393-R, 2394-R | D11: =SUMIF($C$17:$C$28,$A11,$D$17:$D$28) -> 78.5 | E11: =SUMIF($C$17:$C$28,$A11,$E$17:$E$28) -> 78500 | F11: =SUMIF($C$32:$C$47,A11,$F$32:$F$47)+H11 -> 78580.278 | G11: =IF(AND(E11<>"",F11<>"",F11>=0.95*E11),E11-F11,"") -> -80.27808 | H11: 0 | I11: =E11-H11 -> 78500 | J11: 107.5 | K11: 2199 | L11: 42.9
A15: SECTION 2 - ORIGINS LEDGER (loading BOLs at SOPOR)
A16: Date | B16: BOL # | C16: Railcar # | D16: BOL Mass (MT) | E16: BOL Mass (kg)
A17: 46189 | B17: =HYPERLINK("https://drive.google.com/file/d/1G88K5a1UAP-XlRs5kGEFWMltzYU-b21P/view","2389-R") -> 2389-R | C17: SHPX215079 | D17: 25.94 | E17: 25940
A18: 46190 | B18: =HYPERLINK("https://drive.google.com/file/d/1-DagHF0UmkojsAOoXpaxnTieN6UQ6Z5y/view","2390-R") -> 2390-R | C18: SHPX215079 | D18: 26.2 | E18: 26200
A19: 46190 | B19: =HYPERLINK("https://drive.google.com/file/d/1OM_JgSDEClK6h5ODDSM7ZXhF3XdYPDPX/view","2391-R") -> 2391-R | C19: SHPX215079 | D19: 26.19 | E19: 26190
A20: 46191 | B20: =HYPERLINK("https://drive.google.com/file/d/1V0mihqtR1ZKdKLeYPDmMdIqHlr-47Xc5/view","2392-R") -> 2392-R | C20: TIMX201060 | D20: 26.15 | E20: 26150
A21: 46191 | B21: =HYPERLINK("https://drive.google.com/file/d/1XvA-HjKhlgHF426oxFuN6uqr9tSIsCFP/view","2393-R") -> 2393-R | C21: TIMX201060 | D21: 26.19 | E21: 26190
A22: 46192 | B22: =HYPERLINK("https://drive.google.com/file/d/1eiT0igoOPagVkiy_HkE_342PXm2Ex8SU/view","2394-R") -> 2394-R | C22: TIMX201060 | D22: 26.16 | E22: 26160
A30: SECTION 3 - SCALE TICKETS + OFFLOAD WEIGHTS
D31: Full Scale Ticket (lb) | E31: Empty Scale Ticket (lb) | F31: Net Scaled Mass (kg) | G31: pH | H31: Sparging Loss (kg) | I31: Filtration Loss (kg) | J31: Uncertainty Adjustment (kg) | K31: MOBI (kg) | L31: AECN→SOPOR (mi, x3 — full BOL) | M31: Rail (mi — full BOL) | N31: Opel→Basco (mi, x2 — downstream, per offload)
A32: 46213 | B32: Rail_SHPX215079_6.18.2026_offload_1 | C32: SHPX215079 | D32: =HYPERLINK("https://drive.google.com/file/d/1i3jChdazrflMejXxEn41pp8e4A2d_lXX/view", 72240) -> 72240 | E32: =HYPERLINK("https://drive.google.com/file/d/1QSGMa2BZYOlqRJ5Wq3I4im7tR9EyEcxg/view", 29220) -> 29220 | F32: =IF(D32="","",(D32-E32)*$O$4) -> 19513.528 | G32: 3.1 | H32: =IF(F32="","",(F32-J32)*$O$5) -> 251.72451 | I32: =IF(F32="","",(F32-J32)*(1-$O$5)*$O$7) -> 37.560516 | J32: {=IF(F32="","",IF(ROW()=MAX(IF($C$32:$C$47=C32,ROW($C$32:$C$47),0)),MAX(0,IFERROR(VLOOKUP(C32,$A$10:$L$11,6,FALSE)-VLOOKUP(C32,$A$10:$L$11,5,FALSE),0)),0))} -> 0 | K32: =IF(F32="","",F32-H32-I32-J32) -> 19224.243 | L32: =IF(F32="","",(F32-J32)/VLOOKUP(C32,$A$10:$L$11,5,FALSE)*VLOOKUP(C32,$A$10:$L$11,10,FALSE)*$O$8) -> 80.341028 | M32: =IF(F32="","",(F32-J32)/VLOOKUP(C32,$A$10:$L$11,5,FALSE)*VLOOKUP(C32,$A$10:$L$11,11,FALSE)) -> 547.81371 | N32: =IF(F32="","",IFERROR(VLOOKUP(C32,$A$10:$L$11,12,FALSE),0)*$O$9) -> 85.8
A33: 46213 | B33: Rail_TIMX201060_6.22.2026_offload_1 | C33: TIMX201060 | D33: =HYPERLINK("https://drive.google.com/file/d/1sM1QqgCIw5z7T4F-S4tEMHTvEt06g4cs/view", 72920) -> 72920 | E33: =HYPERLINK("https://drive.google.com/file/d/1o3COVad4l3dhPUmyYkr0wvctTL7kIx_5/view", 29020) -> 29020 | F33: =IF(D33="","",(D33-E33)*$O$4) -> 19912.689 | G33: 3.1 | H33: =IF(F33="","",(F33-J33)*$O$5) -> 256.87369 | I33: =IF(F33="","",(F33-J33)*(1-$O$5)*$O$7) -> 38.328839 | J33: {=IF(F33="","",IF(ROW()=MAX(IF($C$32:$C$47=C33,ROW($C$32:$C$47),0)),MAX(0,IFERROR(VLOOKUP(C33,$A$10:$L$11,6,FALSE)-VLOOKUP(C33,$A$10:$L$11,5,FALSE),0)),0))} -> 0 | K33: =IF(F33="","",F33-H33-I33-J33) -> 19617.486 | L33: =IF(F33="","",(F33-J33)/VLOOKUP(C33,$A$10:$L$11,5,FALSE)*VLOOKUP(C33,$A$10:$L$11,10,FALSE)*$O$8) -> 81.806906 | M33: =IF(F33="","",(F33-J33)/VLOOKUP(C33,$A$10:$L$11,5,FALSE)*VLOOKUP(C33,$A$10:$L$11,11,FALSE)) -> 557.80895 | N33: =IF(F33="","",IFERROR(VLOOKUP(C33,$A$10:$L$11,12,FALSE),0)*$O$9) -> 85.8
A34: 46213 | B34: Rail_TIMX201060_6.22.2026_offload_2 | C34: TIMX201060 | D34: =HYPERLINK("https://drive.google.com/file/d/15lD8lVSzzTg3mS99cH_21ADBabpu3kKA/view", 72200) -> 72200 | E34: =HYPERLINK("https://drive.google.com/file/d/1Iyu3DhJSVIFwLJ6rq_E-VG0602Mpm5mw/view", 28940) -> 28940 | F34: =IF(D34="","",(D34-E34)*$O$4) -> 19622.39 | G34: 3.1 | H34: =IF(F34="","",(F34-J34)*$O$5) -> 253.12883 | I34: =IF(F34="","",(F34-J34)*(1-$O$5)*$O$7) -> 37.770059 | J34: {=IF(F34="","",IF(ROW()=MAX(IF($C$32:$C$47=C34,ROW($C$32:$C$47),0)),MAX(0,IFERROR(VLOOKUP(C34,$A$10:$L$11,6,FALSE)-VLOOKUP(C34,$A$10:$L$11,5,FALSE),0)),0))} -> 0 | K34: =IF(F34="","",F34-H34-I34-J34) -> 19331.491 | L34: =IF(F34="","",(F34-J34)/VLOOKUP(C34,$A$10:$L$11,5,FALSE)*VLOOKUP(C34,$A$10:$L$11,10,FALSE)*$O$8) -> 80.614277 | M34: =IF(F34="","",(F34-J34)/VLOOKUP(C34,$A$10:$L$11,5,FALSE)*VLOOKUP(C34,$A$10:$L$11,11,FALSE)) -> 549.67688 | N34: =IF(F34="","",IFERROR(VLOOKUP(C34,$A$10:$L$11,12,FALSE),0)*$O$9) -> 85.8
A35: 46213 | B35: Rail_TIMX201060_6.22.2026_offload_3 | C35: TIMX201060 | D35: =HYPERLINK("https://drive.google.com/file/d/1gtX9Z0UKHcZ5y0GxViu5IRJv34Bz_QQ1/view", 73040) -> 73040 | E35: =HYPERLINK("https://drive.google.com/file/d/1vTleM-_llT-gyoKWltsO2SFmU7OCr7yQ/view", 29320) -> 29320 | F35: =IF(D35="","",(D35-E35)*$O$4) -> 19831.042 | G35: 3.1 | H35: =IF(F35="","",(F35-J35)*$O$5) -> 255.82044 | I35: =IF(F35="","",(F35-J35)*(1-$O$5)*$O$7) -> 38.171683 | J35: {=IF(F35="","",IF(ROW()=MAX(IF($C$32:$C$47=C35,ROW($C$32:$C$47),0)),MAX(0,IFERROR(VLOOKUP(C35,$A$10:$L$11,6,FALSE)-VLOOKUP(C35,$A$10:$L$11,5,FALSE),0)),0))} -> 0 | K35: =IF(F35="","",F35-H35-I35-J35) -> 19537.05 | L35: =IF(F35="","",(F35-J35)/VLOOKUP(C35,$A$10:$L$11,5,FALSE)*VLOOKUP(C35,$A$10:$L$11,10,FALSE)*$O$8) -> 81.471479 | M35: =IF(F35="","",(F35-J35)/VLOOKUP(C35,$A$10:$L$11,5,FALSE)*VLOOKUP(C35,$A$10:$L$11,11,FALSE)) -> 555.52181 | N35: =IF(F35="","",IFERROR(VLOOKUP(C35,$A$10:$L$11,12,FALSE),0)*$O$9) -> 85.8
A36: 46213 | B36: Rail_TIMX201060_6.22.2026_offload_4 | C36: TIMX201060 | D36: =HYPERLINK("https://drive.google.com/file/d/1jQP-e71r63_Qua-w9ycI4_AvwLpJwKxM/view", 71100) -> 71100 | E36: =HYPERLINK("https://drive.google.com/file/d/1ZdesDIApcdRIGiASelt5tGMbX1n7MFVA/view", 28740) -> 28740 | F36: =IF(D36="","",(D36-E36)*$O$4) -> 19214.157 | G36: 3.1 | H36: =IF(F36="","",(F36-J36)*$O$5) -> 246.82704 | I36: =IF(F36="","",(F36-J36)*(1-$O$5)*$O$7) -> 36.829751 | J36: {=IF(F36="","",IF(ROW()=MAX(IF($C$32:$C$47=C36,ROW($C$32:$C$47),0)),MAX(0,IFERROR(VLOOKUP(C36,$A$10:$L$11,6,FALSE)-VLOOKUP(C36,$A$10:$L$11,5,FALSE),0)),0))} -> 80.27808 | K36: =IF(F36="","",F36-H36-I36-J36) -> 18850.222 | L36: =IF(F36="","",(F36-J36)/VLOOKUP(C36,$A$10:$L$11,5,FALSE)*VLOOKUP(C36,$A$10:$L$11,10,FALSE)*$O$8) -> 78.607337 | M36: =IF(F36="","",(F36-J36)/VLOOKUP(C36,$A$10:$L$11,5,FALSE)*VLOOKUP(C36,$A$10:$L$11,11,FALSE)) -> 535.99236 | N36: =IF(F36="","",IFERROR(VLOOKUP(C36,$A$10:$L$11,12,FALSE),0)*$O$9) -> 85.8
A48: EE Totals (rows 32-47) | L48: =SUM(L32:L47) -> 402.84103 | M48: =SUM(M32:M47) -> 2746.8137 | N48: =SUM(N32:N47) -> 429
A50: SECTION 4 - ROLLUP (Mass Used = Deliveries - Uncertainty Adj)
A51: Pyrolysis + Upstream Transport (BOL, kg) | B51: Deliveries raw / Downstream Transport (scale tickets, kg) | C51: Uncertainty Adj (kg) | D51: Mass Used (post-adj) (kg) | E51: Sparging Loss (kg) | F51: Filtration Loss (kg) | G51: MOBI (kg) | H51: pH | N51: Origins list (BOLs)
A52: =SUM(I10:I13) -> 98013.528 | B52: =SUM(F32:F47) -> 98093.806 | C52: =SUM(J32:J47) -> 80.27808 | D52: =B52-C52 -> 98013.528 | E52: =SUM(H32:H47) -> 1264.3745 | F52: =SUM(I32:I47) -> 188.66085 | G52: =SUM(K32:K47) -> 96560.492 | H52: =IFERROR(AVERAGE(G32:G47),"") -> 3.1 | N52: =IFERROR(__xludf.DUMMYFUNCTION("TRIM(TEXTJOIN("", "",TRUE,IFERROR(FILTER(B17:B28,B17:B28<>""""),"""")))"),"2389-R, 2390-R, 2391-R, 2392-R, 2393-R, 2394-R") -> 2389-R, 2390-R, 2391-R, 2392-R, 2393-R, 2394-R

Sheet WODO
A1: BATCH HEADER — Charm WODO (IBC Totes)
A2: Batch ID (INJ-YYYY-WXX) | B2: INJ-07-2026-W2 | K2: Constants
A3: Week Start (Sat) | B3: 46207 | K3: Lbs/Kg | L3: 2.20462
A4: Week End (Sat) | B4: 46214 | K4: Kg/Lbs | L4: 0.453592
K5: Sparging Mass Loss | L5: 0.0129
K6: pH range (target) | L6: 2.0 - 4.0
A8: SECTION 1 - IBC LEDGER (one row per IBC tote; tote tag mass is authoritative)
B9: Transport Emissions | D9: Pyrolysis Emissions Mass | F9: MOBI
A10: Tag | B10: Gross Mass (kg) | C10: Tote Mass (kg) | D10: Net Oil Produced (kg) | E10: Empty Tote Weight (kg) | F10: Net Oil Injected (kg) | G10: Production Period | H10: Carbon Intensity | I10: Production Emissions | J10: Scale Uncertainty
A11: 301041 | B11: 1092 | C11: 57.6 | D11: =B11-C11 -> 1034.4 | E11: 58 | F11: =IF(E11="","",B11-E11) -> 1034 | G11: MFO Lot 301041 (LOT00301041), March 2026 | H11: 0.7901 | I11: =H11*D11 -> 817.27944 | J11: =2.5*$L$4 -> 1.13398
A12: 301089 | B12: 1078 | C12: 57.6 | D12: =B12-C12 -> 1020.4 | E12: 58 | F12: =IF(E12="","",B12-E12) -> 1020 | G12: MFO Lot 301089 (LOT00301089), April 2026 | H12: 0.7848 | I12: =H12*D12 -> 800.80992 | J12: =2.5*$L$4 -> 1.13398
A13: 301128 | B13: 1076 | C13: 57.6 | D13: =B13-C13 -> 1018.4 | E13: 62 | F13: =IF(E13="","",B13-E13) -> 1014 | G13: MFO Lot 301128 (LOT00301128), April 2026 | H13: 0.7848 | I13: =H13*D13 -> 799.24032 | J13: =2.5*$L$4 -> 1.13398
B26: =SUM(B11:B24) -> 3246 | D26: =SUM(D9:D24) -> 3073.2 | E26: =SUM(E9:E24) -> 178 | F26: =SUM(F9:F24) -> 3068 | H26: =I26/D26 -> 0.78658391 | I26: =SUM(I9:I24) -> 2417.3297 | J26: =SUM(J9:J24) -> 3.40194
A31: SECTION 2 - ROLLUP
A32: Transport Mass | B32: Σ Net Oil Produced (kg) | C32: Loss (kg) | D32: MOBI — Σ Net Oil Injected (kg)
A33: =B26 -> 3246 | B33: =SUM(D11:D24) -> 3073.2 | C33: =B33-D33 -> 5.2 | D33: =SUM(F11:F24) -> 3068

Sheet AECN Truck
A1: BATCH HEADER — AECN Truck (Direct from Fort Lupton)
A2: Batch ID (INJ-YYYY-WXX) | B2: INJ-07-2026-W2 | K2: Constants
A3: Week Start (Sat) | B3: 46207 | K3: Lbs/Kg | L3: 2.20462
A4: Week End (Sat) | B4: 46214 | K4: Kg/Lbs | L4: 0.453592
K5: Sparging Mass Loss | L5: 0.0129
K6: pH range (target) | L6: 2.0 - 4.0
K7: Filtration Solids Content | L7: =HYPERLINK("https://docs.google.com/spreadsheets/d/16shKoa1KP34kQJyQvzclBejW9L5-ubNSqPsMOVB7zDY/edit?usp=sharing", 0.00195) -> 0.00195
A8: SECTION 1 - DELIVERIES LEDGER (one row per direct truck; BOL & scale ticket on same row)
A9: Date | B9: BOL # / SO # | C9: BOL Mass (MT) | D9: BOL Mass (kg) | E9: Scale Full (lb) | F9: Scale Empty (lb) | G9: Cargo (kg) | H9: pH | I9: Notes | J9: Sparging Loss (kg) | K9: Filtration Loss (kg) | L9: MOBI (kg) | M9: C Content
J10: =IF(D10="","",D10*$L$5) | K10: =IF(D10="","",(D10-J10)*$L$7) | L10: =IF(D10="","",D10-J10-K10)
J11: =IF(D11="","",D11*$L$5) | K11: =IF(D11="","",(D11-J11)*$L$7) | L11: =IF(D11="","",D11-J11-K11)
J12: =IF(D12="","",D12*$L$5) | K12: =IF(D12="","",(D12-J12)*$L$7) | L12: =IF(D12="","",D12-J12-K12)
J13: =IF(D13="","",D13*$L$5) | K13: =IF(D13="","",(D13-J13)*$L$7) | L13: =IF(D13="","",D13-J13-K13)
J14: =IF(D14="","",D14*$L$5) | K14: =IF(D14="","",(D14-J14)*$L$7) | L14: =IF(D14="","",D14-J14-K14)
J15: =IF(D15="","",D15*$L$5) | K15: =IF(D15="","",(D15-J15)*$L$7) | L15: =IF(D15="","",D15-J15-K15)
J16: =IF(D16="","",D16*$L$5) | K16: =IF(D16="","",(D16-J16)*$L$7) | L16: =IF(D16="","",D16-J16-K16)
J17: =IF(D17="","",D17*$L$5) | K17: =IF(D17="","",(D17-J17)*$L$7) | L17: =IF(D17="","",D17-J17-K17)
J18: =IF(D18="","",D18*$L$5) | K18: =IF(D18="","",(D18-J18)*$L$7) | L18: =IF(D18="","",D18-J18-K18)
J19: =IF(D19="","",D19*$L$5) | K19: =IF(D19="","",(D19-J19)*$L$7) | L19: =IF(D19="","",D19-J19-K19)
J20: =IF(D20="","",D20*$L$5) | K20: =IF(D20="","",(D20-J20)*$L$7) | L20: =IF(D20="","",D20-J20-K20)
J21: =IF(D21="","",D21*$L$5) | K21: =IF(D21="","",(D21-J21)*$L$7) | L21: =IF(D21="","",D21-J21-K21)
... J24: =IF(D24="","",D24*$L$5) | K24: =IF(D24="","",(D24-J24)*$L$7) | L24: =IF(D24="","",D24-J24-K24)
A26: SECTION 2 - ROLLUP (Mass Used = Σ BOL kg; scale tickets no longer required for direct trucks per 2026-05-26)
A27: Σ BOL (kg) | B27: Σ Cargo (kg) | C27: Mass Used (kg) | D27: Sparging Loss (kg) | E27: Filtration Loss (kg) | F27: Uncertainty Adjustment (kg) | G27: MOBI (kg) | H27: pH | I27: C Content (MOBI-wtd) | K27: Origins list (BOLs)
A28: =SUMIFS(D10:D24,B10:B24,"<>") -> 0 | B28: =SUMIFS(G10:G24,B10:B24,"<>") -> 0 | C28: =A28 -> 0 | D28: =C28*$L$5 -> 0 | E28: =(C28-D28)*$L$7 -> 0 | F28: 0 | G28: =C28-D28-E28-F28 -> 0 | H28: =IFERROR(AVERAGE(H10:H24),"") | I28: =IFERROR(SUMPRODUCT(L10:L24,M10:M24)/SUM(L10:L24),"") | K28: =IFERROR(__xludf.DUMMYFUNCTION("TRIM(TEXTJOIN("", "",TRUE,IFERROR(FILTER(B10:B24,B10:B24<>""""),"""")))"),"")

Sheet QOWV
A1: BATCH HEADER — QOWV (Aqueous Bio-Oil, IBC Totes)
A2: Batch ID (INJ-YYYY-WXX) | B2: INJ-07-2026-W2 | K2: Constants
A3: Week Start (Sat) | B3: 46207 | K3: Lbs/Kg | L3: 2.20462
A4: Week End (Sat) | B4: 46214 | K4: Kg/Lbs | L4: 0.453592
K5: Sparging Mass Loss | L5: 0.0129
K6: pH range (target) | L6: 2.0 - 4.0
A8: SECTION 1 - IBC LEDGER (one row per IBC tote; tote tag mass is authoritative)
B9: Transport Emissions | D9: Pyrolysis Emissions Mass | F9: MOBI
A10: Tag | B10: Gross Mass (kg) | C10: Tote Mass (kg) | D10: Net Oil Produced (kg) | E10: Empty Tote Weight (kg) | F10: Net Oil Injected (kg) | G10: Production Period | H10: Carbon Intensity | I10: Production Emissions | J10: Scale Uncertainty
A11: 120555 | B11: 772 | C11: 57.6 | D11: =B11-C11 -> 714.4 | E11: 149 | F11: =IF(E11="","",B11-E11) -> 623 | G11: MFO Lot 2808 (LOT00002808), July 2025 | H11: 0.1374 | I11: =H11*D11 -> 98.15856 | J11: =2.5*$L$4 -> 1.13398
A12: 120504 | B12: 666 | C12: 57.6 | D12: =B12-C12 -> 608.4 | E12: 380 | F12: =IF(E12="","",B12-E12) -> 286 | G12: MFO Lot 2908 (LOT00002908), July 2025 | H12: 0.1374 | I12: =H12*D12 -> 83.59416 | J12: =2.5*$L$4 -> 1.13398
A13: 15194 | B13: 854.5 | C13: 57.6 | D13: =B13-C13 -> 796.9 | E13: 193.5 | F13: =IF(E13="","",B13-E13) -> 661 | G13: MFO Lot 3312 (LOT00003312), August 2025 | H13: 0.1106 | I13: =H13*D13 -> 88.13714 | J13: =2.5*$L$4 -> 1.13398
A14: 15160 | B14: 890.5 | C14: 57.6 | D14: =B14-C14 -> 832.9 | E14: 128.5 | F14: =IF(E14="","",B14-E14) -> 762 | G14: MFO Lot 3314 (LOT00003314), August 2025 | H14: 0.1106 | I14: =H14*D14 -> 92.11874 | J14: =2.5*$L$4 -> 1.13398
A15: 15189 | B15: 790 | C15: 57.6 | D15: =B15-C15 -> 732.4 | E15: 198 | F15: =IF(E15="","",B15-E15) -> 592 | G15: MFO Lot 3316 (LOT00003316), August 2025 | H15: 0.1106 | I15: =H15*D15 -> 81.00344 | J15: =2.5*$L$4 -> 1.13398
A16: 15193 | B16: 876 | C16: 57.6 | D16: =B16-C16 -> 818.4 | E16: 170 | F16: =IF(E16="","",B16-E16) -> 706 | G16: MFO Lot 3370 (LOT00003370), August 2025 | H16: 0.1106 | I16: =H16*D16 -> 90.51504 | J16: =2.5*$L$4 -> 1.13398
A17: 15192 | B17: 920.5 | C17: 57.6 | D17: =B17-C17 -> 862.9 | E17: 154.5 | F17: =IF(E17="","",B17-E17) -> 766 | G17: MFO Lot 3372 (LOT00003372), August 2025 | H17: 0.1106 | I17: =H17*D17 -> 95.43674 | J17: =2.5*$L$4 -> 1.13398
A18: 15171 | B18: 923 | C18: 57.6 | D18: =B18-C18 -> 865.4 | E18: 146 | F18: =IF(E18="","",B18-E18) -> 777 | G18: MFO Lot 3376 (LOT00003376), August 2025 | H18: 0.1106 | I18: =H18*D18 -> 95.71324 | J18: =2.5*$L$4 -> 1.13398
A19: 15168 | B19: 806.5 | C19: 57.6 | D19: =B19-C19 -> 748.9 | E19: 200.5 | F19: =IF(E19="","",B19-E19) -> 606 | G19: MFO Lot 3378 (LOT00003378), August 2025 | H19: 0.1106 | I19: =H19*D19 -> 82.82834 | J19: =2.5*$L$4 -> 1.13398
A20: 245120 | B20: 864.5 | C20: 57.6 | D20: =B20-C20 -> 806.9 | E20: 166.5 | F20: =IF(E20="","",B20-E20) -> 698 | G20: MFO Lot 3380 (LOT00003380), August 2025 | H20: 0.1106 | I20: =H20*D20 -> 89.24314 | J20: =2.5*$L$4 -> 1.13398
A21: 245115 | B21: 940 | C21: 57.6 | D21: =B21-C21 -> 882.4 | E21: 146 | F21: =IF(E21="","",B21-E21) -> 794 | G21: MFO Lot 3382 (LOT00003382), August 2025 | H21: 0.1106 | I21: =H21*D21 -> 97.59344 | J21: =2.5*$L$4 -> 1.13398
A22: 245117 | B22: 943 | C22: 57.6 | D22: =B22-C22 -> 885.4 | E22: 179 | F22: =IF(E22="","",B22-E22) -> 764 | G22: MFO Lot 3384 (LOT00003384), August 2025 | H22: 0.1106 | I22: =H22*D22 -> 97.92524 | J22: =2.5*$L$4 -> 1.13398
... A46: 228082 | B46: 1025 | C46: 57.6 | D46: =B46-C46 -> 967.4 | E46: 129 | F46: =IF(E46="","",B46-E46) -> 896 | G46: MFO Lot 4450 (LOT00004450), December 2025 | H46: 0.1631 | I46: =H46*D46 -> 157.78294 | J46: =2.5*$L$4 -> 1.13398
A53: TOTAL | B53: =SUM(B11:B46) -> 31529 | C53: =SUM(C11:C46) -> 2073.6 | D53: =SUM(D11:D46) -> 29455.4 | E53: =SUM(E11:E46) -> 6008 | F53: =SUM(F11:F46) -> 25521 | H53: =IFERROR(SUMPRODUCT(D11:D46,H11:H46)/SUM(D11:D46),"") -> 0.12104859 | I53: =SUM(I11:I46) -> 3565.5346 | J53: =SUM(J11:J46) -> 40.82328
G56: =IF(AND(D56<>"",F56<>""),(D56-F56)*$L$4,"") | H56: =IF(G56="","",G56*(1-$L$5))
G57: =IF(AND(D57<>"",F57<>""),(D57-F57)*$L$4,"") | H57: =IF(G57="","",G57*(1-$L$5))
G58: =IF(AND(D58<>"",F58<>""),(D58-F58)*$L$4,"") | H58: =IF(G58="","",G58*(1-$L$5))
G59: =IF(AND(D59<>"",F59<>""),(D59-F59)*$L$4,"") | H59: =IF(G59="","",G59*(1-$L$5))
G60: =IF(AND(D60<>"",F60<>""),(D60-F60)*$L$4,"") | H60: =IF(G60="","",G60*(1-$L$5))
G61: =IF(AND(D61<>"",F61<>""),(D61-F61)*$L$4,"") | H61: =IF(G61="","",G61*(1-$L$5))
G62: =IF(AND(D62<>"",F62<>""),(D62-F62)*$L$4,"") | H62: =IF(G62="","",G62*(1-$L$5))
G63: =IF(AND(D63<>"",F63<>""),(D63-F63)*$L$4,"") | H63: =IF(G63="","",G63*(1-$L$5))
G64: =IF(AND(D64<>"",F64<>""),(D64-F64)*$L$4,"") | H64: =IF(G64="","",G64*(1-$L$5))
G65: =IF(AND(D65<>"",F65<>""),(D65-F65)*$L$4,"") | H65: =IF(G65="","",G65*(1-$L$5))
G66: =IF(AND(D66<>"",F66<>""),(D66-F66)*$L$4,"") | H66: =IF(G66="","",G66*(1-$L$5))
G67: =IF(AND(D67<>"",F67<>""),(D67-F67)*$L$4,"") | H67: =IF(G67="","",G67*(1-$L$5))
... G73: =IF(AND(D73<>"",F73<>""),(D73-F73)*$L$4,"") | H73: =IF(G73="","",G73*(1-$L$5))

Sheet Kerry
A1: BATCH HEADER — Kerry (Calciner Waste Oil, IBC Totes)
A2: Batch ID (INJ-YYYY-WXX) | B2: INJ-07-2026-W2 | L2: Constants
A3: Week Start (Sat) | B3: 46207 | L3: Lbs/Kg | M3: 2.20462
A4: Week End (Sat) | B4: 46214 | L4: Kg/Lbs | M4: 0.453592
L5: Sparging Mass Loss | M5: 0.0129
L6: pH range (target) | M6: 2.0 - 4.0
L7: Testing Uncertainty | M7: 0.004
A8: SECTION 1 - IBC LEDGER (one row per Kerry tote; tote tag mass is authoritative)
A9: Date | B9: Tote Tag # | C9: Gross Mass (kg) — transport | D9: Tote Empty (kg) | E9: Net Oil (kg) — production | F9: Net Injected (kg) — MOBI | G9: pH | H9: Notes | I9: C Content | J9: C Content Uncertainty | K9: Mass Uncertainty (Scaling)
A31: SECTION 2 - ROLLUP
A32: Σ Net Injected (kg) | B32: Sparging Loss (kg) | C32: MOBI (kg) | D32: pH | E32: C Content (MOBI-wtd) | G32: Origins list (Tote tags)
A33: =SUMIFS(F10:F29,B10:B29,"<>") -> 0 | B33: =A33*$M$5 -> 0 | C33: =A33-B33 -> 0 | D33: =IFERROR(AVERAGE(G10:G29),"") | E33: =IFERROR(__xludf.DUMMYFUNCTION("IFERROR(AVERAGE.WEIGHTED(I10:I29,F10:F29),"""")"),"") | G33: =IFERROR(__xludf.DUMMYFUNCTION("TRIM(TEXTJOIN("", "",TRUE,IFERROR(FILTER(B10:B29,B10:B29<>""""),"""")))"),"")

Sheet QOWV Shipments & EE Allocation
A1: INJ-07-2026-W2 — QOWV Shipments & EE Allocation
A4: BATCH SUMMARY
A5: Batch | B5: Fraction | C5: Inj. Week | D5: # Totes | E5: Shipping Orders (relevant totes)
A6: INJ-07-2026-W2 | B6: QOWV | C6: 2026-07-04 to 2026-07-11 | D6: 36 | E6: COLA_8 (16), CO_AQUEOUS_12.3 (1), CO_AQUEOUS_12.3_02 (8), CO_AQUEOUS_12.01.25 (1), CO_AQUEOUS_12.1.25_T2 (1), COLA20 (9)
A8: Charm CO -> Basco LA distance (one-way mi) | B8: 1201
A10: EE ALLOCATION TABLE
A11: Truck (shipping order) | B11: Ship Date | C11: Total Totes on Truck | D11: Batch-Relevant Totes | E11: Batch Share of Truck | F11: Mileage (one-way) | G11: Allocated Miles
A12: COLA_8 | C12: 18 | D12: 16 | E12: =D12/C12 -> 0.88888889 | F12: =$B$8 -> 1201 | G12: =E12*F12 -> 1067.5556
A13: CO_AQUEOUS_12.3 | C13: 17 | D13: 1 | E13: =D13/C13 -> 0.058823529 | F13: =$B$8 -> 1201 | G13: =E13*F13 -> 70.647059
A14: CO_AQUEOUS_12.3_02 | C14: 8 | D14: 8 | E14: =D14/C14 -> 1 | F14: =$B$8 -> 1201 | G14: =E14*F14 -> 1201
A15: CO_AQUEOUS_12.01.25 | C15: 20 | D15: 1 | E15: =D15/C15 -> 0.05 | F15: =$B$8 -> 1201 | G15: =E15*F15 -> 60.05
A16: CO_AQUEOUS_12.1.25_T2 | C16: 20 | D16: 1 | E16: =D16/C16 -> 0.05 | F16: =$B$8 -> 1201 | G16: =E16*F16 -> 60.05
A17: COLA20 | C17: 19 | D17: 9 | E17: =D17/C17 -> 0.47368421 | F17: =$B$8 -> 1201 | G17: =E17*F17 -> 568.89474
A18: TOTAL | C18: =SUM(C12:C17) -> 102 | D18: =SUM(D12:D17) -> 36 | G18: =SUM(G12:G17) -> 3028.1974
A20: BATCH MILEAGE ALLOCATION
A21: Batch | B21: Per-Truck Allocation | C21: Allocated Miles | D21: # Totes
A22: INJ-07-2026-W2 | B22: COLA_8 (16/18), CO_AQUEOUS_12.3 (1/17), CO_AQUEOUS_12.3_02 (8/8), CO_AQUEOUS_12.01.25 (1/20), CO_AQUEOUS_12.1.25_T2 (1/20), COLA20 (9/19) | C22: =G18 -> 3028.1974 | D22: =D18 -> 36
A24: --- Shipping Order COLA_8 ---
A25: Metal Tag | B25: Fraction | C25: Production Period | D25: Shipping Order | E25: Batch
A26: 120555 | B26: QOWV | C26: 45839 | D26: COLA_8 | E26: INJ-07-2026-W2
A27: 15160 | B27: QOWV | C27: 45870 | D27: COLA_8 | E27: INJ-07-2026-W2
A28: 15193 | B28: QOWV | C28: 45870 | D28: COLA_8 | E28: INJ-07-2026-W2
A29: 15171 | B29: QOWV | C29: 45870 | D29: COLA_8 | E29: INJ-07-2026-W2
A30: 15168 | B30: QOWV | C30: 45870 | D30: COLA_8 | E30: INJ-07-2026-W2
A31: 245120 | B31: QOWV | C31: 45870 | D31: COLA_8 | E31: INJ-07-2026-W2
A32: 245115 | B32: QOWV | C32: 45870 | D32: COLA_8 | E32: INJ-07-2026-W2
A33: 245117 | B33: QOWV | C33: 45870 | D33: COLA_8 | E33: INJ-07-2026-W2
A34: 245119 | B34: QOWV | C34: 45870 | D34: COLA_8 | E34: INJ-07-2026-W2
A35: 245116 | B35: QOWV | C35: 45870 | D35: COLA_8 | E35: INJ-07-2026-W2
A36: 245193 | B36: QOWV | C36: 45870 | D36: COLA_8 | E36: INJ-07-2026-W2
A37: 245194 | B37: QOWV | C37: 45870 | D37: COLA_8 | E37: INJ-07-2026-W2
... A41: 245169 | B41: QOWV | C41: 45870 | D41: COLA_8 | E41: INJ-07-2026-W2
A42: --- Shipping Order CO_AQUEOUS_12.3 ---
A43: Metal Tag | B43: Fraction | C43: Production Period | D43: Shipping Order | E43: Batch
A44: 120504 | B44: QOWV | C44: 45839 | D44: CO_AQUEOUS_12.3 | E44: INJ-07-2026-W2
A45: --- Shipping Order CO_AQUEOUS_12.3_02 ---
A46: Metal Tag | B46: Fraction | C46: Production Period | D46: Shipping Order | E46: Batch
A47: 15194 | B47: QOWV | C47: 45870 | D47: CO_AQUEOUS_12.3_02 | E47: INJ-07-2026-W2
A48: 15189 | B48: QOWV | C48: 45870 | D48: CO_AQUEOUS_12.3_02 | E48: INJ-07-2026-W2
A49: 15192 | B49: QOWV | C49: 45870 | D49: CO_AQUEOUS_12.3_02 | E49: INJ-07-2026-W2
...

Sheet WODO Shipments & EE Allocation
A1: INJ-07-2026-W2 — WODO Shipments & EE Allocation
A4: BATCH SUMMARY
A5: Batch | B5: Fraction | C5: Inj. Week | D5: # Totes | E5: Shipping Orders (relevant totes)
A6: INJ-07-2026-W2 | B6: WODO | C6: 2026-07-04 to 2026-07-11 | D6: 3 | E6: COLA18 (3)
A8: Charm CO -> Basco LA distance (one-way mi) | B8: 1201
A10: EE ALLOCATION TABLE
A11: Truck (shipping order) | B11: Ship Date | C11: Total Totes on Truck | D11: Batch-Relevant Totes | E11: Batch Share of Truck | F11: Mileage (one-way) | G11: Allocated Miles
A12: COLA18 | C12: 3 | D12: 3 | E12: =D12/C12 -> 1 | F12: =$B$8 -> 1201 | G12: =E12*F12 -> 1201
A13: TOTAL | C13: =SUM(C12) -> 3 | D13: =SUM(D12) -> 3 | G13: =SUM(G12) -> 1201
A15: BATCH MILEAGE ALLOCATION
A16: Batch | B16: Per-Truck Allocation | C16: Allocated Miles | D16: # Totes
A17: INJ-07-2026-W2 | B17: COLA18 (3/3) | C17: =G13 -> 1201 | D17: =D13 -> 3
A19: --- Shipping Order COLA18 ---
A20: Metal Tag | B20: Fraction | C20: Production Period | D20: Shipping Order | E20: Batch
A21: 301041 | B21: WODO | C21: 46082 | D21: COLA18 | E21: INJ-07-2026-W2
A22: 301089 | B22: WODO | C22: 46113 | D22: COLA18 | E22: INJ-07-2026-W2
A23: 301128 | B23: WODO | C23: 46113 | D23: COLA18 | E23: INJ-07-2026-W2
