Workbook

Sheet Summary
A1: BATCH SUMMARY
A2: Batch ID | B2: INJ-06-2026-W2
A3: Week Start (Sat) | B3: 46179
A4: Week End (Sat) | B4: 46186
A6: SECTION 1 - PER-TAB SUMMARY (each row pulls from its mode tab)
A7: Source Tab | B7: Σ Deliveries / Cargo (kg) | C7: Σ Uncertainty Adj (kg) | D7: Mass Used (kg) | E7: Sparging Loss (kg) | F7: Filtration Loss (kg) | G7: MOBI (kg) | H7: AECN→SOPOR EE (mi) | I7: Rail EE (mi) | J7: Opel→Basco EE (mi)
A8: AECN Rail | B8: ='AECN Rail'!A52 -> 312715.4 | C8: ='AECN Rail'!B52 -> 1046.235 | D8: ='AECN Rail'!C52 -> 311669.16 | E8: ='AECN Rail'!D52 -> 4020.5322 | F8: ='AECN Rail'!E52 -> 599.91483 | G8: ='AECN Rail'!F52 -> 307048.71 | H8: =SUM('AECN Rail'!L32:L47) -> 1286.225 | I8: =SUM('AECN Rail'!M32:M47) -> 8770.2601 | J8: =SUM('AECN Rail'!N32:N47) -> 1372.8
A9: AECN Truck | B9: ='AECN Truck'!B28 -> 0 | C9: ='AECN Truck'!F28 -> 0 | D9: ='AECN Truck'!C28 -> 0 | E9: ='AECN Truck'!D28 -> 0 | F9: ='AECN Truck'!E28 -> 0 | G9: ='AECN Truck'!G28 -> 0
A10: Charm WODO | B10: =WODO!A33 -> 15480.6 | C10: 0 | D10: =WODO!A33 -> 15480.6 | E10: =WODO!B33 -> 76.6 | F10: 0 | G10: =WODO!C33 -> 15404
A11: Kerry | B11: =Kerry!A33 -> 0 | C11: 0 | D11: =Kerry!A33 -> 0 | E11: =Kerry!B33 -> 0 | F11: 0 | G11: =Kerry!C33 -> 0
A12: QOWV | B12: =QOWV!B53 -> 37833 | C12: 0 | D12: =QOWV!D53 -> 35759.4 | E12: 0 | F12: 0 | G12: =QOWV!F53 -> 31437
A13: TOTAL | B13: =SUM(B8:B12) -> 366029 | C13: =SUM(C8:C12) -> 1046.235 | D13: =SUM(D8:D12) -> 362909.16 | E13: =SUM(E8:E12) -> 4097.1322 | F13: =SUM(F8:F12) -> 599.91483 | G13: =SUM(G8:G12) -> 353889.71 | H13: =SUM(H8:H12) -> 1286.225 | I13: =SUM(I8:I12) -> 8770.2601 | J13: =SUM(J8:J12) -> 1372.8
A15: SECTION 2 - PER-OIL-TYPE ROLLUP (composite C% per oil type per week)
A16: Oil Type | B16: MOBI (kg) | C16: Composite Sample ID | D16: C % | E16: Lab COA Link | F16: C Content Uncertainty | G16: Testing Uncertainty
A17: AECN | B17: =G8+G9 -> 307048.71 | C17: 6-2026-W2 AECN | D17: 0.408 | F17: =D17*G17 -> 0.001632 | G17: 0.004
A18: WODO | B18: =G10 -> 15404 | F18: =D18*G18 -> 0 | G18: 0.004
A19: Kerry | B19: =G11 -> 0
A20: QOWV | B20: =G12 -> 31437 | F20: =D20*G20 -> 0 | G20: 0.004
A21: TOTAL | B21: =SUM(B17:B20) -> 353889.71

Sheet AECN Rail
A1: BATCH HEADER — AECN Rail
A2: Batch ID (INJ-YYYY-WXX) | B2: INJ-06-2026-W2 | N2: Constants
A3: Week Start (Sat) | B3: 46179 | N3: Lbs/Kg | O3: 2.20462
A4: Week End (Sat) | B4: 46186 | N4: Kg/Lbs | O4: 0.453592
N5: Sparging Mass Loss | O5: 0.0129
N6: pH range (target) | O6: 2.0 - 4.0
N7: Filtration Solids Content | O7: =HYPERLINK("https://docs.google.com/spreadsheets/d/16shKoa1KP34kQJyQvzclBejW9L5-ubNSqPsMOVB7zDY/edit?usp=sharing", 0.00195) -> 0.00195
A8: SECTION 1 - RAILCARS RECEIVED THIS WEEK (entity-level) | N8: BOL Trips (AECN→SOPOR) | O8: 3
A9: Railcar # | B9: Arrival Date at Opelousas | C9: Loading BOLs (comma-sep) | D9: Total Loaded (MT) | E9: Total Loaded (kg) | F9: Total Offloaded (kg, auto) | G9: Loss (kg) | H9: Prior Period Mass | I9: Prior-RP Claimed (kg) | J9: AECN→SOPOR (mi) | K9: Rail (mi) | L9: Opel→Basco (mi) | M9: Notes | N9: Round Trip (Opel→Basco) | O9: 2
A10: GPRX5240 | B10: 46149 | C10: 2356-R, 2357-R, 2358-R | D10: 77.73 | E10: 77730 | F10: =SUMIF($C$32:$C$47,A10,$F$32:$F$47)+H10 -> 76947.347 | G10: =IF(AND(E10<>"",F10<>"",F10>=0.95*E10),E10-F10,"") -> 782.65312 | H10: 0 | I10: =E10-H10 -> 77730 | J10: 107.5 | K10: 2199 | L10: 42.9 | M10: New loading. Prior-RP claimed: 0 kg.
A11: GPRX5139 | B11: 46150 | C11: 2365-R, 2366-R, 2367-R | D11: 78.14 | E11: 78140 | F11: =SUMIF($C$32:$C$47,A11,$F$32:$F$47)+H11 -> 78072.255 | G11: =IF(AND(E11<>"",F11<>"",F11>=0.95*E11),E11-F11,"") -> 67.74496 | H11: 0 | I11: =E11-H11 -> 78140 | J11: 107.5 | K11: 2199 | L11: 42.9 | M11: New loading. Prior-RP claimed: 0 kg.
A12: TILX200228 | B12: 46153 | C12: 2371-R, 2372-R, 2373-R | D12: 78.16 | E12: 78160 | F12: =SUMIF($C$32:$C$47,A12,$F$32:$F$47)+H12 -> 79206.235 | G12: =IF(AND(E12<>"",F12<>"",F12>=0.95*E12),E12-F12,"") -> -1046.235 | H12: 0 | I12: =E12-H12 -> 78160 | J12: 107.5 | K12: 2199 | L12: 42.9 | M12: New loading (5.11.2026). Prior COBB entries are separate trips; prior-RP claimed=0.
A13: GPRX5106 | B13: 46155 | C13: 2374-R, 2375-R, 2376-R | D13: 78.55 | E13: 78550 | F13: =SUMIF($C$32:$C$47,A13,$F$32:$F$47)+H13 -> 78489.56 | G13: =IF(AND(E13<>"",F13<>"",F13>=0.95*E13),E13-F13,"") -> 60.44032 | H13: 0 | I13: =E13-H13 -> 78550 | J13: 107.5 | K13: 2199 | L13: 42.9 | M13: New loading. Prior-RP claimed: 0 kg.
A15: SECTION 2 - ORIGINS LEDGER (loading BOLs at SOPOR)
A16: Date | B16: BOL # | C16: Railcar # | D16: BOL Mass (MT) | E16: BOL Mass (kg)
A17: 46149 | B17: =HYPERLINK("https://drive.google.com/file/d/1vg7nEvLsucGgbfDmiU8L8mW6rzpEuNIv/view","2356-R") -> 2356-R | C17: GPRX5240 | D17: 25.82 | E17: 25820
A18: 46149 | B18: =HYPERLINK("https://drive.google.com/file/d/1krKxAuH-DbXN9s5iq6PYuXSyNdBVn3n0/view","2357-R") -> 2357-R | C18: GPRX5240 | D18: 25.82 | E18: 25820
A19: 46149 | B19: =HYPERLINK("https://drive.google.com/file/d/1usMicBmGMeNx329XU1m87DieIFdOVqdE/view","2358-R") -> 2358-R | C19: GPRX5240 | D19: 26.09 | E19: 26090
A20: 46150 | B20: =HYPERLINK("https://drive.google.com/file/d/1Z2fhfX0p3Jr2mMYUZhtZ6GkBNGFinbzz/view","2365-R") -> 2365-R | C20: GPRX5139 | D20: 25.9 | E20: 25900
A21: 46150 | B21: =HYPERLINK("https://drive.google.com/file/d/17bAPK44won-kXWtPL_58jH3OjSByrbik/view","2366-R") -> 2366-R | C21: GPRX5139 | D21: 26.1 | E21: 26100
A22: 46150 | B22: =HYPERLINK("https://drive.google.com/file/d/1fykgF9gnvdeUut1QAEZtif94NzzolEZw/view","2367-R") -> 2367-R | C22: GPRX5139 | D22: 26.14 | E22: 26140
A23: 46153 | B23: =HYPERLINK("https://drive.google.com/file/d/1ozXYn6L97OjJ5I7KfrJC_gbjMiSNPDJ0/view","2371-R") -> 2371-R | C23: TILX200228 | D23: 25.93 | E23: 25930
A24: 46153 | B24: =HYPERLINK("https://drive.google.com/file/d/1LvICkmZIUSr0ePBmKFnEJGyq8PNOto39/view","2372-R") -> 2372-R | C24: TILX200228 | D24: 26 | E24: 26000
A25: 46153 | B25: =HYPERLINK("https://drive.google.com/file/d/19b5M9G8qOfJpiOWBTfgJzoF8WuBKRoWI/view","2373-R") -> 2373-R | C25: TILX200228 | D25: 26.23 | E25: 26230
A26: 46155 | B26: =HYPERLINK("https://drive.google.com/file/d/1SA7HyJLkykR_A1usVFJ99rniIvXYoOMb/view","2374-R") -> 2374-R | C26: GPRX5106 | D26: 26.16 | E26: 26160
A27: 46155 | B27: =HYPERLINK("https://drive.google.com/file/d/14iM4fibnuU_QJvb-ko1giNNRVVPxdFtU/view","2375-R") -> 2375-R | C27: GPRX5106 | D27: 26.2 | E27: 26200
A28: 46155 | B28: =HYPERLINK("https://drive.google.com/file/d/1L2NksqEFbEIjD-mNj1ZAFN2rEJuT3D-A/view","2376-R") -> 2376-R | C28: GPRX5106 | D28: 26.19 | E28: 26190
A30: SECTION 3 - SCALE TICKETS + OFFLOAD WEIGHTS
D31: Full Scale Ticket (lb) | E31: Empty Scale Ticket (lb) | F31: Net Scaled Mass (kg) | G31: pH | H31: Sparging Loss (kg) | I31: Filtration Loss (kg) | J31: Uncertainty Adjustment (kg) | K31: MOBI (kg) | L31: AECN->SOPOR (mi, x3) | M31: Rail (mi, alloc) | N31: Opel->Basco (mi, x2)
A32: 46187 | B32: Rail_GPRX5240_5.7.2026_offload_1 | C32: GPRX5240 | D32: =HYPERLINK("https://drive.google.com/file/d/1IH9TQaxlB7cAC950ez_Dfmf9NfZdO411/view",80080) -> 80080 | E32: =HYPERLINK("https://drive.google.com/file/d/1YCU7u2meB2mdPilVWgCWiEhncmN73gLE/view",28860) -> 28860 | F32: =(D32-E32)*$O$4 -> 23232.982 | G32: 2.7 | H32: =IF(F32="","",(F32-J32)*$O$5) -> 299.70547 | I32: =IF(F32="","",(F32-J32)*(1-$O$5)*$O$7) -> 44.71989 | J32: 0 | K32: =IF(F32="","",F32-H32-I32-J32) -> 22888.557 | L32: =IF(F32="","",(F32-J32)/VLOOKUP(C32,$A$10:$L$13,5,FALSE)*VLOOKUP(C32,$A$10:$L$13,10,FALSE)*$O$8) -> 96.393114 | M32: =IF(F32="","",(F32-J32)/VLOOKUP(C32,$A$10:$L$13,5,FALSE)*VLOOKUP(C32,$A$10:$L$13,11,FALSE)) -> 657.26654 | N32: =IF(F32="","",IFERROR(VLOOKUP(C32,$A$10:$L$13,12,FALSE),0)*$O$9) -> 85.8
A33: 46187 | B33: Rail_GPRX5240_5.7.2026_offload_2 | C33: GPRX5240 | D33: =HYPERLINK("https://drive.google.com/file/d/1Q3xiDM-F60Lk-gMXCyeaerJVUoerrMEG/view",78360) -> 78360 | E33: =HYPERLINK("https://drive.google.com/file/d/1ZW96ZQkWSJgmaNw7F-2oJMxyAuzObG3k/view",29480) -> 29480 | F33: =(D33-E33)*$O$4 -> 22171.577 | G33: 2.7 | H33: =IF(F33="","",(F33-J33)*$O$5) -> 286.01334 | I33: =IF(F33="","",(F33-J33)*(1-$O$5)*$O$7) -> 42.676849 | J33: 0 | K33: =IF(F33="","",F33-H33-I33-J33) -> 21842.887 | L33: =IF(F33="","",(F33-J33)/VLOOKUP(C33,$A$10:$L$13,5,FALSE)*VLOOKUP(C33,$A$10:$L$13,10,FALSE)*$O$8) -> 91.989368 | M33: =IF(F33="","",(F33-J33)/VLOOKUP(C33,$A$10:$L$13,5,FALSE)*VLOOKUP(C33,$A$10:$L$13,11,FALSE)) -> 627.23913 | N33: =IF(F33="","",IFERROR(VLOOKUP(C33,$A$10:$L$13,12,FALSE),0)*$O$9) -> 85.8
A34: 46187 | B34: Rail_GPRX5240_5.7.2026_offload_3 | C34: GPRX5240 | D34: =HYPERLINK("https://drive.google.com/file/d/1uyIwNTVkKeMMO6c0VvEp620peyrVP6ZO/view",75500) -> 75500 | E34: =HYPERLINK("https://drive.google.com/file/d/1F7auZRUdT6_MkM2wC-odo2AJV7p_XW4R/view",29660) -> 29660 | F34: =(D34-E34)*$O$4 -> 20792.657 | G34: 2.7 | H34: =IF(F34="","",(F34-J34)*$O$5) -> 268.22528 | I34: =IF(F34="","",(F34-J34)*(1-$O$5)*$O$7) -> 40.022642 | J34: 0 | K34: =IF(F34="","",F34-H34-I34-J34) -> 20484.409 | L34: =IF(F34="","",(F34-J34)/VLOOKUP(C34,$A$10:$L$13,5,FALSE)*VLOOKUP(C34,$A$10:$L$13,10,FALSE)*$O$8) -> 86.268262 | M34: =IF(F34="","",(F34-J34)/VLOOKUP(C34,$A$10:$L$13,5,FALSE)*VLOOKUP(C34,$A$10:$L$13,11,FALSE)) -> 588.22917 | N34: =IF(F34="","",IFERROR(VLOOKUP(C34,$A$10:$L$13,12,FALSE),0)*$O$9) -> 85.8
A35: 46187 | B35: Rail_GPRX5240_5.7.2026_offload_4 | C35: GPRX5240 | D35: =HYPERLINK("https://drive.google.com/file/d/1qzfbUAmmm6ldCcKCswj5_fkzL53UgWOq/view",53220) -> 53220 | E35: =HYPERLINK("https://drive.google.com/file/d/1-ZIAfNVkLNBvBB1LgWFabzbGyydoJjRS/view",29520) -> 29520 | F35: =(D35-E35)*$O$4 -> 10750.13 | G35: 2.7 | H35: =IF(F35="","",(F35-J35)*$O$5) -> 138.67668 | I35: =IF(F35="","",(F35-J35)*(1-$O$5)*$O$7) -> 20.692335 | J35: =MAX(0,IFERROR(VLOOKUP(C35,$A$10:$L$13,6,FALSE)-VLOOKUP(C35,$A$10:$L$13,5,FALSE),0)) -> 0 | K35: =IF(F35="","",F35-H35-I35-J35) -> 10590.761 | L35: =IF(F35="","",(F35-J35)/VLOOKUP(C35,$A$10:$L$13,5,FALSE)*VLOOKUP(C35,$A$10:$L$13,10,FALSE)*$O$8) -> 44.602046 | M35: =IF(F35="","",(F35-J35)/VLOOKUP(C35,$A$10:$L$13,5,FALSE)*VLOOKUP(C35,$A$10:$L$13,11,FALSE)) -> 304.12372 | N35: =IF(F35="","",IFERROR(VLOOKUP(C35,$A$10:$L$13,12,FALSE),0)*$O$9) -> 85.8
A36: 46187 | B36: Rail_GPRX5139_5.8.2026_offload_1 | C36: GPRX5139 | D36: =HYPERLINK("https://drive.google.com/file/d/1VB9Q56NO_2Hy5L0KK4dGtqe4LMtsFkQ1/view",79260) -> 79260 | E36: =HYPERLINK("https://drive.google.com/file/d/1Mexndl2ECLx8AS9T7Z47D50pYCc0o8oi/view",29380) -> 29380 | F36: =(D36-E36)*$O$4 -> 22625.169 | G36: 2.7 | H36: =IF(F36="","",(F36-J36)*$O$5) -> 291.86468 | I36: =IF(F36="","",(F36-J36)*(1-$O$5)*$O$7) -> 43.549943 | J36: 0 | K36: =IF(F36="","",F36-H36-I36-J36) -> 22289.754 | L36: =IF(F36="","",(F36-J36)/VLOOKUP(C36,$A$10:$L$13,5,FALSE)*VLOOKUP(C36,$A$10:$L$13,10,FALSE)*$O$8) -> 93.378769 | M36: =IF(F36="","",(F36-J36)/VLOOKUP(C36,$A$10:$L$13,5,FALSE)*VLOOKUP(C36,$A$10:$L$13,11,FALSE)) -> 636.71291 | N36: =IF(F36="","",IFERROR(VLOOKUP(C36,$A$10:$L$13,12,FALSE),0)*$O$9) -> 85.8
A37: 46187 | B37: Rail_GPRX5139_5.8.2026_offload_2 | C37: GPRX5139 | D37: =HYPERLINK("https://drive.google.com/file/d/1p5Jj_-6GS8kEbq80zJm0tJmyJ4w1FMEq/view",76020) -> 76020 | E37: =HYPERLINK("https://drive.google.com/file/d/1grnI5djqhJl8ybrJ9Hlm252AZLz7nYdm/view",29340) -> 29340 | F37: =(D37-E37)*$O$4 -> 21173.675 | G37: 2.7 | H37: =IF(F37="","",(F37-J37)*$O$5) -> 273.1404 | I37: =IF(F37="","",(F37-J37)*(1-$O$5)*$O$7) -> 40.756042 | J37: 0 | K37: =IF(F37="","",F37-H37-I37-J37) -> 20859.778 | L37: =IF(F37="","",(F37-J37)/VLOOKUP(C37,$A$10:$L$13,5,FALSE)*VLOOKUP(C37,$A$10:$L$13,10,FALSE)*$O$8) -> 87.38815 | M37: =IF(F37="","",(F37-J37)/VLOOKUP(C37,$A$10:$L$13,5,FALSE)*VLOOKUP(C37,$A$10:$L$13,11,FALSE)) -> 595.86525 | N37: =IF(F37="","",IFERROR(VLOOKUP(C37,$A$10:$L$13,12,FALSE),0)*$O$9) -> 85.8
A38: 46187 | B38: Rail_GPRX5139_5.8.2026_offload_3 | C38: GPRX5139 | D38: =HYPERLINK("https://drive.google.com/file/d/1j86bAOWsgD7dDKBzSb1h-KuX01ywqMVT/view",72400) -> 72400 | E38: =HYPERLINK("https://drive.google.com/file/d/1TcDXkehTVxkuXypfDffpcbB-xNQy7ti3/view",29560) -> 29560 | F38: =(D38-E38)*$O$4 -> 19431.881 | G38: 2.7 | H38: =IF(F38="","",(F38-J38)*$O$5) -> 250.67127 | I38: =IF(F38="","",(F38-J38)*(1-$O$5)*$O$7) -> 37.40336 | J38: 0 | K38: =IF(F38="","",F38-H38-I38-J38) -> 19143.807 | L38: =IF(F38="","",(F38-J38)/VLOOKUP(C38,$A$10:$L$13,5,FALSE)*VLOOKUP(C38,$A$10:$L$13,10,FALSE)*$O$8) -> 80.199408 | M38: =IF(F38="","",(F38-J38)/VLOOKUP(C38,$A$10:$L$13,5,FALSE)*VLOOKUP(C38,$A$10:$L$13,11,FALSE)) -> 546.84805 | N38: =IF(F38="","",IFERROR(VLOOKUP(C38,$A$10:$L$13,12,FALSE),0)*$O$9) -> 85.8
A39: 46187 | B39: Rail_GPRX5139_5.8.2026_offload_4 | C39: GPRX5139 | D39: =HYPERLINK("https://drive.google.com/file/d/1R2hdDpsNaTTjpfMgNCU0APKX1kE0218j/view",61960) -> 61960 | E39: =HYPERLINK("https://drive.google.com/file/d/1W_nWc1sEdah-boT6M7L4whjYJ31y_wYk/view",29240) -> 29240 | F39: =(D39-E39)*$O$4 -> 14841.53 | G39: 2.7 | H39: =IF(F39="","",(F39-J39)*$O$5) -> 191.45574 | I39: =IF(F39="","",(F39-J39)*(1-$O$5)*$O$7) -> 28.567645 | J39: =MAX(0,IFERROR(VLOOKUP(C39,$A$10:$L$13,6,FALSE)-VLOOKUP(C39,$A$10:$L$13,5,FALSE),0)) -> 0 | K39: =IF(F39="","",F39-H39-I39-J39) -> 14621.507 | L39: =IF(F39="","",(F39-J39)/VLOOKUP(C39,$A$10:$L$13,5,FALSE)*VLOOKUP(C39,$A$10:$L$13,10,FALSE)*$O$8) -> 61.254076 | M39: =IF(F39="","",(F39-J39)/VLOOKUP(C39,$A$10:$L$13,5,FALSE)*VLOOKUP(C39,$A$10:$L$13,11,FALSE)) -> 417.66733 | N39: =IF(F39="","",IFERROR(VLOOKUP(C39,$A$10:$L$13,12,FALSE),0)*$O$9) -> 85.8
A40: 46187 | B40: Rail_TILX200228_5.11.2026_offload_1 | C40: TILX200228 | D40: =HYPERLINK("https://drive.google.com/file/d/1xLRw4GeqCfikUgkMtyRXuYOXGvyEoYF8/view",80240) -> 80240 | E40: =HYPERLINK("https://drive.google.com/file/d/1ivRr9Oc3eTI2pvzZPu2ZXTpDGxBMtW8G/view",29400) -> 29400 | F40: =(D40-E40)*$O$4 -> 23060.617 | G40: 2.7 | H40: =IF(F40="","",(F40-J40)*$O$5) -> 297.48196 | I40: =IF(F40="","",(F40-J40)*(1-$O$5)*$O$7) -> 44.388114 | J40: 0 | K40: =IF(F40="","",F40-H40-I40-J40) -> 22718.747 | L40: =IF(F40="","",(F40-J40)/VLOOKUP(C40,$A$10:$L$13,5,FALSE)*VLOOKUP(C40,$A$10:$L$13,10,FALSE)*$O$8) -> 95.1516 | M40: =IF(F40="","",(F40-J40)/VLOOKUP(C40,$A$10:$L$13,5,FALSE)*VLOOKUP(C40,$A$10:$L$13,11,FALSE)) -> 648.80114 | N40: =IF(F40="","",IFERROR(VLOOKUP(C40,$A$10:$L$13,12,FALSE),0)*$O$9) -> 85.8
A41: 46187 | B41: Rail_TILX200228_5.11.2026_offload_2 | C41: TILX200228 | D41: =HYPERLINK("https://drive.google.com/file/d/1oklSTp1YbzWSlaWSE9vOtMy_Jkwu8HFe/view",79080) -> 79080 | E41: =HYPERLINK("https://drive.google.com/file/d/1VPjcRSDkPv72Skze6G5g68EsjzcYDWhS/view",28920) -> 28920 | F41: =(D41-E41)*$O$4 -> 22752.175 | G41: 2.7 | H41: =IF(F41="","",(F41-J41)*$O$5) -> 293.50305 | I41: =IF(F41="","",(F41-J41)*(1-$O$5)*$O$7) -> 43.79441 | J41: 0 | K41: =IF(F41="","",F41-H41-I41-J41) -> 22414.877 | L41: =IF(F41="","",(F41-J41)/VLOOKUP(C41,$A$10:$L$13,5,FALSE)*VLOOKUP(C41,$A$10:$L$13,10,FALSE)*$O$8) -> 93.878919 | M41: =IF(F41="","",(F41-J41)/VLOOKUP(C41,$A$10:$L$13,5,FALSE)*VLOOKUP(C41,$A$10:$L$13,11,FALSE)) -> 640.12324 | N41: =IF(F41="","",IFERROR(VLOOKUP(C41,$A$10:$L$13,12,FALSE),0)*$O$9) -> 85.8
A42: 46187 | B42: Rail_TILX200228_5.11.2026_offload_3 | C42: TILX200228 | D42: =HYPERLINK("https://drive.google.com/file/d/1poO7bqN-YTnev2HlUBvnr19hKEO9g5Nu/view",78560) -> 78560 | E42: =HYPERLINK("https://drive.google.com/file/d/1adApkIyVEwccbck8rZ_XWqIWaukR7Jua/view",29260) -> 29260 | F42: =(D42-E42)*$O$4 -> 22362.086 | G42: 2.7 | H42: =IF(F42="","",(F42-J42)*$O$5) -> 288.4709 | I42: =IF(F42="","",(F42-J42)*(1-$O$5)*$O$7) -> 43.043549 | J42: 0 | K42: =IF(F42="","",F42-H42-I42-J42) -> 22030.571 | L42: =IF(F42="","",(F42-J42)/VLOOKUP(C42,$A$10:$L$13,5,FALSE)*VLOOKUP(C42,$A$10:$L$13,10,FALSE)*$O$8) -> 92.269353 | M42: =IF(F42="","",(F42-J42)/VLOOKUP(C42,$A$10:$L$13,5,FALSE)*VLOOKUP(C42,$A$10:$L$13,11,FALSE)) -> 629.14824 | N42: =IF(F42="","",IFERROR(VLOOKUP(C42,$A$10:$L$13,12,FALSE),0)*$O$9) -> 85.8
...

Sheet WODO
A1: BATCH HEADER — Charm WODO (IBC Totes)
A2: Batch ID (INJ-YYYY-WXX) | B2: INJ-06-2026-W2 | K2: Constants
A3: Week Start (Sat) | B3: 46179 | K3: Lbs/Kg | L3: 2.20462
A4: Week End (Sat) | B4: 46186 | K4: Kg/Lbs | L4: 0.453592
K5: Sparging Mass Loss | L5: 0.0129
K6: pH range (target) | L6: 2.0 - 4.0
A8: SECTION 1 - IBC LEDGER (one row per IBC tote; tote tag mass is authoritative)
B9: Transport Emissions | D9: Pyrolysis Emissions Mass | F9: MOBI
A10: Tag | B10: Gross Mass (kg) | C10: Tote Mass (kg) | D10: Net Oil Produced (kg) | E10: Empty Tote Weight (kg) | F10: Net Oil Injected (kg) | G10: Production Period | H10: Carbon Intensity | I10: Production Emissions | J10: Scale Uncertainty
A11: 301007 | B11: 1129 | C11: 57.6 | D11: =B11-C11 -> 1071.4 | E11: 64 | F11: =IF(E11="","",B11-E11) -> 1065 | G11: MFO Lot 301007 (LOT00301007), April 2026 | H11: 0.96110149 | I11: =H11*D11 -> 1029.7241 | J11: =2.5*$L$4 -> 1.13398
A12: 301023 | B12: 1194 | C12: 57.6 | D12: =B12-C12 -> 1136.4 | E12: 61.5 | F12: =IF(E12="","",B12-E12) -> 1132.5 | G12: MFO Lot 301023 (LOT00301023), April 2026 | H12: 0.96110149 | I12: =H12*D12 -> 1092.1957 | J12: =2.5*$L$4 -> 1.13398
A13: 301033 | B13: 1192 | C13: 57.6 | D13: =B13-C13 -> 1134.4 | E13: 66.5 | F13: =IF(E13="","",B13-E13) -> 1125.5 | G13: MFO Lot 301033 (LOT00301033), April 2026 | H13: 0.96110149 | I13: =H13*D13 -> 1090.2735 | J13: =2.5*$L$4 -> 1.13398
A14: 301058 | B14: 1200 | C14: 57.6 | D14: =B14-C14 -> 1142.4 | E14: 61 | F14: =IF(E14="","",B14-E14) -> 1139 | G14: MFO Lot 301058 (LOT00301058), March 2026 | H14: 0.79006453 | I14: =H14*D14 -> 902.56972 | J14: =2.5*$L$4 -> 1.13398
A15: 301066 | B15: 1147 | C15: 57.6 | D15: =B15-C15 -> 1089.4 | E15: 70 | F15: =IF(E15="","",B15-E15) -> 1077 | G15: MFO Lot 301066 (LOT00301066), March 2026 | H15: 0.79006453 | I15: =H15*D15 -> 860.6963 | J15: =2.5*$L$4 -> 1.13398
A16: 301090 | B16: 1124 | C16: 57.6 | D16: =B16-C16 -> 1066.4 | E16: 54 | F16: =IF(E16="","",B16-E16) -> 1070 | G16: MFO Lot 301090 (LOT00301090), April 2026 | H16: 0.96110149 | I16: =H16*D16 -> 1024.9186 | J16: =2.5*$L$4 -> 1.13398
A17: 301098 | B17: 1172 | C17: 57.6 | D17: =B17-C17 -> 1114.4 | E17: 59 | F17: =IF(E17="","",B17-E17) -> 1113 | G17: MFO Lot 301098 (LOT00301098), April 2026 | H17: 0.96110149 | I17: =H17*D17 -> 1071.0515 | J17: =2.5*$L$4 -> 1.13398
A18: 301109 | B18: 1162 | C18: 57.6 | D18: =B18-C18 -> 1104.4 | E18: 69 | F18: =IF(E18="","",B18-E18) -> 1093 | G18: MFO Lot 301109 (LOT00301109), April 2026 | H18: 0.96110149 | I18: =H18*D18 -> 1061.4405 | J18: =2.5*$L$4 -> 1.13398
A19: 301113 | B19: 1196 | C19: 57.6 | D19: =B19-C19 -> 1138.4 | E19: 62.5 | F19: =IF(E19="","",B19-E19) -> 1133.5 | G19: MFO Lot 301113 (LOT00301113), April 2026 | H19: 0.96110149 | I19: =H19*D19 -> 1094.1179 | J19: =2.5*$L$4 -> 1.13398
A20: 301124 | B20: 1180 | C20: 57.6 | D20: =B20-C20 -> 1122.4 | E20: 65.5 | F20: =IF(E20="","",B20-E20) -> 1114.5 | G20: MFO Lot 301124 (LOT00301124), April 2026 | H20: 0.96110149 | I20: =H20*D20 -> 1078.7403 | J20: =2.5*$L$4 -> 1.13398
A21: 301125 | B21: 1183 | C21: 57.6 | D21: =B21-C21 -> 1125.4 | E21: 59.5 | F21: =IF(E21="","",B21-E21) -> 1123.5 | G21: MFO Lot 301125 (LOT00301125), April 2026 | H21: 0.96110149 | I21: =H21*D21 -> 1081.6236 | J21: =2.5*$L$4 -> 1.13398
A22: 301127 | B22: 1138 | C22: 57.6 | D22: =B22-C22 -> 1080.4 | E22: 61.5 | F22: =IF(E22="","",B22-E22) -> 1076.5 | G22: MFO Lot 301127 (LOT00301127), April 2026 | H22: 0.96110149 | I22: =H22*D22 -> 1038.3741 | J22: =2.5*$L$4 -> 1.13398
... A24: 301183 | B24: 1105 | C24: 57.6 | D24: =B24-C24 -> 1047.4 | E24: 62 | F24: =IF(E24="","",B24-E24) -> 1043 | G24: MFO Lot 301183 (LOT00301183), April 2026 | H24: 0.96110149 | I24: =H24*D24 -> 1006.6577 | J24: =2.5*$L$4 -> 1.13398
B26: =SUM(B11:B24) -> 16287 | D26: =SUM(D9:D24) -> 15480.6 | E26: =SUM(E9:E24) -> 883 | F26: =SUM(F9:F24) -> 15404 | H26: =I26/D26 -> 0.93644352 | I26: =SUM(I9:I24) -> 14496.708 | J26: =SUM(J9:J24) -> 15.87572
A31: SECTION 2 - ROLLUP
A32: Σ Net Oil Produced (kg) | B32: Loss (kg) | C32: MOBI — Σ Net Oil Injected (kg) | D32: Σ Production Emissions (kg)
A33: =SUM(D11:D24) -> 15480.6 | B33: =A33-C33 -> 76.6 | C33: =SUM(F11:F24) -> 15404 | D33: =SUM(I11:I24) -> 14496.708

Sheet AECN Truck
A1: BATCH HEADER — AECN Truck (Direct from Fort Lupton)
A2: Batch ID (INJ-YYYY-WXX) | B2: INJ-06-2026-W2 | K2: Constants
A3: Week Start (Sat) | B3: 46179 | K3: Lbs/Kg | L3: 2.20462
A4: Week End (Sat) | B4: 46186 | K4: Kg/Lbs | L4: 0.453592
K5: Sparging Mass Loss | L5: 0.0129
K6: pH range (target) | L6: 2.0 - 4.0
K7: Filtration Solids Content | L7: =HYPERLINK("https://docs.google.com/spreadsheets/d/16shKoa1KP34kQJyQvzclBejW9L5-ubNSqPsMOVB7zDY/edit?usp=sharing", 0.00195) -> 0.00195
A8: SECTION 1 - DELIVERIES LEDGER (one row per direct truck; BOL & scale ticket on same row)
A9: Date | B9: BOL # / SO # | C9: BOL Mass (MT) | D9: BOL Mass (kg) | E9: Scale Full (lb) | F9: Scale Empty (lb) | G9: Cargo (kg) | H9: pH | I9: Notes | J9: Sparging Loss (kg) | K9: Filtration Loss (kg) | L9: MOBI (kg) | M9: C Content
J10: =IF(D10="","",D10*$L$5) | K10: =IF(D10="","",(D10-J10)*$L$7) | L10: =IF(D10="","",D10-J10-K10)
J11: =IF(D11="","",D11*$L$5) | K11: =IF(D11="","",(D11-J11)*$L$7) | L11: =IF(D11="","",D11-J11-K11)
J12: =IF(D12="","",D12*$L$5) | K12: =IF(D12="","",(D12-J12)*$L$7) | L12: =IF(D12="","",D12-J12-K12)
J13: =IF(D13="","",D13*$L$5) | K13: =IF(D13="","",(D13-J13)*$L$7) | L13: =IF(D13="","",D13-J13-K13)
J14: =IF(D14="","",D14*$L$5) | K14: =IF(D14="","",(D14-J14)*$L$7) | L14: =IF(D14="","",D14-J14-K14)
J15: =IF(D15="","",D15*$L$5) | K15: =IF(D15="","",(D15-J15)*$L$7) | L15: =IF(D15="","",D15-J15-K15)
J16: =IF(D16="","",D16*$L$5) | K16: =IF(D16="","",(D16-J16)*$L$7) | L16: =IF(D16="","",D16-J16-K16)
J17: =IF(D17="","",D17*$L$5) | K17: =IF(D17="","",(D17-J17)*$L$7) | L17: =IF(D17="","",D17-J17-K17)
J18: =IF(D18="","",D18*$L$5) | K18: =IF(D18="","",(D18-J18)*$L$7) | L18: =IF(D18="","",D18-J18-K18)
J19: =IF(D19="","",D19*$L$5) | K19: =IF(D19="","",(D19-J19)*$L$7) | L19: =IF(D19="","",D19-J19-K19)
J20: =IF(D20="","",D20*$L$5) | K20: =IF(D20="","",(D20-J20)*$L$7) | L20: =IF(D20="","",D20-J20-K20)
J21: =IF(D21="","",D21*$L$5) | K21: =IF(D21="","",(D21-J21)*$L$7) | L21: =IF(D21="","",D21-J21-K21)
... J24: =IF(D24="","",D24*$L$5) | K24: =IF(D24="","",(D24-J24)*$L$7) | L24: =IF(D24="","",D24-J24-K24)
A26: SECTION 2 - ROLLUP (Mass Used = Σ BOL kg; scale tickets no longer required for direct trucks per 2026-05-26)
A27: Σ BOL (kg) | B27: Σ Cargo (kg) | C27: Mass Used (kg) | D27: Sparging Loss (kg) | E27: Filtration Loss (kg) | F27: Uncertainty Adjustment (kg) | G27: MOBI (kg) | H27: pH | I27: C Content (MOBI-wtd) | K27: Origins list (BOLs)
A28: =SUMIFS(D10:D24,B10:B24,"<>") -> 0 | B28: =SUMIFS(G10:G24,B10:B24,"<>") -> 0 | C28: =A28 -> 0 | D28: =C28*$L$5 -> 0 | E28: =(C28-D28)*$L$7 -> 0 | F28: 0 | G28: =C28-D28-E28-F28 -> 0 | H28: =IFERROR(AVERAGE(H10:H24),"") | I28: =IFERROR(SUMPRODUCT(L10:L24,M10:M24)/SUM(L10:L24),"") | K28: =IFERROR(__xludf.DUMMYFUNCTION("TRIM(TEXTJOIN("", "",TRUE,IFERROR(FILTER(B10:B24,B10:B24<>""""),"""")))"),"")

Sheet QOWV
A1: BATCH HEADER — QOWV (Aqueous Bio-Oil, IBC Totes)
A2: Batch ID (INJ-YYYY-WXX) | B2: INJ-06-2026-W2 | K2: Constants
A3: Week Start (Sat) | B3: 46179 | K3: Lbs/Kg | L3: 2.20462
A4: Week End (Sat) | B4: 46186 | K4: Kg/Lbs | L4: 0.453592
K5: Sparging Mass Loss | L5: 0.0129
K6: pH range (target) | L6: 2.0 - 4.0
A8: SECTION 1 - IBC LEDGER (one row per IBC tote; tote tag mass is authoritative)
B9: Transport Emissions | D9: Pyrolysis Emissions Mass | F9: MOBI
A10: Tag | B10: Gross Mass (kg) | C10: Tote Mass (kg) | D10: Net Oil Produced (kg) | E10: Empty Tote Weight (kg) | F10: Net Oil Injected (kg) | G10: Production Period | H10: Carbon Intensity | I10: Production Emissions | J10: Scale Uncertainty
A11: 118850 | B11: 977 | C11: 57.6 | D11: =B11-C11 -> 919.4 | E11: 138 | F11: =IF(E11="","",B11-E11) -> 839 | G11: MFO Lot 2374 (LOT00002374), PP#7 | H11: 0.13736711 | I11: =H11*D11 -> 126.29532 | J11: =2.5*$L$4 -> 1.13398
A12: 118827 | B12: 941 | C12: 57.6 | D12: =B12-C12 -> 883.4 | E12: 137 | F12: =IF(E12="","",B12-E12) -> 804 | G12: MFO Lot 2404 (LOT00002404), PP#7 | H12: 0.13736711 | I12: =H12*D12 -> 121.35011 | J12: =2.5*$L$4 -> 1.13398
A13: 118848 | B13: 1049 | C13: 57.6 | D13: =B13-C13 -> 991.4 | E13: 181.5 | F13: =IF(E13="","",B13-E13) -> 867.5 | G13: MFO Lot 2444 (LOT00002444), PP#7 | H13: 0.13736711 | I13: =H13*D13 -> 136.18576 | J13: =2.5*$L$4 -> 1.13398
A14: 118802 | B14: 1009 | C14: 57.6 | D14: =B14-C14 -> 951.4 | E14: 174 | F14: =IF(E14="","",B14-E14) -> 835 | G14: MFO Lot 2460 (LOT00002460), PP#7 | H14: 0.13736711 | I14: =H14*D14 -> 130.69107 | J14: =2.5*$L$4 -> 1.13398
A15: 118838 | B15: 966 | C15: 57.6 | D15: =B15-C15 -> 908.4 | E15: 173 | F15: =IF(E15="","",B15-E15) -> 793 | G15: MFO Lot 2464 (LOT00002464), PP#7 | H15: 0.13736711 | I15: =H15*D15 -> 124.78429 | J15: =2.5*$L$4 -> 1.13398
A16: 118861 | B16: 1081 | C16: 57.6 | D16: =B16-C16 -> 1023.4 | E16: 161 | F16: =IF(E16="","",B16-E16) -> 920 | G16: MFO Lot 2514 (LOT00002514), PP#7 | H16: 0.13736711 | I16: =H16*D16 -> 140.5815 | J16: =2.5*$L$4 -> 1.13398
A17: 118866 | B17: 994 | C17: 57.6 | D17: =B17-C17 -> 936.4 | E17: 153 | F17: =IF(E17="","",B17-E17) -> 841 | G17: MFO Lot 2534 (LOT00002534), PP#7 | H17: 0.13736711 | I17: =H17*D17 -> 128.63056 | J17: =2.5*$L$4 -> 1.13398
A18: 118882 | B18: 983 | C18: 57.6 | D18: =B18-C18 -> 925.4 | E18: 148 | F18: =IF(E18="","",B18-E18) -> 835 | G18: MFO Lot 2576 (LOT00002576), PP#7 | H18: 0.13736711 | I18: =H18*D18 -> 127.11953 | J18: =2.5*$L$4 -> 1.13398
A19: 118885 | B19: 1124 | C19: 57.6 | D19: =B19-C19 -> 1066.4 | E19: 152 | F19: =IF(E19="","",B19-E19) -> 972 | G19: MFO Lot 2578 (LOT00002578), PP#7 | H19: 0.13736711 | I19: =H19*D19 -> 146.48829 | J19: =2.5*$L$4 -> 1.13398
A20: 118814 | B20: 1161 | C20: 57.6 | D20: =B20-C20 -> 1103.4 | E20: 149 | F20: =IF(E20="","",B20-E20) -> 1012 | G20: MFO Lot 2586 (LOT00002586), PP#7 | H20: 0.13736711 | I20: =H20*D20 -> 151.57087 | J20: =2.5*$L$4 -> 1.13398
A21: 118883 | B21: 1049 | C21: 57.6 | D21: =B21-C21 -> 991.4 | E21: 218 | F21: =IF(E21="","",B21-E21) -> 831 | G21: MFO Lot 2588 (LOT00002588), PP#7 | H21: 0.13736711 | I21: =H21*D21 -> 136.18576 | J21: =2.5*$L$4 -> 1.13398
A22: 118881 | B22: 1074 | C22: 57.6 | D22: =B22-C22 -> 1016.4 | E22: 181 | F22: =IF(E22="","",B22-E22) -> 893 | G22: MFO Lot 2638 (LOT00002638), PP#7 | H22: 0.13736711 | I22: =H22*D22 -> 139.61993 | J22: =2.5*$L$4 -> 1.13398
... A46: 228402 | B46: 969 | C46: 57.6 | D46: =B46-C46 -> 911.4 | E46: 218 | F46: =IF(E46="","",B46-E46) -> 751 | G46: MFO Lot 4196 (LOT00004196), October 2025 | H46: 0.11101762 | I46: =H46*D46 -> 101.18146 | J46: =2.5*$L$4 -> 1.13398
A53: TOTAL | B53: =SUM(B11:B46) -> 37833 | C53: =SUM(C11:C46) -> 2073.6 | D53: =SUM(D11:D46) -> 35759.4 | E53: =SUM(E11:E46) -> 6396 | F53: =SUM(F11:F46) -> 31437 | H53: =IFERROR(SUMPRODUCT(D11:D46,H11:H46)/SUM(D11:D46),"") -> 0.12473991 | I53: =SUM(I11:I46) -> 4460.6245 | J53: =SUM(J11:J46) -> 40.82328
G56: =IF(AND(D56<>"",F56<>""),(D56-F56)*$L$4,"") | H56: =IF(G56="","",G56*(1-$L$5))
G57: =IF(AND(D57<>"",F57<>""),(D57-F57)*$L$4,"") | H57: =IF(G57="","",G57*(1-$L$5))
G58: =IF(AND(D58<>"",F58<>""),(D58-F58)*$L$4,"") | H58: =IF(G58="","",G58*(1-$L$5))
G59: =IF(AND(D59<>"",F59<>""),(D59-F59)*$L$4,"") | H59: =IF(G59="","",G59*(1-$L$5))
G60: =IF(AND(D60<>"",F60<>""),(D60-F60)*$L$4,"") | H60: =IF(G60="","",G60*(1-$L$5))
G61: =IF(AND(D61<>"",F61<>""),(D61-F61)*$L$4,"") | H61: =IF(G61="","",G61*(1-$L$5))
G62: =IF(AND(D62<>"",F62<>""),(D62-F62)*$L$4,"") | H62: =IF(G62="","",G62*(1-$L$5))
G63: =IF(AND(D63<>"",F63<>""),(D63-F63)*$L$4,"") | H63: =IF(G63="","",G63*(1-$L$5))
G64: =IF(AND(D64<>"",F64<>""),(D64-F64)*$L$4,"") | H64: =IF(G64="","",G64*(1-$L$5))
G65: =IF(AND(D65<>"",F65<>""),(D65-F65)*$L$4,"") | H65: =IF(G65="","",G65*(1-$L$5))
G66: =IF(AND(D66<>"",F66<>""),(D66-F66)*$L$4,"") | H66: =IF(G66="","",G66*(1-$L$5))
G67: =IF(AND(D67<>"",F67<>""),(D67-F67)*$L$4,"") | H67: =IF(G67="","",G67*(1-$L$5))
... G73: =IF(AND(D73<>"",F73<>""),(D73-F73)*$L$4,"") | H73: =IF(G73="","",G73*(1-$L$5))

Sheet Kerry
A1: BATCH HEADER — Kerry (Calciner Waste Oil, IBC Totes)
A2: Batch ID (INJ-YYYY-WXX) | B2: INJ-06-2026-W2 | L2: Constants
A3: Week Start (Sat) | B3: 46179 | L3: Lbs/Kg | M3: 2.20462
A4: Week End (Sat) | B4: 46186 | L4: Kg/Lbs | M4: 0.453592
L5: Sparging Mass Loss | M5: 0.0129
L6: pH range (target) | M6: 2.0 - 4.0
L7: Testing Uncertainty | M7: 0.004
A8: SECTION 1 - IBC LEDGER (one row per Kerry tote; tote tag mass is authoritative)
A9: Date | B9: Tote Tag # | C9: Gross Mass (kg) — transport | D9: Tote Empty (kg) | E9: Net Oil (kg) — production | F9: Net Injected (kg) — MOBI | G9: pH | H9: Notes | I9: C Content | J9: C Content Uncertainty | K9: Mass Uncertainty (Scaling)
A31: SECTION 2 - ROLLUP
A32: Σ Net Injected (kg) | B32: Sparging Loss (kg) | C32: MOBI (kg) | D32: pH | E32: C Content (MOBI-wtd) | G32: Origins list (Tote tags)
A33: =SUMIFS(F10:F29,B10:B29,"<>") -> 0 | B33: =A33*$M$5 -> 0 | C33: =A33-B33 -> 0 | D33: =IFERROR(AVERAGE(G10:G29),"") | E33: =IFERROR(__xludf.DUMMYFUNCTION("IFERROR(AVERAGE.WEIGHTED(I10:I29,F10:F29),"""")"),"") | G33: =IFERROR(__xludf.DUMMYFUNCTION("TRIM(TEXTJOIN("", "",TRUE,IFERROR(FILTER(B10:B29,B10:B29<>""""),"""")))"),"")

Sheet QOWV Shipments & EE Allocation
A1: INJ-06-2026-W2 — QOWV Shipments & EE Mileage Allocation
A4: BATCH SUMMARY
A5: Batch | B5: Fraction | C5: Inj. Week | D5: # Totes | E5: Ship Date(s)
A6: INJ-06-2026-W2 | B6: QOWV | C6: 2026-06-06 to 2026-06-13 | D6: 36 | E6: 2025-12-09 (18), 2025-12-10 (18)
A8: Charm CO -> Basco LA distance (one-way miles): | B8: 1201
A10: EE ALLOCATION TABLE
A11: Truck (shipment) | B11: Ship Date | C11: Total Totes on Truck | D11: Batch-Relevant Totes | E11: Batch Share of Truck | F11: Mileage (one-way) | G11: Allocated Miles
A12: Shipment 12-09 | B12: 46000 | C12: 36 | D12: 18 | E12: =D12/C12 -> 0.5 | F12: =$B$8 -> 1201 | G12: =E12*F12 -> 600.5
A13: Shipment 12-10 | B13: 46001 | C13: 35 | D13: 18 | E13: =D13/C13 -> 0.51428571 | F13: =$B$8 -> 1201 | G13: =E13*F13 -> 617.65714
A14: TOTAL | C14: =SUM(C12:C13) -> 71 | D14: =SUM(D12:D13) -> 36 | G14: =SUM(G12:G13) -> 1218.1571
A16: BATCH MILEAGE ALLOCATION
A17: Batch | B17: Per-Truck Allocation (relevant/total) | C17: Allocated Miles | D17: # Totes
A18: INJ-06-2026-W2 | B18: 12-09 (18/36), 12-10 (18/35) | C18: =G14 -> 1218.1571 | D18: =D14 -> 36
A20: --- Shipment 2025-12-09 --- (18 of 36 totes on this truck are W2-relevant)
A21: Metal Tag | B21: Fraction | C21: Production Period | D21: Date Loaded | E21: Batch
A22: 118814 | B22: QOWV | C22: PP#7 | D22: 46000 | E22: INJ-06-2026-W2
A23: 120524 | B23: QOWV | C23: PP#8 | D23: 46000 | E23: INJ-06-2026-W2
A24: 120505 | B24: QOWV | C24: PP#8 | D24: 46000 | E24: INJ-06-2026-W2
A25: 120516 | B25: QOWV | C25: PP#8 | D25: 46000 | E25: INJ-06-2026-W2
A26: 228437 | B26: QOWV | C26: 45931 | D26: 46000 | E26: INJ-06-2026-W2
A27: 228426 | B27: QOWV | C27: 45931 | D27: 46000 | E27: INJ-06-2026-W2
A28: 228471 | B28: QOWV | C28: 45931 | D28: 46000 | E28: INJ-06-2026-W2
A29: 228449 | B29: QOWV | C29: 45931 | D29: 46000 | E29: INJ-06-2026-W2
A30: 228472 | B30: QOWV | C30: 45931 | D30: 46000 | E30: INJ-06-2026-W2
A31: 228463 | B31: QOWV | C31: 45931 | D31: 46000 | E31: INJ-06-2026-W2
A32: 228454 | B32: QOWV | C32: 45931 | D32: 46000 | E32: INJ-06-2026-W2
A33: 228492 | B33: QOWV | C33: 45931 | D33: 46000 | E33: INJ-06-2026-W2
A34: 228491 | B34: QOWV | C34: 45931 | D34: 46000 | E34: INJ-06-2026-W2
A35: 228420 | B35: QOWV | C35: 45931 | D35: 46000 | E35: INJ-06-2026-W2
A36: 228434 | B36: QOWV | C36: 45931 | D36: 46000 | E36: INJ-06-2026-W2
A37: 228448 | B37: QOWV | C37: 45931 | D37: 46000 | E37: INJ-06-2026-W2
... A39: 228402 | B39: QOWV | C39: 45931 | D39: 46000 | E39: INJ-06-2026-W2
A41: --- Shipment 2025-12-10 --- (18 of 35 totes on this truck are W2-relevant)
A42: Metal Tag | B42: Fraction | C42: Production Period | D42: Date Loaded | E42: Batch
A43: 118850 | B43: QOWV | C43: PP#7 | D43: 46001 | E43: INJ-06-2026-W2
A44: 118827 | B44: QOWV | C44: PP#7 | D44: 46001 | E44: INJ-06-2026-W2
A45: 118848 | B45: QOWV | C45: PP#7 | D45: 46001 | E45: INJ-06-2026-W2
A46: 118802 | B46: QOWV | C46: PP#7 | D46: 46001 | E46: INJ-06-2026-W2
A47: 118838 | B47: QOWV | C47: PP#7 | D47: 46001 | E47: INJ-06-2026-W2
A48: 118861 | B48: QOWV | C48: PP#7 | D48: 46001 | E48: INJ-06-2026-W2
...

Sheet WODO Shipments & EE Allocation
A1: INJ-06-2026-W2 — WODO Shipments & EE Mileage Allocation
A4: BATCH SUMMARY
A5: Batch | B5: Fraction | C5: Inj. Week | D5: # Totes | E5: Ship Date(s)
A6: INJ-06-2026-W2 | B6: WODO | C6: 2026-06-06 to 2026-06-13 | D6: 14 | E6: 2026-05-12 (14 of 17 on truck)
A8: Charm CO -> Basco LA distance (one-way miles): | B8: 1201
A10: EE ALLOCATION TABLE
A11: Truck (shipment) | B11: Ship Date | C11: Total Totes on Truck | D11: Batch-Relevant Totes | E11: Batch Share of Truck | F11: Mileage (one-way) | G11: Allocated Miles
A12: Shipment 05-12 | B12: 46154 | C12: 17 | D12: 14 | E12: =D12/C12 -> 0.82352941 | F12: =$B$8 -> 1201 | G12: =E12*F12 -> 989.05882
A13: TOTAL | C13: =SUM(C12) -> 17 | D13: =SUM(D12) -> 14 | G13: =SUM(G12) -> 989.05882
A15: BATCH MILEAGE ALLOCATION
A16: Batch | B16: Per-Truck Allocation (relevant/total) | C16: Allocated Miles | D16: # Totes
A17: INJ-06-2026-W2 | B17: 05-12 (14/17) | C17: =G13 -> 989.05882 | D17: =D13 -> 14
A19: --- Shipment 2026-05-12 --- (14 of 17 totes on this truck are W2-relevant; 16 WODO + 1 QOWV)
A20: Metal Tag | B20: Fraction | C20: Production Period | D20: Date Loaded | E20: Batch
A21: 301007 | B21: WODO | C21: 46113 | D21: 46154 | E21: INJ-06-2026-W2
A22: 301023 | B22: WODO | C22: 46113 | D22: 46154 | E22: INJ-06-2026-W2
A23: 301033 | B23: WODO | C23: 46113 | D23: 46154 | E23: INJ-06-2026-W2
A24: 301058 | B24: WODO | C24: 46113 | D24: 46154 | E24: INJ-06-2026-W2
A25: 301066 | B25: WODO | C25: 46113 | D25: 46154 | E25: INJ-06-2026-W2
A26: 301090 | B26: WODO | C26: 46113 | D26: 46154 | E26: INJ-06-2026-W2
A27: 301098 | B27: WODO | C27: 46113 | D27: 46154 | E27: INJ-06-2026-W2
A28: 301109 | B28: WODO | C28: 46113 | D28: 46154 | E28: INJ-06-2026-W2
A29: 301113 | B29: WODO | C29: 46113 | D29: 46154 | E29: INJ-06-2026-W2
A30: 301124 | B30: WODO | C30: 46113 | D30: 46154 | E30: INJ-06-2026-W2
A31: 301125 | B31: WODO | C31: 46113 | D31: 46154 | E31: INJ-06-2026-W2
A32: 301127 | B32: WODO | C32: 46113 | D32: 46154 | E32: INJ-06-2026-W2
... A34: 301183 | B34: WODO | C34: 46113 | D34: 46154 | E34: INJ-06-2026-W2
