Workbook

Sheet Summary
A1: BATCH SUMMARY
A2: Batch ID | B2: INJ-07-2026-W1
A3: Week Start (Sat) | B3: 46200
A4: Week End (Sat) | B4: 46207
A6: SECTION 1 - PER-TAB SUMMARY (each row pulls from its mode tab)
A7: Source Tab | B7: Σ Deliveries / Cargo (kg) | C7: Σ Uncertainty Adj (kg) | D7: Mass Used (kg) | E7: Sparging Loss (kg) | F7: Filtration Loss (kg) | G7: MOBI (kg) | H7: AECN→SOPOR EE (mi) | I7: Rail EE (mi) | J7: Opel→Basco EE (mi)
A8: AECN Rail | B8: ='AECN Rail'!B52 -> 313028.38 | C8: ='AECN Rail'!C52 -> 103.48208 | D8: ='AECN Rail'!D52 -> 312924.89 | E8: ='AECN Rail'!E52 -> 4036.7311 | F8: ='AECN Rail'!F52 -> 602.33192 | G8: ='AECN Rail'!G52 -> 308285.83 | H8: =SUM('AECN Rail'!L32:L47) -> 1287.5147 | I8: =SUM('AECN Rail'!M32:M47) -> 8779.0539 | J8: =SUM('AECN Rail'!N32:N47) -> 1372.8
A9: AECN Truck | B9: ='AECN Truck'!B28 | C9: ='AECN Truck'!F28 | D9: ='AECN Truck'!C28 | E9: ='AECN Truck'!D28 | F9: ='AECN Truck'!E28 | G9: ='AECN Truck'!G28
A10: Charm WODO | B10: =WODO!A33 -> 18926 | C10: 0 | D10: =WODO!B33 -> 17946.8 | E10: =WODO!C33 -> 979.2 | F10: 0 | G10: =WODO!D33 -> 17885
A11: Kerry | B11: =Kerry!A33 -> 0 | C11: 0 | D11: =Kerry!A33 -> 0 | E11: =Kerry!B33 -> 0 | F11: 0 | G11: =Kerry!C33 -> 0
A12: QOWV | B12: =QOWV!B53 -> 37833 | C12: 0 | D12: =QOWV!D53 -> 35759.4 | E12: 0 | F12: 0 | G12: =QOWV!F53 -> 31437
A13: TOTAL | B13: =SUM(B8:B12) -> 369787.38 | C13: =SUM(C8:C12) -> 103.48208 | D13: =SUM(D8:D12) -> 366631.09 | E13: =SUM(E8:E12) -> 5015.9311 | F13: =SUM(F8:F12) -> 602.33192 | G13: =SUM(G8:G12) -> 357607.83
A15: SECTION 2 - PER-OIL-TYPE ROLLUP (composite C% per oil type per week)
A16: Oil Type | B16: MOBI (kg) | C16: Composite Sample ID | D16: C % | E16: Lab COA Link | F16: C Content Uncertainty | G16: Testing Uncertainty
A17: AECN | B17: =G8+G9 -> 308285.83 | C17: 7-2026-W1 AECN | D17: 0.405 | E17: =HYPERLINK("https://drive.google.com/file/d/1viuXyvEjs-qR0fJHdIA1U4Gvrz7btAcb/view","COA SR26-04220.001") -> COA SR26-04220.001 | F17: =D17*G17 -> 0.00162 | G17: 0.004
A18: WODO | B18: =G10 -> 17885 | C18: 7-2026-W1 WODO | D18: 0.516 | E18: =HYPERLINK("https://drive.google.com/file/d/1TQ634HZcwFBWundVrdjV281Mr0wOPIyc/view","COA SR26-04242.001") -> COA SR26-04242.001 | F18: =D18*G18 -> 0.002064 | G18: 0.004
A19: Kerry | B19: =G11 -> 0
A20: QOWV | B20: =G12 -> 31437 | C20: 07/26/W1-QOWV | D20: 0.092 | E20: 07-26-W1-QOWV.pdf | F20: =D20*G20 -> 0.000368 | G20: 0.004
A21: TOTAL | B21: =SUM(B17:B20) -> 357607.83

Sheet AECN Rail
A1: BATCH HEADER — AECN Rail
B2: INJ-07-2026-W1 | N2: Constants
B3: 46200 | N3: Lbs/Kg | O3: 2.20462
B4: 46207 | N4: Kg/Lbs | O4: 0.453592
N5: Sparging Mass Loss | O5: 0.0129
N6: pH range (target) | O6: 2.0 - 4.0
N7: Filtration Solids Content | O7: =HYPERLINK("https://docs.google.com/spreadsheets/d/16shKoa1KP34kQJyQvzclBejW9L5-ubNSqPsMOVB7zDY/edit?usp=sharing", 0.00195) -> 0.00195
A8: SECTION 1 - RAILCARS RECEIVED THIS WEEK (entity-level) | N8: BOL Trips (AECN→SOPOR) | O8: 3
A9: Railcar # | B9: Arrival Date at Opelousas | C9: Loading BOLs (comma-sep) | D9: Total Loaded (MT) | E9: Total Loaded (kg) | F9: Total Offloaded (kg, auto) | G9: Loss (kg) | H9: Previously Claimed (kg) | I9: Claimed This Week (kg) | J9: AECN→SOPOR (mi) | K9: Rail (mi) | L9: Opel→Basco (mi) | N9: Round Trip (Opel→Basco) | O9: 2
A10: GRPX5188 | B10: 46188 | C10: 2386-R, 2387-R, 2388-R | D10: =SUMIF($C$17:$C$28,$A10,$D$17:$D$28) -> 78.03 | E10: =SUMIF($C$17:$C$28,$A10,$E$17:$E$28) -> 78030 | F10: =SUMIF($C$32:$C$47,A10,$F$32:$F$47)+H10 -> 77981.537 | G10: =IF(AND(E10<>"",F10<>"",F10>=0.95*E10),E10-F10,"") -> 48.46336 | H10: 0 | I10: =E10-H10 -> 78030 | J10: 107.5 | K10: 2199 | L10: 42.9
A11: GPRX5098 | B11: 46182 | C11: 2380-R, 2381-R, 2382-R | D11: =SUMIF($C$17:$C$28,$A11,$D$17:$D$28) -> 78.25 | E11: =SUMIF($C$17:$C$28,$A11,$E$17:$E$28) -> 78250 | F11: =SUMIF($C$32:$C$47,A11,$F$32:$F$47)+H11 -> 78353.482 | G11: =IF(AND(E11<>"",F11<>"",F11>=0.95*E11),E11-F11,"") -> -103.48208 | H11: 0 | I11: =E11-H11 -> 78250 | J11: 107.5 | K11: 2199 | L11: 42.9
A12: GPRX5236 | B12: 46155 | C12: 2377-R, 2378-R, 2379-R | D12: =SUMIF($C$17:$C$28,$A12,$D$17:$D$28) -> 78.54 | E12: =SUMIF($C$17:$C$28,$A12,$E$17:$E$28) -> 78540 | F12: =SUMIF($C$32:$C$47,A12,$F$32:$F$47)+H12 -> 78063.183 | G12: =IF(AND(E12<>"",F12<>"",F12>=0.95*E12),E12-F12,"") -> 476.8168 | H12: 0 | I12: =E12-H12 -> 78540 | J12: 107.5 | K12: 2199 | L12: 42.9
A13: GPRX5107 | B13: 46184 | C13: 2383-R, 2384-R, 2385-R | D13: =SUMIF($C$17:$C$28,$A13,$D$17:$D$28) -> 78.71 | E13: =SUMIF($C$17:$C$28,$A13,$E$17:$E$28) -> 78710 | F13: =SUMIF($C$32:$C$47,A13,$F$32:$F$47)+H13 -> 78630.173 | G13: =IF(AND(E13<>"",F13<>"",F13>=0.95*E13),E13-F13,"") -> 79.8268 | H13: 0 | I13: =E13-H13 -> 78710 | J13: 107.5 | K13: 2199 | L13: 42.9
A15: SECTION 2 - ORIGINS LEDGER (loading BOLs at SOPOR)
A16: Date | B16: BOL # | C16: Railcar # | D16: BOL Mass (MT) | E16: BOL Mass (kg)
A17: 46188 | B17: =HYPERLINK("https://drive.google.com/file/d/1_iu32iFx1mMculBhUZ4MH7mPB_VRnLeR/view","2386-R") -> 2386-R | C17: GRPX5188 | D17: 25.9 | E17: 25900
A18: 46188 | B18: =HYPERLINK("https://drive.google.com/file/d/1q1iuhYR1YckLXroWLvnY-J7SLQdbHDhk/view","2387-R") -> 2387-R | C18: GRPX5188 | D18: 25.95 | E18: 25950
A19: 46188 | B19: =HYPERLINK("https://drive.google.com/file/d/1oHjjumPOHGtrVe1TXFmSQZqZrzL9yVsj/view","2388-R") -> 2388-R | C19: GRPX5188 | D19: 26.18 | E19: 26180
A20: 46182 | B20: =HYPERLINK("https://drive.google.com/file/d/1TAT7U9cwWtYriZn__bmfO14fICjo4gO1/view","2380-R") -> 2380-R | C20: GPRX5098 | D20: 26.16 | E20: 26160
A21: 46182 | B21: =HYPERLINK("https://drive.google.com/file/d/1kfD85BpfUOSeU1mtGDNSGGhVaCVTLrrO/view","2381-R") -> 2381-R | C21: GPRX5098 | D21: 25.91 | E21: 25910
A22: 46182 | B22: =HYPERLINK("https://drive.google.com/file/d/1nOvwWLLJ6Gm-ydUxHG0KOEoxN9EG42XK/view","2382-R") -> 2382-R | C22: GPRX5098 | D22: 26.18 | E22: 26180
A23: 46155 | B23: =HYPERLINK("https://drive.google.com/file/d/1e8SlHlb2Fjv2N-xB0KxmazlX3dT84prX/view","2377-R") -> 2377-R | C23: GPRX5236 | D23: 26.19 | E23: 26190
A24: 46155 | B24: =HYPERLINK("https://drive.google.com/file/d/1KoSJIptvcvTmLIeSkSgowmldz7HV0h3y/view","2378-R") -> 2378-R | C24: GPRX5236 | D24: 26.08 | E24: 26080
A25: 46155 | B25: =HYPERLINK("https://drive.google.com/file/d/1qSSMLaWo26SsLfvzVNtH-qJLH5l9Xk9V/view","2379-R") -> 2379-R | C25: GPRX5236 | D25: 26.27 | E25: 26270
A26: 46184 | B26: =HYPERLINK("https://drive.google.com/file/d/1uJfwAnsO1a3niJ7iYfC7bIJylwE8j_7O/view","2383-R") -> 2383-R | C26: GPRX5107 | D26: 26.52 | E26: 26520
A27: 46184 | B27: =HYPERLINK("https://drive.google.com/file/d/1NvpkFmdMrx7bm-DrF0U2M0l_MDUTn66Z/view","2384-R") -> 2384-R | C27: GPRX5107 | D27: 25.97 | E27: 25970 | N27: Opel→Basco (mi, full ×2)
A28: 46184 | B28: =HYPERLINK("https://drive.google.com/file/d/1XaENmZK39RONif-XdGXYD9Kx5qeN4p1J/view","2385-R") -> 2385-R | C28: GPRX5107 | D28: 26.22 | E28: 26220 | N28: =IF(F28="","",IFERROR(VLOOKUP(C28,$A$10:$L$14,12,FALSE),0)*$O$9)
N29: =IF(F29="","",IFERROR(VLOOKUP(C29,$A$10:$L$14,12,FALSE),0)*$O$9)
A30: SECTION 3 - SCALE TICKETS + OFFLOAD WEIGHTS | N30: =IF(F30="","",IFERROR(VLOOKUP(C30,$A$10:$L$14,12,FALSE),0)*$O$9)
D31: Full Scale Ticket (lb) | E31: Empty Scale Ticket (lb) | F31: Net Scaled Mass (kg) | G31: pH | H31: Sparging Loss (kg) | I31: Filtration Loss (kg) | J31: Uncertainty Adjustment (kg) | K31: MOBI (kg) | L31: AECN→SOPOR (mi, x3 - full BOL) | M31: Rail (mi - full BOL) | N31: Opel→Basco (mi, x2 - downstream, per offload)
A32: 46207 | B32: Rail_GRPX5188_6.15.2026_offload_1 | C32: GRPX5188 | D32: =HYPERLINK("https://drive.google.com/file/d/1-HW52IxnT_xZxWOtorW32Tm6UbiDCGn2/view", 76560) -> 76560 | E32: 29510 | F32: =IF(D32="","",(D32-E32)*$O$4) -> 21341.504 | G32: 3.7 | H32: =IF(F32="","",(F32-J32)*$O$5) -> 275.3054 | I32: =IF(F32="","",(F32-J32)*(1-$O$5)*$O$7) -> 41.079087 | J32: {=IF(F32="","",IF(ROW()=MAX(IF($C$32:$C$47=C32,ROW($C$32:$C$47),0)),MAX(0,IFERROR(VLOOKUP(C32,$A$10:$L$13,6,FALSE)-VLOOKUP(C32,$A$10:$L$13,5,FALSE),0)),0))} -> 0 | K32: =IF(F32="","",F32-H32-I32-J32) -> 21025.119 | L32: =IF(F32="","",(F32-J32)/VLOOKUP(C32,$A$10:$L$13,5,FALSE)*VLOOKUP(C32,$A$10:$L$13,10,FALSE)*$O$8) -> 88.204984 | M32: =IF(F32="","",(F32-J32)/VLOOKUP(C32,$A$10:$L$13,5,FALSE)*VLOOKUP(C32,$A$10:$L$13,11,FALSE)) -> 601.43492 | N32: =IF(F32="","",IFERROR(VLOOKUP(C32,$A$10:$L$13,12,FALSE),0)*$O$9) -> 85.8
A33: 46207 | B33: Rail_GRPX5188_6.15.2026_offload_2 | C33: GRPX5188 | D33: =HYPERLINK("https://drive.google.com/file/d/1BrM9PKOPco-VQGXwOLCIstKcIQkAHGoO/view", 75160) -> 75160 | E33: =HYPERLINK("https://drive.google.com/file/d/1tqYLBsR0COmeIePMQ8rHud4eWFDdetOc/view", 28540) -> 28540 | F33: =IF(D33="","",(D33-E33)*$O$4) -> 21146.459 | G33: 3.7 | H33: =IF(F33="","",(F33-J33)*$O$5) -> 272.78932 | I33: =IF(F33="","",(F33-J33)*(1-$O$5)*$O$7) -> 40.703656 | J33: {=IF(F33="","",IF(ROW()=MAX(IF($C$32:$C$47=C33,ROW($C$32:$C$47),0)),MAX(0,IFERROR(VLOOKUP(C33,$A$10:$L$13,6,FALSE)-VLOOKUP(C33,$A$10:$L$13,5,FALSE),0)),0))} -> 0 | K33: =IF(F33="","",F33-H33-I33-J33) -> 20832.966 | L33: =IF(F33="","",(F33-J33)/VLOOKUP(C33,$A$10:$L$13,5,FALSE)*VLOOKUP(C33,$A$10:$L$13,10,FALSE)*$O$8) -> 87.39886 | M33: =IF(F33="","",(F33-J33)/VLOOKUP(C33,$A$10:$L$13,5,FALSE)*VLOOKUP(C33,$A$10:$L$13,11,FALSE)) -> 595.93827 | N33: =IF(F33="","",IFERROR(VLOOKUP(C33,$A$10:$L$13,12,FALSE),0)*$O$9) -> 85.8
A34: 46207 | B34: Rail_GRPX5188_6.15.2026_offload_3 | C34: GRPX5188 | D34: =HYPERLINK("https://drive.google.com/file/d/1a3Iym4IgeMqUypjWigs0QPGOkBgEA1-q/view", 70460) -> 70460 | E34: 29510 | F34: =IF(D34="","",(D34-E34)*$O$4) -> 18574.592 | G34: 3.7 | H34: =IF(F34="","",(F34-J34)*$O$5) -> 239.61224 | I34: =IF(F34="","",(F34-J34)*(1-$O$5)*$O$7) -> 35.753211 | J34: {=IF(F34="","",IF(ROW()=MAX(IF($C$32:$C$47=C34,ROW($C$32:$C$47),0)),MAX(0,IFERROR(VLOOKUP(C34,$A$10:$L$13,6,FALSE)-VLOOKUP(C34,$A$10:$L$13,5,FALSE),0)),0))} -> 0 | K34: =IF(F34="","",F34-H34-I34-J34) -> 18299.227 | L34: =IF(F34="","",(F34-J34)/VLOOKUP(C34,$A$10:$L$13,5,FALSE)*VLOOKUP(C34,$A$10:$L$13,10,FALSE)*$O$8) -> 76.769269 | M34: =IF(F34="","",(F34-J34)/VLOOKUP(C34,$A$10:$L$13,5,FALSE)*VLOOKUP(C34,$A$10:$L$13,11,FALSE)) -> 523.45929 | N34: =IF(F34="","",IFERROR(VLOOKUP(C34,$A$10:$L$13,12,FALSE),0)*$O$9) -> 85.8
A35: 46207 | B35: Rail_GRPX5188_6.15.2026_offload_4 | C35: GRPX5188 | D35: =HYPERLINK("https://drive.google.com/file/d/1vhqYpsp01i2fnxhktEzlXqKrg1VmmBkF/view", 66500) -> 66500 | E35: =HYPERLINK("https://drive.google.com/file/d/1NhLzg-rkPfql6fu2J02ZgA_u6SG-dlcm/view", 29200) -> 29200 | F35: =IF(D35="","",(D35-E35)*$O$4) -> 16918.982 | G35: 3.7 | H35: =IF(F35="","",(F35-J35)*$O$5) -> 218.25486 | I35: =IF(F35="","",(F35-J35)*(1-$O$5)*$O$7) -> 32.566417 | J35: {=IF(F35="","",IF(ROW()=MAX(IF($C$32:$C$47=C35,ROW($C$32:$C$47),0)),MAX(0,IFERROR(VLOOKUP(C35,$A$10:$L$13,6,FALSE)-VLOOKUP(C35,$A$10:$L$13,5,FALSE),0)),0))} -> 0 | K35: =IF(F35="","",F35-H35-I35-J35) -> 16668.16 | L35: =IF(F35="","",(F35-J35)/VLOOKUP(C35,$A$10:$L$13,5,FALSE)*VLOOKUP(C35,$A$10:$L$13,10,FALSE)*$O$8) -> 69.926587 | M35: =IF(F35="","",(F35-J35)/VLOOKUP(C35,$A$10:$L$13,5,FALSE)*VLOOKUP(C35,$A$10:$L$13,11,FALSE)) -> 476.80175 | N35: =IF(F35="","",IFERROR(VLOOKUP(C35,$A$10:$L$13,12,FALSE),0)*$O$9) -> 85.8
A36: 46207 | B36: Rail_GPRX5098_6.10.2026_offload_1 | C36: GPRX5098 | D36: =HYPERLINK("https://drive.google.com/file/d/1_ANYuo0ysZcM1qlb4NR5HzLBrf2wRVZc/view", 79840) -> 79840 | E36: =HYPERLINK("https://drive.google.com/file/d/1uCnran7RmhPUTPd-VZx-Rm777zRnxLt_/view", 29280) -> 29280 | F36: =IF(D36="","",(D36-E36)*$O$4) -> 22933.612 | G36: 3.7 | H36: =IF(F36="","",(F36-J36)*$O$5) -> 295.84359 | I36: =IF(F36="","",(F36-J36)*(1-$O$5)*$O$7) -> 44.143647 | J36: {=IF(F36="","",IF(ROW()=MAX(IF($C$32:$C$47=C36,ROW($C$32:$C$47),0)),MAX(0,IFERROR(VLOOKUP(C36,$A$10:$L$13,6,FALSE)-VLOOKUP(C36,$A$10:$L$13,5,FALSE),0)),0))} -> 0 | K36: =IF(F36="","",F36-H36-I36-J36) -> 22593.624 | L36: =IF(F36="","",(F36-J36)/VLOOKUP(C36,$A$10:$L$13,5,FALSE)*VLOOKUP(C36,$A$10:$L$13,10,FALSE)*$O$8) -> 94.518718 | M36: =IF(F36="","",(F36-J36)/VLOOKUP(C36,$A$10:$L$13,5,FALSE)*VLOOKUP(C36,$A$10:$L$13,11,FALSE)) -> 644.48577 | N36: =IF(F36="","",IFERROR(VLOOKUP(C36,$A$10:$L$13,12,FALSE),0)*$O$9) -> 85.8
A37: 46207 | B37: Rail_GPRX5098_6.10.2026_offload_2 | C37: GPRX5098 | D37: =HYPERLINK("https://drive.google.com/file/d/1YDpVKxFd3RQnWaRY40JR3U3j6u4Ji0xB/view", 78640) -> 78640 | E37: =HYPERLINK("https://drive.google.com/file/d/15BxkKsmRzXNfQN6g631VQYX_HF0XTnpL/view", 28920) -> 28920 | F37: =IF(D37="","",(D37-E37)*$O$4) -> 22552.594 | G37: 3.7 | H37: =IF(F37="","",(F37-J37)*$O$5) -> 290.92847 | I37: =IF(F37="","",(F37-J37)*(1-$O$5)*$O$7) -> 43.410248 | J37: {=IF(F37="","",IF(ROW()=MAX(IF($C$32:$C$47=C37,ROW($C$32:$C$47),0)),MAX(0,IFERROR(VLOOKUP(C37,$A$10:$L$13,6,FALSE)-VLOOKUP(C37,$A$10:$L$13,5,FALSE),0)),0))} -> 0 | K37: =IF(F37="","",F37-H37-I37-J37) -> 22218.256 | L37: =IF(F37="","",(F37-J37)/VLOOKUP(C37,$A$10:$L$13,5,FALSE)*VLOOKUP(C37,$A$10:$L$13,10,FALSE)*$O$8) -> 92.948392 | M37: =IF(F37="","",(F37-J37)/VLOOKUP(C37,$A$10:$L$13,5,FALSE)*VLOOKUP(C37,$A$10:$L$13,11,FALSE)) -> 633.77834 | N37: =IF(F37="","",IFERROR(VLOOKUP(C37,$A$10:$L$13,12,FALSE),0)*$O$9) -> 85.8
A38: 46207 | B38: Rail_GPRX5098_6.10.2026_offload_3 | C38: GPRX5098 | D38: =HYPERLINK("https://drive.google.com/file/d/10qZDKVkzmycBc6c8UIRBlzBLfH0SIHZN/view", 72040) -> 72040 | E38: =HYPERLINK("https://drive.google.com/file/d/1BACGKknSvrPmcL_2VcRg3CbVU-uTyTqv/view", 29080) -> 29080 | F38: =IF(D38="","",(D38-E38)*$O$4) -> 19486.312 | G38: 3.7 | H38: =IF(F38="","",(F38-J38)*$O$5) -> 251.37343 | I38: =IF(F38="","",(F38-J38)*(1-$O$5)*$O$7) -> 37.508131 | J38: {=IF(F38="","",IF(ROW()=MAX(IF($C$32:$C$47=C38,ROW($C$32:$C$47),0)),MAX(0,IFERROR(VLOOKUP(C38,$A$10:$L$13,6,FALSE)-VLOOKUP(C38,$A$10:$L$13,5,FALSE),0)),0))} -> 0 | K38: =IF(F38="","",F38-H38-I38-J38) -> 19197.431 | L38: =IF(F38="","",(F38-J38)/VLOOKUP(C38,$A$10:$L$13,5,FALSE)*VLOOKUP(C38,$A$10:$L$13,10,FALSE)*$O$8) -> 80.311 | M38: =IF(F38="","",(F38-J38)/VLOOKUP(C38,$A$10:$L$13,5,FALSE)*VLOOKUP(C38,$A$10:$L$13,11,FALSE)) -> 547.60896 | N38: =IF(F38="","",IFERROR(VLOOKUP(C38,$A$10:$L$13,12,FALSE),0)*$O$9) -> 85.8
A39: 46207 | B39: Rail_GPRX5098_6.10.2026_offload_4 | C39: GPRX5098 | D39: =HYPERLINK("https://drive.google.com/file/d/1gtVMyWN9eLcV8LMjUAK3TbEx6T80Atd5/view", 58220) -> 58220 | E39: =HYPERLINK("https://drive.google.com/file/d/1URY_X58vrKD0xevWAy8gKwk6rMBZ0b23/view", 28720) -> 28720 | F39: =IF(D39="","",(D39-E39)*$O$4) -> 13380.964 | G39: 3.7 | H39: =IF(F39="","",(F39-J39)*$O$5) -> 171.27952 | I39: =IF(F39="","",(F39-J39)*(1-$O$5)*$O$7) -> 25.557095 | J39: {=IF(F39="","",IF(ROW()=MAX(IF($C$32:$C$47=C39,ROW($C$32:$C$47),0)),MAX(0,IFERROR(VLOOKUP(C39,$A$10:$L$13,6,FALSE)-VLOOKUP(C39,$A$10:$L$13,5,FALSE),0)),0))} -> 103.48208 | K39: =IF(F39="","",F39-H39-I39-J39) -> 13080.645 | L39: =IF(F39="","",(F39-J39)/VLOOKUP(C39,$A$10:$L$13,5,FALSE)*VLOOKUP(C39,$A$10:$L$13,10,FALSE)*$O$8) -> 54.72189 | M39: =IF(F39="","",(F39-J39)/VLOOKUP(C39,$A$10:$L$13,5,FALSE)*VLOOKUP(C39,$A$10:$L$13,11,FALSE)) -> 373.12694 | N39: =IF(F39="","",IFERROR(VLOOKUP(C39,$A$10:$L$13,12,FALSE),0)*$O$9) -> 85.8
A40: 46207 | B40: Rail_GPRX5236_5.22.2026_offload_1 | C40: GPRX5236 | D40: 74300 | E40: =HYPERLINK("https://drive.google.com/file/d/1itRdMHPV5-IiOfFuRKR4qEZnfjVgMrIY/view", 29040) -> 29040 | F40: =IF(D40="","",(D40-E40)*$O$4) -> 20529.574 | G40: 3.7 | H40: =IF(F40="","",(F40-J40)*$O$5) -> 264.8315 | I40: =IF(F40="","",(F40-J40)*(1-$O$5)*$O$7) -> 39.516248 | J40: {=IF(F40="","",IF(ROW()=MAX(IF($C$32:$C$47=C40,ROW($C$32:$C$47),0)),MAX(0,IFERROR(VLOOKUP(C40,$A$10:$L$13,6,FALSE)-VLOOKUP(C40,$A$10:$L$13,5,FALSE),0)),0))} -> 0 | K40: =IF(F40="","",F40-H40-I40-J40) -> 20225.226 | L40: =IF(F40="","",(F40-J40)/VLOOKUP(C40,$A$10:$L$13,5,FALSE)*VLOOKUP(C40,$A$10:$L$13,10,FALSE)*$O$8) -> 84.298289 | M40: =IF(F40="","",(F40-J40)/VLOOKUP(C40,$A$10:$L$13,5,FALSE)*VLOOKUP(C40,$A$10:$L$13,11,FALSE)) -> 574.7967 | N40: =IF(F40="","",IFERROR(VLOOKUP(C40,$A$10:$L$13,12,FALSE),0)*$O$9) -> 85.8
A41: 46207 | B41: Rail_GPRX5236_5.22.2026_offload_2 | C41: GPRX5236 | D41: =HYPERLINK("https://drive.google.com/file/d/1OtRTwTH78CTHCt6A-PEkZzs1Jn12Z5WQ/view", 72900) -> 72900 | E41: =HYPERLINK("https://drive.google.com/file/d/1g1z8zI66m5KFviRNnTHXfYB3QcuTws04/view", 28940) -> 28940 | F41: =IF(D41="","",(D41-E41)*$O$4) -> 19939.904 | G41: 3.7 | H41: =IF(F41="","",(F41-J41)*$O$5) -> 257.22477 | I41: =IF(F41="","",(F41-J41)*(1-$O$5)*$O$7) -> 38.381225 | J41: {=IF(F41="","",IF(ROW()=MAX(IF($C$32:$C$47=C41,ROW($C$32:$C$47),0)),MAX(0,IFERROR(VLOOKUP(C41,$A$10:$L$13,6,FALSE)-VLOOKUP(C41,$A$10:$L$13,5,FALSE),0)),0))} -> 0 | K41: =IF(F41="","",F41-H41-I41-J41) -> 19644.298 | L41: =IF(F41="","",(F41-J41)/VLOOKUP(C41,$A$10:$L$13,5,FALSE)*VLOOKUP(C41,$A$10:$L$13,10,FALSE)*$O$8) -> 81.876994 | M41: =IF(F41="","",(F41-J41)/VLOOKUP(C41,$A$10:$L$13,5,FALSE)*VLOOKUP(C41,$A$10:$L$13,11,FALSE)) -> 558.28686 | N41: =IF(F41="","",IFERROR(VLOOKUP(C41,$A$10:$L$13,12,FALSE),0)*$O$9) -> 85.8
...

Sheet WODO
A1: BATCH HEADER — Charm WODO (IBC Totes)
B2: INJ-07-2026-W1 | K2: Constants
B3: 46200 | K3: Lbs/Kg | L3: 2.20462
B4: 46207 | K4: Kg/Lbs | L4: 0.453592
K5: Sparging Mass Loss | L5: 0.0129
K6: pH range (target) | L6: 2.0 - 4.0
A8: SECTION 1 - IBC LEDGER (one row per IBC tote; tote tag mass is authoritative)
B9: Transport Emissions | D9: Pyrolysis Emissions Mass | F9: MOBI
A10: Tag | B10: Gross Mass (kg) | C10: Tote Mass (kg) | D10: Net Oil Produced (kg) | E10: Empty Tote Weight (kg) | F10: Net Oil Injected (kg) | G10: Production Period | H10: Carbon Intensity | I10: Production Emissions | J10: Scale Uncertainty
A11: 300063 | B11: 1085 | C11: 57.6 | D11: =B11-C11 -> 1027.4 | E11: 63 | F11: =IF(E11="","",B11-E11) -> 1022 | G11: MFO Lot 4634 (LOT00004634), Jan 2026 | H11: 0.93199449 | I11: =H11*D11 -> 957.53114 | J11: =2.5*$L$4 -> 1.13398
A12: 300077 | B12: 1145.5 | C12: 57.6 | D12: =B12-C12 -> 1087.9 | E12: 59.5 | F12: =IF(E12="","",B12-E12) -> 1086 | G12: MFO Lot 4636 (LOT00004636), Jan 2026 | H12: 0.93199449 | I12: =H12*D12 -> 1013.9168 | J12: =2.5*$L$4 -> 1.13398
A13: 300065 | B13: 1075 | C13: 57.6 | D13: =B13-C13 -> 1017.4 | E13: 59 | F13: =IF(E13="","",B13-E13) -> 1016 | G13: MFO Lot 4642 (LOT00004642), Jan 2026 | H13: 0.93199449 | I13: =H13*D13 -> 948.21119 | J13: =2.5*$L$4 -> 1.13398
A14: 300064 | B14: 1090 | C14: 57.6 | D14: =B14-C14 -> 1032.4 | E14: 58 | F14: =IF(E14="","",B14-E14) -> 1032 | G14: MFO Lot 4654 (LOT00004654), Jan 2026 | H14: 0.93199449 | I14: =H14*D14 -> 962.19111 | J14: =2.5*$L$4 -> 1.13398
A15: 300099 | B15: 1144.5 | C15: 57.6 | D15: =B15-C15 -> 1086.9 | E15: 63.5 | F15: =IF(E15="","",B15-E15) -> 1081 | G15: MFO Lot 4660 (LOT00004660), Jan 2026 | H15: 0.93199449 | I15: =H15*D15 -> 1012.9848 | J15: =2.5*$L$4 -> 1.13398
A16: 300095 | B16: 1156 | C16: 57.6 | D16: =B16-C16 -> 1098.4 | E16: 58 | F16: =IF(E16="","",B16-E16) -> 1098 | G16: MFO Lot 4662 (LOT00004662), Jan 2026 | H16: 0.93199449 | I16: =H16*D16 -> 1023.7027 | J16: =2.5*$L$4 -> 1.13398
A17: 300054 | B17: 1157.5 | C17: 57.6 | D17: =B17-C17 -> 1099.9 | E17: 60.5 | F17: =IF(E17="","",B17-E17) -> 1097 | G17: MFO Lot 4691 (LOT00004691), Feb 2026 | H17: 0.84989612 | I17: =H17*D17 -> 934.80075 | J17: =2.5*$L$4 -> 1.13398
A18: 301020 | B18: 1017.5 | C18: 57.6 | D18: =B18-C18 -> 959.9 | E18: 60.5 | F18: =IF(E18="","",B18-E18) -> 957 | G18: MFO Lot 4782 (LOT00004782), Feb 2026 | H18: 0.84989612 | I18: =H18*D18 -> 815.81529 | J18: =2.5*$L$4 -> 1.13398
A19: 301012 | B19: 1131 | C19: 57.6 | D19: =B19-C19 -> 1073.4 | E19: 61 | F19: =IF(E19="","",B19-E19) -> 1070 | G19: MFO Lot 4809 (LOT00004809), Mar 2026 | H19: 0.79006453 | I19: =H19*D19 -> 848.05527 | J19: =2.5*$L$4 -> 1.13398
A20: 301001 | B20: 1073.5 | C20: 57.6 | D20: =B20-C20 -> 1015.9 | E20: 66.5 | F20: =IF(E20="","",B20-E20) -> 1007 | G20: MFO Lot 301001 (LOT00301001), Mar 2026 | H20: 0.79006453 | I20: =H20*D20 -> 802.62656 | J20: =2.5*$L$4 -> 1.13398
A21: 301016 | B21: 1189.5 | C21: 57.6 | D21: =B21-C21 -> 1131.9 | E21: 59.5 | F21: =IF(E21="","",B21-E21) -> 1130 | G21: MFO Lot 301016 (LOT00301016), Apr 2026 | H21: 0.78450015 | I21: =H21*D21 -> 887.97572 | J21: =2.5*$L$4 -> 1.13398
A22: 301055 | B22: 1120.5 | C22: 57.6 | D22: =B22-C22 -> 1062.9 | E22: 64.5 | F22: =IF(E22="","",B22-E22) -> 1056 | G22: MFO Lot 301055 (LOT00301055), Apr 2026 | H22: 0.78450015 | I22: =H22*D22 -> 833.84521 | J22: =2.5*$L$4 -> 1.13398
... A27: 301187 | B27: 1119 | C27: 57.6 | D27: =B27-C27 -> 1061.4 | E27: 62 | F27: =IF(E27="","",B27-E27) -> 1057 | G27: MFO Lot 301187 (LOT00301187), May 2026 | H27: 0.63284589 | I27: =H27*D27 -> 671.70263 | J27: =2.5*$L$4 -> 1.13398
B29: =SUM(B11:B27) -> 18926 | D29: =SUM(D11:D27) -> 17946.8 | E29: =SUM(E11:E27) -> 1041 | F29: =SUM(F11:F27) -> 17885 | H29: =IFERROR(I29/D29,"") -> 0.80971125 | I29: =SUM(I11:I27) -> 14531.726 | J29: =SUM(J11:J27) -> 19.27766
A31: SECTION 2 - ROLLUP
A32: Transport Mass | B32: Sigma Net Oil Produced (kg) | C32: Loss (kg) | D32: MOBI - Sigma Net Oil Injected (kg)
A33: =B29 -> 18926 | B33: =SUM(D11:D27) -> 17946.8 | C33: =A33-B33 -> 979.2 | D33: =SUM(F11:F27) -> 17885

Sheet AECN Truck
A1: BATCH HEADER — AECN Truck (Direct from Fort Lupton)
B2: INJ-07-2026-W1
B3: 46200
B4: 46207

Sheet Kerry
A1: BATCH HEADER — Kerry (Calciner Waste Oil, IBC Totes)
B2: INJ-07-2026-W1
B3: 46200
B4: 46207
A31: SECTION 2 - ROLLUP
A32: Σ Net Injected (kg) | B32: Sparging Loss (kg) | C32: MOBI (kg) | D32: pH | E32: C Content (MOBI-wtd) | G32: Origins list (Tote tags)
A33: =SUMIFS(F10:F29,B10:B29,"<>") -> 0 | B33: =A33*$M$5 -> 0 | C33: =A33-B33 -> 0 | D33: =IFERROR(AVERAGE(G10:G29),"") | E33: =IFERROR(__xludf.DUMMYFUNCTION("IFERROR(AVERAGE.WEIGHTED(I10:I29,F10:F29),"""")"),"") | G33: =IFERROR(__xludf.DUMMYFUNCTION("TRIM(TEXTJOIN("", "",TRUE,IFERROR(FILTER(B10:B29,B10:B29<>""""),"""")))"),"")

Sheet QOWV
A1: BATCH HEADER — QOWV (Aqueous Bio-Oil, IBC Totes)
A2: Batch ID (INJ-YYYY-WXX) | B2: INJ-06-2026-W2 | K2: Constants
A3: Week Start (Sat) | B3: 46179 | K3: Lbs/Kg | L3: 2.20462
A4: Week End (Sat) | B4: 46186 | K4: Kg/Lbs | L4: 0.453592
K5: Sparging Mass Loss | L5: 0.0129
K6: pH range (target) | L6: 2.0 - 4.0
A8: SECTION 1 - IBC LEDGER (one row per IBC tote; tote tag mass is authoritative)
B9: Transport Emissions | D9: Pyrolysis Emissions Mass | F9: MOBI
A10: Tag | B10: Gross Mass (kg) | C10: Tote Mass (kg) | D10: Net Oil Produced (kg) | E10: Empty Tote Weight (kg) | F10: Net Oil Injected (kg) | G10: Production Period | H10: Carbon Intensity | I10: Production Emissions | J10: Scale Uncertainty
A11: 118850 | B11: 977 | C11: 57.6 | D11: =B11-C11 -> 919.4 | E11: 138 | F11: =IF(E11="","",B11-E11) -> 839 | G11: MFO Lot 2374 (LOT00002374), PP#7 | H11: 0.13736711 | I11: =H11*D11 -> 126.29532 | J11: =2.5*$L$4 -> 1.13398
A12: 118827 | B12: 941 | C12: 57.6 | D12: =B12-C12 -> 883.4 | E12: 137 | F12: =IF(E12="","",B12-E12) -> 804 | G12: MFO Lot 2404 (LOT00002404), PP#7 | H12: 0.13736711 | I12: =H12*D12 -> 121.35011 | J12: =2.5*$L$4 -> 1.13398
A13: 118848 | B13: 1049 | C13: 57.6 | D13: =B13-C13 -> 991.4 | E13: 181.5 | F13: =IF(E13="","",B13-E13) -> 867.5 | G13: MFO Lot 2444 (LOT00002444), PP#7 | H13: 0.13736711 | I13: =H13*D13 -> 136.18576 | J13: =2.5*$L$4 -> 1.13398
A14: 118802 | B14: 1009 | C14: 57.6 | D14: =B14-C14 -> 951.4 | E14: 174 | F14: =IF(E14="","",B14-E14) -> 835 | G14: MFO Lot 2460 (LOT00002460), PP#7 | H14: 0.13736711 | I14: =H14*D14 -> 130.69107 | J14: =2.5*$L$4 -> 1.13398
A15: 118838 | B15: 966 | C15: 57.6 | D15: =B15-C15 -> 908.4 | E15: 173 | F15: =IF(E15="","",B15-E15) -> 793 | G15: MFO Lot 2464 (LOT00002464), PP#7 | H15: 0.13736711 | I15: =H15*D15 -> 124.78429 | J15: =2.5*$L$4 -> 1.13398
A16: 118861 | B16: 1081 | C16: 57.6 | D16: =B16-C16 -> 1023.4 | E16: 161 | F16: =IF(E16="","",B16-E16) -> 920 | G16: MFO Lot 2514 (LOT00002514), PP#7 | H16: 0.13736711 | I16: =H16*D16 -> 140.5815 | J16: =2.5*$L$4 -> 1.13398
A17: 118866 | B17: 994 | C17: 57.6 | D17: =B17-C17 -> 936.4 | E17: 153 | F17: =IF(E17="","",B17-E17) -> 841 | G17: MFO Lot 2534 (LOT00002534), PP#7 | H17: 0.13736711 | I17: =H17*D17 -> 128.63056 | J17: =2.5*$L$4 -> 1.13398
A18: 118882 | B18: 983 | C18: 57.6 | D18: =B18-C18 -> 925.4 | E18: 148 | F18: =IF(E18="","",B18-E18) -> 835 | G18: MFO Lot 2576 (LOT00002576), PP#7 | H18: 0.13736711 | I18: =H18*D18 -> 127.11953 | J18: =2.5*$L$4 -> 1.13398
A19: 118885 | B19: 1124 | C19: 57.6 | D19: =B19-C19 -> 1066.4 | E19: 152 | F19: =IF(E19="","",B19-E19) -> 972 | G19: MFO Lot 2578 (LOT00002578), PP#7 | H19: 0.13736711 | I19: =H19*D19 -> 146.48829 | J19: =2.5*$L$4 -> 1.13398
A20: 118814 | B20: 1161 | C20: 57.6 | D20: =B20-C20 -> 1103.4 | E20: 149 | F20: =IF(E20="","",B20-E20) -> 1012 | G20: MFO Lot 2586 (LOT00002586), PP#7 | H20: 0.13736711 | I20: =H20*D20 -> 151.57087 | J20: =2.5*$L$4 -> 1.13398
A21: 118883 | B21: 1049 | C21: 57.6 | D21: =B21-C21 -> 991.4 | E21: 218 | F21: =IF(E21="","",B21-E21) -> 831 | G21: MFO Lot 2588 (LOT00002588), PP#7 | H21: 0.13736711 | I21: =H21*D21 -> 136.18576 | J21: =2.5*$L$4 -> 1.13398
A22: 118881 | B22: 1074 | C22: 57.6 | D22: =B22-C22 -> 1016.4 | E22: 181 | F22: =IF(E22="","",B22-E22) -> 893 | G22: MFO Lot 2638 (LOT00002638), PP#7 | H22: 0.13736711 | I22: =H22*D22 -> 139.61993 | J22: =2.5*$L$4 -> 1.13398
... A46: 228402 | B46: 969 | C46: 57.6 | D46: =B46-C46 -> 911.4 | E46: 218 | F46: =IF(E46="","",B46-E46) -> 751 | G46: MFO Lot 4196 (LOT00004196), October 2025 | H46: 0.11101762 | I46: =H46*D46 -> 101.18146 | J46: =2.5*$L$4 -> 1.13398
A53: TOTAL | B53: =SUM(B11:B46) -> 37833 | C53: =SUM(C11:C46) -> 2073.6 | D53: =SUM(D11:D46) -> 35759.4 | E53: =SUM(E11:E46) -> 6396 | F53: =SUM(F11:F46) -> 31437 | H53: =IFERROR(SUMPRODUCT(D11:D46,H11:H46)/SUM(D11:D46),"") -> 0.12473991 | I53: =SUM(I11:I46) -> 4460.6245 | J53: =SUM(J11:J46) -> 40.82328
G56: =IF(AND(D56<>"",F56<>""),(D56-F56)*$L$4,"") | H56: =IF(G56="","",G56*(1-$L$5))
G57: =IF(AND(D57<>"",F57<>""),(D57-F57)*$L$4,"") | H57: =IF(G57="","",G57*(1-$L$5))
G58: =IF(AND(D58<>"",F58<>""),(D58-F58)*$L$4,"") | H58: =IF(G58="","",G58*(1-$L$5))
G59: =IF(AND(D59<>"",F59<>""),(D59-F59)*$L$4,"") | H59: =IF(G59="","",G59*(1-$L$5))
G60: =IF(AND(D60<>"",F60<>""),(D60-F60)*$L$4,"") | H60: =IF(G60="","",G60*(1-$L$5))
G61: =IF(AND(D61<>"",F61<>""),(D61-F61)*$L$4,"") | H61: =IF(G61="","",G61*(1-$L$5))
G62: =IF(AND(D62<>"",F62<>""),(D62-F62)*$L$4,"") | H62: =IF(G62="","",G62*(1-$L$5))
G63: =IF(AND(D63<>"",F63<>""),(D63-F63)*$L$4,"") | H63: =IF(G63="","",G63*(1-$L$5))
G64: =IF(AND(D64<>"",F64<>""),(D64-F64)*$L$4,"") | H64: =IF(G64="","",G64*(1-$L$5))
G65: =IF(AND(D65<>"",F65<>""),(D65-F65)*$L$4,"") | H65: =IF(G65="","",G65*(1-$L$5))
G66: =IF(AND(D66<>"",F66<>""),(D66-F66)*$L$4,"") | H66: =IF(G66="","",G66*(1-$L$5))
G67: =IF(AND(D67<>"",F67<>""),(D67-F67)*$L$4,"") | H67: =IF(G67="","",G67*(1-$L$5))
... G73: =IF(AND(D73<>"",F73<>""),(D73-F73)*$L$4,"") | H73: =IF(G73="","",G73*(1-$L$5))

Sheet WODO Shipments & EE Allocation
A1: INJ-07-2026-W1 — WODO Shipments & EE Allocation
A4: BATCH SUMMARY
A5: Batch | B5: Fraction | C5: Inj. Week | D5: # Totes | E5: Shipping Orders (relevant totes)
A6: INJ-07-2026-W1 | B6: WODO | C6: 2026-06-27 to 2026-07-04 | D6: 17 | E6: COLA19 (17)
A8: Charm CO -> Basco LA distance (one-way mi) | B8: 1201
A10: EE ALLOCATION TABLE
A11: Truck (shipping order) | B11: Ship Date | C11: Total Totes on Truck | D11: Batch-Relevant Totes | E11: Batch Share of Truck | F11: Mileage (one-way) | G11: Allocated Miles
A12: COLA19 | C12: 17 | D12: 17 | E12: =D12/C12 -> 1 | F12: =$B$8 -> 1201 | G12: =E12*F12 -> 1201
A13: TOTAL | C13: =SUM(C12) -> 17 | D13: =SUM(D12) -> 17 | G13: =SUM(G12) -> 1201
A15: BATCH MILEAGE ALLOCATION
A16: Batch | B16: Per-Truck Allocation | C16: Allocated Miles | D16: # Totes
A17: INJ-07-2026-W1 | B17: COLA19 (17/17) | C17: =G13 -> 1201 | D17: =D13 -> 17
A19: --- Shipping Order COLA19 ---
A20: Metal Tag | B20: Fraction | C20: Production Period | D20: Shipping Order | E20: Batch
A21: 300063 | B21: WODO | C21: 46023 | D21: COLA19 | E21: INJ-07-2026-W1
A22: 300077 | B22: WODO | C22: 46023 | D22: COLA19 | E22: INJ-07-2026-W1
A23: 300065 | B23: WODO | C23: 46023 | D23: COLA19 | E23: INJ-07-2026-W1
A24: 300064 | B24: WODO | C24: 46023 | D24: COLA19 | E24: INJ-07-2026-W1
A25: 300099 | B25: WODO | C25: 46023 | D25: COLA19 | E25: INJ-07-2026-W1
A26: 300095 | B26: WODO | C26: 46023 | D26: COLA19 | E26: INJ-07-2026-W1
A27: 300054 | B27: WODO | C27: 46054 | D27: COLA19 | E27: INJ-07-2026-W1
A28: 301020 | B28: WODO | C28: 46054 | D28: COLA19 | E28: INJ-07-2026-W1
A29: 301012 | B29: WODO | C29: 46082 | D29: COLA19 | E29: INJ-07-2026-W1
A30: 301001 | B30: WODO | C30: 46082 | D30: COLA19 | E30: INJ-07-2026-W1
A31: 301016 | B31: WODO | C31: 46113 | D31: COLA19 | E31: INJ-07-2026-W1
A32: 301055 | B32: WODO | C32: 46113 | D32: COLA19 | E32: INJ-07-2026-W1
... A37: 301187 | B37: WODO | C37: 46143 | D37: COLA19 | E37: INJ-07-2026-W1

Sheet QOWV Shipments & EE Allocation
A1: INJ-06-2026-W2 — QOWV Shipments & EE Mileage Allocation
A4: BATCH SUMMARY
A5: Batch | B5: Fraction | C5: Inj. Week | D5: # Totes | E5: Ship Date(s)
A6: INJ-06-2026-W2 | B6: QOWV | C6: 2026-06-06 to 2026-06-13 | D6: 36 | E6: 2025-12-09 (18), 2025-12-10 (18)
A8: Charm CO -> Basco LA distance (one-way miles): | B8: 1201
A10: EE ALLOCATION TABLE
A11: Truck (shipment) | B11: Ship Date | C11: Total Totes on Truck | D11: Batch-Relevant Totes | E11: Batch Share of Truck | F11: Mileage (one-way) | G11: Allocated Miles
A12: Shipment 12-09 | B12: 46000 | C12: 36 | D12: 18 | E12: =D12/C12 -> 0.5 | F12: =$B$8 -> 1201 | G12: =E12*F12 -> 600.5
A13: Shipment 12-10 | B13: 46001 | C13: 35 | D13: 18 | E13: =D13/C13 -> 0.51428571 | F13: =$B$8 -> 1201 | G13: =E13*F13 -> 617.65714
A14: TOTAL | C14: =SUM(C12:C13) -> 71 | D14: =SUM(D12:D13) -> 36 | G14: =SUM(G12:G13) -> 1218.1571
A16: BATCH MILEAGE ALLOCATION
A17: Batch | B17: Per-Truck Allocation (relevant/total) | C17: Allocated Miles | D17: # Totes
A18: INJ-06-2026-W2 | B18: 12-09 (18/36), 12-10 (18/35) | C18: =G14 -> 1218.1571 | D18: =D14 -> 36
A20: --- Shipment 2025-12-09 --- (18 of 36 totes on this truck are W2-relevant)
A21: Metal Tag | B21: Fraction | C21: Production Period | D21: Date Loaded | E21: Batch
A22: 118814 | B22: QOWV | C22: PP#7 | D22: 46000 | E22: INJ-06-2026-W2
A23: 120524 | B23: QOWV | C23: PP#8 | D23: 46000 | E23: INJ-06-2026-W2
A24: 120505 | B24: QOWV | C24: PP#8 | D24: 46000 | E24: INJ-06-2026-W2
A25: 120516 | B25: QOWV | C25: PP#8 | D25: 46000 | E25: INJ-06-2026-W2
A26: 228437 | B26: QOWV | C26: 45931 | D26: 46000 | E26: INJ-06-2026-W2
A27: 228426 | B27: QOWV | C27: 45931 | D27: 46000 | E27: INJ-06-2026-W2
A28: 228471 | B28: QOWV | C28: 45931 | D28: 46000 | E28: INJ-06-2026-W2
A29: 228449 | B29: QOWV | C29: 45931 | D29: 46000 | E29: INJ-06-2026-W2
A30: 228472 | B30: QOWV | C30: 45931 | D30: 46000 | E30: INJ-06-2026-W2
A31: 228463 | B31: QOWV | C31: 45931 | D31: 46000 | E31: INJ-06-2026-W2
A32: 228454 | B32: QOWV | C32: 45931 | D32: 46000 | E32: INJ-06-2026-W2
A33: 228492 | B33: QOWV | C33: 45931 | D33: 46000 | E33: INJ-06-2026-W2
A34: 228491 | B34: QOWV | C34: 45931 | D34: 46000 | E34: INJ-06-2026-W2
A35: 228420 | B35: QOWV | C35: 45931 | D35: 46000 | E35: INJ-06-2026-W2
A36: 228434 | B36: QOWV | C36: 45931 | D36: 46000 | E36: INJ-06-2026-W2
A37: 228448 | B37: QOWV | C37: 45931 | D37: 46000 | E37: INJ-06-2026-W2
... A39: 228402 | B39: QOWV | C39: 45931 | D39: 46000 | E39: INJ-06-2026-W2
A41: --- Shipment 2025-12-10 --- (18 of 35 totes on this truck are W2-relevant)
A42: Metal Tag | B42: Fraction | C42: Production Period | D42: Date Loaded | E42: Batch
A43: 118850 | B43: QOWV | C43: PP#7 | D43: 46001 | E43: INJ-06-2026-W2
A44: 118827 | B44: QOWV | C44: PP#7 | D44: 46001 | E44: INJ-06-2026-W2
A45: 118848 | B45: QOWV | C45: PP#7 | D45: 46001 | E45: INJ-06-2026-W2
A46: 118802 | B46: QOWV | C46: PP#7 | D46: 46001 | E46: INJ-06-2026-W2
A47: 118838 | B47: QOWV | C47: PP#7 | D47: 46001 | E47: INJ-06-2026-W2
A48: 118861 | B48: QOWV | C48: PP#7 | D48: 46001 | E48: INJ-06-2026-W2
...
