Workbook

Sheet Summary
A1: BATCH SUMMARY
A2: Batch ID | B2: INJ-08-2026-W5
A3: Week Start (Sat) | B3: 46256
A4: Week End (Sat) | B4: 46263
A6: SECTION 1 - PER-TAB SUMMARY (each row pulls from its mode tab)
A7: Source Tab | B7: Σ Deliveries / Cargo (kg) | C7: Σ Uncertainty Adj (kg) | D7: Mass Used (kg) | E7: Sparging Loss (kg) | F7: Filtration Loss (kg) | G7: MOBI (kg) | H7: AECN→SOPOR EE (mi) | I7: Rail EE (mi) | J7: Opel→Basco EE (mi)
A8: AECN Rail | B8: ='AECN Rail'!B65 -> 155545.77 | C8: ='AECN Rail'!C65 -> 81.028 | D8: ='AECN Rail'!D65 -> 155464.74 | E8: ='AECN Rail'!E65 -> 2005.4952 | F8: ='AECN Rail'!F65 -> 299.24553 | G8: ='AECN Rail'!G65 -> 153160 | H8: =SUM('AECN Rail'!L39:L60) -> 644.39864 | I8: =SUM('AECN Rail'!M39:M60) -> 4398 | J8: =SUM('AECN Rail'!N39:N60) -> 686.4
A9: AECN Truck | B9: ='AECN Truck'!A28 -> 158850 | C9: ='AECN Truck'!E28 -> 0 | D9: ='AECN Truck'!B28 -> 158850 | E9: ='AECN Truck'!C28 -> 2049.165 | F9: ='AECN Truck'!D28 -> 305.76163 | G9: ='AECN Truck'!F28 -> 156495.07
A10: Charm WODO | B10: =WODO!A34 -> 20554 | C10: 0 | D10: =WODO!B34 -> 19517.2 | E10: =WODO!C34 -> 141.12 | F10: 0 | G10: =WODO!D34 -> 19376.08
A11: Kerry | B11: =Kerry!A22 -> 0 | C11: 0 | D11: =Kerry!A22 -> 0 | E11: 0 | F11: =Kerry!B22 -> 0 | G11: =Kerry!C22 -> 0
A12: QOWV | B12: =QOWV!B91 -> 81961 | C12: 0 | D12: =QOWV!D91 -> 77309.9 | E12: 0 | F12: 0 | G12: =QOWV!F91 -> 66060.68
A13: TOTAL | B13: =SUM(B8:B12) -> 416910.77 | C13: =SUM(C8:C12) -> 81.028 | D13: =SUM(D8:D12) -> 411141.84 | E13: =SUM(E8:E12) -> 4195.7802 | F13: =SUM(F8:F12) -> 605.00716 | G13: =SUM(G8:G12) -> 395091.83 | H13: =SUM(H8:H12) -> 644.39864 | I13: =SUM(I8:I12) -> 4398 | J13: =SUM(J8:J12) -> 686.4
A15: SECTION 2 - PER-OIL-TYPE ROLLUP (composite C% per oil type per week)
A16: Oil Type | B16: Transport Mass - upstream (kg) | C16: Transport Mass - downstream Opel→Basco (kg) | D16: Pyrolysis Mass (kg) | E16: MOBI - sequestration (kg) | F16: Composite Sample ID | G16: C % | H16: Lab COA Link | I16: C Content Uncertainty | J16: Testing Uncertainty
A17: AECN | B17: =SUM('AECN Rail'!I10:I15)+'AECN Truck'!A28 -> 314395.77 | C17: ='AECN Rail'!B65 -> 155545.77 | D17: =SUM('AECN Rail'!I10:I15)+'AECN Truck'!A28 -> 314395.77 | E17: ='AECN Rail'!G65+'AECN Truck'!F28 -> 309655.07 | F17: 08-2026-W5 AECN | G17: 0.385 | H17: =HYPERLINK("https://drive.google.com/file/d/1AcpLB0UiP-Hw0g2CEbIgGD-e0-Xur_vi/view","COA SR26-05208.001 (reissued 2026-09-04)") -> COA SR26-05208.001 (reissued 2026-09-04) | I17: =G17*J17 -> 0.00154 | J17: 0.004
A18: WODO | B18: =WODO!A34 -> 20554 | D18: =WODO!B34 -> 19517.2 | E18: =WODO!D34 -> 19376.08 | F18: 8-2026-W5 WODO | G18: 0.554 | H18: =HYPERLINK("https://drive.google.com/file/d/1s1HRex54JkWAtwQy7Y6EUWRYwzHQ7_7h/view","COA SR26-05246.001") -> COA SR26-05246.001 | I18: =G18*J18 -> 0.002216 | J18: 0.004
A19: Kerry | B19: =Kerry!A22 -> 0 | D19: =Kerry!A22 -> 0 | E19: =Kerry!C22 -> 0 | I19: =G19*J19 -> 0 | J19: 0.004
A20: QOWV | B20: =QOWV!B91 -> 81961 | D20: =QOWV!D91 -> 77309.9 | E20: =QOWV!F91 -> 66060.68 | F20: 08-2026-W5 QOWV | G20: 0.124 | H20: =HYPERLINK("https://drive.google.com/file/d/1AcpLB0UiP-Hw0g2CEbIgGD-e0-Xur_vi/view","COA SR26-05208.002 (reissued 2026-09-04)") -> COA SR26-05208.002 (reissued 2026-09-04) | I20: =G20*J20 -> 0.000496 | J20: 0.004
A21: TOTAL | B21: =SUM(B17:B20) -> 416910.77 | C21: =SUM(C17:C20) -> 155545.77 | D21: =SUM(D17:D20) -> 411222.87 | E21: =SUM(E17:E20) -> 395091.83

Sheet AECN Rail
A1: BATCH HEADER — AECN Rail
A2: Batch ID (INJ-YYYY-WXX) | B2: INJ-08-2026-W5 | N2: Constants
A3: Week Start (Sat) | B3: 46256 | N3: Lbs/Kg | O3: 2.20462
A4: Week End (Sat) | B4: 46263 | N4: Kg/Lbs | O4: 0.453592
N5: Sparging Mass Loss | O5: 0.0129
N6: pH range (target) | O6: 2.0 - 4.0
N7: Filtration Solids Content | O7: =HYPERLINK("https://docs.google.com/spreadsheets/d/16shKoa1KP34kQJyQvzclBejW9L5-ubNSqPsMOVB7zDY/edit?usp=sharing", 0.00195) -> 0.00195
A8: SECTION 1 - RAILCARS RECEIVED THIS WEEK (entity-level) | I8: Pyrolysis Emissions Mass | N8: BOL Trips (AECN→SOPOR) | O8: 3
A9: Railcar # | B9: Arrival Date at Opelousas | C9: Loading BOLs (comma-sep) | D9: Total Loaded (MT) | E9: Total Loaded (kg) | F9: Total Offloaded (kg, auto) | G9: Loss (kg) | H9: Previously Claimed (kg) | I9: Claimed This Week (kg) | J9: AECN→SOPOR (mi) | K9: Rail (mi) | L9: Opel→Basco (mi) | M9: Full Railcar This Week? | N9: Round Trip (Opel→Basco) | O9: 2
A10: GPRX5188 | B10: 46263 | C10: 2447-R, 2448-R, 2449-R | D10: =SUMIF($C$19:$C$36,$A10,$D$19:$D$36) -> 77.71 | E10: =SUMIF($C$19:$C$36,$A10,$E$19:$E$36) -> 77710 | F10: =SUMIF($C$39:$C$60,A10,$F$39:$F$60)+H10 -> 77791.028 | G10: =IF(AND(E10<>"",F10<>"",F10>=0.95*E10),E10-F10,"") -> -81.028 | H10: 0 | I10: =F10-H10 -> 77791.028 | J10: 107.5 | K10: 2199 | L10: 42.9 | M10: =IF(OR($E10="",$F10=""),"",IF(AND($H10=0,$F10>=0.95*$E10),"FULL","PARTIAL")) -> FULL
A11: GPRX5236 | B11: 46263 | C11: 2441-R, 2442-R, 2443-R | D11: =SUMIF($C$19:$C$36,$A11,$D$19:$D$36) -> 77.9 | E11: =SUMIF($C$19:$C$36,$A11,$E$19:$E$36) -> 77900 | F11: =SUMIF($C$39:$C$60,A11,$F$39:$F$60)+H11 -> 77754.741 | G11: =IF(AND(E11<>"",F11<>"",F11>=0.95*E11),E11-F11,"") -> 145.25936 | H11: 0 | I11: =F11-H11 -> 77754.741 | J11: 107.5 | K11: 2199 | L11: 42.9 | M11: =IF(OR($E11="",$F11=""),"",IF(AND($H11=0,$F11>=0.95*$E11),"FULL","PARTIAL")) -> FULL
A17: SECTION 2 - ORIGINS LEDGER (loading BOLs at SOPOR)
A18: Date | B18: BOL # | C18: Railcar # | D18: BOL Mass (MT) | E18: BOL Mass (kg)
A19: 46231 | B19: =HYPERLINK("https://drive.google.com/file/d/1URGuPezV94NFvBd_sum57DZUa8UvnOxV/view","2447-R") -> 2447-R | C19: GPRX5188 | D19: 25.82 | E19: =D19*1000 -> 25820
A20: 46231 | B20: =HYPERLINK("https://drive.google.com/file/d/1bK9RrAiy8Z-g1PQz6ES6NsFtu9imyMQE/view","2448-R") -> 2448-R | C20: GPRX5188 | D20: 25.84 | E20: =D20*1000 -> 25840
A21: 46232 | B21: =HYPERLINK("https://drive.google.com/file/d/1TMqmC8VU5Bs58y1BlnnyggX-jbHUhBzS/view","2449-R") -> 2449-R | C21: GPRX5188 | D21: 26.05 | E21: =D21*1000 -> 26050
A22: 46230 | B22: =HYPERLINK("https://drive.google.com/file/d/1fAXkc5pctEiC1cPOioUGR2mLXCE3b5Cv/view","2441-R") -> 2441-R | C22: GPRX5236 | D22: 26.04 | E22: =D22*1000 -> 26040
A23: 46230 | B23: =HYPERLINK("https://drive.google.com/file/d/1Q8XS9_RDa34_ZZbby9j3MAqsZZads3Hr/view","2442-R") -> 2442-R | C23: GPRX5236 | D23: 26.03 | E23: =D23*1000 -> 26030
A24: 46230 | B24: =HYPERLINK("https://drive.google.com/file/d/1Yi7kD6ZcO3CamRJwZYGUquzg2PeRpHDL/view","2443-R") -> 2443-R | C24: GPRX5236 | D24: 25.83 | E24: =D24*1000 -> 25830
A37: SECTION 3 - SCALE TICKETS + OFFLOAD WEIGHTS
A38: Date | B38: Offload Key | C38: Railcar # | D38: Full Scale Ticket (lb) | E38: Empty Scale Ticket (lb) | F38: Net Scaled Mass (kg) | G38: pH | H38: Sparging Loss (kg) | I38: Filtration Loss (kg) | J38: Uncertainty Adjustment (kg) | K38: MOBI (kg) | L38: AECN→SOPOR (mi, x3 — full BOL) | M38: Rail (mi) — FULL railcar: flat 2199 on first offload; PARTIAL: offload-mass-basis allocation | N38: Opel→Basco (mi, x2 — downstream, per offload)
A39: 46263 | B39: Rail_GPRX5188_7.30.2026_offload_1 | C39: GPRX5188 | D39: 74140 | E39: 28900 | F39: =IF(OR(D39="",E39=""),"",(D39-E39)*$O$4) -> 20520.502 | G39: 2.93 | H39: =IF(F39="","",(F39-J39)*$O$5) -> 264.71448 | I39: =IF(F39="","",(F39-J39)*(1-$O$5)*$O$7) -> 39.498786 | J39: {=IF(F39="","",IF(ROW()=MAX(IF($C$39:$C$60=C39,ROW($C$39:$C$60),0)),MAX(0,IFERROR(VLOOKUP(C39,$A$10:$L$15,6,FALSE)-VLOOKUP(C39,$A$10:$L$15,5,FALSE),0)),0))} -> 0 | K39: =IF(F39="","",F39-H39-I39-J39) -> 20216.289 | L39: =IF(F39="","",(F39-J39)/VLOOKUP(C39,$A$10:$L$15,5,FALSE)*VLOOKUP(C39,$A$10:$L$15,10,FALSE)*$O$8) -> 85.161008 | M39: {=IF(F39="","",IF(IFERROR(VLOOKUP(C39,$A$10:$M$15,13,FALSE),"")="FULL",IF(ROW()=MIN(IF($C$39:$C$60=C39,ROW($C$39:$C$60),10^9)),VLOOKUP(C39,$A$10:$M$15,11,FALSE),0),(F39-J39)/VLOOKUP(C39,$A$10:$M$15,5,FALSE)*VLOOKUP(C39,$A$10:$M$15,11,FALSE)))} -> 2199 | N39: =IF(F39="","",IFERROR(VLOOKUP(C39,$A$10:$L$15,12,FALSE),0)*$O$9) -> 85.8 | O39: 0.385
A40: 46263 | B40: Rail_GPRX5188_7.30.2026_offload_2 | C40: GPRX5188 | D40: 71740 | E40: 29300 | F40: =IF(OR(D40="",E40=""),"",(D40-E40)*$O$4) -> 19250.444 | G40: 2.93 | H40: =IF(F40="","",(F40-J40)*$O$5) -> 248.33073 | I40: =IF(F40="","",(F40-J40)*(1-$O$5)*$O$7) -> 37.054122 | J40: {=IF(F40="","",IF(ROW()=MAX(IF($C$39:$C$60=C40,ROW($C$39:$C$60),0)),MAX(0,IFERROR(VLOOKUP(C40,$A$10:$L$15,6,FALSE)-VLOOKUP(C40,$A$10:$L$15,5,FALSE),0)),0))} -> 0 | K40: =IF(F40="","",F40-H40-I40-J40) -> 18965.06 | L40: =IF(F40="","",(F40-J40)/VLOOKUP(C40,$A$10:$L$15,5,FALSE)*VLOOKUP(C40,$A$10:$L$15,10,FALSE)*$O$8) -> 79.890212 | M40: {=IF(F40="","",IF(IFERROR(VLOOKUP(C40,$A$10:$M$15,13,FALSE),"")="FULL",IF(ROW()=MIN(IF($C$39:$C$60=C40,ROW($C$39:$C$60),10^9)),VLOOKUP(C40,$A$10:$M$15,11,FALSE),0),(F40-J40)/VLOOKUP(C40,$A$10:$M$15,5,FALSE)*VLOOKUP(C40,$A$10:$M$15,11,FALSE)))} -> 0 | N40: =IF(F40="","",IFERROR(VLOOKUP(C40,$A$10:$L$15,12,FALSE),0)*$O$9) -> 85.8 | O40: 0.385
A41: 46263 | B41: Rail_GPRX5188_7.30.2026_offload_3 | C41: GPRX5188 | D41: 72200 | E41: 28580 | F41: =IF(OR(D41="",E41=""),"",(D41-E41)*$O$4) -> 19785.683 | G41: 2.93 | H41: =IF(F41="","",(F41-J41)*$O$5) -> 255.23531 | I41: =IF(F41="","",(F41-J41)*(1-$O$5)*$O$7) -> 38.084373 | J41: {=IF(F41="","",IF(ROW()=MAX(IF($C$39:$C$60=C41,ROW($C$39:$C$60),0)),MAX(0,IFERROR(VLOOKUP(C41,$A$10:$L$15,6,FALSE)-VLOOKUP(C41,$A$10:$L$15,5,FALSE),0)),0))} -> 0 | K41: =IF(F41="","",F41-H41-I41-J41) -> 19492.363 | L41: =IF(F41="","",(F41-J41)/VLOOKUP(C41,$A$10:$L$15,5,FALSE)*VLOOKUP(C41,$A$10:$L$15,10,FALSE)*$O$8) -> 82.111476 | M41: {=IF(F41="","",IF(IFERROR(VLOOKUP(C41,$A$10:$M$15,13,FALSE),"")="FULL",IF(ROW()=MIN(IF($C$39:$C$60=C41,ROW($C$39:$C$60),10^9)),VLOOKUP(C41,$A$10:$M$15,11,FALSE),0),(F41-J41)/VLOOKUP(C41,$A$10:$M$15,5,FALSE)*VLOOKUP(C41,$A$10:$M$15,11,FALSE)))} -> 0 | N41: =IF(F41="","",IFERROR(VLOOKUP(C41,$A$10:$L$15,12,FALSE),0)*$O$9) -> 85.8 | O41: 0.385
A42: 46263 | B42: Rail_GPRX5188_7.30.2026_offload_4 | C42: GPRX5188 | D42: 69820 | E42: 29620 | F42: =IF(OR(D42="",E42=""),"",(D42-E42)*$O$4) -> 18234.398 | G42: 2.93 | H42: =IF(F42="","",(F42-J42)*$O$5) -> 234.17848 | I42: =IF(F42="","",(F42-J42)*(1-$O$5)*$O$7) -> 34.942424 | J42: {=IF(F42="","",IF(ROW()=MAX(IF($C$39:$C$60=C42,ROW($C$39:$C$60),0)),MAX(0,IFERROR(VLOOKUP(C42,$A$10:$L$15,6,FALSE)-VLOOKUP(C42,$A$10:$L$15,5,FALSE),0)),0))} -> 81.028 | K42: =IF(F42="","",F42-H42-I42-J42) -> 17884.25 | L42: =IF(F42="","",(F42-J42)/VLOOKUP(C42,$A$10:$L$15,5,FALSE)*VLOOKUP(C42,$A$10:$L$15,10,FALSE)*$O$8) -> 75.337305 | M42: {=IF(F42="","",IF(IFERROR(VLOOKUP(C42,$A$10:$M$15,13,FALSE),"")="FULL",IF(ROW()=MIN(IF($C$39:$C$60=C42,ROW($C$39:$C$60),10^9)),VLOOKUP(C42,$A$10:$M$15,11,FALSE),0),(F42-J42)/VLOOKUP(C42,$A$10:$M$15,5,FALSE)*VLOOKUP(C42,$A$10:$M$15,11,FALSE)))} -> 0 | N42: =IF(F42="","",IFERROR(VLOOKUP(C42,$A$10:$L$15,12,FALSE),0)*$O$9) -> 85.8 | O42: 0.385
A43: 46263 | B43: Rail_GPRX5236_7.28.2026_offload_1 | C43: GPRX5236 | D43: 74260 | E43: 28520 | F43: =IF(OR(D43="",E43=""),"",(D43-E43)*$O$4) -> 20747.298 | G43: 2.93 | H43: =IF(F43="","",(F43-J43)*$O$5) -> 267.64015 | I43: =IF(F43="","",(F43-J43)*(1-$O$5)*$O$7) -> 39.935333 | J43: {=IF(F43="","",IF(ROW()=MAX(IF($C$39:$C$60=C43,ROW($C$39:$C$60),0)),MAX(0,IFERROR(VLOOKUP(C43,$A$10:$L$15,6,FALSE)-VLOOKUP(C43,$A$10:$L$15,5,FALSE),0)),0))} -> 0 | K43: =IF(F43="","",F43-H43-I43-J43) -> 20439.723 | L43: =IF(F43="","",(F43-J43)/VLOOKUP(C43,$A$10:$L$15,5,FALSE)*VLOOKUP(C43,$A$10:$L$15,10,FALSE)*$O$8) -> 85.892216 | M43: {=IF(F43="","",IF(IFERROR(VLOOKUP(C43,$A$10:$M$15,13,FALSE),"")="FULL",IF(ROW()=MIN(IF($C$39:$C$60=C43,ROW($C$39:$C$60),10^9)),VLOOKUP(C43,$A$10:$M$15,11,FALSE),0),(F43-J43)/VLOOKUP(C43,$A$10:$M$15,5,FALSE)*VLOOKUP(C43,$A$10:$M$15,11,FALSE)))} -> 2199 | N43: =IF(F43="","",IFERROR(VLOOKUP(C43,$A$10:$L$15,12,FALSE),0)*$O$9) -> 85.8 | O43: 0.385
A44: 46263 | B44: Rail_GPRX5236_7.28.2026_offload_2 | C44: GPRX5236 | D44: 73240 | E44: 28780 | F44: =IF(OR(D44="",E44=""),"",(D44-E44)*$O$4) -> 20166.7 | G44: 2.93 | H44: =IF(F44="","",(F44-J44)*$O$5) -> 260.15043 | I44: =IF(F44="","",(F44-J44)*(1-$O$5)*$O$7) -> 38.817772 | J44: {=IF(F44="","",IF(ROW()=MAX(IF($C$39:$C$60=C44,ROW($C$39:$C$60),0)),MAX(0,IFERROR(VLOOKUP(C44,$A$10:$L$15,6,FALSE)-VLOOKUP(C44,$A$10:$L$15,5,FALSE),0)),0))} -> 0 | K44: =IF(F44="","",F44-H44-I44-J44) -> 19867.732 | L44: =IF(F44="","",(F44-J44)/VLOOKUP(C44,$A$10:$L$15,5,FALSE)*VLOOKUP(C44,$A$10:$L$15,10,FALSE)*$O$8) -> 83.488586 | M44: {=IF(F44="","",IF(IFERROR(VLOOKUP(C44,$A$10:$M$15,13,FALSE),"")="FULL",IF(ROW()=MIN(IF($C$39:$C$60=C44,ROW($C$39:$C$60),10^9)),VLOOKUP(C44,$A$10:$M$15,11,FALSE),0),(F44-J44)/VLOOKUP(C44,$A$10:$M$15,5,FALSE)*VLOOKUP(C44,$A$10:$M$15,11,FALSE)))} -> 0 | N44: =IF(F44="","",IFERROR(VLOOKUP(C44,$A$10:$L$15,12,FALSE),0)*$O$9) -> 85.8 | O44: 0.385
A45: 46263 | B45: Rail_GPRX5236_7.28.2026_offload_3 | C45: GPRX5236 | D45: 71820 | E45: 28660 | F45: =IF(OR(D45="",E45=""),"",(D45-E45)*$O$4) -> 19577.031 | G45: 2.93 | H45: =IF(F45="","",(F45-J45)*$O$5) -> 252.5437 | I45: =IF(F45="","",(F45-J45)*(1-$O$5)*$O$7) -> 37.68275 | J45: {=IF(F45="","",IF(ROW()=MAX(IF($C$39:$C$60=C45,ROW($C$39:$C$60),0)),MAX(0,IFERROR(VLOOKUP(C45,$A$10:$L$15,6,FALSE)-VLOOKUP(C45,$A$10:$L$15,5,FALSE),0)),0))} -> 0 | K45: =IF(F45="","",F45-H45-I45-J45) -> 19286.804 | L45: =IF(F45="","",(F45-J45)/VLOOKUP(C45,$A$10:$L$15,5,FALSE)*VLOOKUP(C45,$A$10:$L$15,10,FALSE)*$O$8) -> 81.047399 | M45: {=IF(F45="","",IF(IFERROR(VLOOKUP(C45,$A$10:$M$15,13,FALSE),"")="FULL",IF(ROW()=MIN(IF($C$39:$C$60=C45,ROW($C$39:$C$60),10^9)),VLOOKUP(C45,$A$10:$M$15,11,FALSE),0),(F45-J45)/VLOOKUP(C45,$A$10:$M$15,5,FALSE)*VLOOKUP(C45,$A$10:$M$15,11,FALSE)))} -> 0 | N45: =IF(F45="","",IFERROR(VLOOKUP(C45,$A$10:$L$15,12,FALSE),0)*$O$9) -> 85.8 | O45: 0.385
A46: 46263 | B46: Rail_GPRX5236_7.28.2026_offload_4 | C46: GPRX5236 | D46: 66840 | E46: 28780 | F46: =IF(OR(D46="",E46=""),"",(D46-E46)*$O$4) -> 17263.712 | G46: 2.93 | H46: =IF(F46="","",(F46-J46)*$O$5) -> 222.70188 | I46: =IF(F46="","",(F46-J46)*(1-$O$5)*$O$7) -> 33.229969 | J46: {=IF(F46="","",IF(ROW()=MAX(IF($C$39:$C$60=C46,ROW($C$39:$C$60),0)),MAX(0,IFERROR(VLOOKUP(C46,$A$10:$L$15,6,FALSE)-VLOOKUP(C46,$A$10:$L$15,5,FALSE),0)),0))} -> 0 | K46: =IF(F46="","",F46-H46-I46-J46) -> 17007.78 | L46: =IF(F46="","",(F46-J46)/VLOOKUP(C46,$A$10:$L$15,5,FALSE)*VLOOKUP(C46,$A$10:$L$15,10,FALSE)*$O$8) -> 71.470436 | M46: {=IF(F46="","",IF(IFERROR(VLOOKUP(C46,$A$10:$M$15,13,FALSE),"")="FULL",IF(ROW()=MIN(IF($C$39:$C$60=C46,ROW($C$39:$C$60),10^9)),VLOOKUP(C46,$A$10:$M$15,11,FALSE),0),(F46-J46)/VLOOKUP(C46,$A$10:$M$15,5,FALSE)*VLOOKUP(C46,$A$10:$M$15,11,FALSE)))} -> 0 | N46: =IF(F46="","",IFERROR(VLOOKUP(C46,$A$10:$L$15,12,FALSE),0)*$O$9) -> 85.8 | O46: 0.385
F47: =IF(OR(D47="",E47=""),"",(D47-E47)*$O$4) | H47: =IF(F47="","",(F47-J47)*$O$5) | I47: =IF(F47="","",(F47-J47)*(1-$O$5)*$O$7) | J47: {=IF(F47="","",IF(ROW()=MAX(IF($C$39:$C$60=C47,ROW($C$39:$C$60),0)),MAX(0,IFERROR(VLOOKUP(C47,$A$10:$L$15,6,FALSE)-VLOOKUP(C47,$A$10:$L$15,5,FALSE),0)),0))} | K47: =IF(F47="","",F47-H47-I47-J47) | L47: =IF(F47="","",(F47-J47)/VLOOKUP(C47,$A$10:$L$15,5,FALSE)*VLOOKUP(C47,$A$10:$L$15,10,FALSE)*$O$8) | M47: {=IF(F47="","",IF(IFERROR(VLOOKUP(C47,$A$10:$M$15,13,FALSE),"")="FULL",IF(ROW()=MIN(IF($C$39:$C$60=C47,ROW($C$39:$C$60),10^9)),VLOOKUP(C47,$A$10:$M$15,11,FALSE),0),(F47-J47)/VLOOKUP(C47,$A$10:$M$15,5,FALSE)*VLOOKUP(C47,$A$10:$M$15,11,FALSE)))} | N47: =IF(F47="","",IFERROR(VLOOKUP(C47,$A$10:$L$15,12,FALSE),0)*$O$9)
F48: =IF(OR(D48="",E48=""),"",(D48-E48)*$O$4) | H48: =IF(F48="","",(F48-J48)*$O$5) | I48: =IF(F48="","",(F48-J48)*(1-$O$5)*$O$7) | J48: {=IF(F48="","",IF(ROW()=MAX(IF($C$39:$C$60=C48,ROW($C$39:$C$60),0)),MAX(0,IFERROR(VLOOKUP(C48,$A$10:$L$15,6,FALSE)-VLOOKUP(C48,$A$10:$L$15,5,FALSE),0)),0))} | K48: =IF(F48="","",F48-H48-I48-J48) | L48: =IF(F48="","",(F48-J48)/VLOOKUP(C48,$A$10:$L$15,5,FALSE)*VLOOKUP(C48,$A$10:$L$15,10,FALSE)*$O$8) | M48: {=IF(F48="","",IF(IFERROR(VLOOKUP(C48,$A$10:$M$15,13,FALSE),"")="FULL",IF(ROW()=MIN(IF($C$39:$C$60=C48,ROW($C$39:$C$60),10^9)),VLOOKUP(C48,$A$10:$M$15,11,FALSE),0),(F48-J48)/VLOOKUP(C48,$A$10:$M$15,5,FALSE)*VLOOKUP(C48,$A$10:$M$15,11,FALSE)))} | N48: =IF(F48="","",IFERROR(VLOOKUP(C48,$A$10:$L$15,12,FALSE),0)*$O$9)
F49: =IF(OR(D49="",E49=""),"",(D49-E49)*$O$4) | H49: =IF(F49="","",(F49-J49)*$O$5) | I49: =IF(F49="","",(F49-J49)*(1-$O$5)*$O$7) | J49: {=IF(F49="","",IF(ROW()=MAX(IF($C$39:$C$60=C49,ROW($C$39:$C$60),0)),MAX(0,IFERROR(VLOOKUP(C49,$A$10:$L$15,6,FALSE)-VLOOKUP(C49,$A$10:$L$15,5,FALSE),0)),0))} | K49: =IF(F49="","",F49-H49-I49-J49) | L49: =IF(F49="","",(F49-J49)/VLOOKUP(C49,$A$10:$L$15,5,FALSE)*VLOOKUP(C49,$A$10:$L$15,10,FALSE)*$O$8) | M49: {=IF(F49="","",IF(IFERROR(VLOOKUP(C49,$A$10:$M$15,13,FALSE),"")="FULL",IF(ROW()=MIN(IF($C$39:$C$60=C49,ROW($C$39:$C$60),10^9)),VLOOKUP(C49,$A$10:$M$15,11,FALSE),0),(F49-J49)/VLOOKUP(C49,$A$10:$M$15,5,FALSE)*VLOOKUP(C49,$A$10:$M$15,11,FALSE)))} | N49: =IF(F49="","",IFERROR(VLOOKUP(C49,$A$10:$L$15,12,FALSE),0)*$O$9)
F50: =IF(OR(D50="",E50=""),"",(D50-E50)*$O$4) | H50: =IF(F50="","",(F50-J50)*$O$5) | I50: =IF(F50="","",(F50-J50)*(1-$O$5)*$O$7) | J50: {=IF(F50="","",IF(ROW()=MAX(IF($C$39:$C$60=C50,ROW($C$39:$C$60),0)),MAX(0,IFERROR(VLOOKUP(C50,$A$10:$L$15,6,FALSE)-VLOOKUP(C50,$A$10:$L$15,5,FALSE),0)),0))} | K50: =IF(F50="","",F50-H50-I50-J50) | L50: =IF(F50="","",(F50-J50)/VLOOKUP(C50,$A$10:$L$15,5,FALSE)*VLOOKUP(C50,$A$10:$L$15,10,FALSE)*$O$8) | M50: {=IF(F50="","",IF(IFERROR(VLOOKUP(C50,$A$10:$M$15,13,FALSE),"")="FULL",IF(ROW()=MIN(IF($C$39:$C$60=C50,ROW($C$39:$C$60),10^9)),VLOOKUP(C50,$A$10:$M$15,11,FALSE),0),(F50-J50)/VLOOKUP(C50,$A$10:$M$15,5,FALSE)*VLOOKUP(C50,$A$10:$M$15,11,FALSE)))} | N50: =IF(F50="","",IFERROR(VLOOKUP(C50,$A$10:$L$15,12,FALSE),0)*$O$9)
L61: =SUM(L39:L60) -> 644.39864 | M61: =SUM(M39:M60) -> 4398 | N61: =SUM(N39:N60) -> 686.4
A63: SECTION 4 - ROLLUP (Mass Used = Deliveries - Uncertainty Adj)
A64: Pyrolysis + Upstream Transport (BOL, kg) | B64: Deliveries raw / Downstream Transport (scale tickets, kg) | C64: Uncertainty Adj (kg) | D64: Mass Used (post-adj) (kg) | E64: Sparging Loss (kg) | F64: Filtration Loss (kg) | G64: MOBI (kg) | H64: pH | N64: Origins list (BOLs)
A65: =sum(E19:E24) -> 155610 | B65: =SUM(F39:F60) -> 155545.77 | C65: =SUM(J39:J60) -> 81.028 | D65: =B65-C65 -> 155464.74 | E65: =SUM(H39:H60) -> 2005.4952 | F65: =SUM(I39:I60) -> 299.24553 | G65: =SUM(K39:K60) -> 153160 | H65: =IFERROR(AVERAGE(G39:G60),"") -> 2.93 | N65: =IFERROR(__xludf.DUMMYFUNCTION("TRIM(TEXTJOIN("", "",TRUE,IFERROR(FILTER(B19:B36,B19:B36<>""""),"""")))"),"2447-R, 2448-R, 2449-R, 2441-R, 2442-R, 2443-R") -> 2447-R, 2448-R, 2449-R, 2441-R, 2442-R, 2443-R

Sheet AECN Truck
A1: BATCH HEADER — AECN Truck (Direct from Fort Lupton)
A2: Batch ID (INJ-YYYY-WXX) | B2: INJ-08-2026-W5 | K2: Constants
A3: Week Start (Sat) | B3: 46256 | K3: Lbs/Kg | L3: 2.20462
A4: Week End (Sat) | B4: 46263 | K4: Kg/Lbs | L4: 0.453592
K5: Sparging Mass Loss | L5: 0.0129
K6: pH range (target) | L6: 2.0 - 4.0
K7: Filtration Solids Content | L7: =HYPERLINK("https://docs.google.com/spreadsheets/d/16shKoa1KP34kQJyQvzclBejW9L5-ubNSqPsMOVB7zDY/edit?usp=sharing", 0.00195) -> 0.00195
A8: SECTION 1 - DELIVERIES LEDGER (one row per direct truck; BOL & scale ticket on same row)
A9: Date | B9: BOL # / SO # | C9: BOL Mass (MT) | D9: BOL Mass (kg) | E9: pH | F9: Notes | G9: Sparging Loss (kg) | H9: Filtration Loss (kg) | I9: MOBI (kg) | J9: C Content | L9: Mileage EE
A10: 46263 | B10: =HYPERLINK("https://drive.google.com/file/d/1w9ncSyp6Zv7l8Npn_VJrzaPPR_tGVyFL/view","2473-T") -> 2473-T | C10: 19.99 | D10: =IF(C10="","",C10*1000) -> 19990 | E10: 2.93 | F10: AECN delivery 8/24/2026 | G10: =IF(D10="","",D10*$L$5) -> 257.871 | H10: =IF(D10="","",(D10-G10)*$L$7) -> 38.477652 | I10: =IF(D10="","",D10-G10-H10) -> 19693.651 | J10: 0.385 | L10: 2197
A11: 46263 | B11: =HYPERLINK("https://drive.google.com/file/d/1y-SiWBZFwx8Gtm3wEs5CIUS7Vk37-khl/view","2475-T") -> 2475-T | C11: 19.46 | D11: =IF(C11="","",C11*1000) -> 19460 | E11: 2.93 | F11: AECN delivery 8/22/2026 | G11: =IF(D11="","",D11*$L$5) -> 251.034 | H11: =IF(D11="","",(D11-G11)*$L$7) -> 37.457484 | I11: =IF(D11="","",D11-G11-H11) -> 19171.509 | J11: 0.385 | L11: 2197
A12: 46263 | B12: =HYPERLINK("https://drive.google.com/file/d/1kmstFd3Rc-Tw50qIaP1xjGozn_h7X-GH/view","2476-T") -> 2476-T | C12: 20.1 | D12: =IF(C12="","",C12*1000) -> 20100 | E12: 2.93 | F12: AECN delivery 8/22/2026 | G12: =IF(D12="","",D12*$L$5) -> 259.29 | H12: =IF(D12="","",(D12-G12)*$L$7) -> 38.689385 | I12: =IF(D12="","",D12-G12-H12) -> 19802.021 | J12: 0.385 | L12: 2197
A13: 46263 | B13: =HYPERLINK("https://drive.google.com/file/d/1CaRRycxo-oOsKfrsn73gkX6EL7MvK0Wk/view","2478-T") -> 2478-T | C13: 19.47 | D13: =IF(C13="","",C13*1000) -> 19470 | E13: 2.93 | F13: AECN delivery 8/24/2026 | G13: =IF(D13="","",D13*$L$5) -> 251.163 | H13: =IF(D13="","",(D13-G13)*$L$7) -> 37.476732 | I13: =IF(D13="","",D13-G13-H13) -> 19181.36 | J13: 0.385 | L13: 2197
A14: 46263 | B14: =HYPERLINK("https://drive.google.com/file/d/1WJu4JKq_CoxDfXKR7R4t8h2PBkqSUluy/view","2479-T") -> 2479-T | C14: 19.95 | D14: =IF(C14="","",C14*1000) -> 19950 | E14: 2.93 | F14: AECN delivery 8/24/2026 | G14: =IF(D14="","",D14*$L$5) -> 257.355 | H14: =IF(D14="","",(D14-G14)*$L$7) -> 38.400658 | I14: =IF(D14="","",D14-G14-H14) -> 19654.244 | J14: 0.385 | L14: 2197
A15: 46263 | B15: =HYPERLINK("https://drive.google.com/file/d/1YeP7H4ij91CBOQjhhmRvPsufb4qB03Gz/view","2480-T") -> 2480-T | C15: 19.91 | D15: =IF(C15="","",C15*1000) -> 19910 | E15: 2.93 | F15: AECN delivery 8/26/2026 | G15: =IF(D15="","",D15*$L$5) -> 256.839 | H15: =IF(D15="","",(D15-G15)*$L$7) -> 38.323664 | I15: =IF(D15="","",D15-G15-H15) -> 19614.837 | J15: 0.385 | L15: 2197
A16: 46263 | B16: =HYPERLINK("https://drive.google.com/file/d/1rTaerP2EP0F_870HVoQzXuADL5T2BnUK/view","2482-T") -> 2482-T | C16: 19.96 | D16: =IF(C16="","",C16*1000) -> 19960 | E16: 2.93 | F16: AECN delivery 8/27/2026 | G16: =IF(D16="","",D16*$L$5) -> 257.484 | H16: =IF(D16="","",(D16-G16)*$L$7) -> 38.419906 | I16: =IF(D16="","",D16-G16-H16) -> 19664.096 | J16: 0.385 | L16: 2197
A17: 46263 | B17: =HYPERLINK("https://drive.google.com/file/d/1VFY2kXSVbKu2XYjKjP9I1EpukLD5GHEv/view","2483-T") -> 2483-T | C17: 20.01 | D17: =IF(C17="","",C17*1000) -> 20010 | E17: 2.93 | F17: AECN delivery 8/27/2026 | G17: =IF(D17="","",D17*$L$5) -> 258.129 | H17: =IF(D17="","",(D17-G17)*$L$7) -> 38.516148 | I17: =IF(D17="","",D17-G17-H17) -> 19713.355 | J17: 0.385 | L17: 2197
D18: =IF(C18="","",C18*1000) | G18: =IF(D18="","",D18*$L$5) | H18: =IF(D18="","",(D18-G18)*$L$7) | I18: =IF(D18="","",D18-G18-H18)
D19: =IF(C19="","",C19*1000) | G19: =IF(D19="","",D19*$L$5) | H19: =IF(D19="","",(D19-G19)*$L$7) | I19: =IF(D19="","",D19-G19-H19)
D20: =IF(C20="","",C20*1000) | G20: =IF(D20="","",D20*$L$5) | H20: =IF(D20="","",(D20-G20)*$L$7) | I20: =IF(D20="","",D20-G20-H20) | L20: =SUM(L10:L17) -> 17576
D21: =IF(C21="","",C21*1000) | G21: =IF(D21="","",D21*$L$5) | H21: =IF(D21="","",(D21-G21)*$L$7) | I21: =IF(D21="","",D21-G21-H21)
D22: =IF(C22="","",C22*1000) | G22: =IF(D22="","",D22*$L$5) | H22: =IF(D22="","",(D22-G22)*$L$7) | I22: =IF(D22="","",D22-G22-H22)
D23: =IF(C23="","",C23*1000) | G23: =IF(D23="","",D23*$L$5) | H23: =IF(D23="","",(D23-G23)*$L$7) | I23: =IF(D23="","",D23-G23-H23)
D24: =IF(C24="","",C24*1000) | G24: =IF(D24="","",D24*$L$5) | H24: =IF(D24="","",(D24-G24)*$L$7) | I24: =IF(D24="","",D24-G24-H24)
A26: SECTION 2 - ROLLUP (Mass Used = Σ BOL kg; scale tickets no longer required for direct trucks per 2026-05-26)
A27: Σ BOL (kg) | B27: Mass Used (kg) | C27: Sparging Loss (kg) | D27: Filtration Loss (kg) | E27: Uncertainty Adjustment (kg) | F27: MOBI (kg) | G27: pH | H27: C Content (MOBI-wtd) | J27: Origins list (BOLs)
A28: =SUMIFS(D10:D24,B10:B24,"<>") -> 158850 | B28: =A28 -> 158850 | C28: =B28*$L$5 -> 2049.165 | D28: =(B28-C28)*$L$7 -> 305.76163 | E28: 0 | F28: =B28-C28-D28-E28 -> 156495.07 | G28: =IFERROR(AVERAGE(E10:E24),"") -> 2.93 | H28: =IFERROR(SUMPRODUCT(I10:I24,J10:J24)/SUM(I10:I24),"") -> 0.385 | J28: =IFERROR(__xludf.DUMMYFUNCTION("TRIM(TEXTJOIN("", "",TRUE,IFERROR(FILTER(B10:B24,B10:B24<>""""),"""")))"),"2473-T, 2475-T, 2476-T, 2478-T, 2479-T, 2480-T, 2482-T, 2483-T") -> 2473-T, 2475-T, 2476-T, 2478-T, 2479-T, 2480-T, 2482-T, 2483-T

Sheet WODO
A1: BATCH HEADER — Charm WODO (IBC Totes)
A2: Batch ID (INJ-YYYY-WXX) | B2: INJ-08-2026-W5 | K2: Constants
A3: Week Start (Sat) | B3: 46256 | K3: Lbs/Kg | L3: 2.20462
A4: Week End (Sat) | B4: 46263 | K4: Kg/Lbs | L4: 0.453592
K5: Sparging Mass Loss | L5: 0.0129
K6: pH range (target) | L6: 2.0 - 4.0
K7: WODO 6-Mo CI (kg CO2e/kg), Jul-Dec 2026 | L7: 0.795241
A8: SECTION 1 - IBC LEDGER (one row per IBC tote; tote tag mass is authoritative) | K8: WODO Standard Loss (kg/tote), 2026 = Mean + 1 SD | L8: 7.84 | M8: =HYPERLINK("https://docs.google.com/spreadsheets/d/15fnYOYMmu-7a-p8Alst6mAOsV7X854y6HBDYwQRUm5s/edit","Tote Loss Dataset") -> Tote Loss Dataset
B9: Transport Emissions | D9: Pyrolysis Emissions Mass & Standard Loss | F9: MOBI | K9: Per-Production-Month CI (kg CO2e/kg) - PP Summary Output Type table, col T
A10: Tag | B10: Gross Mass (kg) | C10: Tote Mass (kg) | D10: Net Oil Produced (kg) | E10: Standard Loss (kg) | F10: Net Oil Injected (kg) | G10: Production Period | H10: Carbon Intensity | I10: Production Emissions | J10: Scale Uncertainty | K10: PP#8 | L10: 0.71282902 | M10: =HYPERLINK("https://docs.google.com/spreadsheets/d/1L167k_JS3mnisFy3VpS-OXgI8U0cK-4nC6A9sxl-ozk/edit","PP Summary") -> PP Summary
A11: 301047 | B11: 1198 | C11: 57.6 | D11: =B11-C11 -> 1140.4 | E11: =$L$8 -> 7.84 | F11: =D11-E11 -> 1132.56 | G11: MFO Lot 301047 (LOT00301047), March 2026 | H11: =$L$15 -> 0.79006453 | I11: =IF(H11="","",H11*D11) -> 900.98959 | J11: =2.5*$L$4 -> 1.13398 | K11: 45962 | L11: 0.97484085 | M11: =HYPERLINK("https://docs.google.com/spreadsheets/d/1W8jWu3sp39WnSuds1Ja0FWDG5UuWN9v5NUmF6yh_WbI/edit","PP Summary") -> PP Summary
A12: 301052 | B12: 1119 | C12: 57.6 | D12: =B12-C12 -> 1061.4 | E12: =$L$8 -> 7.84 | F12: =D12-E12 -> 1053.56 | G12: MFO Lot 301052 (LOT00301052), March 2026 | H12: =$L$15 -> 0.79006453 | I12: =IF(H12="","",H12*D12) -> 838.5745 | J12: =2.5*$L$4 -> 1.13398 | K12: 45992 | L12: 0.97218282 | M12: =HYPERLINK("https://docs.google.com/spreadsheets/d/1-L6m2wYknC3o-yIts9KK7FrYAb5lZIv4AwaizK8FbMc/edit","PP Summary") -> PP Summary
A13: 301068 | B13: 1170 | C13: 57.6 | D13: =B13-C13 -> 1112.4 | E13: =$L$8 -> 7.84 | F13: =D13-E13 -> 1104.56 | G13: MFO Lot 301068 (LOT00301068), March 2026 | H13: =$L$15 -> 0.79006453 | I13: =IF(H13="","",H13*D13) -> 878.86779 | J13: =2.5*$L$4 -> 1.13398 | K13: 46023 | L13: 0.93199449 | M13: =HYPERLINK("https://docs.google.com/spreadsheets/d/1bPZ7pNsR5rv-om-BypF4lK3nczjn4HJNO2dzimwnx7E/edit","PP Summary") -> PP Summary
A14: 301081 | B14: 1138 | C14: 57.6 | D14: =B14-C14 -> 1080.4 | E14: =$L$8 -> 7.84 | F14: =D14-E14 -> 1072.56 | G14: MFO Lot 301081 (LOT00301081), March 2026 | H14: =$L$15 -> 0.79006453 | I14: =IF(H14="","",H14*D14) -> 853.58572 | J14: =2.5*$L$4 -> 1.13398 | K14: 46054 | L14: 0.84989612 | M14: =HYPERLINK("https://docs.google.com/spreadsheets/d/1vH7bborVnc-TCby3wEkpzi7GGMOI5jMJooEW0V-rOQ4/edit","PP Summary") -> PP Summary
A15: 301091 | B15: 1103 | C15: 57.6 | D15: =B15-C15 -> 1045.4 | E15: =$L$8 -> 7.84 | F15: =D15-E15 -> 1037.56 | G15: MFO Lot 301091 (LOT00301091), March 2026 | H15: =$L$15 -> 0.79006453 | I15: =IF(H15="","",H15*D15) -> 825.93346 | J15: =2.5*$L$4 -> 1.13398 | K15: 46082 | L15: 0.79006453 | M15: =HYPERLINK("https://docs.google.com/spreadsheets/d/1O7y30opa_u1_deqFm_w2qgVyxi_75X00xnzKuyVyh6o/edit","PP Summary") -> PP Summary
A16: 301096 | B16: 968 | C16: 57.6 | D16: =B16-C16 -> 910.4 | E16: =$L$8 -> 7.84 | F16: =D16-E16 -> 902.56 | G16: MFO Lot 301096 (LOT00301096), March 2026 | H16: =$L$15 -> 0.79006453 | I16: =IF(H16="","",H16*D16) -> 719.27475 | J16: =2.5*$L$4 -> 1.13398 | K16: 46113 | L16: 0.78483234 | M16: =HYPERLINK("https://docs.google.com/spreadsheets/d/10Qwx7K6sUcOBrCebGUGVaVeLQnhzvcT8sHQ0Sy3VBBM/edit","PP Summary") -> PP Summary
A17: 301241 | B17: 1241 | C17: 57.6 | D17: =B17-C17 -> 1183.4 | E17: =$L$8 -> 7.84 | F17: =D17-E17 -> 1175.56 | G17: MFO Lot 301241 (LOT00301241), July 2026 | H17: =$L$19 -> 0.795241 | I17: =IF(H17="","",H17*D17) -> 941.0882 | J17: =2.5*$L$4 -> 1.13398 | K17: 46143 | L17: 0.63284589 | M17: =HYPERLINK("https://docs.google.com/spreadsheets/d/1m66t1jsLGc4e6AWnCFMsFbkSceZ9IYC_-bfTsbP_OYc/edit","PP Summary") -> PP Summary
A18: 301250 | B18: 1181 | C18: 57.6 | D18: =B18-C18 -> 1123.4 | E18: =$L$8 -> 7.84 | F18: =D18-E18 -> 1115.56 | G18: MFO Lot 301250 (LOT00301250), July 2026 | H18: =$L$19 -> 0.795241 | I18: =IF(H18="","",H18*D18) -> 893.37374 | J18: =2.5*$L$4 -> 1.13398 | K18: 46174 | L18: 1.1105356 | M18: =HYPERLINK("https://docs.google.com/spreadsheets/d/1MUQajDI2a_Cn9xWGPP7z4PhhphZnfl2_CSTnpB07Wgk/edit","PP Summary") -> PP Summary
A19: 301251 | B19: 1123 | C19: 57.6 | D19: =B19-C19 -> 1065.4 | E19: =$L$8 -> 7.84 | F19: =D19-E19 -> 1057.56 | G19: MFO Lot 301251 (LOT00301251), June 2026 | H19: =$L$18 -> 1.1105356 | I19: =IF(H19="","",H19*D19) -> 1183.1646 | J19: =2.5*$L$4 -> 1.13398 | K19: July 2026 and later (Jan-Jun 2026 rolling) | L19: =$L$7 -> 0.795241
A20: 301264 | B20: 1177 | C20: 57.6 | D20: =B20-C20 -> 1119.4 | E20: =$L$8 -> 7.84 | F20: =D20-E20 -> 1111.56 | G20: MFO Lot 301264 (LOT00301264), July 2026 | H20: =$L$19 -> 0.795241 | I20: =IF(H20="","",H20*D20) -> 890.19278 | J20: =2.5*$L$4 -> 1.13398
A21: 301286 | B21: 1213 | C21: 57.6 | D21: =B21-C21 -> 1155.4 | E21: =$L$8 -> 7.84 | F21: =D21-E21 -> 1147.56 | G21: MFO Lot 301286 (LOT00301286), July 2026 | H21: =$L$19 -> 0.795241 | I21: =IF(H21="","",H21*D21) -> 918.82145 | J21: =2.5*$L$4 -> 1.13398
A22: 301304 | B22: 1131 | C22: 57.6 | D22: =B22-C22 -> 1073.4 | E22: =$L$8 -> 7.84 | F22: =D22-E22 -> 1065.56 | G22: MFO Lot 301304 (LOT00301304), July 2026 | H22: =$L$19 -> 0.795241 | I22: =IF(H22="","",H22*D22) -> 853.61169 | J22: =2.5*$L$4 -> 1.13398
A23: 301314 | B23: 1103 | C23: 57.6 | D23: =B23-C23 -> 1045.4 | E23: =$L$8 -> 7.84 | F23: =D23-E23 -> 1037.56 | G23: MFO Lot 301314 (LOT00301314), July 2026 | H23: =$L$19 -> 0.795241 | I23: =IF(H23="","",H23*D23) -> 831.34494 | J23: =2.5*$L$4 -> 1.13398
A24: 301333 | B24: 1096 | C24: 57.6 | D24: =B24-C24 -> 1038.4 | E24: =$L$8 -> 7.84 | F24: =D24-E24 -> 1030.56 | G24: MFO Lot 301333 (LOT00301333), July 2026 | H24: =$L$19 -> 0.795241 | I24: =IF(H24="","",H24*D24) -> 825.77825 | J24: =2.5*$L$4 -> 1.13398
A25: 301372 | B25: 1191 | C25: 57.6 | D25: =B25-C25 -> 1133.4 | E25: =$L$8 -> 7.84 | F25: =D25-E25 -> 1125.56 | G25: MFO Lot 301372 (LOT00301372), July 2026 | H25: =$L$19 -> 0.795241 | I25: =IF(H25="","",H25*D25) -> 901.32615 | J25: =2.5*$L$4 -> 1.13398
A26: 300048 | B26: 1058 | C26: 57.6 | D26: =B26-C26 -> 1000.4 | E26: =$L$8 -> 7.84 | F26: =D26-E26 -> 992.56 | G26: MFO Lot 4678 (LOT00004678), February 2026 | H26: =$L$14 -> 0.84989612 | I26: =IF(H26="","",H26*D26) -> 850.23608 | J26: =2.5*$L$4 -> 1.13398
A27: 300021 | B27: 1204 | C27: 57.6 | D27: =B27-C27 -> 1146.4 | E27: =$L$8 -> 7.84 | F27: =D27-E27 -> 1138.56 | G27: MFO Lot 4731 (LOT00004731), February 2026 | H27: =$L$14 -> 0.84989612 | I27: =IF(H27="","",H27*D27) -> 974.32091 | J27: =2.5*$L$4 -> 1.13398
A28: 300080 | B28: 1140 | C28: 57.6 | D28: =B28-C28 -> 1082.4 | E28: =$L$8 -> 7.84 | F28: =D28-E28 -> 1074.56 | G28: MFO Lot 4745 (LOT00004745), February 2026 | H28: =$L$14 -> 0.84989612 | I28: =IF(H28="","",H28*D28) -> 919.92756 | J28: =2.5*$L$4 -> 1.13398
A30: TOTAL | B30: =SUM(B11:B28) -> 20554 | C30: =SUM(C11:C28) -> 1036.8 | D30: =SUM(D11:D28) -> 19517.2 | E30: =SUM(E11:E28) -> 141.12 | F30: =SUM(F11:F28) -> 19376.08 | H30: =I30/D30 -> 0.81981084 | I30: =SUM(I11:I28) -> 16000.412 | J30: =SUM(J11:J28) -> 20.41164
A32: SECTION 2 - ROLLUP
A33: Transport Mass | B33: Σ Net Oil Produced (kg) | C33: Loss (kg) | D33: MOBI — Σ Net Oil Injected (kg)
A34: =B30 -> 20554 | B34: =SUM(D11:D28) -> 19517.2 | C34: =IF(D34=0,"",B34-D34) -> 141.12 | D34: =SUM(F11:F28) -> 19376.08

Sheet QOWV
A1: BATCH HEADER — QOWV (Aqueous Bio-Oil, IBC Totes)
A2: Batch ID (INJ-YYYY-WXX) | B2: INJ-08-2026-W5 | K2: Constants
A3: Week Start (Sat) | B3: 46256 | K3: Lbs/Kg | L3: 2.20462
A4: Week End (Sat) | B4: 46263 | K4: Kg/Lbs | L4: 0.453592
K5: Sparging Mass Loss | L5: 0.0129
K6: pH range (target) | L6: 2.0 - 4.0
K7: QOWV 6-Mo CI (kg CO2e/kg), Jul-Dec 2026 | L7: 0.120947
A8: SECTION 1 - IBC LEDGER (one row per IBC tote; tote tag mass is authoritative)
B9: Transport Emissions | D9: Pyrolysis Emissions Mass | F9: MOBI | K9: Per-Production-Month CI (kg CO2e/kg) - PP Summary Output Type table, col T
A10: Tag | B10: Gross Mass (kg) | C10: Tote Mass (kg) | D10: Net Oil Produced (kg) | E10: Empty Tote Weight (kg) | F10: Net Oil Injected (kg) | G10: Production Period | H10: Carbon Intensity | I10: Production Emissions | J10: Scale Uncertainty | K10: PP#8 | L10: 0.15755534 | M10: =HYPERLINK("https://docs.google.com/spreadsheets/d/1L167k_JS3mnisFy3VpS-OXgI8U0cK-4nC6A9sxl-ozk/edit","PP Summary") -> PP Summary
A11: 15158 | B11: 1069 | C11: 57.6 | D11: =B11-C11 -> 1011.4 | E11: 204.87 | F11: =IF(E11="","",B11-E11) -> 864.13 | G11: MFO Lot 15158 (LOT00015158), PP#8 | H11: =$L$10 -> 0.15755534 | I11: =IF(H11="","",H11*D11) -> 159.35147 | J11: =2.5*$L$4 -> 1.13398 | K11: 45962 | L11: 0.13921405 | M11: =HYPERLINK("https://docs.google.com/spreadsheets/d/1W8jWu3sp39WnSuds1Ja0FWDG5UuWN9v5NUmF6yh_WbI/edit","PP Summary") -> PP Summary
A12: 245109 | B12: 1034 | C12: 57.6 | D12: =B12-C12 -> 976.4 | E12: 204.87 | F12: =IF(E12="","",B12-E12) -> 829.13 | G12: MFO Lot 7580 (LOT00245109), PP#10 | H12: =$L$22 -> 0.12868957 | I12: =IF(H12="","",H12*D12) -> 125.65249 | J12: =2.5*$L$4 -> 1.13398 | K12: 45992 | L12: 0.16306166 | M12: =HYPERLINK("https://docs.google.com/spreadsheets/d/1-L6m2wYknC3o-yIts9KK7FrYAb5lZIv4AwaizK8FbMc/edit","PP Summary") -> PP Summary
A13: 245168 | B13: 1047 | C13: 57.6 | D13: =B13-C13 -> 989.4 | E13: 195.5 | F13: =IF(E13="","",B13-E13) -> 851.5 | G13: MFO Lot 245168 (LOT00245168), PP#10 | H13: =$L$22 -> 0.12868957 | I13: =IF(H13="","",H13*D13) -> 127.32546 | J13: =2.5*$L$4 -> 1.13398 | K13: 46023 | L13: 0.15683402 | M13: =HYPERLINK("https://docs.google.com/spreadsheets/d/1bPZ7pNsR5rv-om-BypF4lK3nczjn4HJNO2dzimwnx7E/edit","PP Summary") -> PP Summary
A14: 301032 | B14: 972 | C14: 57.6 | D14: =B14-C14 -> 914.4 | E14: 145 | F14: =IF(E14="","",B14-E14) -> 827 | G14: MFO Lot 301032 (LOT00301032), March 2026 | H14: =$L$15 -> 0.11852515 | I14: =IF(H14="","",H14*D14) -> 108.3794 | J14: =2.5*$L$4 -> 1.13398 | K14: 46054 | L14: 0.13304979 | M14: =HYPERLINK("https://docs.google.com/spreadsheets/d/1vH7bborVnc-TCby3wEkpzi7GGMOI5jMJooEW0V-rOQ4/edit","PP Summary") -> PP Summary
A15: 301053 | B15: 1006 | C15: 57.6 | D15: =B15-C15 -> 948.4 | E15: 166.5 | F15: =IF(E15="","",B15-E15) -> 839.5 | G15: MFO Lot 301053 (LOT00301053), April 2026 | H15: =$L$16 -> 0.13141845 | I15: =IF(H15="","",H15*D15) -> 124.63726 | J15: =2.5*$L$4 -> 1.13398 | K15: 46082 | L15: 0.11852515 | M15: =HYPERLINK("https://docs.google.com/spreadsheets/d/1O7y30opa_u1_deqFm_w2qgVyxi_75X00xnzKuyVyh6o/edit","PP Summary") -> PP Summary
A16: 301135 | B16: 1027 | C16: 57.6 | D16: =B16-C16 -> 969.4 | E16: 152 | F16: =IF(E16="","",B16-E16) -> 875 | G16: MFO Lot 301135 (LOT00301135), April 2026 | H16: =$L$16 -> 0.13141845 | I16: =IF(H16="","",H16*D16) -> 127.39705 | J16: =2.5*$L$4 -> 1.13398 | K16: 46113 | L16: 0.13141845 | M16: =HYPERLINK("https://docs.google.com/spreadsheets/d/10Qwx7K6sUcOBrCebGUGVaVeLQnhzvcT8sHQ0Sy3VBBM/edit","PP Summary") -> PP Summary
A17: 301137 | B17: 1094 | C17: 57.6 | D17: =B17-C17 -> 1036.4 | E17: 170.5 | F17: =IF(E17="","",B17-E17) -> 923.5 | G17: MFO Lot 301137 (LOT00301137), April 2026 | H17: =$L$16 -> 0.13141845 | I17: =IF(H17="","",H17*D17) -> 136.20208 | J17: =2.5*$L$4 -> 1.13398 | K17: 46143 | L17: 0.11066158 | M17: =HYPERLINK("https://docs.google.com/spreadsheets/d/1m66t1jsLGc4e6AWnCFMsFbkSceZ9IYC_-bfTsbP_OYc/edit","PP Summary") -> PP Summary
A18: 301160 | B18: 1049 | C18: 57.6 | D18: =B18-C18 -> 991.4 | E18: 247.5 | F18: =IF(E18="","",B18-E18) -> 801.5 | G18: MFO Lot 301160 (LOT00301160), April 2026 | H18: =$L$16 -> 0.13141845 | I18: =IF(H18="","",H18*D18) -> 130.28825 | J18: =2.5*$L$4 -> 1.13398 | K18: 46174 | L18: 0.12368967 | M18: =HYPERLINK("https://docs.google.com/spreadsheets/d/1MUQajDI2a_Cn9xWGPP7z4PhhphZnfl2_CSTnpB07Wgk/edit","PP Summary") -> PP Summary
A19: 301161 | B19: 1111 | C19: 57.6 | D19: =B19-C19 -> 1053.4 | E19: 237.5 | F19: =IF(E19="","",B19-E19) -> 873.5 | G19: MFO Lot 301161 (LOT00301161), May 2026 | H19: =$L$17 -> 0.11066158 | I19: =IF(H19="","",H19*D19) -> 116.5709 | J19: =2.5*$L$4 -> 1.13398 | K19: July 2026 and later (Jan-Jun 2026 rolling) | L19: =$L$7 -> 0.120947
A20: 301164 | B20: 1054 | C20: 57.6 | D20: =B20-C20 -> 996.4 | E20: 284.5 | F20: =IF(E20="","",B20-E20) -> 769.5 | G20: MFO Lot 301164 (LOT00301164), May 2026 | H20: =$L$17 -> 0.11066158 | I20: =IF(H20="","",H20*D20) -> 110.26319 | J20: =2.5*$L$4 -> 1.13398 | K20: PP#7 | L20: 0.13736711 | M20: =HYPERLINK("https://docs.google.com/spreadsheets/d/1qPyS0H9Wx8z2vMl_3ANE1YLYahKLeL1Qo8OmZ_ol9aI/edit","PP Summary") -> PP Summary
A21: 301177 | B21: 1001 | C21: 57.6 | D21: =B21-C21 -> 943.4 | E21: 265 | F21: =IF(E21="","",B21-E21) -> 736 | G21: MFO Lot 301177 (LOT00301177), May 2026 | H21: =$L$17 -> 0.11066158 | I21: =IF(H21="","",H21*D21) -> 104.39813 | J21: =2.5*$L$4 -> 1.13398 | K21: PP#9 | L21: 0.11056982 | M21: =HYPERLINK("https://docs.google.com/spreadsheets/d/1Kt3H_bffKPxvyBHqOAdrhnGxRzwfAQXFnsLBczb9EKE/edit","PP Summary") -> PP Summary
A22: 120559 | B22: 1121 | C22: 62.9 | D22: =B22-C22 -> 1058.1 | E22: 152 | F22: =IF(E22="","",B22-E22) -> 969 | G22: MFO Lot 2774 (LOT00002774), PP#7 | H22: =$L$20 -> 0.13736711 | I22: =IF(H22="","",H22*D22) -> 145.34814 | J22: =2.5*$L$4 -> 1.13398 | K22: PP#10 | L22: 0.12868957 | M22: =HYPERLINK("https://docs.google.com/spreadsheets/d/1ZSnVAnmV96Ux_GwEJ_1zeATDHlQlHr5rvKAh3NOG2s0/edit","PP Summary") -> PP Summary
A23: 120577 | B23: 1045 | C23: 62.9 | D23: =B23-C23 -> 982.1 | E23: 204.87 | F23: =IF(E23="","",B23-E23) -> 840.13 | G23: MFO Lot 2814 (LOT00002814), PP#8 | H23: =$L$10 -> 0.15755534 | I23: =IF(H23="","",H23*D23) -> 154.7351 | J23: =2.5*$L$4 -> 1.13398
A24: 120529 | B24: 936 | C24: 62.9 | D24: =B24-C24 -> 873.1 | E24: 204.87 | F24: =IF(E24="","",B24-E24) -> 731.13 | G24: MFO Lot 2832 (LOT00002832), PP#8 | H24: =$L$10 -> 0.15755534 | I24: =IF(H24="","",H24*D24) -> 137.56157 | J24: =2.5*$L$4 -> 1.13398
A25: 120526 | B25: 1010 | C25: 62.9 | D25: =B25-C25 -> 947.1 | E25: 204.87 | F25: =IF(E25="","",B25-E25) -> 805.13 | G25: MFO Lot 2838 (LOT00002838), PP#8 | H25: =$L$10 -> 0.15755534 | I25: =IF(H25="","",H25*D25) -> 149.22066 | J25: =2.5*$L$4 -> 1.13398
A26: 120530 | B26: 994 | C26: 62.9 | D26: =B26-C26 -> 931.1 | E26: 204.39 | F26: =IF(E26="","",B26-E26) -> 789.61 | G26: MFO Lot 2878 (LOT00002878), PP#8 | H26: =$L$10 -> 0.15755534 | I26: =IF(H26="","",H26*D26) -> 146.69978 | J26: =2.5*$L$4 -> 1.13398
A27: 120556 | B27: 1074 | C27: 62.9 | D27: =B27-C27 -> 1011.1 | E27: 205.35 | F27: =IF(E27="","",B27-E27) -> 868.65 | G27: MFO Lot 2884 (LOT00002884), PP#8 | H27: =$L$10 -> 0.15755534 | I27: =IF(H27="","",H27*D27) -> 159.3042 | J27: =2.5*$L$4 -> 1.13398
A28: 120536 | B28: 1066 | C28: 62.9 | D28: =B28-C28 -> 1003.1 | E28: 204.87 | F28: =IF(E28="","",B28-E28) -> 861.13 | G28: MFO Lot 2888 (LOT00002888), PP#8 | H28: =$L$10 -> 0.15755534 | I28: =IF(H28="","",H28*D28) -> 158.04376 | J28: =2.5*$L$4 -> 1.13398
A29: 120533 | B29: 1035 | C29: 62.9 | D29: =B29-C29 -> 972.1 | E29: 204.87 | F29: =IF(E29="","",B29-E29) -> 830.13 | G29: MFO Lot 2890 (LOT00002890), PP#8 | H29: =$L$10 -> 0.15755534 | I29: =IF(H29="","",H29*D29) -> 153.15955 | J29: =2.5*$L$4 -> 1.13398
A30: 120571 | B30: 1030 | C30: 62.9 | D30: =B30-C30 -> 967.1 | E30: 172 | F30: =IF(E30="","",B30-E30) -> 858 | G30: MFO Lot 2906 (LOT00002906), PP#8 | H30: =$L$10 -> 0.15755534 | I30: =IF(H30="","",H30*D30) -> 152.37177 | J30: =2.5*$L$4 -> 1.13398
A31: 120539 | B31: 1002 | C31: 62.9 | D31: =B31-C31 -> 939.1 | E31: 204.87 | F31: =IF(E31="","",B31-E31) -> 797.13 | G31: MFO Lot 2916 (LOT00002916), PP#8 | H31: =$L$10 -> 0.15755534 | I31: =IF(H31="","",H31*D31) -> 147.96022 | J31: =2.5*$L$4 -> 1.13398
A32: 120535 | B32: 906 | C32: 62.9 | D32: =B32-C32 -> 843.1 | E32: 204.87 | F32: =IF(E32="","",B32-E32) -> 701.13 | G32: MFO Lot 2918 (LOT00002918), PP#8 | H32: =$L$10 -> 0.15755534 | I32: =IF(H32="","",H32*D32) -> 132.83491 | J32: =2.5*$L$4 -> 1.13398
A33: 120510 | B33: 1053 | C33: 62.9 | D33: =B33-C33 -> 990.1 | E33: 204.87 | F33: =IF(E33="","",B33-E33) -> 848.13 | G33: MFO Lot 2926 (LOT00002926), PP#8 | H33: =$L$10 -> 0.15755534 | I33: =IF(H33="","",H33*D33) -> 155.99554 | J33: =2.5*$L$4 -> 1.13398
A34: 120557 | B34: 928 | C34: 62.9 | D34: =B34-C34 -> 865.1 | E34: 204.87 | F34: =IF(E34="","",B34-E34) -> 723.13 | G34: MFO Lot 2928 (LOT00002928), PP#8 | H34: =$L$10 -> 0.15755534 | I34: =IF(H34="","",H34*D34) -> 136.30112 | J34: =2.5*$L$4 -> 1.13398
... A60: 15198 | B60: 1034 | C60: 57.6 | D60: =B60-C60 -> 976.4 | E60: 156 | F60: =IF(E60="","",B60-E60) -> 878 | G60: MFO Lot 3281 (LOT00003281), PP#8 | H60: =$L$10 -> 0.15755534 | I60: =IF(H60="","",H60*D60) -> 153.83703 | J60: =2.5*$L$4 -> 1.13398
A61: 15183 | B61: 1011 | C61: 57.6 | D61: =B61-C61 -> 953.4 | E61: 204.87 | F61: =IF(E61="","",B61-E61) -> 806.13 | G61: MFO Lot 3374 (LOT00003374), PP#9 | H61: =$L$21 -> 0.11056982 | I61: =IF(H61="","",H61*D61) -> 105.41727 | J61: =2.5*$L$4 -> 1.13398
A62: 245132 | B62: 1086 | C62: 57.6 | D62: =B62-C62 -> 1028.4 | E62: 204.87 | F62: =IF(E62="","",B62-E62) -> 881.13 | G62: MFO Lot 3704 (LOT00003704), PP#9 | H62: =$L$21 -> 0.11056982 | I62: =IF(H62="","",H62*D62) -> 113.71001 | J62: =2.5*$L$4 -> 1.13398
A63: 245180 | B63: 1033 | C63: 57.6 | D63: =B63-C63 -> 975.4 | E63: 204.87 | F63: =IF(E63="","",B63-E63) -> 828.13 | G63: MFO Lot 3750 (LOT00003750), PP#10 | H63: =$L$22 -> 0.12868957 | I63: =IF(H63="","",H63*D63) -> 125.5238 | J63: =2.5*$L$4 -> 1.13398
A64: 228474 | B64: 1102 | C64: 57.6 | D64: =B64-C64 -> 1044.4 | E64: 204.87 | F64: =IF(E64="","",B64-E64) -> 897.13 | G64: MFO Lot 4242 (LOT00004242), November 2025 | H64: =$L$11 -> 0.13921405 | I64: =IF(H64="","",H64*D64) -> 145.39516 | J64: =2.5*$L$4 -> 1.13398
A65: 228477 | B65: 1051 | C65: 57.6 | D65: =B65-C65 -> 993.4 | E65: 204.87 | F65: =IF(E65="","",B65-E65) -> 846.13 | G65: MFO Lot 4318 (LOT00004318), November 2025 | H65: =$L$11 -> 0.13921405 | I65: =IF(H65="","",H65*D65) -> 138.29524 | J65: =2.5*$L$4 -> 1.13398
...

Sheet Kerry
A1: BATCH HEADER — Kerry (Calciner Waste Oil, IBC Totes)
A2: Batch ID (INJ-YYYY-WXX) | B2: INJ-08-2026-W5 | N2: Constants
A3: Week Start (Sat) | B3: 46256 | N3: Lbs/Kg | O3: 2.20462
A4: Week End (Sat) | B4: 46263 | N4: Kg/Lbs | O4: 0.453592
N5: Filtration Solids Content (Kerry Calciner) | O5: =HYPERLINK("https://drive.google.com/file/d/1twIf0H9Ma4crVsPgD0Iq6eFDwxQIC-ni/view",0.00071) -> 0.00071
N6: pH range (target) | O6: 2.0 - 4.0
N7: Testing Uncertainty | O7: 0.004
A8: SECTION 1 - IBC LEDGER (one row per Kerry tote; tote tag mass is authoritative)
A9: Date | B9: Full Ticket (lb) | C9: Empty Ticket 2 (lb) | D9: Gross Mass (kg) — transport | E9: Net Oil (kg) | F9: Net Injected (kg) — MOBI | G9: pH | H9: Notes | I9: C Content | J9: C Content Uncertainty | K9: Mass Uncertainty (kg)
A20: SECTION 2 - ROLLUP
A21: Σ Net Oil — pre-filtration (kg) | B21: Filtration Loss (kg) | C21: MOBI (kg) | D21: pH
A22: =SUMIFS(E10:E18,A10:A18,"<>") -> 0 | B22: =A22*$O$5 -> 0 | C22: =A22-B22 -> 0 | D22: =IFERROR(AVERAGE(G10:G18),"")

Sheet QOWV Shipments & EE Allocation
A1: INJ-08-2026-W5 - QOWV Shipments & EE Mileage Allocation
A4: BATCH SUMMARY
A5: Batch | B5: Fraction | C5: Inj. Week | D5: # Totes | E5: Shipping Orders (relevant totes)
A6: INJ-08-2026-W5 | B6: QOWV | C6: 2026-08-22 to 2026-08-29 | D6: =COUNTA(QOWV!A11:A89) -> 79 | E6: 12 shipping group(s) direct CO->LA = 79 totes, all injected this week. Totals-on-truck counted from BGN master Ship Status; groups with Ship Status "Shipped" are resolved by Date Shipped. No Kansas-routed totes this week (Table B = 0).
A8: Charm CO -> Basco LA distance (one-way mi) | B8: 1201
A10: EE ALLOCATION TABLE - A. Direct Charm CO -> Basco LA
A11: Truck (shipping order) | B11: Ship Date | C11: Total Totes on Truck | D11: Batch-Relevant Totes | E11: Batch Share of Truck | F11: Mileage (one-way) | G11: Allocated Miles
A12: Shipped 12/2/2025 (by Date Shipped) | B12: 45993 | C12: 36 | D12: 23 | E12: =IFERROR(D12/C12,"") -> 0.63888889 | F12: =$B$8 -> 1201 | G12: =IFERROR(E12*F12,"") -> 767.30556
A13: COLA23 | C13: 20 | D13: 20 | E13: =IFERROR(D13/C13,"") -> 1 | F13: =$B$8 -> 1201 | G13: =IFERROR(E13*F13,"") -> 1201
A14: Shipped 12/3/2025 (by Date Shipped) | B14: 45994 | C14: 18 | D14: 16 | E14: =IFERROR(D14/C14,"") -> 0.88888889 | F14: =$B$8 -> 1201 | G14: =IFERROR(E14*F14,"") -> 1067.5556
A15: COLA_32 | B15: 46254 | C15: 18 | D15: 5 | E15: =IFERROR(D15/C15,"") -> 0.27777778 | F15: =$B$8 -> 1201 | G15: =IFERROR(E15*F15,"") -> 333.61111
A16: Shipped 12/1/2025 (by Date Shipped) | B16: 45992 | C16: 40 | D16: 3 | E16: =IFERROR(D16/C16,"") -> 0.075 | F16: =$B$8 -> 1201 | G16: =IFERROR(E16*F16,"") -> 90.075
A17: COLA21 | C17: 20 | D17: 3 | E17: =IFERROR(D17/C17,"") -> 0.15 | F17: =$B$8 -> 1201 | G17: =IFERROR(E17*F17,"") -> 180.15
A18: Shipped 12/5/2025 (by Date Shipped) | B18: 45996 | C18: 36 | D18: 2 | E18: =IFERROR(D18/C18,"") -> 0.055555556 | F18: =$B$8 -> 1201 | G18: =IFERROR(E18*F18,"") -> 66.722222
A19: COLA20 | B19: 46195 | C19: 19 | D19: 2 | E19: =IFERROR(D19/C19,"") -> 0.10526316 | F19: =$B$8 -> 1201 | G19: =IFERROR(E19*F19,"") -> 126.42105
A20: COLA-31 | B20: 46252 | C20: 20 | D20: 2 | E20: =IFERROR(D20/C20,"") -> 0.1 | F20: =$B$8 -> 1201 | G20: =IFERROR(E20*F20,"") -> 120.1
A21: Shipped 12/9/2025 (by Date Shipped) | B21: 46000 | C21: 36 | D21: 1 | E21: =IFERROR(D21/C21,"") -> 0.027777778 | F21: =$B$8 -> 1201 | G21: =IFERROR(E21*F21,"") -> 33.361111
A22: Shipped 12/16/2025 (by Date Shipped) | B22: 46007 | C22: 1 | D22: 1 | E22: =IFERROR(D22/C22,"") -> 1 | F22: =$B$8 -> 1201 | G22: =IFERROR(E22*F22,"") -> 1201
A23: COLA_27 | B23: 46227 | C23: 20 | D23: 1 | E23: =IFERROR(D23/C23,"") -> 0.05 | F23: =$B$8 -> 1201 | G23: =IFERROR(E23*F23,"") -> 60.05
A24: SUBTOTAL A - Direct | C24: =SUM(C12:C23) -> 284 | D24: =SUM(D12:D23) -> 79 | G24: =SUM(G12:G23) -> 5247.3516

Sheet WODO Shipments & EE Allocation
A1: INJ-08-2026-W5 - WODO Shipments & EE Mileage Allocation
A4: BATCH SUMMARY
A5: Batch | B5: Fraction | C5: Inj. Week | D5: # Totes | E5: Shipping Orders (relevant totes)
A6: INJ-08-2026-W5 | B6: WODO | C6: 2026-08-22 to 2026-08-29 | D6: =COUNTA(WODO!A11:A28) -> 18 | E6: 1 shipping order(s) direct CO->LA: COLA_33 = 18 totes. Total-on-truck counted from BGN master Ship Status; COLA_33 carries exactly these 18 WODO totes, so batch share = 100%.
A8: Charm CO -> Basco LA distance (one-way mi) | B8: 1201
A10: EE ALLOCATION TABLE
A11: Truck (shipping order) | B11: Ship Date | C11: Total Totes on Truck | D11: Batch-Relevant Totes | E11: Batch Share of Truck | F11: Mileage (one-way) | G11: Allocated Miles
A12: COLA_33 | B12: 46258 | C12: 18 | D12: 18 | E12: =IFERROR(D12/C12,"") -> 1 | F12: =$B$8 -> 1201 | G12: =IFERROR(E12*F12,"") -> 1201
A14: TOTAL | C14: =SUM(C12:C13) -> 18 | D14: =SUM(D12:D13) -> 18 | G14: =SUM(G12:G13) -> 1201
